Workbook

Sheet 目录
A1: 项目目录
A2: 序号 | B2: 项目名称 | C2: 项目简称 | D2: 备注 | F2: 汇总序号(辅助)
A3: 1 | B3: 重庆铜梁110kV淮阳站阳高线10kV配套送出工程（安装） | C3: 淮阳站阳高线 | F3: =IF(C3="","",IF(COUNTIF(C$3:C3,C3)=1,MAX(F$2:F2)+1,"")) -> 1
A4: 2 | B4: 重庆市合川区云门街道云龙社区居民委员会(铁工厂还房建设项目)高压新装用电工程 | C4: 云龙社区 | F4: =IF(C4="","",IF(COUNTIF(C$3:C4,C4)=1,MAX(F$2:F3)+1,"")) -> 2
A5: 3 | B5: 高新区厂房及配套设施提质改造项目开票到瑞翔厂区电力土建(管廊)建设工程 | C5: 合川瑞翔 | F5: =IF(C5="","",IF(COUNTIF(C$3:C5,C5)=1,MAX(F$2:F4)+1,"")) -> 3
A6: 4 | B6: 重庆铜梁铜城2回金龙物业管理有限公司10kV业扩配套工程 | C6: 铜城2回、玉璟尚线、铁井一回、淮拦线4 | F6: =IF(C6="","",IF(COUNTIF(C$3:C6,C6)=1,MAX(F$2:F5)+1,"")) -> 4
A7: 5 | B7: 重庆铜梁玉璟尚线金龙物业管理有限公司10kV业扩配套工程 | C7: 铜城2回、玉璟尚线、铁井一回、淮拦线4 | F7: =IF(C7="","",IF(COUNTIF(C$3:C7,C7)=1,MAX(F$2:F6)+1,""))
A8: 6 | B8: 重庆铜梁铁井一回1#环网柜等6个10kV老旧环网柜改造工程(安装) | C8: 铜城2回、玉璟尚线、铁井一回、淮拦线4 | F8: =IF(C8="","",IF(COUNTIF(C$3:C8,C8)=1,MAX(F$2:F7)+1,""))
A9: 7 | B9: 重庆铜梁淮拦线4#环网柜等6个10kV老旧环网柜改造工程（安装） | C9: 铜城2回、玉璟尚线、铁井一回、淮拦线4 | F9: =IF(C9="","",IF(COUNTIF(C$3:C9,C9)=1,MAX(F$2:F8)+1,""))
A10: 8 | B10: 国网重庆合川供电公司2026年用电信息采集系统建筑相关工程施工(包4) | C10: 合川表计 | F10: =IF(C10="","",IF(COUNTIF(C$3:C10,C10)=1,MAX(F$2:F9)+1,"")) -> 5
A11: 9 | B11: 铜梁区园区屋顶分布式光伏发电建设项目-蒲吕片区A段10千伏电力新建工程 | C11: 蒲吕片区A段 | F11: =IF(C11="","",IF(COUNTIF(C$3:C11,C11)=1,MAX(F$2:F10)+1,"")) -> 6
A12: 10 | F12: =IF(C12="","",IF(COUNTIF(C$3:C12,C12)=1,MAX(F$2:F11)+1,""))
A13: 11 | F13: =IF(C13="","",IF(COUNTIF(C$3:C13,C13)=1,MAX(F$2:F12)+1,""))
A14: 12 | F14: =IF(C14="","",IF(COUNTIF(C$3:C14,C14)=1,MAX(F$2:F13)+1,""))
A15: 13 | F15: =IF(C15="","",IF(COUNTIF(C$3:C15,C15)=1,MAX(F$2:F14)+1,""))
A16: 14 | F16: =IF(C16="","",IF(COUNTIF(C$3:C16,C16)=1,MAX(F$2:F15)+1,""))
A17: 15 | F17: =IF(C17="","",IF(COUNTIF(C$3:C17,C17)=1,MAX(F$2:F16)+1,""))
A18: 16 | F18: =IF(C18="","",IF(COUNTIF(C$3:C18,C18)=1,MAX(F$2:F17)+1,""))
A19: 17 | F19: =IF(C19="","",IF(COUNTIF(C$3:C19,C19)=1,MAX(F$2:F18)+1,""))
A20: 18 | F20: =IF(C20="","",IF(COUNTIF(C$3:C20,C20)=1,MAX(F$2:F19)+1,""))
A21: 19 | F21: =IF(C21="","",IF(COUNTIF(C$3:C21,C21)=1,MAX(F$2:F20)+1,""))
A22: 20 | F22: =IF(C22="","",IF(COUNTIF(C$3:C22,C22)=1,MAX(F$2:F21)+1,""))
F23: =IF(C23="","",IF(COUNTIF(C$3:C23,C23)=1,MAX(F$2:F22)+1,""))
F24: =IF(C24="","",IF(COUNTIF(C$3:C24,C24)=1,MAX(F$2:F23)+1,""))
F25: =IF(C25="","",IF(COUNTIF(C$3:C25,C25)=1,MAX(F$2:F24)+1,""))
F26: =IF(C26="","",IF(COUNTIF(C$3:C26,C26)=1,MAX(F$2:F25)+1,""))
F27: =IF(C27="","",IF(COUNTIF(C$3:C27,C27)=1,MAX(F$2:F26)+1,""))
F28: =IF(C28="","",IF(COUNTIF(C$3:C28,C28)=1,MAX(F$2:F27)+1,""))
F29: =IF(C29="","",IF(COUNTIF(C$3:C29,C29)=1,MAX(F$2:F28)+1,""))
F30: =IF(C30="","",IF(COUNTIF(C$3:C30,C30)=1,MAX(F$2:F29)+1,""))
F31: =IF(C31="","",IF(COUNTIF(C$3:C31,C31)=1,MAX(F$2:F30)+1,""))
F32: =IF(C32="","",IF(COUNTIF(C$3:C32,C32)=1,MAX(F$2:F31)+1,""))
F33: =IF(C33="","",IF(COUNTIF(C$3:C33,C33)=1,MAX(F$2:F32)+1,""))
F34: =IF(C34="","",IF(COUNTIF(C$3:C34,C34)=1,MAX(F$2:F33)+1,""))
... F102: =IF(C102="","",IF(COUNTIF(C$3:C102,C102)=1,MAX(F$2:F101)+1,""))

Sheet 发票统计
A1: 项目总台账
A2: 项目 简称 | B2: 月份 | C2: 项目 名称 | D2: 摘要 | E2: 收票 单位 | F2: 发票 性质 | G2: 管理 费点 | H2: 销售金额 | I2: 管理费 | J2: 应开 成本票 | K2: 已开 成本票 | L2: 未开 成本票 | M2: 应收款 | N2: 质保金 | O2: 已收款 | P2: 未收款 | Q2: 应付 工程款 | R2: 扣除 管理费 | S2: 已付 工程款 | T2: 未付 工程款 | U2: 备注 | V2: 校验 | W2: 取数键(辅助)
H3: =SUM(H4:H1003) -> 2206559.2 | I3: =SUM(I4:I1003) -> 65304.158 | J3: =SUM(J4:J1003) -> 2141255 | K3: =SUM(K4:K1003) -> 2098816.7 | L3: =J3-K3 -> 42438.29 | M3: =SUM(M4:M1003) -> 2206559.2 | N3: =SUM(N4:N1003) -> 0 | O3: =SUM(O4:O1003) -> 1500594.2 | P3: =M3-N3-O3 -> 705964.91 | Q3: =SUM(Q4:Q1003) -> 0 | R3: =SUM(R4:R1003) -> 0 | S3: =SUM(S4:S1003) -> 576643 | T3: =Q3-R3-S3 -> -576643 | V3: =IF(COUNTA(C4:C1003)>COUNTIF(W4:W1003,"?*"),"⚠ 有 "&(COUNTA(C4:C1003)-COUNTIF(W4:W1003,"?*"))&" 行缺公式或缺简称",IF(COUNTIF(V4:V1003,"⚠*")>0,"⚠ "&COUNTIF(V4:V1003,"⚠*")&" 行有错，往下看",IF(COUNTIF(V4:V1003,"△*")>0,"△ "&COUNTIF(V4:V1003,"△*")&" 行请留意","✓ 全部通过"))) -> △ 2 行请留意
A4: =IF($C4="","",IFERROR(VLOOKUP($C4,目录!$B:$C,2,0)&"","⚠目录里没有")) -> 淮阳站阳高线 | B4: =IF($D4="","",IFERROR(MID($D4,FIND(".",$D4)+1,FIND(".",$D4,FIND(".",$D4)+1)-FIND(".",$D4)-1)&"月","")) -> 3月 | C4: 重庆铜梁110kV淮阳站阳高线10kV配套送出工程（安装） | D4: 2026.3.25新德润开票到民能：淮阳站阳高线 | E4: 民能 | F4: 3%专票 | H4: 57824 | I4: =IF($H4="","",N($H4)*N($G4)) -> 0 | J4: =IF($H4="","",N($H4)-N($I4)) -> 57824 | K4: 57824 | L4: =IF($A4="","",SUMIF($A$4:$A4,$A4,$J$4:$J4)-SUMIF($A$4:$A4,$A4,$K$4:$K4)) -> 0 | M4: =IF($H4="","",N($H4)) -> 57824 | P4: =IF($A4="","",SUMIF($A$4:$A4,$A4,$M$4:$M4)-SUMIF($A$4:$A4,$A4,$N$4:$N4)-SUMIF($A$4:$A4,$A4,$O$4:$O4)) -> 57824 | R4: 0 | S4: 0 | T4: =IF($A4="","",SUMIF($A$4:$A4,$A4,$Q$4:$Q4)-SUMIF($A$4:$A4,$A4,$R$4:$R4)-SUMIF($A$4:$A4,$A4,$S$4:$S4)) -> 0 | V4: =IF(AND($C4="",COUNTA($D4:$H4,$K4,$N4:$O4,$Q4:$S4,$U4)=0),"",IF($C4="","⚠ 没填项目名称",IF($A4="⚠目录里没有","⚠ 项目名称在目录里找不到（先加到目录）",IF($A4="","⚠ 目录里这个项目没填简称",IF(ISTEXT($G4)+ISTEXT($H4)+ISTEXT($K4)+ISTEXT($N4)+ISTEXT($O4)+ISTEXT($Q4)+ISTEXT($R4)+ISTEXT($S4)>0,"⚠ 金额列里有文字，算不进合计",IF(N($G4)>=1,"⚠ 管理费点要填百分比，如 10%",IF(AND($D4<>"",$B4=""),"△ 摘要开头没写日期（如 2026.9.21），月份取不到",IF(AND(N($H4)<>0,COUNTIFS($A$4:$A$1003,$A4,$H$4:$H$1003,$H4,$D$4:$D$1003,LEFT($D4,9)&"*")>1),"△ 同一天同项目有一样的销售金额，看看是不是录重了","✓")))))))) -> ✓ | W4: =IF($A4="","",$A4&"#"&COUNTIF($A$4:$A4,$A4)) -> 淮阳站阳高线#1
A5: =IF($C5="","",IFERROR(VLOOKUP($C5,目录!$B:$C,2,0)&"","⚠目录里没有")) -> 淮阳站阳高线 | B5: =IF($D5="","",IFERROR(MID($D5,FIND(".",$D5)+1,FIND(".",$D5,FIND(".",$D5)+1)-FIND(".",$D5)-1)&"月","")) -> 3月 | C5: 重庆铜梁110kV淮阳站阳高线10kV配套送出工程（安装） | D5: 2026.3.25张氏机电-新德润：淮阳站阳高线 | E5: 新德润 | H5: 50120.61 | I5: =IF($H5="","",N($H5)*N($G5)) -> 0 | J5: =IF($H5="","",N($H5)-N($I5)) -> 50120.61 | K5: 50120.61 | L5: =IF($A5="","",SUMIF($A$4:$A5,$A5,$J$4:$J5)-SUMIF($A$4:$A5,$A5,$K$4:$K5)) -> 0 | M5: =IF($H5="","",N($H5)) -> 50120.61 | P5: =IF($A5="","",SUMIF($A$4:$A5,$A5,$M$4:$M5)-SUMIF($A$4:$A5,$A5,$N$4:$N5)-SUMIF($A$4:$A5,$A5,$O$4:$O5)) -> 107944.61 | T5: =IF($A5="","",SUMIF($A$4:$A5,$A5,$Q$4:$Q5)-SUMIF($A$4:$A5,$A5,$R$4:$R5)-SUMIF($A$4:$A5,$A5,$S$4:$S5)) -> 0 | V5: =IF(AND($C5="",COUNTA($D5:$H5,$K5,$N5:$O5,$Q5:$S5,$U5)=0),"",IF($C5="","⚠ 没填项目名称",IF($A5="⚠目录里没有","⚠ 项目名称在目录里找不到（先加到目录）",IF($A5="","⚠ 目录里这个项目没填简称",IF(ISTEXT($G5)+ISTEXT($H5)+ISTEXT($K5)+ISTEXT($N5)+ISTEXT($O5)+ISTEXT($Q5)+ISTEXT($R5)+ISTEXT($S5)>0,"⚠ 金额列里有文字，算不进合计",IF(N($G5)>=1,"⚠ 管理费点要填百分比，如 10%",IF(AND($D5<>"",$B5=""),"△ 摘要开头没写日期（如 2026.9.21），月份取不到",IF(AND(N($H5)<>0,COUNTIFS($A$4:$A$1003,$A5,$H$4:$H$1003,$H5,$D$4:$D$1003,LEFT($D5,9)&"*")>1),"△ 同一天同项目有一样的销售金额，看看是不是录重了","✓")))))))) -> ✓ | W5: =IF($A5="","",$A5&"#"&COUNTIF($A$4:$A5,$A5)) -> 淮阳站阳高线#2
A6: =IF($C6="","",IFERROR(VLOOKUP($C6,目录!$B:$C,2,0)&"","⚠目录里没有")) -> 云龙社区 | B6: =IF($D6="","",IFERROR(MID($D6,FIND(".",$D6)+1,FIND(".",$D6,FIND(".",$D6)+1)-FIND(".",$D6)-1)&"月","")) -> 4月 | C6: 重庆市合川区云门街道云龙社区居民委员会(铁工厂还房建设项目)高压新装用电工程 | D6: 2026.4.28庆文开票给新德润：云龙社区居民委员会 | E6: 新德润 | F6: 3%专票 | H6: 183486.24 | I6: =IF($H6="","",N($H6)*N($G6)) -> 0 | J6: =IF($H6="","",N($H6)-N($I6)) -> 183486.24 | K6: 183486.24 | L6: =IF($A6="","",SUMIF($A$4:$A6,$A6,$J$4:$J6)-SUMIF($A$4:$A6,$A6,$K$4:$K6)) -> 0 | M6: =IF($H6="","",N($H6)) -> 183486.24 | P6: =IF($A6="","",SUMIF($A$4:$A6,$A6,$M$4:$M6)-SUMIF($A$4:$A6,$A6,$N$4:$N6)-SUMIF($A$4:$A6,$A6,$O$4:$O6)) -> 183486.24 | T6: =IF($A6="","",SUMIF($A$4:$A6,$A6,$Q$4:$Q6)-SUMIF($A$4:$A6,$A6,$R$4:$R6)-SUMIF($A$4:$A6,$A6,$S$4:$S6)) -> 0 | V6: =IF(AND($C6="",COUNTA($D6:$H6,$K6,$N6:$O6,$Q6:$S6,$U6)=0),"",IF($C6="","⚠ 没填项目名称",IF($A6="⚠目录里没有","⚠ 项目名称在目录里找不到（先加到目录）",IF($A6="","⚠ 目录里这个项目没填简称",IF(ISTEXT($G6)+ISTEXT($H6)+ISTEXT($K6)+ISTEXT($N6)+ISTEXT($O6)+ISTEXT($Q6)+ISTEXT($R6)+ISTEXT($S6)>0,"⚠ 金额列里有文字，算不进合计",IF(N($G6)>=1,"⚠ 管理费点要填百分比，如 10%",IF(AND($D6<>"",$B6=""),"△ 摘要开头没写日期（如 2026.9.21），月份取不到",IF(AND(N($H6)<>0,COUNTIFS($A$4:$A$1003,$A6,$H$4:$H$1003,$H6,$D$4:$D$1003,LEFT($D6,9)&"*")>1),"△ 同一天同项目有一样的销售金额，看看是不是录重了","✓")))))))) -> ✓ | W6: =IF($A6="","",$A6&"#"&COUNTIF($A$4:$A6,$A6)) -> 云龙社区#1
A7: =IF($C7="","",IFERROR(VLOOKUP($C7,目录!$B:$C,2,0)&"","⚠目录里没有")) -> 云龙社区 | B7: =IF($D7="","",IFERROR(MID($D7,FIND(".",$D7)+1,FIND(".",$D7,FIND(".",$D7)+1)-FIND(".",$D7)-1)&"月","")) -> 4月 | C7: 重庆市合川区云门街道云龙社区居民委员会(铁工厂还房建设项目)高压新装用电工程 | D7: 2026.4.30莨富收到新德润款项：云龙社区居民委员会 | E7: 新德润 | I7: =IF($H7="","",N($H7)*N($G7)) | J7: =IF($H7="","",N($H7)-N($I7)) | L7: =IF($A7="","",SUMIF($A$4:$A7,$A7,$J$4:$J7)-SUMIF($A$4:$A7,$A7,$K$4:$K7)) -> 0 | M7: =IF($H7="","",N($H7)) | O7: 183486.24 | P7: =IF($A7="","",SUMIF($A$4:$A7,$A7,$M$4:$M7)-SUMIF($A$4:$A7,$A7,$N$4:$N7)-SUMIF($A$4:$A7,$A7,$O$4:$O7)) -> 0 | T7: =IF($A7="","",SUMIF($A$4:$A7,$A7,$Q$4:$Q7)-SUMIF($A$4:$A7,$A7,$R$4:$R7)-SUMIF($A$4:$A7,$A7,$S$4:$S7)) -> 0 | V7: =IF(AND($C7="",COUNTA($D7:$H7,$K7,$N7:$O7,$Q7:$S7,$U7)=0),"",IF($C7="","⚠ 没填项目名称",IF($A7="⚠目录里没有","⚠ 项目名称在目录里找不到（先加到目录）",IF($A7="","⚠ 目录里这个项目没填简称",IF(ISTEXT($G7)+ISTEXT($H7)+ISTEXT($K7)+ISTEXT($N7)+ISTEXT($O7)+ISTEXT($Q7)+ISTEXT($R7)+ISTEXT($S7)>0,"⚠ 金额列里有文字，算不进合计",IF(N($G7)>=1,"⚠ 管理费点要填百分比，如 10%",IF(AND($D7<>"",$B7=""),"△ 摘要开头没写日期（如 2026.9.21），月份取不到",IF(AND(N($H7)<>0,COUNTIFS($A$4:$A$1003,$A7,$H$4:$H$1003,$H7,$D$4:$D$1003,LEFT($D7,9)&"*")>1),"△ 同一天同项目有一样的销售金额，看看是不是录重了","✓")))))))) -> ✓ | W7: =IF($A7="","",$A7&"#"&COUNTIF($A$4:$A7,$A7)) -> 云龙社区#2
A8: =IF($C8="","",IFERROR(VLOOKUP($C8,目录!$B:$C,2,0)&"","⚠目录里没有")) -> 云龙社区 | B8: =IF($D8="","",IFERROR(MID($D8,FIND(".",$D8)+1,FIND(".",$D8,FIND(".",$D8)+1)-FIND(".",$D8)-1)&"月","")) -> 5月 | C8: 重庆市合川区云门街道云龙社区居民委员会(铁工厂还房建设项目)高压新装用电工程 | D8: 2026.5.7庆文开票给新德润：云龙社区居民委员会 | E8: 新德润 | F8: 3%专票 | H8: 43774.56 | I8: =IF($H8="","",N($H8)*N($G8)) -> 0 | J8: =IF($H8="","",N($H8)-N($I8)) -> 43774.56 | K8: 43774.56 | L8: =IF($A8="","",SUMIF($A$4:$A8,$A8,$J$4:$J8)-SUMIF($A$4:$A8,$A8,$K$4:$K8)) -> 0 | M8: =IF($H8="","",N($H8)) -> 43774.56 | P8: =IF($A8="","",SUMIF($A$4:$A8,$A8,$M$4:$M8)-SUMIF($A$4:$A8,$A8,$N$4:$N8)-SUMIF($A$4:$A8,$A8,$O$4:$O8)) -> 43774.56 | T8: =IF($A8="","",SUMIF($A$4:$A8,$A8,$Q$4:$Q8)-SUMIF($A$4:$A8,$A8,$R$4:$R8)-SUMIF($A$4:$A8,$A8,$S$4:$S8)) -> 0 | V8: =IF(AND($C8="",COUNTA($D8:$H8,$K8,$N8:$O8,$Q8:$S8,$U8)=0),"",IF($C8="","⚠ 没填项目名称",IF($A8="⚠目录里没有","⚠ 项目名称在目录里找不到（先加到目录）",IF($A8="","⚠ 目录里这个项目没填简称",IF(ISTEXT($G8)+ISTEXT($H8)+ISTEXT($K8)+ISTEXT($N8)+ISTEXT($O8)+ISTEXT($Q8)+ISTEXT($R8)+ISTEXT($S8)>0,"⚠ 金额列里有文字，算不进合计",IF(N($G8)>=1,"⚠ 管理费点要填百分比，如 10%",IF(AND($D8<>"",$B8=""),"△ 摘要开头没写日期（如 2026.9.21），月份取不到",IF(AND(N($H8)<>0,COUNTIFS($A$4:$A$1003,$A8,$H$4:$H$1003,$H8,$D$4:$D$1003,LEFT($D8,9)&"*")>1),"△ 同一天同项目有一样的销售金额，看看是不是录重了","✓")))))))) -> ✓ | W8: =IF($A8="","",$A8&"#"&COUNTIF($A$4:$A8,$A8)) -> 云龙社区#3
A9: =IF($C9="","",IFERROR(VLOOKUP($C9,目录!$B:$C,2,0)&"","⚠目录里没有")) -> 云龙社区 | B9: =IF($D9="","",IFERROR(MID($D9,FIND(".",$D9)+1,FIND(".",$D9,FIND(".",$D9)+1)-FIND(".",$D9)-1)&"月","")) -> 5月 | C9: 重庆市合川区云门街道云龙社区居民委员会(铁工厂还房建设项目)高压新装用电工程 | D9: 2026.5.13庆文公账收到新德润款项：云龙社区居民委员会 | E9: 新德润 | I9: =IF($H9="","",N($H9)*N($G9)) | J9: =IF($H9="","",N($H9)-N($I9)) | L9: =IF($A9="","",SUMIF($A$4:$A9,$A9,$J$4:$J9)-SUMIF($A$4:$A9,$A9,$K$4:$K9)) -> 0 | M9: =IF($H9="","",N($H9)) | O9: 43774.56 | P9: =IF($A9="","",SUMIF($A$4:$A9,$A9,$M$4:$M9)-SUMIF($A$4:$A9,$A9,$N$4:$N9)-SUMIF($A$4:$A9,$A9,$O$4:$O9)) -> 0 | T9: =IF($A9="","",SUMIF($A$4:$A9,$A9,$Q$4:$Q9)-SUMIF($A$4:$A9,$A9,$R$4:$R9)-SUMIF($A$4:$A9,$A9,$S$4:$S9)) -> 0 | V9: =IF(AND($C9="",COUNTA($D9:$H9,$K9,$N9:$O9,$Q9:$S9,$U9)=0),"",IF($C9="","⚠ 没填项目名称",IF($A9="⚠目录里没有","⚠ 项目名称在目录里找不到（先加到目录）",IF($A9="","⚠ 目录里这个项目没填简称",IF(ISTEXT($G9)+ISTEXT($H9)+ISTEXT($K9)+ISTEXT($N9)+ISTEXT($O9)+ISTEXT($Q9)+ISTEXT($R9)+ISTEXT($S9)>0,"⚠ 金额列里有文字，算不进合计",IF(N($G9)>=1,"⚠ 管理费点要填百分比，如 10%",IF(AND($D9<>"",$B9=""),"△ 摘要开头没写日期（如 2026.9.21），月份取不到",IF(AND(N($H9)<>0,COUNTIFS($A$4:$A$1003,$A9,$H$4:$H$1003,$H9,$D$4:$D$1003,LEFT($D9,9)&"*")>1),"△ 同一天同项目有一样的销售金额，看看是不是录重了","✓")))))))) -> ✓ | W9: =IF($A9="","",$A9&"#"&COUNTIF($A$4:$A9,$A9)) -> 云龙社区#4
A10: =IF($C10="","",IFERROR(VLOOKUP($C10,目录!$B:$C,2,0)&"","⚠目录里没有")) -> 合川瑞翔 | B10: =IF($D10="","",IFERROR(MID($D10,FIND(".",$D10)+1,FIND(".",$D10,FIND(".",$D10)+1)-FIND(".",$D10)-1)&"月","")) -> 6月 | C10: 高新区厂房及配套设施提质改造项目开票到瑞翔厂区电力土建(管廊)建设工程 | D10: 2026.6.17庆文开票给新德润：瑞翔厂区电力土建 | E10: 新德润 | F10: 1%专票 | H10: 100000 | I10: =IF($H10="","",N($H10)*N($G10)) -> 0 | J10: =IF($H10="","",N($H10)-N($I10)) -> 100000 | K10: 100000 | L10: =IF($A10="","",SUMIF($A$4:$A10,$A10,$J$4:$J10)-SUMIF($A$4:$A10,$A10,$K$4:$K10)) -> 0 | M10: =IF($H10="","",N($H10)) -> 100000 | P10: =IF($A10="","",SUMIF($A$4:$A10,$A10,$M$4:$M10)-SUMIF($A$4:$A10,$A10,$N$4:$N10)-SUMIF($A$4:$A10,$A10,$O$4:$O10)) -> 100000 | T10: =IF($A10="","",SUMIF($A$4:$A10,$A10,$Q$4:$Q10)-SUMIF($A$4:$A10,$A10,$R$4:$R10)-SUMIF($A$4:$A10,$A10,$S$4:$S10)) -> 0 | V10: =IF(AND($C10="",COUNTA($D10:$H10,$K10,$N10:$O10,$Q10:$S10,$U10)=0),"",IF($C10="","⚠ 没填项目名称",IF($A10="⚠目录里没有","⚠ 项目名称在目录里找不到（先加到目录）",IF($A10="","⚠ 目录里这个项目没填简称",IF(ISTEXT($G10)+ISTEXT($H10)+ISTEXT($K10)+ISTEXT($N10)+ISTEXT($O10)+ISTEXT($Q10)+ISTEXT($R10)+ISTEXT($S10)>0,"⚠ 金额列里有文字，算不进合计",IF(N($G10)>=1,"⚠ 管理费点要填百分比，如 10%",IF(AND($D10<>"",$B10=""),"△ 摘要开头没写日期（如 2026.9.21），月份取不到",IF(AND(N($H10)<>0,COUNTIFS($A$4:$A$1003,$A10,$H$4:$H$1003,$H10,$D$4:$D$1003,LEFT($D10,9)&"*")>1),"△ 同一天同项目有一样的销售金额，看看是不是录重了","✓")))))))) -> ✓ | W10: =IF($A10="","",$A10&"#"&COUNTIF($A$4:$A10,$A10)) -> 合川瑞翔#1
A11: =IF($C11="","",IFERROR(VLOOKUP($C11,目录!$B:$C,2,0)&"","⚠目录里没有")) -> 合川瑞翔 | B11: =IF($D11="","",IFERROR(MID($D11,FIND(".",$D11)+1,FIND(".",$D11,FIND(".",$D11)+1)-FIND(".",$D11)-1)&"月","")) -> 6月 | C11: 高新区厂房及配套设施提质改造项目开票到瑞翔厂区电力土建(管廊)建设工程 | D11: 2026.6.18庆文收到新德润打款：瑞翔厂区电力 | E11: 新德润 | I11: =IF($H11="","",N($H11)*N($G11)) | J11: =IF($H11="","",N($H11)-N($I11)) | L11: =IF($A11="","",SUMIF($A$4:$A11,$A11,$J$4:$J11)-SUMIF($A$4:$A11,$A11,$K$4:$K11)) -> 0 | M11: =IF($H11="","",N($H11)) | O11: 100000 | P11: =IF($A11="","",SUMIF($A$4:$A11,$A11,$M$4:$M11)-SUMIF($A$4:$A11,$A11,$N$4:$N11)-SUMIF($A$4:$A11,$A11,$O$4:$O11)) -> 0 | T11: =IF($A11="","",SUMIF($A$4:$A11,$A11,$Q$4:$Q11)-SUMIF($A$4:$A11,$A11,$R$4:$R11)-SUMIF($A$4:$A11,$A11,$S$4:$S11)) -> 0 | V11: =IF(AND($C11="",COUNTA($D11:$H11,$K11,$N11:$O11,$Q11:$S11,$U11)=0),"",IF($C11="","⚠ 没填项目名称",IF($A11="⚠目录里没有","⚠ 项目名称在目录里找不到（先加到目录）",IF($A11="","⚠ 目录里这个项目没填简称",IF(ISTEXT($G11)+ISTEXT($H11)+ISTEXT($K11)+ISTEXT($N11)+ISTEXT($O11)+ISTEXT($Q11)+ISTEXT($R11)+ISTEXT($S11)>0,"⚠ 金额列里有文字，算不进合计",IF(N($G11)>=1,"⚠ 管理费点要填百分比，如 10%",IF(AND($D11<>"",$B11=""),"△ 摘要开头没写日期（如 2026.9.21），月份取不到",IF(AND(N($H11)<>0,COUNTIFS($A$4:$A$1003,$A11,$H$4:$H$1003,$H11,$D$4:$D$1003,LEFT($D11,9)&"*")>1),"△ 同一天同项目有一样的销售金额，看看是不是录重了","✓")))))))) -> ✓ | W11: =IF($A11="","",$A11&"#"&COUNTIF($A$4:$A11,$A11)) -> 合川瑞翔#2
A12: =IF($C12="","",IFERROR(VLOOKUP($C12,目录!$B:$C,2,0)&"","⚠目录里没有")) -> 合川瑞翔 | B12: =IF($D12="","",IFERROR(MID($D12,FIND(".",$D12)+1,FIND(".",$D12,FIND(".",$D12)+1)-FIND(".",$D12)-1)&"月","")) -> 7月 | C12: 高新区厂房及配套设施提质改造项目开票到瑞翔厂区电力土建(管廊)建设工程 | D12: 2026.7.2朱氏水泥管件开票到新德润：瑞翔厂区电力土建 | E12: 新德润 | F12: 1%普票 | H12: 50200 | I12: =IF($H12="","",N($H12)*N($G12)) -> 0 | J12: =IF($H12="","",N($H12)-N($I12)) -> 50200 | K12: 50200 | L12: =IF($A12="","",SUMIF($A$4:$A12,$A12,$J$4:$J12)-SUMIF($A$4:$A12,$A12,$K$4:$K12)) -> 0 | M12: =IF($H12="","",N($H12)) -> 50200 | P12: =IF($A12="","",SUMIF($A$4:$A12,$A12,$M$4:$M12)-SUMIF($A$4:$A12,$A12,$N$4:$N12)-SUMIF($A$4:$A12,$A12,$O$4:$O12)) -> 50200 | T12: =IF($A12="","",SUMIF($A$4:$A12,$A12,$Q$4:$Q12)-SUMIF($A$4:$A12,$A12,$R$4:$R12)-SUMIF($A$4:$A12,$A12,$S$4:$S12)) -> 0 | V12: =IF(AND($C12="",COUNTA($D12:$H12,$K12,$N12:$O12,$Q12:$S12,$U12)=0),"",IF($C12="","⚠ 没填项目名称",IF($A12="⚠目录里没有","⚠ 项目名称在目录里找不到（先加到目录）",IF($A12="","⚠ 目录里这个项目没填简称",IF(ISTEXT($G12)+ISTEXT($H12)+ISTEXT($K12)+ISTEXT($N12)+ISTEXT($O12)+ISTEXT($Q12)+ISTEXT($R12)+ISTEXT($S12)>0,"⚠ 金额列里有文字，算不进合计",IF(N($G12)>=1,"⚠ 管理费点要填百分比，如 10%",IF(AND($D12<>"",$B12=""),"△ 摘要开头没写日期（如 2026.9.21），月份取不到",IF(AND(N($H12)<>0,COUNTIFS($A$4:$A$1003,$A12,$H$4:$H$1003,$H12,$D$4:$D$1003,LEFT($D12,9)&"*")>1),"△ 同一天同项目有一样的销售金额，看看是不是录重了","✓")))))))) -> ✓ | W12: =IF($A12="","",$A12&"#"&COUNTIF($A$4:$A12,$A12)) -> 合川瑞翔#3
A13: =IF($C13="","",IFERROR(VLOOKUP($C13,目录!$B:$C,2,0)&"","⚠目录里没有")) -> 合川瑞翔 | B13: =IF($D13="","",IFERROR(MID($D13,FIND(".",$D13)+1,FIND(".",$D13,FIND(".",$D13)+1)-FIND(".",$D13)-1)&"月","")) -> 7月 | C13: 高新区厂房及配套设施提质改造项目开票到瑞翔厂区电力土建(管廊)建设工程 | D13: 2026.7.6朱氏水泥管收到新德润：瑞翔厂区电力 | E13: 新德润 | I13: =IF($H13="","",N($H13)*N($G13)) | J13: =IF($H13="","",N($H13)-N($I13)) | L13: =IF($A13="","",SUMIF($A$4:$A13,$A13,$J$4:$J13)-SUMIF($A$4:$A13,$A13,$K$4:$K13)) -> 0 | M13: =IF($H13="","",N($H13)) | O13: 50200 | P13: =IF($A13="","",SUMIF($A$4:$A13,$A13,$M$4:$M13)-SUMIF($A$4:$A13,$A13,$N$4:$N13)-SUMIF($A$4:$A13,$A13,$O$4:$O13)) -> 0 | T13: =IF($A13="","",SUMIF($A$4:$A13,$A13,$Q$4:$Q13)-SUMIF($A$4:$A13,$A13,$R$4:$R13)-SUMIF($A$4:$A13,$A13,$S$4:$S13)) -> 0 | V13: =IF(AND($C13="",COUNTA($D13:$H13,$K13,$N13:$O13,$Q13:$S13,$U13)=0),"",IF($C13="","⚠ 没填项目名称",IF($A13="⚠目录里没有","⚠ 项目名称在目录里找不到（先加到目录）",IF($A13="","⚠ 目录里这个项目没填简称",IF(ISTEXT($G13)+ISTEXT($H13)+ISTEXT($K13)+ISTEXT($N13)+ISTEXT($O13)+ISTEXT($Q13)+ISTEXT($R13)+ISTEXT($S13)>0,"⚠ 金额列里有文字，算不进合计",IF(N($G13)>=1,"⚠ 管理费点要填百分比，如 10%",IF(AND($D13<>"",$B13=""),"△ 摘要开头没写日期（如 2026.9.21），月份取不到",IF(AND(N($H13)<>0,COUNTIFS($A$4:$A$1003,$A13,$H$4:$H$1003,$H13,$D$4:$D$1003,LEFT($D13,9)&"*")>1),"△ 同一天同项目有一样的销售金额，看看是不是录重了","✓")))))))) -> ✓ | W13: =IF($A13="","",$A13&"#"&COUNTIF($A$4:$A13,$A13)) -> 合川瑞翔#4
A14: =IF($C14="","",IFERROR(VLOOKUP($C14,目录!$B:$C,2,0)&"","⚠目录里没有")) -> 合川瑞翔 | B14: =IF($D14="","",IFERROR(MID($D14,FIND(".",$D14)+1,FIND(".",$D14,FIND(".",$D14)+1)-FIND(".",$D14)-1)&"月","")) -> 7月 | C14: 高新区厂房及配套设施提质改造项目开票到瑞翔厂区电力土建(管廊)建设工程 | D14: 2026.7.8庆文开票给新德润：瑞翔厂区电力土建 | E14: 新德润 | F14: 1%专票 | H14: 100000 | I14: =IF($H14="","",N($H14)*N($G14)) -> 0 | J14: =IF($H14="","",N($H14)-N($I14)) -> 100000 | K14: 100000 | L14: =IF($A14="","",SUMIF($A$4:$A14,$A14,$J$4:$J14)-SUMIF($A$4:$A14,$A14,$K$4:$K14)) -> 0 | M14: =IF($H14="","",N($H14)) -> 100000 | P14: =IF($A14="","",SUMIF($A$4:$A14,$A14,$M$4:$M14)-SUMIF($A$4:$A14,$A14,$N$4:$N14)-SUMIF($A$4:$A14,$A14,$O$4:$O14)) -> 100000 | T14: =IF($A14="","",SUMIF($A$4:$A14,$A14,$Q$4:$Q14)-SUMIF($A$4:$A14,$A14,$R$4:$R14)-SUMIF($A$4:$A14,$A14,$S$4:$S14)) -> 0 | V14: =IF(AND($C14="",COUNTA($D14:$H14,$K14,$N14:$O14,$Q14:$S14,$U14)=0),"",IF($C14="","⚠ 没填项目名称",IF($A14="⚠目录里没有","⚠ 项目名称在目录里找不到（先加到目录）",IF($A14="","⚠ 目录里这个项目没填简称",IF(ISTEXT($G14)+ISTEXT($H14)+ISTEXT($K14)+ISTEXT($N14)+ISTEXT($O14)+ISTEXT($Q14)+ISTEXT($R14)+ISTEXT($S14)>0,"⚠ 金额列里有文字，算不进合计",IF(N($G14)>=1,"⚠ 管理费点要填百分比，如 10%",IF(AND($D14<>"",$B14=""),"△ 摘要开头没写日期（如 2026.9.21），月份取不到",IF(AND(N($H14)<>0,COUNTIFS($A$4:$A$1003,$A14,$H$4:$H$1003,$H14,$D$4:$D$1003,LEFT($D14,9)&"*")>1),"△ 同一天同项目有一样的销售金额，看看是不是录重了","✓")))))))) -> ✓ | W14: =IF($A14="","",$A14&"#"&COUNTIF($A$4:$A14,$A14)) -> 合川瑞翔#5
A15: =IF($C15="","",IFERROR(VLOOKUP($C15,目录!$B:$C,2,0)&"","⚠目录里没有")) -> 合川瑞翔 | B15: =IF($D15="","",IFERROR(MID($D15,FIND(".",$D15)+1,FIND(".",$D15,FIND(".",$D15)+1)-FIND(".",$D15)-1)&"月","")) -> 7月 | C15: 高新区厂房及配套设施提质改造项目开票到瑞翔厂区电力土建(管廊)建设工程 | D15: 2026.7.9庆文收到新德润打款：瑞翔厂区电力 | E15: 新德润 | I15: =IF($H15="","",N($H15)*N($G15)) | J15: =IF($H15="","",N($H15)-N($I15)) | K15: 0 | L15: =IF($A15="","",SUMIF($A$4:$A15,$A15,$J$4:$J15)-SUMIF($A$4:$A15,$A15,$K$4:$K15)) -> 0 | M15: =IF($H15="","",N($H15)) | O15: 100000 | P15: =IF($A15="","",SUMIF($A$4:$A15,$A15,$M$4:$M15)-SUMIF($A$4:$A15,$A15,$N$4:$N15)-SUMIF($A$4:$A15,$A15,$O$4:$O15)) -> 0 | T15: =IF($A15="","",SUMIF($A$4:$A15,$A15,$Q$4:$Q15)-SUMIF($A$4:$A15,$A15,$R$4:$R15)-SUMIF($A$4:$A15,$A15,$S$4:$S15)) -> 0 | V15: =IF(AND($C15="",COUNTA($D15:$H15,$K15,$N15:$O15,$Q15:$S15,$U15)=0),"",IF($C15="","⚠ 没填项目名称",IF($A15="⚠目录里没有","⚠ 项目名称在目录里找不到（先加到目录）",IF($A15="","⚠ 目录里这个项目没填简称",IF(ISTEXT($G15)+ISTEXT($H15)+ISTEXT($K15)+ISTEXT($N15)+ISTEXT($O15)+ISTEXT($Q15)+ISTEXT($R15)+ISTEXT($S15)>0,"⚠ 金额列里有文字，算不进合计",IF(N($G15)>=1,"⚠ 管理费点要填百分比，如 10%",IF(AND($D15<>"",$B15=""),"△ 摘要开头没写日期（如 2026.9.21），月份取不到",IF(AND(N($H15)<>0,COUNTIFS($A$4:$A$1003,$A15,$H$4:$H$1003,$H15,$D$4:$D$1003,LEFT($D15,9)&"*")>1),"△ 同一天同项目有一样的销售金额，看看是不是录重了","✓")))))))) -> ✓ | W15: =IF($A15="","",$A15&"#"&COUNTIF($A$4:$A15,$A15)) -> 合川瑞翔#6
A16: =IF($C16="","",IFERROR(VLOOKUP($C16,目录!$B:$C,2,0)&"","⚠目录里没有")) -> 合川瑞翔 | B16: =IF($D16="","",IFERROR(MID($D16,FIND(".",$D16)+1,FIND(".",$D16,FIND(".",$D16)+1)-FIND(".",$D16)-1)&"月","")) -> 7月 | C16: 高新区厂房及配套设施提质改造项目开票到瑞翔厂区电力土建(管廊)建设工程 | D16: 2026.7.8铜桐桐建材开票到新德润：瑞翔厂区电力土建 | E16: 新德润 | F16: 1%普票 | H16: 49800 | I16: =IF($H16="","",N($H16)*N($G16)) -> 0 | J16: =IF($H16="","",N($H16)-N($I16)) -> 49800 | K16: 49800 | L16: =IF($A16="","",SUMIF($A$4:$A16,$A16,$J$4:$J16)-SUMIF($A$4:$A16,$A16,$K$4:$K16)) -> 0 | M16: =IF($H16="","",N($H16)) -> 49800 | P16: =IF($A16="","",SUMIF($A$4:$A16,$A16,$M$4:$M16)-SUMIF($A$4:$A16,$A16,$N$4:$N16)-SUMIF($A$4:$A16,$A16,$O$4:$O16)) -> 49800 | T16: =IF($A16="","",SUMIF($A$4:$A16,$A16,$Q$4:$Q16)-SUMIF($A$4:$A16,$A16,$R$4:$R16)-SUMIF($A$4:$A16,$A16,$S$4:$S16)) -> 0 | V16: =IF(AND($C16="",COUNTA($D16:$H16,$K16,$N16:$O16,$Q16:$S16,$U16)=0),"",IF($C16="","⚠ 没填项目名称",IF($A16="⚠目录里没有","⚠ 项目名称在目录里找不到（先加到目录）",IF($A16="","⚠ 目录里这个项目没填简称",IF(ISTEXT($G16)+ISTEXT($H16)+ISTEXT($K16)+ISTEXT($N16)+ISTEXT($O16)+ISTEXT($Q16)+ISTEXT($R16)+ISTEXT($S16)>0,"⚠ 金额列里有文字，算不进合计",IF(N($G16)>=1,"⚠ 管理费点要填百分比，如 10%",IF(AND($D16<>"",$B16=""),"△ 摘要开头没写日期（如 2026.9.21），月份取不到",IF(AND(N($H16)<>0,COUNTIFS($A$4:$A$1003,$A16,$H$4:$H$1003,$H16,$D$4:$D$1003,LEFT($D16,9)&"*")>1),"△ 同一天同项目有一样的销售金额，看看是不是录重了","✓")))))))) -> ✓ | W16: =IF($A16="","",$A16&"#"&COUNTIF($A$4:$A16,$A16)) -> 合川瑞翔#7
A17: =IF($C17="","",IFERROR(VLOOKUP($C17,目录!$B:$C,2,0)&"","⚠目录里没有")) -> 合川瑞翔 | B17: =IF($D17="","",IFERROR(MID($D17,FIND(".",$D17)+1,FIND(".",$D17,FIND(".",$D17)+1)-FIND(".",$D17)-1)&"月","")) -> 7月 | C17: 高新区厂房及配套设施提质改造项目开票到瑞翔厂区电力土建(管廊)建设工程 | D17: 2026.7.7号收到新德润打款给胡崇文：瑞翔厂区电力 | E17: 新德润 | I17: =IF($H17="","",N($H17)*N($G17)) | J17: =IF($H17="","",N($H17)-N($I17)) | K17: 0 | L17: =IF($A17="","",SUMIF($A$4:$A17,$A17,$J$4:$J17)-SUMIF($A$4:$A17,$A17,$K$4:$K17)) -> 0 | M17: =IF($H17="","",N($H17)) | O17: 49800 | P17: =IF($A17="","",SUMIF($A$4:$A17,$A17,$M$4:$M17)-SUMIF($A$4:$A17,$A17,$N$4:$N17)-SUMIF($A$4:$A17,$A17,$O$4:$O17)) -> 0 | T17: =IF($A17="","",SUMIF($A$4:$A17,$A17,$Q$4:$Q17)-SUMIF($A$4:$A17,$A17,$R$4:$R17)-SUMIF($A$4:$A17,$A17,$S$4:$S17)) -> 0 | V17: =IF(AND($C17="",COUNTA($D17:$H17,$K17,$N17:$O17,$Q17:$S17,$U17)=0),"",IF($C17="","⚠ 没填项目名称",IF($A17="⚠目录里没有","⚠ 项目名称在目录里找不到（先加到目录）",IF($A17="","⚠ 目录里这个项目没填简称",IF(ISTEXT($G17)+ISTEXT($H17)+ISTEXT($K17)+ISTEXT($N17)+ISTEXT($O17)+ISTEXT($Q17)+ISTEXT($R17)+ISTEXT($S17)>0,"⚠ 金额列里有文字，算不进合计",IF(N($G17)>=1,"⚠ 管理费点要填百分比，如 10%",IF(AND($D17<>"",$B17=""),"△ 摘要开头没写日期（如 2026.9.21），月份取不到",IF(AND(N($H17)<>0,COUNTIFS($A$4:$A$1003,$A17,$H$4:$H$1003,$H17,$D$4:$D$1003,LEFT($D17,9)&"*")>1),"△ 同一天同项目有一样的销售金额，看看是不是录重了","✓")))))))) -> ✓ | W17: =IF($A17="","",$A17&"#"&COUNTIF($A$4:$A17,$A17)) -> 合川瑞翔#8
A18: =IF($C18="","",IFERROR(VLOOKUP($C18,目录!$B:$C,2,0)&"","⚠目录里没有")) -> 合川瑞翔 | B18: =IF($D18="","",IFERROR(MID($D18,FIND(".",$D18)+1,FIND(".",$D18,FIND(".",$D18)+1)-FIND(".",$D18)-1)&"月","")) -> 7月 | C18: 高新区厂房及配套设施提质改造项目开票到瑞翔厂区电力土建(管廊)建设工程 | D18: 2026.7.13小溪建材开票到新德润：瑞翔厂区电力土建 | E18: 新德润 | F18: 13%专票 | H18: 50220 | I18: =IF($H18="","",N($H18)*N($G18)) -> 0 | J18: =IF($H18="","",N($H18)-N($I18)) -> 50220 | K18: 50220 | L18: =IF($A18="","",SUMIF($A$4:$A18,$A18,$J$4:$J18)-SUMIF($A$4:$A18,$A18,$K$4:$K18)) -> 0 | M18: =IF($H18="","",N($H18)) -> 50220 | P18: =IF($A18="","",SUMIF($A$4:$A18,$A18,$M$4:$M18)-SUMIF($A$4:$A18,$A18,$N$4:$N18)-SUMIF($A$4:$A18,$A18,$O$4:$O18)) -> 50220 | T18: =IF($A18="","",SUMIF($A$4:$A18,$A18,$Q$4:$Q18)-SUMIF($A$4:$A18,$A18,$R$4:$R18)-SUMIF($A$4:$A18,$A18,$S$4:$S18)) -> 0 | V18: =IF(AND($C18="",COUNTA($D18:$H18,$K18,$N18:$O18,$Q18:$S18,$U18)=0),"",IF($C18="","⚠ 没填项目名称",IF($A18="⚠目录里没有","⚠ 项目名称在目录里找不到（先加到目录）",IF($A18="","⚠ 目录里这个项目没填简称",IF(ISTEXT($G18)+ISTEXT($H18)+ISTEXT($K18)+ISTEXT($N18)+ISTEXT($O18)+ISTEXT($Q18)+ISTEXT($R18)+ISTEXT($S18)>0,"⚠ 金额列里有文字，算不进合计",IF(N($G18)>=1,"⚠ 管理费点要填百分比，如 10%",IF(AND($D18<>"",$B18=""),"△ 摘要开头没写日期（如 2026.9.21），月份取不到",IF(AND(N($H18)<>0,COUNTIFS($A$4:$A$1003,$A18,$H$4:$H$1003,$H18,$D$4:$D$1003,LEFT($D18,9)&"*")>1),"△ 同一天同项目有一样的销售金额，看看是不是录重了","✓")))))))) -> ✓ | W18: =IF($A18="","",$A18&"#"&COUNTIF($A$4:$A18,$A18)) -> 合川瑞翔#9
A19: =IF($C19="","",IFERROR(VLOOKUP($C19,目录!$B:$C,2,0)&"","⚠目录里没有")) -> 合川瑞翔 | B19: =IF($D19="","",IFERROR(MID($D19,FIND(".",$D19)+1,FIND(".",$D19,FIND(".",$D19)+1)-FIND(".",$D19)-1)&"月","")) -> 7月 | C19: 高新区厂房及配套设施提质改造项目开票到瑞翔厂区电力土建(管廊)建设工程 | D19: 2026.7.15小溪建材收到新德润打款：瑞翔厂区电力 | E19: 新德润 | I19: =IF($H19="","",N($H19)*N($G19)) | J19: =IF($H19="","",N($H19)-N($I19)) | L19: =IF($A19="","",SUMIF($A$4:$A19,$A19,$J$4:$J19)-SUMIF($A$4:$A19,$A19,$K$4:$K19)) -> 0 | M19: =IF($H19="","",N($H19)) | O19: 50220 | P19: =IF($A19="","",SUMIF($A$4:$A19,$A19,$M$4:$M19)-SUMIF($A$4:$A19,$A19,$N$4:$N19)-SUMIF($A$4:$A19,$A19,$O$4:$O19)) -> 0 | T19: =IF($A19="","",SUMIF($A$4:$A19,$A19,$Q$4:$Q19)-SUMIF($A$4:$A19,$A19,$R$4:$R19)-SUMIF($A$4:$A19,$A19,$S$4:$S19)) -> 0 | V19: =IF(AND($C19="",COUNTA($D19:$H19,$K19,$N19:$O19,$Q19:$S19,$U19)=0),"",IF($C19="","⚠ 没填项目名称",IF($A19="⚠目录里没有","⚠ 项目名称在目录里找不到（先加到目录）",IF($A19="","⚠ 目录里这个项目没填简称",IF(ISTEXT($G19)+ISTEXT($H19)+ISTEXT($K19)+ISTEXT($N19)+ISTEXT($O19)+ISTEXT($Q19)+ISTEXT($R19)+ISTEXT($S19)>0,"⚠ 金额列里有文字，算不进合计",IF(N($G19)>=1,"⚠ 管理费点要填百分比，如 10%",IF(AND($D19<>"",$B19=""),"△ 摘要开头没写日期（如 2026.9.21），月份取不到",IF(AND(N($H19)<>0,COUNTIFS($A$4:$A$1003,$A19,$H$4:$H$1003,$H19,$D$4:$D$1003,LEFT($D19,9)&"*")>1),"△ 同一天同项目有一样的销售金额，看看是不是录重了","✓")))))))) -> ✓ | W19: =IF($A19="","",$A19&"#"&COUNTIF($A$4:$A19,$A19)) -> 合川瑞翔#10
A20: =IF($C20="","",IFERROR(VLOOKUP($C20,目录!$B:$C,2,0)&"","⚠目录里没有")) -> 合川瑞翔 | B20: =IF($D20="","",IFERROR(MID($D20,FIND(".",$D20)+1,FIND(".",$D20,FIND(".",$D20)+1)-FIND(".",$D20)-1)&"月","")) -> 7月 | C20: 高新区厂房及配套设施提质改造项目开票到瑞翔厂区电力土建(管廊)建设工程 | D20: 2026.7.13旭承机械开票到新德润：瑞翔厂区电力土建 | E20: 新德润 | F20: 1%普票 | H20: 100000 | I20: =IF($H20="","",N($H20)*N($G20)) -> 0 | J20: =IF($H20="","",N($H20)-N($I20)) -> 100000 | K20: 100000 | L20: =IF($A20="","",SUMIF($A$4:$A20,$A20,$J$4:$J20)-SUMIF($A$4:$A20,$A20,$K$4:$K20)) -> 0 | M20: =IF($H20="","",N($H20)) -> 100000 | P20: =IF($A20="","",SUMIF($A$4:$A20,$A20,$M$4:$M20)-SUMIF($A$4:$A20,$A20,$N$4:$N20)-SUMIF($A$4:$A20,$A20,$O$4:$O20)) -> 100000 | T20: =IF($A20="","",SUMIF($A$4:$A20,$A20,$Q$4:$Q20)-SUMIF($A$4:$A20,$A20,$R$4:$R20)-SUMIF($A$4:$A20,$A20,$S$4:$S20)) -> 0 | V20: =IF(AND($C20="",COUNTA($D20:$H20,$K20,$N20:$O20,$Q20:$S20,$U20)=0),"",IF($C20="","⚠ 没填项目名称",IF($A20="⚠目录里没有","⚠ 项目名称在目录里找不到（先加到目录）",IF($A20="","⚠ 目录里这个项目没填简称",IF(ISTEXT($G20)+ISTEXT($H20)+ISTEXT($K20)+ISTEXT($N20)+ISTEXT($O20)+ISTEXT($Q20)+ISTEXT($R20)+ISTEXT($S20)>0,"⚠ 金额列里有文字，算不进合计",IF(N($G20)>=1,"⚠ 管理费点要填百分比，如 10%",IF(AND($D20<>"",$B20=""),"△ 摘要开头没写日期（如 2026.9.21），月份取不到",IF(AND(N($H20)<>0,COUNTIFS($A$4:$A$1003,$A20,$H$4:$H$1003,$H20,$D$4:$D$1003,LEFT($D20,9)&"*")>1),"△ 同一天同项目有一样的销售金额，看看是不是录重了","✓")))))))) -> ✓ | W20: =IF($A20="","",$A20&"#"&COUNTIF($A$4:$A20,$A20)) -> 合川瑞翔#11
A21: =IF($C21="","",IFERROR(VLOOKUP($C21,目录!$B:$C,2,0)&"","⚠目录里没有")) -> 合川瑞翔 | B21: =IF($D21="","",IFERROR(MID($D21,FIND(".",$D21)+1,FIND(".",$D21,FIND(".",$D21)+1)-FIND(".",$D21)-1)&"月","")) -> 7月 | C21: 高新区厂房及配套设施提质改造项目开票到瑞翔厂区电力土建(管廊)建设工程 | D21: 2026.7.15旭承机械收到新德润打款：瑞翔厂区电力土建 | E21: 新德润 | I21: =IF($H21="","",N($H21)*N($G21)) | J21: =IF($H21="","",N($H21)-N($I21)) | L21: =IF($A21="","",SUMIF($A$4:$A21,$A21,$J$4:$J21)-SUMIF($A$4:$A21,$A21,$K$4:$K21)) -> 0 | M21: =IF($H21="","",N($H21)) | O21: 100000 | P21: =IF($A21="","",SUMIF($A$4:$A21,$A21,$M$4:$M21)-SUMIF($A$4:$A21,$A21,$N$4:$N21)-SUMIF($A$4:$A21,$A21,$O$4:$O21)) -> 0 | T21: =IF($A21="","",SUMIF($A$4:$A21,$A21,$Q$4:$Q21)-SUMIF($A$4:$A21,$A21,$R$4:$R21)-SUMIF($A$4:$A21,$A21,$S$4:$S21)) -> 0 | V21: =IF(AND($C21="",COUNTA($D21:$H21,$K21,$N21:$O21,$Q21:$S21,$U21)=0),"",IF($C21="","⚠ 没填项目名称",IF($A21="⚠目录里没有","⚠ 项目名称在目录里找不到（先加到目录）",IF($A21="","⚠ 目录里这个项目没填简称",IF(ISTEXT($G21)+ISTEXT($H21)+ISTEXT($K21)+ISTEXT($N21)+ISTEXT($O21)+ISTEXT($Q21)+ISTEXT($R21)+ISTEXT($S21)>0,"⚠ 金额列里有文字，算不进合计",IF(N($G21)>=1,"⚠ 管理费点要填百分比，如 10%",IF(AND($D21<>"",$B21=""),"△ 摘要开头没写日期（如 2026.9.21），月份取不到",IF(AND(N($H21)<>0,COUNTIFS($A$4:$A$1003,$A21,$H$4:$H$1003,$H21,$D$4:$D$1003,LEFT($D21,9)&"*")>1),"△ 同一天同项目有一样的销售金额，看看是不是录重了","✓")))))))) -> ✓ | W21: =IF($A21="","",$A21&"#"&COUNTIF($A$4:$A21,$A21)) -> 合川瑞翔#12
A22: =IF($C22="","",IFERROR(VLOOKUP($C22,目录!$B:$C,2,0)&"","⚠目录里没有")) -> 合川瑞翔 | B22: =IF($D22="","",IFERROR(MID($D22,FIND(".",$D22)+1,FIND(".",$D22,FIND(".",$D22)+1)-FIND(".",$D22)-1)&"月","")) -> 7月 | C22: 高新区厂房及配套设施提质改造项目开票到瑞翔厂区电力土建(管廊)建设工程 | D22: 2026.7.14凯樽物资开票到新德润：瑞翔厂区电力土建 | E22: 新德润 | F22: 13%专票 | H22: 49780 | I22: =IF($H22="","",N($H22)*N($G22)) -> 0 | J22: =IF($H22="","",N($H22)-N($I22)) -> 49780 | K22: 49780 | L22: =IF($A22="","",SUMIF($A$4:$A22,$A22,$J$4:$J22)-SUMIF($A$4:$A22,$A22,$K$4:$K22)) -> 0 | M22: =IF($H22="","",N($H22)) -> 49780 | P22: =IF($A22="","",SUMIF($A$4:$A22,$A22,$M$4:$M22)-SUMIF($A$4:$A22,$A22,$N$4:$N22)-SUMIF($A$4:$A22,$A22,$O$4:$O22)) -> 49780 | T22: =IF($A22="","",SUMIF($A$4:$A22,$A22,$Q$4:$Q22)-SUMIF($A$4:$A22,$A22,$R$4:$R22)-SUMIF($A$4:$A22,$A22,$S$4:$S22)) -> 0 | V22: =IF(AND($C22="",COUNTA($D22:$H22,$K22,$N22:$O22,$Q22:$S22,$U22)=0),"",IF($C22="","⚠ 没填项目名称",IF($A22="⚠目录里没有","⚠ 项目名称在目录里找不到（先加到目录）",IF($A22="","⚠ 目录里这个项目没填简称",IF(ISTEXT($G22)+ISTEXT($H22)+ISTEXT($K22)+ISTEXT($N22)+ISTEXT($O22)+ISTEXT($Q22)+ISTEXT($R22)+ISTEXT($S22)>0,"⚠ 金额列里有文字，算不进合计",IF(N($G22)>=1,"⚠ 管理费点要填百分比，如 10%",IF(AND($D22<>"",$B22=""),"△ 摘要开头没写日期（如 2026.9.21），月份取不到",IF(AND(N($H22)<>0,COUNTIFS($A$4:$A$1003,$A22,$H$4:$H$1003,$H22,$D$4:$D$1003,LEFT($D22,9)&"*")>1),"△ 同一天同项目有一样的销售金额，看看是不是录重了","✓")))))))) -> ✓ | W22: =IF($A22="","",$A22&"#"&COUNTIF($A$4:$A22,$A22)) -> 合川瑞翔#13
A23: =IF($C23="","",IFERROR(VLOOKUP($C23,目录!$B:$C,2,0)&"","⚠目录里没有")) -> 合川瑞翔 | B23: =IF($D23="","",IFERROR(MID($D23,FIND(".",$D23)+1,FIND(".",$D23,FIND(".",$D23)+1)-FIND(".",$D23)-1)&"月","")) -> 7月 | C23: 高新区厂房及配套设施提质改造项目开票到瑞翔厂区电力土建(管廊)建设工程 | D23: 2026.7.15凯樽物资收到新德润打款：瑞翔厂区电力土建 | E23: 新德润 | I23: =IF($H23="","",N($H23)*N($G23)) | J23: =IF($H23="","",N($H23)-N($I23)) | L23: =IF($A23="","",SUMIF($A$4:$A23,$A23,$J$4:$J23)-SUMIF($A$4:$A23,$A23,$K$4:$K23)) -> 0 | M23: =IF($H23="","",N($H23)) | O23: 49780 | P23: =IF($A23="","",SUMIF($A$4:$A23,$A23,$M$4:$M23)-SUMIF($A$4:$A23,$A23,$N$4:$N23)-SUMIF($A$4:$A23,$A23,$O$4:$O23)) -> 0 | T23: =IF($A23="","",SUMIF($A$4:$A23,$A23,$Q$4:$Q23)-SUMIF($A$4:$A23,$A23,$R$4:$R23)-SUMIF($A$4:$A23,$A23,$S$4:$S23)) -> 0 | V23: =IF(AND($C23="",COUNTA($D23:$H23,$K23,$N23:$O23,$Q23:$S23,$U23)=0),"",IF($C23="","⚠ 没填项目名称",IF($A23="⚠目录里没有","⚠ 项目名称在目录里找不到（先加到目录）",IF($A23="","⚠ 目录里这个项目没填简称",IF(ISTEXT($G23)+ISTEXT($H23)+ISTEXT($K23)+ISTEXT($N23)+ISTEXT($O23)+ISTEXT($Q23)+ISTEXT($R23)+ISTEXT($S23)>0,"⚠ 金额列里有文字，算不进合计",IF(N($G23)>=1,"⚠ 管理费点要填百分比，如 10%",IF(AND($D23<>"",$B23=""),"△ 摘要开头没写日期（如 2026.9.21），月份取不到",IF(AND(N($H23)<>0,COUNTIFS($A$4:$A$1003,$A23,$H$4:$H$1003,$H23,$D$4:$D$1003,LEFT($D23,9)&"*")>1),"△ 同一天同项目有一样的销售金额，看看是不是录重了","✓")))))))) -> ✓ | W23: =IF($A23="","",$A23&"#"&COUNTIF($A$4:$A23,$A23)) -> 合川瑞翔#14
A24: =IF($C24="","",IFERROR(VLOOKUP($C24,目录!$B:$C,2,0)&"","⚠目录里没有")) -> 合川瑞翔 | B24: =IF($D24="","",IFERROR(MID($D24,FIND(".",$D24)+1,FIND(".",$D24,FIND(".",$D24)+1)-FIND(".",$D24)-1)&"月","")) -> 9月 | C24: 高新区厂房及配套设施提质改造项目开票到瑞翔厂区电力土建(管廊)建设工程 | D24: 2026.9.14新德润代胡崇文支付宜宾翠屏货款：42800-39473.83=3326.17 | E24: 新德润 | I24: =IF($H24="","",N($H24)*N($G24)) | J24: =IF($H24="","",N($H24)-N($I24)) | L24: =IF($A24="","",SUMIF($A$4:$A24,$A24,$J$4:$J24)-SUMIF($A$4:$A24,$A24,$K$4:$K24)) -> 0 | M24: =IF($H24="","",N($H24)) | O24: 3326.17 | P24: =IF($A24="","",SUMIF($A$4:$A24,$A24,$M$4:$M24)-SUMIF($A$4:$A24,$A24,$N$4:$N24)-SUMIF($A$4:$A24,$A24,$O$4:$O24)) -> -3326.17 | T24: =IF($A24="","",SUMIF($A$4:$A24,$A24,$Q$4:$Q24)-SUMIF($A$4:$A24,$A24,$R$4:$R24)-SUMIF($A$4:$A24,$A24,$S$4:$S24)) -> 0 | V24: =IF(AND($C24="",COUNTA($D24:$H24,$K24,$N24:$O24,$Q24:$S24,$U24)=0),"",IF($C24="","⚠ 没填项目名称",IF($A24="⚠目录里没有","⚠ 项目名称在目录里找不到（先加到目录）",IF($A24="","⚠ 目录里这个项目没填简称",IF(ISTEXT($G24)+ISTEXT($H24)+ISTEXT($K24)+ISTEXT($N24)+ISTEXT($O24)+ISTEXT($Q24)+ISTEXT($R24)+ISTEXT($S24)>0,"⚠ 金额列里有文字，算不进合计",IF(N($G24)>=1,"⚠ 管理费点要填百分比，如 10%",IF(AND($D24<>"",$B24=""),"△ 摘要开头没写日期（如 2026.9.21），月份取不到",IF(AND(N($H24)<>0,COUNTIFS($A$4:$A$1003,$A24,$H$4:$H$1003,$H24,$D$4:$D$1003,LEFT($D24,9)&"*")>1),"△ 同一天同项目有一样的销售金额，看看是不是录重了","✓")))))))) -> ✓ | W24: =IF($A24="","",$A24&"#"&COUNTIF($A$4:$A24,$A24)) -> 合川瑞翔#15
A25: =IF($C25="","",IFERROR(VLOOKUP($C25,目录!$B:$C,2,0)&"","⚠目录里没有")) -> 铜城2回、玉璟尚线、铁井一回、淮拦线4 | B25: =IF($D25="","",IFERROR(MID($D25,FIND(".",$D25)+1,FIND(".",$D25,FIND(".",$D25)+1)-FIND(".",$D25)-1)&"月","")) -> 6月 | C25: 重庆铜梁铜城2回金龙物业管理有限公司10kV业扩配套工程 | D25: 2026.6.24新德润开票民能：铜城2回，10%管理费 | E25: 民能 | F25: 3%专票 | G25: 0.1 | H25: 4002.66 | I25: =IF($H25="","",N($H25)*N($G25)) -> 400.266 | J25: =IF($H25="","",N($H25)-N($I25)) -> 3602.394 | L25: =IF($A25="","",SUMIF($A$4:$A25,$A25,$J$4:$J25)-SUMIF($A$4:$A25,$A25,$K$4:$K25)) -> 3602.394 | M25: =IF($H25="","",N($H25)) -> 4002.66 | P25: =IF($A25="","",SUMIF($A$4:$A25,$A25,$M$4:$M25)-SUMIF($A$4:$A25,$A25,$N$4:$N25)-SUMIF($A$4:$A25,$A25,$O$4:$O25)) -> 4002.66 | T25: =IF($A25="","",SUMIF($A$4:$A25,$A25,$Q$4:$Q25)-SUMIF($A$4:$A25,$A25,$R$4:$R25)-SUMIF($A$4:$A25,$A25,$S$4:$S25)) -> 0 | V25: =IF(AND($C25="",COUNTA($D25:$H25,$K25,$N25:$O25,$Q25:$S25,$U25)=0),"",IF($C25="","⚠ 没填项目名称",IF($A25="⚠目录里没有","⚠ 项目名称在目录里找不到（先加到目录）",IF($A25="","⚠ 目录里这个项目没填简称",IF(ISTEXT($G25)+ISTEXT($H25)+ISTEXT($K25)+ISTEXT($N25)+ISTEXT($O25)+ISTEXT($Q25)+ISTEXT($R25)+ISTEXT($S25)>0,"⚠ 金额列里有文字，算不进合计",IF(N($G25)>=1,"⚠ 管理费点要填百分比，如 10%",IF(AND($D25<>"",$B25=""),"△ 摘要开头没写日期（如 2026.9.21），月份取不到",IF(AND(N($H25)<>0,COUNTIFS($A$4:$A$1003,$A25,$H$4:$H$1003,$H25,$D$4:$D$1003,LEFT($D25,9)&"*")>1),"△ 同一天同项目有一样的销售金额，看看是不是录重了","✓")))))))) -> ✓ | W25: =IF($A25="","",$A25&"#"&COUNTIF($A$4:$A25,$A25)) -> 铜城2回、玉璟尚线、铁井一回、淮拦线4#1
A26: =IF($C26="","",IFERROR(VLOOKUP($C26,目录!$B:$C,2,0)&"","⚠目录里没有")) -> 铜城2回、玉璟尚线、铁井一回、淮拦线4 | B26: =IF($D26="","",IFERROR(MID($D26,FIND(".",$D26)+1,FIND(".",$D26,FIND(".",$D26)+1)-FIND(".",$D26)-1)&"月","")) -> 6月 | C26: 重庆铜梁玉璟尚线金龙物业管理有限公司10kV业扩配套工程 | D26: 2026.6.24新德润开票民能：玉璟尚线，10%管理费 | E26: 民能 | F26: 3%专票 | G26: 0.1 | H26: 13079.84 | I26: =IF($H26="","",N($H26)*N($G26)) -> 1307.984 | J26: =IF($H26="","",N($H26)-N($I26)) -> 11771.856 | L26: =IF($A26="","",SUMIF($A$4:$A26,$A26,$J$4:$J26)-SUMIF($A$4:$A26,$A26,$K$4:$K26)) -> 15374.25 | M26: =IF($H26="","",N($H26)) -> 13079.84 | P26: =IF($A26="","",SUMIF($A$4:$A26,$A26,$M$4:$M26)-SUMIF($A$4:$A26,$A26,$N$4:$N26)-SUMIF($A$4:$A26,$A26,$O$4:$O26)) -> 17082.5 | T26: =IF($A26="","",SUMIF($A$4:$A26,$A26,$Q$4:$Q26)-SUMIF($A$4:$A26,$A26,$R$4:$R26)-SUMIF($A$4:$A26,$A26,$S$4:$S26)) -> 0 | V26: =IF(AND($C26="",COUNTA($D26:$H26,$K26,$N26:$O26,$Q26:$S26,$U26)=0),"",IF($C26="","⚠ 没填项目名称",IF($A26="⚠目录里没有","⚠ 项目名称在目录里找不到（先加到目录）",IF($A26="","⚠ 目录里这个项目没填简称",IF(ISTEXT($G26)+ISTEXT($H26)+ISTEXT($K26)+ISTEXT($N26)+ISTEXT($O26)+ISTEXT($Q26)+ISTEXT($R26)+ISTEXT($S26)>0,"⚠ 金额列里有文字，算不进合计",IF(N($G26)>=1,"⚠ 管理费点要填百分比，如 10%",IF(AND($D26<>"",$B26=""),"△ 摘要开头没写日期（如 2026.9.21），月份取不到",IF(AND(N($H26)<>0,COUNTIFS($A$4:$A$1003,$A26,$H$4:$H$1003,$H26,$D$4:$D$1003,LEFT($D26,9)&"*")>1),"△ 同一天同项目有一样的销售金额，看看是不是录重了","✓")))))))) -> ✓ | W26: =IF($A26="","",$A26&"#"&COUNTIF($A$4:$A26,$A26)) -> 铜城2回、玉璟尚线、铁井一回、淮拦线4#2
A27: =IF($C27="","",IFERROR(VLOOKUP($C27,目录!$B:$C,2,0)&"","⚠目录里没有")) -> 铜城2回、玉璟尚线、铁井一回、淮拦线4 | B27: =IF($D27="","",IFERROR(MID($D27,FIND(".",$D27)+1,FIND(".",$D27,FIND(".",$D27)+1)-FIND(".",$D27)-1)&"月","")) -> 6月 | C27: 重庆铜梁铁井一回1#环网柜等6个10kV老旧环网柜改造工程(安装) | D27: 2026.6.24新德润开票民能：铁井一回1#环网柜，10%管理费 | E27: 民能 | F27: 3%专票 | G27: 0.1 | H27: 47546.28 | I27: =IF($H27="","",N($H27)*N($G27)) -> 4754.628 | J27: =IF($H27="","",N($H27)-N($I27)) -> 42791.652 | L27: =IF($A27="","",SUMIF($A$4:$A27,$A27,$J$4:$J27)-SUMIF($A$4:$A27,$A27,$K$4:$K27)) -> 58165.902 | M27: =IF($H27="","",N($H27)) -> 47546.28 | P27: =IF($A27="","",SUMIF($A$4:$A27,$A27,$M$4:$M27)-SUMIF($A$4:$A27,$A27,$N$4:$N27)-SUMIF($A$4:$A27,$A27,$O$4:$O27)) -> 64628.78 | T27: =IF($A27="","",SUMIF($A$4:$A27,$A27,$Q$4:$Q27)-SUMIF($A$4:$A27,$A27,$R$4:$R27)-SUMIF($A$4:$A27,$A27,$S$4:$S27)) -> 0 | V27: =IF(AND($C27="",COUNTA($D27:$H27,$K27,$N27:$O27,$Q27:$S27,$U27)=0),"",IF($C27="","⚠ 没填项目名称",IF($A27="⚠目录里没有","⚠ 项目名称在目录里找不到（先加到目录）",IF($A27="","⚠ 目录里这个项目没填简称",IF(ISTEXT($G27)+ISTEXT($H27)+ISTEXT($K27)+ISTEXT($N27)+ISTEXT($O27)+ISTEXT($Q27)+ISTEXT($R27)+ISTEXT($S27)>0,"⚠ 金额列里有文字，算不进合计",IF(N($G27)>=1,"⚠ 管理费点要填百分比，如 10%",IF(AND($D27<>"",$B27=""),"△ 摘要开头没写日期（如 2026.9.21），月份取不到",IF(AND(N($H27)<>0,COUNTIFS($A$4:$A$1003,$A27,$H$4:$H$1003,$H27,$D$4:$D$1003,LEFT($D27,9)&"*")>1),"△ 同一天同项目有一样的销售金额，看看是不是录重了","✓")))))))) -> ✓ | W27: =IF($A27="","",$A27&"#"&COUNTIF($A$4:$A27,$A27)) -> 铜城2回、玉璟尚线、铁井一回、淮拦线4#3
A28: =IF($C28="","",IFERROR(VLOOKUP($C28,目录!$B:$C,2,0)&"","⚠目录里没有")) -> 铜城2回、玉璟尚线、铁井一回、淮拦线4 | B28: =IF($D28="","",IFERROR(MID($D28,FIND(".",$D28)+1,FIND(".",$D28,FIND(".",$D28)+1)-FIND(".",$D28)-1)&"月","")) -> 6月 | C28: 重庆铜梁淮拦线4#环网柜等6个10kV老旧环网柜改造工程（安装） | D28: 2026.6.24新德润开票民能：淮拦线4#环网柜，10%管理费 | E28: 民能 | F28: 3%专票 | G28: 0.1 | H28: 56969.32 | I28: =IF($H28="","",N($H28)*N($G28)) -> 5696.932 | J28: =IF($H28="","",N($H28)-N($I28)) -> 51272.388 | L28: =IF($A28="","",SUMIF($A$4:$A28,$A28,$J$4:$J28)-SUMIF($A$4:$A28,$A28,$K$4:$K28)) -> 109438.29 | M28: =IF($H28="","",N($H28)) -> 56969.32 | P28: =IF($A28="","",SUMIF($A$4:$A28,$A28,$M$4:$M28)-SUMIF($A$4:$A28,$A28,$N$4:$N28)-SUMIF($A$4:$A28,$A28,$O$4:$O28)) -> 121598.1 | T28: =IF($A28="","",SUMIF($A$4:$A28,$A28,$Q$4:$Q28)-SUMIF($A$4:$A28,$A28,$R$4:$R28)-SUMIF($A$4:$A28,$A28,$S$4:$S28)) -> 0 | V28: =IF(AND($C28="",COUNTA($D28:$H28,$K28,$N28:$O28,$Q28:$S28,$U28)=0),"",IF($C28="","⚠ 没填项目名称",IF($A28="⚠目录里没有","⚠ 项目名称在目录里找不到（先加到目录）",IF($A28="","⚠ 目录里这个项目没填简称",IF(ISTEXT($G28)+ISTEXT($H28)+ISTEXT($K28)+ISTEXT($N28)+ISTEXT($O28)+ISTEXT($Q28)+ISTEXT($R28)+ISTEXT($S28)>0,"⚠ 金额列里有文字，算不进合计",IF(N($G28)>=1,"⚠ 管理费点要填百分比，如 10%",IF(AND($D28<>"",$B28=""),"△ 摘要开头没写日期（如 2026.9.21），月份取不到",IF(AND(N($H28)<>0,COUNTIFS($A$4:$A$1003,$A28,$H$4:$H$1003,$H28,$D$4:$D$1003,LEFT($D28,9)&"*")>1),"△ 同一天同项目有一样的销售金额，看看是不是录重了","✓")))))))) -> ✓ | W28: =IF($A28="","",$A28&"#"&COUNTIF($A$4:$A28,$A28)) -> 铜城2回、玉璟尚线、铁井一回、淮拦线4#4
A29: =IF($C29="","",IFERROR(VLOOKUP($C29,目录!$B:$C,2,0)&"","⚠目录里没有")) -> 铜城2回、玉璟尚线、铁井一回、淮拦线4 | B29: =IF($D29="","",IFERROR(MID($D29,FIND(".",$D29)+1,FIND(".",$D29,FIND(".",$D29)+1)-FIND(".",$D29)-1)&"月","")) -> 6月 | C29: 重庆铜梁淮拦线4#环网柜等6个10kV老旧环网柜改造工程（安装） | D29: 2026.6.23桐桐建材开票到新德润：淮拦、铁井、玉璟、铜城2回 | E29: 新德润 | F29: 1%普票 | I29: =IF($H29="","",N($H29)*N($G29)) | J29: =IF($H29="","",N($H29)-N($I29)) | K29: 67200 | L29: =IF($A29="","",SUMIF($A$4:$A29,$A29,$J$4:$J29)-SUMIF($A$4:$A29,$A29,$K$4:$K29)) -> 42238.29 | M29: =IF($H29="","",N($H29)) | P29: =IF($A29="","",SUMIF($A$4:$A29,$A29,$M$4:$M29)-SUMIF($A$4:$A29,$A29,$N$4:$N29)-SUMIF($A$4:$A29,$A29,$O$4:$O29)) -> 121598.1 | T29: =IF($A29="","",SUMIF($A$4:$A29,$A29,$Q$4:$Q29)-SUMIF($A$4:$A29,$A29,$R$4:$R29)-SUMIF($A$4:$A29,$A29,$S$4:$S29)) -> 0 | V29: =IF(AND($C29="",COUNTA($D29:$H29,$K29,$N29:$O29,$Q29:$S29,$U29)=0),"",IF($C29="","⚠ 没填项目名称",IF($A29="⚠目录里没有","⚠ 项目名称在目录里找不到（先加到目录）",IF($A29="","⚠ 目录里这个项目没填简称",IF(ISTEXT($G29)+ISTEXT($H29)+ISTEXT($K29)+ISTEXT($N29)+ISTEXT($O29)+ISTEXT($Q29)+ISTEXT($R29)+ISTEXT($S29)>0,"⚠ 金额列里有文字，算不进合计",IF(N($G29)>=1,"⚠ 管理费点要填百分比，如 10%",IF(AND($D29<>"",$B29=""),"△ 摘要开头没写日期（如 2026.9.21），月份取不到",IF(AND(N($H29)<>0,COUNTIFS($A$4:$A$1003,$A29,$H$4:$H$1003,$H29,$D$4:$D$1003,LEFT($D29,9)&"*")>1),"△ 同一天同项目有一样的销售金额，看看是不是录重了","✓")))))))) -> ✓ | W29: =IF($A29="","",$A29&"#"&COUNTIF($A$4:$A29,$A29)) -> 铜城2回、玉璟尚线、铁井一回、淮拦线4#5
A30: =IF($C30="","",IFERROR(VLOOKUP($C30,目录!$B:$C,2,0)&"","⚠目录里没有")) -> 铜城2回、玉璟尚线、铁井一回、淮拦线4 | B30: =IF($D30="","",IFERROR(MID($D30,FIND(".",$D30)+1,FIND(".",$D30,FIND(".",$D30)+1)-FIND(".",$D30)-1)&"月","")) -> 6月 | C30: 重庆铜梁淮拦线4#环网柜等6个10kV老旧环网柜改造工程（安装） | D30: 2026.6.24宜宾翠屏开票到新德润淮：淮拦、铁井、玉璟、铜城2回 | E30: 新德润 | F30: 1%普票 | I30: =IF($H30="","",N($H30)*N($G30)) | J30: =IF($H30="","",N($H30)-N($I30)) | K30: 42800 | L30: =IF($A30="","",SUMIF($A$4:$A30,$A30,$J$4:$J30)-SUMIF($A$4:$A30,$A30,$K$4:$K30)) -> -561.71 | M30: =IF($H30="","",N($H30)) | P30: =IF($A30="","",SUMIF($A$4:$A30,$A30,$M$4:$M30)-SUMIF($A$4:$A30,$A30,$N$4:$N30)-SUMIF($A$4:$A30,$A30,$O$4:$O30)) -> 121598.1 | T30: =IF($A30="","",SUMIF($A$4:$A30,$A30,$Q$4:$Q30)-SUMIF($A$4:$A30,$A30,$R$4:$R30)-SUMIF($A$4:$A30,$A30,$S$4:$S30)) -> 0 | V30: =IF(AND($C30="",COUNTA($D30:$H30,$K30,$N30:$O30,$Q30:$S30,$U30)=0),"",IF($C30="","⚠ 没填项目名称",IF($A30="⚠目录里没有","⚠ 项目名称在目录里找不到（先加到目录）",IF($A30="","⚠ 目录里这个项目没填简称",IF(ISTEXT($G30)+ISTEXT($H30)+ISTEXT($K30)+ISTEXT($N30)+ISTEXT($O30)+ISTEXT($Q30)+ISTEXT($R30)+ISTEXT($S30)>0,"⚠ 金额列里有文字，算不进合计",IF(N($G30)>=1,"⚠ 管理费点要填百分比，如 10%",IF(AND($D30<>"",$B30=""),"△ 摘要开头没写日期（如 2026.9.21），月份取不到",IF(AND(N($H30)<>0,COUNTIFS($A$4:$A$1003,$A30,$H$4:$H$1003,$H30,$D$4:$D$1003,LEFT($D30,9)&"*")>1),"△ 同一天同项目有一样的销售金额，看看是不是录重了","✓")))))))) -> ✓ | W30: =IF($A30="","",$A30&"#"&COUNTIF($A$4:$A30,$A30)) -> 铜城2回、玉璟尚线、铁井一回、淮拦线4#6
A31: =IF($C31="","",IFERROR(VLOOKUP($C31,目录!$B:$C,2,0)&"","⚠目录里没有")) -> 铜城2回、玉璟尚线、铁井一回、淮拦线4 | B31: =IF($D31="","",IFERROR(MID($D31,FIND(".",$D31)+1,FIND(".",$D31,FIND(".",$D31)+1)-FIND(".",$D31)-1)&"月","")) -> 9月 | C31: 重庆铜梁淮拦线4#环网柜等6个10kV老旧环网柜改造工程（安装） | D31: 2026.9.14新德润扣8月民能农民工工资个税 | E31: 新德润 | F31: 1%普票 | I31: =IF($H31="","",N($H31)*N($G31)) | J31: =IF($H31="","",N($H31)-N($I31)) | K31: 57000 | L31: =IF($A31="","",SUMIF($A$4:$A31,$A31,$J$4:$J31)-SUMIF($A$4:$A31,$A31,$K$4:$K31)) -> -57561.71 | M31: =IF($H31="","",N($H31)) | O31: 810 | P31: =IF($A31="","",SUMIF($A$4:$A31,$A31,$M$4:$M31)-SUMIF($A$4:$A31,$A31,$N$4:$N31)-SUMIF($A$4:$A31,$A31,$O$4:$O31)) -> 120788.1 | T31: =IF($A31="","",SUMIF($A$4:$A31,$A31,$Q$4:$Q31)-SUMIF($A$4:$A31,$A31,$R$4:$R31)-SUMIF($A$4:$A31,$A31,$S$4:$S31)) -> 0 | V31: =IF(AND($C31="",COUNTA($D31:$H31,$K31,$N31:$O31,$Q31:$S31,$U31)=0),"",IF($C31="","⚠ 没填项目名称",IF($A31="⚠目录里没有","⚠ 项目名称在目录里找不到（先加到目录）",IF($A31="","⚠ 目录里这个项目没填简称",IF(ISTEXT($G31)+ISTEXT($H31)+ISTEXT($K31)+ISTEXT($N31)+ISTEXT($O31)+ISTEXT($Q31)+ISTEXT($R31)+ISTEXT($S31)>0,"⚠ 金额列里有文字，算不进合计",IF(N($G31)>=1,"⚠ 管理费点要填百分比，如 10%",IF(AND($D31<>"",$B31=""),"△ 摘要开头没写日期（如 2026.9.21），月份取不到",IF(AND(N($H31)<>0,COUNTIFS($A$4:$A$1003,$A31,$H$4:$H$1003,$H31,$D$4:$D$1003,LEFT($D31,9)&"*")>1),"△ 同一天同项目有一样的销售金额，看看是不是录重了","✓")))))))) -> ✓ | W31: =IF($A31="","",$A31&"#"&COUNTIF($A$4:$A31,$A31)) -> 铜城2回、玉璟尚线、铁井一回、淮拦线4#7
A32: =IF($C32="","",IFERROR(VLOOKUP($C32,目录!$B:$C,2,0)&"","⚠目录里没有")) -> 铜城2回、玉璟尚线、铁井一回、淮拦线4 | B32: =IF($D32="","",IFERROR(MID($D32,FIND(".",$D32)+1,FIND(".",$D32,FIND(".",$D32)+1)-FIND(".",$D32)-1)&"月","")) -> 9月 | C32: 重庆铜梁铁井一回1#环网柜等6个10kV老旧环网柜改造工程(安装) | D32: 2026.9.14新德润扣8月民能农民工工资：铁井一回1 | E32: 新德润 | I32: =IF($H32="","",N($H32)*N($G32)) | J32: =IF($H32="","",N($H32)-N($I32)) | L32: =IF($A32="","",SUMIF($A$4:$A32,$A32,$J$4:$J32)-SUMIF($A$4:$A32,$A32,$K$4:$K32)) -> -57561.71 | M32: =IF($H32="","",N($H32)) | O32: 22000 | P32: =IF($A32="","",SUMIF($A$4:$A32,$A32,$M$4:$M32)-SUMIF($A$4:$A32,$A32,$N$4:$N32)-SUMIF($A$4:$A32,$A32,$O$4:$O32)) -> 98788.1 | T32: =IF($A32="","",SUMIF($A$4:$A32,$A32,$Q$4:$Q32)-SUMIF($A$4:$A32,$A32,$R$4:$R32)-SUMIF($A$4:$A32,$A32,$S$4:$S32)) -> 0 | V32: =IF(AND($C32="",COUNTA($D32:$H32,$K32,$N32:$O32,$Q32:$S32,$U32)=0),"",IF($C32="","⚠ 没填项目名称",IF($A32="⚠目录里没有","⚠ 项目名称在目录里找不到（先加到目录）",IF($A32="","⚠ 目录里这个项目没填简称",IF(ISTEXT($G32)+ISTEXT($H32)+ISTEXT($K32)+ISTEXT($N32)+ISTEXT($O32)+ISTEXT($Q32)+ISTEXT($R32)+ISTEXT($S32)>0,"⚠ 金额列里有文字，算不进合计",IF(N($G32)>=1,"⚠ 管理费点要填百分比，如 10%",IF(AND($D32<>"",$B32=""),"△ 摘要开头没写日期（如 2026.9.21），月份取不到",IF(AND(N($H32)<>0,COUNTIFS($A$4:$A$1003,$A32,$H$4:$H$1003,$H32,$D$4:$D$1003,LEFT($D32,9)&"*")>1),"△ 同一天同项目有一样的销售金额，看看是不是录重了","✓")))))))) -> ✓ | W32: =IF($A32="","",$A32&"#"&COUNTIF($A$4:$A32,$A32)) -> 铜城2回、玉璟尚线、铁井一回、淮拦线4#8
A33: =IF($C33="","",IFERROR(VLOOKUP($C33,目录!$B:$C,2,0)&"","⚠目录里没有")) -> 铜城2回、玉璟尚线、铁井一回、淮拦线4 | B33: =IF($D33="","",IFERROR(MID($D33,FIND(".",$D33)+1,FIND(".",$D33,FIND(".",$D33)+1)-FIND(".",$D33)-1)&"月","")) -> 9月 | C33: 重庆铜梁淮拦线4#环网柜等6个10kV老旧环网柜改造工程（安装） | D33: 2026.9.14新德润扣8月民能农民工工资：淮拦线4 | E33: 新德润 | I33: =IF($H33="","",N($H33)*N($G33)) | J33: =IF($H33="","",N($H33)-N($I33)) | L33: =IF($A33="","",SUMIF($A$4:$A33,$A33,$J$4:$J33)-SUMIF($A$4:$A33,$A33,$K$4:$K33)) -> -57561.71 | M33: =IF($H33="","",N($H33)) | O33: 27000 | P33: =IF($A33="","",SUMIF($A$4:$A33,$A33,$M$4:$M33)-SUMIF($A$4:$A33,$A33,$N$4:$N33)-SUMIF($A$4:$A33,$A33,$O$4:$O33)) -> 71788.1 | T33: =IF($A33="","",SUMIF($A$4:$A33,$A33,$Q$4:$Q33)-SUMIF($A$4:$A33,$A33,$R$4:$R33)-SUMIF($A$4:$A33,$A33,$S$4:$S33)) -> 0 | V33: =IF(AND($C33="",COUNTA($D33:$H33,$K33,$N33:$O33,$Q33:$S33,$U33)=0),"",IF($C33="","⚠ 没填项目名称",IF($A33="⚠目录里没有","⚠ 项目名称在目录里找不到（先加到目录）",IF($A33="","⚠ 目录里这个项目没填简称",IF(ISTEXT($G33)+ISTEXT($H33)+ISTEXT($K33)+ISTEXT($N33)+ISTEXT($O33)+ISTEXT($Q33)+ISTEXT($R33)+ISTEXT($S33)>0,"⚠ 金额列里有文字，算不进合计",IF(N($G33)>=1,"⚠ 管理费点要填百分比，如 10%",IF(AND($D33<>"",$B33=""),"△ 摘要开头没写日期（如 2026.9.21），月份取不到",IF(AND(N($H33)<>0,COUNTIFS($A$4:$A$1003,$A33,$H$4:$H$1003,$H33,$D$4:$D$1003,LEFT($D33,9)&"*")>1),"△ 同一天同项目有一样的销售金额，看看是不是录重了","✓")))))))) -> ✓ | W33: =IF($A33="","",$A33&"#"&COUNTIF($A$4:$A33,$A33)) -> 铜城2回、玉璟尚线、铁井一回、淮拦线4#9
A34: =IF($C34="","",IFERROR(VLOOKUP($C34,目录!$B:$C,2,0)&"","⚠目录里没有")) -> 铜城2回、玉璟尚线、铁井一回、淮拦线4 | B34: =IF($D34="","",IFERROR(MID($D34,FIND(".",$D34)+1,FIND(".",$D34,FIND(".",$D34)+1)-FIND(".",$D34)-1)&"月","")) -> 9月 | C34: 重庆铜梁铜城2回金龙物业管理有限公司10kV业扩配套工程 | D34: 2026.9.14新德润扣8月民能农民工工资：铜城2回 | E34: 新德润 | I34: =IF($H34="","",N($H34)*N($G34)) | J34: =IF($H34="","",N($H34)-N($I34)) | L34: =IF($A34="","",SUMIF($A$4:$A34,$A34,$J$4:$J34)-SUMIF($A$4:$A34,$A34,$K$4:$K34)) -> -57561.71 | M34: =IF($H34="","",N($H34)) | O34: 2000 | P34: =IF($A34="","",SUMIF($A$4:$A34,$A34,$M$4:$M34)-SUMIF($A$4:$A34,$A34,$N$4:$N34)-SUMIF($A$4:$A34,$A34,$O$4:$O34)) -> 69788.1 | T34: =IF($A34="","",SUMIF($A$4:$A34,$A34,$Q$4:$Q34)-SUMIF($A$4:$A34,$A34,$R$4:$R34)-SUMIF($A$4:$A34,$A34,$S$4:$S34)) -> 0 | V34: =IF(AND($C34="",COUNTA($D34:$H34,$K34,$N34:$O34,$Q34:$S34,$U34)=0),"",IF($C34="","⚠ 没填项目名称",IF($A34="⚠目录里没有","⚠ 项目名称在目录里找不到（先加到目录）",IF($A34="","⚠ 目录里这个项目没填简称",IF(ISTEXT($G34)+ISTEXT($H34)+ISTEXT($K34)+ISTEXT($N34)+ISTEXT($O34)+ISTEXT($Q34)+ISTEXT($R34)+ISTEXT($S34)>0,"⚠ 金额列里有文字，算不进合计",IF(N($G34)>=1,"⚠ 管理费点要填百分比，如 10%",IF(AND($D34<>"",$B34=""),"△ 摘要开头没写日期（如 2026.9.21），月份取不到",IF(AND(N($H34)<>0,COUNTIFS($A$4:$A$1003,$A34,$H$4:$H$1003,$H34,$D$4:$D$1003,LEFT($D34,9)&"*")>1),"△ 同一天同项目有一样的销售金额，看看是不是录重了","✓")))))))) -> ✓ | W34: =IF($A34="","",$A34&"#"&COUNTIF($A$4:$A34,$A34)) -> 铜城2回、玉璟尚线、铁井一回、淮拦线4#10
A35: =IF($C35="","",IFERROR(VLOOKUP($C35,目录!$B:$C,2,0)&"","⚠目录里没有")) -> 铜城2回、玉璟尚线、铁井一回、淮拦线4 | B35: =IF($D35="","",IFERROR(MID($D35,FIND(".",$D35)+1,FIND(".",$D35,FIND(".",$D35)+1)-FIND(".",$D35)-1)&"月","")) -> 9月 | C35: 重庆铜梁玉璟尚线金龙物业管理有限公司10kV业扩配套工程 | D35: 2026.9.14新德润扣8月民能农民工工资：玉璟尚线 | E35: 新德润 | I35: =IF($H35="","",N($H35)*N($G35)) | J35: =IF($H35="","",N($H35)-N($I35)) | L35: =IF($A35="","",SUMIF($A$4:$A35,$A35,$J$4:$J35)-SUMIF($A$4:$A35,$A35,$K$4:$K35)) -> -57561.71 | M35: =IF($H35="","",N($H35)) | O35: 6000 | P35: =IF($A35="","",SUMIF($A$4:$A35,$A35,$M$4:$M35)-SUMIF($A$4:$A35,$A35,$N$4:$N35)-SUMIF($A$4:$A35,$A35,$O$4:$O35)) -> 63788.1 | T35: =IF($A35="","",SUMIF($A$4:$A35,$A35,$Q$4:$Q35)-SUMIF($A$4:$A35,$A35,$R$4:$R35)-SUMIF($A$4:$A35,$A35,$S$4:$S35)) -> 0 | V35: =IF(AND($C35="",COUNTA($D35:$H35,$K35,$N35:$O35,$Q35:$S35,$U35)=0),"",IF($C35="","⚠ 没填项目名称",IF($A35="⚠目录里没有","⚠ 项目名称在目录里找不到（先加到目录）",IF($A35="","⚠ 目录里这个项目没填简称",IF(ISTEXT($G35)+ISTEXT($H35)+ISTEXT($K35)+ISTEXT($N35)+ISTEXT($O35)+ISTEXT($Q35)+ISTEXT($R35)+ISTEXT($S35)>0,"⚠ 金额列里有文字，算不进合计",IF(N($G35)>=1,"⚠ 管理费点要填百分比，如 10%",IF(AND($D35<>"",$B35=""),"△ 摘要开头没写日期（如 2026.9.21），月份取不到",IF(AND(N($H35)<>0,COUNTIFS($A$4:$A$1003,$A35,$H$4:$H$1003,$H35,$D$4:$D$1003,LEFT($D35,9)&"*")>1),"△ 同一天同项目有一样的销售金额，看看是不是录重了","✓")))))))) -> ✓ | W35: =IF($A35="","",$A35&"#"&COUNTIF($A$4:$A35,$A35)) -> 铜城2回、玉璟尚线、铁井一回、淮拦线4#11
A36: =IF($C36="","",IFERROR(VLOOKUP($C36,目录!$B:$C,2,0)&"","⚠目录里没有")) -> 铜城2回、玉璟尚线、铁井一回、淮拦线4 | B36: =IF($D36="","",IFERROR(MID($D36,FIND(".",$D36)+1,FIND(".",$D36,FIND(".",$D36)+1)-FIND(".",$D36)-1)&"月","")) -> 9月 | C36: 重庆铜梁淮拦线4#环网柜等6个10kV老旧环网柜改造工程（安装） | D36: 2026.9.14新德润扣工资残保金1.5% | E36: 新德润 | I36: =IF($H36="","",N($H36)*N($G36)) | J36: =IF($H36="","",N($H36)-N($I36)) | L36: =IF($A36="","",SUMIF($A$4:$A36,$A36,$J$4:$J36)-SUMIF($A$4:$A36,$A36,$K$4:$K36)) -> -57561.71 | M36: =IF($H36="","",N($H36)) | O36: 1823.97 | P36: =IF($A36="","",SUMIF($A$4:$A36,$A36,$M$4:$M36)-SUMIF($A$4:$A36,$A36,$N$4:$N36)-SUMIF($A$4:$A36,$A36,$O$4:$O36)) -> 61964.13 | T36: =IF($A36="","",SUMIF($A$4:$A36,$A36,$Q$4:$Q36)-SUMIF($A$4:$A36,$A36,$R$4:$R36)-SUMIF($A$4:$A36,$A36,$S$4:$S36)) -> 0 | V36: =IF(AND($C36="",COUNTA($D36:$H36,$K36,$N36:$O36,$Q36:$S36,$U36)=0),"",IF($C36="","⚠ 没填项目名称",IF($A36="⚠目录里没有","⚠ 项目名称在目录里找不到（先加到目录）",IF($A36="","⚠ 目录里这个项目没填简称",IF(ISTEXT($G36)+ISTEXT($H36)+ISTEXT($K36)+ISTEXT($N36)+ISTEXT($O36)+ISTEXT($Q36)+ISTEXT($R36)+ISTEXT($S36)>0,"⚠ 金额列里有文字，算不进合计",IF(N($G36)>=1,"⚠ 管理费点要填百分比，如 10%",IF(AND($D36<>"",$B36=""),"△ 摘要开头没写日期（如 2026.9.21），月份取不到",IF(AND(N($H36)<>0,COUNTIFS($A$4:$A$1003,$A36,$H$4:$H$1003,$H36,$D$4:$D$1003,LEFT($D36,9)&"*")>1),"△ 同一天同项目有一样的销售金额，看看是不是录重了","✓")))))))) -> ✓ | W36: =IF($A36="","",$A36&"#"&COUNTIF($A$4:$A36,$A36)) -> 铜城2回、玉璟尚线、铁井一回、淮拦线4#12
A37: =IF($C37="","",IFERROR(VLOOKUP($C37,目录!$B:$C,2,0)&"","⚠目录里没有")) -> 铜城2回、玉璟尚线、铁井一回、淮拦线4 | B37: =IF($D37="","",IFERROR(MID($D37,FIND(".",$D37)+1,FIND(".",$D37,FIND(".",$D37)+1)-FIND(".",$D37)-1)&"月","")) -> 9月 | C37: 重庆铜梁淮拦线4#环网柜等6个10kV老旧环网柜改造工程（安装） | D37: 2026.9.14新德润扣增值税3541.69，附加税425，印花税72.96 | E37: 新德润 | I37: =IF($H37="","",N($H37)*N($G37)) | J37: =IF($H37="","",N($H37)-N($I37)) | L37: =IF($A37="","",SUMIF($A$4:$A37,$A37,$J$4:$J37)-SUMIF($A$4:$A37,$A37,$K$4:$K37)) -> -57561.71 | M37: =IF($H37="","",N($H37)) | O37: =3541.69+425+72.96 -> 4039.65 | P37: =IF($A37="","",SUMIF($A$4:$A37,$A37,$M$4:$M37)-SUMIF($A$4:$A37,$A37,$N$4:$N37)-SUMIF($A$4:$A37,$A37,$O$4:$O37)) -> 57924.48 | T37: =IF($A37="","",SUMIF($A$4:$A37,$A37,$Q$4:$Q37)-SUMIF($A$4:$A37,$A37,$R$4:$R37)-SUMIF($A$4:$A37,$A37,$S$4:$S37)) -> 0 | V37: =IF(AND($C37="",COUNTA($D37:$H37,$K37,$N37:$O37,$Q37:$S37,$U37)=0),"",IF($C37="","⚠ 没填项目名称",IF($A37="⚠目录里没有","⚠ 项目名称在目录里找不到（先加到目录）",IF($A37="","⚠ 目录里这个项目没填简称",IF(ISTEXT($G37)+ISTEXT($H37)+ISTEXT($K37)+ISTEXT($N37)+ISTEXT($O37)+ISTEXT($Q37)+ISTEXT($R37)+ISTEXT($S37)>0,"⚠ 金额列里有文字，算不进合计",IF(N($G37)>=1,"⚠ 管理费点要填百分比，如 10%",IF(AND($D37<>"",$B37=""),"△ 摘要开头没写日期（如 2026.9.21），月份取不到",IF(AND(N($H37)<>0,COUNTIFS($A$4:$A$1003,$A37,$H$4:$H$1003,$H37,$D$4:$D$1003,LEFT($D37,9)&"*")>1),"△ 同一天同项目有一样的销售金额，看看是不是录重了","✓")))))))) -> ✓ | W37: =IF($A37="","",$A37&"#"&COUNTIF($A$4:$A37,$A37)) -> 铜城2回、玉璟尚线、铁井一回、淮拦线4#13
A38: =IF($C38="","",IFERROR(VLOOKUP($C38,目录!$B:$C,2,0)&"","⚠目录里没有")) -> 铜城2回、玉璟尚线、铁井一回、淮拦线4 | B38: =IF($D38="","",IFERROR(MID($D38,FIND(".",$D38)+1,FIND(".",$D38,FIND(".",$D38)+1)-FIND(".",$D38)-1)&"月","")) -> 9月 | C38: 重庆铜梁淮拦线4#环网柜等6个10kV老旧环网柜改造工程（安装） | D38: 2026.9.14新德润扣管理费 | E38: 新德润 | I38: =IF($H38="","",N($H38)*N($G38)) | J38: =IF($H38="","",N($H38)-N($I38)) | L38: =IF($A38="","",SUMIF($A$4:$A38,$A38,$J$4:$J38)-SUMIF($A$4:$A38,$A38,$K$4:$K38)) -> -57561.71 | M38: =IF($H38="","",N($H38)) | O38: 12159.81 | P38: =IF($A38="","",SUMIF($A$4:$A38,$A38,$M$4:$M38)-SUMIF($A$4:$A38,$A38,$N$4:$N38)-SUMIF($A$4:$A38,$A38,$O$4:$O38)) -> 45764.67 | T38: =IF($A38="","",SUMIF($A$4:$A38,$A38,$Q$4:$Q38)-SUMIF($A$4:$A38,$A38,$R$4:$R38)-SUMIF($A$4:$A38,$A38,$S$4:$S38)) -> 0 | V38: =IF(AND($C38="",COUNTA($D38:$H38,$K38,$N38:$O38,$Q38:$S38,$U38)=0),"",IF($C38="","⚠ 没填项目名称",IF($A38="⚠目录里没有","⚠ 项目名称在目录里找不到（先加到目录）",IF($A38="","⚠ 目录里这个项目没填简称",IF(ISTEXT($G38)+ISTEXT($H38)+ISTEXT($K38)+ISTEXT($N38)+ISTEXT($O38)+ISTEXT($Q38)+ISTEXT($R38)+ISTEXT($S38)>0,"⚠ 金额列里有文字，算不进合计",IF(N($G38)>=1,"⚠ 管理费点要填百分比，如 10%",IF(AND($D38<>"",$B38=""),"△ 摘要开头没写日期（如 2026.9.21），月份取不到",IF(AND(N($H38)<>0,COUNTIFS($A$4:$A$1003,$A38,$H$4:$H$1003,$H38,$D$4:$D$1003,LEFT($D38,9)&"*")>1),"△ 同一天同项目有一样的销售金额，看看是不是录重了","✓")))))))) -> ✓ | W38: =IF($A38="","",$A38&"#"&COUNTIF($A$4:$A38,$A38)) -> 铜城2回、玉璟尚线、铁井一回、淮拦线4#14
A39: =IF($C39="","",IFERROR(VLOOKUP($C39,目录!$B:$C,2,0)&"","⚠目录里没有")) -> 铜城2回、玉璟尚线、铁井一回、淮拦线4 | B39: =IF($D39="","",IFERROR(MID($D39,FIND(".",$D39)+1,FIND(".",$D39,FIND(".",$D39)+1)-FIND(".",$D39)-1)&"月","")) -> 9月 | C39: 重庆铜梁淮拦线4#环网柜等6个10kV老旧环网柜改造工程（安装） | D39: 2026.9.14新德润代胡崇文支付宜宾翠屏货款：42800-39473.83=3326.17 | E39: 新德润 | I39: =IF($H39="","",N($H39)*N($G39)) | J39: =IF($H39="","",N($H39)-N($I39)) | L39: =IF($A39="","",SUMIF($A$4:$A39,$A39,$J$4:$J39)-SUMIF($A$4:$A39,$A39,$K$4:$K39)) -> -57561.71 | M39: =IF($H39="","",N($H39)) | O39: 39473.83 | P39: =IF($A39="","",SUMIF($A$4:$A39,$A39,$M$4:$M39)-SUMIF($A$4:$A39,$A39,$N$4:$N39)-SUMIF($A$4:$A39,$A39,$O$4:$O39)) -> 6290.84 | T39: =IF($A39="","",SUMIF($A$4:$A39,$A39,$Q$4:$Q39)-SUMIF($A$4:$A39,$A39,$R$4:$R39)-SUMIF($A$4:$A39,$A39,$S$4:$S39)) -> 0 | V39: =IF(AND($C39="",COUNTA($D39:$H39,$K39,$N39:$O39,$Q39:$S39,$U39)=0),"",IF($C39="","⚠ 没填项目名称",IF($A39="⚠目录里没有","⚠ 项目名称在目录里找不到（先加到目录）",IF($A39="","⚠ 目录里这个项目没填简称",IF(ISTEXT($G39)+ISTEXT($H39)+ISTEXT($K39)+ISTEXT($N39)+ISTEXT($O39)+ISTEXT($Q39)+ISTEXT($R39)+ISTEXT($S39)>0,"⚠ 金额列里有文字，算不进合计",IF(N($G39)>=1,"⚠ 管理费点要填百分比，如 10%",IF(AND($D39<>"",$B39=""),"△ 摘要开头没写日期（如 2026.9.21），月份取不到",IF(AND(N($H39)<>0,COUNTIFS($A$4:$A$1003,$A39,$H$4:$H$1003,$H39,$D$4:$D$1003,LEFT($D39,9)&"*")>1),"△ 同一天同项目有一样的销售金额，看看是不是录重了","✓")))))))) -> ✓ | W39: =IF($A39="","",$A39&"#"&COUNTIF($A$4:$A39,$A39)) -> 铜城2回、玉璟尚线、铁井一回、淮拦线4#15
A40: =IF($C40="","",IFERROR(VLOOKUP($C40,目录!$B:$C,2,0)&"","⚠目录里没有")) -> 合川表计 | B40: =IF($D40="","",IFERROR(MID($D40,FIND(".",$D40)+1,FIND(".",$D40,FIND(".",$D40)+1)-FIND(".",$D40)-1)&"月","")) -> 6月 | C40: 国网重庆合川供电公司2026年用电信息采集系统建筑相关工程施工(包4) | D40: 2026.6.1张氏机电开票到新德润：合川表计项目 | E40: 新德润 | F40: 1%普票 | H40: 100000 | I40: =IF($H40="","",N($H40)*N($G40)) -> 0 | J40: =IF($H40="","",N($H40)-N($I40)) -> 100000 | K40: 100000 | L40: =IF($A40="","",SUMIF($A$4:$A40,$A40,$J$4:$J40)-SUMIF($A$4:$A40,$A40,$K$4:$K40)) -> 0 | M40: =IF($H40="","",N($H40)) -> 100000 | P40: =IF($A40="","",SUMIF($A$4:$A40,$A40,$M$4:$M40)-SUMIF($A$4:$A40,$A40,$N$4:$N40)-SUMIF($A$4:$A40,$A40,$O$4:$O40)) -> 100000 | T40: =IF($A40="","",SUMIF($A$4:$A40,$A40,$Q$4:$Q40)-SUMIF($A$4:$A40,$A40,$R$4:$R40)-SUMIF($A$4:$A40,$A40,$S$4:$S40)) -> 0 | V40: =IF(AND($C40="",COUNTA($D40:$H40,$K40,$N40:$O40,$Q40:$S40,$U40)=0),"",IF($C40="","⚠ 没填项目名称",IF($A40="⚠目录里没有","⚠ 项目名称在目录里找不到（先加到目录）",IF($A40="","⚠ 目录里这个项目没填简称",IF(ISTEXT($G40)+ISTEXT($H40)+ISTEXT($K40)+ISTEXT($N40)+ISTEXT($O40)+ISTEXT($Q40)+ISTEXT($R40)+ISTEXT($S40)>0,"⚠ 金额列里有文字，算不进合计",IF(N($G40)>=1,"⚠ 管理费点要填百分比，如 10%",IF(AND($D40<>"",$B40=""),"△ 摘要开头没写日期（如 2026.9.21），月份取不到",IF(AND(N($H40)<>0,COUNTIFS($A$4:$A$1003,$A40,$H$4:$H$1003,$H40,$D$4:$D$1003,LEFT($D40,9)&"*")>1),"△ 同一天同项目有一样的销售金额，看看是不是录重了","✓")))))))) -> ✓ | W40: =IF($A40="","",$A40&"#"&COUNTIF($A$4:$A40,$A40)) -> 合川表计#1
...

Sheet 项目汇总
A1: 项目汇总
A2: 序号 | B2: 项目简称 （点开分表） | C2: 笔数 | D2: 最后一笔摘要 | E2: 销售金额 | F2: 管理费 | G2: 应开 成本票 | H2: 已开 成本票 | I2: 未开 成本票 | J2: 应收款 | K2: 质保金 | L2: 已收款 | M2: 未收款 | N2: 应付 工程款 | O2: 扣除 管理费 | P2: 已付 工程款 | Q2: 未付 工程款 | R2: 分表核对
A3: 合计 | E3: =SUM(E4:E53) -> 2206559.2 | F3: =SUM(F4:F53) -> 65304.158 | G3: =SUM(G4:G53) -> 2141255 | H3: =SUM(H4:H53) -> 2098816.7 | I3: =G3-H3 -> 42438.29 | J3: =SUM(J4:J53) -> 2206559.2 | K3: =SUM(K4:K53) -> 0 | L3: =SUM(L4:L53) -> 1500594.2 | M3: =J3-K3-L3 -> 705964.91 | N3: =SUM(N4:N53) -> 0 | O3: =SUM(O4:O53) -> 0 | P3: =SUM(P4:P53) -> 576643 | Q3: =N3-O3-P3 -> -576643 | R3: =IF(SUMPRODUCT(ABS(E3:Q3-发票统计!H3:T3))<0.01,"✓ 与发票统计合计一致","⚠ 与发票统计合计对不上：有行没归到项目，看发票统计 V 列") -> ✓ 与发票统计合计一致
A4: =IF($B4="","",ROWS(A$4:A4)) -> 1 | B4: =IFERROR(HYPERLINK("#'"&INDEX(目录!$C$3:$C$102,MATCH(ROWS(B$4:B4),目录!$F$3:$F$102,0))&"'!A1",INDEX(目录!$C$3:$C$102,MATCH(ROWS(B$4:B4),目录!$F$3:$F$102,0))),"") -> 淮阳站阳高线 | C4: =IF($B4="","",COUNTIF(发票统计!$A$4:$A$1003,$B4)) -> 2 | D4: =IF(N($C4)=0,"",INDEX(发票统计!$D$4:$D$1003,MATCH($B4&"#"&$C4,发票统计!$W$4:$W$1003,0))&"") -> 2026.3.25张氏机电-新德润：淮阳站阳高线 | E4: =IF($B4="","",SUMIF(发票统计!$A$4:$A$1003,$B4,发票统计!$H$4:$H$1003)) -> 107944.61 | F4: =IF($B4="","",SUMIF(发票统计!$A$4:$A$1003,$B4,发票统计!$I$4:$I$1003)) -> 0 | G4: =IF($B4="","",SUMIF(发票统计!$A$4:$A$1003,$B4,发票统计!$J$4:$J$1003)) -> 107944.61 | H4: =IF($B4="","",SUMIF(发票统计!$A$4:$A$1003,$B4,发票统计!$K$4:$K$1003)) -> 107944.61 | I4: =IF($B4="","",G4-H4) -> 0 | J4: =IF($B4="","",SUMIF(发票统计!$A$4:$A$1003,$B4,发票统计!$M$4:$M$1003)) -> 107944.61 | K4: =IF($B4="","",SUMIF(发票统计!$A$4:$A$1003,$B4,发票统计!$N$4:$N$1003)) -> 0 | L4: =IF($B4="","",SUMIF(发票统计!$A$4:$A$1003,$B4,发票统计!$O$4:$O$1003)) -> 0 | M4: =IF($B4="","",J4-K4-L4) -> 107944.61 | N4: =IF($B4="","",SUMIF(发票统计!$A$4:$A$1003,$B4,发票统计!$Q$4:$Q$1003)) -> 0 | O4: =IF($B4="","",SUMIF(发票统计!$A$4:$A$1003,$B4,发票统计!$R$4:$R$1003)) -> 0 | P4: =IF($B4="","",SUMIF(发票统计!$A$4:$A$1003,$B4,发票统计!$S$4:$S$1003)) -> 0 | Q4: =IF($B4="","",N4-O4-P4) -> 0 | R4: =IF($B4="","",IFERROR(IF(SUMPRODUCT(ABS(INDIRECT("'"&$B4&"'!H3:T3")-$E4:$Q4))<0.01,"✓","⚠ 分表合计对不上"),"⚠ 还没建分表")) -> ✓
A5: =IF($B5="","",ROWS(A$4:A5)) -> 2 | B5: =IFERROR(HYPERLINK("#'"&INDEX(目录!$C$3:$C$102,MATCH(ROWS(B$4:B5),目录!$F$3:$F$102,0))&"'!A1",INDEX(目录!$C$3:$C$102,MATCH(ROWS(B$4:B5),目录!$F$3:$F$102,0))),"") -> 云龙社区 | C5: =IF($B5="","",COUNTIF(发票统计!$A$4:$A$1003,$B5)) -> 4 | D5: =IF(N($C5)=0,"",INDEX(发票统计!$D$4:$D$1003,MATCH($B5&"#"&$C5,发票统计!$W$4:$W$1003,0))&"") -> 2026.5.13庆文公账收到新德润款项：云龙社区居民委员会 | E5: =IF($B5="","",SUMIF(发票统计!$A$4:$A$1003,$B5,发票统计!$H$4:$H$1003)) -> 227260.8 | F5: =IF($B5="","",SUMIF(发票统计!$A$4:$A$1003,$B5,发票统计!$I$4:$I$1003)) -> 0 | G5: =IF($B5="","",SUMIF(发票统计!$A$4:$A$1003,$B5,发票统计!$J$4:$J$1003)) -> 227260.8 | H5: =IF($B5="","",SUMIF(发票统计!$A$4:$A$1003,$B5,发票统计!$K$4:$K$1003)) -> 227260.8 | I5: =IF($B5="","",G5-H5) -> 0 | J5: =IF($B5="","",SUMIF(发票统计!$A$4:$A$1003,$B5,发票统计!$M$4:$M$1003)) -> 227260.8 | K5: =IF($B5="","",SUMIF(发票统计!$A$4:$A$1003,$B5,发票统计!$N$4:$N$1003)) -> 0 | L5: =IF($B5="","",SUMIF(发票统计!$A$4:$A$1003,$B5,发票统计!$O$4:$O$1003)) -> 227260.8 | M5: =IF($B5="","",J5-K5-L5) -> 0 | N5: =IF($B5="","",SUMIF(发票统计!$A$4:$A$1003,$B5,发票统计!$Q$4:$Q$1003)) -> 0 | O5: =IF($B5="","",SUMIF(发票统计!$A$4:$A$1003,$B5,发票统计!$R$4:$R$1003)) -> 0 | P5: =IF($B5="","",SUMIF(发票统计!$A$4:$A$1003,$B5,发票统计!$S$4:$S$1003)) -> 0 | Q5: =IF($B5="","",N5-O5-P5) -> 0 | R5: =IF($B5="","",IFERROR(IF(SUMPRODUCT(ABS(INDIRECT("'"&$B5&"'!H3:T3")-$E5:$Q5))<0.01,"✓","⚠ 分表合计对不上"),"⚠ 还没建分表")) -> ✓
A6: =IF($B6="","",ROWS(A$4:A6)) -> 3 | B6: =IFERROR(HYPERLINK("#'"&INDEX(目录!$C$3:$C$102,MATCH(ROWS(B$4:B6),目录!$F$3:$F$102,0))&"'!A1",INDEX(目录!$C$3:$C$102,MATCH(ROWS(B$4:B6),目录!$F$3:$F$102,0))),"") -> 合川瑞翔 | C6: =IF($B6="","",COUNTIF(发票统计!$A$4:$A$1003,$B6)) -> 15 | D6: =IF(N($C6)=0,"",INDEX(发票统计!$D$4:$D$1003,MATCH($B6&"#"&$C6,发票统计!$W$4:$W$1003,0))&"") -> 2026.9.14新德润代胡崇文支付宜宾翠屏货款：42800-39473.83=3326.17 | E6: =IF($B6="","",SUMIF(发票统计!$A$4:$A$1003,$B6,发票统计!$H$4:$H$1003)) -> 500000 | F6: =IF($B6="","",SUMIF(发票统计!$A$4:$A$1003,$B6,发票统计!$I$4:$I$1003)) -> 0 | G6: =IF($B6="","",SUMIF(发票统计!$A$4:$A$1003,$B6,发票统计!$J$4:$J$1003)) -> 500000 | H6: =IF($B6="","",SUMIF(发票统计!$A$4:$A$1003,$B6,发票统计!$K$4:$K$1003)) -> 500000 | I6: =IF($B6="","",G6-H6) -> 0 | J6: =IF($B6="","",SUMIF(发票统计!$A$4:$A$1003,$B6,发票统计!$M$4:$M$1003)) -> 500000 | K6: =IF($B6="","",SUMIF(发票统计!$A$4:$A$1003,$B6,发票统计!$N$4:$N$1003)) -> 0 | L6: =IF($B6="","",SUMIF(发票统计!$A$4:$A$1003,$B6,发票统计!$O$4:$O$1003)) -> 503326.17 | M6: =IF($B6="","",J6-K6-L6) -> -3326.17 | N6: =IF($B6="","",SUMIF(发票统计!$A$4:$A$1003,$B6,发票统计!$Q$4:$Q$1003)) -> 0 | O6: =IF($B6="","",SUMIF(发票统计!$A$4:$A$1003,$B6,发票统计!$R$4:$R$1003)) -> 0 | P6: =IF($B6="","",SUMIF(发票统计!$A$4:$A$1003,$B6,发票统计!$S$4:$S$1003)) -> 0 | Q6: =IF($B6="","",N6-O6-P6) -> 0 | R6: =IF($B6="","",IFERROR(IF(SUMPRODUCT(ABS(INDIRECT("'"&$B6&"'!H3:T3")-$E6:$Q6))<0.01,"✓","⚠ 分表合计对不上"),"⚠ 还没建分表")) -> ✓
