Workbook
Name 账户表: 基础资料!$A$4:$A$13
Name 账户期初: 基础资料!$A$4:$B$13
Name 客户表: 基础资料!$E$4:$E$253
Name 供应商表: 基础资料!$G$4:$G$153
Name 类别表: 基础资料!$I$4:$I$83
Name 类别归属: 基础资料!$I$4:$J$83
Name 归属表: 基础资料!$L$4:$L$23
Name 人员表: 基础资料!$N$4:$N$53
Name 项目类型表: 基础资料!$P$4:$P$15
Name 材料类别表: 基础资料!$R$4:$R$15
Name 材料归属: 基础资料!$R$4:$S$15
Name 工作类型表: 基础资料!$U$4:$U$17
Name 工作归属: 基础资料!$U$4:$V$17
Name 单位表: 基础资料!$X$4:$X$33
Name 往来单位表: 基础资料!$Z$4:$Z$403
Name 收支表: 基础资料!$AB$4:$AB$7
Name 外叫表: 基础资料!$AD$4:$AD$7
Name 项目名表: 项目台账!$B$4:$B$403

Sheet 使用说明
A1: 广告公司项目管理系统 · 使用说明
A2: 全公司一个文件。各人只管自己那张录入表，绿色标签的核算表全是公式，不用填也别删。
A3: 一、谁填哪一张表
A4: 岗位 | B4: 表名 | C4: 填什么
A5: 业务 / 下单 | B5: 项目台账 | C5: 接到单就开一行：项目名、客户、合同额、下单日期。做完了把「完工日期」填上——利润表就是按这个日期确认收入的。
A6: 设计 / 下单 | B6: 订单明细 | C6: 按件报价的客户（一次几十个标牌那种）在这里逐项登记，金额自动汇总进项目台账。整单包死的项目不用填这张。
A7: 采购 | B7: 采购单 | C7: 买的每一笔材料：供应商、项目、主材还是辅材、数量单价。金额自动算。
A8: 设计 / 制作 / 安装 | B8: 生产安装 | C8: 设计费、制作工时、安装工时、加班、外叫小工、吊车租车，按项目登记。
A9: 财务 / 出纳 | B9: 资金日记账 | C9: 五个账户（支付宝、平安银行、中信银行、微信1、微信2）所有进出都记这一张，右边自动结出该账户的即时余额。
A11: 二、三条规则，记住就不会乱
A12: 规则 1 | B12: 成本从哪来 | C12: 项目成本 = 采购单 + 生产安装 + 日记账里选了成本类别的支出。三个来源相加，所以同一笔钱只能记在其中一个地方。
A13: 规则 2 | B13: 别把一笔钱记两次 | C13: 登过采购单的料，出纳付钱时「费用类别」要选『付供应商货款』（它不计成本）；没登采购单的零星开支（配送费、运费、餐费），出纳直接选成本类别即可，不用再补采购单。
A14: 规则 3 | B14: 收入按完工确认 | C14: 利润表的营业收入 = 当月填了「完工日期」的项目合同额，成本也跟着那个月走，这样毛利才配得上。没完工的项目算「在制」，不进利润表。长期客户（比如东尼电子）建议按月建一个项目，月底填完工日期。
A15: 账户互转 | B15: 记两行 | C15: 从支付宝转到平安银行：支付宝记一行支出、平安银行记一行收入，两行的费用类别都选『账户互转』，它不进利润表。
A17: 三、颜色和符号
A18: 淡黄色格子 | B18: 请填写 | C18: 这是要人填的。
A19: 灰色格子 | B19: 公式自动算 | C19: 别手动改，改了就断了。整列往下都有公式，新增数据直接往下填即可。
A20: ※ 开头的红字 | B20: 有问题 | C20: 「核对」列会自己挑毛病：项目不在台账、类别没选、收支金额对不上、可能和采购单重复。看到红的就去改。
A22: 四、录入体检（活的，随时看这里）
A23: 检查项 | B23: 数值 | C23: 说明
A24: 日记账还没分类的笔数 | C24: =COUNTIF(资金日记账!$E:$E,"待分类") | D24: 这些笔的费用类别请挑一个，否则不进利润表
A25: 对应金额（收+支） | C25: =ROUND(SUMIF(资金日记账!$E:$E,"待分类",资金日记账!$J:$J)+SUMIF(资金日记账!$E:$E,"待分类",资金日记账!$K:$K),2)
A26: 成本类支出没填项目的笔数 | C26: =COUNTIF(资金日记账!$P:$P,"※成本类支出没填项目") | D26: 补上项目名，这些钱就能进对应项目的成本，利润表也就准了
A27: 对应金额 | C27: =ROUND(SUMIFS(资金日记账!$K:$K,资金日记账!$P:$P,"※成本类支出没填项目"),2)
A28: 还没填完工日期的项目数 | C28: =COUNTIFS(项目台账!$B$4:$B$403,"<>",项目台账!$J$4:$J$403,"") | D28: 这些项目的收入和成本都还没进利润表
A29: 这些项目的合同额 | C29: =ROUND(SUMIFS(项目台账!$M$4:$M$403,项目台账!$B$4:$B$403,"<>",项目台账!$J$4:$J$403,""),2)
A30: 日记账其它红字提示笔数 | C30: =COUNTIF(资金日记账!$P:$P,"※*")-COUNTIF(资金日记账!$P:$P,"※成本类支出没填项目") | D30: 去【资金日记账】最后一列看
A31: 采购单有红字提示的笔数 | C31: =COUNTIF(采购单!$N:$N,"※*")
A32: 生产安装有红字提示的笔数 | C32: =COUNTIF(生产安装!$M:$M,"※*")
A33: 项目台账有红字提示的条数 | C33: =COUNTIF(项目台账!$S:$S,"※*")
A34: 订单明细项目对不上的条数 | C34: =COUNTIF(订单明细!$J:$J,"※*")
A36: 五、一眼看家底
A37: 五个账户余额合计 | C37: =账户余额!$E$14
A38: 客户还欠我们（应收） | C38: =项目核算!$K$4
A39: 我们还欠供应商（应付） | C39: =供应商对账!$F$4
A40: 在制项目已投入成本 | C40: =利润表!$B$34
A41: 本年累计毛利 | C41: =利润表!$N$17
A42: 本年累计净利 | C42: =利润表!$N$27
A44: 六、这份表是怎么从旧表搬过来的
A45: · 旧文件 22 张表全部取过来了：940 行日记帐、17 张项目表、东尼电子和 Sheet1 两张制作清单、综合汇总表。
...

Sheet 基础资料
A1: 基础资料 · 所有下拉菜单的来源
A2: 要加客户、加供应商、加人，就在这里往下接着写，别留空行。改了这里，所有表的下拉菜单立刻跟着变。
A3: 资金账户 | B3: 期初余额 | E3: 客户名称 | G3: 供应商名称 | I3: 费用类别 | J3: 归属大类 | L3: 归属大类清单 | N3: 人员 | P3: 项目类型 | R3: 材料类别 | S3: 成本归属 | U3: 工作类型 | V3: 成本归属 | X3: 计量单位 | Z3: 往来单位(自动合并) | AB3: 收支方向 | AD3: 是否外叫
A4: 支付宝 | B4: 0 | E4: 南浔美食城 | G4: 炳秀 | I4: 项目收款 | J4: 收款-项目 | L4: 收款-项目 | N4: 杨德 | P4: 门头招牌 | R4: 主材 | S4: 成本-主材 | U4: 设计费 | V4: 成本-人工 | X4: 个 | Z4: =IF(ROW()-3<=COUNTA($E$4:$E$253),INDEX($E$4:$E$253,ROW()-3),IF(ROW()-3-COUNTA($E$4:$E$253)<=COUNTA($G$4:$G$153),INDEX($G$4:$G$153,ROW()-3-COUNTA($E$4:$E$253)),"")) | AB4: 收入 | AD4: 自有员工
A5: 平安银行 | B5: 0 | E5: 德清津华钢铁 | G5: 付久华 | I5: 预收定金 | J5: 收款-项目 | L5: 收入-其他 | N5: 凌宇 | P5: 发光字/灯箱 | R5: 外发加工 | S5: 成本-主材 | U5: 制作工时 | V5: 成本-人工 | X5: 套 | Z5: =IF(ROW()-3<=COUNTA($E$4:$E$253),INDEX($E$4:$E$253,ROW()-3),IF(ROW()-3-COUNTA($E$4:$E$253)<=COUNTA($G$4:$G$153),INDEX($G$4:$G$153,ROW()-3-COUNTA($E$4:$E$253)),"")) | AB5: 支出 | AD5: 外叫
A6: 中信银行 | B6: 0 | E6: 兰溪手擀面 | G6: 货拉拉 | I6: 退还客户款 | J6: 收款-项目 | L6: 成本-主材 | N6: 章凡 | P6: 亮化工程 | R6: 辅材 | S6: 成本-辅材 | U6: 安装工时 | V6: 成本-人工 | X6: 块 | Z6: =IF(ROW()-3<=COUNTA($E$4:$E$253),INDEX($E$4:$E$253,ROW()-3),IF(ROW()-3-COUNTA($E$4:$E$253)<=COUNTA($G$4:$G$153),INDEX($G$4:$G$153,ROW()-3-COUNTA($E$4:$E$253)),""))
A7: 微信1 | B7: 0 | E7: 莫盾服饰 | G7: 拼多多 | I7: 零星物料销售 | J7: 收入-其他 | L7: 成本-辅材 | N7: 徐可欣 | P7: 室内标识 | R7: 五金耗材 | S7: 成本-辅材 | U7: 加班费 | V7: 成本-人工 | X7: 张 | Z7: =IF(ROW()-3<=COUNTA($E$4:$E$253),INDEX($E$4:$E$253,ROW()-3),IF(ROW()-3-COUNTA($E$4:$E$253)<=COUNTA($G$4:$G$153),INDEX($G$4:$G$153,ROW()-3-COUNTA($E$4:$E$253)),""))
A8: 微信2 | B8: 0 | E8: 君澜服饰 | G8: 顺丰速运 | I8: 设计费收入 | J8: 收入-其他 | L8: 成本-人工 | N8: 老姚 | P8: 广告物料 | R8: 其他材料 | S8: 成本-其他 | U8: 外叫小工 | V8: 成本-人工 | X8: 米 | Z8: =IF(ROW()-3<=COUNTA($E$4:$E$253),INDEX($E$4:$E$253,ROW()-3),IF(ROW()-3-COUNTA($E$4:$E$253)<=COUNTA($G$4:$G$153),INDEX($G$4:$G$153,ROW()-3-COUNTA($E$4:$E$253)),""))
A9: 现金 | B9: 0 | E9: 芭比贝克 | G9: 盛世大瑞 | I9: 其他收入 | J9: 收入-其他 | L9: 成本-车运 | N9: 小章 | P9: 车贴喷绘 | U9: 其他人工 | V9: 成本-人工 | X9: 平方 | Z9: =IF(ROW()-3<=COUNTA($E$4:$E$253),INDEX($E$4:$E$253,ROW()-3),IF(ROW()-3-COUNTA($E$4:$E$253)<=COUNTA($G$4:$G$153),INDEX($G$4:$G$153,ROW()-3-COUNTA($E$4:$E$253)),""))
E10: 铁柱烧烤店 | G10: 淘宝 | I10: 主材采购 | J10: 成本-主材 | L10: 成本-其他 | N10: 小姜 | P10: 维修保养 | U10: 吊车/租车 | V10: 成本-车运 | X10: 根 | Z10: =IF(ROW()-3<=COUNTA($E$4:$E$253),INDEX($E$4:$E$253,ROW()-3),IF(ROW()-3-COUNTA($E$4:$E$253)<=COUNTA($G$4:$G$153),INDEX($G$4:$G$153,ROW()-3-COUNTA($E$4:$E$253)),""))
E11: 钟管熟食店 | G11: 安吉鑫龙 | I11: 外发加工 | J11: 成本-主材 | L11: 费用-管理 | P11: 其他 | U11: 运费/搬运 | V11: 成本-车运 | X11: 条 | Z11: =IF(ROW()-3<=COUNTA($E$4:$E$253),INDEX($E$4:$E$253,ROW()-3),IF(ROW()-3-COUNTA($E$4:$E$253)<=COUNTA($G$4:$G$153),INDEX($G$4:$G$153,ROW()-3-COUNTA($E$4:$E$253)),""))
E12: 螺有名灯箱门头 | G12: 章凡 | I12: 辅材采购 | J12: 成本-辅材 | L12: 费用-销售 | X12: 箱 | Z12: =IF(ROW()-3<=COUNTA($E$4:$E$253),INDEX($E$4:$E$253,ROW()-3),IF(ROW()-3-COUNTA($E$4:$E$253)<=COUNTA($G$4:$G$153),INDEX($G$4:$G$153,ROW()-3-COUNTA($E$4:$E$253)),""))
E13: 汕味杏花室内项目 | G13: 浩智蚀刻标识标牌 | I13: 网购材料耗材 | J13: 成本-辅材 | L13: 费用-财务 | X13: 桶 | Z13: =IF(ROW()-3<=COUNTA($E$4:$E$253),INDEX($E$4:$E$253,ROW()-3),IF(ROW()-3-COUNTA($E$4:$E$253)<=COUNTA($G$4:$G$153),INDEX($G$4:$G$153,ROW()-3-COUNTA($E$4:$E$253)),""))
E14: 双林面馆-滨河路 | G14: 天津货拉拉科技有限 | I14: 五金耗材 | J14: 成本-辅材 | L14: 其他-营业外收入 | X14: 支 | Z14: =IF(ROW()-3<=COUNTA($E$4:$E$253),INDEX($E$4:$E$253,ROW()-3),IF(ROW()-3-COUNTA($E$4:$E$253)<=COUNTA($G$4:$G$153),INDEX($G$4:$G$153,ROW()-3-COUNTA($E$4:$E$253)),""))
E15: 梓灿软装 | G15: 一利钢材 | I15: 设计费 | J15: 成本-人工 | L15: 其他-营业外支出 | X15: 卷 | Z15: =IF(ROW()-3<=COUNTA($E$4:$E$253),INDEX($E$4:$E$253,ROW()-3),IF(ROW()-3-COUNTA($E$4:$E$253)<=COUNTA($G$4:$G$153),INDEX($G$4:$G$153,ROW()-3-COUNTA($E$4:$E$253)),""))
E16: 长颈鹿庄园 | G16: 小王加工厂 | I16: 制作工资 | J16: 成本-人工 | L16: 往来-货款 | X16: 工 | Z16: =IF(ROW()-3<=COUNTA($E$4:$E$253),INDEX($E$4:$E$253,ROW()-3),IF(ROW()-3-COUNTA($E$4:$E$253)<=COUNTA($G$4:$G$153),INDEX($G$4:$G$153,ROW()-3-COUNTA($E$4:$E$253)),""))
E17: 国智校服 | G17: 甄铭 | I17: 安装工资 | J17: 成本-人工 | L17: 往来-借贷 | X17: 天 | Z17: =IF(ROW()-3<=COUNTA($E$4:$E$253),INDEX($E$4:$E$253,ROW()-3),IF(ROW()-3-COUNTA($E$4:$E$253)<=COUNTA($G$4:$G$153),INDEX($G$4:$G$153,ROW()-3-COUNTA($E$4:$E$253)),""))
E18: 民盛生鲜店 | G18: 小王 | I18: 加班费 | J18: 成本-人工 | L18: 内部转账 | X18: 次 | Z18: =IF(ROW()-3<=COUNTA($E$4:$E$253),INDEX($E$4:$E$253,ROW()-3),IF(ROW()-3-COUNTA($E$4:$E$253)<=COUNTA($G$4:$G$153),INDEX($G$4:$G$153,ROW()-3-COUNTA($E$4:$E$253)),""))
E19: 饺子店 | G19: 水尚 | I19: 外叫小工 | J19: 成本-人工 | X19: 趟 | Z19: =IF(ROW()-3<=COUNTA($E$4:$E$253),INDEX($E$4:$E$253,ROW()-3),IF(ROW()-3-COUNTA($E$4:$E$253)<=COUNTA($G$4:$G$153),INDEX($G$4:$G$153,ROW()-3-COUNTA($E$4:$E$253)),""))
E20: 睿芯行 | G20: 杭州杜邦软膜 | I20: 运费/快递费 | J20: 成本-车运 | X20: 项 | Z20: =IF(ROW()-3<=COUNTA($E$4:$E$253),INDEX($E$4:$E$253,ROW()-3),IF(ROW()-3-COUNTA($E$4:$E$253)<=COUNTA($G$4:$G$153),INDEX($G$4:$G$153,ROW()-3-COUNTA($E$4:$E$253)),""))
E21: 东尼新能源 | G21: 浙江孚泰 | I21: 车费/油费/过路费 | J21: 成本-车运 | X21: 批 | Z21: =IF(ROW()-3<=COUNTA($E$4:$E$253),INDEX($E$4:$E$253,ROW()-3),IF(ROW()-3-COUNTA($E$4:$E$253)<=COUNTA($G$4:$G$153),INDEX($G$4:$G$153,ROW()-3-COUNTA($E$4:$E$253)),""))
E22: 盛昊篷车 | G22: 吉祥铝板吴玲芳 | I22: 吊车/租车费 | J22: 成本-车运 | X22: 台 | Z22: =IF(ROW()-3<=COUNTA($E$4:$E$253),INDEX($E$4:$E$253,ROW()-3),IF(ROW()-3-COUNTA($E$4:$E$253)<=COUNTA($G$4:$G$153),INDEX($G$4:$G$153,ROW()-3-COUNTA($E$4:$E$253)),""))
E23: 付炳秀配送 | G23: 上达铝板 | I23: 项目餐费补助 | J23: 成本-其他 | X23: 组 | Z23: =IF(ROW()-3<=COUNTA($E$4:$E$253),INDEX($E$4:$E$253,ROW()-3),IF(ROW()-3-COUNTA($E$4:$E$253)<=COUNTA($G$4:$G$153),INDEX($G$4:$G$153,ROW()-3-COUNTA($E$4:$E$253)),""))
E24: 万达kvv | G24: 北京京邦达贸易有限 | I24: 其他直接费用 | J24: 成本-其他 | X24: m² | Z24: =IF(ROW()-3<=COUNTA($E$4:$E$253),INDEX($E$4:$E$253,ROW()-3),IF(ROW()-3-COUNTA($E$4:$E$253)<=COUNTA($G$4:$G$153),INDEX($G$4:$G$153,ROW()-3-COUNTA($E$4:$E$253)),""))
E25: 织里店 | G25: 外叫租赁 | I25: 员工工资 | J25: 费用-管理 | X25: 千克 | Z25: =IF(ROW()-3<=COUNTA($E$4:$E$253),INDEX($E$4:$E$253,ROW()-3),IF(ROW()-3-COUNTA($E$4:$E$253)<=COUNTA($G$4:$G$153),INDEX($G$4:$G$153,ROW()-3-COUNTA($E$4:$E$253)),""))
E26: 高恒荣熟食店 | G26: 匠心 | I26: 社保公积金 | J26: 费用-管理 | Z26: =IF(ROW()-3<=COUNTA($E$4:$E$253),INDEX($E$4:$E$253,ROW()-3),IF(ROW()-3-COUNTA($E$4:$E$253)<=COUNTA($G$4:$G$153),INDEX($G$4:$G$153,ROW()-3-COUNTA($E$4:$E$253)),""))
E27: 卓越桌球 | G27: 杭州水尚装饰 | I27: 房租水电 | J27: 费用-管理 | Z27: =IF(ROW()-3<=COUNTA($E$4:$E$253),INDEX($E$4:$E$253,ROW()-3),IF(ROW()-3-COUNTA($E$4:$E$253)<=COUNTA($G$4:$G$153),INDEX($G$4:$G$153,ROW()-3-COUNTA($E$4:$E$253)),""))
E28: 东尼电子 | G28: 点工 | I28: 办公用品 | J28: 费用-管理 | Z28: =IF(ROW()-3<=COUNTA($E$4:$E$253),INDEX($E$4:$E$253,ROW()-3),IF(ROW()-3-COUNTA($E$4:$E$253)<=COUNTA($G$4:$G$153),INDEX($G$4:$G$153,ROW()-3-COUNTA($E$4:$E$253)),""))
E29: 犇腾牛排 | G29: 灯箱哥 | I29: 通讯费 | J29: 费用-管理 | Z29: =IF(ROW()-3<=COUNTA($E$4:$E$253),INDEX($E$4:$E$253,ROW()-3),IF(ROW()-3-COUNTA($E$4:$E$253)<=COUNTA($G$4:$G$153),INDEX($G$4:$G$153,ROW()-3-COUNTA($E$4:$E$253)),""))
E30: 校服基地 | G30: 1.71*5.61 | I30: 差旅费 | J30: 费用-管理 | Z30: =IF(ROW()-3<=COUNTA($E$4:$E$253),INDEX($E$4:$E$253,ROW()-3),IF(ROW()-3-COUNTA($E$4:$E$253)<=COUNTA($G$4:$G$153),INDEX($G$4:$G$153,ROW()-3-COUNTA($E$4:$E$253)),""))
E31: 德清钟管菜市场 | G31: 武帝 | I31: 业务招待/餐费 | J31: 费用-管理 | Z31: =IF(ROW()-3<=COUNTA($E$4:$E$253),INDEX($E$4:$E$253,ROW()-3),IF(ROW()-3-COUNTA($E$4:$E$253)<=COUNTA($G$4:$G$153),INDEX($G$4:$G$153,ROW()-3-COUNTA($E$4:$E$253)),""))
E32: 中交 | G32: 泰发五金 | I32: 团建费 | J32: 费用-管理 | Z32: =IF(ROW()-3<=COUNTA($E$4:$E$253),INDEX($E$4:$E$253,ROW()-3),IF(ROW()-3-COUNTA($E$4:$E$253)<=COUNTA($G$4:$G$153),INDEX($G$4:$G$153,ROW()-3-COUNTA($E$4:$E$253)),""))
E33: vip宠物乐园 | G33: 周学峰 | I33: 车辆费用(非项目) | J33: 费用-管理 | Z33: =IF(ROW()-3<=COUNTA($E$4:$E$253),INDEX($E$4:$E$253,ROW()-3),IF(ROW()-3-COUNTA($E$4:$E$253)<=COUNTA($G$4:$G$153),INDEX($G$4:$G$153,ROW()-3-COUNTA($E$4:$E$253)),""))
E34: 安吉车贴项目 | G34: 顺丰快递费 | I34: 税金 | J34: 费用-管理 | Z34: =IF(ROW()-3<=COUNTA($E$4:$E$253),INDEX($E$4:$E$253,ROW()-3),IF(ROW()-3-COUNTA($E$4:$E$253)<=COUNTA($G$4:$G$153),INDEX($G$4:$G$153,ROW()-3-COUNTA($E$4:$E$253)),""))
E35: 最爱潘多拉ktv | G35: 吴玲芳 | I35: 其他管理费用 | J35: 费用-管理 | Z35: =IF(ROW()-3<=COUNTA($E$4:$E$253),INDEX($E$4:$E$253,ROW()-3),IF(ROW()-3-COUNTA($E$4:$E$253)<=COUNTA($G$4:$G$153),INDEX($G$4:$G$153,ROW()-3-COUNTA($E$4:$E$253)),""))
E36: 小谷姐姐 | G36: 津华钢铁张总 | I36: 广告推广 | J36: 费用-销售 | Z36: =IF(ROW()-3<=COUNTA($E$4:$E$253),INDEX($E$4:$E$253,ROW()-3),IF(ROW()-3-COUNTA($E$4:$E$253)<=COUNTA($G$4:$G$153),INDEX($G$4:$G$153,ROW()-3-COUNTA($E$4:$E$253)),""))
E37: 每甜 | G37: 220V不防水区块65 | I37: 平台服务费 | J37: 费用-销售 | Z37: =IF(ROW()-3<=COUNTA($E$4:$E$253),INDEX($E$4:$E$253,ROW()-3),IF(ROW()-3-COUNTA($E$4:$E$253)<=COUNTA($G$4:$G$153),INDEX($G$4:$G$153,ROW()-3-COUNTA($E$4:$E$253)),""))
... E54: 凤姐早餐店 | G54: 货拉拉运费 | I54: 营业外支出 | J54: 其他-营业外支出 | Z54: =IF(ROW()-3<=COUNTA($E$4:$E$253),INDEX($E$4:$E$253,ROW()-3),IF(ROW()-3-COUNTA($E$4:$E$253)<=COUNTA($G$4:$G$153),INDEX($G$4:$G$153,ROW()-3-COUNTA($E$4:$E$253)),""))
E55: 焰燃烧烤 | G55: 温州五金 | I55: 待分类 | Z55: =IF(ROW()-3<=COUNTA($E$4:$E$253),INDEX($E$4:$E$253,ROW()-3),IF(ROW()-3-COUNTA($E$4:$E$253)<=COUNTA($G$4:$G$153),INDEX($G$4:$G$153,ROW()-3-COUNTA($E$4:$E$253)),""))
E56: 湖岸漫食 | G56: 京东货拉拉运费 | Z56: =IF(ROW()-3<=COUNTA($E$4:$E$253),INDEX($E$4:$E$253,ROW()-3),IF(ROW()-3-COUNTA($E$4:$E$253)<=COUNTA($G$4:$G$153),INDEX($G$4:$G$153,ROW()-3-COUNTA($E$4:$E$253)),""))
...

Sheet 项目台账
A1: 项目台账 · 业务 / 下单岗位填
A2: 接到单就开一行。做完了一定要填「完工日期」——利润表就是按这个日期把收入和成本算进当月的。
A3: 项目编号 | B3: 项目名称 ★ | C3: 客户名称 ★ | D3: 项目类型 | E3: 负责人 | F3: 下单日期 ★ | G3: 设计完成 | H3: 制作完成 | I3: 安装完成 | J3: 完工日期 ★ (确认收入) | K3: 合同额 (整单包死) | L3: 订单明细额 (自动) | M3: 合同总额 | N3: 期初已收 (导入用) | O3: 已收款 | P3: 未收款 | Q3: 状态 | R3: 备注 | S3: 核对
A4: =IF($B4="","","P"&TEXT(ROW()-3,"000")) | B4: 南浔美食城 | C4: 南浔美食城 | D4: 门头招牌 | F4: 46043 | K4: 42294 | L4: =IF($B4="","",ROUND(SUMIF(订单明细!$C:$C,$B4,订单明细!$I:$I),2)) | M4: =IF($B4="","",ROUND(N($K4)+N($L4),2)) | N4: 20000 | O4: =IF($B4="","",ROUND(N($N4)+SUMIFS(资金日记账!$J$4:$J$2503,资金日记账!$G$4:$G$2503,$B4,资金日记账!$F$4:$F$2503,"收款-项目")-SUMIFS(资金日记账!$K$4:$K$2503,资金日记账!$G$4:$G$2503,$B4,资金日记账!$F$4:$F$2503,"收款-项目"),2)) | P4: =IF($B4="","",ROUND($M4-$O4,2)) | Q4: =IF($B4="","",IF(AND($J4<>"",ROUND($P4,2)<=0),"已完工·已结清",IF($J4<>"","已完工·还有尾款",IF($I4<>"","已安装",IF($H4<>"","已制作",IF($G4<>"","设计完成","已下单")))))) | R4: 来源：1-南浔美食城 | S4: =IF($B4="","",IF(COUNTIF($B$4:$B$403,$B4)>1,"※项目名重复了",IF(AND($C4<>"",ISNA(MATCH($C4,客户表,0))),"※客户不在基础资料里",IF(AND($J4<>"",$F4<>"",$J4<$F4),"※完工日期早于下单日期",""))))
A5: =IF($B5="","","P"&TEXT(ROW()-3,"000")) | B5: 德清津华钢铁 | C5: 德清津华钢铁 | D5: 门头招牌 | F5: 46060 | J5: 46082 | K5: 11000 | L5: =IF($B5="","",ROUND(SUMIF(订单明细!$C:$C,$B5,订单明细!$I:$I),2)) | M5: =IF($B5="","",ROUND(N($K5)+N($L5),2)) | N5: 11000 | O5: =IF($B5="","",ROUND(N($N5)+SUMIFS(资金日记账!$J$4:$J$2503,资金日记账!$G$4:$G$2503,$B5,资金日记账!$F$4:$F$2503,"收款-项目")-SUMIFS(资金日记账!$K$4:$K$2503,资金日记账!$G$4:$G$2503,$B5,资金日记账!$F$4:$F$2503,"收款-项目"),2)) | P5: =IF($B5="","",ROUND($M5-$O5,2)) | Q5: =IF($B5="","",IF(AND($J5<>"",ROUND($P5,2)<=0),"已完工·已结清",IF($J5<>"","已完工·还有尾款",IF($I5<>"","已安装",IF($H5<>"","已制作",IF($G5<>"","设计完成","已下单")))))) | R5: 来源：2-德清津华钢铁 | S5: =IF($B5="","",IF(COUNTIF($B$4:$B$403,$B5)>1,"※项目名重复了",IF(AND($C5<>"",ISNA(MATCH($C5,客户表,0))),"※客户不在基础资料里",IF(AND($J5<>"",$F5<>"",$J5<$F5),"※完工日期早于下单日期",""))))
A6: =IF($B6="","","P"&TEXT(ROW()-3,"000")) | B6: 兰溪手擀面 | C6: 兰溪手擀面 | D6: 门头招牌 | F6: 46083 | J6: 46083 | K6: 1400 | L6: =IF($B6="","",ROUND(SUMIF(订单明细!$C:$C,$B6,订单明细!$I:$I),2)) | M6: =IF($B6="","",ROUND(N($K6)+N($L6),2)) | O6: =IF($B6="","",ROUND(N($N6)+SUMIFS(资金日记账!$J$4:$J$2503,资金日记账!$G$4:$G$2503,$B6,资金日记账!$F$4:$F$2503,"收款-项目")-SUMIFS(资金日记账!$K$4:$K$2503,资金日记账!$G$4:$G$2503,$B6,资金日记账!$F$4:$F$2503,"收款-项目"),2)) | P6: =IF($B6="","",ROUND($M6-$O6,2)) | Q6: =IF($B6="","",IF(AND($J6<>"",ROUND($P6,2)<=0),"已完工·已结清",IF($J6<>"","已完工·还有尾款",IF($I6<>"","已安装",IF($H6<>"","已制作",IF($G6<>"","设计完成","已下单")))))) | R6: 来源：3-兰溪手擀面 | S6: =IF($B6="","",IF(COUNTIF($B$4:$B$403,$B6)>1,"※项目名重复了",IF(AND($C6<>"",ISNA(MATCH($C6,客户表,0))),"※客户不在基础资料里",IF(AND($J6<>"",$F6<>"",$J6<$F6),"※完工日期早于下单日期",""))))
A7: =IF($B7="","","P"&TEXT(ROW()-3,"000")) | B7: 莫盾服饰 | C7: 莫盾服饰 | D7: 门头招牌 | K7: 12623 | L7: =IF($B7="","",ROUND(SUMIF(订单明细!$C:$C,$B7,订单明细!$I:$I),2)) | M7: =IF($B7="","",ROUND(N($K7)+N($L7),2)) | O7: =IF($B7="","",ROUND(N($N7)+SUMIFS(资金日记账!$J$4:$J$2503,资金日记账!$G$4:$G$2503,$B7,资金日记账!$F$4:$F$2503,"收款-项目")-SUMIFS(资金日记账!$K$4:$K$2503,资金日记账!$G$4:$G$2503,$B7,资金日记账!$F$4:$F$2503,"收款-项目"),2)) | P7: =IF($B7="","",ROUND($M7-$O7,2)) | Q7: =IF($B7="","",IF(AND($J7<>"",ROUND($P7,2)<=0),"已完工·已结清",IF($J7<>"","已完工·还有尾款",IF($I7<>"","已安装",IF($H7<>"","已制作",IF($G7<>"","设计完成","已下单")))))) | R7: 来源：4-莫盾服饰 | S7: =IF($B7="","",IF(COUNTIF($B$4:$B$403,$B7)>1,"※项目名重复了",IF(AND($C7<>"",ISNA(MATCH($C7,客户表,0))),"※客户不在基础资料里",IF(AND($J7<>"",$F7<>"",$J7<$F7),"※完工日期早于下单日期",""))))
A8: =IF($B8="","","P"&TEXT(ROW()-3,"000")) | B8: 君澜服饰 | C8: 君澜服饰 | D8: 门头招牌 | F8: 46106 | K8: 9350 | L8: =IF($B8="","",ROUND(SUMIF(订单明细!$C:$C,$B8,订单明细!$I:$I),2)) | M8: =IF($B8="","",ROUND(N($K8)+N($L8),2)) | O8: =IF($B8="","",ROUND(N($N8)+SUMIFS(资金日记账!$J$4:$J$2503,资金日记账!$G$4:$G$2503,$B8,资金日记账!$F$4:$F$2503,"收款-项目")-SUMIFS(资金日记账!$K$4:$K$2503,资金日记账!$G$4:$G$2503,$B8,资金日记账!$F$4:$F$2503,"收款-项目"),2)) | P8: =IF($B8="","",ROUND($M8-$O8,2)) | Q8: =IF($B8="","",IF(AND($J8<>"",ROUND($P8,2)<=0),"已完工·已结清",IF($J8<>"","已完工·还有尾款",IF($I8<>"","已安装",IF($H8<>"","已制作",IF($G8<>"","设计完成","已下单")))))) | R8: 来源：5-君澜服饰 | S8: =IF($B8="","",IF(COUNTIF($B$4:$B$403,$B8)>1,"※项目名重复了",IF(AND($C8<>"",ISNA(MATCH($C8,客户表,0))),"※客户不在基础资料里",IF(AND($J8<>"",$F8<>"",$J8<$F8),"※完工日期早于下单日期",""))))
A9: =IF($B9="","","P"&TEXT(ROW()-3,"000")) | B9: 芭比贝克 | C9: 芭比贝克 | D9: 门头招牌 | F9: 46082 | J9: 46128 | K9: 820 | L9: =IF($B9="","",ROUND(SUMIF(订单明细!$C:$C,$B9,订单明细!$I:$I),2)) | M9: =IF($B9="","",ROUND(N($K9)+N($L9),2)) | O9: =IF($B9="","",ROUND(N($N9)+SUMIFS(资金日记账!$J$4:$J$2503,资金日记账!$G$4:$G$2503,$B9,资金日记账!$F$4:$F$2503,"收款-项目")-SUMIFS(资金日记账!$K$4:$K$2503,资金日记账!$G$4:$G$2503,$B9,资金日记账!$F$4:$F$2503,"收款-项目"),2)) | P9: =IF($B9="","",ROUND($M9-$O9,2)) | Q9: =IF($B9="","",IF(AND($J9<>"",ROUND($P9,2)<=0),"已完工·已结清",IF($J9<>"","已完工·还有尾款",IF($I9<>"","已安装",IF($H9<>"","已制作",IF($G9<>"","设计完成","已下单")))))) | R9: 来源：6-芭比贝克1 | S9: =IF($B9="","",IF(COUNTIF($B$4:$B$403,$B9)>1,"※项目名重复了",IF(AND($C9<>"",ISNA(MATCH($C9,客户表,0))),"※客户不在基础资料里",IF(AND($J9<>"",$F9<>"",$J9<$F9),"※完工日期早于下单日期",""))))
A10: =IF($B10="","","P"&TEXT(ROW()-3,"000")) | B10: 铁柱烧烤店 | C10: 铁柱烧烤店 | D10: 门头招牌 | F10: 46100 | J10: 46139 | K10: 7800 | L10: =IF($B10="","",ROUND(SUMIF(订单明细!$C:$C,$B10,订单明细!$I:$I),2)) | M10: =IF($B10="","",ROUND(N($K10)+N($L10),2)) | O10: =IF($B10="","",ROUND(N($N10)+SUMIFS(资金日记账!$J$4:$J$2503,资金日记账!$G$4:$G$2503,$B10,资金日记账!$F$4:$F$2503,"收款-项目")-SUMIFS(资金日记账!$K$4:$K$2503,资金日记账!$G$4:$G$2503,$B10,资金日记账!$F$4:$F$2503,"收款-项目"),2)) | P10: =IF($B10="","",ROUND($M10-$O10,2)) | Q10: =IF($B10="","",IF(AND($J10<>"",ROUND($P10,2)<=0),"已完工·已结清",IF($J10<>"","已完工·还有尾款",IF($I10<>"","已安装",IF($H10<>"","已制作",IF($G10<>"","设计完成","已下单")))))) | R10: 来源：7-铁柱烧烤店 | S10: =IF($B10="","",IF(COUNTIF($B$4:$B$403,$B10)>1,"※项目名重复了",IF(AND($C10<>"",ISNA(MATCH($C10,客户表,0))),"※客户不在基础资料里",IF(AND($J10<>"",$F10<>"",$J10<$F10),"※完工日期早于下单日期",""))))
A11: =IF($B11="","","P"&TEXT(ROW()-3,"000")) | B11: 钟管熟食店 | C11: 钟管熟食店 | D11: 门头招牌 | F11: 46084 | J11: 46084 | K11: 24000 | L11: =IF($B11="","",ROUND(SUMIF(订单明细!$C:$C,$B11,订单明细!$I:$I),2)) | M11: =IF($B11="","",ROUND(N($K11)+N($L11),2)) | N11: 24000 | O11: =IF($B11="","",ROUND(N($N11)+SUMIFS(资金日记账!$J$4:$J$2503,资金日记账!$G$4:$G$2503,$B11,资金日记账!$F$4:$F$2503,"收款-项目")-SUMIFS(资金日记账!$K$4:$K$2503,资金日记账!$G$4:$G$2503,$B11,资金日记账!$F$4:$F$2503,"收款-项目"),2)) | P11: =IF($B11="","",ROUND($M11-$O11,2)) | Q11: =IF($B11="","",IF(AND($J11<>"",ROUND($P11,2)<=0),"已完工·已结清",IF($J11<>"","已完工·还有尾款",IF($I11<>"","已安装",IF($H11<>"","已制作",IF($G11<>"","设计完成","已下单")))))) | R11: 来源：8-钟管熟食店 | S11: =IF($B11="","",IF(COUNTIF($B$4:$B$403,$B11)>1,"※项目名重复了",IF(AND($C11<>"",ISNA(MATCH($C11,客户表,0))),"※客户不在基础资料里",IF(AND($J11<>"",$F11<>"",$J11<$F11),"※完工日期早于下单日期",""))))
A12: =IF($B12="","","P"&TEXT(ROW()-3,"000")) | B12: 螺有名灯箱门头 | C12: 螺有名灯箱门头 | D12: 门头招牌 | F12: 46100 | J12: 46100 | K12: 1314 | L12: =IF($B12="","",ROUND(SUMIF(订单明细!$C:$C,$B12,订单明细!$I:$I),2)) | M12: =IF($B12="","",ROUND(N($K12)+N($L12),2)) | N12: 1314 | O12: =IF($B12="","",ROUND(N($N12)+SUMIFS(资金日记账!$J$4:$J$2503,资金日记账!$G$4:$G$2503,$B12,资金日记账!$F$4:$F$2503,"收款-项目")-SUMIFS(资金日记账!$K$4:$K$2503,资金日记账!$G$4:$G$2503,$B12,资金日记账!$F$4:$F$2503,"收款-项目"),2)) | P12: =IF($B12="","",ROUND($M12-$O12,2)) | Q12: =IF($B12="","",IF(AND($J12<>"",ROUND($P12,2)<=0),"已完工·已结清",IF($J12<>"","已完工·还有尾款",IF($I12<>"","已安装",IF($H12<>"","已制作",IF($G12<>"","设计完成","已下单")))))) | R12: 来源：9-螺有名灯箱门头 | S12: =IF($B12="","",IF(COUNTIF($B$4:$B$403,$B12)>1,"※项目名重复了",IF(AND($C12<>"",ISNA(MATCH($C12,客户表,0))),"※客户不在基础资料里",IF(AND($J12<>"",$F12<>"",$J12<$F12),"※完工日期早于下单日期",""))))
A13: =IF($B13="","","P"&TEXT(ROW()-3,"000")) | B13: 汕味杏花室内项目 | C13: 汕味杏花室内项目 | D13: 门头招牌 | F13: 46102 | J13: 46120 | K13: 5665.5 | L13: =IF($B13="","",ROUND(SUMIF(订单明细!$C:$C,$B13,订单明细!$I:$I),2)) | M13: =IF($B13="","",ROUND(N($K13)+N($L13),2)) | N13: 3000 | O13: =IF($B13="","",ROUND(N($N13)+SUMIFS(资金日记账!$J$4:$J$2503,资金日记账!$G$4:$G$2503,$B13,资金日记账!$F$4:$F$2503,"收款-项目")-SUMIFS(资金日记账!$K$4:$K$2503,资金日记账!$G$4:$G$2503,$B13,资金日记账!$F$4:$F$2503,"收款-项目"),2)) | P13: =IF($B13="","",ROUND($M13-$O13,2)) | Q13: =IF($B13="","",IF(AND($J13<>"",ROUND($P13,2)<=0),"已完工·已结清",IF($J13<>"","已完工·还有尾款",IF($I13<>"","已安装",IF($H13<>"","已制作",IF($G13<>"","设计完成","已下单")))))) | R13: 来源：10-汕味杏花室内项目 | S13: =IF($B13="","",IF(COUNTIF($B$4:$B$403,$B13)>1,"※项目名重复了",IF(AND($C13<>"",ISNA(MATCH($C13,客户表,0))),"※客户不在基础资料里",IF(AND($J13<>"",$F13<>"",$J13<$F13),"※完工日期早于下单日期",""))))
A14: =IF($B14="","","P"&TEXT(ROW()-3,"000")) | B14: 双林面馆-滨河路 | C14: 双林面馆-滨河路 | D14: 门头招牌 | F14: 46086 | K14: 4400 | L14: =IF($B14="","",ROUND(SUMIF(订单明细!$C:$C,$B14,订单明细!$I:$I),2)) | M14: =IF($B14="","",ROUND(N($K14)+N($L14),2)) | N14: 1700 | O14: =IF($B14="","",ROUND(N($N14)+SUMIFS(资金日记账!$J$4:$J$2503,资金日记账!$G$4:$G$2503,$B14,资金日记账!$F$4:$F$2503,"收款-项目")-SUMIFS(资金日记账!$K$4:$K$2503,资金日记账!$G$4:$G$2503,$B14,资金日记账!$F$4:$F$2503,"收款-项目"),2)) | P14: =IF($B14="","",ROUND($M14-$O14,2)) | Q14: =IF($B14="","",IF(AND($J14<>"",ROUND($P14,2)<=0),"已完工·已结清",IF($J14<>"","已完工·还有尾款",IF($I14<>"","已安装",IF($H14<>"","已制作",IF($G14<>"","设计完成","已下单")))))) | R14: 来源：11-双林面馆-滨河路 | S14: =IF($B14="","",IF(COUNTIF($B$4:$B$403,$B14)>1,"※项目名重复了",IF(AND($C14<>"",ISNA(MATCH($C14,客户表,0))),"※客户不在基础资料里",IF(AND($J14<>"",$F14<>"",$J14<$F14),"※完工日期早于下单日期",""))))
A15: =IF($B15="","","P"&TEXT(ROW()-3,"000")) | B15: 梓灿软装 | C15: 梓灿软装 | D15: 门头招牌 | F15: 46102 | K15: 3400 | L15: =IF($B15="","",ROUND(SUMIF(订单明细!$C:$C,$B15,订单明细!$I:$I),2)) | M15: =IF($B15="","",ROUND(N($K15)+N($L15),2)) | O15: =IF($B15="","",ROUND(N($N15)+SUMIFS(资金日记账!$J$4:$J$2503,资金日记账!$G$4:$G$2503,$B15,资金日记账!$F$4:$F$2503,"收款-项目")-SUMIFS(资金日记账!$K$4:$K$2503,资金日记账!$G$4:$G$2503,$B15,资金日记账!$F$4:$F$2503,"收款-项目"),2)) | P15: =IF($B15="","",ROUND($M15-$O15,2)) | Q15: =IF($B15="","",IF(AND($J15<>"",ROUND($P15,2)<=0),"已完工·已结清",IF($J15<>"","已完工·还有尾款",IF($I15<>"","已安装",IF($H15<>"","已制作",IF($G15<>"","设计完成","已下单")))))) | R15: 来源：12-梓灿软装 | S15: =IF($B15="","",IF(COUNTIF($B$4:$B$403,$B15)>1,"※项目名重复了",IF(AND($C15<>"",ISNA(MATCH($C15,客户表,0))),"※客户不在基础资料里",IF(AND($J15<>"",$F15<>"",$J15<$F15),"※完工日期早于下单日期",""))))
A16: =IF($B16="","","P"&TEXT(ROW()-3,"000")) | B16: 长颈鹿庄园 | C16: 长颈鹿庄园 | D16: 门头招牌 | F16: 46083 | J16: 46112 | K16: 4050 | L16: =IF($B16="","",ROUND(SUMIF(订单明细!$C:$C,$B16,订单明细!$I:$I),2)) | M16: =IF($B16="","",ROUND(N($K16)+N($L16),2)) | O16: =IF($B16="","",ROUND(N($N16)+SUMIFS(资金日记账!$J$4:$J$2503,资金日记账!$G$4:$G$2503,$B16,资金日记账!$F$4:$F$2503,"收款-项目")-SUMIFS(资金日记账!$K$4:$K$2503,资金日记账!$G$4:$G$2503,$B16,资金日记账!$F$4:$F$2503,"收款-项目"),2)) | P16: =IF($B16="","",ROUND($M16-$O16,2)) | Q16: =IF($B16="","",IF(AND($J16<>"",ROUND($P16,2)<=0),"已完工·已结清",IF($J16<>"","已完工·还有尾款",IF($I16<>"","已安装",IF($H16<>"","已制作",IF($G16<>"","设计完成","已下单")))))) | R16: 来源：13-长颈鹿庄园 | S16: =IF($B16="","",IF(COUNTIF($B$4:$B$403,$B16)>1,"※项目名重复了",IF(AND($C16<>"",ISNA(MATCH($C16,客户表,0))),"※客户不在基础资料里",IF(AND($J16<>"",$F16<>"",$J16<$F16),"※完工日期早于下单日期",""))))
A17: =IF($B17="","","P"&TEXT(ROW()-3,"000")) | B17: 国智校服 | C17: 国智校服 | D17: 门头招牌 | F17: 46083 | K17: 4904.2 | L17: =IF($B17="","",ROUND(SUMIF(订单明细!$C:$C,$B17,订单明细!$I:$I),2)) | M17: =IF($B17="","",ROUND(N($K17)+N($L17),2)) | O17: =IF($B17="","",ROUND(N($N17)+SUMIFS(资金日记账!$J$4:$J$2503,资金日记账!$G$4:$G$2503,$B17,资金日记账!$F$4:$F$2503,"收款-项目")-SUMIFS(资金日记账!$K$4:$K$2503,资金日记账!$G$4:$G$2503,$B17,资金日记账!$F$4:$F$2503,"收款-项目"),2)) | P17: =IF($B17="","",ROUND($M17-$O17,2)) | Q17: =IF($B17="","",IF(AND($J17<>"",ROUND($P17,2)<=0),"已完工·已结清",IF($J17<>"","已完工·还有尾款",IF($I17<>"","已安装",IF($H17<>"","已制作",IF($G17<>"","设计完成","已下单")))))) | R17: 来源：14-国智校服 | S17: =IF($B17="","",IF(COUNTIF($B$4:$B$403,$B17)>1,"※项目名重复了",IF(AND($C17<>"",ISNA(MATCH($C17,客户表,0))),"※客户不在基础资料里",IF(AND($J17<>"",$F17<>"",$J17<$F17),"※完工日期早于下单日期",""))))
A18: =IF($B18="","","P"&TEXT(ROW()-3,"000")) | B18: 民盛生鲜店 | C18: 民盛生鲜店 | D18: 门头招牌 | F18: 46107 | J18: 46129 | K18: 2000 | L18: =IF($B18="","",ROUND(SUMIF(订单明细!$C:$C,$B18,订单明细!$I:$I),2)) | M18: =IF($B18="","",ROUND(N($K18)+N($L18),2)) | O18: =IF($B18="","",ROUND(N($N18)+SUMIFS(资金日记账!$J$4:$J$2503,资金日记账!$G$4:$G$2503,$B18,资金日记账!$F$4:$F$2503,"收款-项目")-SUMIFS(资金日记账!$K$4:$K$2503,资金日记账!$G$4:$G$2503,$B18,资金日记账!$F$4:$F$2503,"收款-项目"),2)) | P18: =IF($B18="","",ROUND($M18-$O18,2)) | Q18: =IF($B18="","",IF(AND($J18<>"",ROUND($P18,2)<=0),"已完工·已结清",IF($J18<>"","已完工·还有尾款",IF($I18<>"","已安装",IF($H18<>"","已制作",IF($G18<>"","设计完成","已下单")))))) | R18: 来源：15-民盛生鲜店 | S18: =IF($B18="","",IF(COUNTIF($B$4:$B$403,$B18)>1,"※项目名重复了",IF(AND($C18<>"",ISNA(MATCH($C18,客户表,0))),"※客户不在基础资料里",IF(AND($J18<>"",$F18<>"",$J18<$F18),"※完工日期早于下单日期",""))))
A19: =IF($B19="","","P"&TEXT(ROW()-3,"000")) | B19: 饺子店 | C19: 饺子店 | D19: 门头招牌 | F19: 46108 | J19: 46119 | K19: 1928 | L19: =IF($B19="","",ROUND(SUMIF(订单明细!$C:$C,$B19,订单明细!$I:$I),2)) | M19: =IF($B19="","",ROUND(N($K19)+N($L19),2)) | O19: =IF($B19="","",ROUND(N($N19)+SUMIFS(资金日记账!$J$4:$J$2503,资金日记账!$G$4:$G$2503,$B19,资金日记账!$F$4:$F$2503,"收款-项目")-SUMIFS(资金日记账!$K$4:$K$2503,资金日记账!$G$4:$G$2503,$B19,资金日记账!$F$4:$F$2503,"收款-项目"),2)) | P19: =IF($B19="","",ROUND($M19-$O19,2)) | Q19: =IF($B19="","",IF(AND($J19<>"",ROUND($P19,2)<=0),"已完工·已结清",IF($J19<>"","已完工·还有尾款",IF($I19<>"","已安装",IF($H19<>"","已制作",IF($G19<>"","设计完成","已下单")))))) | R19: 来源：16-饺子店 | S19: =IF($B19="","",IF(COUNTIF($B$4:$B$403,$B19)>1,"※项目名重复了",IF(AND($C19<>"",ISNA(MATCH($C19,客户表,0))),"※客户不在基础资料里",IF(AND($J19<>"",$F19<>"",$J19<$F19),"※完工日期早于下单日期",""))))
A20: =IF($B20="","","P"&TEXT(ROW()-3,"000")) | B20: 睿芯行 | C20: 睿芯行 | D20: 门头招牌 | F20: 46108 | K20: 39800 | L20: =IF($B20="","",ROUND(SUMIF(订单明细!$C:$C,$B20,订单明细!$I:$I),2)) | M20: =IF($B20="","",ROUND(N($K20)+N($L20),2)) | N20: 19800 | O20: =IF($B20="","",ROUND(N($N20)+SUMIFS(资金日记账!$J$4:$J$2503,资金日记账!$G$4:$G$2503,$B20,资金日记账!$F$4:$F$2503,"收款-项目")-SUMIFS(资金日记账!$K$4:$K$2503,资金日记账!$G$4:$G$2503,$B20,资金日记账!$F$4:$F$2503,"收款-项目"),2)) | P20: =IF($B20="","",ROUND($M20-$O20,2)) | Q20: =IF($B20="","",IF(AND($J20<>"",ROUND($P20,2)<=0),"已完工·已结清",IF($J20<>"","已完工·还有尾款",IF($I20<>"","已安装",IF($H20<>"","已制作",IF($G20<>"","设计完成","已下单")))))) | R20: 来源：17-睿芯行 | S20: =IF($B20="","",IF(COUNTIF($B$4:$B$403,$B20)>1,"※项目名重复了",IF(AND($C20<>"",ISNA(MATCH($C20,客户表,0))),"※客户不在基础资料里",IF(AND($J20<>"",$F20<>"",$J20<$F20),"※完工日期早于下单日期",""))))
A21: =IF($B21="","","P"&TEXT(ROW()-3,"000")) | B21: 东尼电子26.3-4 | C21: 东尼新能源 | D21: 门头招牌 | F21: 46087 | J21: 46106 | L21: =IF($B21="","",ROUND(SUMIF(订单明细!$C:$C,$B21,订单明细!$I:$I),2)) | M21: =IF($B21="","",ROUND(N($K21)+N($L21),2)) | O21: =IF($B21="","",ROUND(N($N21)+SUMIFS(资金日记账!$J$4:$J$2503,资金日记账!$G$4:$G$2503,$B21,资金日记账!$F$4:$F$2503,"收款-项目")-SUMIFS(资金日记账!$K$4:$K$2503,资金日记账!$G$4:$G$2503,$B21,资金日记账!$F$4:$F$2503,"收款-项目"),2)) | P21: =IF($B21="","",ROUND($M21-$O21,2)) | Q21: =IF($B21="","",IF(AND($J21<>"",ROUND($P21,2)<=0),"已完工·已结清",IF($J21<>"","已完工·还有尾款",IF($I21<>"","已安装",IF($H21<>"","已制作",IF($G21<>"","设计完成","已下单")))))) | R21: 原「东尼电子」制作清单 | S21: =IF($B21="","",IF(COUNTIF($B$4:$B$403,$B21)>1,"※项目名重复了",IF(AND($C21<>"",ISNA(MATCH($C21,客户表,0))),"※客户不在基础资料里",IF(AND($J21<>"",$F21<>"",$J21<$F21),"※完工日期早于下单日期",""))))
A22: =IF($B22="","","P"&TEXT(ROW()-3,"000")) | B22: 东尼电子26.5 | C22: 东尼新能源 | D22: 门头招牌 | F22: 46148 | J22: 46169 | L22: =IF($B22="","",ROUND(SUMIF(订单明细!$C:$C,$B22,订单明细!$I:$I),2)) | M22: =IF($B22="","",ROUND(N($K22)+N($L22),2)) | O22: =IF($B22="","",ROUND(N($N22)+SUMIFS(资金日记账!$J$4:$J$2503,资金日记账!$G$4:$G$2503,$B22,资金日记账!$F$4:$F$2503,"收款-项目")-SUMIFS(资金日记账!$K$4:$K$2503,资金日记账!$G$4:$G$2503,$B22,资金日记账!$F$4:$F$2503,"收款-项目"),2)) | P22: =IF($B22="","",ROUND($M22-$O22,2)) | Q22: =IF($B22="","",IF(AND($J22<>"",ROUND($P22,2)<=0),"已完工·已结清",IF($J22<>"","已完工·还有尾款",IF($I22<>"","已安装",IF($H22<>"","已制作",IF($G22<>"","设计完成","已下单")))))) | R22: 原「Sheet1」制作清单 | S22: =IF($B22="","",IF(COUNTIF($B$4:$B$403,$B22)>1,"※项目名重复了",IF(AND($C22<>"",ISNA(MATCH($C22,客户表,0))),"※客户不在基础资料里",IF(AND($J22<>"",$F22<>"",$J22<$F22),"※完工日期早于下单日期",""))))
A23: =IF($B23="","","P"&TEXT(ROW()-3,"000")) | B23: 盛昊篷车 | C23: 盛昊篷车 | D23: 门头招牌 | F23: 46079 | L23: =IF($B23="","",ROUND(SUMIF(订单明细!$C:$C,$B23,订单明细!$I:$I),2)) | M23: =IF($B23="","",ROUND(N($K23)+N($L23),2)) | O23: =IF($B23="","",ROUND(N($N23)+SUMIFS(资金日记账!$J$4:$J$2503,资金日记账!$G$4:$G$2503,$B23,资金日记账!$F$4:$F$2503,"收款-项目")-SUMIFS(资金日记账!$K$4:$K$2503,资金日记账!$G$4:$G$2503,$B23,资金日记账!$F$4:$F$2503,"收款-项目"),2)) | P23: =IF($B23="","",ROUND($M23-$O23,2)) | Q23: =IF($B23="","",IF(AND($J23<>"",ROUND($P23,2)<=0),"已完工·已结清",IF($J23<>"","已完工·还有尾款",IF($I23<>"","已安装",IF($H23<>"","已制作",IF($G23<>"","设计完成","已下单")))))) | S23: =IF($B23="","",IF(COUNTIF($B$4:$B$403,$B23)>1,"※项目名重复了",IF(AND($C23<>"",ISNA(MATCH($C23,客户表,0))),"※客户不在基础资料里",IF(AND($J23<>"",$F23<>"",$J23<$F23),"※完工日期早于下单日期",""))))
A24: =IF($B24="","","P"&TEXT(ROW()-3,"000")) | B24: 付炳秀配送 | C24: 付炳秀配送 | D24: 门头招牌 | F24: 46080 | L24: =IF($B24="","",ROUND(SUMIF(订单明细!$C:$C,$B24,订单明细!$I:$I),2)) | M24: =IF($B24="","",ROUND(N($K24)+N($L24),2)) | O24: =IF($B24="","",ROUND(N($N24)+SUMIFS(资金日记账!$J$4:$J$2503,资金日记账!$G$4:$G$2503,$B24,资金日记账!$F$4:$F$2503,"收款-项目")-SUMIFS(资金日记账!$K$4:$K$2503,资金日记账!$G$4:$G$2503,$B24,资金日记账!$F$4:$F$2503,"收款-项目"),2)) | P24: =IF($B24="","",ROUND($M24-$O24,2)) | Q24: =IF($B24="","",IF(AND($J24<>"",ROUND($P24,2)<=0),"已完工·已结清",IF($J24<>"","已完工·还有尾款",IF($I24<>"","已安装",IF($H24<>"","已制作",IF($G24<>"","设计完成","已下单")))))) | S24: =IF($B24="","",IF(COUNTIF($B$4:$B$403,$B24)>1,"※项目名重复了",IF(AND($C24<>"",ISNA(MATCH($C24,客户表,0))),"※客户不在基础资料里",IF(AND($J24<>"",$F24<>"",$J24<$F24),"※完工日期早于下单日期",""))))
A25: =IF($B25="","","P"&TEXT(ROW()-3,"000")) | B25: 万达kvv | C25: 万达kvv | D25: 门头招牌 | F25: 46083 | L25: =IF($B25="","",ROUND(SUMIF(订单明细!$C:$C,$B25,订单明细!$I:$I),2)) | M25: =IF($B25="","",ROUND(N($K25)+N($L25),2)) | O25: =IF($B25="","",ROUND(N($N25)+SUMIFS(资金日记账!$J$4:$J$2503,资金日记账!$G$4:$G$2503,$B25,资金日记账!$F$4:$F$2503,"收款-项目")-SUMIFS(资金日记账!$K$4:$K$2503,资金日记账!$G$4:$G$2503,$B25,资金日记账!$F$4:$F$2503,"收款-项目"),2)) | P25: =IF($B25="","",ROUND($M25-$O25,2)) | Q25: =IF($B25="","",IF(AND($J25<>"",ROUND($P25,2)<=0),"已完工·已结清",IF($J25<>"","已完工·还有尾款",IF($I25<>"","已安装",IF($H25<>"","已制作",IF($G25<>"","设计完成","已下单")))))) | S25: =IF($B25="","",IF(COUNTIF($B$4:$B$403,$B25)>1,"※项目名重复了",IF(AND($C25<>"",ISNA(MATCH($C25,客户表,0))),"※客户不在基础资料里",IF(AND($J25<>"",$F25<>"",$J25<$F25),"※完工日期早于下单日期",""))))
A26: =IF($B26="","","P"&TEXT(ROW()-3,"000")) | B26: 织里店 | C26: 织里店 | D26: 门头招牌 | F26: 46084 | L26: =IF($B26="","",ROUND(SUMIF(订单明细!$C:$C,$B26,订单明细!$I:$I),2)) | M26: =IF($B26="","",ROUND(N($K26)+N($L26),2)) | O26: =IF($B26="","",ROUND(N($N26)+SUMIFS(资金日记账!$J$4:$J$2503,资金日记账!$G$4:$G$2503,$B26,资金日记账!$F$4:$F$2503,"收款-项目")-SUMIFS(资金日记账!$K$4:$K$2503,资金日记账!$G$4:$G$2503,$B26,资金日记账!$F$4:$F$2503,"收款-项目"),2)) | P26: =IF($B26="","",ROUND($M26-$O26,2)) | Q26: =IF($B26="","",IF(AND($J26<>"",ROUND($P26,2)<=0),"已完工·已结清",IF($J26<>"","已完工·还有尾款",IF($I26<>"","已安装",IF($H26<>"","已制作",IF($G26<>"","设计完成","已下单")))))) | S26: =IF($B26="","",IF(COUNTIF($B$4:$B$403,$B26)>1,"※项目名重复了",IF(AND($C26<>"",ISNA(MATCH($C26,客户表,0))),"※客户不在基础资料里",IF(AND($J26<>"",$F26<>"",$J26<$F26),"※完工日期早于下单日期",""))))
A27: =IF($B27="","","P"&TEXT(ROW()-3,"000")) | B27: 高恒荣熟食店 | C27: 高恒荣熟食店 | D27: 门头招牌 | F27: 46084 | L27: =IF($B27="","",ROUND(SUMIF(订单明细!$C:$C,$B27,订单明细!$I:$I),2)) | M27: =IF($B27="","",ROUND(N($K27)+N($L27),2)) | O27: =IF($B27="","",ROUND(N($N27)+SUMIFS(资金日记账!$J$4:$J$2503,资金日记账!$G$4:$G$2503,$B27,资金日记账!$F$4:$F$2503,"收款-项目")-SUMIFS(资金日记账!$K$4:$K$2503,资金日记账!$G$4:$G$2503,$B27,资金日记账!$F$4:$F$2503,"收款-项目"),2)) | P27: =IF($B27="","",ROUND($M27-$O27,2)) | Q27: =IF($B27="","",IF(AND($J27<>"",ROUND($P27,2)<=0),"已完工·已结清",IF($J27<>"","已完工·还有尾款",IF($I27<>"","已安装",IF($H27<>"","已制作",IF($G27<>"","设计完成","已下单")))))) | S27: =IF($B27="","",IF(COUNTIF($B$4:$B$403,$B27)>1,"※项目名重复了",IF(AND($C27<>"",ISNA(MATCH($C27,客户表,0))),"※客户不在基础资料里",IF(AND($J27<>"",$F27<>"",$J27<$F27),"※完工日期早于下单日期",""))))
A28: =IF($B28="","","P"&TEXT(ROW()-3,"000")) | B28: 卓越桌球 | C28: 卓越桌球 | D28: 门头招牌 | F28: 46085 | L28: =IF($B28="","",ROUND(SUMIF(订单明细!$C:$C,$B28,订单明细!$I:$I),2)) | M28: =IF($B28="","",ROUND(N($K28)+N($L28),2)) | O28: =IF($B28="","",ROUND(N($N28)+SUMIFS(资金日记账!$J$4:$J$2503,资金日记账!$G$4:$G$2503,$B28,资金日记账!$F$4:$F$2503,"收款-项目")-SUMIFS(资金日记账!$K$4:$K$2503,资金日记账!$G$4:$G$2503,$B28,资金日记账!$F$4:$F$2503,"收款-项目"),2)) | P28: =IF($B28="","",ROUND($M28-$O28,2)) | Q28: =IF($B28="","",IF(AND($J28<>"",ROUND($P28,2)<=0),"已完工·已结清",IF($J28<>"","已完工·还有尾款",IF($I28<>"","已安装",IF($H28<>"","已制作",IF($G28<>"","设计完成","已下单")))))) | S28: =IF($B28="","",IF(COUNTIF($B$4:$B$403,$B28)>1,"※项目名重复了",IF(AND($C28<>"",ISNA(MATCH($C28,客户表,0))),"※客户不在基础资料里",IF(AND($J28<>"",$F28<>"",$J28<$F28),"※完工日期早于下单日期",""))))
A29: =IF($B29="","","P"&TEXT(ROW()-3,"000")) | B29: 东尼电子 | C29: 东尼电子 | D29: 门头招牌 | F29: 46085 | L29: =IF($B29="","",ROUND(SUMIF(订单明细!$C:$C,$B29,订单明细!$I:$I),2)) | M29: =IF($B29="","",ROUND(N($K29)+N($L29),2)) | O29: =IF($B29="","",ROUND(N($N29)+SUMIFS(资金日记账!$J$4:$J$2503,资金日记账!$G$4:$G$2503,$B29,资金日记账!$F$4:$F$2503,"收款-项目")-SUMIFS(资金日记账!$K$4:$K$2503,资金日记账!$G$4:$G$2503,$B29,资金日记账!$F$4:$F$2503,"收款-项目"),2)) | P29: =IF($B29="","",ROUND($M29-$O29,2)) | Q29: =IF($B29="","",IF(AND($J29<>"",ROUND($P29,2)<=0),"已完工·已结清",IF($J29<>"","已完工·还有尾款",IF($I29<>"","已安装",IF($H29<>"","已制作",IF($G29<>"","设计完成","已下单")))))) | S29: =IF($B29="","",IF(COUNTIF($B$4:$B$403,$B29)>1,"※项目名重复了",IF(AND($C29<>"",ISNA(MATCH($C29,客户表,0))),"※客户不在基础资料里",IF(AND($J29<>"",$F29<>"",$J29<$F29),"※完工日期早于下单日期",""))))
A30: =IF($B30="","","P"&TEXT(ROW()-3,"000")) | B30: 犇腾牛排 | C30: 犇腾牛排 | D30: 门头招牌 | F30: 46088 | L30: =IF($B30="","",ROUND(SUMIF(订单明细!$C:$C,$B30,订单明细!$I:$I),2)) | M30: =IF($B30="","",ROUND(N($K30)+N($L30),2)) | O30: =IF($B30="","",ROUND(N($N30)+SUMIFS(资金日记账!$J$4:$J$2503,资金日记账!$G$4:$G$2503,$B30,资金日记账!$F$4:$F$2503,"收款-项目")-SUMIFS(资金日记账!$K$4:$K$2503,资金日记账!$G$4:$G$2503,$B30,资金日记账!$F$4:$F$2503,"收款-项目"),2)) | P30: =IF($B30="","",ROUND($M30-$O30,2)) | Q30: =IF($B30="","",IF(AND($J30<>"",ROUND($P30,2)<=0),"已完工·已结清",IF($J30<>"","已完工·还有尾款",IF($I30<>"","已安装",IF($H30<>"","已制作",IF($G30<>"","设计完成","已下单")))))) | S30: =IF($B30="","",IF(COUNTIF($B$4:$B$403,$B30)>1,"※项目名重复了",IF(AND($C30<>"",ISNA(MATCH($C30,客户表,0))),"※客户不在基础资料里",IF(AND($J30<>"",$F30<>"",$J30<$F30),"※完工日期早于下单日期",""))))
A31: =IF($B31="","","P"&TEXT(ROW()-3,"000")) | B31: 校服基地 | C31: 校服基地 | D31: 门头招牌 | F31: 46090 | L31: =IF($B31="","",ROUND(SUMIF(订单明细!$C:$C,$B31,订单明细!$I:$I),2)) | M31: =IF($B31="","",ROUND(N($K31)+N($L31),2)) | O31: =IF($B31="","",ROUND(N($N31)+SUMIFS(资金日记账!$J$4:$J$2503,资金日记账!$G$4:$G$2503,$B31,资金日记账!$F$4:$F$2503,"收款-项目")-SUMIFS(资金日记账!$K$4:$K$2503,资金日记账!$G$4:$G$2503,$B31,资金日记账!$F$4:$F$2503,"收款-项目"),2)) | P31: =IF($B31="","",ROUND($M31-$O31,2)) | Q31: =IF($B31="","",IF(AND($J31<>"",ROUND($P31,2)<=0),"已完工·已结清",IF($J31<>"","已完工·还有尾款",IF($I31<>"","已安装",IF($H31<>"","已制作",IF($G31<>"","设计完成","已下单")))))) | S31: =IF($B31="","",IF(COUNTIF($B$4:$B$403,$B31)>1,"※项目名重复了",IF(AND($C31<>"",ISNA(MATCH($C31,客户表,0))),"※客户不在基础资料里",IF(AND($J31<>"",$F31<>"",$J31<$F31),"※完工日期早于下单日期",""))))
A32: =IF($B32="","","P"&TEXT(ROW()-3,"000")) | B32: 德清钟管菜市场 | C32: 德清钟管菜市场 | D32: 门头招牌 | F32: 46090 | L32: =IF($B32="","",ROUND(SUMIF(订单明细!$C:$C,$B32,订单明细!$I:$I),2)) | M32: =IF($B32="","",ROUND(N($K32)+N($L32),2)) | O32: =IF($B32="","",ROUND(N($N32)+SUMIFS(资金日记账!$J$4:$J$2503,资金日记账!$G$4:$G$2503,$B32,资金日记账!$F$4:$F$2503,"收款-项目")-SUMIFS(资金日记账!$K$4:$K$2503,资金日记账!$G$4:$G$2503,$B32,资金日记账!$F$4:$F$2503,"收款-项目"),2)) | P32: =IF($B32="","",ROUND($M32-$O32,2)) | Q32: =IF($B32="","",IF(AND($J32<>"",ROUND($P32,2)<=0),"已完工·已结清",IF($J32<>"","已完工·还有尾款",IF($I32<>"","已安装",IF($H32<>"","已制作",IF($G32<>"","设计完成","已下单")))))) | S32: =IF($B32="","",IF(COUNTIF($B$4:$B$403,$B32)>1,"※项目名重复了",IF(AND($C32<>"",ISNA(MATCH($C32,客户表,0))),"※客户不在基础资料里",IF(AND($J32<>"",$F32<>"",$J32<$F32),"※完工日期早于下单日期",""))))
A33: =IF($B33="","","P"&TEXT(ROW()-3,"000")) | B33: 中交 | C33: 中交 | D33: 门头招牌 | F33: 46092 | L33: =IF($B33="","",ROUND(SUMIF(订单明细!$C:$C,$B33,订单明细!$I:$I),2)) | M33: =IF($B33="","",ROUND(N($K33)+N($L33),2)) | O33: =IF($B33="","",ROUND(N($N33)+SUMIFS(资金日记账!$J$4:$J$2503,资金日记账!$G$4:$G$2503,$B33,资金日记账!$F$4:$F$2503,"收款-项目")-SUMIFS(资金日记账!$K$4:$K$2503,资金日记账!$G$4:$G$2503,$B33,资金日记账!$F$4:$F$2503,"收款-项目"),2)) | P33: =IF($B33="","",ROUND($M33-$O33,2)) | Q33: =IF($B33="","",IF(AND($J33<>"",ROUND($P33,2)<=0),"已完工·已结清",IF($J33<>"","已完工·还有尾款",IF($I33<>"","已安装",IF($H33<>"","已制作",IF($G33<>"","设计完成","已下单")))))) | S33: =IF($B33="","",IF(COUNTIF($B$4:$B$403,$B33)>1,"※项目名重复了",IF(AND($C33<>"",ISNA(MATCH($C33,客户表,0))),"※客户不在基础资料里",IF(AND($J33<>"",$F33<>"",$J33<$F33),"※完工日期早于下单日期",""))))
A34: =IF($B34="","","P"&TEXT(ROW()-3,"000")) | B34: vip宠物乐园 | C34: vip宠物乐园 | D34: 门头招牌 | F34: 46093 | L34: =IF($B34="","",ROUND(SUMIF(订单明细!$C:$C,$B34,订单明细!$I:$I),2)) | M34: =IF($B34="","",ROUND(N($K34)+N($L34),2)) | O34: =IF($B34="","",ROUND(N($N34)+SUMIFS(资金日记账!$J$4:$J$2503,资金日记账!$G$4:$G$2503,$B34,资金日记账!$F$4:$F$2503,"收款-项目")-SUMIFS(资金日记账!$K$4:$K$2503,资金日记账!$G$4:$G$2503,$B34,资金日记账!$F$4:$F$2503,"收款-项目"),2)) | P34: =IF($B34="","",ROUND($M34-$O34,2)) | Q34: =IF($B34="","",IF(AND($J34<>"",ROUND($P34,2)<=0),"已完工·已结清",IF($J34<>"","已完工·还有尾款",IF($I34<>"","已安装",IF($H34<>"","已制作",IF($G34<>"","设计完成","已下单")))))) | S34: =IF($B34="","",IF(COUNTIF($B$4:$B$403,$B34)>1,"※项目名重复了",IF(AND($C34<>"",ISNA(MATCH($C34,客户表,0))),"※客户不在基础资料里",IF(AND($J34<>"",$F34<>"",$J34<$F34),"※完工日期早于下单日期",""))))
... A88: =IF($B88="","","P"&TEXT(ROW()-3,"000")) | B88: nook咖啡店 | C88: nook咖啡店 | D88: 门头招牌 | F88: 46186 | L88: =IF($B88="","",ROUND(SUMIF(订单明细!$C:$C,$B88,订单明细!$I:$I),2)) | M88: =IF($B88="","",ROUND(N($K88)+N($L88),2)) | O88: =IF($B88="","",ROUND(N($N88)+SUMIFS(资金日记账!$J$4:$J$2503,资金日记账!$G$4:$G$2503,$B88,资金日记账!$F$4:$F$2503,"收款-项目")-SUMIFS(资金日记账!$K$4:$K$2503,资金日记账!$G$4:$G$2503,$B88,资金日记账!$F$4:$F$2503,"收款-项目"),2)) | P88: =IF($B88="","",ROUND($M88-$O88,2)) | Q88: =IF($B88="","",IF(AND($J88<>"",ROUND($P88,2)<=0),"已完工·已结清",IF($J88<>"","已完工·还有尾款",IF($I88<>"","已安装",IF($H88<>"","已制作",IF($G88<>"","设计完成","已下单")))))) | S88: =IF($B88="","",IF(COUNTIF($B$4:$B$403,$B88)>1,"※项目名重复了",IF(AND($C88<>"",ISNA(MATCH($C88,客户表,0))),"※客户不在基础资料里",IF(AND($J88<>"",$F88<>"",$J88<$F88),"※完工日期早于下单日期",""))))
A89: =IF($B89="","","P"&TEXT(ROW()-3,"000")) | L89: =IF($B89="","",ROUND(SUMIF(订单明细!$C:$C,$B89,订单明细!$I:$I),2)) | M89: =IF($B89="","",ROUND(N($K89)+N($L89),2)) | O89: =IF($B89="","",ROUND(N($N89)+SUMIFS(资金日记账!$J$4:$J$2503,资金日记账!$G$4:$G$2503,$B89,资金日记账!$F$4:$F$2503,"收款-项目")-SUMIFS(资金日记账!$K$4:$K$2503,资金日记账!$G$4:$G$2503,$B89,资金日记账!$F$4:$F$2503,"收款-项目"),2)) | P89: =IF($B89="","",ROUND($M89-$O89,2)) | Q89: =IF($B89="","",IF(AND($J89<>"",ROUND($P89,2)<=0),"已完工·已结清",IF($J89<>"","已完工·还有尾款",IF($I89<>"","已安装",IF($H89<>"","已制作",IF($G89<>"","设计完成","已下单")))))) | S89: =IF($B89="","",IF(COUNTIF($B$4:$B$403,$B89)>1,"※项目名重复了",IF(AND($C89<>"",ISNA(MATCH($C89,客户表,0))),"※客户不在基础资料里",IF(AND($J89<>"",$F89<>"",$J89<$F89),"※完工日期早于下单日期",""))))
A90: =IF($B90="","","P"&TEXT(ROW()-3,"000")) | L90: =IF($B90="","",ROUND(SUMIF(订单明细!$C:$C,$B90,订单明细!$I:$I),2)) | M90: =IF($B90="","",ROUND(N($K90)+N($L90),2)) | O90: =IF($B90="","",ROUND(N($N90)+SUMIFS(资金日记账!$J$4:$J$2503,资金日记账!$G$4:$G$2503,$B90,资金日记账!$F$4:$F$2503,"收款-项目")-SUMIFS(资金日记账!$K$4:$K$2503,资金日记账!$G$4:$G$2503,$B90,资金日记账!$F$4:$F$2503,"收款-项目"),2)) | P90: =IF($B90="","",ROUND($M90-$O90,2)) | Q90: =IF($B90="","",IF(AND($J90<>"",ROUND($P90,2)<=0),"已完工·已结清",IF($J90<>"","已完工·还有尾款",IF($I90<>"","已安装",IF($H90<>"","已制作",IF($G90<>"","设计完成","已下单")))))) | S90: =IF($B90="","",IF(COUNTIF($B$4:$B$403,$B90)>1,"※项目名重复了",IF(AND($C90<>"",ISNA(MATCH($C90,客户表,0))),"※客户不在基础资料里",IF(AND($J90<>"",$F90<>"",$J90<$F90),"※完工日期早于下单日期",""))))
A91: =IF($B91="","","P"&TEXT(ROW()-3,"000")) | L91: =IF($B91="","",ROUND(SUMIF(订单明细!$C:$C,$B91,订单明细!$I:$I),2)) | M91: =IF($B91="","",ROUND(N($K91)+N($L91),2)) | O91: =IF($B91="","",ROUND(N($N91)+SUMIFS(资金日记账!$J$4:$J$2503,资金日记账!$G$4:$G$2503,$B91,资金日记账!$F$4:$F$2503,"收款-项目")-SUMIFS(资金日记账!$K$4:$K$2503,资金日记账!$G$4:$G$2503,$B91,资金日记账!$F$4:$F$2503,"收款-项目"),2)) | P91: =IF($B91="","",ROUND($M91-$O91,2)) | Q91: =IF($B91="","",IF(AND($J91<>"",ROUND($P91,2)<=0),"已完工·已结清",IF($J91<>"","已完工·还有尾款",IF($I91<>"","已安装",IF($H91<>"","已制作",IF($G91<>"","设计完成","已下单")))))) | S91: =IF($B91="","",IF(COUNTIF($B$4:$B$403,$B91)>1,"※项目名重复了",IF(AND($C91<>"",ISNA(MATCH($C91,客户表,0))),"※客户不在基础资料里",IF(AND($J91<>"",$F91<>"",$J91<$F91),"※完工日期早于下单日期",""))))
A92: =IF($B92="","","P"&TEXT(ROW()-3,"000")) | L92: =IF($B92="","",ROUND(SUMIF(订单明细!$C:$C,$B92,订单明细!$I:$I),2)) | M92: =IF($B92="","",ROUND(N($K92)+N($L92),2)) | O92: =IF($B92="","",ROUND(N($N92)+SUMIFS(资金日记账!$J$4:$J$2503,资金日记账!$G$4:$G$2503,$B92,资金日记账!$F$4:$F$2503,"收款-项目")-SUMIFS(资金日记账!$K$4:$K$2503,资金日记账!$G$4:$G$2503,$B92,资金日记账!$F$4:$F$2503,"收款-项目"),2)) | P92: =IF($B92="","",ROUND($M92-$O92,2)) | Q92: =IF($B92="","",IF(AND($J92<>"",ROUND($P92,2)<=0),"已完工·已结清",IF($J92<>"","已完工·还有尾款",IF($I92<>"","已安装",IF($H92<>"","已制作",IF($G92<>"","设计完成","已下单")))))) | S92: =IF($B92="","",IF(COUNTIF($B$4:$B$403,$B92)>1,"※项目名重复了",IF(AND($C92<>"",ISNA(MATCH($C92,客户表,0))),"※客户不在基础资料里",IF(AND($J92<>"",$F92<>"",$J92<$F92),"※完工日期早于下单日期",""))))
A93: =IF($B93="","","P"&TEXT(ROW()-3,"000")) | L93: =IF($B93="","",ROUND(SUMIF(订单明细!$C:$C,$B93,订单明细!$I:$I),2)) | M93: =IF($B93="","",ROUND(N($K93)+N($L93),2)) | O93: =IF($B93="","",ROUND(N($N93)+SUMIFS(资金日记账!$J$4:$J$2503,资金日记账!$G$4:$G$2503,$B93,资金日记账!$F$4:$F$2503,"收款-项目")-SUMIFS(资金日记账!$K$4:$K$2503,资金日记账!$G$4:$G$2503,$B93,资金日记账!$F$4:$F$2503,"收款-项目"),2)) | P93: =IF($B93="","",ROUND($M93-$O93,2)) | Q93: =IF($B93="","",IF(AND($J93<>"",ROUND($P93,2)<=0),"已完工·已结清",IF($J93<>"","已完工·还有尾款",IF($I93<>"","已安装",IF($H93<>"","已制作",IF($G93<>"","设计完成","已下单")))))) | S93: =IF($B93="","",IF(COUNTIF($B$4:$B$403,$B93)>1,"※项目名重复了",IF(AND($C93<>"",ISNA(MATCH($C93,客户表,0))),"※客户不在基础资料里",IF(AND($J93<>"",$F93<>"",$J93<$F93),"※完工日期早于下单日期",""))))
...

Sheet 订单明细
A1: 订单明细 · 按件报价的客户用（下单 / 设计岗位填）
A2: 一次几十个标牌那种客户在这里逐项登记，金额会自动加进【项目台账】的「订单明细额」。整单包死的项目不用填这张表。
A3: 序号 | B3: 下单日期 ★ | C3: 项目名称 ★ | D3: 品名 ★ | E3: 规格 | F3: 单位 | G3: 数量 | H3: 单价 | I3: 金额 | J3: 客户 | K3: 备注
A4: =IF($C4="","",ROW()-3) | B4: 46087 | C4: 东尼电子26.3-4 | D4: 作业表单放置处 | E4: 15*3cm | F4: 张 | G4: 50 | H4: 1 | I4: =IF($C4="","",ROUND(IF($G4="",1,$G4)*N($H4),2)) | J4: =IF($C4="","",IFERROR(VLOOKUP($C4,项目台账!$B:$C,2,0),"※项目不在项目台账里"))
A5: =IF($C5="","",ROW()-3) | B5: 46087 | C5: 东尼电子26.3-4 | D5: 准文件放置处 | E5: 15*3cm | F5: 张 | G5: 50 | H5: 1 | I5: =IF($C5="","",ROUND(IF($G5="",1,$G5)*N($H5),2)) | J5: =IF($C5="","",IFERROR(VLOOKUP($C5,项目台账!$B:$C,2,0),"※项目不在项目台账里"))
A6: =IF($C6="","",ROW()-3) | B6: 46087 | C6: 东尼电子26.3-4 | D6: 标识牌（物料专用通道） | E6: 40*80 | F6: 块 | G6: 4 | H6: 40 | I6: =IF($C6="","",ROUND(IF($G6="",1,$G6)*N($H6),2)) | J6: =IF($C6="","",IFERROR(VLOOKUP($C6,项目台账!$B:$C,2,0),"※项目不在项目台账里"))
A7: =IF($C7="","",ROW()-3) | B7: 46095 | C7: 东尼电子26.3-4 | D7: 玻璃磨砂膜 | E7: 指定尺寸 | F7: 平方 | G7: 51.705 | H7: 35 | I7: =IF($C7="","",ROUND(IF($G7="",1,$G7)*N($H7),2)) | J7: =IF($C7="","",IFERROR(VLOOKUP($C7,项目台账!$B:$C,2,0),"※项目不在项目台账里"))
A8: =IF($C8="","",ROW()-3) | B8: 46095 | C8: 东尼电子26.3-4 | D8: 安装费 | E8: - | F8: 次 | G8: 1 | H8: 600 | I8: =IF($C8="","",ROUND(IF($G8="",1,$G8)*N($H8),2)) | J8: =IF($C8="","",IFERROR(VLOOKUP($C8,项目台账!$B:$C,2,0),"※项目不在项目台账里"))
A9: =IF($C9="","",ROW()-3) | B9: 46095 | C9: 东尼电子26.3-4 | D9: 告示牌（道路施工） | E9: 40cm*80cm | F9: 块 | G9: 2 | H9: 20 | I9: =IF($C9="","",ROUND(IF($G9="",1,$G9)*N($H9),2)) | J9: =IF($C9="","",IFERROR(VLOOKUP($C9,项目台账!$B:$C,2,0),"※项目不在项目台账里"))
A10: =IF($C10="","",ROW()-3) | B10: 46099 | C10: 东尼电子26.3-4 | D10: 斜纹贴（点检表放置处 | E10: :20*5cm | F10: 张 | G10: 100 | H10: 2 | I10: =IF($C10="","",ROUND(IF($G10="",1,$G10)*N($H10),2)) | J10: =IF($C10="","",IFERROR(VLOOKUP($C10,项目台账!$B:$C,2,0),"※项目不在项目台账里"))
A11: =IF($C11="","",ROW()-3) | B11: 46099 | C11: 东尼电子26.3-4 | D11: 斜纹贴（SOP作业指导书放置处） | E11: 20*5cm | F11: 张 | G11: 80 | H11: 2 | I11: =IF($C11="","",ROUND(IF($G11="",1,$G11)*N($H11),2)) | J11: =IF($C11="","",IFERROR(VLOOKUP($C11,项目台账!$B:$C,2,0),"※项目不在项目台账里"))
A12: =IF($C12="","",ROW()-3) | B12: 46104 | C12: 东尼电子26.3-4 | D12: 斜纹贴（点检表放置处） | E12: 20*3cm | F12: 张 | G12: 100 | H12: 2 | I12: =IF($C12="","",ROUND(IF($G12="",1,$G12)*N($H12),2)) | J12: =IF($C12="","",IFERROR(VLOOKUP($C12,项目台账!$B:$C,2,0),"※项目不在项目台账里"))
A13: =IF($C13="","",ROW()-3) | B13: 46104 | C13: 东尼电子26.3-4 | D13: 斜纹贴（SOP作业指导书放置处） | E13: 20*3cm | F13: 张 | G13: 100 | H13: 2 | I13: =IF($C13="","",ROUND(IF($G13="",1,$G13)*N($H13),2)) | J13: =IF($C13="","",IFERROR(VLOOKUP($C13,项目台账!$B:$C,2,0),"※项目不在项目台账里"))
A14: =IF($C14="","",ROW()-3) | B14: 46104 | C14: 东尼电子26.3-4 | D14: 当心夹手 | E14: 10*6cm | F14: 张 | G14: 50 | H14: 2 | I14: =IF($C14="","",ROUND(IF($G14="",1,$G14)*N($H14),2)) | J14: =IF($C14="","",IFERROR(VLOOKUP($C14,项目台账!$B:$C,2,0),"※项目不在项目台账里"))
A15: =IF($C15="","",ROW()-3) | B15: 46104 | C15: 东尼电子26.3-4 | D15: 机器运转时禁止开门 | E15: 10*6cm | F15: 张 | G15: 50 | H15: 2 | I15: =IF($C15="","",ROUND(IF($G15="",1,$G15)*N($H15),2)) | J15: =IF($C15="","",IFERROR(VLOOKUP($C15,项目台账!$B:$C,2,0),"※项目不在项目台账里"))
... A38: =IF($C38="","",ROW()-3) | B38: 46104 | C38: 东尼电子26.3-4 | D38: 注意压接面向 | E38: 10*6cm | F38: 张 | G38: 20 | H38: 2 | I38: =IF($C38="","",ROUND(IF($G38="",1,$G38)*N($H38),2)) | J38: =IF($C38="","",IFERROR(VLOOKUP($C38,项目台账!$B:$C,2,0),"※项目不在项目台账里"))
A39: =IF($C39="","",ROW()-3) | B39: 46106 | C39: 东尼电子26.3-4 | D39: 号码牌 | E39: - | F39: 张 | G39: 190 | H39: 1.85 | I39: =IF($C39="","",ROUND(IF($G39="",1,$G39)*N($H39),2)) | J39: =IF($C39="","",IFERROR(VLOOKUP($C39,项目台账!$B:$C,2,0),"※项目不在项目台账里")) | K39: 待打拔产品放置处*30 待专检产品放置处*30 打拔毕产品放置处*30 待包装产品放置处*30
A40: =IF($C40="","",ROW()-3) | B40: 46106 | C40: 东尼电子26.3-4 | D40: 斜纹贴纸（待专检产品放置处、 | E40: 28*5cm | F40: 张 | G40: 120 | H40: 2 | I40: =IF($C40="","",ROUND(IF($G40="",1,$G40)*N($H40),2)) | J40: =IF($C40="","",IFERROR(VLOOKUP($C40,项目台账!$B:$C,2,0),"※项目不在项目台账里"))
A41: =IF($C41="","",ROW()-3) | B41: 46106 | C41: 东尼电子26.3-4 | D41: 标识牌（阀体保养室） | E41: 42*30cm | F41: 块 | G41: 1 | H41: 20 | I41: =IF($C41="","",ROUND(IF($G41="",1,$G41)*N($H41),2)) | J41: =IF($C41="","",IFERROR(VLOOKUP($C41,项目台账!$B:$C,2,0),"※项目不在项目台账里"))
A42: =IF($C42="","",ROW()-3) | B42: 46148 | C42: 东尼电子26.5 | D42: 贴纸（宿舍值日表) | E42: A4户外防水贴纸 | F42: 张 | G42: 330 | H42: 3 | I42: =IF($C42="","",ROUND(IF($G42="",1,$G42)*N($H42),2)) | J42: =IF($C42="","",IFERROR(VLOOKUP($C42,项目台账!$B:$C,2,0),"※项目不在项目台账里"))
A43: =IF($C43="","",ROW()-3) | B43: 46148 | C43: 东尼电子26.5 | D43: 超透彩白彩 | E43: 高50CM 宽70CM | F43: 张 | G43: 2 | H43: 16 | I43: =IF($C43="","",ROUND(IF($G43="",1,$G43)*N($H43),2)) | J43: =IF($C43="","",IFERROR(VLOOKUP($C43,项目台账!$B:$C,2,0),"※项目不在项目台账里"))
A44: =IF($C44="","",ROW()-3) | B44: 46150 | C44: 东尼电子26.5 | D44: 标识牌（固定车位、请勿占用） | E44: 不锈钢 10*70 | F44: 块 | G44: 17 | I44: =IF($C44="","",ROUND(IF($G44="",1,$G44)*N($H44),2)) | J44: =IF($C44="","",IFERROR(VLOOKUP($C44,项目台账!$B:$C,2,0),"※项目不在项目台账里"))
A45: =IF($C45="","",ROW()-3) | B45: 46150 | C45: 东尼电子26.5 | D45: 斜纹贴纸（通风口 禁止遮挡） | E45: 210*150mm | F45: 张 | G45: 50 | H45: 3 | I45: =IF($C45="","",ROUND(IF($G45="",1,$G45)*N($H45),2)) | J45: =IF($C45="","",IFERROR(VLOOKUP($C45,项目台账!$B:$C,2,0),"※项目不在项目台账里"))
A46: =IF($C46="","",ROW()-3) | B46: 46154 | C46: 东尼电子26.5 | D46: 标识牌（异常反馈机制） | E46: 29cmX5cm 1mm亚克力+背胶 | F46: 张 | G46: 30 | H46: 4.2 | I46: =IF($C46="","",ROUND(IF($G46="",1,$G46)*N($H46),2)) | J46: =IF($C46="","",IFERROR(VLOOKUP($C46,项目台账!$B:$C,2,0),"※项目不在项目台账里"))
A47: =IF($C47="","",ROW()-3) | B47: 46154 | C47: 东尼电子26.5 | D47: 标识牌（细心点检） | E47: :14cmX3cm 1mm亚克力+背胶 | F47: 张 | G47: 30 | H47: 1.5 | I47: =IF($C47="","",ROUND(IF($G47="",1,$G47)*N($H47),2)) | J47: =IF($C47="","",IFERROR(VLOOKUP($C47,项目台账!$B:$C,2,0),"※项目不在项目台账里"))
A48: =IF($C48="","",ROW()-3) | B48: 46154 | C48: 东尼电子26.5 | D48: 标识（卷帘门下严禁站人和堆物） | E48: 宽20cm*高80cm 2mm亚克力+背胶 | F48: 张 | G48: 3 | H48: 60 | I48: =IF($C48="","",ROUND(IF($G48="",1,$G48)*N($H48),2)) | J48: =IF($C48="","",IFERROR(VLOOKUP($C48,项目台账!$B:$C,2,0),"※项目不在项目台账里"))
A49: =IF($C49="","",ROW()-3) | B49: 46160 | C49: 东尼电子26.5 | D49: 设备编码标签 | E49: 65*30mm 2mm亚克力+背胶 | F49: 张 | G49: 6 | H49: 1.5 | I49: =IF($C49="","",ROUND(IF($G49="",1,$G49)*N($H49),2)) | J49: =IF($C49="","",IFERROR(VLOOKUP($C49,项目台账!$B:$C,2,0),"※项目不在项目台账里"))
A50: =IF($C50="","",ROW()-3) | B50: 46160 | C50: 东尼电子26.5 | D50: 设备验收合格标签 | E50: 75*23mm 2mm亚克力+背胶 | F50: 张 | G50: 6 | H50: 1.5 | I50: =IF($C50="","",ROUND(IF($G50="",1,$G50)*N($H50),2)) | J50: =IF($C50="","",IFERROR(VLOOKUP($C50,项目台账!$B:$C,2,0),"※项目不在项目台账里"))
A51: =IF($C51="","",ROW()-3) | B51: 46160 | C51: 东尼电子26.5 | D51: 背胶贴膜 | E51: 30*40cm | F51: 块 | G51: 12 | H51: 6 | I51: =IF($C51="","",ROUND(IF($G51="",1,$G51)*N($H51),2)) | J51: =IF($C51="","",IFERROR(VLOOKUP($C51,项目台账!$B:$C,2,0),"※项目不在项目台账里"))
A52: =IF($C52="","",ROW()-3) | B52: 46161 | C52: 东尼电子26.5 | D52: 标识牌（FPCA-课线边物料仓） | E52: 42*30cm | F52: 块 | G52: 1 | H52: 20 | I52: =IF($C52="","",ROUND(IF($G52="",1,$G52)*N($H52),2)) | J52: =IF($C52="","",IFERROR(VLOOKUP($C52,项目台账!$B:$C,2,0),"※项目不在项目台账里"))
A53: =IF($C53="","",ROW()-3) | B53: 46162 | C53: 东尼电子26.5 | D53: 标识牌（专注做事） | E53: 110X200cm 5mm雪弗板覆钢化膜 包安装 | F53: 块 | G53: 1 | H53: 540 | I53: =IF($C53="","",ROUND(IF($G53="",1,$G53)*N($H53),2)) | J53: =IF($C53="","",IFERROR(VLOOKUP($C53,项目台账!$B:$C,2,0),"※项目不在项目台账里"))
A54: =IF($C54="","",ROW()-3) | B54: 46163 | C54: 东尼电子26.5 | D54: 标识牌（连廊通行须知） | E54: 8mmpvc板 0.6*0.9m | F54: 块 | G54: 2 | H54: 60 | I54: =IF($C54="","",ROUND(IF($G54="",1,$G54)*N($H54),2)) | J54: =IF($C54="","",IFERROR(VLOOKUP($C54,项目台账!$B:$C,2,0),"※项目不在项目台账里"))
A55: =IF($C55="","",ROW()-3) | B55: 46167 | C55: 东尼电子26.5 | D55: 斜纹背胶贴（人行通道、推车通道） | E55: 239*30cm | F55: 张 | G55: 2 | H55: 20 | I55: =IF($C55="","",ROUND(IF($G55="",1,$G55)*N($H55),2)) | J55: =IF($C55="","",IFERROR(VLOOKUP($C55,项目台账!$B:$C,2,0),"※项目不在项目台账里"))
A56: =IF($C56="","",ROW()-3) | B56: 46169 | C56: 东尼电子26.5 | D56: 横幅 | E56: 220*50cm | F56: 条 | G56: 1 | H56: 15 | I56: =IF($C56="","",ROUND(IF($G56="",1,$G56)*N($H56),2)) | J56: =IF($C56="","",IFERROR(VLOOKUP($C56,项目台账!$B:$C,2,0),"※项目不在项目台账里"))
... A58: =IF($C58="","",ROW()-3) | B58: 46169 | C58: 东尼电子26.5 | D58: 斜纹背胶贴（人行通道、推车通道） | E58: 239*30cm | F58: 张 | G58: 2 | H58: 20 | I58: =IF($C58="","",ROUND(IF($G58="",1,$G58)*N($H58),2)) | J58: =IF($C58="","",IFERROR(VLOOKUP($C58,项目台账!$B:$C,2,0),"※项目不在项目台账里"))
A59: =IF($C59="","",ROW()-3) | I59: =IF($C59="","",ROUND(IF($G59="",1,$G59)*N($H59),2)) | J59: =IF($C59="","",IFERROR(VLOOKUP($C59,项目台账!$B:$C,2,0),"※项目不在项目台账里"))
A60: =IF($C60="","",ROW()-3) | I60: =IF($C60="","",ROUND(IF($G60="",1,$G60)*N($H60),2)) | J60: =IF($C60="","",IFERROR(VLOOKUP($C60,项目台账!$B:$C,2,0),"※项目不在项目台账里"))
A61: =IF($C61="","",ROW()-3) | I61: =IF($C61="","",ROUND(IF($G61="",1,$G61)*N($H61),2)) | J61: =IF($C61="","",IFERROR(VLOOKUP($C61,项目台账!$B:$C,2,0),"※项目不在项目台账里"))
A62: =IF($C62="","",ROW()-3) | I62: =IF($C62="","",ROUND(IF($G62="",1,$G62)*N($H62),2)) | J62: =IF($C62="","",IFERROR(VLOOKUP($C62,项目台账!$B:$C,2,0),"※项目不在项目台账里"))
A63: =IF($C63="","",ROW()-3) | I63: =IF($C63="","",ROUND(IF($G63="",1,$G63)*N($H63),2)) | J63: =IF($C63="","",IFERROR(VLOOKUP($C63,项目台账!$B:$C,2,0),"※项目不在项目台账里"))
...

Sheet 采购单
A1: 采购单 · 采购岗位填
A2: 买的每一笔材料都记一行。注意：登过这里的料，出纳付钱时费用类别要选『付供应商货款』，不然成本会算两遍。
A3: 序号 | B3: 采购日期 ★ | C3: 供应商 ★ | D3: 项目名称 ★ | E3: 材料类别 ★ | F3: 成本归属 | G3: 品名 ★ | H3: 规格 | I3: 单位 | J3: 数量 | K3: 单价 | L3: 金额 | M3: 备注 | N3: 核对
A4: =IF($D4="","",ROW()-3) | B4: 46043 | C4: 炳秀 | D4: 南浔美食城 | E4: 主材 | F4: =IF($D4="","",IFERROR(VLOOKUP($E4,材料归属,2,0),"※材料类别没选")) | G4: 7.5*7.5黑边灯箱型材 | I4: 米 | J4: 146 | K4: 10 | L4: =IF($D4="","",ROUND(IF($J4="",1,$J4)*N($K4),2)) | M4: 原表·主材 | N4: =IF($D4="","",IF(ISNA(MATCH($D4,项目名表,0)),"※项目不在项目台账里",IF($F4="※材料类别没选","※材料类别没选",IF(AND($C4<>"",ISNA(MATCH($C4,供应商表,0))),"※供应商不在基础资料里",""))))
A5: =IF($D5="","",ROW()-3) | B5: 46043 | D5: 南浔美食城 | E5: 主材 | F5: =IF($D5="","",IFERROR(VLOOKUP($E5,材料归属,2,0),"※材料类别没选")) | G5: 25*25方管 | I5: 根 | J5: 29 | K5: 19 | L5: =IF($D5="","",ROUND(IF($J5="",1,$J5)*N($K5),2)) | M5: 原表·主材 | N5: =IF($D5="","",IF(ISNA(MATCH($D5,项目名表,0)),"※项目不在项目台账里",IF($F5="※材料类别没选","※材料类别没选",IF(AND($C5<>"",ISNA(MATCH($C5,供应商表,0))),"※供应商不在基础资料里",""))))
A6: =IF($D6="","",ROW()-3) | B6: 46043 | D6: 南浔美食城 | E6: 主材 | F6: =IF($D6="","",IFERROR(VLOOKUP($E6,材料归属,2,0),"※材料类别没选")) | G6: 反光背板 | I6: 张 | J6: 58 | K6: 19 | L6: =IF($D6="","",ROUND(IF($J6="",1,$J6)*N($K6),2)) | M6: 原表·主材 | N6: =IF($D6="","",IF(ISNA(MATCH($D6,项目名表,0)),"※项目不在项目台账里",IF($F6="※材料类别没选","※材料类别没选",IF(AND($C6<>"",ISNA(MATCH($C6,供应商表,0))),"※供应商不在基础资料里",""))))
A7: =IF($D7="","",ROW()-3) | B7: 46043 | D7: 南浔美食城 | E7: 主材 | F7: =IF($D7="","",IFERROR(VLOOKUP($E7,材料归属,2,0),"※材料类别没选")) | G7: 3000K区块 | I7: 箱 | J7: 500 | K7: 1 | L7: =IF($D7="","",ROUND(IF($J7="",1,$J7)*N($K7),2)) | M7: 原表·主材 | N7: =IF($D7="","",IF(ISNA(MATCH($D7,项目名表,0)),"※项目不在项目台账里",IF($F7="※材料类别没选","※材料类别没选",IF(AND($C7<>"",ISNA(MATCH($C7,供应商表,0))),"※供应商不在基础资料里",""))))
A8: =IF($D8="","",ROW()-3) | B8: 46043 | D8: 南浔美食城 | E8: 主材 | F8: =IF($D8="","",IFERROR(VLOOKUP($E8,材料归属,2,0),"※材料类别没选")) | G8: 7.5*7.5黑边灯箱型材 | I8: 米 | J8: 75 | K8: 10 | L8: =IF($D8="","",ROUND(IF($J8="",1,$J8)*N($K8),2)) | M8: 原表·主材 | N8: =IF($D8="","",IF(ISNA(MATCH($D8,项目名表,0)),"※项目不在项目台账里",IF($F8="※材料类别没选","※材料类别没选",IF(AND($C8<>"",ISNA(MATCH($C8,供应商表,0))),"※供应商不在基础资料里",""))))
A9: =IF($D9="","",ROW()-3) | B9: 46043 | D9: 南浔美食城 | E9: 辅材 | F9: =IF($D9="","",IFERROR(VLOOKUP($E9,材料归属,2,0),"※材料类别没选")) | G9: 12V/10000K灯条 | I9: 根 | J9: 100 | K9: 1.5 | L9: =IF($D9="","",ROUND(IF($J9="",1,$J9)*N($K9),2)) | M9: 原表·辅材 | N9: =IF($D9="","",IF(ISNA(MATCH($D9,项目名表,0)),"※项目不在项目台账里",IF($F9="※材料类别没选","※材料类别没选",IF(AND($C9<>"",ISNA(MATCH($C9,供应商表,0))),"※供应商不在基础资料里",""))))
A10: =IF($D10="","",ROW()-3) | B10: 46043 | D10: 南浔美食城 | E10: 辅材 | F10: =IF($D10="","",IFERROR(VLOOKUP($E10,材料归属,2,0),"※材料类别没选")) | G10: 辅材 | J10: 1 | K10: 500 | L10: =IF($D10="","",ROUND(IF($J10="",1,$J10)*N($K10),2)) | M10: 原表·辅材 | N10: =IF($D10="","",IF(ISNA(MATCH($D10,项目名表,0)),"※项目不在项目台账里",IF($F10="※材料类别没选","※材料类别没选",IF(AND($C10<>"",ISNA(MATCH($C10,供应商表,0))),"※供应商不在基础资料里",""))))
A11: =IF($D11="","",ROW()-3) | B11: 46060 | C11: 一利钢材 | D11: 德清津华钢铁 | E11: 主材 | F11: =IF($D11="","",IFERROR(VLOOKUP($E11,材料归属,2,0),"※材料类别没选")) | G11: 3*3*1.2镀锌方管 | I11: 根 | J11: 25 | K11: 23.52 | L11: =IF($D11="","",ROUND(IF($J11="",1,$J11)*N($K11),2)) | M11: 原表·主材 | N11: =IF($D11="","",IF(ISNA(MATCH($D11,项目名表,0)),"※项目不在项目台账里",IF($F11="※材料类别没选","※材料类别没选",IF(AND($C11<>"",ISNA(MATCH($C11,供应商表,0))),"※供应商不在基础资料里",""))))
A12: =IF($D12="","",ROW()-3) | B12: 46060 | C12: 一利钢材 | D12: 德清津华钢铁 | E12: 主材 | F12: =IF($D12="","",IFERROR(VLOOKUP($E12,材料归属,2,0),"※材料类别没选")) | G12: 4*4*2镀锌角铁 | I12: 根 | J12: 1 | K12: 60 | L12: =IF($D12="","",ROUND(IF($J12="",1,$J12)*N($K12),2)) | M12: 原表·主材 | N12: =IF($D12="","",IF(ISNA(MATCH($D12,项目名表,0)),"※项目不在项目台账里",IF($F12="※材料类别没选","※材料类别没选",IF(AND($C12<>"",ISNA(MATCH($C12,供应商表,0))),"※供应商不在基础资料里",""))))
A13: =IF($D13="","",ROW()-3) | B13: 46060 | C13: 小王加工厂 | D13: 德清津华钢铁 | E13: 主材 | F13: =IF($D13="","",IFERROR(VLOOKUP($E13,材料归属,2,0),"※材料类别没选")) | G13: 550喷绘布 | I13: m² | J13: 184.97 | K13: 8 | L13: =IF($D13="","",ROUND(IF($J13="",1,$J13)*N($K13),2)) | M13: 原表·主材 | N13: =IF($D13="","",IF(ISNA(MATCH($D13,项目名表,0)),"※项目不在项目台账里",IF($F13="※材料类别没选","※材料类别没选",IF(AND($C13<>"",ISNA(MATCH($C13,供应商表,0))),"※供应商不在基础资料里",""))))
A14: =IF($D14="","",ROW()-3) | B14: 46060 | C14: 小王加工厂 | D14: 德清津华钢铁 | E14: 主材 | F14: =IF($D14="","",IFERROR(VLOOKUP($E14,材料归属,2,0),"※材料类别没选")) | G14: 550喷绘布 | I14: m² | J14: 75.43 | K14: 6 | L14: =IF($D14="","",ROUND(IF($J14="",1,$J14)*N($K14),2)) | M14: 原表·主材 | N14: =IF($D14="","",IF(ISNA(MATCH($D14,项目名表,0)),"※项目不在项目台账里",IF($F14="※材料类别没选","※材料类别没选",IF(AND($C14<>"",ISNA(MATCH($C14,供应商表,0))),"※供应商不在基础资料里",""))))
A15: =IF($D15="","",ROW()-3) | B15: 46060 | D15: 德清津华钢铁 | E15: 辅材 | F15: =IF($D15="","",IFERROR(VLOOKUP($E15,材料归属,2,0),"※材料类别没选")) | G15: 车辆+辅材 | I15: 趟 | J15: 1 | K15: 200 | L15: =IF($D15="","",ROUND(IF($J15="",1,$J15)*N($K15),2)) | M15: 原表·辅材 | N15: =IF($D15="","",IF(ISNA(MATCH($D15,项目名表,0)),"※项目不在项目台账里",IF($F15="※材料类别没选","※材料类别没选",IF(AND($C15<>"",ISNA(MATCH($C15,供应商表,0))),"※供应商不在基础资料里",""))))
A16: =IF($D16="","",ROW()-3) | B16: 46083 | C16: 匠心 | D16: 兰溪手擀面 | E16: 主材 | F16: =IF($D16="","",IFERROR(VLOOKUP($E16,材料归属,2,0),"※材料类别没选")) | G16: 发光字 | I16: 套 | J16: 1 | K16: 440 | L16: =IF($D16="","",ROUND(IF($J16="",1,$J16)*N($K16),2)) | M16: 原表·主材 | N16: =IF($D16="","",IF(ISNA(MATCH($D16,项目名表,0)),"※项目不在项目台账里",IF($F16="※材料类别没选","※材料类别没选",IF(AND($C16<>"",ISNA(MATCH($C16,供应商表,0))),"※供应商不在基础资料里",""))))
A17: =IF($D17="","",ROW()-3) | B17: 46083 | D17: 兰溪手擀面 | E17: 辅材 | F17: =IF($D17="","",IFERROR(VLOOKUP($E17,材料归属,2,0),"※材料类别没选")) | G17: 辅材+车辆 | I17: 1 | J17: 1 | K17: 100 | L17: =IF($D17="","",ROUND(IF($J17="",1,$J17)*N($K17),2)) | M17: 原表·辅材 | N17: =IF($D17="","",IF(ISNA(MATCH($D17,项目名表,0)),"※项目不在项目台账里",IF($F17="※材料类别没选","※材料类别没选",IF(AND($C17<>"",ISNA(MATCH($C17,供应商表,0))),"※供应商不在基础资料里",""))))
A18: =IF($D18="","",ROW()-3) | C18: 杭州水尚装饰 | D18: 莫盾服饰 | E18: 主材 | F18: =IF($D18="","",IFERROR(VLOOKUP($E18,材料归属,2,0),"※材料类别没选")) | G18: 烫边软膜 | I18: m² | J18: 34.713 | K18: 20 | L18: =IF($D18="","",ROUND(IF($J18="",1,$J18)*N($K18),2)) | M18: 原表·主材 | N18: =IF($D18="","",IF(ISNA(MATCH($D18,项目名表,0)),"※项目不在项目台账里",IF($F18="※材料类别没选","※材料类别没选",IF(AND($C18<>"",ISNA(MATCH($C18,供应商表,0))),"※供应商不在基础资料里",""))))
A19: =IF($D19="","",ROW()-3) | D19: 莫盾服饰 | E19: 主材 | F19: =IF($D19="","",IFERROR(VLOOKUP($E19,材料归属,2,0),"※材料类别没选")) | G19: 室内6000K区块 | I19: 块 | J19: 750 | K19: 1 | L19: =IF($D19="","",ROUND(IF($J19="",1,$J19)*N($K19),2)) | M19: 原表·主材 | N19: =IF($D19="","",IF(ISNA(MATCH($D19,项目名表,0)),"※项目不在项目台账里",IF($F19="※材料类别没选","※材料类别没选",IF(AND($C19<>"",ISNA(MATCH($C19,供应商表,0))),"※供应商不在基础资料里",""))))
A20: =IF($D20="","",ROW()-3) | D20: 莫盾服饰 | E20: 主材 | F20: =IF($D20="","",IFERROR(VLOOKUP($E20,材料归属,2,0),"※材料类别没选")) | G20: 烫边软膜专用铝型材 | I20: 米 | J20: 25.38 | K20: 8 | L20: =IF($D20="","",ROUND(IF($J20="",1,$J20)*N($K20),2)) | M20: 原表·主材 | N20: =IF($D20="","",IF(ISNA(MATCH($D20,项目名表,0)),"※项目不在项目台账里",IF($F20="※材料类别没选","※材料类别没选",IF(AND($C20<>"",ISNA(MATCH($C20,供应商表,0))),"※供应商不在基础资料里",""))))
A21: =IF($D21="","",ROW()-3) | D21: 莫盾服饰 | E21: 主材 | F21: =IF($D21="","",IFERROR(VLOOKUP($E21,材料归属,2,0),"※材料类别没选")) | G21: 发光字埋线 | I21: 套 | J21: 2 | K21: 200 | L21: =IF($D21="","",ROUND(IF($J21="",1,$J21)*N($K21),2)) | M21: 原表·主材 | N21: =IF($D21="","",IF(ISNA(MATCH($D21,项目名表,0)),"※项目不在项目台账里",IF($F21="※材料类别没选","※材料类别没选",IF(AND($C21<>"",ISNA(MATCH($C21,供应商表,0))),"※供应商不在基础资料里",""))))
A22: =IF($D22="","",ROW()-3) | C22: 盛世大瑞 | D22: 莫盾服饰 | E22: 主材 | F22: =IF($D22="","",IFERROR(VLOOKUP($E22,材料归属,2,0),"※材料类别没选")) | G22: 发光字 | I22: 套 | J22: 2 | K22: 1300 | L22: =IF($D22="","",ROUND(IF($J22="",1,$J22)*N($K22),2)) | M22: 原表·主材 | N22: =IF($D22="","",IF(ISNA(MATCH($D22,项目名表,0)),"※项目不在项目台账里",IF($F22="※材料类别没选","※材料类别没选",IF(AND($C22<>"",ISNA(MATCH($C22,供应商表,0))),"※供应商不在基础资料里",""))))
A23: =IF($D23="","",ROW()-3) | D23: 莫盾服饰 | E23: 辅材 | F23: =IF($D23="","",IFERROR(VLOOKUP($E23,材料归属,2,0),"※材料类别没选")) | G23: 车辆+辅材 | I23: 趟 | J23: 2 | K23: 100 | L23: =IF($D23="","",ROUND(IF($J23="",1,$J23)*N($K23),2)) | M23: 原表·辅材 | N23: =IF($D23="","",IF(ISNA(MATCH($D23,项目名表,0)),"※项目不在项目台账里",IF($F23="※材料类别没选","※材料类别没选",IF(AND($C23<>"",ISNA(MATCH($C23,供应商表,0))),"※供应商不在基础资料里",""))))
A24: =IF($D24="","",ROW()-3) | B24: 46106 | C24: 甄铭 | D24: 君澜服饰 | E24: 主材 | F24: =IF($D24="","",IFERROR(VLOOKUP($E24,材料归属,2,0),"※材料类别没选")) | G24: 发光字 | I24: 套 | J24: 1 | K24: 244 | L24: =IF($D24="","",ROUND(IF($J24="",1,$J24)*N($K24),2)) | M24: 原表·主材 | N24: =IF($D24="","",IF(ISNA(MATCH($D24,项目名表,0)),"※项目不在项目台账里",IF($F24="※材料类别没选","※材料类别没选",IF(AND($C24<>"",ISNA(MATCH($C24,供应商表,0))),"※供应商不在基础资料里",""))))
A25: =IF($D25="","",ROW()-3) | B25: 46106 | C25: 甄铭 | D25: 君澜服饰 | E25: 主材 | F25: =IF($D25="","",IFERROR(VLOOKUP($E25,材料归属,2,0),"※材料类别没选")) | G25: 发光字 | I25: 套 | J25: 1 | K25: 362 | L25: =IF($D25="","",ROUND(IF($J25="",1,$J25)*N($K25),2)) | M25: 原表·主材 | N25: =IF($D25="","",IF(ISNA(MATCH($D25,项目名表,0)),"※项目不在项目台账里",IF($F25="※材料类别没选","※材料类别没选",IF(AND($C25<>"",ISNA(MATCH($C25,供应商表,0))),"※供应商不在基础资料里",""))))
