Workbook

Sheet 目录
A1: 项目目录
A2: 序号 | B2: 项目名称 | C2: 项目简称 | D2: 备注
A3: 1 | B3: 重庆铜梁110kV淮阳站阳高线10kV配套送出工程（安装） | C3: 淮阳站阳高线
A4: 2 | B4: 重庆市合川区云门街道云龙社区居民委员会(铁工厂还房建设项目)高压新装用电工程 | C4: 云龙社区
A5: 3 | B5: 高新区厂房及配套设施提质改造项目开票到瑞翔厂区电力土建(管廊)建设工程 | C5: 合川瑞翔
A6: 4 | B6: 重庆铜梁铜城2回金龙物业管理有限公司10kV业扩配套工程 | C6: 铜城2回、玉璟尚线、铁井一回、淮拦线4
A7: 5 | B7: 重庆铜梁玉璟尚线金龙物业管理有限公司10kV业扩配套工程 | C7: 铜城2回、玉璟尚线、铁井一回、淮拦线4
A8: 6 | B8: 重庆铜梁铁井一回1#环网柜等6个10kV老旧环网柜改造工程(安装) | C8: 铜城2回、玉璟尚线、铁井一回、淮拦线4
A9: 7 | B9: 重庆铜梁淮拦线4#环网柜等6个10kV老旧环网柜改造工程（安装） | C9: 铜城2回、玉璟尚线、铁井一回、淮拦线4
A10: 8 | B10: 国网重庆合川供电公司2026年用电信息采集系统建筑相关工程施工(包4) | C10: 合川表计
A11: 9 | B11: 铜梁区园区屋顶分布式光伏发电建设项目-蒲吕片区A段10千伏电力新建工程 | C11: 蒲吕片区A段
A15: 13
A16: 14
A17: 15
A18: 16
A19: 17
A20: 18
A21: 19
A22: 20

Sheet 发票统计
A1: 项目总台账
A2: 项目 简称 | B2: 月份 | C2: 项目 名称 | D2: 摘要 | E2: 收票 单位 | F2: 发票 性质 | G2: 管理 费点 | H2: 销售金额 | I2: 管理费 | J2: 应开 成本票 | K2: 已开 成本票 | L2: 未开 成本票 | M2: 应收款 | N2: 质保金 | O2: 已收款 | P2: 未收款 | Q2: 应付 工程款 | R2: 扣除 管理费 | S2: 已付 工程款 | T2: 未付 工程款 | U2: 备注
H3: =SUM(H4:H318) -> 2206559.2 | I3: =SUM(I4:I318) -> 65304.158 | J3: =SUM(J4:J318) -> 2041255 | K3: =SUM(K4:K318) -> 2098816.7 | L3: =J3-K3 -> -57561.71 | M3: =SUM(M4:M318) -> 2006559.2 | N3: =SUM(N4:N318) -> 0 | O3: =SUM(O4:O318) -> 1500594.2 | P3: =M3-O3 -> 505964.91 | Q3: =SUM(Q4:Q318) -> 0 | R3: =SUM(R4:R318) -> 0 | S3: =SUM(S4:S318) -> 576643 | T3: =SUM(T4:T318) -> -22480349 | U3: =SUM(U4:U318) -> 0
A4: =IFERROR(VLOOKUP(C4,目录!B:C,2,0),"") -> 淮阳站阳高线 | B4: =MID(D4,FIND(".",D4)+1,FIND(".",D4,FIND(".",D4)+1)-FIND(".",D4)-1)&"月" -> 3月 | C4: 重庆铜梁110kV淮阳站阳高线10kV配套送出工程（安装） | D4: 2026.3.25新德润开票到民能：淮阳站阳高线 | E4: 民能 | F4: 3%专票 | H4: 57824 | I4: =H4*G4 -> 0 | J4: =H4-I4 -> 57824 | K4: 57824 | L4: =J4-K4 -> 0 | M4: =H4 -> 57824 | P4: =M4-O4-N4 -> 57824 | R4: 0 | S4: 0 | T4: =Q4-R4-S4 -> 0
A5: =IFERROR(VLOOKUP(C5,目录!B:C,2,0),"") -> 淮阳站阳高线 | B5: =MID(D5,FIND(".",D5)+1,FIND(".",D5,FIND(".",D5)+1)-FIND(".",D5)-1)&"月" -> 3月 | C5: 重庆铜梁110kV淮阳站阳高线10kV配套送出工程（安装） | D5: 2026.3.25张氏机电-新德润：淮阳站阳高线 | E5: 新德润 | H5: 50120.61 | I5: =H5*G5 -> 0 | J5: =H5-I5 -> 50120.61 | K5: 50120.61 | L5: =L4+J5-K5 -> 0 | M5: =H5 -> 50120.61 | P5: =P4+M5-N5-O5 -> 107944.61 | T5: =T4+Q5-R5-S5 -> 0
A6: =IFERROR(VLOOKUP(C6,目录!B:C,2,0),"") -> 云龙社区 | B6: =MID(D6,FIND(".",D6)+1,FIND(".",D6,FIND(".",D6)+1)-FIND(".",D6)-1)&"月" -> 4月 | C6: 重庆市合川区云门街道云龙社区居民委员会(铁工厂还房建设项目)高压新装用电工程 | D6: 2026.4.28庆文开票给新德润：云龙社区居民委员会 | E6: 新德润 | F6: 3%专票 | H6: 183486.24 | I6: =H6*G6 -> 0 | J6: =H6-I6 -> 183486.24 | K6: 183486.24 | L6: =L5+J6-K6 -> 0 | M6: =H6 -> 183486.24 | P6: =P5+M6-N6-O6 -> 291430.85 | T6: =T5+Q6-R6-S6 -> 0
A7: =IFERROR(VLOOKUP(C7,目录!B:C,2,0),"") -> 云龙社区 | B7: =MID(D7,FIND(".",D7)+1,FIND(".",D7,FIND(".",D7)+1)-FIND(".",D7)-1)&"月" -> 4月 | C7: 重庆市合川区云门街道云龙社区居民委员会(铁工厂还房建设项目)高压新装用电工程 | D7: 2026.4.30莨富收到新德润款项：云龙社区居民委员会 | E7: 新德润 | O7: 183486.24 | P7: =P6+M7-N7-O7 -> 107944.61 | T7: =T6+Q7-R7-S7 -> 0
A8: =IFERROR(VLOOKUP(C8,目录!B:C,2,0),"") -> 云龙社区 | B8: =MID(D8,FIND(".",D8)+1,FIND(".",D8,FIND(".",D8)+1)-FIND(".",D8)-1)&"月" -> 5月 | C8: 重庆市合川区云门街道云龙社区居民委员会(铁工厂还房建设项目)高压新装用电工程 | D8: 2026.5.7庆文开票给新德润：云龙社区居民委员会 | E8: 新德润 | F8: 3%专票 | H8: 43774.56 | I8: =H8*G8 -> 0 | J8: =H8-I8 -> 43774.56 | K8: 43774.56 | L8: =L6+J8-K8 -> 0 | M8: =H8 -> 43774.56 | P8: =P7+M8-N8-O8 -> 151719.17 | T8: =T7+Q8-R8-S8 -> 0
A9: =IFERROR(VLOOKUP(C9,目录!B:C,2,0),"") -> 云龙社区 | B9: =MID(D9,FIND(".",D9)+1,FIND(".",D9,FIND(".",D9)+1)-FIND(".",D9)-1)&"月" -> 5月 | C9: 重庆市合川区云门街道云龙社区居民委员会(铁工厂还房建设项目)高压新装用电工程 | D9: 2026.5.13庆文公账收到新德润款项：云龙社区居民委员会 | E9: 新德润 | M9: =H9 -> 0 | O9: 43774.56 | P9: =P8+M9-N9-O9 -> 107944.61 | T9: =T8+Q9-R9-S9 -> 0
A10: =IFERROR(VLOOKUP(C10,目录!B:C,2,0),"") -> 合川瑞翔 | B10: =MID(D10,FIND(".",D10)+1,FIND(".",D10,FIND(".",D10)+1)-FIND(".",D10)-1)&"月" -> 6月 | C10: 高新区厂房及配套设施提质改造项目开票到瑞翔厂区电力土建(管廊)建设工程 | D10: 2026.6.17庆文开票给新德润：瑞翔厂区电力土建 | E10: 新德润 | F10: 1%专票 | H10: 100000 | I10: =H10*G10 -> 0 | J10: =H10-I10 -> 100000 | K10: 100000 | L10: =L6+J10-K10 -> 0 | M10: =H10 -> 100000 | P10: =P9+M10-N10-O10 -> 207944.61 | T10: =T9+Q10-R10-S10 -> 0
A11: =IFERROR(VLOOKUP(C11,目录!B:C,2,0),"") -> 合川瑞翔 | B11: =MID(D11,FIND(".",D11)+1,FIND(".",D11,FIND(".",D11)+1)-FIND(".",D11)-1)&"月" -> 6月 | C11: 高新区厂房及配套设施提质改造项目开票到瑞翔厂区电力土建(管廊)建设工程 | D11: 2026.6.18庆文收到新德润打款：瑞翔厂区电力 | E11: 新德润 | L11: =L10+J11-K11 -> 0 | M11: =H11 -> 0 | O11: 100000 | P11: =P10+M11-N11-O11 -> 107944.61 | T11: =T10+Q11-R11-S11 -> 0
A12: =IFERROR(VLOOKUP(C12,目录!B:C,2,0),"") -> 合川瑞翔 | B12: =MID(D12,FIND(".",D12)+1,FIND(".",D12,FIND(".",D12)+1)-FIND(".",D12)-1)&"月" -> 7月 | C12: 高新区厂房及配套设施提质改造项目开票到瑞翔厂区电力土建(管廊)建设工程 | D12: 2026.7.2朱氏水泥管件开票到新德润：瑞翔厂区电力土建 | E12: 新德润 | F12: 1%普票 | H12: 50200 | I12: =H12*G12 -> 0 | J12: =H12-I12 -> 50200 | K12: 50200 | L12: =L11+J12-K12 -> 0 | M12: =H12 -> 50200 | P12: =P11+M12-N12-O12 -> 158144.61 | T12: =T11+Q12-R12-S12 -> 0
A13: =IFERROR(VLOOKUP(C13,目录!B:C,2,0),"") -> 合川瑞翔 | B13: =MID(D13,FIND(".",D13)+1,FIND(".",D13,FIND(".",D13)+1)-FIND(".",D13)-1)&"月" -> 7月 | C13: 高新区厂房及配套设施提质改造项目开票到瑞翔厂区电力土建(管廊)建设工程 | D13: 2026.7.6朱氏水泥管收到新德润：瑞翔厂区电力 | E13: 新德润 | L13: =L12+J13-K13 -> 0 | M13: =H13 -> 0 | O13: 50200 | P13: =P12+M13-N13-O13 -> 107944.61 | T13: =T12+Q13-R13-S13 -> 0
A14: =IFERROR(VLOOKUP(C14,目录!B:C,2,0),"") -> 合川瑞翔 | B14: =MID(D14,FIND(".",D14)+1,FIND(".",D14,FIND(".",D14)+1)-FIND(".",D14)-1)&"月" -> 7月 | C14: 高新区厂房及配套设施提质改造项目开票到瑞翔厂区电力土建(管廊)建设工程 | D14: 2026.7.8庆文开票给新德润：瑞翔厂区电力土建 | E14: 新德润 | F14: 1%专票 | H14: 100000 | I14: =H14*G14 -> 0 | J14: =H14-I14 -> 100000 | K14: 100000 | L14: =L13+J14-K14 -> 0 | M14: =H14 -> 100000 | P14: =P13+M14-N14-O14 -> 207944.61 | T14: =T13+Q14-R14-S14 -> 0
A15: =IFERROR(VLOOKUP(C15,目录!B:C,2,0),"") -> 合川瑞翔 | B15: =MID(D15,FIND(".",D15)+1,FIND(".",D15,FIND(".",D15)+1)-FIND(".",D15)-1)&"月" -> 7月 | C15: 高新区厂房及配套设施提质改造项目开票到瑞翔厂区电力土建(管廊)建设工程 | D15: 2026.7.9庆文收到新德润打款：瑞翔厂区电力 | E15: 新德润 | I15: =H15*G15 -> 0 | J15: =H15-I15 -> 0 | K15: 0 | L15: =L14+J15-K15 -> 0 | M15: =H15 -> 0 | O15: 100000 | P15: =P14+M15-N15-O15 -> 107944.61 | T15: =T14+Q15-R15-S15 -> 0
A16: =IFERROR(VLOOKUP(C16,目录!B:C,2,0),"") -> 合川瑞翔 | B16: =MID(D16,FIND(".",D16)+1,FIND(".",D16,FIND(".",D16)+1)-FIND(".",D16)-1)&"月" -> 7月 | C16: 高新区厂房及配套设施提质改造项目开票到瑞翔厂区电力土建(管廊)建设工程 | D16: 2026.7.8铜桐桐建材开票到新德润：瑞翔厂区电力土建 | E16: 新德润 | F16: 1%普票 | H16: 49800 | I16: =H16*G16 -> 0 | J16: =H16-I16 -> 49800 | K16: 49800 | L16: =L15+J16-K16 -> 0 | M16: =H16 -> 49800 | P16: =P15+M16-N16-O16 -> 157744.61 | T16: =T15+Q16-R16-S16 -> 0
A17: =IFERROR(VLOOKUP(C17,目录!B:C,2,0),"") -> 合川瑞翔 | B17: =MID(D17,FIND(".",D17)+1,FIND(".",D17,FIND(".",D17)+1)-FIND(".",D17)-1)&"月" -> 7月 | C17: 高新区厂房及配套设施提质改造项目开票到瑞翔厂区电力土建(管廊)建设工程 | D17: 2026.7.7号收到新德润打款给胡崇文：瑞翔厂区电力 | E17: 新德润 | I17: =H17*G17 -> 0 | J17: =H17-I17 -> 0 | K17: 0 | L17: =L16+J17-K17 -> 0 | M17: =H17 -> 0 | O17: 49800 | P17: =P16+M17-N17-O17 -> 107944.61 | T17: =T16+Q17-R17-S17 -> 0
A18: =IFERROR(VLOOKUP(C18,目录!B:C,2,0),"") -> 合川瑞翔 | B18: =MID(D18,FIND(".",D18)+1,FIND(".",D18,FIND(".",D18)+1)-FIND(".",D18)-1)&"月" -> 7月 | C18: 高新区厂房及配套设施提质改造项目开票到瑞翔厂区电力土建(管廊)建设工程 | D18: 2026.7.13小溪建材开票到新德润：瑞翔厂区电力土建 | E18: 新德润 | F18: 13%专票 | H18: 50220 | I18: =H18*G18 -> 0 | J18: =H18-I18 -> 50220 | K18: 50220 | L18: =L17+J18-K18 -> 0 | M18: =H18 -> 50220 | P18: =P17+M18-N18-O18 -> 158164.61 | T18: =T17+Q18-R18-S18 -> 0
A19: =IFERROR(VLOOKUP(C19,目录!B:C,2,0),"") -> 合川瑞翔 | B19: =MID(D19,FIND(".",D19)+1,FIND(".",D19,FIND(".",D19)+1)-FIND(".",D19)-1)&"月" -> 7月 | C19: 高新区厂房及配套设施提质改造项目开票到瑞翔厂区电力土建(管廊)建设工程 | D19: 2026.7.15小溪建材收到新德润打款：瑞翔厂区电力 | E19: 新德润 | L19: =L18+J19-K19 -> 0 | M19: =H19 -> 0 | O19: 50220 | P19: =P18+M19-N19-O19 -> 107944.61 | T19: =T18+Q19-R19-S19 -> 0
A20: =IFERROR(VLOOKUP(C20,目录!B:C,2,0),"") -> 合川瑞翔 | B20: =MID(D20,FIND(".",D20)+1,FIND(".",D20,FIND(".",D20)+1)-FIND(".",D20)-1)&"月" -> 7月 | C20: 高新区厂房及配套设施提质改造项目开票到瑞翔厂区电力土建(管廊)建设工程 | D20: 2026.7.13旭承机械开票到新德润：瑞翔厂区电力土建 | E20: 新德润 | F20: 1%普票 | H20: 100000 | I20: =H20*G20 -> 0 | J20: =H20-I20 -> 100000 | K20: 100000 | L20: =L19+J20-K20 -> 0 | M20: =H20 -> 100000 | P20: =P19+M20-N20-O20 -> 207944.61 | T20: =T19+Q20-R20-S20 -> 0
A21: =IFERROR(VLOOKUP(C21,目录!B:C,2,0),"") -> 合川瑞翔 | B21: =MID(D21,FIND(".",D21)+1,FIND(".",D21,FIND(".",D21)+1)-FIND(".",D21)-1)&"月" -> 7月 | C21: 高新区厂房及配套设施提质改造项目开票到瑞翔厂区电力土建(管廊)建设工程 | D21: 2026.7.15旭承机械收到新德润打款：瑞翔厂区电力土建 | E21: 新德润 | L21: =L20+J21-K21 -> 0 | M21: =H21 -> 0 | O21: 100000 | P21: =P20+M21-N21-O21 -> 107944.61 | T21: =T20+Q21-R21-S21 -> 0
A22: =IFERROR(VLOOKUP(C22,目录!B:C,2,0),"") -> 合川瑞翔 | B22: =MID(D22,FIND(".",D22)+1,FIND(".",D22,FIND(".",D22)+1)-FIND(".",D22)-1)&"月" -> 7月 | C22: 高新区厂房及配套设施提质改造项目开票到瑞翔厂区电力土建(管廊)建设工程 | D22: 2026.7.14凯樽物资开票到新德润：瑞翔厂区电力土建 | E22: 新德润 | F22: 13%专票 | H22: 49780 | I22: =H22*G22 -> 0 | J22: =H22-I22 -> 49780 | K22: 49780 | L22: =L21+J22-K22 -> 0 | M22: =H22 -> 49780 | P22: =P21+M22-N22-O22 -> 157724.61 | T22: =T21+Q22-R22-S22 -> 0
A23: =IFERROR(VLOOKUP(C23,目录!B:C,2,0),"") -> 合川瑞翔 | B23: =MID(D23,FIND(".",D23)+1,FIND(".",D23,FIND(".",D23)+1)-FIND(".",D23)-1)&"月" -> 7月 | C23: 高新区厂房及配套设施提质改造项目开票到瑞翔厂区电力土建(管廊)建设工程 | D23: 2026.7.15凯樽物资收到新德润打款：瑞翔厂区电力土建 | E23: 新德润 | L23: =L22+J23-K23 -> 0 | M23: =H23 -> 0 | O23: 49780 | P23: =P22+M23-N23-O23 -> 107944.61 | T23: =T22+Q23-R23-S23 -> 0
A24: =IFERROR(VLOOKUP(C24,目录!B:C,2,0),"") -> 合川瑞翔 | B24: =MID(D24,FIND(".",D24)+1,FIND(".",D24,FIND(".",D24)+1)-FIND(".",D24)-1)&"月" -> 9月 | C24: 高新区厂房及配套设施提质改造项目开票到瑞翔厂区电力土建(管廊)建设工程 | D24: 2026.9.14新德润代胡崇文支付宜宾翠屏货款：42800-39473.83=3326.17 | E24: 新德润 | L24: =L23+J24-K24 -> 0 | M24: =H24 -> 0 | O24: 3326.17 | P24: =P23+M24-N24-O24 -> 104618.44 | T24: =T23+Q24-R24-S24 -> 0
A25: =IFERROR(VLOOKUP(C25,目录!B:C,2,0),"") -> 铜城2回、玉璟尚线、铁井一回、淮拦线4 | B25: =MID(D25,FIND(".",D25)+1,FIND(".",D25,FIND(".",D25)+1)-FIND(".",D25)-1)&"月" -> 6月 | C25: 重庆铜梁铜城2回金龙物业管理有限公司10kV业扩配套工程 | D25: 2026.6.24新德润开票民能：铜城2回，10%管理费 | E25: 民能 | F25: 3%专票 | G25: 0.1 | H25: 4002.66 | I25: =H25*G25 -> 400.266 | J25: =H25-I25 -> 3602.394 | L25: =L24+J25-K25 -> 3602.394 | M25: =H25 -> 4002.66 | P25: =P24+M25-N25-O25 -> 108621.1 | T25: =T24+Q25-R25-S25 -> 0
A26: =IFERROR(VLOOKUP(C26,目录!B:C,2,0),"") -> 铜城2回、玉璟尚线、铁井一回、淮拦线4 | B26: =MID(D26,FIND(".",D26)+1,FIND(".",D26,FIND(".",D26)+1)-FIND(".",D26)-1)&"月" -> 6月 | C26: 重庆铜梁玉璟尚线金龙物业管理有限公司10kV业扩配套工程 | D26: 2026.6.24新德润开票民能：玉璟尚线，10%管理费 | E26: 民能 | F26: 3%专票 | G26: 0.1 | H26: 13079.84 | I26: =H26*G26 -> 1307.984 | J26: =H26-I26 -> 11771.856 | L26: =L25+J26-K26 -> 15374.25 | M26: =H26 -> 13079.84 | P26: =P25+M26-N26-O26 -> 121700.94 | T26: =T25+Q26-R26-S26 -> 0
A27: =IFERROR(VLOOKUP(C27,目录!B:C,2,0),"") -> 铜城2回、玉璟尚线、铁井一回、淮拦线4 | B27: =MID(D27,FIND(".",D27)+1,FIND(".",D27,FIND(".",D27)+1)-FIND(".",D27)-1)&"月" -> 6月 | C27: 重庆铜梁铁井一回1#环网柜等6个10kV老旧环网柜改造工程(安装) | D27: 2026.6.24新德润开票民能：铁井一回1#环网柜，10%管理费 | E27: 民能 | F27: 3%专票 | G27: 0.1 | H27: 47546.28 | I27: =H27*G27 -> 4754.628 | J27: =H27-I27 -> 42791.652 | L27: =L26+J27-K27 -> 58165.902 | M27: =H27 -> 47546.28 | P27: =P26+M27-N27-O27 -> 169247.22 | T27: =T26+Q27-R27-S27 -> 0
A28: =IFERROR(VLOOKUP(C28,目录!B:C,2,0),"") -> 铜城2回、玉璟尚线、铁井一回、淮拦线4 | B28: =MID(D28,FIND(".",D28)+1,FIND(".",D28,FIND(".",D28)+1)-FIND(".",D28)-1)&"月" -> 6月 | C28: 重庆铜梁淮拦线4#环网柜等6个10kV老旧环网柜改造工程（安装） | D28: 2026.6.24新德润开票民能：淮拦线4#环网柜，10%管理费 | E28: 民能 | F28: 3%专票 | G28: 0.1 | H28: 56969.32 | I28: =H28*G28 -> 5696.932 | J28: =H28-I28 -> 51272.388 | L28: =L27+J28-K28 -> 109438.29 | M28: =H28 -> 56969.32 | P28: =P27+M28-N28-O28 -> 226216.54 | T28: =T27+Q28-R28-S28 -> 0
A29: =IFERROR(VLOOKUP(C29,目录!B:C,2,0),"") -> 铜城2回、玉璟尚线、铁井一回、淮拦线4 | B29: =MID(D29,FIND(".",D29)+1,FIND(".",D29,FIND(".",D29)+1)-FIND(".",D29)-1)&"月" -> 6月 | C29: 重庆铜梁淮拦线4#环网柜等6个10kV老旧环网柜改造工程（安装） | D29: 2026.6.23桐桐建材开票到新德润：淮拦、铁井、玉璟、铜城2回 | E29: 新德润 | F29: 1%普票 | I29: =H29*G29 -> 0 | J29: =H29-I29 -> 0 | K29: 67200 | L29: =L28+J29-K29 -> 42238.29 | M29: =H29 -> 0 | P29: =P28+M29-N29-O29 -> 226216.54 | T29: =T28+Q29-R29-S29 -> 0
A30: =IFERROR(VLOOKUP(C30,目录!B:C,2,0),"") -> 铜城2回、玉璟尚线、铁井一回、淮拦线4 | B30: =MID(D30,FIND(".",D30)+1,FIND(".",D30,FIND(".",D30)+1)-FIND(".",D30)-1)&"月" -> 6月 | C30: 重庆铜梁淮拦线4#环网柜等6个10kV老旧环网柜改造工程（安装） | D30: 2026.6.24宜宾翠屏开票到新德润淮：淮拦、铁井、玉璟、铜城2回 | E30: 新德润 | F30: 1%普票 | I30: =H30*G30 -> 0 | J30: =H30-I30 -> 0 | K30: 42800 | L30: =L29+J30-K30 -> -561.71 | M30: =H30 -> 0 | P30: =P29+M30-N30-O30 -> 226216.54 | T30: =T29+Q30-R30-S30 -> 0
A31: =IFERROR(VLOOKUP(C31,目录!B:C,2,0),"") -> 铜城2回、玉璟尚线、铁井一回、淮拦线4 | B31: =MID(D31,FIND(".",D31)+1,FIND(".",D31,FIND(".",D31)+1)-FIND(".",D31)-1)&"月" -> 9月 | C31: 重庆铜梁淮拦线4#环网柜等6个10kV老旧环网柜改造工程（安装） | D31: 2026.9.14新德润扣8月民能农民工工资个税 | E31: 新德润 | F31: 1%普票 | I31: =H31*G31 -> 0 | J31: =H31-I31 -> 0 | K31: 57000 | L31: =L30+J31-K31 -> -57561.71 | M31: =H31 -> 0 | O31: 810 | P31: =P30+M31-N31-O31 -> 225406.54 | T31: =T30+Q31-R31-S31 -> 0
A32: =IFERROR(VLOOKUP(C32,目录!B:C,2,0),"") -> 铜城2回、玉璟尚线、铁井一回、淮拦线4 | B32: =MID(D32,FIND(".",D32)+1,FIND(".",D32,FIND(".",D32)+1)-FIND(".",D32)-1)&"月" -> 9月 | C32: 重庆铜梁铁井一回1#环网柜等6个10kV老旧环网柜改造工程(安装) | D32: 2026.9.14新德润扣8月民能农民工工资：铁井一回1 | E32: 新德润 | J32: =H32-I32 -> 0 | L32: =L31+J32-K32 -> -57561.71 | M32: =H32 -> 0 | O32: 22000 | P32: =P31+M32-N32-O32 -> 203406.54 | T32: =T31+Q32-R32-S32 -> 0
A33: =IFERROR(VLOOKUP(C33,目录!B:C,2,0),"") -> 铜城2回、玉璟尚线、铁井一回、淮拦线4 | B33: =MID(D33,FIND(".",D33)+1,FIND(".",D33,FIND(".",D33)+1)-FIND(".",D33)-1)&"月" -> 9月 | C33: 重庆铜梁淮拦线4#环网柜等6个10kV老旧环网柜改造工程（安装） | D33: 2026.9.14新德润扣8月民能农民工工资：淮拦线4 | E33: 新德润 | J33: =H33-I33 -> 0 | L33: =L32+J33-K33 -> -57561.71 | M33: =H33 -> 0 | O33: 27000 | P33: =P32+M33-N33-O33 -> 176406.54 | T33: =T32+Q33-R33-S33 -> 0
A34: =IFERROR(VLOOKUP(C34,目录!B:C,2,0),"") -> 铜城2回、玉璟尚线、铁井一回、淮拦线4 | B34: =MID(D34,FIND(".",D34)+1,FIND(".",D34,FIND(".",D34)+1)-FIND(".",D34)-1)&"月" -> 9月 | C34: 重庆铜梁铜城2回金龙物业管理有限公司10kV业扩配套工程 | D34: 2026.9.14新德润扣8月民能农民工工资：铜城2回 | E34: 新德润 | J34: =H34-I34 -> 0 | L34: =L33+J34-K34 -> -57561.71 | M34: =H34 -> 0 | O34: 2000 | P34: =P33+M34-N34-O34 -> 174406.54 | T34: =T33+Q34-R34-S34 -> 0
A35: =IFERROR(VLOOKUP(C35,目录!B:C,2,0),"") -> 铜城2回、玉璟尚线、铁井一回、淮拦线4 | B35: =MID(D35,FIND(".",D35)+1,FIND(".",D35,FIND(".",D35)+1)-FIND(".",D35)-1)&"月" -> 9月 | C35: 重庆铜梁玉璟尚线金龙物业管理有限公司10kV业扩配套工程 | D35: 2026.9.14新德润扣8月民能农民工工资：玉璟尚线 | E35: 新德润 | J35: =H35-I35 -> 0 | L35: =L34+J35-K35 -> -57561.71 | M35: =H35 -> 0 | O35: 6000 | P35: =P34+M35-N35-O35 -> 168406.54 | T35: =T34+Q35-R35-S35 -> 0
A36: =IFERROR(VLOOKUP(C36,目录!B:C,2,0),"") -> 铜城2回、玉璟尚线、铁井一回、淮拦线4 | B36: =MID(D36,FIND(".",D36)+1,FIND(".",D36,FIND(".",D36)+1)-FIND(".",D36)-1)&"月" -> 9月 | C36: 重庆铜梁淮拦线4#环网柜等6个10kV老旧环网柜改造工程（安装） | D36: 2026.9.14新德润扣工资残保金1.5% | E36: 新德润 | J36: =H36-I36 -> 0 | L36: =L35+J36-K36 -> -57561.71 | M36: =H36 -> 0 | O36: 1823.97 | P36: =P35+M36-N36-O36 -> 166582.57 | T36: =T35+Q36-R36-S36 -> 0
A37: =IFERROR(VLOOKUP(C37,目录!B:C,2,0),"") -> 铜城2回、玉璟尚线、铁井一回、淮拦线4 | B37: =MID(D37,FIND(".",D37)+1,FIND(".",D37,FIND(".",D37)+1)-FIND(".",D37)-1)&"月" -> 9月 | C37: 重庆铜梁淮拦线4#环网柜等6个10kV老旧环网柜改造工程（安装） | D37: 2026.9.14新德润扣增值税3541.69，附加税425，印花税72.96 | E37: 新德润 | J37: =H37-I37 -> 0 | L37: =L36+J37-K37 -> -57561.71 | M37: =H37 -> 0 | O37: =3541.69+425+72.96 -> 4039.65 | P37: =P36+M37-N37-O37 -> 162542.92 | T37: =T36+Q37-R37-S37 -> 0
A38: =IFERROR(VLOOKUP(C38,目录!B:C,2,0),"") -> 铜城2回、玉璟尚线、铁井一回、淮拦线4 | B38: =MID(D38,FIND(".",D38)+1,FIND(".",D38,FIND(".",D38)+1)-FIND(".",D38)-1)&"月" -> 9月 | C38: 重庆铜梁淮拦线4#环网柜等6个10kV老旧环网柜改造工程（安装） | D38: 2026.9.14新德润扣管理费 | E38: 新德润 | J38: =H38-I38 -> 0 | L38: =L37+J38-K38 -> -57561.71 | M38: =H38 -> 0 | O38: 12159.81 | P38: =P37+M38-N38-O38 -> 150383.11 | T38: =T37+Q38-R38-S38 -> 0
A39: =IFERROR(VLOOKUP(C39,目录!B:C,2,0),"") -> 铜城2回、玉璟尚线、铁井一回、淮拦线4 | B39: =MID(D39,FIND(".",D39)+1,FIND(".",D39,FIND(".",D39)+1)-FIND(".",D39)-1)&"月" -> 9月 | C39: 重庆铜梁淮拦线4#环网柜等6个10kV老旧环网柜改造工程（安装） | D39: 2026.9.14新德润代胡崇文支付宜宾翠屏货款：42800-39473.83=3326.17 | E39: 新德润 | J39: =H39-I39 -> 0 | L39: =L38+J39-K39 -> -57561.71 | M39: =H39 -> 0 | O39: 39473.83 | P39: =P38+M39-N39-O39 -> 110909.28 | T39: =T38+Q39-R39-S39 -> 0
A40: =IFERROR(VLOOKUP(C40,目录!B:C,2,0),"") -> 合川表计 | B40: =MID(D40,FIND(".",D40)+1,FIND(".",D40,FIND(".",D40)+1)-FIND(".",D40)-1)&"月" -> 6月 | C40: 国网重庆合川供电公司2026年用电信息采集系统建筑相关工程施工(包4) | D40: 2026.6.1张氏机电开票到新德润：合川表计项目 | E40: 新德润 | F40: 1%普票 | H40: 100000 | I40: =H40*G40 -> 0 | J40: =H40-I40 -> 100000 | K40: 100000 | L40: =L39+J40-K40 -> -57561.71 | M40: =H40 -> 100000 | P40: =P39+M40-N40-O40 -> 210909.28 | T40: =T39+Q40-R40-S40 -> 0
...

Sheet 蒲吕片区A段
A1: 铜梁区园区屋顶分布式光伏发电建设项目-蒲吕片区A段10千伏电力新建工程
A2: 对账 单位 | B2: 月份 | C2: 项目 名称 | D2: 摘要 | E2: 收票 单位 | F2: 发票 性质 | G2: 管理 费点 | H2: 销售金额 | I2: 管理费 | J2: 应开 成本票 | K2: 已开 成本票 | L2: 未开 成本票 | M2: 应收款 | N2: 质保金 | O2: 已收款 | P2: 未收款 | Q2: 应付 工程款 | R2: 扣除 管理费 | S2: 已付 工程款 | T2: 未付 工程款 | U2: 备注
H3: =SUM(H4:H306) -> 354295.65 | I3: =SUM(I4:I306) -> 53144.348 | J3: =SUM(J4:J306) -> 301151.3 | K3: =SUM(K4:K306) -> 301151.3 | L3: =J3-K3 -> 0 | M3: =SUM(M4:M306) -> 354295.65 | N3: =SUM(N4:N306) -> 0 | O3: =SUM(O4:O306) -> 304700.02 | P3: =M3-O3 -> 49595.633 | Q3: =SUM(Q4:Q306) -> 0 | R3: =SUM(R4:R306) -> 0 | S3: =SUM(S4:S306) -> 0 | T3: =SUM(T4:T306) -> 0 | U3: =SUM(U4:U306) -> 0
A4: {=_xlfn._xlws.FILTER(发票统计!A:K,发票统计!A:A=_wpsfn.SHEETSNAME(A2))} -> 蒲吕片区A段 | B4: 2月 | C4: 铜梁区园区屋顶分布式光伏发电建设项目-蒲吕片区A段10千伏电力新建工程 | D4: 2026.2.9新德润开9%专票到民能：蒲吕片区A段10千伏电力新建 | E4: 民能 | F4: 9%专票 | G4: 0.15 | H4: 200000 | I4: 30000 | J4: 170000 | K4: 0 | L4: =J4-K4 -> 170000 | M4: {=_xlfn._xlws.FILTER(发票统计!M:O,发票统计!A:A=_wpsfn.SHEETSNAME(A2))} -> 200000 | N4: 0 | O4: 0 | P4: =M4-N4 -> 200000 | Q4: {=_xlfn._xlws.FILTER(发票统计!Q:S,发票统计!A:A=_wpsfn.SHEETSNAME(A2))} -> 0 | R4: 0 | S4: 0 | T4: {=铜城2回、玉璟尚线、铁井一回、淮拦线4!Q3:Q3-铜城2回、玉璟尚线、铁井一回、淮拦线4!R3:R3-铜城2回、玉璟尚线、铁井一回、淮拦线4!S3:S3} -> 0
A5: 蒲吕片区A段 | B5: 9月 | C5: 铜梁区园区屋顶分布式光伏发电建设项目-蒲吕片区A段10千伏电力新建工程 | D5: 2026.9.1扣15%管理费 | E5: 民能 | F5: 9%专票 | G5: 0.15 | H5: 0 | I5: 0 | J5: 0 | K5: 0 | L5: =L4+J5-K5 -> 170000 | M5: 0 | N5: 0 | O5: 30000 | P5: =P4+M5-N5-O5 -> 170000 | Q5: 0 | R5: 0 | S5: 0 | T5: {=铜城2回、玉璟尚线、铁井一回、淮拦线4!T3:T3+铜城2回、玉璟尚线、铁井一回、淮拦线4!Q4:Q4-铜城2回、玉璟尚线、铁井一回、淮拦线4!R4:R4-铜城2回、玉璟尚线、铁井一回、淮拦线4!S4:S4} -> 0
A6: 蒲吕片区A段 | B6: 9月 | C6: 铜梁区园区屋顶分布式光伏发电建设项目-蒲吕片区A段10千伏电力新建工程 | D6: 2026.9.1确认前期收到代发工资 | E6: 民能 | F6: 9%专票 | G6: 0.15 | H6: 0 | I6: 0 | J6: 0 | K6: 200000 | L6: =L5+J6-K6 -> -30000 | M6: 0 | N6: 0 | O6: 200000 | P6: =P5+M6-N6-O6 -> -30000 | Q6: 0 | R6: 0 | S6: 0
A7: 蒲吕片区A段 | B7: 9月 | C7: 铜梁区园区屋顶分布式光伏发电建设项目-蒲吕片区A段10千伏电力新建工程 | D7: 2026.9.1确认扣9%增值税29253.77，附加科3510.45，印花税212.58，合计32976.8 | E7: 民能 | F7: 9%专票 | G7: 0.15 | H7: 0 | I7: 0 | J7: 0 | K7: 32976.8 | L7: =L6+J7-K7 -> -62976.8 | M7: 0 | N7: 0 | O7: 32976.8 | P7: =P6+M7-N7-O7 -> -62976.8 | Q7: 0 | R7: 0 | S7: 0
A8: 蒲吕片区A段 | B8: 9月 | C8: 铜梁区园区屋顶分布式光伏发电建设项目-蒲吕片区A段10千伏电力新建工程 | D8: 2026.9.1扣残保金20W*1.5% | E8: 民能 | F8: 9%专票 | G8: 0.15 | H8: 0 | I8: 0 | J8: 0 | K8: 3000 | L8: =L7+J8-K8 -> -65976.8 | M8: 0 | N8: 0 | O8: 3000 | P8: =P7+M8-N8-O8 -> -65976.8 | Q8: 0 | R8: 0 | S8: 0
A9: 蒲吕片区A段 | B9: 9月 | C9: 铜梁区园区屋顶分布式光伏发电建设项目-蒲吕片区A段10千伏电力新建工程 | D9: 2026.9.1扣个税 | E9: 民能 | F9: 9%专票 | G9: 0.15 | H9: 0 | I9: 0 | J9: 0 | K9: 4950 | L9: =L8+J9-K9 -> -70926.8 | M9: 0 | N9: 0 | O9: 4950 | P9: =P8+M9-N9-O9 -> -70926.8 | Q9: 0 | R9: 0 | S9: 0
A10: 蒲吕片区A段 | B10: 9月 | C10: 铜梁区园区屋顶分布式光伏发电建设项目-蒲吕片区A段10千伏电力新建工程 | D10: 2026.9.1质保金354295.65*3% | E10: 民能 | F10: 9%专票 | G10: 0.15 | H10: 0 | I10: 0 | J10: 0 | K10: 10628.87 | L10: =L9+J10-K10 -> -81555.67 | M10: 0 | N10: 0 | O10: 10628.87 | P10: =P9+M10-N10-O10 -> -81555.67 | Q10: 0 | R10: 0 | S10: 0
A11: 蒲吕片区A段 | B11: 9月 | C11: 铜梁区园区屋顶分布式光伏发电建设项目-蒲吕片区A段10千伏电力新建工程 | D11: 2026.9.4新德润开9%专票到民能：蒲吕片区A段10千伏电力新建 | E11: 民能 | F11: 9%专票 | G11: 0.15 | H11: 154295.65 | I11: 23144.347 | J11: 131151.3 | K11: 49595.632 | L11: =L10+J11-K11 -> 0 | M11: 154295.65 | N11: 0 | O11: 23144.347 | P11: =P10+M11-N11-O11 -> 49595.632 | Q11: 0 | R11: 0 | S11: 0
L12: =L11+J12-K12 -> 0 | P12: =P11+M12-N12-O12 -> 49595.632
L13: =L12+J13-K13 -> 0 | P13: =P12+M13-N13-O13 -> 49595.632
L14: =L13+J14-K14 -> 0 | P14: =P13+M14-N14-O14 -> 49595.632
L15: =L14+J15-K15 -> 0 | P15: =P14+M15-N15-O15 -> 49595.632
L16: =L15+J16-K16 -> 0 | P16: =P15+M16-N16-O16 -> 49595.632
L17: =L16+J17-K17 -> 0 | P17: =P16+M17-N17-O17 -> 49595.632
L18: =L17+J18-K18 -> 0 | P18: =P17+M18-O18 -> 49595.632
L19: =L18+J19-K19 -> 0 | P19: =P18+M19-O19 -> 49595.632
L20: =L19+J20-K20 -> 0 | P20: =P19+M20-O20 -> 49595.632
L21: =L20+J21-K21 -> 0 | P21: =P20+M21-O21 -> 49595.632
L22: =L21+J22-K22 -> 0 | P22: =P21+M22-O22 -> 49595.632
L23: =L22+J23-K23 -> 0 | P23: =P22+M23-O23 -> 49595.632
L24: =L23+J24-K24 -> 0 | P24: =P23+M24-O24 -> 49595.632
P25: =P24+M25-O25 -> 49595.632
P26: =P25+M26-O26 -> 49595.632
P27: =P26+M27-O27 -> 49595.632
P28: =P27+M28-O28 -> 49595.632
P29: =P28+M29-O29 -> 49595.632
P30: =P29+M30-O30 -> 49595.632
P31: =P30+M31-O31 -> 49595.632
P32: =P31+M32-O32 -> 49595.632
P33: =P32+M33-O33 -> 49595.632
P34: =P33+M34-O34 -> 49595.632

Sheet 淮阳站阳高线
A1: 淮阳站阳高线
A2: 对账 单位 | B2: 月份 | C2: 项目 名称 | D2: 摘要 | E2: 收票 单位 | F2: 发票 性质 | G2: 管理 费点 | H2: 销售金额 | I2: 管理费 | J2: 应开 成本票 | K2: 已开 成本票 | L2: 未开 成本票 | M2: 应收款 | N2: 质保金 | O2: 已收款 | P2: 未收款 | Q2: 应付 工程款 | R2: 扣除 管理费 | S2: 已付 工程款 | T2: 未付 工程款 | U2: 备注
H3: =SUM(H4:H306) -> 107944.61 | I3: =SUM(I4:I306) -> 0 | J3: =SUM(J4:J306) -> 107944.61 | K3: =SUM(K4:K306) -> 107944.61 | L3: =J3-K3 -> 0 | M3: =SUM(M4:M306) -> 107944.61 | N3: =SUM(N4:N306) -> 0 | O3: =SUM(O4:O306) -> 0 | P3: =M3-O3 -> 107944.61 | Q3: =SUM(Q4:Q306) -> 0 | R3: =SUM(R4:R306) -> 0 | S3: =SUM(S4:S306) -> 0 | T3: =SUM(T4:T306) -> 0 | U3: =SUM(U4:U306) -> 0
A4: {=_xlfn._xlws.FILTER(发票统计!A:K,发票统计!A:A=_wpsfn.SHEETSNAME(A2))} -> 淮阳站阳高线 | B4: 3月 | C4: 重庆铜梁110kV淮阳站阳高线10kV配套送出工程（安装） | D4: 2026.3.25新德润开票到民能：淮阳站阳高线 | E4: 民能 | F4: 3%专票 | G4: 0 | H4: 57824 | I4: 0 | J4: 57824 | K4: 57824 | L4: =J4-K4 -> 0 | M4: {=_xlfn._xlws.FILTER(发票统计!M:O,发票统计!A:A=_wpsfn.SHEETSNAME(A2))} -> 57824 | N4: 0 | O4: 0 | P4: =M4-N4 -> 57824 | Q4: {=_xlfn._xlws.FILTER(发票统计!Q:S,发票统计!A:A=_wpsfn.SHEETSNAME(A2))} -> 0 | R4: 0 | S4: 0 | T4: {=铜城2回、玉璟尚线、铁井一回、淮拦线4!Q3:Q3-铜城2回、玉璟尚线、铁井一回、淮拦线4!R3:R3-铜城2回、玉璟尚线、铁井一回、淮拦线4!S3:S3} -> 0
A5: 淮阳站阳高线 | B5: 3月 | C5: 重庆铜梁110kV淮阳站阳高线10kV配套送出工程（安装） | D5: 2026.3.25张氏机电-新德润：淮阳站阳高线 | E5: 新德润 | F5: 0 | G5: 0 | H5: 50120.61 | I5: 0 | J5: 50120.61 | K5: 50120.61 | L5: =L4+J5-K5 -> 0 | M5: 50120.61 | N5: 0 | O5: 0 | P5: =P4+M5-N5-O5 -> 107944.61 | Q5: 0 | R5: 0 | S5: 0 | T5: {=铜城2回、玉璟尚线、铁井一回、淮拦线4!T3:T3+铜城2回、玉璟尚线、铁井一回、淮拦线4!Q4:Q4-铜城2回、玉璟尚线、铁井一回、淮拦线4!R4:R4-铜城2回、玉璟尚线、铁井一回、淮拦线4!S4:S4} -> 0
L6: =L5+J6-K6 -> 0 | P6: =P5+M6-N6-O6 -> 107944.61
L7: =L6+J7-K7 -> 0 | P7: =P6+M7-N7-O7 -> 107944.61
L8: =L7+J8-K8 -> 0 | P8: =P7+M8-N8-O8 -> 107944.61
L9: =L8+J9-K9 -> 0 | P9: =P8+M9-N9-O9 -> 107944.61
L10: =L9+J10-K10 -> 0 | P10: =P9+M10-N10-O10 -> 107944.61
L11: =L10+J11-K11 -> 0 | P11: =P10+M11-N11-O11 -> 107944.61
L12: =L11+J12-K12 -> 0 | P12: =P11+M12-N12-O12 -> 107944.61
L13: =L12+J13-K13 -> 0 | P13: =P12+M13-N13-O13 -> 107944.61
L14: =L13+J14-K14 -> 0 | P14: =P13+M14-N14-O14 -> 107944.61
L15: =L14+J15-K15 -> 0 | P15: =P14+M15-N15-O15 -> 107944.61
L16: =L15+J16-K16 -> 0 | P16: =P15+M16-N16-O16 -> 107944.61
L17: =L16+J17-K17 -> 0 | P17: =P16+M17-N17-O17 -> 107944.61
L18: =L17+J18-K18 -> 0 | P18: =P17+M18-O18 -> 107944.61
L19: =L18+J19-K19 -> 0 | P19: =P18+M19-O19 -> 107944.61
L20: =L19+J20-K20 -> 0 | P20: =P19+M20-O20 -> 107944.61
L21: =L20+J21-K21 -> 0 | P21: =P20+M21-O21 -> 107944.61
L22: =L21+J22-K22 -> 0 | P22: =P21+M22-O22 -> 107944.61
L23: =L22+J23-K23 -> 0 | P23: =P22+M23-O23 -> 107944.61
L24: =L23+J24-K24 -> 0 | P24: =P23+M24-O24 -> 107944.61
P25: =P24+M25-O25 -> 107944.61
P26: =P25+M26-O26 -> 107944.61
P27: =P26+M27-O27 -> 107944.61
P28: =P27+M28-O28 -> 107944.61
P29: =P28+M29-O29 -> 107944.61
P30: =P29+M30-O30 -> 107944.61
P31: =P30+M31-O31 -> 107944.61
P32: =P31+M32-O32 -> 107944.61
P33: =P32+M33-O33 -> 107944.61
P34: =P33+M34-O34 -> 107944.61

Sheet 合川表计
A1: 合川表计项目
A2: 对账 单位 | B2: 月份 | C2: 项目 名称 | D2: 摘要 | E2: 收票 单位 | F2: 发票 性质 | G2: 管理 费点 | H2: 销售金额 | I2: 管理费 | J2: 应开 成本票 | K2: 已开 成本票 | L2: 未开 成本票 | M2: 应收款 | N2: 扣质保金 | O2: 已收款 | P2: 未收款 | Q2: 应付 工程款 | R2: 扣除 管理费 | S2: 已付 工程款 | T2: 未付 工程款 | U2: 备注
H3: =SUM(H4:H306) -> 895460 | I3: =SUM(I4:I306) -> 0 | J3: =SUM(J4:J306) -> 795460 | K3: =SUM(K4:K306) -> 795460 | L3: =J3-K3 -> 0 | M3: =SUM(M4:M306) -> 695460 | N3: =SUM(N4:N306) -> 0 | O3: =SUM(O4:O306) -> 350000 | P3: =M3-O3 -> 345460 | Q3: =SUM(Q4:Q306) -> 0 | R3: =SUM(R4:R306) -> 0 | S3: =SUM(S4:S306) -> 576643 | T3: =SUM(T4:T306) -> -14491347 | U3: =SUM(U4:U306) -> 0
A4: {=_xlfn._xlws.FILTER(发票统计!A:K,发票统计!A:A=_wpsfn.SHEETSNAME(A2))} -> 合川表计 | B4: 6月 | C4: 国网重庆合川供电公司2026年用电信息采集系统建筑相关工程施工(包4) | D4: 2026.6.1张氏机电开票到新德润：合川表计项目 | E4: 新德润 | F4: 1%普票 | G4: 0 | H4: 100000 | I4: 0 | J4: 100000 | K4: 100000 | L4: =J4-K4 -> 0 | M4: {=_xlfn._xlws.FILTER(发票统计!M:O,发票统计!A:A=_wpsfn.SHEETSNAME(A2))} -> 100000 | N4: 0 | O4: 0 | P4: =M4-N4 -> 100000 | Q4: {=_xlfn._xlws.FILTER(发票统计!Q:S,发票统计!A:A=_wpsfn.SHEETSNAME(A2))} -> 0 | R4: 0 | S4: 0 | T4: =Q4-R4 -> 0
A5: 合川表计 | B5: 7月 | C5: 国网重庆合川供电公司2026年用电信息采集系统建筑相关工程施工(包4) | D5: 2026.7.28冷氏五金开票到众聚能：合川表计项目 | E5: 众聚能 | F5: 3%普票 | G5: 0 | H5: 50000 | I5: 0 | J5: 50000 | K5: 50000 | L5: =L4+J5-K5 -> 0 | M5: 50000 | N5: 0 | O5: 0 | P5: =P4+M5-N5-O5 -> 150000 | Q5: 0 | R5: 0 | S5: 0 | T5: =T4+Q5-R5-S5 -> 0
A6: 合川表计 | B6: 6月 | C6: 国网重庆合川供电公司2026年用电信息采集系统建筑相关工程施工(包4) | D6: 2026.6.5张氏机电收到新德润转款：合川表计项目 | E6: 新德润 | F6: 0 | G6: 0 | H6: 0 | I6: 0 | J6: 0 | K6: 0 | L6: =L5+J6-K6 -> 0 | M6: 0 | N6: 0 | O6: 100000 | P6: =P5+M6-N6-O6 -> 50000 | Q6: 0 | R6: 0 | S6: 0 | T6: =T5+Q6-R6-S6 -> 0
A7: 合川表计 | B7: 7月 | C7: 国网重庆合川供电公司2026年用电信息采集系统建筑相关工程施工(包4) | D7: 2026.7.31陈小琴（冷氏五金开）收到新德润打款：合川表计项目 | E7: 新德润 | F7: 0 | G7: 0 | H7: 0 | I7: 0 | J7: 0 | K7: 0 | L7: =L6+J7-K7 -> 0 | M7: 0 | N7: 0 | O7: 50000 | P7: =P6+M7-N7-O7 -> 0 | Q7: 0 | R7: 0 | S7: 0 | T7: =T6+Q7-R7-S7 -> 0
A8: 合川表计 | B8: 8月 | C8: 国网重庆合川供电公司2026年用电信息采集系统建筑相关工程施工(包4) | D8: 2026.8.21工资表给众聚能挂账：合川表计项目 | E8: 众聚能 | F8: 1%普票 | G8: 0 | H8: 122000 | I8: 0 | J8: 122000 | K8: 122000 | L8: =L7+J8-K8 -> 0 | M8: 122000 | N8: 0 | O8: 0 | P8: =P7+M8-N8-O8 -> 122000 | Q8: 0 | R8: 0 | S8: 0 | T8: =T7+Q8-R8-S8 -> 0
A9: 合川表计 | B9: 8月 | C9: 国网重庆合川供电公司2026年用电信息采集系统建筑相关工程施工(包4) | D9: 2026.8.21众聚能代付工资：合川表计项目 | E9: 众聚能 | F9: 0 | G9: 0 | H9: 0 | I9: 0 | J9: 0 | K9: 0 | L9: =L8+J9-K9 -> 0 | M9: 0 | N9: 0 | O9: 122000 | P9: =P8+M9-N9-O9 -> 0 | Q9: 0 | R9: 0 | S9: 0 | T9: =T8+Q9-R9-S9 -> 0
A10: 合川表计 | B10: 8月 | C10: 国网重庆合川供电公司2026年用电信息采集系统建筑相关工程施工(包4) | D10: 2026.8.21工资表给腾泰挂账：合川表计项目 | E10: 腾泰 | F10: 1%普票 | G10: 0 | H10: 78000 | I10: 0 | J10: 78000 | K10: 78000 | L10: =L9+J10-K10 -> 0 | M10: 78000 | N10: 0 | O10: 0 | P10: =P9+M10-N10-O10 -> 78000 | Q10: 0 | R10: 0 | S10: 0 | T10: =T9+Q10-R10-S10 -> 0
A11: 合川表计 | B11: 8月 | C11: 国网重庆合川供电公司2026年用电信息采集系统建筑相关工程施工(包4) | D11: 2026.8.21腾泰代付工资：合川表计项目 | E11: 腾泰 | F11: 0 | G11: 0 | H11: 0 | I11: 0 | J11: 0 | K11: 0 | L11: =L10+J11-K11 -> 0 | M11: 0 | N11: 0 | O11: 78000 | P11: =P10+M11-N11-O11 -> 0 | Q11: 0 | R11: 0 | S11: 0 | T11: =T10+Q11-R11-S11 -> 0
A12: 合川表计 | B12: 9月 | C12: 国网重庆合川供电公司2026年用电信息采集系统建筑相关工程施工(包4) | D12: 2026.9.14进源开给润德427712.65，提交15万工资（进源部分人工）：合川表计项目 | E12: 润德 | F12: 3%专票 | G12: 0 | H12: 150000 | I12: 0 | J12: 150000 | K12: 150000 | L12: =L11+J12-K12 -> 0 | M12: 150000 | N12: 0 | O12: 0 | P12: =P11+M12-N12-O12 -> 150000 | Q12: 0 | R12: 0 | S12: 0 | T12: =T11+Q12-R12-S12 -> 0
A13: 合川表计 | B13: 9月 | C13: 国网重庆合川供电公司2026年用电信息采集系统建筑相关工程施工(包4) | D13: 2026.9.21维维对账提交腾泰工资：合川表计项目 | E13: 腾泰 | F13: 1%普票 | G13: 0 | H13: 195460 | I13: 0 | J13: 195460 | K13: 195460 | L13: =L12+J13-K13 -> 0 | M13: 195460 | N13: 0 | O13: 0 | P13: =P12+M13-N13-O13 -> 345460 | Q13: 0 | R13: 0 | S13: 0 | T13: =T12+Q13-R13-S13 -> 0
A14: 合川表计 | B14: 9月 | C14: 国网重庆合川供电公司2026年用电信息采集系统建筑相关工程施工(包4) | D14: 2026.9.21何燕反馈提交10W工资表 | E14: 众聚能 | F14: 0 | G14: 0 | H14: 100000 | I14: 0 | J14: 100000 | K14: 100000 | L14: =L13+J14-K14 -> 0 | M14: 0 | N14: 0 | O14: 0 | P14: =P13+M14-N14-O14 -> 345460 | Q14: 0 | R14: 0 | S14: 0 | T14: =T13+Q14-R14-S14 -> 0
A15: 合川表计 | B15: 9月 | C15: 国网重庆合川供电公司2026年用电信息采集系统建筑相关工程施工(包4) | D15: 2026.9.21小温提供表计工资表给众聚能何燕挂账 | E15: 众聚能 | F15: 1%普票 | G15: 0 | H15: 100000 | I15: 0 | J15: 0 | K15: 0 | L15: =L14+J15-K15 -> 0 | M15: 0 | N15: 0 | O15: 0 | P15: =P14+M15-N15-O15 -> 345460 | Q15: 0 | R15: 0 | S15: 0 | T15: =T14+Q15-R15-S15 -> 0
A16: 合川表计 | B16: 5月 | C16: 国网重庆合川供电公司2026年用电信息采集系统建筑相关工程施工(包4) | D16: 2026.5.6/5.23代付合川表计工资 | E16: 0 | F16: 0 | G16: 0 | H16: 0 | I16: 0 | J16: 0 | K16: 0 | L16: =L15+J16-K16 -> 0 | M16: 0 | N16: 0 | O16: 0 | P16: =P15+M16-N16-O16 -> 345460 | Q16: 0 | R16: 0 | S16: 105000 | T16: =T15+Q16-R16-S16 -> -105000
A17: 合川表计 | B17: 5月 | C17: 国网重庆合川供电公司2026年用电信息采集系统建筑相关工程施工(包4) | D17: 2026.5.14伍勇军借支 | E17: 0 | F17: 0 | G17: 0 | H17: 0 | I17: 0 | J17: 0 | K17: 0 | L17: =L16+J17-K17 -> 0 | M17: 0 | N17: 0 | O17: 0 | P17: =P16+M17-N17-O17 -> 345460 | Q17: 0 | R17: 0 | S17: 20000 | T17: =T16+Q17-R17-S17 -> -125000
A18: 合川表计 | B18: 5月 | C18: 国网重庆合川供电公司2026年用电信息采集系统建筑相关工程施工(包4) | D18: 2026.5.27伍勇军借支 | E18: 0 | F18: 0 | G18: 0 | H18: 0 | I18: 0 | J18: 0 | K18: 0 | L18: =L17+J18-K18 -> 0 | M18: 0 | N18: 0 | O18: 0 | P18: =P17+M18-N18-O18 -> 345460 | Q18: 0 | R18: 0 | S18: 10000 | T18: =T17+Q18-R18-S18 -> -135000
A19: 合川表计 | B19: 6月 | C19: 国网重庆合川供电公司2026年用电信息采集系统建筑相关工程施工(包4) | D19: 2026.6.8代付合川表计工资 | E19: 0 | F19: 0 | G19: 0 | H19: 0 | I19: 0 | J19: 0 | K19: 0 | L19: =L18+J19-K19 -> 0 | M19: 0 | N19: 0 | O19: 0 | P19: =P18+M19-N19-O19 -> 345460 | Q19: 0 | R19: 0 | S19: 91200 | T19: =T18+Q19-R19-S19 -> -226200
A20: 合川表计 | B20: 6月 | C20: 国网重庆合川供电公司2026年用电信息采集系统建筑相关工程施工(包4) | D20: 2026.6.18/6.30代付合川表计工资 | E20: 0 | F20: 0 | G20: 0 | H20: 0 | I20: 0 | J20: 0 | K20: 0 | L20: =L19+J20-K20 -> 0 | M20: 0 | N20: 0 | O20: 0 | P20: =P19+M20-N20-O20 -> 345460 | Q20: 0 | R20: 0 | S20: 75943 | T20: =T19+Q20-R20-S20 -> -302143
A21: 合川表计 | B21: 7月 | C21: 国网重庆合川供电公司2026年用电信息采集系统建筑相关工程施工(包4) | D21: 2026.7.2代付伍建华合川表计工资 | E21: 0 | F21: 0 | G21: 0 | H21: 0 | I21: 0 | J21: 0 | K21: 0 | L21: =L20+J21-K21 -> 0 | M21: 0 | N21: 0 | O21: 0 | P21: =P20+M21-N21-O21 -> 345460 | Q21: 0 | R21: 0 | S21: 2000 | T21: =T20+Q21-R21-S21 -> -304143
A22: 合川表计 | B22: 7月 | C22: 国网重庆合川供电公司2026年用电信息采集系统建筑相关工程施工(包4) | D22: 2026.7.9代付伍建华合川表计工资 | E22: 0 | F22: 0 | G22: 0 | H22: 0 | I22: 0 | J22: 0 | K22: 0 | L22: =L21+J22-K22 -> 0 | M22: 0 | N22: 0 | O22: 0 | P22: =P21+M22-N22-O22 -> 345460 | Q22: 0 | R22: 0 | S22: 70000 | T22: =T21+Q22-R22-S22 -> -374143
A23: 合川表计 | B23: 7月 | C23: 国网重庆合川供电公司2026年用电信息采集系统建筑相关工程施工(包4) | D23: 2026.7.13代付伍建华合川表计工资 | E23: 0 | F23: 0 | G23: 0 | H23: 0 | I23: 0 | J23: 0 | K23: 0 | L23: =L22+J23-K23 -> 0 | M23: 0 | N23: 0 | O23: 0 | P23: =P22+M23-N23-O23 -> 345460 | Q23: 0 | R23: 0 | S23: 10000 | T23: =T22+Q23-R23-S23 -> -384143
A24: 合川表计 | B24: 7月 | C24: 国网重庆合川供电公司2026年用电信息采集系统建筑相关工程施工(包4) | D24: 2026.7.25代付伍建华合川表计工资 | E24: 0 | F24: 0 | G24: 0 | H24: 0 | I24: 0 | J24: 0 | K24: 0 | L24: =L23+J24-K24 -> 0 | M24: 0 | N24: 0 | O24: 0 | P24: =P23+M24-N24-O24 -> 345460 | Q24: 0 | R24: 0 | S24: 5000 | T24: =T23+Q24-R24-S24 -> -389143
A25: 合川表计 | B25: 7月 | C25: 国网重庆合川供电公司2026年用电信息采集系统建筑相关工程施工(包4) | D25: 2026.7.31支付伍建华合川表计工资 | E25: 0 | F25: 0 | G25: 0 | H25: 0 | I25: 0 | J25: 0 | K25: 0 | M25: 0 | N25: 0 | O25: 0 | P25: =P24+M25-N25-O25 -> 345460 | Q25: 0 | R25: 0 | S25: 2000 | T25: =T24+Q25-R25-S25 -> -391143
A26: 合川表计 | B26: 8月 | C26: 国网重庆合川供电公司2026年用电信息采集系统建筑相关工程施工(包4) | D26: 2026.8.1支付伍建劳表计费用 | E26: 0 | F26: 0 | G26: 0 | H26: 0 | I26: 0 | J26: 0 | K26: 0 | M26: 0 | N26: 0 | O26: 0 | P26: =P25+M26-N26-O26 -> 345460 | Q26: 0 | R26: 0 | S26: 8000 | T26: =T25+Q26-R26-S26 -> -399143
A27: 合川表计 | B27: 8月 | C27: 国网重庆合川供电公司2026年用电信息采集系统建筑相关工程施工(包4) | D27: 2026.8.6支付合川工资 | E27: 0 | F27: 0 | G27: 0 | H27: 0 | I27: 0 | J27: 0 | K27: 0 | M27: 0 | N27: 0 | O27: 0 | P27: =P26+M27-N27-O27 -> 345460 | Q27: 0 | R27: 0 | S27: 6000 | T27: =T26+Q27-R27-S27 -> -405143
A28: 合川表计 | B28: 8月 | C28: 国网重庆合川供电公司2026年用电信息采集系统建筑相关工程施工(包4) | D28: 2026.8.14支付伍建劳表计费用 | E28: 0 | F28: 0 | G28: 0 | H28: 0 | I28: 0 | J28: 0 | K28: 0 | M28: 0 | N28: 0 | O28: 0 | P28: =P27+M28-N28-O28 -> 345460 | Q28: 0 | R28: 0 | S28: 5000 | T28: =T27+Q28-R28-S28 -> -410143
A29: 合川表计 | B29: 8月 | C29: 国网重庆合川供电公司2026年用电信息采集系统建筑相关工程施工(包4) | D29: 2026.8.20支付合川工资 | E29: 0 | F29: 0 | G29: 0 | H29: 0 | I29: 0 | J29: 0 | K29: 0 | M29: 0 | N29: 0 | O29: 0 | P29: =P28+M29-N29-O29 -> 345460 | Q29: 0 | R29: 0 | S29: 1000 | T29: =T28+Q29-R29-S29 -> -411143
A30: 合川表计 | B30: 8月 | C30: 国网重庆合川供电公司2026年用电信息采集系统建筑相关工程施工(包4) | D30: 2026.8.24支付合川工资 | E30: 0 | F30: 0 | G30: 0 | H30: 0 | I30: 0 | J30: 0 | K30: 0 | M30: 0 | N30: 0 | O30: 0 | P30: =P29+M30-N30-O30 -> 345460 | Q30: 0 | R30: 0 | S30: 65000 | T30: =T29+Q30-R30-S30 -> -476143
A31: 合川表计 | B31: 6月 | C31: 国网重庆合川供电公司2026年用电信息采集系统建筑相关工程施工(包4) | D31: 2026.6.9陈庆奎银付：转伍建华预支工资 | E31: 0 | F31: 0 | G31: 0 | H31: 0 | I31: 0 | J31: 0 | K31: 0 | M31: 0 | N31: 0 | O31: 0 | P31: =P30+M31-N31-O31 -> 345460 | Q31: 0 | R31: 0 | S31: 5000 | T31: =T30+Q31-R31-S31 -> -481143
A32: 合川表计 | B32: 7月 | C32: 国网重庆合川供电公司2026年用电信息采集系统建筑相关工程施工(包4) | D32: 2026.7.11陈庆奎银付：转伍建华预支工资 | E32: 0 | F32: 0 | G32: 0 | H32: 0 | I32: 0 | J32: 0 | K32: 0 | M32: 0 | N32: 0 | O32: 0 | P32: =P31+M32-N32-O32 -> 345460 | Q32: 0 | R32: 0 | S32: 5000 | T32: =T31+Q32-R32-S32 -> -486143
A33: 合川表计 | B33: 7月 | C33: 国网重庆合川供电公司2026年用电信息采集系统建筑相关工程施工(包4) | D33: 2026.7.6陈庆奎银付：转伍建华预支工资 | E33: 0 | F33: 0 | G33: 0 | H33: 0 | I33: 0 | J33: 0 | K33: 0 | M33: 0 | N33: 0 | O33: 0 | P33: =P32+M33-N33-O33 -> 345460 | Q33: 0 | R33: 0 | S33: 5000 | T33: =T32+Q33-R33-S33 -> -491143
A34: 合川表计 | B34: 8月 | C34: 国网重庆合川供电公司2026年用电信息采集系统建筑相关工程施工(包4) | D34: 2026.8.21陈庆奎银付：转伍建华 | E34: 0 | F34: 0 | G34: 0 | H34: 0 | I34: 0 | J34: 0 | K34: 0 | M34: 0 | N34: 0 | O34: 0 | P34: =P33+M34-N34-O34 -> 345460 | Q34: 0 | R34: 0 | S34: 10000 | T34: =T33+Q34-R34-S34 -> -501143
A35: 合川表计 | B35: 8月 | C35: 国网重庆合川供电公司2026年用电信息采集系统建筑相关工程施工(包4) | D35: 2026.8.24陈庆奎银付：陈庆奎转向祥红合川表计工资 | E35: 0 | F35: 0 | G35: 0 | H35: 0 | I35: 0 | J35: 0 | K35: 0 | M35: 0 | N35: 0 | O35: 0 | P35: =P34+M35-N35-O35 -> 345460 | Q35: 0 | R35: 0 | S35: 9000 | T35: =T34+Q35-R35-S35 -> -510143
A36: 合川表计 | B36: 8月 | C36: 国网重庆合川供电公司2026年用电信息采集系统建筑相关工程施工(包4) | D36: 2026.8.24陈庆奎银付：陈庆奎转刘姜龙合川表计工资 | E36: 0 | F36: 0 | G36: 0 | H36: 0 | I36: 0 | J36: 0 | K36: 0 | M36: 0 | N36: 0 | O36: 0 | P36: =P35+M36-N36-O36 -> 345460 | Q36: 0 | R36: 0 | S36: 6000 | T36: =T35+Q36-R36-S36 -> -516143
... A45: 合川表计 | B45: 9月 | C45: 国网重庆合川供电公司2026年用电信息采集系统建筑相关工程施工(包4) | D45: 2026.9.22胡崇文支付表计工资 | E45: 0 | F45: 0 | G45: 0 | H45: 0 | I45: 0 | J45: 0 | K45: 0 | M45: 0 | N45: 0 | O45: 0 | P45: =P44+M45-N45-O45 -> 345460 | Q45: 0 | R45: 0 | S45: 10500 | T45: =T44+Q45-R45-S45 -> -576643
P46: =P45+M46-N46-O46 -> 345460 | T46: =T45+Q46-R46-S46 -> -576643
P47: =P46+M47-N47-O47 -> 345460 | T47: =T46+Q47-R47-S47 -> -576643
P48: =P47+M48-N48-O48 -> 345460 | T48: =T47+Q48-R48-S48 -> -576643

Sheet 云龙社区
A1: 云门街道云龙社区居民委员会(铁工厂还房建设项目)高压新装用电工程
A2: 对账 单位 | B2: 月份 | C2: 项目 名称 | D2: 摘要 | E2: 收票 单位 | F2: 发票 性质 | G2: 管理 费点 | H2: 销售金额 | I2: 管理费 | J2: 应开 成本票 | K2: 已开 成本票 | L2: 未开 成本票 | M2: 应收款 | N2: 质保金 | O2: 已收款 | P2: 未收款 | Q2: 应付 工程款 | R2: 扣除 管理费 | S2: 已付 工程款 | T2: 未付 工程款 | U2: 备注
H3: =SUM(H4:H306) -> 227260.8 | I3: =SUM(I4:I306) -> 0 | J3: =SUM(J4:J306) -> 227260.8 | K3: =SUM(K4:K306) -> 227260.8 | L3: =J3-K3 -> 0 | M3: =SUM(M4:M306) -> 227260.8 | N3: =SUM(N4:N306) -> 0 | O3: =SUM(O4:O306) -> 227260.8 | P3: =M3-O3 -> 0 | Q3: =SUM(Q4:Q306) -> 0 | R3: =SUM(R4:R306) -> 0 | S3: =SUM(S4:S306) -> 0 | T3: =SUM(T4:T306) -> 0 | U3: =SUM(U4:U306) -> 0
A4: {=_xlfn._xlws.FILTER(发票统计!A:K,发票统计!A:A=_wpsfn.SHEETSNAME(A2))} -> 云龙社区 | B4: 4月 | C4: 重庆市合川区云门街道云龙社区居民委员会(铁工厂还房建设项目)高压新装用电工程 | D4: 2026.4.28庆文开票给新德润：云龙社区居民委员会 | E4: 新德润 | F4: 3%专票 | G4: 0 | H4: 183486.24 | I4: 0 | J4: 183486.24 | K4: 183486.24 | L4: =J4-K4 -> 0 | M4: {=_xlfn._xlws.FILTER(发票统计!M:O,发票统计!A:A=_wpsfn.SHEETSNAME(A2))} -> 183486.24 | N4: 0 | O4: 0 | P4: =M4-N4 -> 183486.24 | Q4: {=_xlfn._xlws.FILTER(发票统计!Q:S,发票统计!A:A=_wpsfn.SHEETSNAME(A2))} -> 0 | R4: 0 | S4: 0 | T4: =Q4-R4 -> 0
A5: 云龙社区 | B5: 4月 | C5: 重庆市合川区云门街道云龙社区居民委员会(铁工厂还房建设项目)高压新装用电工程 | D5: 2026.4.30莨富收到新德润款项：云龙社区居民委员会 | E5: 新德润 | F5: 0 | G5: 0 | H5: 0 | I5: 0 | J5: 0 | K5: 0 | L5: =L4+J5-K5 -> 0 | M5: 0 | N5: 0 | O5: 183486.24 | P5: =P4+M5-N5-O5 -> 0 | Q5: 0 | R5: 0 | S5: 0 | T5: =T4+Q5-R5-S5 -> 0
A6: 云龙社区 | B6: 5月 | C6: 重庆市合川区云门街道云龙社区居民委员会(铁工厂还房建设项目)高压新装用电工程 | D6: 2026.5.7庆文开票给新德润：云龙社区居民委员会 | E6: 新德润 | F6: 3%专票 | G6: 0 | H6: 43774.56 | I6: 0 | J6: 43774.56 | K6: 43774.56 | L6: =L5+J6-K6 -> 0 | M6: 43774.56 | N6: 0 | O6: 0 | P6: =P5+M6-N6-O6 -> 43774.56 | Q6: 0 | R6: 0 | S6: 0 | T6: =T5+Q6-R6-S6 -> 0
A7: 云龙社区 | B7: 5月 | C7: 重庆市合川区云门街道云龙社区居民委员会(铁工厂还房建设项目)高压新装用电工程 | D7: 2026.5.13庆文公账收到新德润款项：云龙社区居民委员会 | E7: 新德润 | F7: 0 | G7: 0 | H7: 0 | I7: 0 | J7: 0 | K7: 0 | L7: =L6+J7-K7 -> 0 | M7: 0 | N7: 0 | O7: 43774.56 | P7: =P6+M7-N7-O7 -> 0 | Q7: 0 | R7: 0 | S7: 0 | T7: =T6+Q7-R7-S7 -> 0
L8: =L7+J8-K8 -> 0 | P8: =P7+M8-N8-O8 -> 0 | T8: =T7+Q8-R8-S8 -> 0
L9: =L8+J9-K9 -> 0 | P9: =P8+M9-N9-O9 -> 0 | T9: =T8+Q9-R9-S9 -> 0
L10: =L9+J10-K10 -> 0 | P10: =P9+M10-N10-O10 -> 0 | T10: =T9+Q10-R10-S10 -> 0
L11: =L10+J11-K11 -> 0 | P11: =P10+M11-N11-O11 -> 0 | T11: =T10+Q11-R11-S11 -> 0
L12: =L11+J12-K12 -> 0 | P12: =P11+M12-N12-O12 -> 0 | T12: =T11+Q12-R12-S12 -> 0
L13: =L12+J13-K13 -> 0 | P13: =P12+M13-N13-O13 -> 0 | T13: =T12+Q13-R13-S13 -> 0
L14: =L13+J14-K14 -> 0 | P14: =P13+M14-N14-O14 -> 0
L15: =L14+J15-K15 -> 0 | P15: =P14+M15-N15-O15 -> 0
L16: =L15+J16-K16 -> 0 | P16: =P15+M16-N16-O16 -> 0
L17: =L16+J17-K17 -> 0 | P17: =P16+M17-N17-O17 -> 0
L18: =L17+J18-K18 -> 0 | P18: =P17+M18-O18 -> 0
L19: =L18+J19-K19 -> 0 | P19: =P18+M19-O19 -> 0
L20: =L19+J20-K20 -> 0 | P20: =P19+M20-O20 -> 0
L21: =L20+J21-K21 -> 0 | P21: =P20+M21-O21 -> 0
L22: =L21+J22-K22 -> 0 | P22: =P21+M22-O22 -> 0
L23: =L22+J23-K23 -> 0 | P23: =P22+M23-O23 -> 0
L24: =L23+J24-K24 -> 0 | P24: =P23+M24-O24 -> 0
P25: =P24+M25-O25 -> 0
P26: =P25+M26-O26 -> 0
P27: =P26+M27-O27 -> 0
P28: =P27+M28-O28 -> 0
P29: =P28+M29-O29 -> 0
P30: =P29+M30-O30 -> 0
P31: =P30+M31-O31 -> 0
P32: =P31+M32-O32 -> 0
P33: =P32+M33-O33 -> 0
P34: =P33+M34-O34 -> 0

Sheet 铜城2回、玉璟尚线、铁井一回、淮拦线4
A1: 铜城2回、玉璟尚线、铁井一回、淮拦线4
A2: 对账 单位 | B2: 月份 | C2: 项目 名称 | D2: 摘要 | E2: 收票 单位 | F2: 发票 性质 | G2: 管理 费点 | H2: 销售金额 | I2: 管理费 | J2: 应开 成本票 | K2: 已开 成本票 | L2: 未开 成本票 | M2: 应收款 | N2: 质保金 | O2: 已收款 | P2: 未收款 | Q2: 应付 工程款 | R2: 扣除 管理费 | S2: 已付 工程款 | T2: 未付 工程款 | U2: 备注
H3: =SUM(H4:H306) -> 121598.1 | I3: =SUM(I4:I306) -> 12159.81 | J3: =SUM(J4:J306) -> 109438.29 | K3: =SUM(K4:K306) -> 167000 | L3: =J3-K3 -> -57561.71 | M3: =SUM(M4:M306) -> 121598.1 | N3: =SUM(N4:N306) -> 0 | O3: =SUM(O4:O306) -> 115307.26 | P3: =M3-O3 -> 6290.84 | Q3: =SUM(Q4:Q306) -> 0 | R3: =SUM(R4:R306) -> 0 | S3: =SUM(S4:S306) -> 0 | T3: =SUM(T4:T306) -> 0 | U3: =SUM(U4:U306) -> 0
A4: {=_xlfn._xlws.FILTER(发票统计!A:K,发票统计!A:A=_wpsfn.SHEETSNAME(A2))} -> 铜城2回、玉璟尚线、铁井一回、淮拦线4 | B4: 6月 | C4: 重庆铜梁铜城2回金龙物业管理有限公司10kV业扩配套工程 | D4: 2026.6.24新德润开票民能：铜城2回，10%管理费 | E4: 民能 | F4: 3%专票 | G4: 0.1 | H4: 4002.66 | I4: 400.266 | J4: 3602.394 | K4: 0 | L4: =J4-K4 -> 3602.394 | M4: {=_xlfn._xlws.FILTER(发票统计!M:O,发票统计!A:A=_wpsfn.SHEETSNAME(A2))} -> 4002.66 | N4: 0 | O4: 0 | P4: =M4-N4 -> 4002.66 | Q4: {=_xlfn._xlws.FILTER(发票统计!Q:S,发票统计!A:A=_wpsfn.SHEETSNAME(A2))} -> 0 | R4: 0 | S4: 0 | T4: =Q4-R4 -> 0
A5: 铜城2回、玉璟尚线、铁井一回、淮拦线4 | B5: 6月 | C5: 重庆铜梁玉璟尚线金龙物业管理有限公司10kV业扩配套工程 | D5: 2026.6.24新德润开票民能：玉璟尚线，10%管理费 | E5: 民能 | F5: 3%专票 | G5: 0.1 | H5: 13079.84 | I5: 1307.984 | J5: 11771.856 | K5: 0 | L5: =L4+J5-K5 -> 15374.25 | M5: 13079.84 | N5: 0 | O5: 0 | P5: =P4+M5-N5-O5 -> 17082.5 | Q5: 0 | R5: 0 | S5: 0 | T5: =T4+Q5-R5-S5 -> 0
A6: 铜城2回、玉璟尚线、铁井一回、淮拦线4 | B6: 6月 | C6: 重庆铜梁铁井一回1#环网柜等6个10kV老旧环网柜改造工程(安装) | D6: 2026.6.24新德润开票民能：铁井一回1#环网柜，10%管理费 | E6: 民能 | F6: 3%专票 | G6: 0.1 | H6: 47546.28 | I6: 4754.628 | J6: 42791.652 | K6: 0 | L6: =L5+J6-K6 -> 58165.902 | M6: 47546.28 | N6: 0 | O6: 0 | P6: =P5+M6-N6-O6 -> 64628.78 | Q6: 0 | R6: 0 | S6: 0 | T6: =T5+Q6-R6-S6 -> 0
A7: 铜城2回、玉璟尚线、铁井一回、淮拦线4 | B7: 6月 | C7: 重庆铜梁淮拦线4#环网柜等6个10kV老旧环网柜改造工程（安装） | D7: 2026.6.24新德润开票民能：淮拦线4#环网柜，10%管理费 | E7: 民能 | F7: 3%专票 | G7: 0.1 | H7: 56969.32 | I7: 5696.932 | J7: 51272.388 | K7: 0 | L7: =L6+J7-K7 -> 109438.29 | M7: 56969.32 | N7: 0 | O7: 0 | P7: =P6+M7-N7-O7 -> 121598.1 | Q7: 0 | R7: 0 | S7: 0 | T7: =T6+Q7-R7-S7 -> 0
A8: 铜城2回、玉璟尚线、铁井一回、淮拦线4 | B8: 6月 | C8: 重庆铜梁淮拦线4#环网柜等6个10kV老旧环网柜改造工程（安装） | D8: 2026.6.23桐桐建材开票到新德润：淮拦、铁井、玉璟、铜城2回 | E8: 新德润 | F8: 1%普票 | G8: 0 | H8: 0 | I8: 0 | J8: 0 | K8: 67200 | L8: =L7+J8-K8 -> 42238.29 | M8: 0 | N8: 0 | O8: 0 | P8: =P7+M8-N8-O8 -> 121598.1 | Q8: 0 | R8: 0 | S8: 0 | T8: =T7+Q8-R8-S8 -> 0
A9: 铜城2回、玉璟尚线、铁井一回、淮拦线4 | B9: 6月 | C9: 重庆铜梁淮拦线4#环网柜等6个10kV老旧环网柜改造工程（安装） | D9: 2026.6.24宜宾翠屏开票到新德润淮：淮拦、铁井、玉璟、铜城2回 | E9: 新德润 | F9: 1%普票 | G9: 0 | H9: 0 | I9: 0 | J9: 0 | K9: 42800 | L9: =L8+J9-K9 -> -561.71 | M9: 0 | N9: 0 | O9: 0 | P9: =P8+M9-N9-O9 -> 121598.1 | Q9: 0 | R9: 0 | S9: 0 | T9: =T8+Q9-R9-S9 -> 0
A10: 铜城2回、玉璟尚线、铁井一回、淮拦线4 | B10: 9月 | C10: 重庆铜梁淮拦线4#环网柜等6个10kV老旧环网柜改造工程（安装） | D10: 2026.9.14新德润扣8月民能农民工工资个税 | E10: 新德润 | F10: 1%普票 | G10: 0 | H10: 0 | I10: 0 | J10: 0 | K10: 57000 | L10: =L9+J10-K10 -> -57561.71 | M10: 0 | N10: 0 | O10: 810 | P10: =P9+M10-N10-O10 -> 120788.1 | Q10: 0 | R10: 0 | S10: 0 | T10: =T9+Q10-R10-S10 -> 0
A11: 铜城2回、玉璟尚线、铁井一回、淮拦线4 | B11: 9月 | C11: 重庆铜梁铁井一回1#环网柜等6个10kV老旧环网柜改造工程(安装) | D11: 2026.9.14新德润扣8月民能农民工工资：铁井一回1 | E11: 新德润 | F11: 0 | G11: 0 | H11: 0 | I11: 0 | J11: 0 | K11: 0 | L11: =L10+J11-K11 -> -57561.71 | M11: 0 | N11: 0 | O11: 22000 | P11: =P10+M11-N11-O11 -> 98788.1 | Q11: 0 | R11: 0 | S11: 0 | T11: =T10+Q11-R11-S11 -> 0
A12: 铜城2回、玉璟尚线、铁井一回、淮拦线4 | B12: 9月 | C12: 重庆铜梁淮拦线4#环网柜等6个10kV老旧环网柜改造工程（安装） | D12: 2026.9.14新德润扣8月民能农民工工资：淮拦线4 | E12: 新德润 | F12: 0 | G12: 0 | H12: 0 | I12: 0 | J12: 0 | K12: 0 | L12: =L11+J12-K12 -> -57561.71 | M12: 0 | N12: 0 | O12: 27000 | P12: =P11+M12-N12-O12 -> 71788.1 | Q12: 0 | R12: 0 | S12: 0 | T12: =T11+Q12-R12-S12 -> 0
A13: 铜城2回、玉璟尚线、铁井一回、淮拦线4 | B13: 9月 | C13: 重庆铜梁铜城2回金龙物业管理有限公司10kV业扩配套工程 | D13: 2026.9.14新德润扣8月民能农民工工资：铜城2回 | E13: 新德润 | F13: 0 | G13: 0 | H13: 0 | I13: 0 | J13: 0 | K13: 0 | L13: =L12+J13-K13 -> -57561.71 | M13: 0 | N13: 0 | O13: 2000 | P13: =P12+M13-N13-O13 -> 69788.1 | Q13: 0 | R13: 0 | S13: 0 | T13: =T12+Q13-R13-S13 -> 0
A14: 铜城2回、玉璟尚线、铁井一回、淮拦线4 | B14: 9月 | C14: 重庆铜梁玉璟尚线金龙物业管理有限公司10kV业扩配套工程 | D14: 2026.9.14新德润扣8月民能农民工工资：玉璟尚线 | E14: 新德润 | F14: 0 | G14: 0 | H14: 0 | I14: 0 | J14: 0 | K14: 0 | L14: =L13+J14-K14 -> -57561.71 | M14: 0 | N14: 0 | O14: 6000 | P14: =P13+M14-N14-O14 -> 63788.1 | Q14: 0 | R14: 0 | S14: 0 | T14: {=铜城2回、玉璟尚线、铁井一回、淮拦线4!T12:T12+铜城2回、玉璟尚线、铁井一回、淮拦线4!Q13:Q13-铜城2回、玉璟尚线、铁井一回、淮拦线4!R13:R13-铜城2回、玉璟尚线、铁井一回、淮拦线4!S13:S13} -> 0
A15: 铜城2回、玉璟尚线、铁井一回、淮拦线4 | B15: 9月 | C15: 重庆铜梁淮拦线4#环网柜等6个10kV老旧环网柜改造工程（安装） | D15: 2026.9.14新德润扣工资残保金1.5% | E15: 新德润 | F15: 0 | G15: 0 | H15: 0 | I15: 0 | J15: 0 | K15: 0 | L15: =L14+J15-K15 -> -57561.71 | M15: 0 | N15: 0 | O15: 1823.97 | P15: =P14+M15-N15-O15 -> 61964.13 | Q15: 0 | R15: 0 | S15: 0 | T15: {=铜城2回、玉璟尚线、铁井一回、淮拦线4!T13:T13+铜城2回、玉璟尚线、铁井一回、淮拦线4!Q14:Q14-铜城2回、玉璟尚线、铁井一回、淮拦线4!R14:R14-铜城2回、玉璟尚线、铁井一回、淮拦线4!S14:S14} -> 0
A16: 铜城2回、玉璟尚线、铁井一回、淮拦线4 | B16: 9月 | C16: 重庆铜梁淮拦线4#环网柜等6个10kV老旧环网柜改造工程（安装） | D16: 2026.9.14新德润扣增值税3541.69，附加税425，印花税72.96 | E16: 新德润 | F16: 0 | G16: 0 | H16: 0 | I16: 0 | J16: 0 | K16: 0 | L16: =L15+J16-K16 -> -57561.71 | M16: 0 | N16: 0 | O16: 4039.65 | P16: =P15+M16-N16-O16 -> 57924.48 | Q16: 0 | R16: 0 | S16: 0 | T16: {=铜城2回、玉璟尚线、铁井一回、淮拦线4!T14:T14+铜城2回、玉璟尚线、铁井一回、淮拦线4!Q15:Q15-铜城2回、玉璟尚线、铁井一回、淮拦线4!R15:R15-铜城2回、玉璟尚线、铁井一回、淮拦线4!S15:S15} -> 0
A17: 铜城2回、玉璟尚线、铁井一回、淮拦线4 | B17: 9月 | C17: 重庆铜梁淮拦线4#环网柜等6个10kV老旧环网柜改造工程（安装） | D17: 2026.9.14新德润扣管理费 | E17: 新德润 | F17: 0 | G17: 0 | H17: 0 | I17: 0 | J17: 0 | K17: 0 | L17: =L16+J17-K17 -> -57561.71 | M17: 0 | N17: 0 | O17: 12159.81 | P17: =P16+M17-N17-O17 -> 45764.67 | Q17: 0 | R17: 0 | S17: 0 | T17: {=铜城2回、玉璟尚线、铁井一回、淮拦线4!T15:T15+铜城2回、玉璟尚线、铁井一回、淮拦线4!Q16:Q16-铜城2回、玉璟尚线、铁井一回、淮拦线4!R16:R16-铜城2回、玉璟尚线、铁井一回、淮拦线4!S16:S16} -> 0
A18: 铜城2回、玉璟尚线、铁井一回、淮拦线4 | B18: 9月 | C18: 重庆铜梁淮拦线4#环网柜等6个10kV老旧环网柜改造工程（安装） | D18: 2026.9.14新德润代胡崇文支付宜宾翠屏货款：42800-39473.83=3326.17 | E18: 新德润 | F18: 0 | G18: 0 | H18: 0 | I18: 0 | J18: 0 | K18: 0 | L18: =L17+J18-K18 -> -57561.71 | M18: 0 | N18: 0 | O18: 39473.83 | P18: =P17+M18-O18 -> 6290.84 | Q18: 0 | R18: 0 | S18: 0 | T18: {=铜城2回、玉璟尚线、铁井一回、淮拦线4!T16:T16+铜城2回、玉璟尚线、铁井一回、淮拦线4!Q17:Q17-铜城2回、玉璟尚线、铁井一回、淮拦线4!R17:R17-铜城2回、玉璟尚线、铁井一回、淮拦线4!S17:S17} -> 0
L19: =L18+J19-K19 -> -57561.71 | P19: =P18+M19-O19 -> 6290.84 | T19: {=铜城2回、玉璟尚线、铁井一回、淮拦线4!T17:T17+铜城2回、玉璟尚线、铁井一回、淮拦线4!Q18:Q18-铜城2回、玉璟尚线、铁井一回、淮拦线4!R18:R18-铜城2回、玉璟尚线、铁井一回、淮拦线4!S18:S18} -> 0
L20: =L19+J20-K20 -> -57561.71 | P20: =P19+M20-O20 -> 6290.84 | T20: {=铜城2回、玉璟尚线、铁井一回、淮拦线4!T18:T18+铜城2回、玉璟尚线、铁井一回、淮拦线4!Q19:Q19-铜城2回、玉璟尚线、铁井一回、淮拦线4!R19:R19-铜城2回、玉璟尚线、铁井一回、淮拦线4!S19:S19} -> 0
L21: =L20+J21-K21 -> -57561.71 | P21: =P20+M21-O21 -> 6290.84 | T21: {=铜城2回、玉璟尚线、铁井一回、淮拦线4!T19:T19+铜城2回、玉璟尚线、铁井一回、淮拦线4!Q20:Q20-铜城2回、玉璟尚线、铁井一回、淮拦线4!R20:R20-铜城2回、玉璟尚线、铁井一回、淮拦线4!S20:S20} -> 0
L22: =L21+J22-K22 -> -57561.71 | P22: =P21+M22-O22 -> 6290.84 | T22: {=铜城2回、玉璟尚线、铁井一回、淮拦线4!T20:T20+铜城2回、玉璟尚线、铁井一回、淮拦线4!Q21:Q21-铜城2回、玉璟尚线、铁井一回、淮拦线4!R21:R21-铜城2回、玉璟尚线、铁井一回、淮拦线4!S21:S21} -> 0
L23: =L22+J23-K23 -> -57561.71 | P23: =P22+M23-O23 -> 6290.84 | T23: {=铜城2回、玉璟尚线、铁井一回、淮拦线4!T21:T21+铜城2回、玉璟尚线、铁井一回、淮拦线4!Q22:Q22-铜城2回、玉璟尚线、铁井一回、淮拦线4!R22:R22-铜城2回、玉璟尚线、铁井一回、淮拦线4!S22:S22} -> 0
L24: =L23+J24-K24 -> -57561.71 | P24: =P23+M24-O24 -> 6290.84 | T24: {=铜城2回、玉璟尚线、铁井一回、淮拦线4!T22:T22+铜城2回、玉璟尚线、铁井一回、淮拦线4!Q23:Q23-铜城2回、玉璟尚线、铁井一回、淮拦线4!R23:R23-铜城2回、玉璟尚线、铁井一回、淮拦线4!S23:S23} -> 0
L25: =L24+J25-K25 -> -57561.71 | P25: =P24+M25-O25 -> 6290.84 | T25: {=铜城2回、玉璟尚线、铁井一回、淮拦线4!T23:T23+铜城2回、玉璟尚线、铁井一回、淮拦线4!Q24:Q24-铜城2回、玉璟尚线、铁井一回、淮拦线4!R24:R24-铜城2回、玉璟尚线、铁井一回、淮拦线4!S24:S24} -> 0
L26: =L25+J26-K26 -> -57561.71 | P26: =P25+M26-O26 -> 6290.84 | T26: {=铜城2回、玉璟尚线、铁井一回、淮拦线4!T24:T24+铜城2回、玉璟尚线、铁井一回、淮拦线4!Q25:Q25-铜城2回、玉璟尚线、铁井一回、淮拦线4!R25:R25-铜城2回、玉璟尚线、铁井一回、淮拦线4!S25:S25} -> 0
L27: =L26+J27-K27 -> -57561.71 | P27: =P26+M27-O27 -> 6290.84 | T27: {=铜城2回、玉璟尚线、铁井一回、淮拦线4!T25:T25+铜城2回、玉璟尚线、铁井一回、淮拦线4!Q26:Q26-铜城2回、玉璟尚线、铁井一回、淮拦线4!R26:R26-铜城2回、玉璟尚线、铁井一回、淮拦线4!S26:S26} -> 0
L28: =L27+J28-K28 -> -57561.71 | P28: =P27+M28-O28 -> 6290.84 | T28: {=铜城2回、玉璟尚线、铁井一回、淮拦线4!T26:T26+铜城2回、玉璟尚线、铁井一回、淮拦线4!Q27:Q27-铜城2回、玉璟尚线、铁井一回、淮拦线4!R27:R27-铜城2回、玉璟尚线、铁井一回、淮拦线4!S27:S27} -> 0
L29: =L28+J29-K29 -> -57561.71 | P29: =P28+M29-O29 -> 6290.84 | T29: {=铜城2回、玉璟尚线、铁井一回、淮拦线4!T27:T27+铜城2回、玉璟尚线、铁井一回、淮拦线4!Q28:Q28-铜城2回、玉璟尚线、铁井一回、淮拦线4!R28:R28-铜城2回、玉璟尚线、铁井一回、淮拦线4!S28:S28} -> 0
L30: =L29+J30-K30 -> -57561.71 | P30: =P29+M30-O30 -> 6290.84 | T30: {=铜城2回、玉璟尚线、铁井一回、淮拦线4!T28:T28+铜城2回、玉璟尚线、铁井一回、淮拦线4!Q29:Q29-铜城2回、玉璟尚线、铁井一回、淮拦线4!R29:R29-铜城2回、玉璟尚线、铁井一回、淮拦线4!S29:S29} -> 0
... L77: =L76+J77-K77 -> -57561.71 | P77: =P76+M77-O77 -> 6290.84 | T77: {=铜城2回、玉璟尚线、铁井一回、淮拦线4!T75:T75+铜城2回、玉璟尚线、铁井一回、淮拦线4!Q76:Q76-铜城2回、玉璟尚线、铁井一回、淮拦线4!R76:R76-铜城2回、玉璟尚线、铁井一回、淮拦线4!S76:S76} -> 0
P78: =P77+M78-O78 -> 6290.84 | T78: {=铜城2回、玉璟尚线、铁井一回、淮拦线4!T76:T76+铜城2回、玉璟尚线、铁井一回、淮拦线4!Q77:Q77-铜城2回、玉璟尚线、铁井一回、淮拦线4!R77:R77-铜城2回、玉璟尚线、铁井一回、淮拦线4!S77:S77} -> 0
P79: =P78+M79-O79 -> 6290.84 | T79: {=铜城2回、玉璟尚线、铁井一回、淮拦线4!T77:T77+铜城2回、玉璟尚线、铁井一回、淮拦线4!Q78:Q78-铜城2回、玉璟尚线、铁井一回、淮拦线4!R78:R78-铜城2回、玉璟尚线、铁井一回、淮拦线4!S78:S78} -> 0
P80: =P79+M80-O80 -> 6290.84 | T80: {=铜城2回、玉璟尚线、铁井一回、淮拦线4!T78:T78+铜城2回、玉璟尚线、铁井一回、淮拦线4!Q79:Q79-铜城2回、玉璟尚线、铁井一回、淮拦线4!R79:R79-铜城2回、玉璟尚线、铁井一回、淮拦线4!S79:S79} -> 0
P81: =P80+M81-O81 -> 6290.84 | T81: {=铜城2回、玉璟尚线、铁井一回、淮拦线4!T79:T79+铜城2回、玉璟尚线、铁井一回、淮拦线4!Q80:Q80-铜城2回、玉璟尚线、铁井一回、淮拦线4!R80:R80-铜城2回、玉璟尚线、铁井一回、淮拦线4!S80:S80} -> 0
P82: =P81+M82-O82 -> 6290.84 | T82: {=铜城2回、玉璟尚线、铁井一回、淮拦线4!T80:T80+铜城2回、玉璟尚线、铁井一回、淮拦线4!Q81:Q81-铜城2回、玉璟尚线、铁井一回、淮拦线4!R81:R81-铜城2回、玉璟尚线、铁井一回、淮拦线4!S81:S81} -> 0
P83: =P82+M83-O83 -> 6290.84 | T83: {=铜城2回、玉璟尚线、铁井一回、淮拦线4!T81:T81+铜城2回、玉璟尚线、铁井一回、淮拦线4!Q82:Q82-铜城2回、玉璟尚线、铁井一回、淮拦线4!R82:R82-铜城2回、玉璟尚线、铁井一回、淮拦线4!S82:S82} -> 0

Sheet 合川瑞翔
A1: 云门街道云龙社区居民委员会(铁工厂还房建设项目)高压新装用电工程
A2: 对账 单位 | B2: 月份 | C2: 项目 名称 | D2: 摘要 | E2: 收票 单位 | F2: 发票 性质 | G2: 管理 费点 | H2: 销售金额 | I2: 管理费 | J2: 应开 成本票 | K2: 已开 成本票 | L2: 未开 成本票 | M2: 应收款 | N2: 质保金 | O2: 已收款 | P2: 未收款 | Q2: 应付 工程款 | R2: 扣除 管理费 | S2: 已付 工程款 | T2: 未付 工程款 | U2: 备注
H3: =SUM(H4:H306) -> 500000 | I3: =SUM(I4:I306) -> 0 | J3: =SUM(J4:J306) -> 500000 | K3: =SUM(K4:K306) -> 500000 | L3: =J3-K3 -> 0 | M3: =SUM(M4:M306) -> 500000 | N3: =SUM(N4:N306) -> 0 | O3: =SUM(O4:O306) -> 503326.17 | P3: =M3-O3 -> -3326.17 | Q3: =SUM(Q4:Q306) -> 0 | R3: =SUM(R4:R306) -> 0 | S3: =SUM(S4:S306) -> 0 | T3: =SUM(T4:T306) -> 0 | U3: =SUM(U4:U306) -> 0
A4: {=_xlfn._xlws.FILTER(发票统计!A:K,发票统计!A:A=_wpsfn.SHEETSNAME(A2))} -> 合川瑞翔 | B4: 6月 | C4: 高新区厂房及配套设施提质改造项目开票到瑞翔厂区电力土建(管廊)建设工程 | D4: 2026.6.17庆文开票给新德润：瑞翔厂区电力土建 | E4: 新德润 | F4: 1%专票 | G4: 0 | H4: 100000 | I4: 0 | J4: 100000 | K4: 100000 | L4: =J4-K4 -> 0 | M4: {=_xlfn._xlws.FILTER(发票统计!M:O,发票统计!A:A=_wpsfn.SHEETSNAME(A2))} -> 100000 | N4: 0 | O4: 0 | P4: =M4-N4 -> 100000 | Q4: {=_xlfn._xlws.FILTER(发票统计!Q:S,发票统计!A:A=_wpsfn.SHEETSNAME(A2))} -> 0 | R4: 0 | S4: 0 | T4: =Q4-R4 -> 0
A5: 合川瑞翔 | B5: 6月 | C5: 高新区厂房及配套设施提质改造项目开票到瑞翔厂区电力土建(管廊)建设工程 | D5: 2026.6.18庆文收到新德润打款：瑞翔厂区电力 | E5: 新德润 | F5: 0 | G5: 0 | H5: 0 | I5: 0 | J5: 0 | K5: 0 | L5: =L4+J5-K5 -> 0 | M5: 0 | N5: 0 | O5: 100000 | P5: =P4+M5-N5-O5 -> 0 | Q5: 0 | R5: 0 | S5: 0 | T5: =T4+Q5-R5-S5 -> 0
A6: 合川瑞翔 | B6: 7月 | C6: 高新区厂房及配套设施提质改造项目开票到瑞翔厂区电力土建(管廊)建设工程 | D6: 2026.7.2朱氏水泥管件开票到新德润：瑞翔厂区电力土建 | E6: 新德润 | F6: 1%普票 | G6: 0 | H6: 50200 | I6: 0 | J6: 50200 | K6: 50200 | L6: =L5+J6-K6 -> 0 | M6: 50200 | N6: 0 | O6: 0 | P6: =P5+M6-N6-O6 -> 50200 | Q6: 0 | R6: 0 | S6: 0 | T6: =T5+Q6-R6-S6 -> 0
A7: 合川瑞翔 | B7: 7月 | C7: 高新区厂房及配套设施提质改造项目开票到瑞翔厂区电力土建(管廊)建设工程 | D7: 2026.7.6朱氏水泥管收到新德润：瑞翔厂区电力 | E7: 新德润 | F7: 0 | G7: 0 | H7: 0 | I7: 0 | J7: 0 | K7: 0 | L7: =L6+J7-K7 -> 0 | M7: 0 | N7: 0 | O7: 50200 | P7: =P6+M7-N7-O7 -> 0 | Q7: 0 | R7: 0 | S7: 0 | T7: =T6+Q7-R7-S7 -> 0
A8: 合川瑞翔 | B8: 7月 | C8: 高新区厂房及配套设施提质改造项目开票到瑞翔厂区电力土建(管廊)建设工程 | D8: 2026.7.8庆文开票给新德润：瑞翔厂区电力土建 | E8: 新德润 | F8: 1%专票 | G8: 0 | H8: 100000 | I8: 0 | J8: 100000 | K8: 100000 | L8: =L7+J8-K8 -> 0 | M8: 100000 | N8: 0 | O8: 0 | P8: =P7+M8-N8-O8 -> 100000 | Q8: 0 | R8: 0 | S8: 0 | T8: =T7+Q8-R8-S8 -> 0
A9: 合川瑞翔 | B9: 7月 | C9: 高新区厂房及配套设施提质改造项目开票到瑞翔厂区电力土建(管廊)建设工程 | D9: 2026.7.9庆文收到新德润打款：瑞翔厂区电力 | E9: 新德润 | F9: 0 | G9: 0 | H9: 0 | I9: 0 | J9: 0 | K9: 0 | L9: =L8+J9-K9 -> 0 | M9: 0 | N9: 0 | O9: 100000 | P9: =P8+M9-N9-O9 -> 0 | Q9: 0 | R9: 0 | S9: 0 | T9: =T8+Q9-R9-S9 -> 0
A10: 合川瑞翔 | B10: 7月 | C10: 高新区厂房及配套设施提质改造项目开票到瑞翔厂区电力土建(管廊)建设工程 | D10: 2026.7.8铜桐桐建材开票到新德润：瑞翔厂区电力土建 | E10: 新德润 | F10: 1%普票 | G10: 0 | H10: 49800 | I10: 0 | J10: 49800 | K10: 49800 | L10: =L9+J10-K10 -> 0 | M10: 49800 | N10: 0 | O10: 0 | P10: =P9+M10-N10-O10 -> 49800 | Q10: 0 | R10: 0 | S10: 0 | T10: =T9+Q10-R10-S10 -> 0
A11: 合川瑞翔 | B11: 7月 | C11: 高新区厂房及配套设施提质改造项目开票到瑞翔厂区电力土建(管廊)建设工程 | D11: 2026.7.7号收到新德润打款给胡崇文：瑞翔厂区电力 | E11: 新德润 | F11: 0 | G11: 0 | H11: 0 | I11: 0 | J11: 0 | K11: 0 | L11: =L10+J11-K11 -> 0 | M11: 0 | N11: 0 | O11: 49800 | P11: =P10+M11-N11-O11 -> 0 | Q11: 0 | R11: 0 | S11: 0 | T11: =T10+Q11-R11-S11 -> 0
A12: 合川瑞翔 | B12: 7月 | C12: 高新区厂房及配套设施提质改造项目开票到瑞翔厂区电力土建(管廊)建设工程 | D12: 2026.7.13小溪建材开票到新德润：瑞翔厂区电力土建 | E12: 新德润 | F12: 13%专票 | G12: 0 | H12: 50220 | I12: 0 | J12: 50220 | K12: 50220 | L12: =L11+J12-K12 -> 0 | M12: 50220 | N12: 0 | O12: 0 | P12: =P11+M12-N12-O12 -> 50220 | Q12: 0 | R12: 0 | S12: 0 | T12: =T11+Q12-R12-S12 -> 0
A13: 合川瑞翔 | B13: 7月 | C13: 高新区厂房及配套设施提质改造项目开票到瑞翔厂区电力土建(管廊)建设工程 | D13: 2026.7.15小溪建材收到新德润打款：瑞翔厂区电力 | E13: 新德润 | F13: 0 | G13: 0 | H13: 0 | I13: 0 | J13: 0 | K13: 0 | L13: =L12+J13-K13 -> 0 | M13: 0 | N13: 0 | O13: 50220 | P13: =P12+M13-N13-O13 -> 0 | Q13: 0 | R13: 0 | S13: 0 | T13: =T12+Q13-R13-S13 -> 0
A14: 合川瑞翔 | B14: 7月 | C14: 高新区厂房及配套设施提质改造项目开票到瑞翔厂区电力土建(管廊)建设工程 | D14: 2026.7.13旭承机械开票到新德润：瑞翔厂区电力土建 | E14: 新德润 | F14: 1%普票 | G14: 0 | H14: 100000 | I14: 0 | J14: 100000 | K14: 100000 | L14: =L13+J14-K14 -> 0 | M14: 100000 | N14: 0 | O14: 0 | P14: =P13+M14-N14-O14 -> 100000 | Q14: 0 | R14: 0 | S14: 0 | T14: =T13+Q14-R14-S14 -> 0
A15: 合川瑞翔 | B15: 7月 | C15: 高新区厂房及配套设施提质改造项目开票到瑞翔厂区电力土建(管廊)建设工程 | D15: 2026.7.15旭承机械收到新德润打款：瑞翔厂区电力土建 | E15: 新德润 | F15: 0 | G15: 0 | H15: 0 | I15: 0 | J15: 0 | K15: 0 | L15: =L14+J15-K15 -> 0 | M15: 0 | N15: 0 | O15: 100000 | P15: =P14+M15-N15-O15 -> 0 | Q15: 0 | R15: 0 | S15: 0 | T15: =T14+Q15-R15-S15 -> 0
A16: 合川瑞翔 | B16: 7月 | C16: 高新区厂房及配套设施提质改造项目开票到瑞翔厂区电力土建(管廊)建设工程 | D16: 2026.7.14凯樽物资开票到新德润：瑞翔厂区电力土建 | E16: 新德润 | F16: 13%专票 | G16: 0 | H16: 49780 | I16: 0 | J16: 49780 | K16: 49780 | L16: =L15+J16-K16 -> 0 | M16: 49780 | N16: 0 | O16: 0 | P16: =P15+M16-N16-O16 -> 49780 | Q16: 0 | R16: 0 | S16: 0 | T16: =T15+Q16-R16-S16 -> 0
A17: 合川瑞翔 | B17: 7月 | C17: 高新区厂房及配套设施提质改造项目开票到瑞翔厂区电力土建(管廊)建设工程 | D17: 2026.7.15凯樽物资收到新德润打款：瑞翔厂区电力土建 | E17: 新德润 | F17: 0 | G17: 0 | H17: 0 | I17: 0 | J17: 0 | K17: 0 | L17: =L16+J17-K17 -> 0 | M17: 0 | N17: 0 | O17: 49780 | P17: =P16+M17-N17-O17 -> 0 | Q17: 0 | R17: 0 | S17: 0 | T17: =T16+Q17-R17-S17 -> 0
A18: 合川瑞翔 | B18: 9月 | C18: 高新区厂房及配套设施提质改造项目开票到瑞翔厂区电力土建(管廊)建设工程 | D18: 2026.9.14新德润代胡崇文支付宜宾翠屏货款：42800-39473.83=3326.17 | E18: 新德润 | F18: 0 | G18: 0 | H18: 0 | I18: 0 | J18: 0 | K18: 0 | L18: =L17+J18-K18 -> 0 | M18: 0 | N18: 0 | O18: 3326.17 | P18: =P17+M18-O18 -> -3326.17 | Q18: 0 | R18: 0 | S18: 0 | T18: =T17+Q18-R18-S18 -> 0
L19: =L18+J19-K19 -> 0 | P19: =P18+M19-O19 -> -3326.17 | T19: =T18+Q19-R19-S19 -> 0
L20: =L19+J20-K20 -> 0 | P20: =P19+M20-O20 -> -3326.17 | T20: =T19+Q20-R20-S20 -> 0
L21: =L20+J21-K21 -> 0 | P21: =P20+M21-O21 -> -3326.17 | T21: =T20+Q21-R21-S21 -> 0
L22: =L21+J22-K22 -> 0 | P22: =P21+M22-O22 -> -3326.17 | T22: =T21+Q22-R22-S22 -> 0
L23: =L22+J23-K23 -> 0 | P23: =P22+M23-O23 -> -3326.17 | T23: =T22+Q23-R23-S23 -> 0
L24: =L23+J24-K24 -> 0 | P24: =P23+M24-O24 -> -3326.17 | T24: =T23+Q24-R24-S24 -> 0
P25: =P24+M25-O25 -> -3326.17 | T25: =T24+Q25-R25-S25 -> 0
P26: =P25+M26-O26 -> -3326.17 | T26: =T25+Q26-R26-S26 -> 0
P27: =P26+M27-O27 -> -3326.17 | T27: =T26+Q27-R27-S27 -> 0
P28: =P27+M28-O28 -> -3326.17 | T28: =T27+Q28-R28-S28 -> 0
P29: =P28+M29-O29 -> -3326.17 | T29: =T28+Q29-R29-S29 -> 0
P30: =P29+M30-O30 -> -3326.17 | T30: =T29+Q30-R30-S30 -> 0
P31: =P30+M31-O31 -> -3326.17 | T31: =T30+Q31-R31-S31 -> 0
P32: =P31+M32-O32 -> -3326.17 | T32: =T31+Q32-R32-S32 -> 0
P33: =P32+M33-O33 -> -3326.17 | T33: =T32+Q33-R33-S33 -> 0
P34: =P33+M34-O34 -> -3326.17 | T34: =T33+Q34-R34-S34 -> 0
T35: =T34+Q35-R35-S35 -> 0
T36: =T35+Q36-R36-S36 -> 0
