Workbook

Sheet 使用说明
A1: 公司 LOGO （选中本区域插入图片） | C1: =IF(使用说明!$B$2="","",使用说明!$B$2&" ")&"研发费用归集与分摊台账（2026年度） 使用说明" -> 研发费用归集与分摊台账（2026年度） 使用说明
A2: 企业名称： | F2: ← 填一次，全表标题自动带出
A4: 一、适用范围
B5: 本台账适用于以泡棉发泡成型、泡棉与PET基材贴合（复合）、分切/模切为主要工艺，产品应用于3C电子与新能源汽车板块的企业。
B6: 针对研发人员、仪器设备与无形资产在研发与生产之间“混合使用”的情形，按工时法进行费用分配，形成《费用分配说明》及计算证据材料，满足高新技术企业认定、研发费用加计扣除等对“从事研发活动的人员（含外聘人员）和用于研发活动的仪器、设备、无形资产的费用分配说明（包括工作使用情况记录及费用分配计算证据材料）”的资料要求。
A7: 二、核算原则
B8: ① 按月核算、按年汇总：每月末由研发人员填报工时，财务据以计算分摊，年末自动汇总；
B9: ② 人员人工费用：当月某项目应分摊人工费 = 该人员当月总薪酬（含工资、社保、公积金、外聘劳务费）×（该项目研发工时 ÷ 该人员当月总工时）；
B10: ③ 仪器设备折旧/使用费：当月某项目应分摊设备费 = 该设备当月折旧额（或租赁费）×（该项目使用工时 ÷ 该设备当月总运行工时）；
B11: ④ 无形资产摊销：当月某项目应分摊的摊销额 = 该无形资产当月摊销额 ×（该项目使用工时 ÷ 该资产当月总使用工时），由研发按月填报无形资产使用工时；
B12: ⑤ 研发专用人员/设备/无形资产记录全额工时；研发生产共用的记录实际投入研发的工时；
B13: ⑥ 未分配至研发项目的部分，全额计入生产成本，做到“研发与生产各归其位、合计不重不漏”。
B14: ⑦ 数据来源：薪酬数据源自月度工资表；折旧数据源自月度固定资产折旧明细表；摊销数据源自无形资产摊销表。
A15: 三、每月操作流程（5步）
B16: 第1步 基础维护 | C16: 在【项目清单】【人员名册】【资产台账】中维护当期在研项目、研发人员（含外聘）、研发与生产共用的设备及无形资产。基础信息只需变动时维护。
B17: 第2步 工时填报 | C17: 研发部门于次月3日前完成《研发人员工时分配表》《仪器、设备工时分配表》《无形资产工时分配表》填报（签批用纸质表见【附表1】【附表2】【附表3】），经项目负责人、部门负责人签字确认后交财务。签字件为“工作使用情况记录”原始证据，须装订留存。
B18: 第3步 数据录入 | C18: 财务将签批后的工时录入【研发人员工时分配表】与【仪器设备工时分配表】。注意“工时校验”列必须为0（红色即为不平）。研发专用人员/设备的“非研发工时”应填0。
B19: 第4步 费用分摊 | C19: 在【研发人员工时费用分配表】录入当月薪酬构成；在【仪器设备工时费用分配表】核对当月折旧/租赁金额；在【无形资产费用分配表】核对当月摊销额。三表的各项目分摊金额均按对应工时占比自动计算。【其他研发费用】按需登记直接投入等费用（选填）。
B20: 第5步 汇总复核 | C20: 查看【月度归集汇总】与【年度汇总】（含表四勾稽校验，差异须为0），与研发支出辅助账、财务账核对一致；同步更新【指标监测】中的收入与人数，跟踪三项高企指标；年末打印【费用分配说明】签章存档。
A21: 四、本台账与《研发费用归集》制表要求的对应关系
B22: 指标监测 | C22: 《各项指标监测》—— 科技人员占比≥10%、研发费用占销售收入比例（＜5000万≥5%／5000万~2亿≥4%／＞2亿≥3%）、高新收入占比≥60%。对应页签：【指标监测】
B23: 人员人工 | C23: 《研发人员工时分配表》研发按月填报 → 【研发人员工时分配表】；《研发人员工时费用分配表》财务按月按项目核算、按年汇总 → 【研发人员工时费用分配表】
B24: 仪器设备 | C24: 《仪器、设备工时分配表》研发按月填报 → 【仪器设备工时分配表】；《仪器、设备工时费用分配表》财务按月按项目核算、按年汇总 → 【仪器设备工时费用分配表】
B25: 无形资产 | C25: 《无形资产工时分配表》研发按月填报 → 【无形资产工时分配表】；《无形资产费用分配表》财务按月按项目核算、按年汇总 → 【无形资产费用分配表】
A26: 五、单元格颜色约定
C27: 浅黄底 = 需人工录入 | D27: 由研发/财务填写的原始数据
C28: 浅灰底 = 公式自动计算 | D28: 请勿手工覆盖，改动会破坏勾稽关系
C29: 浅蓝底 = 合计/汇总行 | D29: 自动生成，用于与账面核对
A31: 六、留存备查资料清单（应对“费用分配说明”核查）
B32: 1. 本台账电子版（按年一个文件）及打印的【月度归集汇总】【年度汇总】；
B33: 2. 经签批的《研发人员工时分配表》《仪器、设备工时分配表》《无形资产工时分配表》原件（附表1、附表2、附表3）；
B34: 3. 《研发人员与设备费用分配说明》（本文件【费用分配说明】页，加盖公章）；
B35: 4. 研发人员名册、劳动合同/外聘劳务合同、当月工资表及社保公积金缴纳凭证；
B36: 5. 设备固定资产卡片、折旧计提表、租赁合同及付款凭证，无形资产摊销表；
B37: 6. 研发项目立项决议文件、项目计划书、阶段性研发记录（配方试验记录、贴合/分切工艺试验记录、检测报告等）；
B38: 7. 研发支出辅助账及与财务账、纳税申报表的核对说明。
B40: 提示：各录入表首行标有“★示例”的行为填写示范，正式使用前请整行删除，以免混入统计。

Sheet 指标监测
A1: 公司 LOGO （选中本区域插入图片） | C1: =IF(使用说明!$B$2="","",使用说明!$B$2&" ")&"一、高新技术企业各项指标监测表（2026年度）" -> 一、高新技术企业各项指标监测表（2026年度）
A2: 监测口径：①科技人员占当年职工总数比例不低于10%；②研发费用占销售收入比例——销售收入＜5000万元的不低于5%，5000万元～2亿元的不低于4%，超过2亿元的不低于3%（本表按销售收入自动判定适用档次）；③高新技术产品（服务）收入占同期总收入比例不低于60%。浅黄底单元格需人工录入（数据取自财务报表及人事台账），研发费用自动取自【年度汇总】。
A4: 表一 年度指标达标测算
A5: 指标项目 | C5: 数值 | D5: 标准要求 | E5: 是否达标 | F5: 说明
A6: 当年职工总数（人） | F6: 在职职工月平均人数，与社保缴纳人数、工资表人数一致
A7: 其中：科技人员数（人） | D7: =COUNTIF(人员名册!$H$4:$H$53,"是") -> 4 | F7: 左侧“标准要求”列为【人员名册】中标记“是否科技人员=是”的统计参考值，实际以人事台账为准
A8: 科技人员占比 | C8: =IF($C$6=0,"",$C$7/$C$6) | D8: 不低于10% | E8: =IF($C$8="","",IF($C$8>=0.1,"√ 达标","✗ 未达标")) | F8: 累计实际工作满183天以上的研发人员及相关技术人员
A9: 当年销售收入（元） | F9: 取自利润表“营业收入”中的销售（营业）收入，用于研发费用占比测算
A10: 当年研发费用总额（元） | C10: =年度汇总!$O$16 -> 126067.89 | D10: 自动取数 | F10: 自动取自【年度汇总】表一合计，须与研发支出辅助账、纳税申报一致
A11: 适用研发费用比例标准 | C11: =IF($C$9=0,"",IF($C$9<50000000,0.05,IF($C$9<=200000000,0.04,0.03))) | D11: 按销售收入自动分档 | F11: ＜5000万→5%；5000万～2亿→4%；＞2亿→3%
A12: 研发费用占销售收入比例 | C12: =IF($C$9=0,"",$C$10/$C$9) | D12: =IF($C$11="","",$C$11) | E12: =IF(OR($C$12="",$C$11=""),"",IF($C$12>=$C$11,"√ 达标","✗ 未达标")) | F12: 近三个会计年度分别测算；企业成立不足三年的按实际经营年限计算
A13: 当年总收入（元） | F13: 收入总额减去不征税收入后的余额
A14: 高新技术产品（服务）收入（元） | F14: 对应主要产品（服务）：3C电子用泡棉/复合材料、新能源汽车电池用缓冲阻燃材料等
A15: 高新收入占比 | C15: =IF($C$13=0,"",$C$14/$C$13) | D15: 不低于60% | E15: =IF($C$15="","",IF($C$15>=0.6,"√ 达标","✗ 未达标")) | F15: 高新技术产品（服务）收入占同期总收入比例
A17: 表二 分月监测（收入与研发费用累计进度）
A18: 年月 | B18: 当月销售收入 (元) | C18: 当月高新技术产品 (服务)收入(元) | D18: 当月总收入 (元) | E18: 当月研发费用 (元,自动) | F18: 累计销售收入 (元) | G18: 累计研发费用 (元) | H18: 累计研发费用 占销售收入比例 | I18: 累计高新收入 占总收入比例 | J18: 预警提示
A19: 2026-01 | E19: =月度归集汇总!$K$14 -> 0 | F19: =SUM($B$19:B19) -> 0 | G19: =SUM($E$19:E19) -> 0 | H19: =IF($F19=0,"",$G19/$F19) | I19: =IF(SUM($D$19:D19)=0,"",SUM($C$19:C19)/SUM($D$19:D19)) | J19: =IF(OR($H19="",$C$11=""),"",IF($H19<$C$11,"⚠ 研发费用占比低于标准","√ 正常"))
A20: 2026-02 | E20: =月度归集汇总!$K$25 -> 0 | F20: =SUM($B$19:B20) -> 0 | G20: =SUM($E$19:E20) -> 0 | H20: =IF($F20=0,"",$G20/$F20) | I20: =IF(SUM($D$19:D20)=0,"",SUM($C$19:C20)/SUM($D$19:D20)) | J20: =IF(OR($H20="",$C$11=""),"",IF($H20<$C$11,"⚠ 研发费用占比低于标准","√ 正常"))
A21: 2026-03 | E21: =月度归集汇总!$K$36 -> 0 | F21: =SUM($B$19:B21) -> 0 | G21: =SUM($E$19:E21) -> 0 | H21: =IF($F21=0,"",$G21/$F21) | I21: =IF(SUM($D$19:D21)=0,"",SUM($C$19:C21)/SUM($D$19:D21)) | J21: =IF(OR($H21="",$C$11=""),"",IF($H21<$C$11,"⚠ 研发费用占比低于标准","√ 正常"))
A22: 2026-04 | E22: =月度归集汇总!$K$47 -> 0 | F22: =SUM($B$19:B22) -> 0 | G22: =SUM($E$19:E22) -> 0 | H22: =IF($F22=0,"",$G22/$F22) | I22: =IF(SUM($D$19:D22)=0,"",SUM($C$19:C22)/SUM($D$19:D22)) | J22: =IF(OR($H22="",$C$11=""),"",IF($H22<$C$11,"⚠ 研发费用占比低于标准","√ 正常"))
A23: 2026-05 | E23: =月度归集汇总!$K$58 -> 0 | F23: =SUM($B$19:B23) -> 0 | G23: =SUM($E$19:E23) -> 0 | H23: =IF($F23=0,"",$G23/$F23) | I23: =IF(SUM($D$19:D23)=0,"",SUM($C$19:C23)/SUM($D$19:D23)) | J23: =IF(OR($H23="",$C$11=""),"",IF($H23<$C$11,"⚠ 研发费用占比低于标准","√ 正常"))
A24: 2026-06 | E24: =月度归集汇总!$K$69 -> 0 | F24: =SUM($B$19:B24) -> 0 | G24: =SUM($E$19:E24) -> 0 | H24: =IF($F24=0,"",$G24/$F24) | I24: =IF(SUM($D$19:D24)=0,"",SUM($C$19:C24)/SUM($D$19:D24)) | J24: =IF(OR($H24="",$C$11=""),"",IF($H24<$C$11,"⚠ 研发费用占比低于标准","√ 正常"))
A25: 2026-07 | E25: =月度归集汇总!$K$80 -> 0 | F25: =SUM($B$19:B25) -> 0 | G25: =SUM($E$19:E25) -> 0 | H25: =IF($F25=0,"",$G25/$F25) | I25: =IF(SUM($D$19:D25)=0,"",SUM($C$19:C25)/SUM($D$19:D25)) | J25: =IF(OR($H25="",$C$11=""),"",IF($H25<$C$11,"⚠ 研发费用占比低于标准","√ 正常"))
A26: 2026-08 | E26: =月度归集汇总!$K$91 -> 0 | F26: =SUM($B$19:B26) -> 0 | G26: =SUM($E$19:E26) -> 0 | H26: =IF($F26=0,"",$G26/$F26) | I26: =IF(SUM($D$19:D26)=0,"",SUM($C$19:C26)/SUM($D$19:D26)) | J26: =IF(OR($H26="",$C$11=""),"",IF($H26<$C$11,"⚠ 研发费用占比低于标准","√ 正常"))
A27: 2026-09 | E27: =月度归集汇总!$K$102 -> 126067.89 | F27: =SUM($B$19:B27) -> 0 | G27: =SUM($E$19:E27) -> 126067.89 | H27: =IF($F27=0,"",$G27/$F27) | I27: =IF(SUM($D$19:D27)=0,"",SUM($C$19:C27)/SUM($D$19:D27)) | J27: =IF(OR($H27="",$C$11=""),"",IF($H27<$C$11,"⚠ 研发费用占比低于标准","√ 正常"))
A28: 2026-10 | E28: =月度归集汇总!$K$113 -> 0 | F28: =SUM($B$19:B28) -> 0 | G28: =SUM($E$19:E28) -> 126067.89 | H28: =IF($F28=0,"",$G28/$F28) | I28: =IF(SUM($D$19:D28)=0,"",SUM($C$19:C28)/SUM($D$19:D28)) | J28: =IF(OR($H28="",$C$11=""),"",IF($H28<$C$11,"⚠ 研发费用占比低于标准","√ 正常"))
A29: 2026-11 | E29: =月度归集汇总!$K$124 -> 0 | F29: =SUM($B$19:B29) -> 0 | G29: =SUM($E$19:E29) -> 126067.89 | H29: =IF($F29=0,"",$G29/$F29) | I29: =IF(SUM($D$19:D29)=0,"",SUM($C$19:C29)/SUM($D$19:D29)) | J29: =IF(OR($H29="",$C$11=""),"",IF($H29<$C$11,"⚠ 研发费用占比低于标准","√ 正常"))
A30: 2026-12 | E30: =月度归集汇总!$K$135 -> 0 | F30: =SUM($B$19:B30) -> 0 | G30: =SUM($E$19:E30) -> 126067.89 | H30: =IF($F30=0,"",$G30/$F30) | I30: =IF(SUM($D$19:D30)=0,"",SUM($C$19:C30)/SUM($D$19:D30)) | J30: =IF(OR($H30="",$C$11=""),"",IF($H30<$C$11,"⚠ 研发费用占比低于标准","√ 正常"))
A31: 全年合计 | B31: =ROUND(SUM(B19:B30),2) -> 0 | C31: =ROUND(SUM(C19:C30),2) -> 0 | D31: =ROUND(SUM(D19:D30),2) -> 0 | E31: =ROUND(SUM(E19:E30),2) -> 126067.89 | H31: =IF($B31=0,"",$E31/$B31) | I31: =IF($D31=0,"",$C31/$D31)
A33: 提示：表二“当月研发费用”自动取自【月度归集汇总】各月合计；销售收入、高新技术产品收入、总收入需按月从财务系统取数填列，便于全年动态监测研发费用投入强度，避免年末突击。

Sheet 项目清单
A1: 公司 LOGO （选中本区域插入图片） | C1: =IF(使用说明!$B$2="","",使用说明!$B$2&" ")&"二、研发项目清单（2026年度）" -> 二、研发项目清单（2026年度）
A2: 填写说明：项目编号 RD01～RD10 为全表引用主键，请勿改动编号本身；项目名称、板块等可自由维护，编号顺序不可打乱。通常一个年度应有 5～10 个研发项目（至少 5 个），未使用的编号留空即可，不影响各表计算。
A3: 序号 | B3: 项目编号 | C3: 研发项目名称 | D3: 应用板块 | E3: 主要工艺环节 | F3: 立项日期 | G3: 计划结题日期 | H3: 项目负责人 | I3: 项目状态 | J3: 备注
A4: 1 | B4: RD01 | C4: 高回弹低压缩永久变形3C用聚氨酯泡棉开发 | D4: 3C电子 | E4: 发泡成型 | F4: 2026-01-05 | G4: 2026-12-20 | I4: 在研
A5: 2 | B5: RD02 | C5: 动力电池模组用高阻燃缓冲泡棉研发 | D5: 新能源汽车 | E5: 发泡成型 | F5: 2026-01-05 | G5: 2026-12-20 | I5: 在研
A6: 3 | B6: RD03 | C6: 泡棉与PET基材无溶剂贴合工艺开发 | D6: 通用 | E6: PET贴合 | F6: 2026-02-01 | G6: 2026-11-30 | I6: 在研
A7: 4 | B7: RD04 | C7: 超薄泡棉高精度分切及毛边控制技术研究 | D7: 3C电子 | E7: 分切 | F7: 2026-03-01 | G7: 2026-12-31 | I7: 在研
A8: 5 | B8: RD05 | C8: 新能源汽车电池包用导热缓冲复合材料开发 | D8: 新能源汽车 | E8: PET贴合 | F8: 2026-03-01 | G8: 2027-02-28 | I8: 在研
A9: 6 | B9: RD06 | C9: 3C电子用超薄黑色遮光泡棉制备技术 | D9: 3C电子 | E9: 发泡成型 | I9: 在研
A10: 7 | B10: RD07 | C10: 环保型水性胶泡棉贴合技术开发 | D10: 通用 | E10: PET贴合 | I10: 在研
A11: 8 | B11: RD08 | C11: 泡棉模切自动化在线检测技术研究 | D11: 3C电子 | E11: 模切 | I11: 在研
A12: 9 | B12: RD09
A13: 10 | B13: RD10

Sheet 人员名册
A1: 公司 LOGO （选中本区域插入图片） | C1: =IF(使用说明!$B$2="","",使用说明!$B$2&" ")&"三、研发人员名册（含外聘人员）" -> 三、研发人员名册（含外聘人员）
A2: 填写说明：①工号为工时表引用主键，须唯一且不可重复；②“人员使用性质”区分研发专用与研发生产共用——研发专用人员在工时表中记录全额工时，研发生产共用人员记录实际投入研发的工时；③外聘人员“人员类别”选“外聘”，其劳务费在【研发人员工时费用分配表】的“外聘劳务费”列填列；④“是否科技人员”用于高新技术企业科技人员占比（不低于10%）指标监测。
A3: 序号 | B3: 工号 | C3: 姓名 | D3: 所属部门 | E3: 岗位/承担研发任务 | F3: 人员类别 | G3: 人员使用性质 | H3: 是否科技人员 | I3: 入职/合作日期 | J3: 备注
A4: 1 | B4: YF001 | C4: （示例）张工 | D4: 研发中心 | E4: 配方工程师 | F4: 在职 | G4: 研发专用 | H4: 是 | J4: ★示例行，请删除
A5: 2 | B5: YF002 | C5: （示例）李工 | D5: 研发中心 | E5: 工艺工程师 | F5: 在职 | G5: 研发专用 | H5: 是 | J5: ★示例行，请删除
A6: 3 | B6: YF003 | C6: （示例）王工 | D6: 生产部 | E6: 贴合技师（研发生产共用） | F6: 在职 | G6: 研发生产共用 | H6: 是 | J6: ★示例行，请删除
A7: 4 | B7: WP001 | C7: （示例）赵博 | D7: 外聘专家 | E7: 高分子材料顾问 | F7: 外聘 | G7: 研发生产共用 | H7: 是 | J7: ★示例行，请删除
A8: 5
A9: 6
A10: 7
A11: 8
A12: 9
A13: 10
A14: 11
A15: 12
A16: 13
A17: 14
A18: 15
A19: 16
... A53: 50

Sheet 资产台账
A1: 公司 LOGO （选中本区域插入图片） | C1: =IF(使用说明!$B$2="","",使用说明!$B$2&" ")&"四、研发用仪器设备及无形资产台账（含研发生产共用资产）" -> 四、研发用仪器设备及无形资产台账（含研发生产共用资产）
A2: 填写说明：资产编号为工时表引用主键，须唯一。“月折旧/摊销/租赁额”按财务实际计提数填列，【仪器设备工时费用分配表】表将自动取数（当月实际不同可在该表直接覆盖）。研发与生产共用的设备必须登记，其研发使用工时在【仪器设备工时分配表】中据实填报（研发专用设备记录全额运行工时）；无形资产（配方模拟软件、专利/专有技术等）同样登记，其使用工时在【无形资产工时分配表】中据实填报，摊销额按使用工时占比分摊。数据来源：月度固定资产折旧明细表 / 月度无形资产摊销表。
A3: 序号 | B3: 资产编号 | C3: 资产名称 | D3: 资产类别 | E3: 规格型号 | F3: 所属工序 | G3: 取得日期 | H3: 原值(元) | I3: 预计使用年限(年) | J3: 月折旧/摊销/租赁额(元) | K3: 费用类型 | L3: 资产使用性质 | M3: 存放地点 | N3: 备注
A4: 1 | B4: SB001 | C4: （示例）连续发泡生产线 | D4: 设备 | E4: FP-2000 | F4: 发泡成型 | G4: 2023-06-15 | H4: 1800000 | I4: 10 | J4: 15000 | K4: 折旧 | L4: 研发生产共用 | N4: ★示例行，请删除
A5: 2 | B5: SB002 | C5: （示例）自动贴合复合机 | D5: 设备 | E5: LM-1300 | F5: PET贴合 | G5: 2024-03-20 | H5: 960000 | I5: 10 | J5: 8000 | K5: 折旧 | L5: 研发生产共用 | N5: ★示例行，请删除
A6: 3 | B6: SB003 | C6: （示例）高精度分切机 | D6: 设备 | E6: SL-800 | F6: 分切 | G6: 2024-09-10 | H6: 620000 | I6: 10 | J6: 5166.67 | K6: 折旧 | L6: 研发生产共用 | N6: ★示例行，请删除
A7: 4 | B7: SB004 | C7: （示例）万能材料试验机 | D7: 设备 | E7: UTM-50 | F7: 检测试验 | G7: 2025-01-12 | H7: 180000 | I7: 5 | J7: 3000 | K7: 折旧 | L7: 研发生产共用 | N7: ★示例行，请删除
A8: 5 | B8: SB005 | C8: （示例）租入激光模切设备 | D8: 设备 | E8: LD-600 | F8: 模切 | G8: 2026-01-01 | H8: 0 | I8: 0 | J8: 12000 | K8: 租赁费 | L8: 研发生产共用 | N8: ★示例行，请删除
A9: 6 | B9: WX001 | C9: （示例）泡棉配方模拟软件 | D9: 无形资产 | E9: V3.0 | F9: 研发通用 | G9: 2025-05-06 | H9: 240000 | I9: 5 | J9: 4000 | K9: 摊销 | L9: 研发专用 | N9: ★示例行，请删除
A10: 7
A11: 8
A12: 9
A13: 10
A14: 11
A15: 12
A16: 13
A17: 14
A18: 15
A19: 16
A20: 17
A21: 18
... A53: 50

Sheet 研发人员工时分配表
A1: 公司 LOGO （选中本区域插入图片） | C1: =IF(使用说明!$B$2="","",使用说明!$B$2&" ")&"五、《研发人员工时分配表》（研发部门按月填报，2026年度）" -> 五、《研发人员工时分配表》（研发部门按月填报，2026年度）
A2: 录入说明：①由研发部门按月填报，依据经签批的《附表1-研发人员工时分配表(签批用)》逐人逐月录入；②“当月出勤总工时”为该人当月全部有效工作工时（含加班）；③研发专用人员记录全额工时（非研发工时填0），研发生产共用人员按实际投入分别记录研发工时与非研发（生产）工时；④“工时校验”须为0，显示红色表示总工时与明细不平，须更正后方可分摊；⑤同一人当月只填一行；⑥灰底列为公式自动计算，请勿覆盖。
A3: 年月 (YYYY-MM) | B3: 工号 | C3: 姓名 | D3: 所属部门 | E3: 人员类别 | F3: 当月出勤 总工时 | G3: 非研发工时 (生产及其他) | H3: 各研发项目分配工时（小时） | R3: 研发工时 合计 | S3: 工时校验 (须为0) | T3: 研发工时 占比 | U3: 本月主要研发工作内容 | V3: 备注
H4: =项目清单!$B$4 -> RD01 | I4: =项目清单!$B$5 -> RD02 | J4: =项目清单!$B$6 -> RD03 | K4: =项目清单!$B$7 -> RD04 | L4: =项目清单!$B$8 -> RD05 | M4: =项目清单!$B$9 -> RD06 | N4: =项目清单!$B$10 -> RD07 | O4: =项目清单!$B$11 -> RD08 | P4: =项目清单!$B$12 -> RD09 | Q4: =项目清单!$B$13 -> RD10
H5: =IF(H4="","",IFERROR(VLOOKUP(H4,项目清单!$B$4:$C$13,2,0)&"","")) -> 高回弹低压缩永久变形3C用聚氨酯泡棉开发 | I5: =IF(I4="","",IFERROR(VLOOKUP(I4,项目清单!$B$4:$C$13,2,0)&"","")) -> 动力电池模组用高阻燃缓冲泡棉研发 | J5: =IF(J4="","",IFERROR(VLOOKUP(J4,项目清单!$B$4:$C$13,2,0)&"","")) -> 泡棉与PET基材无溶剂贴合工艺开发 | K5: =IF(K4="","",IFERROR(VLOOKUP(K4,项目清单!$B$4:$C$13,2,0)&"","")) -> 超薄泡棉高精度分切及毛边控制技术研究 | L5: =IF(L4="","",IFERROR(VLOOKUP(L4,项目清单!$B$4:$C$13,2,0)&"","")) -> 新能源汽车电池包用导热缓冲复合材料开发 | M5: =IF(M4="","",IFERROR(VLOOKUP(M4,项目清单!$B$4:$C$13,2,0)&"","")) -> 3C电子用超薄黑色遮光泡棉制备技术 | N5: =IF(N4="","",IFERROR(VLOOKUP(N4,项目清单!$B$4:$C$13,2,0)&"","")) -> 环保型水性胶泡棉贴合技术开发 | O5: =IF(O4="","",IFERROR(VLOOKUP(O4,项目清单!$B$4:$C$13,2,0)&"","")) -> 泡棉模切自动化在线检测技术研究 | ... Q5: =IF(Q4="","",IFERROR(VLOOKUP(Q4,项目清单!$B$4:$C$13,2,0)&"","")) | W5: 匹配主键(勿删)
A6: 2026-09 | B6: YF001 | C6: =IF($B6="","",IFERROR(VLOOKUP($B6,人员名册!$B$4:$G$53,2,0)&"","名册中未登记")) -> （示例）张工 | D6: =IF($B6="","",IFERROR(VLOOKUP($B6,人员名册!$B$4:$G$53,3,0)&"","")) -> 研发中心 | E6: =IF($B6="","",IFERROR(VLOOKUP($B6,人员名册!$B$4:$G$53,5,0)&"","")) -> 在职 | F6: 176 | G6: 16 | H6: 100 | I6: 60 | R6: =IF($A6="","",SUM(H6:Q6)) -> 160 | S6: =IF($A6="","",ROUND($F6-$G6-$R6,2)) -> 0 | T6: =IF(OR($A6="",$F6=0),"",$R6/$F6) -> 0.90909091 | U6: 完成低压变形泡棉配方第3轮小试及压缩永久变形验证 | V6: ★示例行，请删除 | W6: =IF($A6="","",$A6&"|"&$B6) -> 2026-09|YF001
A7: 2026-09 | B7: YF003 | C7: =IF($B7="","",IFERROR(VLOOKUP($B7,人员名册!$B$4:$G$53,2,0)&"","名册中未登记")) -> （示例）王工 | D7: =IF($B7="","",IFERROR(VLOOKUP($B7,人员名册!$B$4:$G$53,3,0)&"","")) -> 生产部 | E7: =IF($B7="","",IFERROR(VLOOKUP($B7,人员名册!$B$4:$G$53,5,0)&"","")) -> 在职 | F7: 176 | G7: 120 | J7: 36 | L7: 20 | R7: =IF($A7="","",SUM(H7:Q7)) -> 56 | S7: =IF($A7="","",ROUND($F7-$G7-$R7,2)) -> 0 | T7: =IF(OR($A7="",$F7=0),"",$R7/$F7) -> 0.31818182 | U7: 无溶剂贴合线速与胶量匹配试验（研发生产共用岗位） | V7: ★示例行，请删除 | W7: =IF($A7="","",$A7&"|"&$B7) -> 2026-09|YF003
A8: 2026-09 | B8: WP001 | C8: =IF($B8="","",IFERROR(VLOOKUP($B8,人员名册!$B$4:$G$53,2,0)&"","名册中未登记")) -> （示例）赵博 | D8: =IF($B8="","",IFERROR(VLOOKUP($B8,人员名册!$B$4:$G$53,3,0)&"","")) -> 外聘专家 | E8: =IF($B8="","",IFERROR(VLOOKUP($B8,人员名册!$B$4:$G$53,5,0)&"","")) -> 外聘 | F8: 80 | G8: 0 | I8: 50 | L8: 30 | R8: =IF($A8="","",SUM(H8:Q8)) -> 80 | S8: =IF($A8="","",ROUND($F8-$G8-$R8,2)) -> 0 | T8: =IF(OR($A8="",$F8=0),"",$R8/$F8) -> 1 | U8: 外聘专家：阻燃体系选型指导与试验方案评审 | V8: ★示例行，请删除 | W8: =IF($A8="","",$A8&"|"&$B8) -> 2026-09|WP001
C9: =IF($B9="","",IFERROR(VLOOKUP($B9,人员名册!$B$4:$G$53,2,0)&"","名册中未登记")) | D9: =IF($B9="","",IFERROR(VLOOKUP($B9,人员名册!$B$4:$G$53,3,0)&"","")) | E9: =IF($B9="","",IFERROR(VLOOKUP($B9,人员名册!$B$4:$G$53,5,0)&"","")) | R9: =IF($A9="","",SUM(H9:Q9)) | S9: =IF($A9="","",ROUND($F9-$G9-$R9,2)) | T9: =IF(OR($A9="",$F9=0),"",$R9/$F9) | W9: =IF($A9="","",$A9&"|"&$B9)
C10: =IF($B10="","",IFERROR(VLOOKUP($B10,人员名册!$B$4:$G$53,2,0)&"","名册中未登记")) | D10: =IF($B10="","",IFERROR(VLOOKUP($B10,人员名册!$B$4:$G$53,3,0)&"","")) | E10: =IF($B10="","",IFERROR(VLOOKUP($B10,人员名册!$B$4:$G$53,5,0)&"","")) | R10: =IF($A10="","",SUM(H10:Q10)) | S10: =IF($A10="","",ROUND($F10-$G10-$R10,2)) | T10: =IF(OR($A10="",$F10=0),"",$R10/$F10) | W10: =IF($A10="","",$A10&"|"&$B10)
C11: =IF($B11="","",IFERROR(VLOOKUP($B11,人员名册!$B$4:$G$53,2,0)&"","名册中未登记")) | D11: =IF($B11="","",IFERROR(VLOOKUP($B11,人员名册!$B$4:$G$53,3,0)&"","")) | E11: =IF($B11="","",IFERROR(VLOOKUP($B11,人员名册!$B$4:$G$53,5,0)&"","")) | R11: =IF($A11="","",SUM(H11:Q11)) | S11: =IF($A11="","",ROUND($F11-$G11-$R11,2)) | T11: =IF(OR($A11="",$F11=0),"",$R11/$F11) | W11: =IF($A11="","",$A11&"|"&$B11)
C12: =IF($B12="","",IFERROR(VLOOKUP($B12,人员名册!$B$4:$G$53,2,0)&"","名册中未登记")) | D12: =IF($B12="","",IFERROR(VLOOKUP($B12,人员名册!$B$4:$G$53,3,0)&"","")) | E12: =IF($B12="","",IFERROR(VLOOKUP($B12,人员名册!$B$4:$G$53,5,0)&"","")) | R12: =IF($A12="","",SUM(H12:Q12)) | S12: =IF($A12="","",ROUND($F12-$G12-$R12,2)) | T12: =IF(OR($A12="",$F12=0),"",$R12/$F12) | W12: =IF($A12="","",$A12&"|"&$B12)
C13: =IF($B13="","",IFERROR(VLOOKUP($B13,人员名册!$B$4:$G$53,2,0)&"","名册中未登记")) | D13: =IF($B13="","",IFERROR(VLOOKUP($B13,人员名册!$B$4:$G$53,3,0)&"","")) | E13: =IF($B13="","",IFERROR(VLOOKUP($B13,人员名册!$B$4:$G$53,5,0)&"","")) | R13: =IF($A13="","",SUM(H13:Q13)) | S13: =IF($A13="","",ROUND($F13-$G13-$R13,2)) | T13: =IF(OR($A13="",$F13=0),"",$R13/$F13) | W13: =IF($A13="","",$A13&"|"&$B13)
C14: =IF($B14="","",IFERROR(VLOOKUP($B14,人员名册!$B$4:$G$53,2,0)&"","名册中未登记")) | D14: =IF($B14="","",IFERROR(VLOOKUP($B14,人员名册!$B$4:$G$53,3,0)&"","")) | E14: =IF($B14="","",IFERROR(VLOOKUP($B14,人员名册!$B$4:$G$53,5,0)&"","")) | R14: =IF($A14="","",SUM(H14:Q14)) | S14: =IF($A14="","",ROUND($F14-$G14-$R14,2)) | T14: =IF(OR($A14="",$F14=0),"",$R14/$F14) | W14: =IF($A14="","",$A14&"|"&$B14)
C15: =IF($B15="","",IFERROR(VLOOKUP($B15,人员名册!$B$4:$G$53,2,0)&"","名册中未登记")) | D15: =IF($B15="","",IFERROR(VLOOKUP($B15,人员名册!$B$4:$G$53,3,0)&"","")) | E15: =IF($B15="","",IFERROR(VLOOKUP($B15,人员名册!$B$4:$G$53,5,0)&"","")) | R15: =IF($A15="","",SUM(H15:Q15)) | S15: =IF($A15="","",ROUND($F15-$G15-$R15,2)) | T15: =IF(OR($A15="",$F15=0),"",$R15/$F15) | W15: =IF($A15="","",$A15&"|"&$B15)
C16: =IF($B16="","",IFERROR(VLOOKUP($B16,人员名册!$B$4:$G$53,2,0)&"","名册中未登记")) | D16: =IF($B16="","",IFERROR(VLOOKUP($B16,人员名册!$B$4:$G$53,3,0)&"","")) | E16: =IF($B16="","",IFERROR(VLOOKUP($B16,人员名册!$B$4:$G$53,5,0)&"","")) | R16: =IF($A16="","",SUM(H16:Q16)) | S16: =IF($A16="","",ROUND($F16-$G16-$R16,2)) | T16: =IF(OR($A16="",$F16=0),"",$R16/$F16) | W16: =IF($A16="","",$A16&"|"&$B16)
C17: =IF($B17="","",IFERROR(VLOOKUP($B17,人员名册!$B$4:$G$53,2,0)&"","名册中未登记")) | D17: =IF($B17="","",IFERROR(VLOOKUP($B17,人员名册!$B$4:$G$53,3,0)&"","")) | E17: =IF($B17="","",IFERROR(VLOOKUP($B17,人员名册!$B$4:$G$53,5,0)&"","")) | R17: =IF($A17="","",SUM(H17:Q17)) | S17: =IF($A17="","",ROUND($F17-$G17-$R17,2)) | T17: =IF(OR($A17="",$F17=0),"",$R17/$F17) | W17: =IF($A17="","",$A17&"|"&$B17)
C18: =IF($B18="","",IFERROR(VLOOKUP($B18,人员名册!$B$4:$G$53,2,0)&"","名册中未登记")) | D18: =IF($B18="","",IFERROR(VLOOKUP($B18,人员名册!$B$4:$G$53,3,0)&"","")) | E18: =IF($B18="","",IFERROR(VLOOKUP($B18,人员名册!$B$4:$G$53,5,0)&"","")) | R18: =IF($A18="","",SUM(H18:Q18)) | S18: =IF($A18="","",ROUND($F18-$G18-$R18,2)) | T18: =IF(OR($A18="",$F18=0),"",$R18/$F18) | W18: =IF($A18="","",$A18&"|"&$B18)
C19: =IF($B19="","",IFERROR(VLOOKUP($B19,人员名册!$B$4:$G$53,2,0)&"","名册中未登记")) | D19: =IF($B19="","",IFERROR(VLOOKUP($B19,人员名册!$B$4:$G$53,3,0)&"","")) | E19: =IF($B19="","",IFERROR(VLOOKUP($B19,人员名册!$B$4:$G$53,5,0)&"","")) | R19: =IF($A19="","",SUM(H19:Q19)) | S19: =IF($A19="","",ROUND($F19-$G19-$R19,2)) | T19: =IF(OR($A19="",$F19=0),"",$R19/$F19) | W19: =IF($A19="","",$A19&"|"&$B19)
C20: =IF($B20="","",IFERROR(VLOOKUP($B20,人员名册!$B$4:$G$53,2,0)&"","名册中未登记")) | D20: =IF($B20="","",IFERROR(VLOOKUP($B20,人员名册!$B$4:$G$53,3,0)&"","")) | E20: =IF($B20="","",IFERROR(VLOOKUP($B20,人员名册!$B$4:$G$53,5,0)&"","")) | R20: =IF($A20="","",SUM(H20:Q20)) | S20: =IF($A20="","",ROUND($F20-$G20-$R20,2)) | T20: =IF(OR($A20="",$F20=0),"",$R20/$F20) | W20: =IF($A20="","",$A20&"|"&$B20)
... C245: =IF($B245="","",IFERROR(VLOOKUP($B245,人员名册!$B$4:$G$53,2,0)&"","名册中未登记")) | D245: =IF($B245="","",IFERROR(VLOOKUP($B245,人员名册!$B$4:$G$53,3,0)&"","")) | E245: =IF($B245="","",IFERROR(VLOOKUP($B245,人员名册!$B$4:$G$53,5,0)&"","")) | R245: =IF($A245="","",SUM(H245:Q245)) | S245: =IF($A245="","",ROUND($F245-$G245-$R245,2)) | T245: =IF(OR($A245="",$F245=0),"",$R245/$F245) | W245: =IF($A245="","",$A245&"|"&$B245)

Sheet 研发人员工时费用分配表
A1: 公司 LOGO （选中本区域插入图片） | C1: =IF(使用说明!$B$2="","",使用说明!$B$2&" ")&"六、《研发人员工时费用分配表》（财务按月按项目核算、按年汇总，2026年度）" -> 六、《研发人员工时费用分配表》（财务按月按项目核算、按年汇总，2026年度）
A2: 计算依据：当月某项目应分摊人工费 = 该人员当月总薪酬（含工资、社保、公积金、外聘劳务费）×（该项目研发工时 ÷ 该人员当月总工时）。数据来源：薪酬数据源自【月度工资表】及社保公积金缴费凭证。录入说明：只需录入 A~I 列（年月、工号及薪酬构成；外聘人员在“外聘劳务费”列填列）；工时及各项目分摊金额由《研发人员工时分配表》按“年月+工号”自动匹配取数。请关注末列“数据校验”，出现⚠提示须先更正工时分配表。
A3: 年月 (YYYY-MM) | B3: 工号 | C3: 姓名 | D3: 人员类别 | E3: 工资薪金 (元) | F3: 社保 (单位承担,元) | G3: 公积金 (单位承担,元) | H3: 外聘劳务费 (元) | I3: 其他人工支出 (元) | J3: 当月薪酬合计 (元) | K3: 当月总工时 | L3: 研发工时合计 | M3: 研发工时占比 (分摊系数) | N3: 各研发项目分摊人工费用（元） | X3: 研发人工费 小计(元) | Y3: 计入生产成本的 人工费(元) | Z3: 数据校验
N4: =项目清单!$B$4 -> RD01 | O4: =项目清单!$B$5 -> RD02 | P4: =项目清单!$B$6 -> RD03 | Q4: =项目清单!$B$7 -> RD04 | R4: =项目清单!$B$8 -> RD05 | S4: =项目清单!$B$9 -> RD06 | T4: =项目清单!$B$10 -> RD07 | U4: =项目清单!$B$11 -> RD08 | V4: =项目清单!$B$12 -> RD09 | W4: =项目清单!$B$13 -> RD10
N5: =IF(N4="","",IFERROR(VLOOKUP(N4,项目清单!$B$4:$C$13,2,0)&"","")) -> 高回弹低压缩永久变形3C用聚氨酯泡棉开发 | O5: =IF(O4="","",IFERROR(VLOOKUP(O4,项目清单!$B$4:$C$13,2,0)&"","")) -> 动力电池模组用高阻燃缓冲泡棉研发 | P5: =IF(P4="","",IFERROR(VLOOKUP(P4,项目清单!$B$4:$C$13,2,0)&"","")) -> 泡棉与PET基材无溶剂贴合工艺开发 | Q5: =IF(Q4="","",IFERROR(VLOOKUP(Q4,项目清单!$B$4:$C$13,2,0)&"","")) -> 超薄泡棉高精度分切及毛边控制技术研究 | R5: =IF(R4="","",IFERROR(VLOOKUP(R4,项目清单!$B$4:$C$13,2,0)&"","")) -> 新能源汽车电池包用导热缓冲复合材料开发 | S5: =IF(S4="","",IFERROR(VLOOKUP(S4,项目清单!$B$4:$C$13,2,0)&"","")) -> 3C电子用超薄黑色遮光泡棉制备技术 | T5: =IF(T4="","",IFERROR(VLOOKUP(T4,项目清单!$B$4:$C$13,2,0)&"","")) -> 环保型水性胶泡棉贴合技术开发 | U5: =IF(U4="","",IFERROR(VLOOKUP(U4,项目清单!$B$4:$C$13,2,0)&"","")) -> 泡棉模切自动化在线检测技术研究 | ... W5: =IF(W4="","",IFERROR(VLOOKUP(W4,项目清单!$B$4:$C$13,2,0)&"","")) | AA5: 匹配行号(勿删) | AB5: 重复计数(勿删)
A6: 2026-09 | B6: YF001 | C6: =IF($B6="","",IFERROR(VLOOKUP($B6,人员名册!$B$4:$G$53,2,0)&"","名册中未登记")) -> （示例）张工 | D6: =IF($B6="","",IFERROR(VLOOKUP($B6,人员名册!$B$4:$G$53,5,0)&"","")) -> 在职 | E6: 15000 | F6: 3900 | G6: 1800 | H6: 0 | I6: 1200 | J6: =IF($A6="","",ROUND(SUM(E6:I6),2)) -> 21900 | K6: =IF(OR($A6="",$AA6=0),0,INDEX(研发人员工时分配表!$F$6:$F$245,$AA6)) -> 176 | L6: =IF(OR($A6="",$AA6=0),0,INDEX(研发人员工时分配表!$R$6:$R$245,$AA6)) -> 160 | M6: =IF(OR($A6="",$K6=0),"",$L6/$K6) -> 0.90909091 | N6: =IF(OR($A6="",$K6=0),"",ROUND($J6*INDEX(研发人员工时分配表!$H$6:$H$245,$AA6)/$K6,2)) -> 12443.18 | O6: =IF(OR($A6="",$K6=0),"",ROUND($J6*INDEX(研发人员工时分配表!$I$6:$I$245,$AA6)/$K6,2)) -> 7465.91 | P6: =IF(OR($A6="",$K6=0),"",ROUND($J6*INDEX(研发人员工时分配表!$J$6:$J$245,$AA6)/$K6,2)) -> 0 | Q6: =IF(OR($A6="",$K6=0),"",ROUND($J6*INDEX(研发人员工时分配表!$K$6:$K$245,$AA6)/$K6,2)) -> 0 | R6: =IF(OR($A6="",$K6=0),"",ROUND($J6*INDEX(研发人员工时分配表!$L$6:$L$245,$AA6)/$K6,2)) -> 0 | S6: =IF(OR($A6="",$K6=0),"",ROUND($J6*INDEX(研发人员工时分配表!$M$6:$M$245,$AA6)/$K6,2)) -> 0 | T6: =IF(OR($A6="",$K6=0),"",ROUND($J6*INDEX(研发人员工时分配表!$N$6:$N$245,$AA6)/$K6,2)) -> 0 | U6: =IF(OR($A6="",$K6=0),"",ROUND($J6*INDEX(研发人员工时分配表!$O$6:$O$245,$AA6)/$K6,2)) -> 0 | V6: =IF(OR($A6="",$K6=0),"",ROUND($J6*INDEX(研发人员工时分配表!$P$6:$P$245,$AA6)/$K6,2)) -> 0 | W6: =IF(OR($A6="",$K6=0),"",ROUND($J6*INDEX(研发人员工时分配表!$Q$6:$Q$245,$AA6)/$K6,2)) -> 0 | X6: =IF($A6="","",ROUND(SUM(N6:W6),2)) -> 19909.09 | Y6: =IF($A6="","",ROUND($J6-X6,2)) -> 1990.91 | Z6: =IF($A6="","",IF($AA6=0,"⚠ 工时分配表无此人当月记录",IF($AB6>1,"⚠ 工时分配表存在重复行","√ 正常"))) -> √ 正常 | AA6: =IF($A6="",0,IFERROR(MATCH($A6&"|"&$B6,研发人员工时分配表!$W$6:$W$245,0),0)) -> 1 | AB6: =IF($A6="",0,COUNTIFS(研发人员工时分配表!$A$6:$A$245,$A6,研发人员工时分配表!$B$6:$B$245,$B6)) -> 1
A7: 2026-09 | B7: YF003 | C7: =IF($B7="","",IFERROR(VLOOKUP($B7,人员名册!$B$4:$G$53,2,0)&"","名册中未登记")) -> （示例）王工 | D7: =IF($B7="","",IFERROR(VLOOKUP($B7,人员名册!$B$4:$G$53,5,0)&"","")) -> 在职 | E7: 9000 | F7: 2340 | G7: 1080 | H7: 0 | I7: 600 | J7: =IF($A7="","",ROUND(SUM(E7:I7),2)) -> 13020 | K7: =IF(OR($A7="",$AA7=0),0,INDEX(研发人员工时分配表!$F$6:$F$245,$AA7)) -> 176 | L7: =IF(OR($A7="",$AA7=0),0,INDEX(研发人员工时分配表!$R$6:$R$245,$AA7)) -> 56 | M7: =IF(OR($A7="",$K7=0),"",$L7/$K7) -> 0.31818182 | N7: =IF(OR($A7="",$K7=0),"",ROUND($J7*INDEX(研发人员工时分配表!$H$6:$H$245,$AA7)/$K7,2)) -> 0 | O7: =IF(OR($A7="",$K7=0),"",ROUND($J7*INDEX(研发人员工时分配表!$I$6:$I$245,$AA7)/$K7,2)) -> 0 | P7: =IF(OR($A7="",$K7=0),"",ROUND($J7*INDEX(研发人员工时分配表!$J$6:$J$245,$AA7)/$K7,2)) -> 2663.18 | Q7: =IF(OR($A7="",$K7=0),"",ROUND($J7*INDEX(研发人员工时分配表!$K$6:$K$245,$AA7)/$K7,2)) -> 0 | R7: =IF(OR($A7="",$K7=0),"",ROUND($J7*INDEX(研发人员工时分配表!$L$6:$L$245,$AA7)/$K7,2)) -> 1479.55 | S7: =IF(OR($A7="",$K7=0),"",ROUND($J7*INDEX(研发人员工时分配表!$M$6:$M$245,$AA7)/$K7,2)) -> 0 | T7: =IF(OR($A7="",$K7=0),"",ROUND($J7*INDEX(研发人员工时分配表!$N$6:$N$245,$AA7)/$K7,2)) -> 0 | U7: =IF(OR($A7="",$K7=0),"",ROUND($J7*INDEX(研发人员工时分配表!$O$6:$O$245,$AA7)/$K7,2)) -> 0 | V7: =IF(OR($A7="",$K7=0),"",ROUND($J7*INDEX(研发人员工时分配表!$P$6:$P$245,$AA7)/$K7,2)) -> 0 | W7: =IF(OR($A7="",$K7=0),"",ROUND($J7*INDEX(研发人员工时分配表!$Q$6:$Q$245,$AA7)/$K7,2)) -> 0 | X7: =IF($A7="","",ROUND(SUM(N7:W7),2)) -> 4142.73 | Y7: =IF($A7="","",ROUND($J7-X7,2)) -> 8877.27 | Z7: =IF($A7="","",IF($AA7=0,"⚠ 工时分配表无此人当月记录",IF($AB7>1,"⚠ 工时分配表存在重复行","√ 正常"))) -> √ 正常 | AA7: =IF($A7="",0,IFERROR(MATCH($A7&"|"&$B7,研发人员工时分配表!$W$6:$W$245,0),0)) -> 2 | AB7: =IF($A7="",0,COUNTIFS(研发人员工时分配表!$A$6:$A$245,$A7,研发人员工时分配表!$B$6:$B$245,$B7)) -> 1
A8: 2026-09 | B8: WP001 | C8: =IF($B8="","",IFERROR(VLOOKUP($B8,人员名册!$B$4:$G$53,2,0)&"","名册中未登记")) -> （示例）赵博 | D8: =IF($B8="","",IFERROR(VLOOKUP($B8,人员名册!$B$4:$G$53,5,0)&"","")) -> 外聘 | E8: 0 | F8: 0 | G8: 0 | H8: 30000 | I8: 0 | J8: =IF($A8="","",ROUND(SUM(E8:I8),2)) -> 30000 | K8: =IF(OR($A8="",$AA8=0),0,INDEX(研发人员工时分配表!$F$6:$F$245,$AA8)) -> 80 | L8: =IF(OR($A8="",$AA8=0),0,INDEX(研发人员工时分配表!$R$6:$R$245,$AA8)) -> 80 | M8: =IF(OR($A8="",$K8=0),"",$L8/$K8) -> 1 | N8: =IF(OR($A8="",$K8=0),"",ROUND($J8*INDEX(研发人员工时分配表!$H$6:$H$245,$AA8)/$K8,2)) -> 0 | O8: =IF(OR($A8="",$K8=0),"",ROUND($J8*INDEX(研发人员工时分配表!$I$6:$I$245,$AA8)/$K8,2)) -> 18750 | P8: =IF(OR($A8="",$K8=0),"",ROUND($J8*INDEX(研发人员工时分配表!$J$6:$J$245,$AA8)/$K8,2)) -> 0 | Q8: =IF(OR($A8="",$K8=0),"",ROUND($J8*INDEX(研发人员工时分配表!$K$6:$K$245,$AA8)/$K8,2)) -> 0 | R8: =IF(OR($A8="",$K8=0),"",ROUND($J8*INDEX(研发人员工时分配表!$L$6:$L$245,$AA8)/$K8,2)) -> 11250 | S8: =IF(OR($A8="",$K8=0),"",ROUND($J8*INDEX(研发人员工时分配表!$M$6:$M$245,$AA8)/$K8,2)) -> 0 | T8: =IF(OR($A8="",$K8=0),"",ROUND($J8*INDEX(研发人员工时分配表!$N$6:$N$245,$AA8)/$K8,2)) -> 0 | U8: =IF(OR($A8="",$K8=0),"",ROUND($J8*INDEX(研发人员工时分配表!$O$6:$O$245,$AA8)/$K8,2)) -> 0 | V8: =IF(OR($A8="",$K8=0),"",ROUND($J8*INDEX(研发人员工时分配表!$P$6:$P$245,$AA8)/$K8,2)) -> 0 | W8: =IF(OR($A8="",$K8=0),"",ROUND($J8*INDEX(研发人员工时分配表!$Q$6:$Q$245,$AA8)/$K8,2)) -> 0 | X8: =IF($A8="","",ROUND(SUM(N8:W8),2)) -> 30000 | Y8: =IF($A8="","",ROUND($J8-X8,2)) -> 0 | Z8: =IF($A8="","",IF($AA8=0,"⚠ 工时分配表无此人当月记录",IF($AB8>1,"⚠ 工时分配表存在重复行","√ 正常"))) -> √ 正常 | AA8: =IF($A8="",0,IFERROR(MATCH($A8&"|"&$B8,研发人员工时分配表!$W$6:$W$245,0),0)) -> 3 | AB8: =IF($A8="",0,COUNTIFS(研发人员工时分配表!$A$6:$A$245,$A8,研发人员工时分配表!$B$6:$B$245,$B8)) -> 1
C9: =IF($B9="","",IFERROR(VLOOKUP($B9,人员名册!$B$4:$G$53,2,0)&"","名册中未登记")) | D9: =IF($B9="","",IFERROR(VLOOKUP($B9,人员名册!$B$4:$G$53,5,0)&"","")) | J9: =IF($A9="","",ROUND(SUM(E9:I9),2)) | K9: =IF(OR($A9="",$AA9=0),0,INDEX(研发人员工时分配表!$F$6:$F$245,$AA9)) -> 0 | L9: =IF(OR($A9="",$AA9=0),0,INDEX(研发人员工时分配表!$R$6:$R$245,$AA9)) -> 0 | M9: =IF(OR($A9="",$K9=0),"",$L9/$K9) | N9: =IF(OR($A9="",$K9=0),"",ROUND($J9*INDEX(研发人员工时分配表!$H$6:$H$245,$AA9)/$K9,2)) | O9: =IF(OR($A9="",$K9=0),"",ROUND($J9*INDEX(研发人员工时分配表!$I$6:$I$245,$AA9)/$K9,2)) | P9: =IF(OR($A9="",$K9=0),"",ROUND($J9*INDEX(研发人员工时分配表!$J$6:$J$245,$AA9)/$K9,2)) | Q9: =IF(OR($A9="",$K9=0),"",ROUND($J9*INDEX(研发人员工时分配表!$K$6:$K$245,$AA9)/$K9,2)) | R9: =IF(OR($A9="",$K9=0),"",ROUND($J9*INDEX(研发人员工时分配表!$L$6:$L$245,$AA9)/$K9,2)) | S9: =IF(OR($A9="",$K9=0),"",ROUND($J9*INDEX(研发人员工时分配表!$M$6:$M$245,$AA9)/$K9,2)) | T9: =IF(OR($A9="",$K9=0),"",ROUND($J9*INDEX(研发人员工时分配表!$N$6:$N$245,$AA9)/$K9,2)) | U9: =IF(OR($A9="",$K9=0),"",ROUND($J9*INDEX(研发人员工时分配表!$O$6:$O$245,$AA9)/$K9,2)) | V9: =IF(OR($A9="",$K9=0),"",ROUND($J9*INDEX(研发人员工时分配表!$P$6:$P$245,$AA9)/$K9,2)) | W9: =IF(OR($A9="",$K9=0),"",ROUND($J9*INDEX(研发人员工时分配表!$Q$6:$Q$245,$AA9)/$K9,2)) | X9: =IF($A9="","",ROUND(SUM(N9:W9),2)) | Y9: =IF($A9="","",ROUND($J9-X9,2)) | Z9: =IF($A9="","",IF($AA9=0,"⚠ 工时分配表无此人当月记录",IF($AB9>1,"⚠ 工时分配表存在重复行","√ 正常"))) | AA9: =IF($A9="",0,IFERROR(MATCH($A9&"|"&$B9,研发人员工时分配表!$W$6:$W$245,0),0)) -> 0 | AB9: =IF($A9="",0,COUNTIFS(研发人员工时分配表!$A$6:$A$245,$A9,研发人员工时分配表!$B$6:$B$245,$B9)) -> 0
C10: =IF($B10="","",IFERROR(VLOOKUP($B10,人员名册!$B$4:$G$53,2,0)&"","名册中未登记")) | D10: =IF($B10="","",IFERROR(VLOOKUP($B10,人员名册!$B$4:$G$53,5,0)&"","")) | J10: =IF($A10="","",ROUND(SUM(E10:I10),2)) | K10: =IF(OR($A10="",$AA10=0),0,INDEX(研发人员工时分配表!$F$6:$F$245,$AA10)) -> 0 | L10: =IF(OR($A10="",$AA10=0),0,INDEX(研发人员工时分配表!$R$6:$R$245,$AA10)) -> 0 | M10: =IF(OR($A10="",$K10=0),"",$L10/$K10) | N10: =IF(OR($A10="",$K10=0),"",ROUND($J10*INDEX(研发人员工时分配表!$H$6:$H$245,$AA10)/$K10,2)) | O10: =IF(OR($A10="",$K10=0),"",ROUND($J10*INDEX(研发人员工时分配表!$I$6:$I$245,$AA10)/$K10,2)) | P10: =IF(OR($A10="",$K10=0),"",ROUND($J10*INDEX(研发人员工时分配表!$J$6:$J$245,$AA10)/$K10,2)) | Q10: =IF(OR($A10="",$K10=0),"",ROUND($J10*INDEX(研发人员工时分配表!$K$6:$K$245,$AA10)/$K10,2)) | R10: =IF(OR($A10="",$K10=0),"",ROUND($J10*INDEX(研发人员工时分配表!$L$6:$L$245,$AA10)/$K10,2)) | S10: =IF(OR($A10="",$K10=0),"",ROUND($J10*INDEX(研发人员工时分配表!$M$6:$M$245,$AA10)/$K10,2)) | T10: =IF(OR($A10="",$K10=0),"",ROUND($J10*INDEX(研发人员工时分配表!$N$6:$N$245,$AA10)/$K10,2)) | U10: =IF(OR($A10="",$K10=0),"",ROUND($J10*INDEX(研发人员工时分配表!$O$6:$O$245,$AA10)/$K10,2)) | V10: =IF(OR($A10="",$K10=0),"",ROUND($J10*INDEX(研发人员工时分配表!$P$6:$P$245,$AA10)/$K10,2)) | W10: =IF(OR($A10="",$K10=0),"",ROUND($J10*INDEX(研发人员工时分配表!$Q$6:$Q$245,$AA10)/$K10,2)) | X10: =IF($A10="","",ROUND(SUM(N10:W10),2)) | Y10: =IF($A10="","",ROUND($J10-X10,2)) | Z10: =IF($A10="","",IF($AA10=0,"⚠ 工时分配表无此人当月记录",IF($AB10>1,"⚠ 工时分配表存在重复行","√ 正常"))) | AA10: =IF($A10="",0,IFERROR(MATCH($A10&"|"&$B10,研发人员工时分配表!$W$6:$W$245,0),0)) -> 0 | AB10: =IF($A10="",0,COUNTIFS(研发人员工时分配表!$A$6:$A$245,$A10,研发人员工时分配表!$B$6:$B$245,$B10)) -> 0
C11: =IF($B11="","",IFERROR(VLOOKUP($B11,人员名册!$B$4:$G$53,2,0)&"","名册中未登记")) | D11: =IF($B11="","",IFERROR(VLOOKUP($B11,人员名册!$B$4:$G$53,5,0)&"","")) | J11: =IF($A11="","",ROUND(SUM(E11:I11),2)) | K11: =IF(OR($A11="",$AA11=0),0,INDEX(研发人员工时分配表!$F$6:$F$245,$AA11)) -> 0 | L11: =IF(OR($A11="",$AA11=0),0,INDEX(研发人员工时分配表!$R$6:$R$245,$AA11)) -> 0 | M11: =IF(OR($A11="",$K11=0),"",$L11/$K11) | N11: =IF(OR($A11="",$K11=0),"",ROUND($J11*INDEX(研发人员工时分配表!$H$6:$H$245,$AA11)/$K11,2)) | O11: =IF(OR($A11="",$K11=0),"",ROUND($J11*INDEX(研发人员工时分配表!$I$6:$I$245,$AA11)/$K11,2)) | P11: =IF(OR($A11="",$K11=0),"",ROUND($J11*INDEX(研发人员工时分配表!$J$6:$J$245,$AA11)/$K11,2)) | Q11: =IF(OR($A11="",$K11=0),"",ROUND($J11*INDEX(研发人员工时分配表!$K$6:$K$245,$AA11)/$K11,2)) | R11: =IF(OR($A11="",$K11=0),"",ROUND($J11*INDEX(研发人员工时分配表!$L$6:$L$245,$AA11)/$K11,2)) | S11: =IF(OR($A11="",$K11=0),"",ROUND($J11*INDEX(研发人员工时分配表!$M$6:$M$245,$AA11)/$K11,2)) | T11: =IF(OR($A11="",$K11=0),"",ROUND($J11*INDEX(研发人员工时分配表!$N$6:$N$245,$AA11)/$K11,2)) | U11: =IF(OR($A11="",$K11=0),"",ROUND($J11*INDEX(研发人员工时分配表!$O$6:$O$245,$AA11)/$K11,2)) | V11: =IF(OR($A11="",$K11=0),"",ROUND($J11*INDEX(研发人员工时分配表!$P$6:$P$245,$AA11)/$K11,2)) | W11: =IF(OR($A11="",$K11=0),"",ROUND($J11*INDEX(研发人员工时分配表!$Q$6:$Q$245,$AA11)/$K11,2)) | X11: =IF($A11="","",ROUND(SUM(N11:W11),2)) | Y11: =IF($A11="","",ROUND($J11-X11,2)) | Z11: =IF($A11="","",IF($AA11=0,"⚠ 工时分配表无此人当月记录",IF($AB11>1,"⚠ 工时分配表存在重复行","√ 正常"))) | AA11: =IF($A11="",0,IFERROR(MATCH($A11&"|"&$B11,研发人员工时分配表!$W$6:$W$245,0),0)) -> 0 | AB11: =IF($A11="",0,COUNTIFS(研发人员工时分配表!$A$6:$A$245,$A11,研发人员工时分配表!$B$6:$B$245,$B11)) -> 0
C12: =IF($B12="","",IFERROR(VLOOKUP($B12,人员名册!$B$4:$G$53,2,0)&"","名册中未登记")) | D12: =IF($B12="","",IFERROR(VLOOKUP($B12,人员名册!$B$4:$G$53,5,0)&"","")) | J12: =IF($A12="","",ROUND(SUM(E12:I12),2)) | K12: =IF(OR($A12="",$AA12=0),0,INDEX(研发人员工时分配表!$F$6:$F$245,$AA12)) -> 0 | L12: =IF(OR($A12="",$AA12=0),0,INDEX(研发人员工时分配表!$R$6:$R$245,$AA12)) -> 0 | M12: =IF(OR($A12="",$K12=0),"",$L12/$K12) | N12: =IF(OR($A12="",$K12=0),"",ROUND($J12*INDEX(研发人员工时分配表!$H$6:$H$245,$AA12)/$K12,2)) | O12: =IF(OR($A12="",$K12=0),"",ROUND($J12*INDEX(研发人员工时分配表!$I$6:$I$245,$AA12)/$K12,2)) | P12: =IF(OR($A12="",$K12=0),"",ROUND($J12*INDEX(研发人员工时分配表!$J$6:$J$245,$AA12)/$K12,2)) | Q12: =IF(OR($A12="",$K12=0),"",ROUND($J12*INDEX(研发人员工时分配表!$K$6:$K$245,$AA12)/$K12,2)) | R12: =IF(OR($A12="",$K12=0),"",ROUND($J12*INDEX(研发人员工时分配表!$L$6:$L$245,$AA12)/$K12,2)) | S12: =IF(OR($A12="",$K12=0),"",ROUND($J12*INDEX(研发人员工时分配表!$M$6:$M$245,$AA12)/$K12,2)) | T12: =IF(OR($A12="",$K12=0),"",ROUND($J12*INDEX(研发人员工时分配表!$N$6:$N$245,$AA12)/$K12,2)) | U12: =IF(OR($A12="",$K12=0),"",ROUND($J12*INDEX(研发人员工时分配表!$O$6:$O$245,$AA12)/$K12,2)) | V12: =IF(OR($A12="",$K12=0),"",ROUND($J12*INDEX(研发人员工时分配表!$P$6:$P$245,$AA12)/$K12,2)) | W12: =IF(OR($A12="",$K12=0),"",ROUND($J12*INDEX(研发人员工时分配表!$Q$6:$Q$245,$AA12)/$K12,2)) | X12: =IF($A12="","",ROUND(SUM(N12:W12),2)) | Y12: =IF($A12="","",ROUND($J12-X12,2)) | Z12: =IF($A12="","",IF($AA12=0,"⚠ 工时分配表无此人当月记录",IF($AB12>1,"⚠ 工时分配表存在重复行","√ 正常"))) | AA12: =IF($A12="",0,IFERROR(MATCH($A12&"|"&$B12,研发人员工时分配表!$W$6:$W$245,0),0)) -> 0 | AB12: =IF($A12="",0,COUNTIFS(研发人员工时分配表!$A$6:$A$245,$A12,研发人员工时分配表!$B$6:$B$245,$B12)) -> 0
C13: =IF($B13="","",IFERROR(VLOOKUP($B13,人员名册!$B$4:$G$53,2,0)&"","名册中未登记")) | D13: =IF($B13="","",IFERROR(VLOOKUP($B13,人员名册!$B$4:$G$53,5,0)&"","")) | J13: =IF($A13="","",ROUND(SUM(E13:I13),2)) | K13: =IF(OR($A13="",$AA13=0),0,INDEX(研发人员工时分配表!$F$6:$F$245,$AA13)) -> 0 | L13: =IF(OR($A13="",$AA13=0),0,INDEX(研发人员工时分配表!$R$6:$R$245,$AA13)) -> 0 | M13: =IF(OR($A13="",$K13=0),"",$L13/$K13) | N13: =IF(OR($A13="",$K13=0),"",ROUND($J13*INDEX(研发人员工时分配表!$H$6:$H$245,$AA13)/$K13,2)) | O13: =IF(OR($A13="",$K13=0),"",ROUND($J13*INDEX(研发人员工时分配表!$I$6:$I$245,$AA13)/$K13,2)) | P13: =IF(OR($A13="",$K13=0),"",ROUND($J13*INDEX(研发人员工时分配表!$J$6:$J$245,$AA13)/$K13,2)) | Q13: =IF(OR($A13="",$K13=0),"",ROUND($J13*INDEX(研发人员工时分配表!$K$6:$K$245,$AA13)/$K13,2)) | R13: =IF(OR($A13="",$K13=0),"",ROUND($J13*INDEX(研发人员工时分配表!$L$6:$L$245,$AA13)/$K13,2)) | S13: =IF(OR($A13="",$K13=0),"",ROUND($J13*INDEX(研发人员工时分配表!$M$6:$M$245,$AA13)/$K13,2)) | T13: =IF(OR($A13="",$K13=0),"",ROUND($J13*INDEX(研发人员工时分配表!$N$6:$N$245,$AA13)/$K13,2)) | U13: =IF(OR($A13="",$K13=0),"",ROUND($J13*INDEX(研发人员工时分配表!$O$6:$O$245,$AA13)/$K13,2)) | V13: =IF(OR($A13="",$K13=0),"",ROUND($J13*INDEX(研发人员工时分配表!$P$6:$P$245,$AA13)/$K13,2)) | W13: =IF(OR($A13="",$K13=0),"",ROUND($J13*INDEX(研发人员工时分配表!$Q$6:$Q$245,$AA13)/$K13,2)) | X13: =IF($A13="","",ROUND(SUM(N13:W13),2)) | Y13: =IF($A13="","",ROUND($J13-X13,2)) | Z13: =IF($A13="","",IF($AA13=0,"⚠ 工时分配表无此人当月记录",IF($AB13>1,"⚠ 工时分配表存在重复行","√ 正常"))) | AA13: =IF($A13="",0,IFERROR(MATCH($A13&"|"&$B13,研发人员工时分配表!$W$6:$W$245,0),0)) -> 0 | AB13: =IF($A13="",0,COUNTIFS(研发人员工时分配表!$A$6:$A$245,$A13,研发人员工时分配表!$B$6:$B$245,$B13)) -> 0
C14: =IF($B14="","",IFERROR(VLOOKUP($B14,人员名册!$B$4:$G$53,2,0)&"","名册中未登记")) | D14: =IF($B14="","",IFERROR(VLOOKUP($B14,人员名册!$B$4:$G$53,5,0)&"","")) | J14: =IF($A14="","",ROUND(SUM(E14:I14),2)) | K14: =IF(OR($A14="",$AA14=0),0,INDEX(研发人员工时分配表!$F$6:$F$245,$AA14)) -> 0 | L14: =IF(OR($A14="",$AA14=0),0,INDEX(研发人员工时分配表!$R$6:$R$245,$AA14)) -> 0 | M14: =IF(OR($A14="",$K14=0),"",$L14/$K14) | N14: =IF(OR($A14="",$K14=0),"",ROUND($J14*INDEX(研发人员工时分配表!$H$6:$H$245,$AA14)/$K14,2)) | O14: =IF(OR($A14="",$K14=0),"",ROUND($J14*INDEX(研发人员工时分配表!$I$6:$I$245,$AA14)/$K14,2)) | P14: =IF(OR($A14="",$K14=0),"",ROUND($J14*INDEX(研发人员工时分配表!$J$6:$J$245,$AA14)/$K14,2)) | Q14: =IF(OR($A14="",$K14=0),"",ROUND($J14*INDEX(研发人员工时分配表!$K$6:$K$245,$AA14)/$K14,2)) | R14: =IF(OR($A14="",$K14=0),"",ROUND($J14*INDEX(研发人员工时分配表!$L$6:$L$245,$AA14)/$K14,2)) | S14: =IF(OR($A14="",$K14=0),"",ROUND($J14*INDEX(研发人员工时分配表!$M$6:$M$245,$AA14)/$K14,2)) | T14: =IF(OR($A14="",$K14=0),"",ROUND($J14*INDEX(研发人员工时分配表!$N$6:$N$245,$AA14)/$K14,2)) | U14: =IF(OR($A14="",$K14=0),"",ROUND($J14*INDEX(研发人员工时分配表!$O$6:$O$245,$AA14)/$K14,2)) | V14: =IF(OR($A14="",$K14=0),"",ROUND($J14*INDEX(研发人员工时分配表!$P$6:$P$245,$AA14)/$K14,2)) | W14: =IF(OR($A14="",$K14=0),"",ROUND($J14*INDEX(研发人员工时分配表!$Q$6:$Q$245,$AA14)/$K14,2)) | X14: =IF($A14="","",ROUND(SUM(N14:W14),2)) | Y14: =IF($A14="","",ROUND($J14-X14,2)) | Z14: =IF($A14="","",IF($AA14=0,"⚠ 工时分配表无此人当月记录",IF($AB14>1,"⚠ 工时分配表存在重复行","√ 正常"))) | AA14: =IF($A14="",0,IFERROR(MATCH($A14&"|"&$B14,研发人员工时分配表!$W$6:$W$245,0),0)) -> 0 | AB14: =IF($A14="",0,COUNTIFS(研发人员工时分配表!$A$6:$A$245,$A14,研发人员工时分配表!$B$6:$B$245,$B14)) -> 0
C15: =IF($B15="","",IFERROR(VLOOKUP($B15,人员名册!$B$4:$G$53,2,0)&"","名册中未登记")) | D15: =IF($B15="","",IFERROR(VLOOKUP($B15,人员名册!$B$4:$G$53,5,0)&"","")) | J15: =IF($A15="","",ROUND(SUM(E15:I15),2)) | K15: =IF(OR($A15="",$AA15=0),0,INDEX(研发人员工时分配表!$F$6:$F$245,$AA15)) -> 0 | L15: =IF(OR($A15="",$AA15=0),0,INDEX(研发人员工时分配表!$R$6:$R$245,$AA15)) -> 0 | M15: =IF(OR($A15="",$K15=0),"",$L15/$K15) | N15: =IF(OR($A15="",$K15=0),"",ROUND($J15*INDEX(研发人员工时分配表!$H$6:$H$245,$AA15)/$K15,2)) | O15: =IF(OR($A15="",$K15=0),"",ROUND($J15*INDEX(研发人员工时分配表!$I$6:$I$245,$AA15)/$K15,2)) | P15: =IF(OR($A15="",$K15=0),"",ROUND($J15*INDEX(研发人员工时分配表!$J$6:$J$245,$AA15)/$K15,2)) | Q15: =IF(OR($A15="",$K15=0),"",ROUND($J15*INDEX(研发人员工时分配表!$K$6:$K$245,$AA15)/$K15,2)) | R15: =IF(OR($A15="",$K15=0),"",ROUND($J15*INDEX(研发人员工时分配表!$L$6:$L$245,$AA15)/$K15,2)) | S15: =IF(OR($A15="",$K15=0),"",ROUND($J15*INDEX(研发人员工时分配表!$M$6:$M$245,$AA15)/$K15,2)) | T15: =IF(OR($A15="",$K15=0),"",ROUND($J15*INDEX(研发人员工时分配表!$N$6:$N$245,$AA15)/$K15,2)) | U15: =IF(OR($A15="",$K15=0),"",ROUND($J15*INDEX(研发人员工时分配表!$O$6:$O$245,$AA15)/$K15,2)) | V15: =IF(OR($A15="",$K15=0),"",ROUND($J15*INDEX(研发人员工时分配表!$P$6:$P$245,$AA15)/$K15,2)) | W15: =IF(OR($A15="",$K15=0),"",ROUND($J15*INDEX(研发人员工时分配表!$Q$6:$Q$245,$AA15)/$K15,2)) | X15: =IF($A15="","",ROUND(SUM(N15:W15),2)) | Y15: =IF($A15="","",ROUND($J15-X15,2)) | Z15: =IF($A15="","",IF($AA15=0,"⚠ 工时分配表无此人当月记录",IF($AB15>1,"⚠ 工时分配表存在重复行","√ 正常"))) | AA15: =IF($A15="",0,IFERROR(MATCH($A15&"|"&$B15,研发人员工时分配表!$W$6:$W$245,0),0)) -> 0 | AB15: =IF($A15="",0,COUNTIFS(研发人员工时分配表!$A$6:$A$245,$A15,研发人员工时分配表!$B$6:$B$245,$B15)) -> 0
C16: =IF($B16="","",IFERROR(VLOOKUP($B16,人员名册!$B$4:$G$53,2,0)&"","名册中未登记")) | D16: =IF($B16="","",IFERROR(VLOOKUP($B16,人员名册!$B$4:$G$53,5,0)&"","")) | J16: =IF($A16="","",ROUND(SUM(E16:I16),2)) | K16: =IF(OR($A16="",$AA16=0),0,INDEX(研发人员工时分配表!$F$6:$F$245,$AA16)) -> 0 | L16: =IF(OR($A16="",$AA16=0),0,INDEX(研发人员工时分配表!$R$6:$R$245,$AA16)) -> 0 | M16: =IF(OR($A16="",$K16=0),"",$L16/$K16) | N16: =IF(OR($A16="",$K16=0),"",ROUND($J16*INDEX(研发人员工时分配表!$H$6:$H$245,$AA16)/$K16,2)) | O16: =IF(OR($A16="",$K16=0),"",ROUND($J16*INDEX(研发人员工时分配表!$I$6:$I$245,$AA16)/$K16,2)) | P16: =IF(OR($A16="",$K16=0),"",ROUND($J16*INDEX(研发人员工时分配表!$J$6:$J$245,$AA16)/$K16,2)) | Q16: =IF(OR($A16="",$K16=0),"",ROUND($J16*INDEX(研发人员工时分配表!$K$6:$K$245,$AA16)/$K16,2)) | R16: =IF(OR($A16="",$K16=0),"",ROUND($J16*INDEX(研发人员工时分配表!$L$6:$L$245,$AA16)/$K16,2)) | S16: =IF(OR($A16="",$K16=0),"",ROUND($J16*INDEX(研发人员工时分配表!$M$6:$M$245,$AA16)/$K16,2)) | T16: =IF(OR($A16="",$K16=0),"",ROUND($J16*INDEX(研发人员工时分配表!$N$6:$N$245,$AA16)/$K16,2)) | U16: =IF(OR($A16="",$K16=0),"",ROUND($J16*INDEX(研发人员工时分配表!$O$6:$O$245,$AA16)/$K16,2)) | V16: =IF(OR($A16="",$K16=0),"",ROUND($J16*INDEX(研发人员工时分配表!$P$6:$P$245,$AA16)/$K16,2)) | W16: =IF(OR($A16="",$K16=0),"",ROUND($J16*INDEX(研发人员工时分配表!$Q$6:$Q$245,$AA16)/$K16,2)) | X16: =IF($A16="","",ROUND(SUM(N16:W16),2)) | Y16: =IF($A16="","",ROUND($J16-X16,2)) | Z16: =IF($A16="","",IF($AA16=0,"⚠ 工时分配表无此人当月记录",IF($AB16>1,"⚠ 工时分配表存在重复行","√ 正常"))) | AA16: =IF($A16="",0,IFERROR(MATCH($A16&"|"&$B16,研发人员工时分配表!$W$6:$W$245,0),0)) -> 0 | AB16: =IF($A16="",0,COUNTIFS(研发人员工时分配表!$A$6:$A$245,$A16,研发人员工时分配表!$B$6:$B$245,$B16)) -> 0
C17: =IF($B17="","",IFERROR(VLOOKUP($B17,人员名册!$B$4:$G$53,2,0)&"","名册中未登记")) | D17: =IF($B17="","",IFERROR(VLOOKUP($B17,人员名册!$B$4:$G$53,5,0)&"","")) | J17: =IF($A17="","",ROUND(SUM(E17:I17),2)) | K17: =IF(OR($A17="",$AA17=0),0,INDEX(研发人员工时分配表!$F$6:$F$245,$AA17)) -> 0 | L17: =IF(OR($A17="",$AA17=0),0,INDEX(研发人员工时分配表!$R$6:$R$245,$AA17)) -> 0 | M17: =IF(OR($A17="",$K17=0),"",$L17/$K17) | N17: =IF(OR($A17="",$K17=0),"",ROUND($J17*INDEX(研发人员工时分配表!$H$6:$H$245,$AA17)/$K17,2)) | O17: =IF(OR($A17="",$K17=0),"",ROUND($J17*INDEX(研发人员工时分配表!$I$6:$I$245,$AA17)/$K17,2)) | P17: =IF(OR($A17="",$K17=0),"",ROUND($J17*INDEX(研发人员工时分配表!$J$6:$J$245,$AA17)/$K17,2)) | Q17: =IF(OR($A17="",$K17=0),"",ROUND($J17*INDEX(研发人员工时分配表!$K$6:$K$245,$AA17)/$K17,2)) | R17: =IF(OR($A17="",$K17=0),"",ROUND($J17*INDEX(研发人员工时分配表!$L$6:$L$245,$AA17)/$K17,2)) | S17: =IF(OR($A17="",$K17=0),"",ROUND($J17*INDEX(研发人员工时分配表!$M$6:$M$245,$AA17)/$K17,2)) | T17: =IF(OR($A17="",$K17=0),"",ROUND($J17*INDEX(研发人员工时分配表!$N$6:$N$245,$AA17)/$K17,2)) | U17: =IF(OR($A17="",$K17=0),"",ROUND($J17*INDEX(研发人员工时分配表!$O$6:$O$245,$AA17)/$K17,2)) | V17: =IF(OR($A17="",$K17=0),"",ROUND($J17*INDEX(研发人员工时分配表!$P$6:$P$245,$AA17)/$K17,2)) | W17: =IF(OR($A17="",$K17=0),"",ROUND($J17*INDEX(研发人员工时分配表!$Q$6:$Q$245,$AA17)/$K17,2)) | X17: =IF($A17="","",ROUND(SUM(N17:W17),2)) | Y17: =IF($A17="","",ROUND($J17-X17,2)) | Z17: =IF($A17="","",IF($AA17=0,"⚠ 工时分配表无此人当月记录",IF($AB17>1,"⚠ 工时分配表存在重复行","√ 正常"))) | AA17: =IF($A17="",0,IFERROR(MATCH($A17&"|"&$B17,研发人员工时分配表!$W$6:$W$245,0),0)) -> 0 | AB17: =IF($A17="",0,COUNTIFS(研发人员工时分配表!$A$6:$A$245,$A17,研发人员工时分配表!$B$6:$B$245,$B17)) -> 0
C18: =IF($B18="","",IFERROR(VLOOKUP($B18,人员名册!$B$4:$G$53,2,0)&"","名册中未登记")) | D18: =IF($B18="","",IFERROR(VLOOKUP($B18,人员名册!$B$4:$G$53,5,0)&"","")) | J18: =IF($A18="","",ROUND(SUM(E18:I18),2)) | K18: =IF(OR($A18="",$AA18=0),0,INDEX(研发人员工时分配表!$F$6:$F$245,$AA18)) -> 0 | L18: =IF(OR($A18="",$AA18=0),0,INDEX(研发人员工时分配表!$R$6:$R$245,$AA18)) -> 0 | M18: =IF(OR($A18="",$K18=0),"",$L18/$K18) | N18: =IF(OR($A18="",$K18=0),"",ROUND($J18*INDEX(研发人员工时分配表!$H$6:$H$245,$AA18)/$K18,2)) | O18: =IF(OR($A18="",$K18=0),"",ROUND($J18*INDEX(研发人员工时分配表!$I$6:$I$245,$AA18)/$K18,2)) | P18: =IF(OR($A18="",$K18=0),"",ROUND($J18*INDEX(研发人员工时分配表!$J$6:$J$245,$AA18)/$K18,2)) | Q18: =IF(OR($A18="",$K18=0),"",ROUND($J18*INDEX(研发人员工时分配表!$K$6:$K$245,$AA18)/$K18,2)) | R18: =IF(OR($A18="",$K18=0),"",ROUND($J18*INDEX(研发人员工时分配表!$L$6:$L$245,$AA18)/$K18,2)) | S18: =IF(OR($A18="",$K18=0),"",ROUND($J18*INDEX(研发人员工时分配表!$M$6:$M$245,$AA18)/$K18,2)) | T18: =IF(OR($A18="",$K18=0),"",ROUND($J18*INDEX(研发人员工时分配表!$N$6:$N$245,$AA18)/$K18,2)) | U18: =IF(OR($A18="",$K18=0),"",ROUND($J18*INDEX(研发人员工时分配表!$O$6:$O$245,$AA18)/$K18,2)) | V18: =IF(OR($A18="",$K18=0),"",ROUND($J18*INDEX(研发人员工时分配表!$P$6:$P$245,$AA18)/$K18,2)) | W18: =IF(OR($A18="",$K18=0),"",ROUND($J18*INDEX(研发人员工时分配表!$Q$6:$Q$245,$AA18)/$K18,2)) | X18: =IF($A18="","",ROUND(SUM(N18:W18),2)) | Y18: =IF($A18="","",ROUND($J18-X18,2)) | Z18: =IF($A18="","",IF($AA18=0,"⚠ 工时分配表无此人当月记录",IF($AB18>1,"⚠ 工时分配表存在重复行","√ 正常"))) | AA18: =IF($A18="",0,IFERROR(MATCH($A18&"|"&$B18,研发人员工时分配表!$W$6:$W$245,0),0)) -> 0 | AB18: =IF($A18="",0,COUNTIFS(研发人员工时分配表!$A$6:$A$245,$A18,研发人员工时分配表!$B$6:$B$245,$B18)) -> 0
C19: =IF($B19="","",IFERROR(VLOOKUP($B19,人员名册!$B$4:$G$53,2,0)&"","名册中未登记")) | D19: =IF($B19="","",IFERROR(VLOOKUP($B19,人员名册!$B$4:$G$53,5,0)&"","")) | J19: =IF($A19="","",ROUND(SUM(E19:I19),2)) | K19: =IF(OR($A19="",$AA19=0),0,INDEX(研发人员工时分配表!$F$6:$F$245,$AA19)) -> 0 | L19: =IF(OR($A19="",$AA19=0),0,INDEX(研发人员工时分配表!$R$6:$R$245,$AA19)) -> 0 | M19: =IF(OR($A19="",$K19=0),"",$L19/$K19) | N19: =IF(OR($A19="",$K19=0),"",ROUND($J19*INDEX(研发人员工时分配表!$H$6:$H$245,$AA19)/$K19,2)) | O19: =IF(OR($A19="",$K19=0),"",ROUND($J19*INDEX(研发人员工时分配表!$I$6:$I$245,$AA19)/$K19,2)) | P19: =IF(OR($A19="",$K19=0),"",ROUND($J19*INDEX(研发人员工时分配表!$J$6:$J$245,$AA19)/$K19,2)) | Q19: =IF(OR($A19="",$K19=0),"",ROUND($J19*INDEX(研发人员工时分配表!$K$6:$K$245,$AA19)/$K19,2)) | R19: =IF(OR($A19="",$K19=0),"",ROUND($J19*INDEX(研发人员工时分配表!$L$6:$L$245,$AA19)/$K19,2)) | S19: =IF(OR($A19="",$K19=0),"",ROUND($J19*INDEX(研发人员工时分配表!$M$6:$M$245,$AA19)/$K19,2)) | T19: =IF(OR($A19="",$K19=0),"",ROUND($J19*INDEX(研发人员工时分配表!$N$6:$N$245,$AA19)/$K19,2)) | U19: =IF(OR($A19="",$K19=0),"",ROUND($J19*INDEX(研发人员工时分配表!$O$6:$O$245,$AA19)/$K19,2)) | V19: =IF(OR($A19="",$K19=0),"",ROUND($J19*INDEX(研发人员工时分配表!$P$6:$P$245,$AA19)/$K19,2)) | W19: =IF(OR($A19="",$K19=0),"",ROUND($J19*INDEX(研发人员工时分配表!$Q$6:$Q$245,$AA19)/$K19,2)) | X19: =IF($A19="","",ROUND(SUM(N19:W19),2)) | Y19: =IF($A19="","",ROUND($J19-X19,2)) | Z19: =IF($A19="","",IF($AA19=0,"⚠ 工时分配表无此人当月记录",IF($AB19>1,"⚠ 工时分配表存在重复行","√ 正常"))) | AA19: =IF($A19="",0,IFERROR(MATCH($A19&"|"&$B19,研发人员工时分配表!$W$6:$W$245,0),0)) -> 0 | AB19: =IF($A19="",0,COUNTIFS(研发人员工时分配表!$A$6:$A$245,$A19,研发人员工时分配表!$B$6:$B$245,$B19)) -> 0
C20: =IF($B20="","",IFERROR(VLOOKUP($B20,人员名册!$B$4:$G$53,2,0)&"","名册中未登记")) | D20: =IF($B20="","",IFERROR(VLOOKUP($B20,人员名册!$B$4:$G$53,5,0)&"","")) | J20: =IF($A20="","",ROUND(SUM(E20:I20),2)) | K20: =IF(OR($A20="",$AA20=0),0,INDEX(研发人员工时分配表!$F$6:$F$245,$AA20)) -> 0 | L20: =IF(OR($A20="",$AA20=0),0,INDEX(研发人员工时分配表!$R$6:$R$245,$AA20)) -> 0 | M20: =IF(OR($A20="",$K20=0),"",$L20/$K20) | N20: =IF(OR($A20="",$K20=0),"",ROUND($J20*INDEX(研发人员工时分配表!$H$6:$H$245,$AA20)/$K20,2)) | O20: =IF(OR($A20="",$K20=0),"",ROUND($J20*INDEX(研发人员工时分配表!$I$6:$I$245,$AA20)/$K20,2)) | P20: =IF(OR($A20="",$K20=0),"",ROUND($J20*INDEX(研发人员工时分配表!$J$6:$J$245,$AA20)/$K20,2)) | Q20: =IF(OR($A20="",$K20=0),"",ROUND($J20*INDEX(研发人员工时分配表!$K$6:$K$245,$AA20)/$K20,2)) | R20: =IF(OR($A20="",$K20=0),"",ROUND($J20*INDEX(研发人员工时分配表!$L$6:$L$245,$AA20)/$K20,2)) | S20: =IF(OR($A20="",$K20=0),"",ROUND($J20*INDEX(研发人员工时分配表!$M$6:$M$245,$AA20)/$K20,2)) | T20: =IF(OR($A20="",$K20=0),"",ROUND($J20*INDEX(研发人员工时分配表!$N$6:$N$245,$AA20)/$K20,2)) | U20: =IF(OR($A20="",$K20=0),"",ROUND($J20*INDEX(研发人员工时分配表!$O$6:$O$245,$AA20)/$K20,2)) | V20: =IF(OR($A20="",$K20=0),"",ROUND($J20*INDEX(研发人员工时分配表!$P$6:$P$245,$AA20)/$K20,2)) | W20: =IF(OR($A20="",$K20=0),"",ROUND($J20*INDEX(研发人员工时分配表!$Q$6:$Q$245,$AA20)/$K20,2)) | X20: =IF($A20="","",ROUND(SUM(N20:W20),2)) | Y20: =IF($A20="","",ROUND($J20-X20,2)) | Z20: =IF($A20="","",IF($AA20=0,"⚠ 工时分配表无此人当月记录",IF($AB20>1,"⚠ 工时分配表存在重复行","√ 正常"))) | AA20: =IF($A20="",0,IFERROR(MATCH($A20&"|"&$B20,研发人员工时分配表!$W$6:$W$245,0),0)) -> 0 | AB20: =IF($A20="",0,COUNTIFS(研发人员工时分配表!$A$6:$A$245,$A20,研发人员工时分配表!$B$6:$B$245,$B20)) -> 0
... C245: =IF($B245="","",IFERROR(VLOOKUP($B245,人员名册!$B$4:$G$53,2,0)&"","名册中未登记")) | D245: =IF($B245="","",IFERROR(VLOOKUP($B245,人员名册!$B$4:$G$53,5,0)&"","")) | J245: =IF($A245="","",ROUND(SUM(E245:I245),2)) | K245: =IF(OR($A245="",$AA245=0),0,INDEX(研发人员工时分配表!$F$6:$F$245,$AA245)) -> 0 | L245: =IF(OR($A245="",$AA245=0),0,INDEX(研发人员工时分配表!$R$6:$R$245,$AA245)) -> 0 | M245: =IF(OR($A245="",$K245=0),"",$L245/$K245) | N245: =IF(OR($A245="",$K245=0),"",ROUND($J245*INDEX(研发人员工时分配表!$H$6:$H$245,$AA245)/$K245,2)) | O245: =IF(OR($A245="",$K245=0),"",ROUND($J245*INDEX(研发人员工时分配表!$I$6:$I$245,$AA245)/$K245,2)) | P245: =IF(OR($A245="",$K245=0),"",ROUND($J245*INDEX(研发人员工时分配表!$J$6:$J$245,$AA245)/$K245,2)) | Q245: =IF(OR($A245="",$K245=0),"",ROUND($J245*INDEX(研发人员工时分配表!$K$6:$K$245,$AA245)/$K245,2)) | R245: =IF(OR($A245="",$K245=0),"",ROUND($J245*INDEX(研发人员工时分配表!$L$6:$L$245,$AA245)/$K245,2)) | S245: =IF(OR($A245="",$K245=0),"",ROUND($J245*INDEX(研发人员工时分配表!$M$6:$M$245,$AA245)/$K245,2)) | T245: =IF(OR($A245="",$K245=0),"",ROUND($J245*INDEX(研发人员工时分配表!$N$6:$N$245,$AA245)/$K245,2)) | U245: =IF(OR($A245="",$K245=0),"",ROUND($J245*INDEX(研发人员工时分配表!$O$6:$O$245,$AA245)/$K245,2)) | V245: =IF(OR($A245="",$K245=0),"",ROUND($J245*INDEX(研发人员工时分配表!$P$6:$P$245,$AA245)/$K245,2)) | W245: =IF(OR($A245="",$K245=0),"",ROUND($J245*INDEX(研发人员工时分配表!$Q$6:$Q$245,$AA245)/$K245,2)) | X245: =IF($A245="","",ROUND(SUM(N245:W245),2)) | Y245: =IF($A245="","",ROUND($J245-X245,2)) | Z245: =IF($A245="","",IF($AA245=0,"⚠ 工时分配表无此人当月记录",IF($AB245>1,"⚠ 工时分配表存在重复行","√ 正常"))) | AA245: =IF($A245="",0,IFERROR(MATCH($A245&"|"&$B245,研发人员工时分配表!$W$6:$W$245,0),0)) -> 0 | AB245: =IF($A245="",0,COUNTIFS(研发人员工时分配表!$A$6:$A$245,$A245,研发人员工时分配表!$B$6:$B$245,$B245)) -> 0

Sheet 仪器设备工时分配表
A1: 公司 LOGO （选中本区域插入图片） | C1: =IF(使用说明!$B$2="","",使用说明!$B$2&" ")&"七、《仪器、设备工时分配表》（研发部门按月填报，2026年度）" -> 七、《仪器、设备工时分配表》（研发部门按月填报，2026年度）
A2: 录入说明：①由研发部门/设备管理员按月填报，依据经签批的《附表2-仪器设备工时分配表(签批用)》录入；②“当月总运行(使用)工时”为该设备当月实际运行总工时（生产+研发），是分摊的分母，须与设备点检表、生产报工记录一致；③研发专用设备记录全额运行工时（非研发使用工时填0），研发生产共用设备按实际使用分别记录；④本表只登记“设备”类资产，无形资产不在此填报（其摊销在【无形资产费用分配表】中按人工工时比例分摊）；⑤同一设备当月只填一行；⑥“工时校验”须为0。
A3: 年月 (YYYY-MM) | B3: 资产编号 | C3: 资产名称 | D3: 资产类别 | E3: 所属工序 | F3: 当月总运行 (使用)工时 | G3: 非研发使用工时 (生产及其他) | H3: 各研发项目使用工时（小时） | R3: 研发使用 工时合计 | S3: 工时校验 (须为0) | T3: 研发使用 占比 | U3: 备注
H4: =项目清单!$B$4 -> RD01 | I4: =项目清单!$B$5 -> RD02 | J4: =项目清单!$B$6 -> RD03 | K4: =项目清单!$B$7 -> RD04 | L4: =项目清单!$B$8 -> RD05 | M4: =项目清单!$B$9 -> RD06 | N4: =项目清单!$B$10 -> RD07 | O4: =项目清单!$B$11 -> RD08 | P4: =项目清单!$B$12 -> RD09 | Q4: =项目清单!$B$13 -> RD10
H5: =IF(H4="","",IFERROR(VLOOKUP(H4,项目清单!$B$4:$C$13,2,0)&"","")) -> 高回弹低压缩永久变形3C用聚氨酯泡棉开发 | I5: =IF(I4="","",IFERROR(VLOOKUP(I4,项目清单!$B$4:$C$13,2,0)&"","")) -> 动力电池模组用高阻燃缓冲泡棉研发 | J5: =IF(J4="","",IFERROR(VLOOKUP(J4,项目清单!$B$4:$C$13,2,0)&"","")) -> 泡棉与PET基材无溶剂贴合工艺开发 | K5: =IF(K4="","",IFERROR(VLOOKUP(K4,项目清单!$B$4:$C$13,2,0)&"","")) -> 超薄泡棉高精度分切及毛边控制技术研究 | L5: =IF(L4="","",IFERROR(VLOOKUP(L4,项目清单!$B$4:$C$13,2,0)&"","")) -> 新能源汽车电池包用导热缓冲复合材料开发 | M5: =IF(M4="","",IFERROR(VLOOKUP(M4,项目清单!$B$4:$C$13,2,0)&"","")) -> 3C电子用超薄黑色遮光泡棉制备技术 | N5: =IF(N4="","",IFERROR(VLOOKUP(N4,项目清单!$B$4:$C$13,2,0)&"","")) -> 环保型水性胶泡棉贴合技术开发 | O5: =IF(O4="","",IFERROR(VLOOKUP(O4,项目清单!$B$4:$C$13,2,0)&"","")) -> 泡棉模切自动化在线检测技术研究 | ... Q5: =IF(Q4="","",IFERROR(VLOOKUP(Q4,项目清单!$B$4:$C$13,2,0)&"","")) | V5: 匹配主键(勿删)
A6: 2026-09 | B6: SB001 | C6: =IF($B6="","",IFERROR(VLOOKUP($B6,资产台账!$B$4:$N$53,2,0)&"","台账中未登记")) -> （示例）连续发泡生产线 | D6: =IF($B6="","",IFERROR(VLOOKUP($B6,资产台账!$B$4:$N$53,3,0)&"","")) -> 设备 | E6: =IF($B6="","",IFERROR(VLOOKUP($B6,资产台账!$B$4:$N$53,5,0)&"","")) -> 发泡成型 | F6: 320 | G6: 260 | H6: 40 | I6: 20 | R6: =IF($A6="","",SUM(H6:Q6)) -> 60 | S6: =IF($A6="","",ROUND($F6-$G6-$R6,2)) -> 0 | T6: =IF(OR($A6="",$F6=0),"",$R6/$F6) -> 0.1875 | U6: ★示例行，请删除 | V6: =IF($A6="","",$A6&"|"&$B6) -> 2026-09|SB001
A7: 2026-09 | B7: SB002 | C7: =IF($B7="","",IFERROR(VLOOKUP($B7,资产台账!$B$4:$N$53,2,0)&"","台账中未登记")) -> （示例）自动贴合复合机 | D7: =IF($B7="","",IFERROR(VLOOKUP($B7,资产台账!$B$4:$N$53,3,0)&"","")) -> 设备 | E7: =IF($B7="","",IFERROR(VLOOKUP($B7,资产台账!$B$4:$N$53,5,0)&"","")) -> PET贴合 | F7: 300 | G7: 240 | J7: 40 | L7: 20 | R7: =IF($A7="","",SUM(H7:Q7)) -> 60 | S7: =IF($A7="","",ROUND($F7-$G7-$R7,2)) -> 0 | T7: =IF(OR($A7="",$F7=0),"",$R7/$F7) -> 0.2 | U7: ★示例行，请删除 | V7: =IF($A7="","",$A7&"|"&$B7) -> 2026-09|SB002
A8: 2026-09 | B8: SB003 | C8: =IF($B8="","",IFERROR(VLOOKUP($B8,资产台账!$B$4:$N$53,2,0)&"","台账中未登记")) -> （示例）高精度分切机 | D8: =IF($B8="","",IFERROR(VLOOKUP($B8,资产台账!$B$4:$N$53,3,0)&"","")) -> 设备 | E8: =IF($B8="","",IFERROR(VLOOKUP($B8,资产台账!$B$4:$N$53,5,0)&"","")) -> 分切 | F8: 280 | G8: 250 | K8: 30 | R8: =IF($A8="","",SUM(H8:Q8)) -> 30 | S8: =IF($A8="","",ROUND($F8-$G8-$R8,2)) -> 0 | T8: =IF(OR($A8="",$F8=0),"",$R8/$F8) -> 0.10714286 | U8: ★示例行，请删除 | V8: =IF($A8="","",$A8&"|"&$B8) -> 2026-09|SB003
A9: 2026-09 | B9: SB005 | C9: =IF($B9="","",IFERROR(VLOOKUP($B9,资产台账!$B$4:$N$53,2,0)&"","台账中未登记")) -> （示例）租入激光模切设备 | D9: =IF($B9="","",IFERROR(VLOOKUP($B9,资产台账!$B$4:$N$53,3,0)&"","")) -> 设备 | E9: =IF($B9="","",IFERROR(VLOOKUP($B9,资产台账!$B$4:$N$53,5,0)&"","")) -> 模切 | F9: 120 | G9: 0 | I9: 70 | L9: 50 | R9: =IF($A9="","",SUM(H9:Q9)) -> 120 | S9: =IF($A9="","",ROUND($F9-$G9-$R9,2)) -> 0 | T9: =IF(OR($A9="",$F9=0),"",$R9/$F9) -> 1 | U9: ★示例行，请删除 | V9: =IF($A9="","",$A9&"|"&$B9) -> 2026-09|SB005
C10: =IF($B10="","",IFERROR(VLOOKUP($B10,资产台账!$B$4:$N$53,2,0)&"","台账中未登记")) | D10: =IF($B10="","",IFERROR(VLOOKUP($B10,资产台账!$B$4:$N$53,3,0)&"","")) | E10: =IF($B10="","",IFERROR(VLOOKUP($B10,资产台账!$B$4:$N$53,5,0)&"","")) | R10: =IF($A10="","",SUM(H10:Q10)) | S10: =IF($A10="","",ROUND($F10-$G10-$R10,2)) | T10: =IF(OR($A10="",$F10=0),"",$R10/$F10) | V10: =IF($A10="","",$A10&"|"&$B10)
C11: =IF($B11="","",IFERROR(VLOOKUP($B11,资产台账!$B$4:$N$53,2,0)&"","台账中未登记")) | D11: =IF($B11="","",IFERROR(VLOOKUP($B11,资产台账!$B$4:$N$53,3,0)&"","")) | E11: =IF($B11="","",IFERROR(VLOOKUP($B11,资产台账!$B$4:$N$53,5,0)&"","")) | R11: =IF($A11="","",SUM(H11:Q11)) | S11: =IF($A11="","",ROUND($F11-$G11-$R11,2)) | T11: =IF(OR($A11="",$F11=0),"",$R11/$F11) | V11: =IF($A11="","",$A11&"|"&$B11)
C12: =IF($B12="","",IFERROR(VLOOKUP($B12,资产台账!$B$4:$N$53,2,0)&"","台账中未登记")) | D12: =IF($B12="","",IFERROR(VLOOKUP($B12,资产台账!$B$4:$N$53,3,0)&"","")) | E12: =IF($B12="","",IFERROR(VLOOKUP($B12,资产台账!$B$4:$N$53,5,0)&"","")) | R12: =IF($A12="","",SUM(H12:Q12)) | S12: =IF($A12="","",ROUND($F12-$G12-$R12,2)) | T12: =IF(OR($A12="",$F12=0),"",$R12/$F12) | V12: =IF($A12="","",$A12&"|"&$B12)
C13: =IF($B13="","",IFERROR(VLOOKUP($B13,资产台账!$B$4:$N$53,2,0)&"","台账中未登记")) | D13: =IF($B13="","",IFERROR(VLOOKUP($B13,资产台账!$B$4:$N$53,3,0)&"","")) | E13: =IF($B13="","",IFERROR(VLOOKUP($B13,资产台账!$B$4:$N$53,5,0)&"","")) | R13: =IF($A13="","",SUM(H13:Q13)) | S13: =IF($A13="","",ROUND($F13-$G13-$R13,2)) | T13: =IF(OR($A13="",$F13=0),"",$R13/$F13) | V13: =IF($A13="","",$A13&"|"&$B13)
C14: =IF($B14="","",IFERROR(VLOOKUP($B14,资产台账!$B$4:$N$53,2,0)&"","台账中未登记")) | D14: =IF($B14="","",IFERROR(VLOOKUP($B14,资产台账!$B$4:$N$53,3,0)&"","")) | E14: =IF($B14="","",IFERROR(VLOOKUP($B14,资产台账!$B$4:$N$53,5,0)&"","")) | R14: =IF($A14="","",SUM(H14:Q14)) | S14: =IF($A14="","",ROUND($F14-$G14-$R14,2)) | T14: =IF(OR($A14="",$F14=0),"",$R14/$F14) | V14: =IF($A14="","",$A14&"|"&$B14)
C15: =IF($B15="","",IFERROR(VLOOKUP($B15,资产台账!$B$4:$N$53,2,0)&"","台账中未登记")) | D15: =IF($B15="","",IFERROR(VLOOKUP($B15,资产台账!$B$4:$N$53,3,0)&"","")) | E15: =IF($B15="","",IFERROR(VLOOKUP($B15,资产台账!$B$4:$N$53,5,0)&"","")) | R15: =IF($A15="","",SUM(H15:Q15)) | S15: =IF($A15="","",ROUND($F15-$G15-$R15,2)) | T15: =IF(OR($A15="",$F15=0),"",$R15/$F15) | V15: =IF($A15="","",$A15&"|"&$B15)
C16: =IF($B16="","",IFERROR(VLOOKUP($B16,资产台账!$B$4:$N$53,2,0)&"","台账中未登记")) | D16: =IF($B16="","",IFERROR(VLOOKUP($B16,资产台账!$B$4:$N$53,3,0)&"","")) | E16: =IF($B16="","",IFERROR(VLOOKUP($B16,资产台账!$B$4:$N$53,5,0)&"","")) | R16: =IF($A16="","",SUM(H16:Q16)) | S16: =IF($A16="","",ROUND($F16-$G16-$R16,2)) | T16: =IF(OR($A16="",$F16=0),"",$R16/$F16) | V16: =IF($A16="","",$A16&"|"&$B16)
C17: =IF($B17="","",IFERROR(VLOOKUP($B17,资产台账!$B$4:$N$53,2,0)&"","台账中未登记")) | D17: =IF($B17="","",IFERROR(VLOOKUP($B17,资产台账!$B$4:$N$53,3,0)&"","")) | E17: =IF($B17="","",IFERROR(VLOOKUP($B17,资产台账!$B$4:$N$53,5,0)&"","")) | R17: =IF($A17="","",SUM(H17:Q17)) | S17: =IF($A17="","",ROUND($F17-$G17-$R17,2)) | T17: =IF(OR($A17="",$F17=0),"",$R17/$F17) | V17: =IF($A17="","",$A17&"|"&$B17)
C18: =IF($B18="","",IFERROR(VLOOKUP($B18,资产台账!$B$4:$N$53,2,0)&"","台账中未登记")) | D18: =IF($B18="","",IFERROR(VLOOKUP($B18,资产台账!$B$4:$N$53,3,0)&"","")) | E18: =IF($B18="","",IFERROR(VLOOKUP($B18,资产台账!$B$4:$N$53,5,0)&"","")) | R18: =IF($A18="","",SUM(H18:Q18)) | S18: =IF($A18="","",ROUND($F18-$G18-$R18,2)) | T18: =IF(OR($A18="",$F18=0),"",$R18/$F18) | V18: =IF($A18="","",$A18&"|"&$B18)
C19: =IF($B19="","",IFERROR(VLOOKUP($B19,资产台账!$B$4:$N$53,2,0)&"","台账中未登记")) | D19: =IF($B19="","",IFERROR(VLOOKUP($B19,资产台账!$B$4:$N$53,3,0)&"","")) | E19: =IF($B19="","",IFERROR(VLOOKUP($B19,资产台账!$B$4:$N$53,5,0)&"","")) | R19: =IF($A19="","",SUM(H19:Q19)) | S19: =IF($A19="","",ROUND($F19-$G19-$R19,2)) | T19: =IF(OR($A19="",$F19=0),"",$R19/$F19) | V19: =IF($A19="","",$A19&"|"&$B19)
C20: =IF($B20="","",IFERROR(VLOOKUP($B20,资产台账!$B$4:$N$53,2,0)&"","台账中未登记")) | D20: =IF($B20="","",IFERROR(VLOOKUP($B20,资产台账!$B$4:$N$53,3,0)&"","")) | E20: =IF($B20="","",IFERROR(VLOOKUP($B20,资产台账!$B$4:$N$53,5,0)&"","")) | R20: =IF($A20="","",SUM(H20:Q20)) | S20: =IF($A20="","",ROUND($F20-$G20-$R20,2)) | T20: =IF(OR($A20="",$F20=0),"",$R20/$F20) | V20: =IF($A20="","",$A20&"|"&$B20)
C21: =IF($B21="","",IFERROR(VLOOKUP($B21,资产台账!$B$4:$N$53,2,0)&"","台账中未登记")) | D21: =IF($B21="","",IFERROR(VLOOKUP($B21,资产台账!$B$4:$N$53,3,0)&"","")) | E21: =IF($B21="","",IFERROR(VLOOKUP($B21,资产台账!$B$4:$N$53,5,0)&"","")) | R21: =IF($A21="","",SUM(H21:Q21)) | S21: =IF($A21="","",ROUND($F21-$G21-$R21,2)) | T21: =IF(OR($A21="",$F21=0),"",$R21/$F21) | V21: =IF($A21="","",$A21&"|"&$B21)
... C245: =IF($B245="","",IFERROR(VLOOKUP($B245,资产台账!$B$4:$N$53,2,0)&"","台账中未登记")) | D245: =IF($B245="","",IFERROR(VLOOKUP($B245,资产台账!$B$4:$N$53,3,0)&"","")) | E245: =IF($B245="","",IFERROR(VLOOKUP($B245,资产台账!$B$4:$N$53,5,0)&"","")) | R245: =IF($A245="","",SUM(H245:Q245)) | S245: =IF($A245="","",ROUND($F245-$G245-$R245,2)) | T245: =IF(OR($A245="",$F245=0),"",$R245/$F245) | V245: =IF($A245="","",$A245&"|"&$B245)

Sheet 仪器设备工时费用分配表
A1: 公司 LOGO （选中本区域插入图片） | C1: =IF(使用说明!$B$2="","",使用说明!$B$2&" ")&"八、《仪器、设备工时费用分配表》（财务按月按项目核算、按年汇总，2026年度）" -> 八、《仪器、设备工时费用分配表》（财务按月按项目核算、按年汇总，2026年度）
A2: 计算依据：当月某项目应分摊设备费 = 该设备当月折旧额（或租赁费）×（该项目使用工时 ÷ 该设备当月总运行工时）。数据来源：折旧数据源自【月度固定资产折旧明细表】。录入说明：只需录入 A、B 两列（年月、资产编号，仅登记“设备”类资产）；F列“当月折旧/租赁额”自动取自【资产台账】，当月实际计提数不同时可直接覆盖填写，但须与折旧明细表一致。请关注末列“数据校验”。
A3: 年月 (YYYY-MM) | B3: 资产编号 | C3: 资产名称 | D3: 资产类别 | E3: 费用类型 | F3: 当月折旧/ 租赁额(元) | G3: 当月总运行 (使用)工时 | H3: 研发使用 工时合计 | I3: 研发使用占比 (分摊系数) | J3: 各研发项目分摊折旧/租赁费用（元） | T3: 研发费用 小计(元) | U3: 计入生产成本的 折旧费用(元) | V3: 数据校验
J4: =项目清单!$B$4 -> RD01 | K4: =项目清单!$B$5 -> RD02 | L4: =项目清单!$B$6 -> RD03 | M4: =项目清单!$B$7 -> RD04 | N4: =项目清单!$B$8 -> RD05 | O4: =项目清单!$B$9 -> RD06 | P4: =项目清单!$B$10 -> RD07 | Q4: =项目清单!$B$11 -> RD08 | R4: =项目清单!$B$12 -> RD09 | S4: =项目清单!$B$13 -> RD10
J5: =IF(J4="","",IFERROR(VLOOKUP(J4,项目清单!$B$4:$C$13,2,0)&"","")) -> 高回弹低压缩永久变形3C用聚氨酯泡棉开发 | K5: =IF(K4="","",IFERROR(VLOOKUP(K4,项目清单!$B$4:$C$13,2,0)&"","")) -> 动力电池模组用高阻燃缓冲泡棉研发 | L5: =IF(L4="","",IFERROR(VLOOKUP(L4,项目清单!$B$4:$C$13,2,0)&"","")) -> 泡棉与PET基材无溶剂贴合工艺开发 | M5: =IF(M4="","",IFERROR(VLOOKUP(M4,项目清单!$B$4:$C$13,2,0)&"","")) -> 超薄泡棉高精度分切及毛边控制技术研究 | N5: =IF(N4="","",IFERROR(VLOOKUP(N4,项目清单!$B$4:$C$13,2,0)&"","")) -> 新能源汽车电池包用导热缓冲复合材料开发 | O5: =IF(O4="","",IFERROR(VLOOKUP(O4,项目清单!$B$4:$C$13,2,0)&"","")) -> 3C电子用超薄黑色遮光泡棉制备技术 | P5: =IF(P4="","",IFERROR(VLOOKUP(P4,项目清单!$B$4:$C$13,2,0)&"","")) -> 环保型水性胶泡棉贴合技术开发 | Q5: =IF(Q4="","",IFERROR(VLOOKUP(Q4,项目清单!$B$4:$C$13,2,0)&"","")) -> 泡棉模切自动化在线检测技术研究 | ... S5: =IF(S4="","",IFERROR(VLOOKUP(S4,项目清单!$B$4:$C$13,2,0)&"","")) | W5: 匹配行号(勿删) | X5: 重复计数(勿删)
A6: 2026-09 | B6: SB001 | C6: =IF($B6="","",IFERROR(VLOOKUP($B6,资产台账!$B$4:$N$53,2,0)&"","台账中未登记")) -> （示例）连续发泡生产线 | D6: =IF($B6="","",IFERROR(VLOOKUP($B6,资产台账!$B$4:$N$53,3,0)&"","")) -> 设备 | E6: =IF($B6="","",IFERROR(VLOOKUP($B6,资产台账!$B$4:$N$53,10,0)&"","")) -> 折旧 | F6: =IF($B6="","",IFERROR(VLOOKUP($B6,资产台账!$B$4:$N$53,9,0),0)) -> 15000 | G6: =IF(OR($A6="",$W6=0),0,INDEX(仪器设备工时分配表!$F$6:$F$245,$W6)) -> 320 | H6: =IF(OR($A6="",$W6=0),0,INDEX(仪器设备工时分配表!$R$6:$R$245,$W6)) -> 60 | I6: =IF(OR($A6="",$G6=0),"",$H6/$G6) -> 0.1875 | J6: =IF(OR($A6="",$G6=0),"",ROUND($F6*INDEX(仪器设备工时分配表!$H$6:$H$245,$W6)/$G6,2)) -> 1875 | K6: =IF(OR($A6="",$G6=0),"",ROUND($F6*INDEX(仪器设备工时分配表!$I$6:$I$245,$W6)/$G6,2)) -> 937.5 | L6: =IF(OR($A6="",$G6=0),"",ROUND($F6*INDEX(仪器设备工时分配表!$J$6:$J$245,$W6)/$G6,2)) -> 0 | M6: =IF(OR($A6="",$G6=0),"",ROUND($F6*INDEX(仪器设备工时分配表!$K$6:$K$245,$W6)/$G6,2)) -> 0 | N6: =IF(OR($A6="",$G6=0),"",ROUND($F6*INDEX(仪器设备工时分配表!$L$6:$L$245,$W6)/$G6,2)) -> 0 | O6: =IF(OR($A6="",$G6=0),"",ROUND($F6*INDEX(仪器设备工时分配表!$M$6:$M$245,$W6)/$G6,2)) -> 0 | P6: =IF(OR($A6="",$G6=0),"",ROUND($F6*INDEX(仪器设备工时分配表!$N$6:$N$245,$W6)/$G6,2)) -> 0 | Q6: =IF(OR($A6="",$G6=0),"",ROUND($F6*INDEX(仪器设备工时分配表!$O$6:$O$245,$W6)/$G6,2)) -> 0 | R6: =IF(OR($A6="",$G6=0),"",ROUND($F6*INDEX(仪器设备工时分配表!$P$6:$P$245,$W6)/$G6,2)) -> 0 | S6: =IF(OR($A6="",$G6=0),"",ROUND($F6*INDEX(仪器设备工时分配表!$Q$6:$Q$245,$W6)/$G6,2)) -> 0 | T6: =IF($A6="","",ROUND(SUM(J6:S6),2)) -> 2812.5 | U6: =IF($A6="","",ROUND($F6-T6,2)) -> 12187.5 | V6: =IF($A6="","",IF($D6="无形资产","⚠ 无形资产请在无形资产费用分配表登记",IF($W6=0,"⚠ 工时分配表无此资产当月记录",IF($X6>1,"⚠ 工时分配表存在重复行","√ 正常")))) -> √ 正常 | W6: =IF($A6="",0,IFERROR(MATCH($A6&"|"&$B6,仪器设备工时分配表!$V$6:$V$245,0),0)) -> 1 | X6: =IF($A6="",0,COUNTIFS(仪器设备工时分配表!$A$6:$A$245,$A6,仪器设备工时分配表!$B$6:$B$245,$B6)) -> 1
