Workbook

Sheet 使用说明
A1: 更多财务实操模板，可自行搜索抖音/视频号：老财务的实操笔记
A3: 【老财务实操自用｜初级版财务台账模板】
A4: 作者：老财务的实操笔记
A5: ——————————————————————————
A6: 适用对象：小微企业、个体工商户、小规模纳税人、商贸服务类等
A7: 版本说明
A8: 本套为**通用基础初级版**，满足税务管理、费用报销、收支登记、票据管理等
A9: 可根据行业属性、业务规模、升级定制版。
A11: 模板清单，持续更新
A12: 1、应收账款风险预警表
A13: 2、日常经营情况汇总表
A14: 3、进项台帐自动查重表
... A47: 老财务自用模板｜禁止外传、倒卖、商用

Sheet 基础资料
A1: 账户 | C1: 支出业务类别 | E1: 客户 | F1: 客户期初余额 | G1: 供应商 | H1: 供应商期初余额
A2: 泰溢农行 | C2: 供应商 | E2: 成都蓉港商业发展有限公司 | G2: 成都鑫鑫向喜商贸有限公司
A3: 泰溢招行 | E3: 成都市双流区公共资源交易服务中心 | G3: 成都统一企业食品有限公司
A4: 趣点购浦发 | C4: 办公费 | E4: 陈金刚 | G4: 陈金刚
A5: 雅安趣点购农行 | C5: 水费 | E5: 成都空港公园城市绿道建设投资有限公司 | G5: 成都勤献食品有限公司
C6: 电费 | E6: 客户5 | G6: 武汉小麦便利科技有限公司
C7: 伙食费 | E7: 客户6 | G7: 供应商6
C8: 工资 | E8: 客户7 | G8: 供应商7
C9: 租赁费 | E9: 客户8 | G9: 供应商8
C10: 差旅费 | E10: 客户9 | G10: 供应商9
C11: 业务招待费 | E11: 客户10 | G11: 供应商10
C12: 车辆费用 | E12: 客户11 | G12: 供应商11
C13: 银行手续费 | E13: 客户12 | G13: 供应商12
C14: 税费 | E14: 客户13 | G14: 供应商13
C15: 设备款
C16: 投标保证金
C17: 合同履约保证金
C18: 借款
C19: 场地租金

Sheet 数据录入
A1: 多帐户收支登记表
F2: 收入总额 | G2: 支出总额 | H2: 账户余额
F3: =SUBTOTAL(109,$F$4:$F$9999) -> 0 | G3: =SUBTOTAL(109,$G$4:$G$9999) -> 733050 | H3: =SUBTOTAL(109,$H$5:$H$18)+F3-G3 -> -733050
A4: 序号 | B4: 日期 | C4: 公司账户 | D4: 支出业务类别 | E4: 摘要内容 | F4: 收入 | G4: 支出 | H4: 账户余额 | I4: 客户 | J4: 供应商 | K4: 月份
A5: =IF(B5="","",COUNTA($B$5:B5)) -> 1 | B5: 46174 | C5: 现金 | E5: 期初余额 | H5: 0 | K5: =IF($B5="","",--TEXT($B5,"yyyymm")) -> 202606
A6: =IF(B6="","",COUNTA($B$5:B6)) -> 2 | B6: 46174 | C6: 微信 | E6: 期初余额 | H6: 0 | K6: =IF($B6="","",--TEXT($B6,"yyyymm")) -> 202606
A7: =IF(B7="","",COUNTA($B$5:B7)) -> 3 | B7: 46174 | C7: 趣点购浦发 | E7: 期初余额 | H7: 0 | K7: =IF($B7="","",--TEXT($B7,"yyyymm")) -> 202606
A8: =IF(B8="","",COUNTA($B$5:B8)) -> 4 | B8: 46174 | C8: 民生 | E8: 期初余额 | H8: 0 | K8: =IF($B8="","",--TEXT($B8,"yyyymm")) -> 202606
A9: =IF(B9="","",COUNTA($B$5:B9)) -> 5 | B9: 46174 | C9: 建行 | E9: 期初余额 | H9: 0 | K9: =IF($B9="","",--TEXT($B9,"yyyymm")) -> 202606
A10: =IF(B10="","",COUNTA($B$5:B10)) -> 6 | B10: 46174 | C10: 农行 | E10: 期初余额 | H10: 0 | K10: =IF($B10="","",--TEXT($B10,"yyyymm")) -> 202606
A11: =IF(B11="","",COUNTA($B$5:B11)) -> 7 | B11: 46174 | C11: 中行 | E11: 期初余额 | H11: 0 | K11: =IF($B11="","",--TEXT($B11,"yyyymm")) -> 202606
A12: =IF(B12="","",COUNTA($B$5:B12)) -> 8 | B12: 46174 | C12: 支付宝 | E12: 期初余额 | H12: 0 | K12: =IF($B12="","",--TEXT($B12,"yyyymm")) -> 202606
A13: =IF(B13="","",COUNTA($B$5:B13)) -> 9 | B13: 46174 | C13: 农商行 | E13: 期初余额 | H13: 0 | K13: =IF($B13="","",--TEXT($B13,"yyyymm")) -> 202606
A14: =IF(B14="","",COUNTA($B$5:B14)) -> 10 | B14: 46174 | C14: 备用 | E14: 期初余额 | H14: 0 | K14: =IF($B14="","",--TEXT($B14,"yyyymm")) -> 202606
A15: =IF(B15="","",COUNTA($B$5:B15)) -> 11 | B15: 46174 | C15: 备用1 | E15: 期初余额 | H15: 0 | K15: =IF($B15="","",--TEXT($B15,"yyyymm")) -> 202606
A16: =IF(B16="","",COUNTA($B$5:B16)) -> 12 | B16: 46174 | C16: 备用2 | E16: 期初余额 | H16: 0 | K16: =IF($B16="","",--TEXT($B16,"yyyymm")) -> 202606
... A18: =IF(B18="","",COUNTA($B$5:B18)) -> 14 | B18: 46174 | C18: 备用4 | E18: 期初余额 | H18: 0 | K18: =IF($B18="","",--TEXT($B18,"yyyymm")) -> 202606
A19: =IF(B19="","",COUNTA($B$5:B19)) -> 15 | B19: 46127 | C19: 趣点购浦发 | E19: 银行变更资料 | F19: 200 | H19: =IFERROR(VLOOKUP($C19,$C$5:$H$18,6,0)+SUMIF($C$19:$C19,$C19,$F$19:$F19)-SUMIF($C$19:$C19,$C19,$G$19:$G19),"") -> 200 | K19: =IF($B19="","",--TEXT($B19,"yyyymm")) -> 202604
A20: =IF(B20="","",COUNTA($B$5:B20)) -> 16 | B20: 46127 | C20: 趣点购浦发 | D20: 银行手续费 | E20: 公司手机银行服务年费 | G20: 43.12 | H20: =IFERROR(VLOOKUP($C20,$C$5:$H$18,6,0)+SUMIF($C$19:$C20,$C20,$F$19:$F20)-SUMIF($C$19:$C20,$C20,$G$19:$G20),"") -> 156.88 | K20: =IF($B20="","",--TEXT($B20,"yyyymm")) -> 202604
A21: =IF(B21="","",COUNTA($B$5:B21)) -> 17 | B21: 46127 | C21: 趣点购浦发 | D21: 银行手续费 | E21: 帐户信息变更 | G21: 16 | H21: =IFERROR(VLOOKUP($C21,$C$5:$H$18,6,0)+SUMIF($C$19:$C21,$C21,$F$19:$F21)-SUMIF($C$19:$C21,$C21,$G$19:$G21),"") -> 140.88 | K21: =IF($B21="","",--TEXT($B21,"yyyymm")) -> 202604
A22: =IF(B22="","",COUNTA($B$5:B22)) -> 18 | B22: 46127 | C22: 趣点购浦发 | D22: 银行手续费 | E22: 印鉴变更 | G22: 10 | H22: =IFERROR(VLOOKUP($C22,$C$5:$H$18,6,0)+SUMIF($C$19:$C22,$C22,$F$19:$F22)-SUMIF($C$19:$C22,$C22,$G$19:$G22),"") -> 130.88 | K22: =IF($B22="","",--TEXT($B22,"yyyymm")) -> 202604
A23: =IF(B23="","",COUNTA($B$5:B23)) -> 19 | B23: 46128 | C23: 趣点购浦发 | D23: 银行手续费 | E23: 公司网银服务年费,公司手机银行服务年费,公司网银数字证书(2张) | G23: 130.88 | H23: =IFERROR(VLOOKUP($C23,$C$5:$H$18,6,0)+SUMIF($C$19:$C23,$C23,$F$19:$F23)-SUMIF($C$19:$C23,$C23,$G$19:$G23),"") -> 0 | K23: =IF($B23="","",--TEXT($B23,"yyyymm")) -> 202604
A24: =IF(B24="","",COUNTA($B$5:B24)) -> 20 | B24: 46129 | C24: 趣点购浦发 | E24: 入股金 | F24: 10000 | H24: =IFERROR(VLOOKUP($C24,$C$5:$H$18,6,0)+SUMIF($C$19:$C24,$C24,$F$19:$F24)-SUMIF($C$19:$C24,$C24,$G$19:$G24),"") -> 10000 | K24: =IF($B24="","",--TEXT($B24,"yyyymm")) -> 202604
A25: =IF(B25="","",COUNTA($B$5:B25)) -> 21 | B25: 46129 | C25: 趣点购浦发 | D25: 银行手续费 | E25: 公司网银数字证书(2张) | G25: 19.12 | H25: =IFERROR(VLOOKUP($C25,$C$5:$H$18,6,0)+SUMIF($C$19:$C25,$C25,$F$19:$F25)-SUMIF($C$19:$C25,$C25,$G$19:$G25),"") -> 9980.88 | K25: =IF($B25="","",--TEXT($B25,"yyyymm")) -> 202604
A26: =IF(B26="","",COUNTA($B$5:B26)) -> 22 | B26: 46129 | C26: 趣点购浦发 | D26: 银行手续费 | E26: 单位结算卡年费金卡 | G26: 100 | H26: =IFERROR(VLOOKUP($C26,$C$5:$H$18,6,0)+SUMIF($C$19:$C26,$C26,$F$19:$F26)-SUMIF($C$19:$C26,$C26,$G$19:$G26),"") -> 9880.88 | K26: =IF($B26="","",--TEXT($B26,"yyyymm")) -> 202604
A27: =IF(B27="","",COUNTA($B$5:B27)) -> 23 | B27: 46136 | C27: 趣点购浦发 | D27: 办公费 | E27: 四川CA电子签名认证证书申请验证 | G27: 0.05 | H27: =IFERROR(VLOOKUP($C27,$C$5:$H$18,6,0)+SUMIF($C$19:$C27,$C27,$F$19:$F27)-SUMIF($C$19:$C27,$C27,$G$19:$G27),"") -> 9880.83 | K27: =IF($B27="","",--TEXT($B27,"yyyymm")) -> 202604
A28: =IF(B28="","",COUNTA($B$5:B28)) -> 24 | B28: 46136 | C28: 趣点购浦发 | D28: 银行手续费 | E28: 网银互联汇出手续费 | G28: 4.5 | H28: =IFERROR(VLOOKUP($C28,$C$5:$H$18,6,0)+SUMIF($C$19:$C28,$C28,$F$19:$F28)-SUMIF($C$19:$C28,$C28,$G$19:$G28),"") -> 9876.33 | K28: =IF($B28="","",--TEXT($B28,"yyyymm")) -> 202604
A29: =IF(B29="","",COUNTA($B$5:B29)) -> 25 | B29: 46140 | C29: 趣点购浦发 | E29: 四川CA电子签名认证证书申请验证退款 | F29: 0.05 | H29: =IFERROR(VLOOKUP($C29,$C$5:$H$18,6,0)+SUMIF($C$19:$C29,$C29,$F$19:$F29)-SUMIF($C$19:$C29,$C29,$G$19:$G29),"") -> 9876.38 | K29: =IF($B29="","",--TEXT($B29,"yyyymm")) -> 202604
A30: =IF(B30="","",COUNTA($B$5:B30)) -> 26 | B30: 46142 | C30: 趣点购浦发 | E30: 入股金 | F30: 70000 | H30: =IFERROR(VLOOKUP($C30,$C$5:$H$18,6,0)+SUMIF($C$19:$C30,$C30,$F$19:$F30)-SUMIF($C$19:$C30,$C30,$G$19:$G30),"") -> 79876.38 | K30: =IF($B30="","",--TEXT($B30,"yyyymm")) -> 202604
A31: =IF(B31="","",COUNTA($B$5:B31)) -> 27 | B31: 46142 | C31: 趣点购浦发 | E31: 入股金 | F31: 50000 | H31: =IFERROR(VLOOKUP($C31,$C$5:$H$18,6,0)+SUMIF($C$19:$C31,$C31,$F$19:$F31)-SUMIF($C$19:$C31,$C31,$G$19:$G31),"") -> 129876.38 | K31: =IF($B31="","",--TEXT($B31,"yyyymm")) -> 202604
A32: =IF(B32="","",COUNTA($B$5:B32)) -> 28 | B32: 46142 | C32: 趣点购浦发 | E32: 雅安趣点购农行互转趣点购浦发 | F32: 20500 | H32: =IFERROR(VLOOKUP($C32,$C$5:$H$18,6,0)+SUMIF($C$19:$C32,$C32,$F$19:$F32)-SUMIF($C$19:$C32,$C32,$G$19:$G32),"") -> 150376.38 | K32: =IF($B32="","",--TEXT($B32,"yyyymm")) -> 202604
A33: =IF(B33="","",COUNTA($B$5:B33)) -> 29 | B33: 46142 | C33: 趣点购浦发 | D33: 往来款 | E33: 脉动货款 | G33: 150000 | H33: =IFERROR(VLOOKUP($C33,$C$5:$H$18,6,0)+SUMIF($C$19:$C33,$C33,$F$19:$F33)-SUMIF($C$19:$C33,$C33,$G$19:$G33),"") -> 376.38 | J33: 成都鑫鑫向喜商贸有限公司 | K33: =IF($B33="","",--TEXT($B33,"yyyymm")) -> 202604
A34: =IF(B34="","",COUNTA($B$5:B34)) -> 30 | B34: 46142 | C34: 趣点购浦发 | D34: 银行手续费 | E34: 网银互联汇出手续费 | G34: 15 | H34: =IFERROR(VLOOKUP($C34,$C$5:$H$18,6,0)+SUMIF($C$19:$C34,$C34,$F$19:$F34)-SUMIF($C$19:$C34,$C34,$G$19:$G34),"") -> 361.38 | K34: =IF($B34="","",--TEXT($B34,"yyyymm")) -> 202604
A35: =IF(B35="","",COUNTA($B$5:B35)) -> 31 | B35: 46146 | C35: 趣点购浦发 | E35: 入股金 | F35: 90000 | H35: =IFERROR(VLOOKUP($C35,$C$5:$H$18,6,0)+SUMIF($C$19:$C35,$C35,$F$19:$F35)-SUMIF($C$19:$C35,$C35,$G$19:$G35),"") -> 90361.38 | K35: =IF($B35="","",--TEXT($B35,"yyyymm")) -> 202605
A36: =IF(B36="","",COUNTA($B$5:B36)) -> 32 | B36: 46146 | C36: 趣点购浦发 | D36: 往来款 | E36: 脉动货款 | G36: 82400 | H36: =IFERROR(VLOOKUP($C36,$C$5:$H$18,6,0)+SUMIF($C$19:$C36,$C36,$F$19:$F36)-SUMIF($C$19:$C36,$C36,$G$19:$G36),"") -> 7961.38 | J36: 成都鑫鑫向喜商贸有限公司 | K36: =IF($B36="","",--TEXT($B36,"yyyymm")) -> 202605
A37: =IF(B37="","",COUNTA($B$5:B37)) -> 33 | B37: 46146 | C37: 趣点购浦发 | D37: 银行手续费 | E37: 网银互联汇出手续费 | G37: 9 | H37: =IFERROR(VLOOKUP($C37,$C$5:$H$18,6,0)+SUMIF($C$19:$C37,$C37,$F$19:$F37)-SUMIF($C$19:$C37,$C37,$G$19:$G37),"") -> 7952.38 | K37: =IF($B37="","",--TEXT($B37,"yyyymm")) -> 202605
A38: =IF(B38="","",COUNTA($B$5:B38)) -> 34 | B38: 46151 | C38: 趣点购浦发 | D38: 税费 | E38: 缴税 | G38: 450 | H38: =IFERROR(VLOOKUP($C38,$C$5:$H$18,6,0)+SUMIF($C$19:$C38,$C38,$F$19:$F38)-SUMIF($C$19:$C38,$C38,$G$19:$G38),"") -> 7502.38 | K38: =IF($B38="","",--TEXT($B38,"yyyymm")) -> 202605
A39: =IF(B39="","",COUNTA($B$5:B39)) -> 35 | B39: 46154 | C39: 趣点购浦发 | D39: 工资 | E39: 陈樨 | G39: 4500 | H39: =IFERROR(VLOOKUP($C39,$C$5:$H$18,6,0)+SUMIF($C$19:$C39,$C39,$F$19:$F39)-SUMIF($C$19:$C39,$C39,$G$19:$G39),"") -> 3002.38 | K39: =IF($B39="","",--TEXT($B39,"yyyymm")) -> 202605
A40: =IF(B40="","",COUNTA($B$5:B40)) -> 36 | B40: 46154 | C40: 趣点购浦发 | D40: 银行手续费 | E40: 网银互联汇出手续费 | G40: 4.5 | H40: =IFERROR(VLOOKUP($C40,$C$5:$H$18,6,0)+SUMIF($C$19:$C40,$C40,$F$19:$F40)-SUMIF($C$19:$C40,$C40,$G$19:$G40),"") -> 2997.88 | K40: =IF($B40="","",--TEXT($B40,"yyyymm")) -> 202605
A41: =IF(B41="","",COUNTA($B$5:B41)) -> 37 | B41: 46158 | C41: 趣点购浦发 | E41: 入股金 | F41: 30000 | H41: =IFERROR(VLOOKUP($C41,$C$5:$H$18,6,0)+SUMIF($C$19:$C41,$C41,$F$19:$F41)-SUMIF($C$19:$C41,$C41,$G$19:$G41),"") -> 32997.88 | K41: =IF($B41="","",--TEXT($B41,"yyyymm")) -> 202605
...

Sheet 投标和合同履约保证金统计
A1: 保证金收款 / 付款统计（按起止日期）
A2: 开始日期 | B2: 46023 | C2: 结束日期 | D2: 46387 | F2: 期初余款 | G2: =SUMIFS(数据录入!$F$5:$F$4999,$Q$5:$Q$4999,1,数据录入!$B$5:$B$4999,"<"&$B$2)-SUMIFS(数据录入!$G$5:$G$4999,$Q$5:$Q$4999,1,数据录入!$B$5:$B$4999,"<"&$B$2)
A3: 说明：修改黄色起止日期即可查询。明细自动提取「数据录入」中业务类别为投标保证金 / 合同履约保证金，或摘要含“保证金”的收付记录；往来单位取自客户与供应商（见「基础资料」）。余额＝期初余款＋收款－付款，负数表示保证金已付出、尚未收回。 | F3: 期间收入 | G3: =SUMIFS(数据录入!$F$5:$F$4999,$Q$5:$Q$4999,1,数据录入!$B$5:$B$4999,">="&$B$2,数据录入!$B$5:$B$4999,"<="&$D$2)
F4: 期间付款 | G4: =SUMIFS(数据录入!$G$5:$G$4999,$Q$5:$Q$4999,1,数据录入!$B$5:$B$4999,">="&$B$2,数据录入!$B$5:$B$4999,"<="&$D$2) | Q4: 保证金标记 | R4: 期内序号
F5: 期末余额 | G5: =G2+G3-G4 | K5: 其他（未指定往来单位） | L5: =$G$2-SUM($L$8:$L$107) | M5: =$G$3-SUM($M$8:$M$107) | N5: =$G$4-SUM($N$8:$N$107) | O5: =L5+M5-N5 | Q5: =IF(数据录入!$B5="",0,IF(OR(数据录入!$D5="投标保证金",数据录入!$D5="合同履约保证金",ISNUMBER(FIND("保证金",数据录入!$E5))),1,0)) | R5: =IF(AND($Q5=1,数据录入!$B5>=$B$2,数据录入!$B5<=$D$2),N(R4)+1,N(R4))
A6: =IF(MAX($R$5:$R$4999)>500,"※ 期间保证金记录超过 500 条，明细仅显示前 500 条，请缩小查询区间或向下复制明细公式。","") | K6: 合计 | L6: =L5+SUM($L$8:$L$107) | M6: =M5+SUM($M$8:$M$107) | N6: =N5+SUM($N$8:$N$107) | O6: =L6+M6-N6 | Q6: =IF(数据录入!$B6="",0,IF(OR(数据录入!$D6="投标保证金",数据录入!$D6="合同履约保证金",ISNUMBER(FIND("保证金",数据录入!$E6))),1,0)) | R6: =IF(AND($Q6=1,数据录入!$B6>=$B$2,数据录入!$B6<=$D$2),N(R5)+1,N(R5))
A7: 日期 | B7: 账户 | C7: 类型 | D7: 往来单位 | E7: 摘要 | F7: 收入金额 | G7: 付款金额 | H7: 余额 | J7: 序 | K7: 往来单位 | L7: 期初余款 | M7: 期间收款 | N7: 期间付款 | O7: 期末余额 | Q7: =IF(数据录入!$B7="",0,IF(OR(数据录入!$D7="投标保证金",数据录入!$D7="合同履约保证金",ISNUMBER(FIND("保证金",数据录入!$E7))),1,0)) | R7: =IF(AND($Q7=1,数据录入!$B7>=$B$2,数据录入!$B7<=$D$2),N(R6)+1,N(R6)) | S7: 明细定位 | U7: 往来单位候选 | V7: 有效标记 | W7: 往来单位序号
A8: =IF($S8="","",INDEX(数据录入!$B$5:$B$4999,$S8)) | B8: =IF($S8="","",INDEX(数据录入!$C$5:$C$4999,$S8)&"") | C8: =IF($S8="","",IF(N($F8)>0,"收款",IF(N($G8)>0,"付款",""))) | D8: =IF($S8="","",IF((INDEX(数据录入!$I$5:$I$4999,$S8)&"")<>"",INDEX(数据录入!$I$5:$I$4999,$S8)&"",INDEX(数据录入!$J$5:$J$4999,$S8)&"")) | E8: =IF($S8="","",INDEX(数据录入!$E$5:$E$4999,$S8)&"") | F8: =IF($S8="","",N(INDEX(数据录入!$F$5:$F$4999,$S8))) | G8: =IF($S8="","",N(INDEX(数据录入!$G$5:$G$4999,$S8))) | H8: =IF($S8="","",$G$2+SUM($F$8:$F8)-SUM($G$8:$G8)) | J8: =IF($K8="","",1) | K8: =IFERROR(INDEX($U$8:$U$107,MATCH(1,$W$8:$W$107,0)),"") | L8: =IF($K8="","",(SUMIFS(数据录入!$F$5:$F$4999,$Q$5:$Q$4999,1,数据录入!$B$5:$B$4999,"<"&$B$2,数据录入!$I$5:$I$4999,$K8)+SUMIFS(数据录入!$F$5:$F$4999,$Q$5:$Q$4999,1,数据录入!$B$5:$B$4999,"<"&$B$2,数据录入!$J$5:$J$4999,$K8))-(SUMIFS(数据录入!$G$5:$G$4999,$Q$5:$Q$4999,1,数据录入!$B$5:$B$4999,"<"&$B$2,数据录入!$I$5:$I$4999,$K8)+SUMIFS(数据录入!$G$5:$G$4999,$Q$5:$Q$4999,1,数据录入!$B$5:$B$4999,"<"&$B$2,数据录入!$J$5:$J$4999,$K8))) | M8: =IF($K8="","",SUMIFS(数据录入!$F$5:$F$4999,$Q$5:$Q$4999,1,数据录入!$B$5:$B$4999,">="&$B$2,数据录入!$B$5:$B$4999,"<="&$D$2,数据录入!$I$5:$I$4999,$K8)+SUMIFS(数据录入!$F$5:$F$4999,$Q$5:$Q$4999,1,数据录入!$B$5:$B$4999,">="&$B$2,数据录入!$B$5:$B$4999,"<="&$D$2,数据录入!$J$5:$J$4999,$K8)) | N8: =IF($K8="","",SUMIFS(数据录入!$G$5:$G$4999,$Q$5:$Q$4999,1,数据录入!$B$5:$B$4999,">="&$B$2,数据录入!$B$5:$B$4999,"<="&$D$2,数据录入!$I$5:$I$4999,$K8)+SUMIFS(数据录入!$G$5:$G$4999,$Q$5:$Q$4999,1,数据录入!$B$5:$B$4999,">="&$B$2,数据录入!$B$5:$B$4999,"<="&$D$2,数据录入!$J$5:$J$4999,$K8)) | O8: =IF($K8="","",L8+M8-N8) | Q8: =IF(数据录入!$B8="",0,IF(OR(数据录入!$D8="投标保证金",数据录入!$D8="合同履约保证金",ISNUMBER(FIND("保证金",数据录入!$E8))),1,0)) | R8: =IF(AND($Q8=1,数据录入!$B8>=$B$2,数据录入!$B8<=$D$2),N(R7)+1,N(R7)) | S8: =IFERROR(MATCH(1,$R$5:$R$4999,0),"") | U8: =IFERROR(IF(1<=50,INDEX(基础资料!$E$2:$E$51,1)&"",INDEX(基础资料!$G$2:$G$51,1-50)&""),"") | V8: =IF($U8="",0,IF(AND(1>50,COUNTIF(基础资料!$E$2:$E$51,$U8)>0),0,1)) | W8: =IF($V8=1,N(W7)+1,N(W7))
A9: =IF($S9="","",INDEX(数据录入!$B$5:$B$4999,$S9)) | B9: =IF($S9="","",INDEX(数据录入!$C$5:$C$4999,$S9)&"") | C9: =IF($S9="","",IF(N($F9)>0,"收款",IF(N($G9)>0,"付款",""))) | D9: =IF($S9="","",IF((INDEX(数据录入!$I$5:$I$4999,$S9)&"")<>"",INDEX(数据录入!$I$5:$I$4999,$S9)&"",INDEX(数据录入!$J$5:$J$4999,$S9)&"")) | E9: =IF($S9="","",INDEX(数据录入!$E$5:$E$4999,$S9)&"") | F9: =IF($S9="","",N(INDEX(数据录入!$F$5:$F$4999,$S9))) | G9: =IF($S9="","",N(INDEX(数据录入!$G$5:$G$4999,$S9))) | H9: =IF($S9="","",$G$2+SUM($F$8:$F9)-SUM($G$8:$G9)) | J9: =IF($K9="","",2) | K9: =IFERROR(INDEX($U$8:$U$107,MATCH(2,$W$8:$W$107,0)),"") | L9: =IF($K9="","",(SUMIFS(数据录入!$F$5:$F$4999,$Q$5:$Q$4999,1,数据录入!$B$5:$B$4999,"<"&$B$2,数据录入!$I$5:$I$4999,$K9)+SUMIFS(数据录入!$F$5:$F$4999,$Q$5:$Q$4999,1,数据录入!$B$5:$B$4999,"<"&$B$2,数据录入!$J$5:$J$4999,$K9))-(SUMIFS(数据录入!$G$5:$G$4999,$Q$5:$Q$4999,1,数据录入!$B$5:$B$4999,"<"&$B$2,数据录入!$I$5:$I$4999,$K9)+SUMIFS(数据录入!$G$5:$G$4999,$Q$5:$Q$4999,1,数据录入!$B$5:$B$4999,"<"&$B$2,数据录入!$J$5:$J$4999,$K9))) | M9: =IF($K9="","",SUMIFS(数据录入!$F$5:$F$4999,$Q$5:$Q$4999,1,数据录入!$B$5:$B$4999,">="&$B$2,数据录入!$B$5:$B$4999,"<="&$D$2,数据录入!$I$5:$I$4999,$K9)+SUMIFS(数据录入!$F$5:$F$4999,$Q$5:$Q$4999,1,数据录入!$B$5:$B$4999,">="&$B$2,数据录入!$B$5:$B$4999,"<="&$D$2,数据录入!$J$5:$J$4999,$K9)) | N9: =IF($K9="","",SUMIFS(数据录入!$G$5:$G$4999,$Q$5:$Q$4999,1,数据录入!$B$5:$B$4999,">="&$B$2,数据录入!$B$5:$B$4999,"<="&$D$2,数据录入!$I$5:$I$4999,$K9)+SUMIFS(数据录入!$G$5:$G$4999,$Q$5:$Q$4999,1,数据录入!$B$5:$B$4999,">="&$B$2,数据录入!$B$5:$B$4999,"<="&$D$2,数据录入!$J$5:$J$4999,$K9)) | O9: =IF($K9="","",L9+M9-N9) | Q9: =IF(数据录入!$B9="",0,IF(OR(数据录入!$D9="投标保证金",数据录入!$D9="合同履约保证金",ISNUMBER(FIND("保证金",数据录入!$E9))),1,0)) | R9: =IF(AND($Q9=1,数据录入!$B9>=$B$2,数据录入!$B9<=$D$2),N(R8)+1,N(R8)) | S9: =IFERROR(MATCH(2,$R$5:$R$4999,0),"") | U9: =IFERROR(IF(2<=50,INDEX(基础资料!$E$2:$E$51,2)&"",INDEX(基础资料!$G$2:$G$51,2-50)&""),"") | V9: =IF($U9="",0,IF(AND(2>50,COUNTIF(基础资料!$E$2:$E$51,$U9)>0),0,1)) | W9: =IF($V9=1,N(W8)+1,N(W8))
A10: =IF($S10="","",INDEX(数据录入!$B$5:$B$4999,$S10)) | B10: =IF($S10="","",INDEX(数据录入!$C$5:$C$4999,$S10)&"") | C10: =IF($S10="","",IF(N($F10)>0,"收款",IF(N($G10)>0,"付款",""))) | D10: =IF($S10="","",IF((INDEX(数据录入!$I$5:$I$4999,$S10)&"")<>"",INDEX(数据录入!$I$5:$I$4999,$S10)&"",INDEX(数据录入!$J$5:$J$4999,$S10)&"")) | E10: =IF($S10="","",INDEX(数据录入!$E$5:$E$4999,$S10)&"") | F10: =IF($S10="","",N(INDEX(数据录入!$F$5:$F$4999,$S10))) | G10: =IF($S10="","",N(INDEX(数据录入!$G$5:$G$4999,$S10))) | H10: =IF($S10="","",$G$2+SUM($F$8:$F10)-SUM($G$8:$G10)) | J10: =IF($K10="","",3) | K10: =IFERROR(INDEX($U$8:$U$107,MATCH(3,$W$8:$W$107,0)),"") | L10: =IF($K10="","",(SUMIFS(数据录入!$F$5:$F$4999,$Q$5:$Q$4999,1,数据录入!$B$5:$B$4999,"<"&$B$2,数据录入!$I$5:$I$4999,$K10)+SUMIFS(数据录入!$F$5:$F$4999,$Q$5:$Q$4999,1,数据录入!$B$5:$B$4999,"<"&$B$2,数据录入!$J$5:$J$4999,$K10))-(SUMIFS(数据录入!$G$5:$G$4999,$Q$5:$Q$4999,1,数据录入!$B$5:$B$4999,"<"&$B$2,数据录入!$I$5:$I$4999,$K10)+SUMIFS(数据录入!$G$5:$G$4999,$Q$5:$Q$4999,1,数据录入!$B$5:$B$4999,"<"&$B$2,数据录入!$J$5:$J$4999,$K10))) | M10: =IF($K10="","",SUMIFS(数据录入!$F$5:$F$4999,$Q$5:$Q$4999,1,数据录入!$B$5:$B$4999,">="&$B$2,数据录入!$B$5:$B$4999,"<="&$D$2,数据录入!$I$5:$I$4999,$K10)+SUMIFS(数据录入!$F$5:$F$4999,$Q$5:$Q$4999,1,数据录入!$B$5:$B$4999,">="&$B$2,数据录入!$B$5:$B$4999,"<="&$D$2,数据录入!$J$5:$J$4999,$K10)) | N10: =IF($K10="","",SUMIFS(数据录入!$G$5:$G$4999,$Q$5:$Q$4999,1,数据录入!$B$5:$B$4999,">="&$B$2,数据录入!$B$5:$B$4999,"<="&$D$2,数据录入!$I$5:$I$4999,$K10)+SUMIFS(数据录入!$G$5:$G$4999,$Q$5:$Q$4999,1,数据录入!$B$5:$B$4999,">="&$B$2,数据录入!$B$5:$B$4999,"<="&$D$2,数据录入!$J$5:$J$4999,$K10)) | O10: =IF($K10="","",L10+M10-N10) | Q10: =IF(数据录入!$B10="",0,IF(OR(数据录入!$D10="投标保证金",数据录入!$D10="合同履约保证金",ISNUMBER(FIND("保证金",数据录入!$E10))),1,0)) | R10: =IF(AND($Q10=1,数据录入!$B10>=$B$2,数据录入!$B10<=$D$2),N(R9)+1,N(R9)) | S10: =IFERROR(MATCH(3,$R$5:$R$4999,0),"") | U10: =IFERROR(IF(3<=50,INDEX(基础资料!$E$2:$E$51,3)&"",INDEX(基础资料!$G$2:$G$51,3-50)&""),"") | V10: =IF($U10="",0,IF(AND(3>50,COUNTIF(基础资料!$E$2:$E$51,$U10)>0),0,1)) | W10: =IF($V10=1,N(W9)+1,N(W9))
A11: =IF($S11="","",INDEX(数据录入!$B$5:$B$4999,$S11)) | B11: =IF($S11="","",INDEX(数据录入!$C$5:$C$4999,$S11)&"") | C11: =IF($S11="","",IF(N($F11)>0,"收款",IF(N($G11)>0,"付款",""))) | D11: =IF($S11="","",IF((INDEX(数据录入!$I$5:$I$4999,$S11)&"")<>"",INDEX(数据录入!$I$5:$I$4999,$S11)&"",INDEX(数据录入!$J$5:$J$4999,$S11)&"")) | E11: =IF($S11="","",INDEX(数据录入!$E$5:$E$4999,$S11)&"") | F11: =IF($S11="","",N(INDEX(数据录入!$F$5:$F$4999,$S11))) | G11: =IF($S11="","",N(INDEX(数据录入!$G$5:$G$4999,$S11))) | H11: =IF($S11="","",$G$2+SUM($F$8:$F11)-SUM($G$8:$G11)) | J11: =IF($K11="","",4) | K11: =IFERROR(INDEX($U$8:$U$107,MATCH(4,$W$8:$W$107,0)),"") | L11: =IF($K11="","",(SUMIFS(数据录入!$F$5:$F$4999,$Q$5:$Q$4999,1,数据录入!$B$5:$B$4999,"<"&$B$2,数据录入!$I$5:$I$4999,$K11)+SUMIFS(数据录入!$F$5:$F$4999,$Q$5:$Q$4999,1,数据录入!$B$5:$B$4999,"<"&$B$2,数据录入!$J$5:$J$4999,$K11))-(SUMIFS(数据录入!$G$5:$G$4999,$Q$5:$Q$4999,1,数据录入!$B$5:$B$4999,"<"&$B$2,数据录入!$I$5:$I$4999,$K11)+SUMIFS(数据录入!$G$5:$G$4999,$Q$5:$Q$4999,1,数据录入!$B$5:$B$4999,"<"&$B$2,数据录入!$J$5:$J$4999,$K11))) | M11: =IF($K11="","",SUMIFS(数据录入!$F$5:$F$4999,$Q$5:$Q$4999,1,数据录入!$B$5:$B$4999,">="&$B$2,数据录入!$B$5:$B$4999,"<="&$D$2,数据录入!$I$5:$I$4999,$K11)+SUMIFS(数据录入!$F$5:$F$4999,$Q$5:$Q$4999,1,数据录入!$B$5:$B$4999,">="&$B$2,数据录入!$B$5:$B$4999,"<="&$D$2,数据录入!$J$5:$J$4999,$K11)) | N11: =IF($K11="","",SUMIFS(数据录入!$G$5:$G$4999,$Q$5:$Q$4999,1,数据录入!$B$5:$B$4999,">="&$B$2,数据录入!$B$5:$B$4999,"<="&$D$2,数据录入!$I$5:$I$4999,$K11)+SUMIFS(数据录入!$G$5:$G$4999,$Q$5:$Q$4999,1,数据录入!$B$5:$B$4999,">="&$B$2,数据录入!$B$5:$B$4999,"<="&$D$2,数据录入!$J$5:$J$4999,$K11)) | O11: =IF($K11="","",L11+M11-N11) | Q11: =IF(数据录入!$B11="",0,IF(OR(数据录入!$D11="投标保证金",数据录入!$D11="合同履约保证金",ISNUMBER(FIND("保证金",数据录入!$E11))),1,0)) | R11: =IF(AND($Q11=1,数据录入!$B11>=$B$2,数据录入!$B11<=$D$2),N(R10)+1,N(R10)) | S11: =IFERROR(MATCH(4,$R$5:$R$4999,0),"") | U11: =IFERROR(IF(4<=50,INDEX(基础资料!$E$2:$E$51,4)&"",INDEX(基础资料!$G$2:$G$51,4-50)&""),"") | V11: =IF($U11="",0,IF(AND(4>50,COUNTIF(基础资料!$E$2:$E$51,$U11)>0),0,1)) | W11: =IF($V11=1,N(W10)+1,N(W10))
A12: =IF($S12="","",INDEX(数据录入!$B$5:$B$4999,$S12)) | B12: =IF($S12="","",INDEX(数据录入!$C$5:$C$4999,$S12)&"") | C12: =IF($S12="","",IF(N($F12)>0,"收款",IF(N($G12)>0,"付款",""))) | D12: =IF($S12="","",IF((INDEX(数据录入!$I$5:$I$4999,$S12)&"")<>"",INDEX(数据录入!$I$5:$I$4999,$S12)&"",INDEX(数据录入!$J$5:$J$4999,$S12)&"")) | E12: =IF($S12="","",INDEX(数据录入!$E$5:$E$4999,$S12)&"") | F12: =IF($S12="","",N(INDEX(数据录入!$F$5:$F$4999,$S12))) | G12: =IF($S12="","",N(INDEX(数据录入!$G$5:$G$4999,$S12))) | H12: =IF($S12="","",$G$2+SUM($F$8:$F12)-SUM($G$8:$G12)) | J12: =IF($K12="","",5) | K12: =IFERROR(INDEX($U$8:$U$107,MATCH(5,$W$8:$W$107,0)),"") | L12: =IF($K12="","",(SUMIFS(数据录入!$F$5:$F$4999,$Q$5:$Q$4999,1,数据录入!$B$5:$B$4999,"<"&$B$2,数据录入!$I$5:$I$4999,$K12)+SUMIFS(数据录入!$F$5:$F$4999,$Q$5:$Q$4999,1,数据录入!$B$5:$B$4999,"<"&$B$2,数据录入!$J$5:$J$4999,$K12))-(SUMIFS(数据录入!$G$5:$G$4999,$Q$5:$Q$4999,1,数据录入!$B$5:$B$4999,"<"&$B$2,数据录入!$I$5:$I$4999,$K12)+SUMIFS(数据录入!$G$5:$G$4999,$Q$5:$Q$4999,1,数据录入!$B$5:$B$4999,"<"&$B$2,数据录入!$J$5:$J$4999,$K12))) | M12: =IF($K12="","",SUMIFS(数据录入!$F$5:$F$4999,$Q$5:$Q$4999,1,数据录入!$B$5:$B$4999,">="&$B$2,数据录入!$B$5:$B$4999,"<="&$D$2,数据录入!$I$5:$I$4999,$K12)+SUMIFS(数据录入!$F$5:$F$4999,$Q$5:$Q$4999,1,数据录入!$B$5:$B$4999,">="&$B$2,数据录入!$B$5:$B$4999,"<="&$D$2,数据录入!$J$5:$J$4999,$K12)) | N12: =IF($K12="","",SUMIFS(数据录入!$G$5:$G$4999,$Q$5:$Q$4999,1,数据录入!$B$5:$B$4999,">="&$B$2,数据录入!$B$5:$B$4999,"<="&$D$2,数据录入!$I$5:$I$4999,$K12)+SUMIFS(数据录入!$G$5:$G$4999,$Q$5:$Q$4999,1,数据录入!$B$5:$B$4999,">="&$B$2,数据录入!$B$5:$B$4999,"<="&$D$2,数据录入!$J$5:$J$4999,$K12)) | O12: =IF($K12="","",L12+M12-N12) | Q12: =IF(数据录入!$B12="",0,IF(OR(数据录入!$D12="投标保证金",数据录入!$D12="合同履约保证金",ISNUMBER(FIND("保证金",数据录入!$E12))),1,0)) | R12: =IF(AND($Q12=1,数据录入!$B12>=$B$2,数据录入!$B12<=$D$2),N(R11)+1,N(R11)) | S12: =IFERROR(MATCH(5,$R$5:$R$4999,0),"") | U12: =IFERROR(IF(5<=50,INDEX(基础资料!$E$2:$E$51,5)&"",INDEX(基础资料!$G$2:$G$51,5-50)&""),"") | V12: =IF($U12="",0,IF(AND(5>50,COUNTIF(基础资料!$E$2:$E$51,$U12)>0),0,1)) | W12: =IF($V12=1,N(W11)+1,N(W11))
A13: =IF($S13="","",INDEX(数据录入!$B$5:$B$4999,$S13)) | B13: =IF($S13="","",INDEX(数据录入!$C$5:$C$4999,$S13)&"") | C13: =IF($S13="","",IF(N($F13)>0,"收款",IF(N($G13)>0,"付款",""))) | D13: =IF($S13="","",IF((INDEX(数据录入!$I$5:$I$4999,$S13)&"")<>"",INDEX(数据录入!$I$5:$I$4999,$S13)&"",INDEX(数据录入!$J$5:$J$4999,$S13)&"")) | E13: =IF($S13="","",INDEX(数据录入!$E$5:$E$4999,$S13)&"") | F13: =IF($S13="","",N(INDEX(数据录入!$F$5:$F$4999,$S13))) | G13: =IF($S13="","",N(INDEX(数据录入!$G$5:$G$4999,$S13))) | H13: =IF($S13="","",$G$2+SUM($F$8:$F13)-SUM($G$8:$G13)) | J13: =IF($K13="","",6) | K13: =IFERROR(INDEX($U$8:$U$107,MATCH(6,$W$8:$W$107,0)),"") | L13: =IF($K13="","",(SUMIFS(数据录入!$F$5:$F$4999,$Q$5:$Q$4999,1,数据录入!$B$5:$B$4999,"<"&$B$2,数据录入!$I$5:$I$4999,$K13)+SUMIFS(数据录入!$F$5:$F$4999,$Q$5:$Q$4999,1,数据录入!$B$5:$B$4999,"<"&$B$2,数据录入!$J$5:$J$4999,$K13))-(SUMIFS(数据录入!$G$5:$G$4999,$Q$5:$Q$4999,1,数据录入!$B$5:$B$4999,"<"&$B$2,数据录入!$I$5:$I$4999,$K13)+SUMIFS(数据录入!$G$5:$G$4999,$Q$5:$Q$4999,1,数据录入!$B$5:$B$4999,"<"&$B$2,数据录入!$J$5:$J$4999,$K13))) | M13: =IF($K13="","",SUMIFS(数据录入!$F$5:$F$4999,$Q$5:$Q$4999,1,数据录入!$B$5:$B$4999,">="&$B$2,数据录入!$B$5:$B$4999,"<="&$D$2,数据录入!$I$5:$I$4999,$K13)+SUMIFS(数据录入!$F$5:$F$4999,$Q$5:$Q$4999,1,数据录入!$B$5:$B$4999,">="&$B$2,数据录入!$B$5:$B$4999,"<="&$D$2,数据录入!$J$5:$J$4999,$K13)) | N13: =IF($K13="","",SUMIFS(数据录入!$G$5:$G$4999,$Q$5:$Q$4999,1,数据录入!$B$5:$B$4999,">="&$B$2,数据录入!$B$5:$B$4999,"<="&$D$2,数据录入!$I$5:$I$4999,$K13)+SUMIFS(数据录入!$G$5:$G$4999,$Q$5:$Q$4999,1,数据录入!$B$5:$B$4999,">="&$B$2,数据录入!$B$5:$B$4999,"<="&$D$2,数据录入!$J$5:$J$4999,$K13)) | O13: =IF($K13="","",L13+M13-N13) | Q13: =IF(数据录入!$B13="",0,IF(OR(数据录入!$D13="投标保证金",数据录入!$D13="合同履约保证金",ISNUMBER(FIND("保证金",数据录入!$E13))),1,0)) | R13: =IF(AND($Q13=1,数据录入!$B13>=$B$2,数据录入!$B13<=$D$2),N(R12)+1,N(R12)) | S13: =IFERROR(MATCH(6,$R$5:$R$4999,0),"") | U13: =IFERROR(IF(6<=50,INDEX(基础资料!$E$2:$E$51,6)&"",INDEX(基础资料!$G$2:$G$51,6-50)&""),"") | V13: =IF($U13="",0,IF(AND(6>50,COUNTIF(基础资料!$E$2:$E$51,$U13)>0),0,1)) | W13: =IF($V13=1,N(W12)+1,N(W12))
A14: =IF($S14="","",INDEX(数据录入!$B$5:$B$4999,$S14)) | B14: =IF($S14="","",INDEX(数据录入!$C$5:$C$4999,$S14)&"") | C14: =IF($S14="","",IF(N($F14)>0,"收款",IF(N($G14)>0,"付款",""))) | D14: =IF($S14="","",IF((INDEX(数据录入!$I$5:$I$4999,$S14)&"")<>"",INDEX(数据录入!$I$5:$I$4999,$S14)&"",INDEX(数据录入!$J$5:$J$4999,$S14)&"")) | E14: =IF($S14="","",INDEX(数据录入!$E$5:$E$4999,$S14)&"") | F14: =IF($S14="","",N(INDEX(数据录入!$F$5:$F$4999,$S14))) | G14: =IF($S14="","",N(INDEX(数据录入!$G$5:$G$4999,$S14))) | H14: =IF($S14="","",$G$2+SUM($F$8:$F14)-SUM($G$8:$G14)) | J14: =IF($K14="","",7) | K14: =IFERROR(INDEX($U$8:$U$107,MATCH(7,$W$8:$W$107,0)),"") | L14: =IF($K14="","",(SUMIFS(数据录入!$F$5:$F$4999,$Q$5:$Q$4999,1,数据录入!$B$5:$B$4999,"<"&$B$2,数据录入!$I$5:$I$4999,$K14)+SUMIFS(数据录入!$F$5:$F$4999,$Q$5:$Q$4999,1,数据录入!$B$5:$B$4999,"<"&$B$2,数据录入!$J$5:$J$4999,$K14))-(SUMIFS(数据录入!$G$5:$G$4999,$Q$5:$Q$4999,1,数据录入!$B$5:$B$4999,"<"&$B$2,数据录入!$I$5:$I$4999,$K14)+SUMIFS(数据录入!$G$5:$G$4999,$Q$5:$Q$4999,1,数据录入!$B$5:$B$4999,"<"&$B$2,数据录入!$J$5:$J$4999,$K14))) | M14: =IF($K14="","",SUMIFS(数据录入!$F$5:$F$4999,$Q$5:$Q$4999,1,数据录入!$B$5:$B$4999,">="&$B$2,数据录入!$B$5:$B$4999,"<="&$D$2,数据录入!$I$5:$I$4999,$K14)+SUMIFS(数据录入!$F$5:$F$4999,$Q$5:$Q$4999,1,数据录入!$B$5:$B$4999,">="&$B$2,数据录入!$B$5:$B$4999,"<="&$D$2,数据录入!$J$5:$J$4999,$K14)) | N14: =IF($K14="","",SUMIFS(数据录入!$G$5:$G$4999,$Q$5:$Q$4999,1,数据录入!$B$5:$B$4999,">="&$B$2,数据录入!$B$5:$B$4999,"<="&$D$2,数据录入!$I$5:$I$4999,$K14)+SUMIFS(数据录入!$G$5:$G$4999,$Q$5:$Q$4999,1,数据录入!$B$5:$B$4999,">="&$B$2,数据录入!$B$5:$B$4999,"<="&$D$2,数据录入!$J$5:$J$4999,$K14)) | O14: =IF($K14="","",L14+M14-N14) | Q14: =IF(数据录入!$B14="",0,IF(OR(数据录入!$D14="投标保证金",数据录入!$D14="合同履约保证金",ISNUMBER(FIND("保证金",数据录入!$E14))),1,0)) | R14: =IF(AND($Q14=1,数据录入!$B14>=$B$2,数据录入!$B14<=$D$2),N(R13)+1,N(R13)) | S14: =IFERROR(MATCH(7,$R$5:$R$4999,0),"") | U14: =IFERROR(IF(7<=50,INDEX(基础资料!$E$2:$E$51,7)&"",INDEX(基础资料!$G$2:$G$51,7-50)&""),"") | V14: =IF($U14="",0,IF(AND(7>50,COUNTIF(基础资料!$E$2:$E$51,$U14)>0),0,1)) | W14: =IF($V14=1,N(W13)+1,N(W13))
A15: =IF($S15="","",INDEX(数据录入!$B$5:$B$4999,$S15)) | B15: =IF($S15="","",INDEX(数据录入!$C$5:$C$4999,$S15)&"") | C15: =IF($S15="","",IF(N($F15)>0,"收款",IF(N($G15)>0,"付款",""))) | D15: =IF($S15="","",IF((INDEX(数据录入!$I$5:$I$4999,$S15)&"")<>"",INDEX(数据录入!$I$5:$I$4999,$S15)&"",INDEX(数据录入!$J$5:$J$4999,$S15)&"")) | E15: =IF($S15="","",INDEX(数据录入!$E$5:$E$4999,$S15)&"") | F15: =IF($S15="","",N(INDEX(数据录入!$F$5:$F$4999,$S15))) | G15: =IF($S15="","",N(INDEX(数据录入!$G$5:$G$4999,$S15))) | H15: =IF($S15="","",$G$2+SUM($F$8:$F15)-SUM($G$8:$G15)) | J15: =IF($K15="","",8) | K15: =IFERROR(INDEX($U$8:$U$107,MATCH(8,$W$8:$W$107,0)),"") | L15: =IF($K15="","",(SUMIFS(数据录入!$F$5:$F$4999,$Q$5:$Q$4999,1,数据录入!$B$5:$B$4999,"<"&$B$2,数据录入!$I$5:$I$4999,$K15)+SUMIFS(数据录入!$F$5:$F$4999,$Q$5:$Q$4999,1,数据录入!$B$5:$B$4999,"<"&$B$2,数据录入!$J$5:$J$4999,$K15))-(SUMIFS(数据录入!$G$5:$G$4999,$Q$5:$Q$4999,1,数据录入!$B$5:$B$4999,"<"&$B$2,数据录入!$I$5:$I$4999,$K15)+SUMIFS(数据录入!$G$5:$G$4999,$Q$5:$Q$4999,1,数据录入!$B$5:$B$4999,"<"&$B$2,数据录入!$J$5:$J$4999,$K15))) | M15: =IF($K15="","",SUMIFS(数据录入!$F$5:$F$4999,$Q$5:$Q$4999,1,数据录入!$B$5:$B$4999,">="&$B$2,数据录入!$B$5:$B$4999,"<="&$D$2,数据录入!$I$5:$I$4999,$K15)+SUMIFS(数据录入!$F$5:$F$4999,$Q$5:$Q$4999,1,数据录入!$B$5:$B$4999,">="&$B$2,数据录入!$B$5:$B$4999,"<="&$D$2,数据录入!$J$5:$J$4999,$K15)) | N15: =IF($K15="","",SUMIFS(数据录入!$G$5:$G$4999,$Q$5:$Q$4999,1,数据录入!$B$5:$B$4999,">="&$B$2,数据录入!$B$5:$B$4999,"<="&$D$2,数据录入!$I$5:$I$4999,$K15)+SUMIFS(数据录入!$G$5:$G$4999,$Q$5:$Q$4999,1,数据录入!$B$5:$B$4999,">="&$B$2,数据录入!$B$5:$B$4999,"<="&$D$2,数据录入!$J$5:$J$4999,$K15)) | O15: =IF($K15="","",L15+M15-N15) | Q15: =IF(数据录入!$B15="",0,IF(OR(数据录入!$D15="投标保证金",数据录入!$D15="合同履约保证金",ISNUMBER(FIND("保证金",数据录入!$E15))),1,0)) | R15: =IF(AND($Q15=1,数据录入!$B15>=$B$2,数据录入!$B15<=$D$2),N(R14)+1,N(R14)) | S15: =IFERROR(MATCH(8,$R$5:$R$4999,0),"") | U15: =IFERROR(IF(8<=50,INDEX(基础资料!$E$2:$E$51,8)&"",INDEX(基础资料!$G$2:$G$51,8-50)&""),"") | V15: =IF($U15="",0,IF(AND(8>50,COUNTIF(基础资料!$E$2:$E$51,$U15)>0),0,1)) | W15: =IF($V15=1,N(W14)+1,N(W14))
A16: =IF($S16="","",INDEX(数据录入!$B$5:$B$4999,$S16)) | B16: =IF($S16="","",INDEX(数据录入!$C$5:$C$4999,$S16)&"") | C16: =IF($S16="","",IF(N($F16)>0,"收款",IF(N($G16)>0,"付款",""))) | D16: =IF($S16="","",IF((INDEX(数据录入!$I$5:$I$4999,$S16)&"")<>"",INDEX(数据录入!$I$5:$I$4999,$S16)&"",INDEX(数据录入!$J$5:$J$4999,$S16)&"")) | E16: =IF($S16="","",INDEX(数据录入!$E$5:$E$4999,$S16)&"") | F16: =IF($S16="","",N(INDEX(数据录入!$F$5:$F$4999,$S16))) | G16: =IF($S16="","",N(INDEX(数据录入!$G$5:$G$4999,$S16))) | H16: =IF($S16="","",$G$2+SUM($F$8:$F16)-SUM($G$8:$G16)) | J16: =IF($K16="","",9) | K16: =IFERROR(INDEX($U$8:$U$107,MATCH(9,$W$8:$W$107,0)),"") | L16: =IF($K16="","",(SUMIFS(数据录入!$F$5:$F$4999,$Q$5:$Q$4999,1,数据录入!$B$5:$B$4999,"<"&$B$2,数据录入!$I$5:$I$4999,$K16)+SUMIFS(数据录入!$F$5:$F$4999,$Q$5:$Q$4999,1,数据录入!$B$5:$B$4999,"<"&$B$2,数据录入!$J$5:$J$4999,$K16))-(SUMIFS(数据录入!$G$5:$G$4999,$Q$5:$Q$4999,1,数据录入!$B$5:$B$4999,"<"&$B$2,数据录入!$I$5:$I$4999,$K16)+SUMIFS(数据录入!$G$5:$G$4999,$Q$5:$Q$4999,1,数据录入!$B$5:$B$4999,"<"&$B$2,数据录入!$J$5:$J$4999,$K16))) | M16: =IF($K16="","",SUMIFS(数据录入!$F$5:$F$4999,$Q$5:$Q$4999,1,数据录入!$B$5:$B$4999,">="&$B$2,数据录入!$B$5:$B$4999,"<="&$D$2,数据录入!$I$5:$I$4999,$K16)+SUMIFS(数据录入!$F$5:$F$4999,$Q$5:$Q$4999,1,数据录入!$B$5:$B$4999,">="&$B$2,数据录入!$B$5:$B$4999,"<="&$D$2,数据录入!$J$5:$J$4999,$K16)) | N16: =IF($K16="","",SUMIFS(数据录入!$G$5:$G$4999,$Q$5:$Q$4999,1,数据录入!$B$5:$B$4999,">="&$B$2,数据录入!$B$5:$B$4999,"<="&$D$2,数据录入!$I$5:$I$4999,$K16)+SUMIFS(数据录入!$G$5:$G$4999,$Q$5:$Q$4999,1,数据录入!$B$5:$B$4999,">="&$B$2,数据录入!$B$5:$B$4999,"<="&$D$2,数据录入!$J$5:$J$4999,$K16)) | O16: =IF($K16="","",L16+M16-N16) | Q16: =IF(数据录入!$B16="",0,IF(OR(数据录入!$D16="投标保证金",数据录入!$D16="合同履约保证金",ISNUMBER(FIND("保证金",数据录入!$E16))),1,0)) | R16: =IF(AND($Q16=1,数据录入!$B16>=$B$2,数据录入!$B16<=$D$2),N(R15)+1,N(R15)) | S16: =IFERROR(MATCH(9,$R$5:$R$4999,0),"") | U16: =IFERROR(IF(9<=50,INDEX(基础资料!$E$2:$E$51,9)&"",INDEX(基础资料!$G$2:$G$51,9-50)&""),"") | V16: =IF($U16="",0,IF(AND(9>50,COUNTIF(基础资料!$E$2:$E$51,$U16)>0),0,1)) | W16: =IF($V16=1,N(W15)+1,N(W15))
A17: =IF($S17="","",INDEX(数据录入!$B$5:$B$4999,$S17)) | B17: =IF($S17="","",INDEX(数据录入!$C$5:$C$4999,$S17)&"") | C17: =IF($S17="","",IF(N($F17)>0,"收款",IF(N($G17)>0,"付款",""))) | D17: =IF($S17="","",IF((INDEX(数据录入!$I$5:$I$4999,$S17)&"")<>"",INDEX(数据录入!$I$5:$I$4999,$S17)&"",INDEX(数据录入!$J$5:$J$4999,$S17)&"")) | E17: =IF($S17="","",INDEX(数据录入!$E$5:$E$4999,$S17)&"") | F17: =IF($S17="","",N(INDEX(数据录入!$F$5:$F$4999,$S17))) | G17: =IF($S17="","",N(INDEX(数据录入!$G$5:$G$4999,$S17))) | H17: =IF($S17="","",$G$2+SUM($F$8:$F17)-SUM($G$8:$G17)) | J17: =IF($K17="","",10) | K17: =IFERROR(INDEX($U$8:$U$107,MATCH(10,$W$8:$W$107,0)),"") | L17: =IF($K17="","",(SUMIFS(数据录入!$F$5:$F$4999,$Q$5:$Q$4999,1,数据录入!$B$5:$B$4999,"<"&$B$2,数据录入!$I$5:$I$4999,$K17)+SUMIFS(数据录入!$F$5:$F$4999,$Q$5:$Q$4999,1,数据录入!$B$5:$B$4999,"<"&$B$2,数据录入!$J$5:$J$4999,$K17))-(SUMIFS(数据录入!$G$5:$G$4999,$Q$5:$Q$4999,1,数据录入!$B$5:$B$4999,"<"&$B$2,数据录入!$I$5:$I$4999,$K17)+SUMIFS(数据录入!$G$5:$G$4999,$Q$5:$Q$4999,1,数据录入!$B$5:$B$4999,"<"&$B$2,数据录入!$J$5:$J$4999,$K17))) | M17: =IF($K17="","",SUMIFS(数据录入!$F$5:$F$4999,$Q$5:$Q$4999,1,数据录入!$B$5:$B$4999,">="&$B$2,数据录入!$B$5:$B$4999,"<="&$D$2,数据录入!$I$5:$I$4999,$K17)+SUMIFS(数据录入!$F$5:$F$4999,$Q$5:$Q$4999,1,数据录入!$B$5:$B$4999,">="&$B$2,数据录入!$B$5:$B$4999,"<="&$D$2,数据录入!$J$5:$J$4999,$K17)) | N17: =IF($K17="","",SUMIFS(数据录入!$G$5:$G$4999,$Q$5:$Q$4999,1,数据录入!$B$5:$B$4999,">="&$B$2,数据录入!$B$5:$B$4999,"<="&$D$2,数据录入!$I$5:$I$4999,$K17)+SUMIFS(数据录入!$G$5:$G$4999,$Q$5:$Q$4999,1,数据录入!$B$5:$B$4999,">="&$B$2,数据录入!$B$5:$B$4999,"<="&$D$2,数据录入!$J$5:$J$4999,$K17)) | O17: =IF($K17="","",L17+M17-N17) | Q17: =IF(数据录入!$B17="",0,IF(OR(数据录入!$D17="投标保证金",数据录入!$D17="合同履约保证金",ISNUMBER(FIND("保证金",数据录入!$E17))),1,0)) | R17: =IF(AND($Q17=1,数据录入!$B17>=$B$2,数据录入!$B17<=$D$2),N(R16)+1,N(R16)) | S17: =IFERROR(MATCH(10,$R$5:$R$4999,0),"") | U17: =IFERROR(IF(10<=50,INDEX(基础资料!$E$2:$E$51,10)&"",INDEX(基础资料!$G$2:$G$51,10-50)&""),"") | V17: =IF($U17="",0,IF(AND(10>50,COUNTIF(基础资料!$E$2:$E$51,$U17)>0),0,1)) | W17: =IF($V17=1,N(W16)+1,N(W16))
A18: =IF($S18="","",INDEX(数据录入!$B$5:$B$4999,$S18)) | B18: =IF($S18="","",INDEX(数据录入!$C$5:$C$4999,$S18)&"") | C18: =IF($S18="","",IF(N($F18)>0,"收款",IF(N($G18)>0,"付款",""))) | D18: =IF($S18="","",IF((INDEX(数据录入!$I$5:$I$4999,$S18)&"")<>"",INDEX(数据录入!$I$5:$I$4999,$S18)&"",INDEX(数据录入!$J$5:$J$4999,$S18)&"")) | E18: =IF($S18="","",INDEX(数据录入!$E$5:$E$4999,$S18)&"") | F18: =IF($S18="","",N(INDEX(数据录入!$F$5:$F$4999,$S18))) | G18: =IF($S18="","",N(INDEX(数据录入!$G$5:$G$4999,$S18))) | H18: =IF($S18="","",$G$2+SUM($F$8:$F18)-SUM($G$8:$G18)) | J18: =IF($K18="","",11) | K18: =IFERROR(INDEX($U$8:$U$107,MATCH(11,$W$8:$W$107,0)),"") | L18: =IF($K18="","",(SUMIFS(数据录入!$F$5:$F$4999,$Q$5:$Q$4999,1,数据录入!$B$5:$B$4999,"<"&$B$2,数据录入!$I$5:$I$4999,$K18)+SUMIFS(数据录入!$F$5:$F$4999,$Q$5:$Q$4999,1,数据录入!$B$5:$B$4999,"<"&$B$2,数据录入!$J$5:$J$4999,$K18))-(SUMIFS(数据录入!$G$5:$G$4999,$Q$5:$Q$4999,1,数据录入!$B$5:$B$4999,"<"&$B$2,数据录入!$I$5:$I$4999,$K18)+SUMIFS(数据录入!$G$5:$G$4999,$Q$5:$Q$4999,1,数据录入!$B$5:$B$4999,"<"&$B$2,数据录入!$J$5:$J$4999,$K18))) | M18: =IF($K18="","",SUMIFS(数据录入!$F$5:$F$4999,$Q$5:$Q$4999,1,数据录入!$B$5:$B$4999,">="&$B$2,数据录入!$B$5:$B$4999,"<="&$D$2,数据录入!$I$5:$I$4999,$K18)+SUMIFS(数据录入!$F$5:$F$4999,$Q$5:$Q$4999,1,数据录入!$B$5:$B$4999,">="&$B$2,数据录入!$B$5:$B$4999,"<="&$D$2,数据录入!$J$5:$J$4999,$K18)) | N18: =IF($K18="","",SUMIFS(数据录入!$G$5:$G$4999,$Q$5:$Q$4999,1,数据录入!$B$5:$B$4999,">="&$B$2,数据录入!$B$5:$B$4999,"<="&$D$2,数据录入!$I$5:$I$4999,$K18)+SUMIFS(数据录入!$G$5:$G$4999,$Q$5:$Q$4999,1,数据录入!$B$5:$B$4999,">="&$B$2,数据录入!$B$5:$B$4999,"<="&$D$2,数据录入!$J$5:$J$4999,$K18)) | O18: =IF($K18="","",L18+M18-N18) | Q18: =IF(数据录入!$B18="",0,IF(OR(数据录入!$D18="投标保证金",数据录入!$D18="合同履约保证金",ISNUMBER(FIND("保证金",数据录入!$E18))),1,0)) | R18: =IF(AND($Q18=1,数据录入!$B18>=$B$2,数据录入!$B18<=$D$2),N(R17)+1,N(R17)) | S18: =IFERROR(MATCH(11,$R$5:$R$4999,0),"") | U18: =IFERROR(IF(11<=50,INDEX(基础资料!$E$2:$E$51,11)&"",INDEX(基础资料!$G$2:$G$51,11-50)&""),"") | V18: =IF($U18="",0,IF(AND(11>50,COUNTIF(基础资料!$E$2:$E$51,$U18)>0),0,1)) | W18: =IF($V18=1,N(W17)+1,N(W17))
A19: =IF($S19="","",INDEX(数据录入!$B$5:$B$4999,$S19)) | B19: =IF($S19="","",INDEX(数据录入!$C$5:$C$4999,$S19)&"") | C19: =IF($S19="","",IF(N($F19)>0,"收款",IF(N($G19)>0,"付款",""))) | D19: =IF($S19="","",IF((INDEX(数据录入!$I$5:$I$4999,$S19)&"")<>"",INDEX(数据录入!$I$5:$I$4999,$S19)&"",INDEX(数据录入!$J$5:$J$4999,$S19)&"")) | E19: =IF($S19="","",INDEX(数据录入!$E$5:$E$4999,$S19)&"") | F19: =IF($S19="","",N(INDEX(数据录入!$F$5:$F$4999,$S19))) | G19: =IF($S19="","",N(INDEX(数据录入!$G$5:$G$4999,$S19))) | H19: =IF($S19="","",$G$2+SUM($F$8:$F19)-SUM($G$8:$G19)) | J19: =IF($K19="","",12) | K19: =IFERROR(INDEX($U$8:$U$107,MATCH(12,$W$8:$W$107,0)),"") | L19: =IF($K19="","",(SUMIFS(数据录入!$F$5:$F$4999,$Q$5:$Q$4999,1,数据录入!$B$5:$B$4999,"<"&$B$2,数据录入!$I$5:$I$4999,$K19)+SUMIFS(数据录入!$F$5:$F$4999,$Q$5:$Q$4999,1,数据录入!$B$5:$B$4999,"<"&$B$2,数据录入!$J$5:$J$4999,$K19))-(SUMIFS(数据录入!$G$5:$G$4999,$Q$5:$Q$4999,1,数据录入!$B$5:$B$4999,"<"&$B$2,数据录入!$I$5:$I$4999,$K19)+SUMIFS(数据录入!$G$5:$G$4999,$Q$5:$Q$4999,1,数据录入!$B$5:$B$4999,"<"&$B$2,数据录入!$J$5:$J$4999,$K19))) | M19: =IF($K19="","",SUMIFS(数据录入!$F$5:$F$4999,$Q$5:$Q$4999,1,数据录入!$B$5:$B$4999,">="&$B$2,数据录入!$B$5:$B$4999,"<="&$D$2,数据录入!$I$5:$I$4999,$K19)+SUMIFS(数据录入!$F$5:$F$4999,$Q$5:$Q$4999,1,数据录入!$B$5:$B$4999,">="&$B$2,数据录入!$B$5:$B$4999,"<="&$D$2,数据录入!$J$5:$J$4999,$K19)) | N19: =IF($K19="","",SUMIFS(数据录入!$G$5:$G$4999,$Q$5:$Q$4999,1,数据录入!$B$5:$B$4999,">="&$B$2,数据录入!$B$5:$B$4999,"<="&$D$2,数据录入!$I$5:$I$4999,$K19)+SUMIFS(数据录入!$G$5:$G$4999,$Q$5:$Q$4999,1,数据录入!$B$5:$B$4999,">="&$B$2,数据录入!$B$5:$B$4999,"<="&$D$2,数据录入!$J$5:$J$4999,$K19)) | O19: =IF($K19="","",L19+M19-N19) | Q19: =IF(数据录入!$B19="",0,IF(OR(数据录入!$D19="投标保证金",数据录入!$D19="合同履约保证金",ISNUMBER(FIND("保证金",数据录入!$E19))),1,0)) | R19: =IF(AND($Q19=1,数据录入!$B19>=$B$2,数据录入!$B19<=$D$2),N(R18)+1,N(R18)) | S19: =IFERROR(MATCH(12,$R$5:$R$4999,0),"") | U19: =IFERROR(IF(12<=50,INDEX(基础资料!$E$2:$E$51,12)&"",INDEX(基础资料!$G$2:$G$51,12-50)&""),"") | V19: =IF($U19="",0,IF(AND(12>50,COUNTIF(基础资料!$E$2:$E$51,$U19)>0),0,1)) | W19: =IF($V19=1,N(W18)+1,N(W18))
A20: =IF($S20="","",INDEX(数据录入!$B$5:$B$4999,$S20)) | B20: =IF($S20="","",INDEX(数据录入!$C$5:$C$4999,$S20)&"") | C20: =IF($S20="","",IF(N($F20)>0,"收款",IF(N($G20)>0,"付款",""))) | D20: =IF($S20="","",IF((INDEX(数据录入!$I$5:$I$4999,$S20)&"")<>"",INDEX(数据录入!$I$5:$I$4999,$S20)&"",INDEX(数据录入!$J$5:$J$4999,$S20)&"")) | E20: =IF($S20="","",INDEX(数据录入!$E$5:$E$4999,$S20)&"") | F20: =IF($S20="","",N(INDEX(数据录入!$F$5:$F$4999,$S20))) | G20: =IF($S20="","",N(INDEX(数据录入!$G$5:$G$4999,$S20))) | H20: =IF($S20="","",$G$2+SUM($F$8:$F20)-SUM($G$8:$G20)) | J20: =IF($K20="","",13) | K20: =IFERROR(INDEX($U$8:$U$107,MATCH(13,$W$8:$W$107,0)),"") | L20: =IF($K20="","",(SUMIFS(数据录入!$F$5:$F$4999,$Q$5:$Q$4999,1,数据录入!$B$5:$B$4999,"<"&$B$2,数据录入!$I$5:$I$4999,$K20)+SUMIFS(数据录入!$F$5:$F$4999,$Q$5:$Q$4999,1,数据录入!$B$5:$B$4999,"<"&$B$2,数据录入!$J$5:$J$4999,$K20))-(SUMIFS(数据录入!$G$5:$G$4999,$Q$5:$Q$4999,1,数据录入!$B$5:$B$4999,"<"&$B$2,数据录入!$I$5:$I$4999,$K20)+SUMIFS(数据录入!$G$5:$G$4999,$Q$5:$Q$4999,1,数据录入!$B$5:$B$4999,"<"&$B$2,数据录入!$J$5:$J$4999,$K20))) | M20: =IF($K20="","",SUMIFS(数据录入!$F$5:$F$4999,$Q$5:$Q$4999,1,数据录入!$B$5:$B$4999,">="&$B$2,数据录入!$B$5:$B$4999,"<="&$D$2,数据录入!$I$5:$I$4999,$K20)+SUMIFS(数据录入!$F$5:$F$4999,$Q$5:$Q$4999,1,数据录入!$B$5:$B$4999,">="&$B$2,数据录入!$B$5:$B$4999,"<="&$D$2,数据录入!$J$5:$J$4999,$K20)) | N20: =IF($K20="","",SUMIFS(数据录入!$G$5:$G$4999,$Q$5:$Q$4999,1,数据录入!$B$5:$B$4999,">="&$B$2,数据录入!$B$5:$B$4999,"<="&$D$2,数据录入!$I$5:$I$4999,$K20)+SUMIFS(数据录入!$G$5:$G$4999,$Q$5:$Q$4999,1,数据录入!$B$5:$B$4999,">="&$B$2,数据录入!$B$5:$B$4999,"<="&$D$2,数据录入!$J$5:$J$4999,$K20)) | O20: =IF($K20="","",L20+M20-N20) | Q20: =IF(数据录入!$B20="",0,IF(OR(数据录入!$D20="投标保证金",数据录入!$D20="合同履约保证金",ISNUMBER(FIND("保证金",数据录入!$E20))),1,0)) | R20: =IF(AND($Q20=1,数据录入!$B20>=$B$2,数据录入!$B20<=$D$2),N(R19)+1,N(R19)) | S20: =IFERROR(MATCH(13,$R$5:$R$4999,0),"") | U20: =IFERROR(IF(13<=50,INDEX(基础资料!$E$2:$E$51,13)&"",INDEX(基础资料!$G$2:$G$51,13-50)&""),"") | V20: =IF($U20="",0,IF(AND(13>50,COUNTIF(基础资料!$E$2:$E$51,$U20)>0),0,1)) | W20: =IF($V20=1,N(W19)+1,N(W19))
A21: =IF($S21="","",INDEX(数据录入!$B$5:$B$4999,$S21)) | B21: =IF($S21="","",INDEX(数据录入!$C$5:$C$4999,$S21)&"") | C21: =IF($S21="","",IF(N($F21)>0,"收款",IF(N($G21)>0,"付款",""))) | D21: =IF($S21="","",IF((INDEX(数据录入!$I$5:$I$4999,$S21)&"")<>"",INDEX(数据录入!$I$5:$I$4999,$S21)&"",INDEX(数据录入!$J$5:$J$4999,$S21)&"")) | E21: =IF($S21="","",INDEX(数据录入!$E$5:$E$4999,$S21)&"") | F21: =IF($S21="","",N(INDEX(数据录入!$F$5:$F$4999,$S21))) | G21: =IF($S21="","",N(INDEX(数据录入!$G$5:$G$4999,$S21))) | H21: =IF($S21="","",$G$2+SUM($F$8:$F21)-SUM($G$8:$G21)) | J21: =IF($K21="","",14) | K21: =IFERROR(INDEX($U$8:$U$107,MATCH(14,$W$8:$W$107,0)),"") | L21: =IF($K21="","",(SUMIFS(数据录入!$F$5:$F$4999,$Q$5:$Q$4999,1,数据录入!$B$5:$B$4999,"<"&$B$2,数据录入!$I$5:$I$4999,$K21)+SUMIFS(数据录入!$F$5:$F$4999,$Q$5:$Q$4999,1,数据录入!$B$5:$B$4999,"<"&$B$2,数据录入!$J$5:$J$4999,$K21))-(SUMIFS(数据录入!$G$5:$G$4999,$Q$5:$Q$4999,1,数据录入!$B$5:$B$4999,"<"&$B$2,数据录入!$I$5:$I$4999,$K21)+SUMIFS(数据录入!$G$5:$G$4999,$Q$5:$Q$4999,1,数据录入!$B$5:$B$4999,"<"&$B$2,数据录入!$J$5:$J$4999,$K21))) | M21: =IF($K21="","",SUMIFS(数据录入!$F$5:$F$4999,$Q$5:$Q$4999,1,数据录入!$B$5:$B$4999,">="&$B$2,数据录入!$B$5:$B$4999,"<="&$D$2,数据录入!$I$5:$I$4999,$K21)+SUMIFS(数据录入!$F$5:$F$4999,$Q$5:$Q$4999,1,数据录入!$B$5:$B$4999,">="&$B$2,数据录入!$B$5:$B$4999,"<="&$D$2,数据录入!$J$5:$J$4999,$K21)) | N21: =IF($K21="","",SUMIFS(数据录入!$G$5:$G$4999,$Q$5:$Q$4999,1,数据录入!$B$5:$B$4999,">="&$B$2,数据录入!$B$5:$B$4999,"<="&$D$2,数据录入!$I$5:$I$4999,$K21)+SUMIFS(数据录入!$G$5:$G$4999,$Q$5:$Q$4999,1,数据录入!$B$5:$B$4999,">="&$B$2,数据录入!$B$5:$B$4999,"<="&$D$2,数据录入!$J$5:$J$4999,$K21)) | O21: =IF($K21="","",L21+M21-N21) | Q21: =IF(数据录入!$B21="",0,IF(OR(数据录入!$D21="投标保证金",数据录入!$D21="合同履约保证金",ISNUMBER(FIND("保证金",数据录入!$E21))),1,0)) | R21: =IF(AND($Q21=1,数据录入!$B21>=$B$2,数据录入!$B21<=$D$2),N(R20)+1,N(R20)) | S21: =IFERROR(MATCH(14,$R$5:$R$4999,0),"") | U21: =IFERROR(IF(14<=50,INDEX(基础资料!$E$2:$E$51,14)&"",INDEX(基础资料!$G$2:$G$51,14-50)&""),"") | V21: =IF($U21="",0,IF(AND(14>50,COUNTIF(基础资料!$E$2:$E$51,$U21)>0),0,1)) | W21: =IF($V21=1,N(W20)+1,N(W20))
A22: =IF($S22="","",INDEX(数据录入!$B$5:$B$4999,$S22)) | B22: =IF($S22="","",INDEX(数据录入!$C$5:$C$4999,$S22)&"") | C22: =IF($S22="","",IF(N($F22)>0,"收款",IF(N($G22)>0,"付款",""))) | D22: =IF($S22="","",IF((INDEX(数据录入!$I$5:$I$4999,$S22)&"")<>"",INDEX(数据录入!$I$5:$I$4999,$S22)&"",INDEX(数据录入!$J$5:$J$4999,$S22)&"")) | E22: =IF($S22="","",INDEX(数据录入!$E$5:$E$4999,$S22)&"") | F22: =IF($S22="","",N(INDEX(数据录入!$F$5:$F$4999,$S22))) | G22: =IF($S22="","",N(INDEX(数据录入!$G$5:$G$4999,$S22))) | H22: =IF($S22="","",$G$2+SUM($F$8:$F22)-SUM($G$8:$G22)) | J22: =IF($K22="","",15) | K22: =IFERROR(INDEX($U$8:$U$107,MATCH(15,$W$8:$W$107,0)),"") | L22: =IF($K22="","",(SUMIFS(数据录入!$F$5:$F$4999,$Q$5:$Q$4999,1,数据录入!$B$5:$B$4999,"<"&$B$2,数据录入!$I$5:$I$4999,$K22)+SUMIFS(数据录入!$F$5:$F$4999,$Q$5:$Q$4999,1,数据录入!$B$5:$B$4999,"<"&$B$2,数据录入!$J$5:$J$4999,$K22))-(SUMIFS(数据录入!$G$5:$G$4999,$Q$5:$Q$4999,1,数据录入!$B$5:$B$4999,"<"&$B$2,数据录入!$I$5:$I$4999,$K22)+SUMIFS(数据录入!$G$5:$G$4999,$Q$5:$Q$4999,1,数据录入!$B$5:$B$4999,"<"&$B$2,数据录入!$J$5:$J$4999,$K22))) | M22: =IF($K22="","",SUMIFS(数据录入!$F$5:$F$4999,$Q$5:$Q$4999,1,数据录入!$B$5:$B$4999,">="&$B$2,数据录入!$B$5:$B$4999,"<="&$D$2,数据录入!$I$5:$I$4999,$K22)+SUMIFS(数据录入!$F$5:$F$4999,$Q$5:$Q$4999,1,数据录入!$B$5:$B$4999,">="&$B$2,数据录入!$B$5:$B$4999,"<="&$D$2,数据录入!$J$5:$J$4999,$K22)) | N22: =IF($K22="","",SUMIFS(数据录入!$G$5:$G$4999,$Q$5:$Q$4999,1,数据录入!$B$5:$B$4999,">="&$B$2,数据录入!$B$5:$B$4999,"<="&$D$2,数据录入!$I$5:$I$4999,$K22)+SUMIFS(数据录入!$G$5:$G$4999,$Q$5:$Q$4999,1,数据录入!$B$5:$B$4999,">="&$B$2,数据录入!$B$5:$B$4999,"<="&$D$2,数据录入!$J$5:$J$4999,$K22)) | O22: =IF($K22="","",L22+M22-N22) | Q22: =IF(数据录入!$B22="",0,IF(OR(数据录入!$D22="投标保证金",数据录入!$D22="合同履约保证金",ISNUMBER(FIND("保证金",数据录入!$E22))),1,0)) | R22: =IF(AND($Q22=1,数据录入!$B22>=$B$2,数据录入!$B22<=$D$2),N(R21)+1,N(R21)) | S22: =IFERROR(MATCH(15,$R$5:$R$4999,0),"") | U22: =IFERROR(IF(15<=50,INDEX(基础资料!$E$2:$E$51,15)&"",INDEX(基础资料!$G$2:$G$51,15-50)&""),"") | V22: =IF($U22="",0,IF(AND(15>50,COUNTIF(基础资料!$E$2:$E$51,$U22)>0),0,1)) | W22: =IF($V22=1,N(W21)+1,N(W21))
A23: =IF($S23="","",INDEX(数据录入!$B$5:$B$4999,$S23)) | B23: =IF($S23="","",INDEX(数据录入!$C$5:$C$4999,$S23)&"") | C23: =IF($S23="","",IF(N($F23)>0,"收款",IF(N($G23)>0,"付款",""))) | D23: =IF($S23="","",IF((INDEX(数据录入!$I$5:$I$4999,$S23)&"")<>"",INDEX(数据录入!$I$5:$I$4999,$S23)&"",INDEX(数据录入!$J$5:$J$4999,$S23)&"")) | E23: =IF($S23="","",INDEX(数据录入!$E$5:$E$4999,$S23)&"") | F23: =IF($S23="","",N(INDEX(数据录入!$F$5:$F$4999,$S23))) | G23: =IF($S23="","",N(INDEX(数据录入!$G$5:$G$4999,$S23))) | H23: =IF($S23="","",$G$2+SUM($F$8:$F23)-SUM($G$8:$G23)) | J23: =IF($K23="","",16) | K23: =IFERROR(INDEX($U$8:$U$107,MATCH(16,$W$8:$W$107,0)),"") | L23: =IF($K23="","",(SUMIFS(数据录入!$F$5:$F$4999,$Q$5:$Q$4999,1,数据录入!$B$5:$B$4999,"<"&$B$2,数据录入!$I$5:$I$4999,$K23)+SUMIFS(数据录入!$F$5:$F$4999,$Q$5:$Q$4999,1,数据录入!$B$5:$B$4999,"<"&$B$2,数据录入!$J$5:$J$4999,$K23))-(SUMIFS(数据录入!$G$5:$G$4999,$Q$5:$Q$4999,1,数据录入!$B$5:$B$4999,"<"&$B$2,数据录入!$I$5:$I$4999,$K23)+SUMIFS(数据录入!$G$5:$G$4999,$Q$5:$Q$4999,1,数据录入!$B$5:$B$4999,"<"&$B$2,数据录入!$J$5:$J$4999,$K23))) | M23: =IF($K23="","",SUMIFS(数据录入!$F$5:$F$4999,$Q$5:$Q$4999,1,数据录入!$B$5:$B$4999,">="&$B$2,数据录入!$B$5:$B$4999,"<="&$D$2,数据录入!$I$5:$I$4999,$K23)+SUMIFS(数据录入!$F$5:$F$4999,$Q$5:$Q$4999,1,数据录入!$B$5:$B$4999,">="&$B$2,数据录入!$B$5:$B$4999,"<="&$D$2,数据录入!$J$5:$J$4999,$K23)) | N23: =IF($K23="","",SUMIFS(数据录入!$G$5:$G$4999,$Q$5:$Q$4999,1,数据录入!$B$5:$B$4999,">="&$B$2,数据录入!$B$5:$B$4999,"<="&$D$2,数据录入!$I$5:$I$4999,$K23)+SUMIFS(数据录入!$G$5:$G$4999,$Q$5:$Q$4999,1,数据录入!$B$5:$B$4999,">="&$B$2,数据录入!$B$5:$B$4999,"<="&$D$2,数据录入!$J$5:$J$4999,$K23)) | O23: =IF($K23="","",L23+M23-N23) | Q23: =IF(数据录入!$B23="",0,IF(OR(数据录入!$D23="投标保证金",数据录入!$D23="合同履约保证金",ISNUMBER(FIND("保证金",数据录入!$E23))),1,0)) | R23: =IF(AND($Q23=1,数据录入!$B23>=$B$2,数据录入!$B23<=$D$2),N(R22)+1,N(R22)) | S23: =IFERROR(MATCH(16,$R$5:$R$4999,0),"") | U23: =IFERROR(IF(16<=50,INDEX(基础资料!$E$2:$E$51,16)&"",INDEX(基础资料!$G$2:$G$51,16-50)&""),"") | V23: =IF($U23="",0,IF(AND(16>50,COUNTIF(基础资料!$E$2:$E$51,$U23)>0),0,1)) | W23: =IF($V23=1,N(W22)+1,N(W22))
A24: =IF($S24="","",INDEX(数据录入!$B$5:$B$4999,$S24)) | B24: =IF($S24="","",INDEX(数据录入!$C$5:$C$4999,$S24)&"") | C24: =IF($S24="","",IF(N($F24)>0,"收款",IF(N($G24)>0,"付款",""))) | D24: =IF($S24="","",IF((INDEX(数据录入!$I$5:$I$4999,$S24)&"")<>"",INDEX(数据录入!$I$5:$I$4999,$S24)&"",INDEX(数据录入!$J$5:$J$4999,$S24)&"")) | E24: =IF($S24="","",INDEX(数据录入!$E$5:$E$4999,$S24)&"") | F24: =IF($S24="","",N(INDEX(数据录入!$F$5:$F$4999,$S24))) | G24: =IF($S24="","",N(INDEX(数据录入!$G$5:$G$4999,$S24))) | H24: =IF($S24="","",$G$2+SUM($F$8:$F24)-SUM($G$8:$G24)) | J24: =IF($K24="","",17) | K24: =IFERROR(INDEX($U$8:$U$107,MATCH(17,$W$8:$W$107,0)),"") | L24: =IF($K24="","",(SUMIFS(数据录入!$F$5:$F$4999,$Q$5:$Q$4999,1,数据录入!$B$5:$B$4999,"<"&$B$2,数据录入!$I$5:$I$4999,$K24)+SUMIFS(数据录入!$F$5:$F$4999,$Q$5:$Q$4999,1,数据录入!$B$5:$B$4999,"<"&$B$2,数据录入!$J$5:$J$4999,$K24))-(SUMIFS(数据录入!$G$5:$G$4999,$Q$5:$Q$4999,1,数据录入!$B$5:$B$4999,"<"&$B$2,数据录入!$I$5:$I$4999,$K24)+SUMIFS(数据录入!$G$5:$G$4999,$Q$5:$Q$4999,1,数据录入!$B$5:$B$4999,"<"&$B$2,数据录入!$J$5:$J$4999,$K24))) | M24: =IF($K24="","",SUMIFS(数据录入!$F$5:$F$4999,$Q$5:$Q$4999,1,数据录入!$B$5:$B$4999,">="&$B$2,数据录入!$B$5:$B$4999,"<="&$D$2,数据录入!$I$5:$I$4999,$K24)+SUMIFS(数据录入!$F$5:$F$4999,$Q$5:$Q$4999,1,数据录入!$B$5:$B$4999,">="&$B$2,数据录入!$B$5:$B$4999,"<="&$D$2,数据录入!$J$5:$J$4999,$K24)) | N24: =IF($K24="","",SUMIFS(数据录入!$G$5:$G$4999,$Q$5:$Q$4999,1,数据录入!$B$5:$B$4999,">="&$B$2,数据录入!$B$5:$B$4999,"<="&$D$2,数据录入!$I$5:$I$4999,$K24)+SUMIFS(数据录入!$G$5:$G$4999,$Q$5:$Q$4999,1,数据录入!$B$5:$B$4999,">="&$B$2,数据录入!$B$5:$B$4999,"<="&$D$2,数据录入!$J$5:$J$4999,$K24)) | O24: =IF($K24="","",L24+M24-N24) | Q24: =IF(数据录入!$B24="",0,IF(OR(数据录入!$D24="投标保证金",数据录入!$D24="合同履约保证金",ISNUMBER(FIND("保证金",数据录入!$E24))),1,0)) | R24: =IF(AND($Q24=1,数据录入!$B24>=$B$2,数据录入!$B24<=$D$2),N(R23)+1,N(R23)) | S24: =IFERROR(MATCH(17,$R$5:$R$4999,0),"") | U24: =IFERROR(IF(17<=50,INDEX(基础资料!$E$2:$E$51,17)&"",INDEX(基础资料!$G$2:$G$51,17-50)&""),"") | V24: =IF($U24="",0,IF(AND(17>50,COUNTIF(基础资料!$E$2:$E$51,$U24)>0),0,1)) | W24: =IF($V24=1,N(W23)+1,N(W23))
A25: =IF($S25="","",INDEX(数据录入!$B$5:$B$4999,$S25)) | B25: =IF($S25="","",INDEX(数据录入!$C$5:$C$4999,$S25)&"") | C25: =IF($S25="","",IF(N($F25)>0,"收款",IF(N($G25)>0,"付款",""))) | D25: =IF($S25="","",IF((INDEX(数据录入!$I$5:$I$4999,$S25)&"")<>"",INDEX(数据录入!$I$5:$I$4999,$S25)&"",INDEX(数据录入!$J$5:$J$4999,$S25)&"")) | E25: =IF($S25="","",INDEX(数据录入!$E$5:$E$4999,$S25)&"") | F25: =IF($S25="","",N(INDEX(数据录入!$F$5:$F$4999,$S25))) | G25: =IF($S25="","",N(INDEX(数据录入!$G$5:$G$4999,$S25))) | H25: =IF($S25="","",$G$2+SUM($F$8:$F25)-SUM($G$8:$G25)) | J25: =IF($K25="","",18) | K25: =IFERROR(INDEX($U$8:$U$107,MATCH(18,$W$8:$W$107,0)),"") | L25: =IF($K25="","",(SUMIFS(数据录入!$F$5:$F$4999,$Q$5:$Q$4999,1,数据录入!$B$5:$B$4999,"<"&$B$2,数据录入!$I$5:$I$4999,$K25)+SUMIFS(数据录入!$F$5:$F$4999,$Q$5:$Q$4999,1,数据录入!$B$5:$B$4999,"<"&$B$2,数据录入!$J$5:$J$4999,$K25))-(SUMIFS(数据录入!$G$5:$G$4999,$Q$5:$Q$4999,1,数据录入!$B$5:$B$4999,"<"&$B$2,数据录入!$I$5:$I$4999,$K25)+SUMIFS(数据录入!$G$5:$G$4999,$Q$5:$Q$4999,1,数据录入!$B$5:$B$4999,"<"&$B$2,数据录入!$J$5:$J$4999,$K25))) | M25: =IF($K25="","",SUMIFS(数据录入!$F$5:$F$4999,$Q$5:$Q$4999,1,数据录入!$B$5:$B$4999,">="&$B$2,数据录入!$B$5:$B$4999,"<="&$D$2,数据录入!$I$5:$I$4999,$K25)+SUMIFS(数据录入!$F$5:$F$4999,$Q$5:$Q$4999,1,数据录入!$B$5:$B$4999,">="&$B$2,数据录入!$B$5:$B$4999,"<="&$D$2,数据录入!$J$5:$J$4999,$K25)) | N25: =IF($K25="","",SUMIFS(数据录入!$G$5:$G$4999,$Q$5:$Q$4999,1,数据录入!$B$5:$B$4999,">="&$B$2,数据录入!$B$5:$B$4999,"<="&$D$2,数据录入!$I$5:$I$4999,$K25)+SUMIFS(数据录入!$G$5:$G$4999,$Q$5:$Q$4999,1,数据录入!$B$5:$B$4999,">="&$B$2,数据录入!$B$5:$B$4999,"<="&$D$2,数据录入!$J$5:$J$4999,$K25)) | O25: =IF($K25="","",L25+M25-N25) | Q25: =IF(数据录入!$B25="",0,IF(OR(数据录入!$D25="投标保证金",数据录入!$D25="合同履约保证金",ISNUMBER(FIND("保证金",数据录入!$E25))),1,0)) | R25: =IF(AND($Q25=1,数据录入!$B25>=$B$2,数据录入!$B25<=$D$2),N(R24)+1,N(R24)) | S25: =IFERROR(MATCH(18,$R$5:$R$4999,0),"") | U25: =IFERROR(IF(18<=50,INDEX(基础资料!$E$2:$E$51,18)&"",INDEX(基础资料!$G$2:$G$51,18-50)&""),"") | V25: =IF($U25="",0,IF(AND(18>50,COUNTIF(基础资料!$E$2:$E$51,$U25)>0),0,1)) | W25: =IF($V25=1,N(W24)+1,N(W24))
A26: =IF($S26="","",INDEX(数据录入!$B$5:$B$4999,$S26)) | B26: =IF($S26="","",INDEX(数据录入!$C$5:$C$4999,$S26)&"") | C26: =IF($S26="","",IF(N($F26)>0,"收款",IF(N($G26)>0,"付款",""))) | D26: =IF($S26="","",IF((INDEX(数据录入!$I$5:$I$4999,$S26)&"")<>"",INDEX(数据录入!$I$5:$I$4999,$S26)&"",INDEX(数据录入!$J$5:$J$4999,$S26)&"")) | E26: =IF($S26="","",INDEX(数据录入!$E$5:$E$4999,$S26)&"") | F26: =IF($S26="","",N(INDEX(数据录入!$F$5:$F$4999,$S26))) | G26: =IF($S26="","",N(INDEX(数据录入!$G$5:$G$4999,$S26))) | H26: =IF($S26="","",$G$2+SUM($F$8:$F26)-SUM($G$8:$G26)) | J26: =IF($K26="","",19) | K26: =IFERROR(INDEX($U$8:$U$107,MATCH(19,$W$8:$W$107,0)),"") | L26: =IF($K26="","",(SUMIFS(数据录入!$F$5:$F$4999,$Q$5:$Q$4999,1,数据录入!$B$5:$B$4999,"<"&$B$2,数据录入!$I$5:$I$4999,$K26)+SUMIFS(数据录入!$F$5:$F$4999,$Q$5:$Q$4999,1,数据录入!$B$5:$B$4999,"<"&$B$2,数据录入!$J$5:$J$4999,$K26))-(SUMIFS(数据录入!$G$5:$G$4999,$Q$5:$Q$4999,1,数据录入!$B$5:$B$4999,"<"&$B$2,数据录入!$I$5:$I$4999,$K26)+SUMIFS(数据录入!$G$5:$G$4999,$Q$5:$Q$4999,1,数据录入!$B$5:$B$4999,"<"&$B$2,数据录入!$J$5:$J$4999,$K26))) | M26: =IF($K26="","",SUMIFS(数据录入!$F$5:$F$4999,$Q$5:$Q$4999,1,数据录入!$B$5:$B$4999,">="&$B$2,数据录入!$B$5:$B$4999,"<="&$D$2,数据录入!$I$5:$I$4999,$K26)+SUMIFS(数据录入!$F$5:$F$4999,$Q$5:$Q$4999,1,数据录入!$B$5:$B$4999,">="&$B$2,数据录入!$B$5:$B$4999,"<="&$D$2,数据录入!$J$5:$J$4999,$K26)) | N26: =IF($K26="","",SUMIFS(数据录入!$G$5:$G$4999,$Q$5:$Q$4999,1,数据录入!$B$5:$B$4999,">="&$B$2,数据录入!$B$5:$B$4999,"<="&$D$2,数据录入!$I$5:$I$4999,$K26)+SUMIFS(数据录入!$G$5:$G$4999,$Q$5:$Q$4999,1,数据录入!$B$5:$B$4999,">="&$B$2,数据录入!$B$5:$B$4999,"<="&$D$2,数据录入!$J$5:$J$4999,$K26)) | O26: =IF($K26="","",L26+M26-N26) | Q26: =IF(数据录入!$B26="",0,IF(OR(数据录入!$D26="投标保证金",数据录入!$D26="合同履约保证金",ISNUMBER(FIND("保证金",数据录入!$E26))),1,0)) | R26: =IF(AND($Q26=1,数据录入!$B26>=$B$2,数据录入!$B26<=$D$2),N(R25)+1,N(R25)) | S26: =IFERROR(MATCH(19,$R$5:$R$4999,0),"") | U26: =IFERROR(IF(19<=50,INDEX(基础资料!$E$2:$E$51,19)&"",INDEX(基础资料!$G$2:$G$51,19-50)&""),"") | V26: =IF($U26="",0,IF(AND(19>50,COUNTIF(基础资料!$E$2:$E$51,$U26)>0),0,1)) | W26: =IF($V26=1,N(W25)+1,N(W25))
A27: =IF($S27="","",INDEX(数据录入!$B$5:$B$4999,$S27)) | B27: =IF($S27="","",INDEX(数据录入!$C$5:$C$4999,$S27)&"") | C27: =IF($S27="","",IF(N($F27)>0,"收款",IF(N($G27)>0,"付款",""))) | D27: =IF($S27="","",IF((INDEX(数据录入!$I$5:$I$4999,$S27)&"")<>"",INDEX(数据录入!$I$5:$I$4999,$S27)&"",INDEX(数据录入!$J$5:$J$4999,$S27)&"")) | E27: =IF($S27="","",INDEX(数据录入!$E$5:$E$4999,$S27)&"") | F27: =IF($S27="","",N(INDEX(数据录入!$F$5:$F$4999,$S27))) | G27: =IF($S27="","",N(INDEX(数据录入!$G$5:$G$4999,$S27))) | H27: =IF($S27="","",$G$2+SUM($F$8:$F27)-SUM($G$8:$G27)) | J27: =IF($K27="","",20) | K27: =IFERROR(INDEX($U$8:$U$107,MATCH(20,$W$8:$W$107,0)),"") | L27: =IF($K27="","",(SUMIFS(数据录入!$F$5:$F$4999,$Q$5:$Q$4999,1,数据录入!$B$5:$B$4999,"<"&$B$2,数据录入!$I$5:$I$4999,$K27)+SUMIFS(数据录入!$F$5:$F$4999,$Q$5:$Q$4999,1,数据录入!$B$5:$B$4999,"<"&$B$2,数据录入!$J$5:$J$4999,$K27))-(SUMIFS(数据录入!$G$5:$G$4999,$Q$5:$Q$4999,1,数据录入!$B$5:$B$4999,"<"&$B$2,数据录入!$I$5:$I$4999,$K27)+SUMIFS(数据录入!$G$5:$G$4999,$Q$5:$Q$4999,1,数据录入!$B$5:$B$4999,"<"&$B$2,数据录入!$J$5:$J$4999,$K27))) | M27: =IF($K27="","",SUMIFS(数据录入!$F$5:$F$4999,$Q$5:$Q$4999,1,数据录入!$B$5:$B$4999,">="&$B$2,数据录入!$B$5:$B$4999,"<="&$D$2,数据录入!$I$5:$I$4999,$K27)+SUMIFS(数据录入!$F$5:$F$4999,$Q$5:$Q$4999,1,数据录入!$B$5:$B$4999,">="&$B$2,数据录入!$B$5:$B$4999,"<="&$D$2,数据录入!$J$5:$J$4999,$K27)) | N27: =IF($K27="","",SUMIFS(数据录入!$G$5:$G$4999,$Q$5:$Q$4999,1,数据录入!$B$5:$B$4999,">="&$B$2,数据录入!$B$5:$B$4999,"<="&$D$2,数据录入!$I$5:$I$4999,$K27)+SUMIFS(数据录入!$G$5:$G$4999,$Q$5:$Q$4999,1,数据录入!$B$5:$B$4999,">="&$B$2,数据录入!$B$5:$B$4999,"<="&$D$2,数据录入!$J$5:$J$4999,$K27)) | O27: =IF($K27="","",L27+M27-N27) | Q27: =IF(数据录入!$B27="",0,IF(OR(数据录入!$D27="投标保证金",数据录入!$D27="合同履约保证金",ISNUMBER(FIND("保证金",数据录入!$E27))),1,0)) | R27: =IF(AND($Q27=1,数据录入!$B27>=$B$2,数据录入!$B27<=$D$2),N(R26)+1,N(R26)) | S27: =IFERROR(MATCH(20,$R$5:$R$4999,0),"") | U27: =IFERROR(IF(20<=50,INDEX(基础资料!$E$2:$E$51,20)&"",INDEX(基础资料!$G$2:$G$51,20-50)&""),"") | V27: =IF($U27="",0,IF(AND(20>50,COUNTIF(基础资料!$E$2:$E$51,$U27)>0),0,1)) | W27: =IF($V27=1,N(W26)+1,N(W26))
A28: =IF($S28="","",INDEX(数据录入!$B$5:$B$4999,$S28)) | B28: =IF($S28="","",INDEX(数据录入!$C$5:$C$4999,$S28)&"") | C28: =IF($S28="","",IF(N($F28)>0,"收款",IF(N($G28)>0,"付款",""))) | D28: =IF($S28="","",IF((INDEX(数据录入!$I$5:$I$4999,$S28)&"")<>"",INDEX(数据录入!$I$5:$I$4999,$S28)&"",INDEX(数据录入!$J$5:$J$4999,$S28)&"")) | E28: =IF($S28="","",INDEX(数据录入!$E$5:$E$4999,$S28)&"") | F28: =IF($S28="","",N(INDEX(数据录入!$F$5:$F$4999,$S28))) | G28: =IF($S28="","",N(INDEX(数据录入!$G$5:$G$4999,$S28))) | H28: =IF($S28="","",$G$2+SUM($F$8:$F28)-SUM($G$8:$G28)) | J28: =IF($K28="","",21) | K28: =IFERROR(INDEX($U$8:$U$107,MATCH(21,$W$8:$W$107,0)),"") | L28: =IF($K28="","",(SUMIFS(数据录入!$F$5:$F$4999,$Q$5:$Q$4999,1,数据录入!$B$5:$B$4999,"<"&$B$2,数据录入!$I$5:$I$4999,$K28)+SUMIFS(数据录入!$F$5:$F$4999,$Q$5:$Q$4999,1,数据录入!$B$5:$B$4999,"<"&$B$2,数据录入!$J$5:$J$4999,$K28))-(SUMIFS(数据录入!$G$5:$G$4999,$Q$5:$Q$4999,1,数据录入!$B$5:$B$4999,"<"&$B$2,数据录入!$I$5:$I$4999,$K28)+SUMIFS(数据录入!$G$5:$G$4999,$Q$5:$Q$4999,1,数据录入!$B$5:$B$4999,"<"&$B$2,数据录入!$J$5:$J$4999,$K28))) | M28: =IF($K28="","",SUMIFS(数据录入!$F$5:$F$4999,$Q$5:$Q$4999,1,数据录入!$B$5:$B$4999,">="&$B$2,数据录入!$B$5:$B$4999,"<="&$D$2,数据录入!$I$5:$I$4999,$K28)+SUMIFS(数据录入!$F$5:$F$4999,$Q$5:$Q$4999,1,数据录入!$B$5:$B$4999,">="&$B$2,数据录入!$B$5:$B$4999,"<="&$D$2,数据录入!$J$5:$J$4999,$K28)) | N28: =IF($K28="","",SUMIFS(数据录入!$G$5:$G$4999,$Q$5:$Q$4999,1,数据录入!$B$5:$B$4999,">="&$B$2,数据录入!$B$5:$B$4999,"<="&$D$2,数据录入!$I$5:$I$4999,$K28)+SUMIFS(数据录入!$G$5:$G$4999,$Q$5:$Q$4999,1,数据录入!$B$5:$B$4999,">="&$B$2,数据录入!$B$5:$B$4999,"<="&$D$2,数据录入!$J$5:$J$4999,$K28)) | O28: =IF($K28="","",L28+M28-N28) | Q28: =IF(数据录入!$B28="",0,IF(OR(数据录入!$D28="投标保证金",数据录入!$D28="合同履约保证金",ISNUMBER(FIND("保证金",数据录入!$E28))),1,0)) | R28: =IF(AND($Q28=1,数据录入!$B28>=$B$2,数据录入!$B28<=$D$2),N(R27)+1,N(R27)) | S28: =IFERROR(MATCH(21,$R$5:$R$4999,0),"") | U28: =IFERROR(IF(21<=50,INDEX(基础资料!$E$2:$E$51,21)&"",INDEX(基础资料!$G$2:$G$51,21-50)&""),"") | V28: =IF($U28="",0,IF(AND(21>50,COUNTIF(基础资料!$E$2:$E$51,$U28)>0),0,1)) | W28: =IF($V28=1,N(W27)+1,N(W27))
A29: =IF($S29="","",INDEX(数据录入!$B$5:$B$4999,$S29)) | B29: =IF($S29="","",INDEX(数据录入!$C$5:$C$4999,$S29)&"") | C29: =IF($S29="","",IF(N($F29)>0,"收款",IF(N($G29)>0,"付款",""))) | D29: =IF($S29="","",IF((INDEX(数据录入!$I$5:$I$4999,$S29)&"")<>"",INDEX(数据录入!$I$5:$I$4999,$S29)&"",INDEX(数据录入!$J$5:$J$4999,$S29)&"")) | E29: =IF($S29="","",INDEX(数据录入!$E$5:$E$4999,$S29)&"") | F29: =IF($S29="","",N(INDEX(数据录入!$F$5:$F$4999,$S29))) | G29: =IF($S29="","",N(INDEX(数据录入!$G$5:$G$4999,$S29))) | H29: =IF($S29="","",$G$2+SUM($F$8:$F29)-SUM($G$8:$G29)) | J29: =IF($K29="","",22) | K29: =IFERROR(INDEX($U$8:$U$107,MATCH(22,$W$8:$W$107,0)),"") | L29: =IF($K29="","",(SUMIFS(数据录入!$F$5:$F$4999,$Q$5:$Q$4999,1,数据录入!$B$5:$B$4999,"<"&$B$2,数据录入!$I$5:$I$4999,$K29)+SUMIFS(数据录入!$F$5:$F$4999,$Q$5:$Q$4999,1,数据录入!$B$5:$B$4999,"<"&$B$2,数据录入!$J$5:$J$4999,$K29))-(SUMIFS(数据录入!$G$5:$G$4999,$Q$5:$Q$4999,1,数据录入!$B$5:$B$4999,"<"&$B$2,数据录入!$I$5:$I$4999,$K29)+SUMIFS(数据录入!$G$5:$G$4999,$Q$5:$Q$4999,1,数据录入!$B$5:$B$4999,"<"&$B$2,数据录入!$J$5:$J$4999,$K29))) | M29: =IF($K29="","",SUMIFS(数据录入!$F$5:$F$4999,$Q$5:$Q$4999,1,数据录入!$B$5:$B$4999,">="&$B$2,数据录入!$B$5:$B$4999,"<="&$D$2,数据录入!$I$5:$I$4999,$K29)+SUMIFS(数据录入!$F$5:$F$4999,$Q$5:$Q$4999,1,数据录入!$B$5:$B$4999,">="&$B$2,数据录入!$B$5:$B$4999,"<="&$D$2,数据录入!$J$5:$J$4999,$K29)) | N29: =IF($K29="","",SUMIFS(数据录入!$G$5:$G$4999,$Q$5:$Q$4999,1,数据录入!$B$5:$B$4999,">="&$B$2,数据录入!$B$5:$B$4999,"<="&$D$2,数据录入!$I$5:$I$4999,$K29)+SUMIFS(数据录入!$G$5:$G$4999,$Q$5:$Q$4999,1,数据录入!$B$5:$B$4999,">="&$B$2,数据录入!$B$5:$B$4999,"<="&$D$2,数据录入!$J$5:$J$4999,$K29)) | O29: =IF($K29="","",L29+M29-N29) | Q29: =IF(数据录入!$B29="",0,IF(OR(数据录入!$D29="投标保证金",数据录入!$D29="合同履约保证金",ISNUMBER(FIND("保证金",数据录入!$E29))),1,0)) | R29: =IF(AND($Q29=1,数据录入!$B29>=$B$2,数据录入!$B29<=$D$2),N(R28)+1,N(R28)) | S29: =IFERROR(MATCH(22,$R$5:$R$4999,0),"") | U29: =IFERROR(IF(22<=50,INDEX(基础资料!$E$2:$E$51,22)&"",INDEX(基础资料!$G$2:$G$51,22-50)&""),"") | V29: =IF($U29="",0,IF(AND(22>50,COUNTIF(基础资料!$E$2:$E$51,$U29)>0),0,1)) | W29: =IF($V29=1,N(W28)+1,N(W28))
A30: =IF($S30="","",INDEX(数据录入!$B$5:$B$4999,$S30)) | B30: =IF($S30="","",INDEX(数据录入!$C$5:$C$4999,$S30)&"") | C30: =IF($S30="","",IF(N($F30)>0,"收款",IF(N($G30)>0,"付款",""))) | D30: =IF($S30="","",IF((INDEX(数据录入!$I$5:$I$4999,$S30)&"")<>"",INDEX(数据录入!$I$5:$I$4999,$S30)&"",INDEX(数据录入!$J$5:$J$4999,$S30)&"")) | E30: =IF($S30="","",INDEX(数据录入!$E$5:$E$4999,$S30)&"") | F30: =IF($S30="","",N(INDEX(数据录入!$F$5:$F$4999,$S30))) | G30: =IF($S30="","",N(INDEX(数据录入!$G$5:$G$4999,$S30))) | H30: =IF($S30="","",$G$2+SUM($F$8:$F30)-SUM($G$8:$G30)) | J30: =IF($K30="","",23) | K30: =IFERROR(INDEX($U$8:$U$107,MATCH(23,$W$8:$W$107,0)),"") | L30: =IF($K30="","",(SUMIFS(数据录入!$F$5:$F$4999,$Q$5:$Q$4999,1,数据录入!$B$5:$B$4999,"<"&$B$2,数据录入!$I$5:$I$4999,$K30)+SUMIFS(数据录入!$F$5:$F$4999,$Q$5:$Q$4999,1,数据录入!$B$5:$B$4999,"<"&$B$2,数据录入!$J$5:$J$4999,$K30))-(SUMIFS(数据录入!$G$5:$G$4999,$Q$5:$Q$4999,1,数据录入!$B$5:$B$4999,"<"&$B$2,数据录入!$I$5:$I$4999,$K30)+SUMIFS(数据录入!$G$5:$G$4999,$Q$5:$Q$4999,1,数据录入!$B$5:$B$4999,"<"&$B$2,数据录入!$J$5:$J$4999,$K30))) | M30: =IF($K30="","",SUMIFS(数据录入!$F$5:$F$4999,$Q$5:$Q$4999,1,数据录入!$B$5:$B$4999,">="&$B$2,数据录入!$B$5:$B$4999,"<="&$D$2,数据录入!$I$5:$I$4999,$K30)+SUMIFS(数据录入!$F$5:$F$4999,$Q$5:$Q$4999,1,数据录入!$B$5:$B$4999,">="&$B$2,数据录入!$B$5:$B$4999,"<="&$D$2,数据录入!$J$5:$J$4999,$K30)) | N30: =IF($K30="","",SUMIFS(数据录入!$G$5:$G$4999,$Q$5:$Q$4999,1,数据录入!$B$5:$B$4999,">="&$B$2,数据录入!$B$5:$B$4999,"<="&$D$2,数据录入!$I$5:$I$4999,$K30)+SUMIFS(数据录入!$G$5:$G$4999,$Q$5:$Q$4999,1,数据录入!$B$5:$B$4999,">="&$B$2,数据录入!$B$5:$B$4999,"<="&$D$2,数据录入!$J$5:$J$4999,$K30)) | O30: =IF($K30="","",L30+M30-N30) | Q30: =IF(数据录入!$B30="",0,IF(OR(数据录入!$D30="投标保证金",数据录入!$D30="合同履约保证金",ISNUMBER(FIND("保证金",数据录入!$E30))),1,0)) | R30: =IF(AND($Q30=1,数据录入!$B30>=$B$2,数据录入!$B30<=$D$2),N(R29)+1,N(R29)) | S30: =IFERROR(MATCH(23,$R$5:$R$4999,0),"") | U30: =IFERROR(IF(23<=50,INDEX(基础资料!$E$2:$E$51,23)&"",INDEX(基础资料!$G$2:$G$51,23-50)&""),"") | V30: =IF($U30="",0,IF(AND(23>50,COUNTIF(基础资料!$E$2:$E$51,$U30)>0),0,1)) | W30: =IF($V30=1,N(W29)+1,N(W29))
A31: =IF($S31="","",INDEX(数据录入!$B$5:$B$4999,$S31)) | B31: =IF($S31="","",INDEX(数据录入!$C$5:$C$4999,$S31)&"") | C31: =IF($S31="","",IF(N($F31)>0,"收款",IF(N($G31)>0,"付款",""))) | D31: =IF($S31="","",IF((INDEX(数据录入!$I$5:$I$4999,$S31)&"")<>"",INDEX(数据录入!$I$5:$I$4999,$S31)&"",INDEX(数据录入!$J$5:$J$4999,$S31)&"")) | E31: =IF($S31="","",INDEX(数据录入!$E$5:$E$4999,$S31)&"") | F31: =IF($S31="","",N(INDEX(数据录入!$F$5:$F$4999,$S31))) | G31: =IF($S31="","",N(INDEX(数据录入!$G$5:$G$4999,$S31))) | H31: =IF($S31="","",$G$2+SUM($F$8:$F31)-SUM($G$8:$G31)) | J31: =IF($K31="","",24) | K31: =IFERROR(INDEX($U$8:$U$107,MATCH(24,$W$8:$W$107,0)),"") | L31: =IF($K31="","",(SUMIFS(数据录入!$F$5:$F$4999,$Q$5:$Q$4999,1,数据录入!$B$5:$B$4999,"<"&$B$2,数据录入!$I$5:$I$4999,$K31)+SUMIFS(数据录入!$F$5:$F$4999,$Q$5:$Q$4999,1,数据录入!$B$5:$B$4999,"<"&$B$2,数据录入!$J$5:$J$4999,$K31))-(SUMIFS(数据录入!$G$5:$G$4999,$Q$5:$Q$4999,1,数据录入!$B$5:$B$4999,"<"&$B$2,数据录入!$I$5:$I$4999,$K31)+SUMIFS(数据录入!$G$5:$G$4999,$Q$5:$Q$4999,1,数据录入!$B$5:$B$4999,"<"&$B$2,数据录入!$J$5:$J$4999,$K31))) | M31: =IF($K31="","",SUMIFS(数据录入!$F$5:$F$4999,$Q$5:$Q$4999,1,数据录入!$B$5:$B$4999,">="&$B$2,数据录入!$B$5:$B$4999,"<="&$D$2,数据录入!$I$5:$I$4999,$K31)+SUMIFS(数据录入!$F$5:$F$4999,$Q$5:$Q$4999,1,数据录入!$B$5:$B$4999,">="&$B$2,数据录入!$B$5:$B$4999,"<="&$D$2,数据录入!$J$5:$J$4999,$K31)) | N31: =IF($K31="","",SUMIFS(数据录入!$G$5:$G$4999,$Q$5:$Q$4999,1,数据录入!$B$5:$B$4999,">="&$B$2,数据录入!$B$5:$B$4999,"<="&$D$2,数据录入!$I$5:$I$4999,$K31)+SUMIFS(数据录入!$G$5:$G$4999,$Q$5:$Q$4999,1,数据录入!$B$5:$B$4999,">="&$B$2,数据录入!$B$5:$B$4999,"<="&$D$2,数据录入!$J$5:$J$4999,$K31)) | O31: =IF($K31="","",L31+M31-N31) | Q31: =IF(数据录入!$B31="",0,IF(OR(数据录入!$D31="投标保证金",数据录入!$D31="合同履约保证金",ISNUMBER(FIND("保证金",数据录入!$E31))),1,0)) | R31: =IF(AND($Q31=1,数据录入!$B31>=$B$2,数据录入!$B31<=$D$2),N(R30)+1,N(R30)) | S31: =IFERROR(MATCH(24,$R$5:$R$4999,0),"") | U31: =IFERROR(IF(24<=50,INDEX(基础资料!$E$2:$E$51,24)&"",INDEX(基础资料!$G$2:$G$51,24-50)&""),"") | V31: =IF($U31="",0,IF(AND(24>50,COUNTIF(基础资料!$E$2:$E$51,$U31)>0),0,1)) | W31: =IF($V31=1,N(W30)+1,N(W30))
