Workbook

Sheet 使用说明
A1: 资金流水 + 成本核算 + 发票登记 一体化台账
A2: 适用：5~6家公司、16个银行账户、项目制经营；小规模与一般纳税人并存 ｜ 收入以开票金额为准
A4: 一、这套表解决什么问题
A5: 原来的做法是：每个账户一张表 → 再手工抄一遍收入明细 → 再手工抄一遍支出明细 → 再汇总。一笔流水要抄三遍，月底还要对不平。
A6: 现在的做法是：所有公司、所有账户的流水，只在「资金流水」一张表里录一遍；收入另外在「开票登记」一张表里录一遍。其余全部报表自动生成。
A7: 新增的三块联动：① 开票登记（既是收入来源，也按发票号自动核销收款）；② 项目核算（按项目自动归集收入与成本）；③ 应收应付台账（处理月末跨期）。
A9: 二、收入口径：以开票为准（重点）
A10: 公司确认的收入 = 「开票登记」里当月开出的发票金额，不是银行到账金额。开了票就算收入，钱什么时候到是回款问题。
A11: 含税还是不含税：由「基础资料」AH4 那一格开关控制，默认「价税合计(含税)」。改这一格，月度汇报表、项目核算表、趋势表、图表全部跟着变。
A12: 为什么默认含税：贵司的成本和费用都是按含税实付金额记的，缴的增值税又已经单列在支出的「税费」里。收入也用含税口径，三者才闭合。
A13: 如果要切到不含税，记得同时把支出端也换成不含税（剥离进项税），否则一般纳税人的毛利会被低估约一个税点。
A14: 没有发票的收入怎么办：利息、理财收益、政府补助这类永远开不出票，不登「开票登记」，在「资金流水」按实收登记，收入类别选「利息收入/理财收入/政府补助」即可 —— 报表会自动把它们并进「损益口径收入」，并在明细里标出取数来源。
... A61: 不够用时，选中最后一行整行下拉复制即可延伸公式；报表里的引用范围如需扩大，用「查找替换」把 3004 改成新的行号。

Sheet 基础资料
A1: 基础资料 — 所有下拉选项的数据源（改这里，全表下拉自动跟着变）
A2: ⚠ 黄色底=必须按贵司实际情况核对/填写。新增公司、账户、项目、类别，直接往下面空行里加即可，报表会自动识别。
A3: 公司简称 | B3: 公司全称 | C3: 纳税人类型 | E3: 账户名称 | F3: 所属公司 | G3: 账户类型 | I3: 项目编号 | J3: 项目名称 | K3: 所属公司 | L3: 客户 | M3: 合同金额 | N3: 签约日期 | O3: 项目状态 | Q3: 收入类别 | R3: 收入大类 | T3: 成本类别 | V3: 费用类别 | W3: 费用大类 | Y3: 客户 | AA3: 供应商 | AC3: 发票类型 | AE3: 税率 | AG3: 全局参数 | AH3: 取值
A4: 双思威 | B4: 双思威（请补全称） | C4: 一般纳税人 | E4: 双思威基本户 | F4: 双思威 | G4: 基本户 | I4: P001 | J4: 昌吉市中小学数字化校园建设工程（昌吉市第十五小学教学仪器设备采购项目） | K4: 双思威 | L4: 中移系统集成有限公司 | M4: 7443095.2 | N4: 2021年9月30 | O4: 在建 | Q4: 项目收入 | R4: 经营收入 | T4: 项目-材料 | V4: 办公费 | W4: 管理费用 | Y4: 客户1 | AA4: 供应商1 | AC4: 增值税专用发票 | AE4: 0.13 | AG4: 收入口径 | AH4: 价税合计(含税)
A5: 晨拓 | B5: 晨拓（请补全称） | C5: 一般纳税人 | E5: 双思威农商行一般户 | F5: 双思威 | G5: 一般户 | I5: P002 | J5: 昌吉市中小学数字化校园建设工程（昌吉市第十八小学教学仪器设备采购项目） | K5: 双思威 | L5: 昌吉代建局 | M5: 7790000 | N5: 2021年9月30 | O5: 在建 | Q5: 劳务/服务收入 | R5: 经营收入 | T5: 项目-人工 | V5: 水费 | W5: 管理费用 | Y5: 客户2 | AA5: 供应商2 | AC5: 增值税普通发票 | AE5: 0.09 | AG5: 说明 | AH5: 收入按开票金额确认。这个开关决定全表“开票收入”取价税合计还是不含税金额——改这一格，月度汇报表、项目核算表、趋势表、图表全部跟着变。因为成本费用都是含税实付、且增值税已单列在支出里，默认用价税合计才闭合。
A6: 瑞盛天 | B6: 瑞盛天（请补全称） | C6: 一般纳税人 | E6: 晨拓农商行基本户 | F6: 晨拓 | G6: 基本户 | I6: P003 | K6: 双思威 | N6: 44995 | O6: 已完工待收款 | Q6: 理财收入 | R6: 非经营收入 | T6: 项目-机械设备 | V6: 电费 | W6: 管理费用 | Y6: 客户3 | AA6: 供应商3 | AC6: 电子发票(普通票) | AE6: 0.06
A7: 鑫海特 | B7: 鑫海特（请补全称） | C7: 一般纳税人 | E7: 元界极光中行基本户 | F7: 元界极光 | G7: 基本户 | J7: 李广新昌吉市第十六小学教学仪器设备采购 | K7: 双思威 | L7: 新疆新广立科技有限公司 | M7: 6210476.1 | N7: 2022年3月20 | O7: 已完工待收款 | Q7: 利息收入 | R7: 非经营收入 | T7: 项目-零星开支 | V7: 伙食费 | W7: 管理费用 | Y7: 客户4 | AA7: 供应商4 | AC7: 电子发票(专用票) | AE7: 0.05
A8: 中展 | B8: 中展（请补全称） | C8: 小规模纳税人 | E8: 元界极光农商行一般户 | F8: 元界极光 | G8: 一般户 | J8: 昌吉市第十八小学教学设备采购及安装设备购置项目（二次） | K8: 双思威 | L8: 昌吉市教育局 | M8: 3733820 | N8: 2022年10月20 | O8: 已完工待收款 | Q8: 政府补助 | R8: 非经营收入 | T8: 项目-运费 | V8: 租赁费 | W8: 管理费用 | Y8: 客户5 | AA8: 供应商5 | AC8: 收据/未开票 | AE8: 0.03
A9: 元界极光 | B9: 元界极光 | C9: 小规模纳税人 | E9: 瑞盛天中行基本户 | F9: 瑞盛天 | G9: 基本户 | J9: 新疆某单位教育教学设备（二标段）六中项目 | K9: 双思威 | L9: 中移系统集成有限公司 | M9: 6515900.9 | N9: 44995 | O9: 已完工待收款 | Q9: 其他收入 | R9: 非经营收入 | T9: 项目-分包/劳务 | V9: 差旅费 | W9: 管理费用 | Y9: 客户6 | AA9: 供应商6 | AE9: 0.01
A10: 元界启辰 | B10: 元界启辰 | C10: 小规模纳税人 | E10: 瑞盛天农商行一般户 | F10: 瑞盛天 | G10: 一般户 | J10: 第二师铁门关市武安街消防站改造项目 | K10: 双思威 | L10: 中国电信股份有限公司巴音郭楞蒙古自治州分公司 | M10: 737890 | N10: 2025.11.24 | O10: 已完工待收款 | Q10: 保证金退回 | R10: 往来及保证金 | T10: 项目-税款 | V10: 业务招待费 | W10: 管理费用 | Y10: 客户7 | AA10: 供应商7 | AE10: 0
A11: 锐思维度 | B11: 锐思维度 | C11: 小规模纳税人 | E11: 中展中行基本户 | F11: 中展 | G11: 基本户 | J11: 昌吉市中等职业学校教学设备采购项目(二标段) | K11: 双思威 | L11: 中移建设有限公司新疆分公司 | M11: 2913561.4 | N11: 2025.8.26 | Q11: 借款收回 | R11: 往来及保证金 | T11: 项目-其他直接成本 | V11: 车辆费用 | W11: 管理费用 | Y11: 客户8 | AA11: 供应商8
A12: 鸿禧 | B12: 鸿禧 | C12: 小规模纳税人 | E12: 中展农商行一般户 | F12: 中展 | G12: 一般户 | J12: 中电信数智科技有限公司昌吉分公司2025年某学校智慧教室建设项目 | K12: 双思威 | L12: 中电信数智科技有限公司昌吉分公司 | M12: 295570 | N12: 2025.12.25 | Q12: 股东投入 | R12: 往来及保证金 | T12: 费用摊销 | V12: 通讯费 | W12: 管理费用 | Y12: 客户9 | AA12: 供应商9
A13: 卓卓通 | B13: 卓卓通 | C13: 小规模纳税人 | E13: 中展准东项目 | F13: 中展 | G13: 一般户 | J13: 中国电信巴州分公司2025年某部幼儿园视频监控系统服务采购 | K13: 双思威 | L13: 中国电信股份有限公司巴音郭楞蒙古自治州分公司 | M13: 126140 | N13: 2025.4.21 | Q13: 内部调拨转入 | R13: 往来及保证金 | V13: 快递费 | W13: 管理费用 | Y13: 客户10 | AA13: 供应商10
A14: 财兴通 | B14: 财兴通 | C14: 小规模纳税人 | E14: 卓卓通农商行基本户 | F14: 卓卓通 | G14: 基本户 | J14: 昌吉市中等职业学校教学设备采购项目（一标段） | K14: 双思威 | L14: 北京竞业达数码科技股份有限公司 | M14: 3903000 | N14: 2025.8.15 | V14: 公证费 | W14: 管理费用 | Y14: 客户11 | AA14: 供应商11
E15: 财兴通农商行基本户 | F15: 财兴通 | G15: 基本户 | J15: 草湖标识标牌项目 | K15: 双思威 | L15: 收新疆博创未来信息工程技术有限公司货款 | M15: 1240000 | N15: 2025.12.20 | V15: 咨询审计费 | W15: 管理费用 | Y15: 客户12 | AA15: 供应商12
E16: 鑫海特工行基本户 | F16: 鑫海特 | G16: 基本户 | J16: 昌吉市第二十一小学教育教学设备采购项目（三标段） | K16: 双思威 | L16: 昌吉市教育局 | M16: 1302839.1 | N16: 2025.8.8 | V16: 软件服务费 | W16: 管理费用 | Y16: 客户13 | AA16: 供应商13
E17: 鸿禧农行基本户 | F17: 鸿禧 | G17: 基本户 | J17: 昌吉市第七小学润苗楼教室文化墙、图书角及会议室项目 | K17: 元界极光 | L17: 昌吉市第七小学 | M17: 162144.8 | N17: 46051 | O17: 已完工已收款 | V17: 保险费 | W17: 管理费用
E18: 元界启辰中行基本户 | F18: 元界启辰 | G18: 基本户 | J18: 昌吉市第十小学售后 | K18: 中展 | L18: 昌吉市第十小学 | M18: 2760 | N18: 2026年3月17 | O18: 已完工已收款 | V18: 物业费 | W18: 管理费用
E19: 锐思维度中行基本户 | F19: 锐思维度 | G19: 基本户 | J19: 昌吉市第三幼儿园（二十幼）厨房设备采购项目 | K19: 中展 | L19: 昌吉市第三幼儿园 | M19: 25000 | N19: 46135 | O19: 已完工已收款 | V19: 职工福利费 | W19: 管理费用
E20: 备用7 | J20: 昌吉市南安幼儿园设备采购项目 | K20: 中展 | L20: 昌吉市第五幼儿园 | M20: 100000 | N20: 46141 | O20: 已完工已收款 | V20: 其他管理费用 | W20: 管理费用
E21: 备用8 | J21: 昌吉市第十小学（昌吉市第十九小学创客项目） | K21: 锐思维度 | L21: 昌吉市第十小学 | M21: 201460 | N21: 46157 | O21: 已完工已收款 | V21: 工资 | W21: 人工社保
E22: 备用9 | J22: 昌吉市第二小学智慧安防系统改造 | K22: 锐思维度 | L22: 昌吉市第二小学 | M22: 233000 | N22: 46164 | O22: 已完工待收款 | V22: 奖金/提成 | W22: 人工社保
E23: 备用10 | J23: 昌吉市第十六小学校园监控设备采购项目 | K23: 锐思维度 | L23: 昌吉市十四小学 | M23: 115130 | N23: 46164 | O23: 已完工待收款 | V23: 养老保险 | W23: 人工社保
J24: 昌吉市第十六小学校园广播设备采购项目 | K24: 中展 | L24: 昌吉市十四小学 | M24: 108510 | N24: 46164 | O24: 已完工待收款 | V24: 医疗保险 | W24: 人工社保
J25: 昌吉市第一小学学生机房项目 | K25: 元界启辰 | L25: 昌吉市第一小学 | M25: 332654 | N25: 46164 | O25: 已完工待收款 | V25: 失业/工伤保险 | W25: 人工社保
J26: 昌吉市第十小学智慧教室项目 | K26: 元界启辰 | L26: 昌吉市第十小学 | M26: 301080 | N26: 2026年6月30 | O26: 已完工已收款 | V26: 住房公积金 | W26: 人工社保
J27: 昌吉市第三中学安检门 | K27: 中展 | L27: 昌吉市第三中学 | M27: 72000 | N27: 2026年6月15 | O27: 已完工已收款 | V27: 劳务费 | W27: 人工社保
J28: 昌吉市第七小学阶梯教室设备采购项目 | K28: 瑞盛天 | L28: 昌吉市教育局 | M28: 1159595 | N28: 2026年7月23 | O28: 未完工未收款 | V28: 增值税 | W28: 税费
J29: 昌吉市第八小学5G+课堂建设采购项目 | K29: 中展 | L29: 昌吉市第八小学 | M29: 508600 | N29: 2026年7月17 | O29: 未完工未收款 | V29: 附加税 | W29: 税费
J30: 2026年新疆信友能源投资有限公司网格优化服务项目 | K30: 双思威 | L30: 新疆信友能源投资有限公司 | M30: 332000 | N30: 46223 | V30: 印花税 | W30: 税费
J31: 昌吉市第十七小学配套附属设施采购项目（教育教学设备 | K31: 元界启辰 | L31: 昌吉市教育局 | M31: 2937098 | N31: 2026年8月5 | O31: 未完工未收款 | V31: 企业所得税 | W31: 税费
J32: 昌吉市第十二小学阶梯教室设备采购项目 | K32: 双思威 | L32: 昌吉市第十二小学 | M32: 953360 | N32: 2026年6月16 | O32: 未完工未收款 | V32: 个人所得税 | W32: 税费
J33: 十八小的厨房监控 | K33: 中展 | L33: 昌吉市第十四小学 | M33: 45000 | N33: 2026年4月28 | O33: 已完工已收款 | V33: 其他税费 | W33: 税费
J34: 昌吉市南安幼儿园设备采购项目 | K34: 中展 | L34: 昌吉市第五幼儿园 | M34: 27155 | N34: 46163 | O34: 已完工已收款 | V34: 银行手续费 | W34: 财务费用
J35: 关于麦盖提县教育局“阳光食堂”硬件采购项目 | K35: 元界启辰 | L35: 新疆嘉盛鸿泰商贸有限公司 | M35: 202000 | V35: 利息支出 | W35: 财务费用
J36: 新疆某单位教育教学设备（二标段）甄选项目-六中 | K36: 双思威 | L36: 中移系统集成有限公司履约保证金 | M36: 6515900.9 | N36: 2023.3.2 | V36: 汇兑损益 | W36: 财务费用
J37: 代建局昌吉市第十八小学教学仪器设备采购项目 | K37: 双思威 | L37: 昌吉市政府投资建设项目代建管理中心 | M37: 7790000 | N37: 2021.9.30 | V37: 投标保证金 | W37: 往来及保证金
J38: 昌吉市四所幼儿园设备采购项目（三标段） | K38: 双思威 | L38: 昌吉市教育局 | M38: 2343634 | N38: 2024.7.2 | V38: 履约保证金 | W38: 往来及保证金
J39: 昌吉市中小学数字化校园建设工程（昌吉市第十五小学教学仪器设备采购项目） | K39: 双思威 | L39: 中移系统集成有限公司 | M39: 7443095.2 | N39: 2021.9.30 | V39: 备用金借出 | W39: 往来及保证金
J40: 铁门关经济技术开发区化工园区周界防护项目 | K40: 双思威 | L40: 中电信数智科技有限公司巴音郭楞蒙古自治州分公司 | M40: 3230000 | N40: 2025.7.20 | V40: 股东分红/抽资 | W40: 往来及保证金
...

Sheet 开票登记
A1: 开票登记表 — 收入以开票为准；逐张登记 + 收款自动核销（小规模 / 一般纳税人分开统计）
A2: 合计→ | C2: =IF(基础资料!$AH$4="不含税金额","本表口径收入(不含税)","本表口径收入(含税)") -> 本表口径收入(含税) | F2: =IF(基础资料!$AH$4="不含税金额",$J$2,$M$2) -> 24007854 | J2: =SUBTOTAL(109,$J$5:$J$504) -> 21870817 | L2: =SUBTOTAL(109,$L$5:$L$504) -> 2137037.7 | M2: =SUBTOTAL(109,$M$5:$M$504) -> 24007854 | N2: =SUBTOTAL(109,$N$5:$N$504) -> #VALUE! | O2: =SUBTOTAL(109,$O$5:$O$504) -> 19010886 | P2: =SUBTOTAL(109,$P$5:$P$504) -> #VALUE!
A3: 登记规则：①每张发票一行——公司确认的“收入”就是这张表，不是银行到账。②I列“发票号码”是核销的钥匙：收到这张票的钱时，在「资金流水」Q列填同一个发票号码，N列自动算出已收款、P列自动算未收款、S列自动算账龄（超90天标红）。③多票合并收款、对不上票号的，直接在O列手工登记已收金额。④H列“收入类别”决定这笔收入进汇报表哪一行，一般选“项目收入”。⑤L列税额=不含税×税率自动算，与发票实际税额有出入可直接覆盖。⑥利息、理财、补助这类永远没有发票的收入，不登这张表，在「资金流水」按实收登记即可，报表会自动并进来。
A4: 序号 | B4: 开票日期 | C4: 开票公司 | D4: 纳税人类型 (自动) | E4: 发票类型 | F4: 购方名称 | G4: 项目名称 | H4: 收入类别 | I4: 发票号码 | J4: 不含税金额 | K4: 税率 | L4: 税额 | M4: 价税合计 | N4: 已收款 (按票号自动) | O4: 已收款 (手工登记) | P4: 未收款 | Q4: 收款状态 | R4: 开票归属月 | S4: 账龄(天) | T4: 备注
A5: =IF($B5="","",COUNTA($B$5:$B5)) -> 1 | B5: 45981 | C5: 双思威 | D5: =IFERROR(INDEX(基础资料!$C$4:$C$11,MATCH($C5,基础资料!$A$4:$A$11,0)),"") -> 一般纳税人 | E5: 增值税专用发票 | F5: 客户3 | G5: 2025年结转项目 | H5: 项目收入 | I5: FP2025110001 | J5: 265486.73 | K5: 0.13 | L5: =IF($J5="","",ROUND($J5*$K5,2)) -> 34513.27 | M5: =IF($J5="","",ROUND($J5+$L5,2)) -> 300000 | N5: =IF($I5="","",SUMIFS(资金流水!$K$5:$K$3032,资金流水!$Q$5:$Q$3015,$I5)) -> #VALUE! | P5: =IF($J5="","",ROUND($M5-IF($N5="",0,$N5)-IF($O5="",0,$O5),2)) -> #VALUE! | Q5: =IF($J5="","",IF($P5<=0.005,"已收齐",IF(IF($N5="",0,$N5)+IF($O5="",0,$O5)<=0,"未收款","部分收款"))) -> #VALUE! | R5: =IF($B5="","",--TEXT($B5,"yyyymm")) -> 202511 | S5: =IF(OR($B5="",$P5="",$P5<=0.005),"",TODAY()-$B5) -> #VALUE! | T5: ★示例发票，可整行删除
A6: =IF($B6="","",COUNTA($B$5:$B6)) -> 2 | B6: 46026 | C6: 双思威 | D6: =IFERROR(INDEX(基础资料!$C$4:$C$11,MATCH($C6,基础资料!$A$4:$A$11,0)),"") -> 一般纳税人 | E6: 增值税专用发票 | F6: 北京竞业达数码科技股份有限公司 | G6: 昌吉市中等职业学校教学设备采购项目（一标段） | H6: 项目收入 | I6: FP20260601 | J6: 2409203.5 | K6: 0.13 | L6: =IF($J6="","",ROUND($J6*$K6,2)) -> 313196.46 | M6: =IF($J6="","",ROUND($J6+$L6,2)) -> 2722400 | O6: 2722400 | P6: =IF($J6="","",ROUND($M6-IF($N6="",0,$N6)-IF($O6="",0,$O6),2)) -> 0 | Q6: =IF($J6="","",IF($P6<=0.005,"已收齐",IF(IF($N6="",0,$N6)+IF($O6="",0,$O6)<=0,"未收款","部分收款"))) -> 已收齐 | R6: =IF($B6="","",--TEXT($B6,"yyyymm")) -> 202601 | S6: =IF(OR($B6="",$P6="",$P6<=0.005),"",TODAY()-$B6) | T6: ★示例发票，可整行删除
A7: =IF($B7="","",COUNTA($B$5:$B7)) -> 3 | B7: 46026 | C7: 双思威 | D7: =IFERROR(INDEX(基础资料!$C$4:$C$11,MATCH($C7,基础资料!$A$4:$A$11,0)),"") -> 一般纳税人 | E7: 增值税专用发票 | F7: 北京竞业达数码科技股份有限公司 | G7: 昌吉市中等职业学校教学设备采购项目（一标段） | H7: 项目收入 | I7: FP20260602 | J7: 377358.49 | K7: 0.06 | L7: =IF($J7="","",ROUND($J7*$K7,2)) -> 22641.51 | M7: =IF($J7="","",ROUND($J7+$L7,2)) -> 400000 | N7: =IF($I7="","",SUMIFS(资金流水!$K$5:$K$3032,资金流水!$Q$5:$Q$3015,$I7)) -> #VALUE! | O7: 400000 | P7: =IF($J7="","",ROUND($M7-IF($N7="",0,$N7)-IF($O7="",0,$O7),2)) -> #VALUE! | Q7: =IF($J7="","",IF($P7<=0.005,"已收齐",IF(IF($N7="",0,$N7)+IF($O7="",0,$O7)<=0,"未收款","部分收款"))) -> #VALUE! | R7: =IF($B7="","",--TEXT($B7,"yyyymm")) -> 202601 | S7: =IF(OR($B7="",$P7="",$P7<=0.005),"",TODAY()-$B7) -> #VALUE! | T7: ★示例发票，可整行删除
A8: =IF($B8="","",COUNTA($B$5:$B8)) -> 4 | B8: 46031 | C8: 双思威 | D8: =IFERROR(INDEX(基础资料!$C$4:$C$11,MATCH($C8,基础资料!$A$4:$A$11,0)),"") -> 一般纳税人 | E8: 增值税专用发票 | F8: 中电信数智科技有限公司昌吉分公司 | G8: 第二师铁门关市武安街消防站改造项目 | H8: 项目收入 | I8: FP20260602 | J8: 253743.29 | K8: 0.13 | L8: =IF($J8="","",ROUND($J8*$K8,2)) -> 32986.63 | M8: =IF($J8="","",ROUND($J8+$L8,2)) -> 286729.92 | N8: =IF($I8="","",SUMIFS(资金流水!$K$5:$K$3032,资金流水!$Q$5:$Q$3015,$I8)) -> #VALUE! | O8: 286729.92 | P8: =IF($J8="","",ROUND($M8-IF($N8="",0,$N8)-IF($O8="",0,$O8),2)) -> #VALUE! | Q8: =IF($J8="","",IF($P8<=0.005,"已收齐",IF(IF($N8="",0,$N8)+IF($O8="",0,$O8)<=0,"未收款","部分收款"))) -> #VALUE! | R8: =IF($B8="","",--TEXT($B8,"yyyymm")) -> 202601 | S8: =IF(OR($B8="",$P8="",$P8<=0.005),"",TODAY()-$B8) -> #VALUE!
A9: =IF($B9="","",COUNTA($B$5:$B9)) -> 5 | B9: 46036 | C9: 双思威 | D9: =IFERROR(INDEX(基础资料!$C$4:$C$11,MATCH($C9,基础资料!$A$4:$A$11,0)),"") -> 一般纳税人 | E9: 增值税专用发票 | F9: 中国电信股份有限公司和硕分公司 | G9: 中电信数智科技有限公司昌吉分公司2025年某学校智慧教室建设项目 | J9: 223071.7 | K9: 0.06 | L9: =IF($J9="","",ROUND($J9*$K9,2)) -> 13384.3 | M9: =IF($J9="","",ROUND($J9+$L9,2)) -> 236456 | N9: =IF($I9="","",SUMIFS(资金流水!$K$5:$K$3032,资金流水!$Q$5:$Q$3015,$I9)) | O9: 236456 | P9: =IF($J9="","",ROUND($M9-IF($N9="",0,$N9)-IF($O9="",0,$O9),2)) -> 0 | Q9: =IF($J9="","",IF($P9<=0.005,"已收齐",IF(IF($N9="",0,$N9)+IF($O9="",0,$O9)<=0,"未收款","部分收款"))) -> 已收齐 | R9: =IF($B9="","",--TEXT($B9,"yyyymm")) -> 202601 | S9: =IF(OR($B9="",$P9="",$P9<=0.005),"",TODAY()-$B9)
A10: =IF($B10="","",COUNTA($B$5:$B10)) -> 6 | B10: 46036 | C10: 双思威 | D10: =IFERROR(INDEX(基础资料!$C$4:$C$11,MATCH($C10,基础资料!$A$4:$A$11,0)),"") -> 一般纳税人 | E10: 增值税专用发票 | F10: 中国电信股份有限公司和硕分公司 | G10: 铁门关市乐美酒店监控项目 | J10: 17735.85 | K10: 0.06 | L10: =IF($J10="","",ROUND($J10*$K10,2)) -> 1064.15 | M10: =IF($J10="","",ROUND($J10+$L10,2)) -> 18800 | N10: =IF($I10="","",SUMIFS(资金流水!$K$5:$K$3032,资金流水!$Q$5:$Q$3015,$I10)) | O10: 18800 | P10: =IF($J10="","",ROUND($M10-IF($N10="",0,$N10)-IF($O10="",0,$O10),2)) -> 0 | Q10: =IF($J10="","",IF($P10<=0.005,"已收齐",IF(IF($N10="",0,$N10)+IF($O10="",0,$O10)<=0,"未收款","部分收款"))) -> 已收齐 | R10: =IF($B10="","",--TEXT($B10,"yyyymm")) -> 202601 | S10: =IF(OR($B10="",$P10="",$P10<=0.005),"",TODAY()-$B10)
A11: =IF($B11="","",COUNTA($B$5:$B11)) -> 7 | B11: 46036 | C11: 双思威 | D11: =IFERROR(INDEX(基础资料!$C$4:$C$11,MATCH($C11,基础资料!$A$4:$A$11,0)),"") -> 一般纳税人 | E11: 增值税专用发票 | F11: 中国电信股份有限公司和硕分公司 | J11: 15094.34 | K11: 0.06 | L11: =IF($J11="","",ROUND($J11*$K11,2)) -> 905.66 | M11: =IF($J11="","",ROUND($J11+$L11,2)) -> 16000 | N11: =IF($I11="","",SUMIFS(资金流水!$K$5:$K$3032,资金流水!$Q$5:$Q$3015,$I11)) | O11: 16000 | P11: =IF($J11="","",ROUND($M11-IF($N11="",0,$N11)-IF($O11="",0,$O11),2)) -> 0 | Q11: =IF($J11="","",IF($P11<=0.005,"已收齐",IF(IF($N11="",0,$N11)+IF($O11="",0,$O11)<=0,"未收款","部分收款"))) -> 已收齐 | R11: =IF($B11="","",--TEXT($B11,"yyyymm")) -> 202601 | S11: =IF(OR($B11="",$P11="",$P11<=0.005),"",TODAY()-$B11)
A12: =IF($B12="","",COUNTA($B$5:$B12)) -> 8 | B12: 46036 | C12: 双思威 | D12: =IFERROR(INDEX(基础资料!$C$4:$C$11,MATCH($C12,基础资料!$A$4:$A$11,0)),"") -> 一般纳税人 | E12: 增值税专用发票 | F12: 中电信数智科技有限公司昌吉分公司 | G12: 铁门关职业技术学院监控维修 | J12: 31037.74 | K12: 0.06 | L12: =IF($J12="","",ROUND($J12*$K12,2)) -> 1862.26 | M12: =IF($J12="","",ROUND($J12+$L12,2)) -> 32900 | N12: =IF($I12="","",SUMIFS(资金流水!$K$5:$K$3032,资金流水!$Q$5:$Q$3015,$I12)) | O12: 32900 | P12: =IF($J12="","",ROUND($M12-IF($N12="",0,$N12)-IF($O12="",0,$O12),2)) -> 0 | Q12: =IF($J12="","",IF($P12<=0.005,"已收齐",IF(IF($N12="",0,$N12)+IF($O12="",0,$O12)<=0,"未收款","部分收款"))) -> 已收齐 | R12: =IF($B12="","",--TEXT($B12,"yyyymm")) -> 202601 | S12: =IF(OR($B12="",$P12="",$P12<=0.005),"",TODAY()-$B12)
A13: =IF($B13="","",COUNTA($B$5:$B13)) -> 9 | B13: 46037 | C13: 双思威 | D13: =IFERROR(INDEX(基础资料!$C$4:$C$11,MATCH($C13,基础资料!$A$4:$A$11,0)),"") -> 一般纳税人 | E13: 增值税专用发票 | F13: 中国电信股份有限公司巴音郭楞蒙古自治州分公司 | G13: 中电信数智科技有限公司昌吉分公司2025年某学校智慧教室建设项目 | J13: 55767.92 | K13: 0.06 | L13: =IF($J13="","",ROUND($J13*$K13,2)) -> 3346.08 | M13: =IF($J13="","",ROUND($J13+$L13,2)) -> 59114 | N13: =IF($I13="","",SUMIFS(资金流水!$K$5:$K$3032,资金流水!$Q$5:$Q$3015,$I13)) | O13: 59114 | P13: =IF($J13="","",ROUND($M13-IF($N13="",0,$N13)-IF($O13="",0,$O13),2)) -> 0 | Q13: =IF($J13="","",IF($P13<=0.005,"已收齐",IF(IF($N13="",0,$N13)+IF($O13="",0,$O13)<=0,"未收款","部分收款"))) -> 已收齐 | R13: =IF($B13="","",--TEXT($B13,"yyyymm")) -> 202601 | S13: =IF(OR($B13="",$P13="",$P13<=0.005),"",TODAY()-$B13)
A14: =IF($B14="","",COUNTA($B$5:$B14)) -> 10 | B14: 46038 | C14: 双思威 | D14: =IFERROR(INDEX(基础资料!$C$4:$C$11,MATCH($C14,基础资料!$A$4:$A$11,0)),"") -> 一般纳税人 | E14: 增值税专用发票 | F14: 中国电信股份有限公司巴音郭楞蒙古自治州分公司 | G14: 中国电信巴州分公司2025年某部幼儿园视频监控系统服务采购 | J14: 72566.37 | K14: 0.13 | L14: =IF($J14="","",ROUND($J14*$K14,2)) -> 9433.63 | M14: =IF($J14="","",ROUND($J14+$L14,2)) -> 82000 | N14: =IF($I14="","",SUMIFS(资金流水!$K$5:$K$3032,资金流水!$Q$5:$Q$3015,$I14)) | O14: 82000 | P14: =IF($J14="","",ROUND($M14-IF($N14="",0,$N14)-IF($O14="",0,$O14),2)) -> 0 | Q14: =IF($J14="","",IF($P14<=0.005,"已收齐",IF(IF($N14="",0,$N14)+IF($O14="",0,$O14)<=0,"未收款","部分收款"))) -> 已收齐 | R14: =IF($B14="","",--TEXT($B14,"yyyymm")) -> 202601 | S14: =IF(OR($B14="",$P14="",$P14<=0.005),"",TODAY()-$B14)
A15: =IF($B15="","",COUNTA($B$5:$B15)) -> 11 | B15: 2026-2-2- | C15: 双思威 | D15: =IFERROR(INDEX(基础资料!$C$4:$C$11,MATCH($C15,基础资料!$A$4:$A$11,0)),"") -> 一般纳税人 | E15: 增值税专用发票 | F15: 中国电信股份有限公司巴音郭楞蒙古自治州分公司 | G15: 第二师民兵训练基地综合指挥系统平台云集成服务项目（陪标中标） | J15: 226415.09 | K15: 0.06 | L15: =IF($J15="","",ROUND($J15*$K15,2)) -> 13584.91 | M15: =IF($J15="","",ROUND($J15+$L15,2)) -> 240000 | N15: =IF($I15="","",SUMIFS(资金流水!$K$5:$K$3032,资金流水!$Q$5:$Q$3015,$I15)) | O15: 240000 | P15: =IF($J15="","",ROUND($M15-IF($N15="",0,$N15)-IF($O15="",0,$O15),2)) -> 0 | Q15: =IF($J15="","",IF($P15<=0.005,"已收齐",IF(IF($N15="",0,$N15)+IF($O15="",0,$O15)<=0,"未收款","部分收款"))) -> 已收齐 | R15: =IF($B15="","",--TEXT($B15,"yyyymm")) -> #VALUE! | S15: =IF(OR($B15="",$P15="",$P15<=0.005),"",TODAY()-$B15)
A16: =IF($B16="","",COUNTA($B$5:$B16)) -> 12 | B16: 46062 | C16: 双思威 | D16: =IFERROR(INDEX(基础资料!$C$4:$C$11,MATCH($C16,基础资料!$A$4:$A$11,0)),"") -> 一般纳税人 | E16: 增值税专用发票 | F16: 中国移动通信集团新疆有限公司昌吉州分公司 | G16: 昌吉健康云120调度指挥中心项目 | J16: 96117.43 | K16: 0.09 | L16: =IF($J16="","",ROUND($J16*$K16,2)) -> 8650.57 | M16: =IF($J16="","",ROUND($J16+$L16,2)) -> 104768 | N16: =IF($I16="","",SUMIFS(资金流水!$K$5:$K$3032,资金流水!$Q$5:$Q$3015,$I16)) | O16: 104768 | P16: =IF($J16="","",ROUND($M16-IF($N16="",0,$N16)-IF($O16="",0,$O16),2)) -> 0 | Q16: =IF($J16="","",IF($P16<=0.005,"已收齐",IF(IF($N16="",0,$N16)+IF($O16="",0,$O16)<=0,"未收款","部分收款"))) -> 已收齐 | R16: =IF($B16="","",--TEXT($B16,"yyyymm")) -> 202602 | S16: =IF(OR($B16="",$P16="",$P16<=0.005),"",TODAY()-$B16)
A17: =IF($B17="","",COUNTA($B$5:$B17)) -> 13 | B17: 46060 | C17: 双思威 | D17: =IFERROR(INDEX(基础资料!$C$4:$C$11,MATCH($C17,基础资料!$A$4:$A$11,0)),"") -> 一般纳税人 | E17: 增值税专用发票 | F17: 中国电信股份有限公司巴音郭楞蒙古自治州分公司 | G17: 中国电信巴州分公司2025年第二师GAJ视频监控平台、云集成服务项目设备及相关服务 | J17: 160000.09 | K17: 0.13 | L17: =IF($J17="","",ROUND($J17*$K17,2)) -> 20800.01 | M17: =IF($J17="","",ROUND($J17+$L17,2)) -> 180800.1 | N17: =IF($I17="","",SUMIFS(资金流水!$K$5:$K$3032,资金流水!$Q$5:$Q$3015,$I17)) | O17: 180800 | P17: =IF($J17="","",ROUND($M17-IF($N17="",0,$N17)-IF($O17="",0,$O17),2)) -> 0.1 | Q17: =IF($J17="","",IF($P17<=0.005,"已收齐",IF(IF($N17="",0,$N17)+IF($O17="",0,$O17)<=0,"未收款","部分收款"))) -> 部分收款 | R17: =IF($B17="","",--TEXT($B17,"yyyymm")) -> 202602 | S17: =IF(OR($B17="",$P17="",$P17<=0.005),"",TODAY()-$B17) -> 217
A18: =IF($B18="","",COUNTA($B$5:$B18)) -> 14 | B18: 46093 | C18: 双思威 | D18: =IFERROR(INDEX(基础资料!$C$4:$C$11,MATCH($C18,基础资料!$A$4:$A$11,0)),"") -> 一般纳税人 | E18: 增值税专用发票 | F18: 中国电信股份有限公司巴音郭楞蒙古自治州分公司 | G18: 中国电信巴州分公司2024年第二师铁门关市29团养殖基地监控部署及视频云存储项目 ]设备及相关服务采购合 | J18: 257180 | K18: 0.06 | L18: =IF($J18="","",ROUND($J18*$K18,2)) -> 15430.8 | M18: =IF($J18="","",ROUND($J18+$L18,2)) -> 272610.8 | N18: =IF($I18="","",SUMIFS(资金流水!$K$5:$K$3032,资金流水!$Q$5:$Q$3015,$I18)) | O18: 272610 | P18: =IF($J18="","",ROUND($M18-IF($N18="",0,$N18)-IF($O18="",0,$O18),2)) -> 0.8 | Q18: =IF($J18="","",IF($P18<=0.005,"已收齐",IF(IF($N18="",0,$N18)+IF($O18="",0,$O18)<=0,"未收款","部分收款"))) -> 部分收款 | R18: =IF($B18="","",--TEXT($B18,"yyyymm")) -> 202603 | S18: =IF(OR($B18="",$P18="",$P18<=0.005),"",TODAY()-$B18) -> 184
A19: =IF($B19="","",COUNTA($B$5:$B19)) -> 15 | B19: 46094 | C19: 双思威 | D19: =IFERROR(INDEX(基础资料!$C$4:$C$11,MATCH($C19,基础资料!$A$4:$A$11,0)),"") -> 一般纳税人 | E19: 增值税专用发票 | F19: 中国电信股份有限公司巴音郭楞蒙古自治州分公司 | G19: 中国电信巴州分公司2025年第二师GAJ视频监控平台、云集成服务项目设备及相关服务 | J19: 376000 | K19: 0.06 | L19: =IF($J19="","",ROUND($J19*$K19,2)) -> 22560 | M19: =IF($J19="","",ROUND($J19+$L19,2)) -> 398560 | N19: =IF($I19="","",SUMIFS(资金流水!$K$5:$K$3032,资金流水!$Q$5:$Q$3015,$I19)) | O19: 398560 | P19: =IF($J19="","",ROUND($M19-IF($N19="",0,$N19)-IF($O19="",0,$O19),2)) -> 0 | Q19: =IF($J19="","",IF($P19<=0.005,"已收齐",IF(IF($N19="",0,$N19)+IF($O19="",0,$O19)<=0,"未收款","部分收款"))) -> 已收齐 | R19: =IF($B19="","",--TEXT($B19,"yyyymm")) -> 202603 | S19: =IF(OR($B19="",$P19="",$P19<=0.005),"",TODAY()-$B19)
A20: =IF($B20="","",COUNTA($B$5:$B20)) -> 16 | B20: 46095 | C20: 双思威 | D20: =IFERROR(INDEX(基础资料!$C$4:$C$11,MATCH($C20,基础资料!$A$4:$A$11,0)),"") -> 一般纳税人 | E20: 增值税专用发票 | F20: 中电信数智科技有限公司昌吉分公司 | G20: 中电信数智科技有限公司昌吉分公司2025年某学校智慧教室建设项目 | J20: 168143.36 | K20: 0.13 | L20: =IF($J20="","",ROUND($J20*$K20,2)) -> 21858.64 | M20: =IF($J20="","",ROUND($J20+$L20,2)) -> 190002 | N20: =IF($I20="","",SUMIFS(资金流水!$K$5:$K$3032,资金流水!$Q$5:$Q$3015,$I20)) | O20: 190002 | P20: =IF($J20="","",ROUND($M20-IF($N20="",0,$N20)-IF($O20="",0,$O20),2)) -> 0 | Q20: =IF($J20="","",IF($P20<=0.005,"已收齐",IF(IF($N20="",0,$N20)+IF($O20="",0,$O20)<=0,"未收款","部分收款"))) -> 已收齐 | R20: =IF($B20="","",--TEXT($B20,"yyyymm")) -> 202603 | S20: =IF(OR($B20="",$P20="",$P20<=0.005),"",TODAY()-$B20)
A21: =IF($B21="","",COUNTA($B$5:$B21)) -> 17 | B21: 46098 | C21: 双思威 | D21: =IFERROR(INDEX(基础资料!$C$4:$C$11,MATCH($C21,基础资料!$A$4:$A$11,0)),"") -> 一般纳税人 | E21: 增值税专用发票 | F21: 中国电信股份有限公司巴音郭楞蒙古自治州分公司 | G21: 二师市民中心迎宾机器人（中国电信巴州分公司2025年第二师铁门关市公安局视频监控链路的设备采购项目） | J21: 242000 | K21: 0.13 | L21: =IF($J21="","",ROUND($J21*$K21,2)) -> 31460 | M21: =IF($J21="","",ROUND($J21+$L21,2)) -> 273460 | N21: =IF($I21="","",SUMIFS(资金流水!$K$5:$K$3032,资金流水!$Q$5:$Q$3015,$I21)) | O21: 273460 | P21: =IF($J21="","",ROUND($M21-IF($N21="",0,$N21)-IF($O21="",0,$O21),2)) -> 0 | Q21: =IF($J21="","",IF($P21<=0.005,"已收齐",IF(IF($N21="",0,$N21)+IF($O21="",0,$O21)<=0,"未收款","部分收款"))) -> 已收齐 | R21: =IF($B21="","",--TEXT($B21,"yyyymm")) -> 202603 | S21: =IF(OR($B21="",$P21="",$P21<=0.005),"",TODAY()-$B21)
A22: =IF($B22="","",COUNTA($B$5:$B22)) -> 18 | B22: 46092 | C22: 中展 | D22: =IFERROR(INDEX(基础资料!$C$4:$C$11,MATCH($C22,基础资料!$A$4:$A$11,0)),"") -> 小规模纳税人 | E22: 增值税普通发票 | F22: 库尔勒市库尔楚园艺场中学 | G22: 库尔楚计算机设备采购 | J22: 2913.84 | K22: 0.01 | L22: =IF($J22="","",ROUND($J22*$K22,2)) -> 29.14 | M22: =IF($J22="","",ROUND($J22+$L22,2)) -> 2942.98 | N22: =IF($I22="","",SUMIFS(资金流水!$K$5:$K$3032,资金流水!$Q$5:$Q$3015,$I22)) | O22: 2942.98 | P22: =IF($J22="","",ROUND($M22-IF($N22="",0,$N22)-IF($O22="",0,$O22),2)) -> 0 | Q22: =IF($J22="","",IF($P22<=0.005,"已收齐",IF(IF($N22="",0,$N22)+IF($O22="",0,$O22)<=0,"未收款","部分收款"))) -> 已收齐 | R22: =IF($B22="","",--TEXT($B22,"yyyymm")) -> 202603 | S22: =IF(OR($B22="",$P22="",$P22<=0.005),"",TODAY()-$B22)
A23: =IF($B23="","",COUNTA($B$5:$B23)) -> 19 | B23: 46092 | C23: 中展 | D23: =IFERROR(INDEX(基础资料!$C$4:$C$11,MATCH($C23,基础资料!$A$4:$A$11,0)),"") -> 小规模纳税人 | E23: 增值税普通发票 | F23: 库尔勒市库尔楚园艺场中学 | G23: 库尔楚计算机设备采购 | J23: 4963.37 | K23: 0.01 | L23: =IF($J23="","",ROUND($J23*$K23,2)) -> 49.63 | M23: =IF($J23="","",ROUND($J23+$L23,2)) -> 5013 | N23: =IF($I23="","",SUMIFS(资金流水!$K$5:$K$3032,资金流水!$Q$5:$Q$3015,$I23)) | O23: 5013 | P23: =IF($J23="","",ROUND($M23-IF($N23="",0,$N23)-IF($O23="",0,$O23),2)) -> 0 | Q23: =IF($J23="","",IF($P23<=0.005,"已收齐",IF(IF($N23="",0,$N23)+IF($O23="",0,$O23)<=0,"未收款","部分收款"))) -> 已收齐 | R23: =IF($B23="","",--TEXT($B23,"yyyymm")) -> 202603 | S23: =IF(OR($B23="",$P23="",$P23<=0.005),"",TODAY()-$B23)
A24: =IF($B24="","",COUNTA($B$5:$B24)) -> 20 | B24: 46098 | C24: 中展 | D24: =IFERROR(INDEX(基础资料!$C$4:$C$11,MATCH($C24,基础资料!$A$4:$A$11,0)),"") -> 小规模纳税人 | E24: 增值税普通发票 | F24: 昌吉市第十小学 | G24: 昌吉市第十小学智慧黑板 | J24: 42574.26 | K24: 0.01 | L24: =IF($J24="","",ROUND($J24*$K24,2)) -> 425.74 | M24: =IF($J24="","",ROUND($J24+$L24,2)) -> 43000 | N24: =IF($I24="","",SUMIFS(资金流水!$K$5:$K$3032,资金流水!$Q$5:$Q$3015,$I24)) | O24: 43000 | P24: =IF($J24="","",ROUND($M24-IF($N24="",0,$N24)-IF($O24="",0,$O24),2)) -> 0 | Q24: =IF($J24="","",IF($P24<=0.005,"已收齐",IF(IF($N24="",0,$N24)+IF($O24="",0,$O24)<=0,"未收款","部分收款"))) -> 已收齐 | R24: =IF($B24="","",--TEXT($B24,"yyyymm")) -> 202603 | S24: =IF(OR($B24="",$P24="",$P24<=0.005),"",TODAY()-$B24)
A25: =IF($B25="","",COUNTA($B$5:$B25)) -> 21 | B25: 46104 | C25: 中展 | D25: =IFERROR(INDEX(基础资料!$C$4:$C$11,MATCH($C25,基础资料!$A$4:$A$11,0)),"") -> 小规模纳税人 | E25: 增值税普通发票 | F25: 昌吉市第五中学 | G25: 昌吉市第五中学采购6台黑板 | J25: 127722.77 | K25: 0.01 | L25: =IF($J25="","",ROUND($J25*$K25,2)) -> 1277.23 | M25: =IF($J25="","",ROUND($J25+$L25,2)) -> 129000 | N25: =IF($I25="","",SUMIFS(资金流水!$K$5:$K$3032,资金流水!$Q$5:$Q$3015,$I25)) | O25: 129000 | P25: =IF($J25="","",ROUND($M25-IF($N25="",0,$N25)-IF($O25="",0,$O25),2)) -> 0 | Q25: =IF($J25="","",IF($P25<=0.005,"已收齐",IF(IF($N25="",0,$N25)+IF($O25="",0,$O25)<=0,"未收款","部分收款"))) -> 已收齐 | R25: =IF($B25="","",--TEXT($B25,"yyyymm")) -> 202603 | S25: =IF(OR($B25="",$P25="",$P25<=0.005),"",TODAY()-$B25)
A26: =IF($B26="","",COUNTA($B$5:$B26)) -> 22 | B26: 46108 | C26: 中展 | D26: =IFERROR(INDEX(基础资料!$C$4:$C$11,MATCH($C26,基础资料!$A$4:$A$11,0)),"") -> 小规模纳税人 | E26: 增值税普通发票 | F26: 昌吉市第十小学 | G26: 26年售后 | J26: 2732.67 | K26: 0.01 | L26: =IF($J26="","",ROUND($J26*$K26,2)) -> 27.33 | M26: =IF($J26="","",ROUND($J26+$L26,2)) -> 2760 | N26: =IF($I26="","",SUMIFS(资金流水!$K$5:$K$3032,资金流水!$Q$5:$Q$3015,$I26)) | O26: 2760 | P26: =IF($J26="","",ROUND($M26-IF($N26="",0,$N26)-IF($O26="",0,$O26),2)) -> 0 | Q26: =IF($J26="","",IF($P26<=0.005,"已收齐",IF(IF($N26="",0,$N26)+IF($O26="",0,$O26)<=0,"未收款","部分收款"))) -> 已收齐 | R26: =IF($B26="","",--TEXT($B26,"yyyymm")) -> 202603 | S26: =IF(OR($B26="",$P26="",$P26<=0.005),"",TODAY()-$B26)
A27: =IF($B27="","",COUNTA($B$5:$B27)) -> 23 | B27: 46121 | C27: 双思威 | D27: =IFERROR(INDEX(基础资料!$C$4:$C$11,MATCH($C27,基础资料!$A$4:$A$11,0)),"") -> 一般纳税人 | E27: 增值税专用发票 | F27: 新疆准东经济技术开发区管理委员会 | G27: 社管局准东学校三期实验楼设施设备配置项目（二次）追加 | J27: 406097.34 | K27: 0.13 | L27: =IF($J27="","",ROUND($J27*$K27,2)) -> 52792.65 | M27: =IF($J27="","",ROUND($J27+$L27,2)) -> 458889.99 | N27: =IF($I27="","",SUMIFS(资金流水!$K$5:$K$3032,资金流水!$Q$5:$Q$3015,$I27)) | O27: 458889.99 | P27: =IF($J27="","",ROUND($M27-IF($N27="",0,$N27)-IF($O27="",0,$O27),2)) -> 0 | Q27: =IF($J27="","",IF($P27<=0.005,"已收齐",IF(IF($N27="",0,$N27)+IF($O27="",0,$O27)<=0,"未收款","部分收款"))) -> 已收齐 | R27: =IF($B27="","",--TEXT($B27,"yyyymm")) -> 202604 | S27: =IF(OR($B27="",$P27="",$P27<=0.005),"",TODAY()-$B27)
... A29: =IF($B29="","",COUNTA($B$5:$B29)) -> 25 | B29: 46126 | C29: 双思威 | D29: =IFERROR(INDEX(基础资料!$C$4:$C$11,MATCH($C29,基础资料!$A$4:$A$11,0)),"") -> 一般纳税人 | E29: 增值税专用发票 | F29: 中国电信股份有限公司巴音郭楞蒙古自治州分公司 | G29: 第二师铁门关信息技术服务中心租赁云服务资源采购项目技术服务合同 | J29: 330000 | K29: 0.06 | L29: =IF($J29="","",ROUND($J29*$K29,2)) -> 19800 | M29: =IF($J29="","",ROUND($J29+$L29,2)) -> 349800 | N29: =IF($I29="","",SUMIFS(资金流水!$K$5:$K$3032,资金流水!$Q$5:$Q$3015,$I29)) | O29: 349800 | P29: =IF($J29="","",ROUND($M29-IF($N29="",0,$N29)-IF($O29="",0,$O29),2)) -> 0 | Q29: =IF($J29="","",IF($P29<=0.005,"已收齐",IF(IF($N29="",0,$N29)+IF($O29="",0,$O29)<=0,"未收款","部分收款"))) -> 已收齐 | R29: =IF($B29="","",--TEXT($B29,"yyyymm")) -> 202604 | S29: =IF(OR($B29="",$P29="",$P29<=0.005),"",TODAY()-$B29)
A30: =IF($B30="","",COUNTA($B$5:$B30)) -> 26 | B30: 46126 | C30: 双思威 | D30: =IFERROR(INDEX(基础资料!$C$4:$C$11,MATCH($C30,基础资料!$A$4:$A$11,0)),"") -> 一般纳税人 | E30: 增值税专用发票 | F30: 中国电信股份有限公司巴音郭楞蒙古自治州分公司 | G30: 中国电信股份有限公司巴州分公司2026年铁门关市民中心视频汇聚改造提升项目 | J30: 142000 | K30: 0.13 | L30: =IF($J30="","",ROUND($J30*$K30,2)) -> 18460 | M30: =IF($J30="","",ROUND($J30+$L30,2)) -> 160460 | N30: =IF($I30="","",SUMIFS(资金流水!$K$5:$K$3032,资金流水!$Q$5:$Q$3015,$I30)) | P30: =IF($J30="","",ROUND($M30-IF($N30="",0,$N30)-IF($O30="",0,$O30),2)) -> 160460 | Q30: =IF($J30="","",IF($P30<=0.005,"已收齐",IF(IF($N30="",0,$N30)+IF($O30="",0,$O30)<=0,"未收款","部分收款"))) -> 未收款 | R30: =IF($B30="","",--TEXT($B30,"yyyymm")) -> 202604 | S30: =IF(OR($B30="",$P30="",$P30<=0.005),"",TODAY()-$B30) -> 151
A31: =IF($B31="","",COUNTA($B$5:$B31)) -> 27 | B31: 46126 | C31: 双思威 | D31: =IFERROR(INDEX(基础资料!$C$4:$C$11,MATCH($C31,基础资料!$A$4:$A$11,0)),"") -> 一般纳税人 | E31: 增值税专用发票 | F31: 中国电信股份有限公司巴音郭楞蒙古自治州分公司 | G31: 中国电信股份有限公司巴州分公司2026年铁门关市民中心视频汇聚改造提升项目 | J31: 117831.13 | K31: 0.06 | L31: =IF($J31="","",ROUND($J31*$K31,2)) -> 7069.87 | M31: =IF($J31="","",ROUND($J31+$L31,2)) -> 124901 | N31: =IF($I31="","",SUMIFS(资金流水!$K$5:$K$3032,资金流水!$Q$5:$Q$3015,$I31)) | O31: 124901 | P31: =IF($J31="","",ROUND($M31-IF($N31="",0,$N31)-IF($O31="",0,$O31),2)) -> 0 | Q31: =IF($J31="","",IF($P31<=0.005,"已收齐",IF(IF($N31="",0,$N31)+IF($O31="",0,$O31)<=0,"未收款","部分收款"))) -> 已收齐 | R31: =IF($B31="","",--TEXT($B31,"yyyymm")) -> 202604 | S31: =IF(OR($B31="",$P31="",$P31<=0.005),"",TODAY()-$B31)
A32: =IF($B32="","",COUNTA($B$5:$B32)) -> 28 | B32: 46132 | C32: 双思威 | D32: =IFERROR(INDEX(基础资料!$C$4:$C$11,MATCH($C32,基础资料!$A$4:$A$11,0)),"") -> 一般纳税人 | E32: 增值税专用发票 | F32: 中电信数智科技有限公司巴音郭楞蒙 古自治州分公司 | G32: 中电信数智巴州分公司 2026 年铁门关经济技术开发区化工园区周界防护 | J32: 621592.92 | K32: 0.13 | L32: =IF($J32="","",ROUND($J32*$K32,2)) -> 80807.08 | M32: =IF($J32="","",ROUND($J32+$L32,2)) -> 702400 | N32: =IF($I32="","",SUMIFS(资金流水!$K$5:$K$3032,资金流水!$Q$5:$Q$3015,$I32)) | O32: 702400 | P32: =IF($J32="","",ROUND($M32-IF($N32="",0,$N32)-IF($O32="",0,$O32),2)) -> 0 | Q32: =IF($J32="","",IF($P32<=0.005,"已收齐",IF(IF($N32="",0,$N32)+IF($O32="",0,$O32)<=0,"未收款","部分收款"))) -> 已收齐 | R32: =IF($B32="","",--TEXT($B32,"yyyymm")) -> 202604 | S32: =IF(OR($B32="",$P32="",$P32<=0.005),"",TODAY()-$B32)
A33: =IF($B33="","",COUNTA($B$5:$B33)) -> 29 | B33: 46132 | C33: 双思威 | D33: =IFERROR(INDEX(基础资料!$C$4:$C$11,MATCH($C33,基础资料!$A$4:$A$11,0)),"") -> 一般纳税人 | E33: 增值税专用发票 | F33: 中电信数智科技有限公司巴音郭楞蒙 古自治州分公司 | G33: 项目采购项目]设备及相关服务采购合同 | J33: 245283.02 | K33: 0.06 | L33: =IF($J33="","",ROUND($J33*$K33,2)) -> 14716.98 | M33: =IF($J33="","",ROUND($J33+$L33,2)) -> 260000 | N33: =IF($I33="","",SUMIFS(资金流水!$K$5:$K$3032,资金流水!$Q$5:$Q$3015,$I33)) | O33: 260000 | P33: =IF($J33="","",ROUND($M33-IF($N33="",0,$N33)-IF($O33="",0,$O33),2)) -> 0 | Q33: =IF($J33="","",IF($P33<=0.005,"已收齐",IF(IF($N33="",0,$N33)+IF($O33="",0,$O33)<=0,"未收款","部分收款"))) -> 已收齐 | R33: =IF($B33="","",--TEXT($B33,"yyyymm")) -> 202604 | S33: =IF(OR($B33="",$P33="",$P33<=0.005),"",TODAY()-$B33)
A34: =IF($B34="","",COUNTA($B$5:$B34)) -> 30 | B34: 46134 | C34: 中展 | D34: =IFERROR(INDEX(基础资料!$C$4:$C$11,MATCH($C34,基础资料!$A$4:$A$11,0)),"") -> 小规模纳税人 | E34: 增值税普通发票 | F34: 玛纳斯县第一中学 | J34: 5445.54 | K34: 0.01 | L34: =IF($J34="","",ROUND($J34*$K34,2)) -> 54.46 | M34: =IF($J34="","",ROUND($J34+$L34,2)) -> 5500 | N34: =IF($I34="","",SUMIFS(资金流水!$K$5:$K$3032,资金流水!$Q$5:$Q$3015,$I34)) | O34: 5500 | P34: =IF($J34="","",ROUND($M34-IF($N34="",0,$N34)-IF($O34="",0,$O34),2)) -> 0 | Q34: =IF($J34="","",IF($P34<=0.005,"已收齐",IF(IF($N34="",0,$N34)+IF($O34="",0,$O34)<=0,"未收款","部分收款"))) -> 已收齐 | R34: =IF($B34="","",--TEXT($B34,"yyyymm")) -> 202604 | S34: =IF(OR($B34="",$P34="",$P34<=0.005),"",TODAY()-$B34)
A35: =IF($B35="","",COUNTA($B$5:$B35)) -> 31 | B35: 46134 | C35: 中展 | D35: =IFERROR(INDEX(基础资料!$C$4:$C$11,MATCH($C35,基础资料!$A$4:$A$11,0)),"") -> 小规模纳税人 | E35: 增值税普通发票 | F35: 玛纳斯县第一中学 | J35: 2277.23 | K35: 0.01 | L35: =IF($J35="","",ROUND($J35*$K35,2)) -> 22.77 | M35: =IF($J35="","",ROUND($J35+$L35,2)) -> 2300 | N35: =IF($I35="","",SUMIFS(资金流水!$K$5:$K$3032,资金流水!$Q$5:$Q$3015,$I35)) | O35: 2300 | P35: =IF($J35="","",ROUND($M35-IF($N35="",0,$N35)-IF($O35="",0,$O35),2)) -> 0 | Q35: =IF($J35="","",IF($P35<=0.005,"已收齐",IF(IF($N35="",0,$N35)+IF($O35="",0,$O35)<=0,"未收款","部分收款"))) -> 已收齐 | R35: =IF($B35="","",--TEXT($B35,"yyyymm")) -> 202604 | S35: =IF(OR($B35="",$P35="",$P35<=0.005),"",TODAY()-$B35)
A36: =IF($B36="","",COUNTA($B$5:$B36)) -> 32 | B36: 46134 | C36: 中展 | D36: =IFERROR(INDEX(基础资料!$C$4:$C$11,MATCH($C36,基础资料!$A$4:$A$11,0)),"") -> 小规模纳税人 | E36: 增值税普通发票 | F36: 昌吉市第十四小学 | G36: 昌吉市第十四小学项目新项目没有项目名称 | J36: 25346.53 | K36: 0.01 | L36: =IF($J36="","",ROUND($J36*$K36,2)) -> 253.47 | M36: =IF($J36="","",ROUND($J36+$L36,2)) -> 25600 | N36: =IF($I36="","",SUMIFS(资金流水!$K$5:$K$3032,资金流水!$Q$5:$Q$3015,$I36)) | O36: 25600 | P36: =IF($J36="","",ROUND($M36-IF($N36="",0,$N36)-IF($O36="",0,$O36),2)) -> 0 | Q36: =IF($J36="","",IF($P36<=0.005,"已收齐",IF(IF($N36="",0,$N36)+IF($O36="",0,$O36)<=0,"未收款","部分收款"))) -> 已收齐 | R36: =IF($B36="","",--TEXT($B36,"yyyymm")) -> 202604 | S36: =IF(OR($B36="",$P36="",$P36<=0.005),"",TODAY()-$B36)
A37: =IF($B37="","",COUNTA($B$5:$B37)) -> 33 | B37: 46140 | C37: 中展 | D37: =IFERROR(INDEX(基础资料!$C$4:$C$11,MATCH($C37,基础资料!$A$4:$A$11,0)),"") -> 小规模纳税人 | E37: 增值税普通发票 | F37: 昌吉市第三幼儿园（陈垒） | G37: 昌吉市第三幼儿园（二十幼）厨房设备采购项目 | J37: 24752.48 | K37: 0.01 | L37: =IF($J37="","",ROUND($J37*$K37,2)) -> 247.52 | M37: =IF($J37="","",ROUND($J37+$L37,2)) -> 25000 | N37: =IF($I37="","",SUMIFS(资金流水!$K$5:$K$3032,资金流水!$Q$5:$Q$3015,$I37)) | O37: 25000 | P37: =IF($J37="","",ROUND($M37-IF($N37="",0,$N37)-IF($O37="",0,$O37),2)) -> 0 | Q37: =IF($J37="","",IF($P37<=0.005,"已收齐",IF(IF($N37="",0,$N37)+IF($O37="",0,$O37)<=0,"未收款","部分收款"))) -> 已收齐 | R37: =IF($B37="","",--TEXT($B37,"yyyymm")) -> 202604 | S37: =IF(OR($B37="",$P37="",$P37<=0.005),"",TODAY()-$B37)
A38: =IF($B38="","",COUNTA($B$5:$B38)) -> 34 | B38: 46141 | C38: 中展 | D38: =IFERROR(INDEX(基础资料!$C$4:$C$11,MATCH($C38,基础资料!$A$4:$A$11,0)),"") -> 小规模纳税人 | E38: 增值税普通发票 | F38: 昌吉市第五幼儿园 | G38: 昌吉市南安幼儿园设备采购项目 | J38: 19801.98 | K38: 0.01 | L38: =IF($J38="","",ROUND($J38*$K38,2)) -> 198.02 | M38: =IF($J38="","",ROUND($J38+$L38,2)) -> 20000 | N38: =IF($I38="","",SUMIFS(资金流水!$K$5:$K$3032,资金流水!$Q$5:$Q$3015,$I38)) | O38: 20000 | P38: =IF($J38="","",ROUND($M38-IF($N38="",0,$N38)-IF($O38="",0,$O38),2)) -> 0 | Q38: =IF($J38="","",IF($P38<=0.005,"已收齐",IF(IF($N38="",0,$N38)+IF($O38="",0,$O38)<=0,"未收款","部分收款"))) -> 已收齐 | R38: =IF($B38="","",--TEXT($B38,"yyyymm")) -> 202604 | S38: =IF(OR($B38="",$P38="",$P38<=0.005),"",TODAY()-$B38)
A39: =IF($B39="","",COUNTA($B$5:$B39)) -> 35 | B39: 46150 | C39: 双思威 | D39: =IFERROR(INDEX(基础资料!$C$4:$C$11,MATCH($C39,基础资料!$A$4:$A$11,0)),"") -> 一般纳税人 | E39: 增值税专用发票 | F39: 昌吉市教育局 | G39: 昌吉市十七小学教学设备采购项目 | J39: 1135398.2 | K39: 0.13 | L39: =IF($J39="","",ROUND($J39*$K39,2)) -> 147601.77 | M39: =IF($J39="","",ROUND($J39+$L39,2)) -> 1283000 | N39: =IF($I39="","",SUMIFS(资金流水!$K$5:$K$3032,资金流水!$Q$5:$Q$3015,$I39)) | O39: 1283000 | P39: =IF($J39="","",ROUND($M39-IF($N39="",0,$N39)-IF($O39="",0,$O39),2)) -> 0 | Q39: =IF($J39="","",IF($P39<=0.005,"已收齐",IF(IF($N39="",0,$N39)+IF($O39="",0,$O39)<=0,"未收款","部分收款"))) -> 已收齐 | R39: =IF($B39="","",--TEXT($B39,"yyyymm")) -> 202605 | S39: =IF(OR($B39="",$P39="",$P39<=0.005),"",TODAY()-$B39)
A40: =IF($B40="","",COUNTA($B$5:$B40)) -> 36 | B40: 46162 | C40: 双思威 | D40: =IFERROR(INDEX(基础资料!$C$4:$C$11,MATCH($C40,基础资料!$A$4:$A$11,0)),"") -> 一般纳税人 | E40: 增值税专用发票 | F40: 新疆准东经济技术开发区管理委员会 | G40: :社管局准东学校三期实验楼设施设备配置项目(二次) | J40: 4141829.9 | K40: 0.13 | L40: =IF($J40="","",ROUND($J40*$K40,2)) -> 538437.89 | M40: =IF($J40="","",ROUND($J40+$L40,2)) -> 4680267.8 | N40: =IF($I40="","",SUMIFS(资金流水!$K$5:$K$3032,资金流水!$Q$5:$Q$3015,$I40)) | O40: 4680267.8 | P40: =IF($J40="","",ROUND($M40-IF($N40="",0,$N40)-IF($O40="",0,$O40),2)) -> 0 | Q40: =IF($J40="","",IF($P40<=0.005,"已收齐",IF(IF($N40="",0,$N40)+IF($O40="",0,$O40)<=0,"未收款","部分收款"))) -> 已收齐 | R40: =IF($B40="","",--TEXT($B40,"yyyymm")) -> 202605 | S40: =IF(OR($B40="",$P40="",$P40<=0.005),"",TODAY()-$B40)
A41: =IF($B41="","",COUNTA($B$5:$B41)) -> 37 | B41: 46148 | C41: 元界极光 | D41: =IFERROR(INDEX(基础资料!$C$4:$C$11,MATCH($C41,基础资料!$A$4:$A$11,0)),"") -> 小规模纳税人 | E41: 增值税普通发票 | F41: 昌吉市第七小学 | G41: 昌吉市第七小学润苗楼教室文化墙、图书角及会议室项目 | J41: 160539.42 | K41: 0.01 | L41: =IF($J41="","",ROUND($J41*$K41,2)) -> 1605.39 | M41: =IF($J41="","",ROUND($J41+$L41,2)) -> 162144.81 | N41: =IF($I41="","",SUMIFS(资金流水!$K$5:$K$3032,资金流水!$Q$5:$Q$3015,$I41)) | O41: 162144.81 | P41: =IF($J41="","",ROUND($M41-IF($N41="",0,$N41)-IF($O41="",0,$O41),2)) -> 0 | Q41: =IF($J41="","",IF($P41<=0.005,"已收齐",IF(IF($N41="",0,$N41)+IF($O41="",0,$O41)<=0,"未收款","部分收款"))) -> 已收齐 | R41: =IF($B41="","",--TEXT($B41,"yyyymm")) -> 202605 | S41: =IF(OR($B41="",$P41="",$P41<=0.005),"",TODAY()-$B41)
...

Sheet 资金流水
A1: 资金流水台账 — 全部公司 / 全部账户，只在这一张表录一遍
A2: 资金总余额(随筛选) | C2: =$M$2+$K$2-$L$2 -> 1.8048975e+09 | D2: 跨期笔数 | F2: =COUNTIF($U$5:$U$3015,"跨期") -> 2 | G2: 已录笔数 | I2: =COUNT($B$5:$B$3032) -> 673 | J2: 筛选后合计→ | K2: =SUBTOTAL(109,$K$5:$K$3032) -> 15241709 | L2: =SUBTOTAL(109,$L$5:$L$3032) -> 9937223.2 | M2: =SUBTOTAL(109,$M$5:$M$3015) -> 1.799593e+09
A3: 录入规则：①每笔银行流水一行，收入填K列、支出填L列（不要同时填）。②每个账户开账时录一行“期初余额”，收支类型选“期初余额”、金额填M列。③项目类收支必须选“项目名称”；支出属于项目成本的填H列成本类别，属于日常费用/税金的填I列费用类别。④跨期业务（如收到去年项目的尾款）在P列填业务归属月(如202512)，留空默认按发生月。⑤与发票或应收应付挂钩的，在Q列填同一个“关联单号”即可自动核销。灰色S~X列是自动计算，请勿手输。
A4: 序号 | B4: 日期 | C4: 账户 | D4: 公司(自动) | E4: 收支类型 | F4: 项目名称 | G4: 收入类别 | H4: 成本类别 | I4: 费用类别 | J4: 摘要内容 | K4: 收入金额 | L4: 支出金额 | M4: 余额 | N4: 客户 | O4: 供应商 | P4: 业务归属月 (跨期时填) | Q4: 关联单号 (发票号/往来号) | R4: 备注 | S4: 发生月 | T4: 归属月 | U4: 跨期 | V4: 项目行号 | W4: 支出大类 | X4: 收入大类
A5: =IF($B5="","",COUNTA($B$5:$B5)) -> 1 | B5: 46023 | C5: 双思威基本户 | D5: =IFERROR(INDEX(基础资料!$F$4:$F$23,MATCH($C5,基础资料!$E$4:$E$23,0)),IF($C5="","","未匹配账户")) -> 双思威 | E5: 期初余额 | J5: 期初余额 | M5: 857870.23 | R5: ★请填入该账户实际期初余额 | S5: =IF($B5="","",--TEXT($B5,"yyyymm")) -> 202601 | T5: =IF($B5="","",IF($P5="",$S5,IFERROR($P5*1,$P5))) -> 202601 | U5: =IF($B5="","",IF($T5=$S5,"","跨期")) | V5: =IF(AND($B5<>"",$F5<>"",$F5=项目明细账!$C$2),N(V4)+1,N(V4)) -> 0 | W5: =IF($H5<>"","项目成本",IFERROR(INDEX(基础资料!$W$4:$W$49,MATCH($I5,基础资料!$V$4:$V$49,0)),"")) | X5: =IFERROR(INDEX(基础资料!$R$4:$R$17,MATCH($G5,基础资料!$Q$4:$Q$17,0)),"")
A6: =IF($B6="","",COUNTA($B$5:$B6)) -> 2 | B6: 46023 | C6: 双思威农商行一般户 | D6: =IFERROR(INDEX(基础资料!$F$4:$F$23,MATCH($C6,基础资料!$E$4:$E$23,0)),IF($C6="","","未匹配账户")) -> 双思威 | E6: 期初余额 | J6: 期初余额 | M6: 996321.15 | R6: ★请填入该账户实际期初余额 | S6: =IF($B6="","",--TEXT($B6,"yyyymm")) -> 202601 | T6: =IF($B6="","",IF($P6="",$S6,IFERROR($P6*1,$P6))) -> 202601 | U6: =IF($B6="","",IF($T6=$S6,"","跨期")) | V6: =IF(AND($B6<>"",$F6<>"",$F6=项目明细账!$C$2),N(V5)+1,N(V5)) -> 0 | W6: =IF($H6<>"","项目成本",IFERROR(INDEX(基础资料!$W$4:$W$49,MATCH($I6,基础资料!$V$4:$V$49,0)),"")) | X6: =IFERROR(INDEX(基础资料!$R$4:$R$17,MATCH($G6,基础资料!$Q$4:$Q$17,0)),"")
A7: =IF($B7="","",COUNTA($B$5:$B7)) -> 3 | B7: 46023 | C7: 晨拓农商行基本户 | D7: =IFERROR(INDEX(基础资料!$F$4:$F$23,MATCH($C7,基础资料!$E$4:$E$23,0)),IF($C7="","","未匹配账户")) -> 晨拓 | E7: 期初余额 | J7: 期初余额 | M7: 1695593.5 | R7: ★请填入该账户实际期初余额 | S7: =IF($B7="","",--TEXT($B7,"yyyymm")) -> 202601 | T7: =IF($B7="","",IF($P7="",$S7,IFERROR($P7*1,$P7))) -> 202601 | U7: =IF($B7="","",IF($T7=$S7,"","跨期")) | V7: =IF(AND($B7<>"",$F7<>"",$F7=项目明细账!$C$2),N(V6)+1,N(V6)) -> 0 | W7: =IF($H7<>"","项目成本",IFERROR(INDEX(基础资料!$W$4:$W$49,MATCH($I7,基础资料!$V$4:$V$49,0)),"")) | X7: =IFERROR(INDEX(基础资料!$R$4:$R$17,MATCH($G7,基础资料!$Q$4:$Q$17,0)),"")
A8: =IF($B8="","",COUNTA($B$5:$B8)) -> 4 | B8: 46023 | C8: 元界极光中行基本户 | D8: =IFERROR(INDEX(基础资料!$F$4:$F$23,MATCH($C8,基础资料!$E$4:$E$23,0)),IF($C8="","","未匹配账户")) -> 元界极光 | E8: 期初余额 | J8: 期初余额 | M8: 450747.19 | R8: ★请填入该账户实际期初余额 | S8: =IF($B8="","",--TEXT($B8,"yyyymm")) -> 202601 | T8: =IF($B8="","",IF($P8="",$S8,IFERROR($P8*1,$P8))) -> 202601 | U8: =IF($B8="","",IF($T8=$S8,"","跨期")) | V8: =IF(AND($B8<>"",$F8<>"",$F8=项目明细账!$C$2),N(V7)+1,N(V7)) -> 0 | W8: =IF($H8<>"","项目成本",IFERROR(INDEX(基础资料!$W$4:$W$49,MATCH($I8,基础资料!$V$4:$V$49,0)),"")) | X8: =IFERROR(INDEX(基础资料!$R$4:$R$17,MATCH($G8,基础资料!$Q$4:$Q$17,0)),"")
A9: =IF($B9="","",COUNTA($B$5:$B9)) -> 5 | B9: 46023 | C9: 元界极光农商行一般户 | D9: =IFERROR(INDEX(基础资料!$F$4:$F$23,MATCH($C9,基础资料!$E$4:$E$23,0)),IF($C9="","","未匹配账户")) -> 元界极光 | E9: 期初余额 | J9: 期初余额 | M9: 200010.67 | R9: ★请填入该账户实际期初余额 | S9: =IF($B9="","",--TEXT($B9,"yyyymm")) -> 202601 | T9: =IF($B9="","",IF($P9="",$S9,IFERROR($P9*1,$P9))) -> 202601 | U9: =IF($B9="","",IF($T9=$S9,"","跨期")) | V9: =IF(AND($B9<>"",$F9<>"",$F9=项目明细账!$C$2),N(V8)+1,N(V8)) -> 0 | W9: =IF($H9<>"","项目成本",IFERROR(INDEX(基础资料!$W$4:$W$49,MATCH($I9,基础资料!$V$4:$V$49,0)),"")) | X9: =IFERROR(INDEX(基础资料!$R$4:$R$17,MATCH($G9,基础资料!$Q$4:$Q$17,0)),"")
A10: =IF($B10="","",COUNTA($B$5:$B10)) -> 6 | B10: 46023 | C10: 瑞盛天中行基本户 | D10: =IFERROR(INDEX(基础资料!$F$4:$F$23,MATCH($C10,基础资料!$E$4:$E$23,0)),IF($C10="","","未匹配账户")) -> 瑞盛天 | E10: 期初余额 | J10: 期初余额 | M10: 1332384.2 | R10: ★请填入该账户实际期初余额 | S10: =IF($B10="","",--TEXT($B10,"yyyymm")) -> 202601 | T10: =IF($B10="","",IF($P10="",$S10,IFERROR($P10*1,$P10))) -> 202601 | U10: =IF($B10="","",IF($T10=$S10,"","跨期")) | V10: =IF(AND($B10<>"",$F10<>"",$F10=项目明细账!$C$2),N(V9)+1,N(V9)) -> 0 | W10: =IF($H10<>"","项目成本",IFERROR(INDEX(基础资料!$W$4:$W$49,MATCH($I10,基础资料!$V$4:$V$49,0)),"")) | X10: =IFERROR(INDEX(基础资料!$R$4:$R$17,MATCH($G10,基础资料!$Q$4:$Q$17,0)),"")
A11: =IF($B11="","",COUNTA($B$5:$B11)) -> 7 | B11: 46023 | C11: 瑞盛天农商行一般户 | D11: =IFERROR(INDEX(基础资料!$F$4:$F$23,MATCH($C11,基础资料!$E$4:$E$23,0)),IF($C11="","","未匹配账户")) -> 瑞盛天 | E11: 期初余额 | J11: 期初余额 | M11: 201465.55 | R11: ★请填入该账户实际期初余额 | S11: =IF($B11="","",--TEXT($B11,"yyyymm")) -> 202601 | T11: =IF($B11="","",IF($P11="",$S11,IFERROR($P11*1,$P11))) -> 202601 | U11: =IF($B11="","",IF($T11=$S11,"","跨期")) | V11: =IF(AND($B11<>"",$F11<>"",$F11=项目明细账!$C$2),N(V10)+1,N(V10)) -> 0 | W11: =IF($H11<>"","项目成本",IFERROR(INDEX(基础资料!$W$4:$W$49,MATCH($I11,基础资料!$V$4:$V$49,0)),"")) | X11: =IFERROR(INDEX(基础资料!$R$4:$R$17,MATCH($G11,基础资料!$Q$4:$Q$17,0)),"")
A12: =IF($B12="","",COUNTA($B$5:$B12)) -> 8 | B12: 46023 | C12: 中展中行基本户 | D12: =IFERROR(INDEX(基础资料!$F$4:$F$23,MATCH($C12,基础资料!$E$4:$E$23,0)),IF($C12="","","未匹配账户")) -> 中展 | E12: 期初余额 | J12: 期初余额 | M12: 237547.75 | R12: ★请填入该账户实际期初余额 | S12: =IF($B12="","",--TEXT($B12,"yyyymm")) -> 202601 | T12: =IF($B12="","",IF($P12="",$S12,IFERROR($P12*1,$P12))) -> 202601 | U12: =IF($B12="","",IF($T12=$S12,"","跨期")) | V12: =IF(AND($B12<>"",$F12<>"",$F12=项目明细账!$C$2),N(V11)+1,N(V11)) -> 0 | W12: =IF($H12<>"","项目成本",IFERROR(INDEX(基础资料!$W$4:$W$49,MATCH($I12,基础资料!$V$4:$V$49,0)),"")) | X12: =IFERROR(INDEX(基础资料!$R$4:$R$17,MATCH($G12,基础资料!$Q$4:$Q$17,0)),"")
A13: =IF($B13="","",COUNTA($B$5:$B13)) -> 9 | B13: 46050 | C13: 中展农商行一般户 | D13: =IFERROR(INDEX(基础资料!$F$4:$F$23,MATCH($C13,基础资料!$E$4:$E$23,0)),IF($C13="","","未匹配账户")) -> 中展 | E13: 期初余额 | J13: 期初余额 | M13: 100000 | R13: ★请填入该账户实际期初余额 | S13: =IF($B13="","",--TEXT($B13,"yyyymm")) -> 202601 | T13: =IF($B13="","",IF($P13="",$S13,IFERROR($P13*1,$P13))) -> 202601 | U13: =IF($B13="","",IF($T13=$S13,"","跨期")) | V13: =IF(AND($B13<>"",$F13<>"",$F13=项目明细账!$C$2),N(V12)+1,N(V12)) -> 0 | W13: =IF($H13<>"","项目成本",IFERROR(INDEX(基础资料!$W$4:$W$49,MATCH($I13,基础资料!$V$4:$V$49,0)),"")) | X13: =IFERROR(INDEX(基础资料!$R$4:$R$17,MATCH($G13,基础资料!$Q$4:$Q$17,0)),"")
A14: =IF($B14="","",COUNTA($B$5:$B14)) -> 10 | B14: 46023 | C14: 卓卓通农商行基本户 | D14: =IFERROR(INDEX(基础资料!$F$4:$F$23,MATCH($C14,基础资料!$E$4:$E$23,0)),IF($C14="","","未匹配账户")) -> 卓卓通 | E14: 期初余额 | J14: 期初余额 | M14: 283669.65 | R14: ★请填入该账户实际期初余额 | S14: =IF($B14="","",--TEXT($B14,"yyyymm")) -> 202601 | T14: =IF($B14="","",IF($P14="",$S14,IFERROR($P14*1,$P14))) -> 202601 | U14: =IF($B14="","",IF($T14=$S14,"","跨期")) | V14: =IF(AND($B14<>"",$F14<>"",$F14=项目明细账!$C$2),N(V13)+1,N(V13)) -> 0 | W14: =IF($H14<>"","项目成本",IFERROR(INDEX(基础资料!$W$4:$W$49,MATCH($I14,基础资料!$V$4:$V$49,0)),"")) | X14: =IFERROR(INDEX(基础资料!$R$4:$R$17,MATCH($G14,基础资料!$Q$4:$Q$17,0)),"")
A15: =IF($B15="","",COUNTA($B$5:$B15)) -> 11 | B15: 46023 | C15: 财兴通农商行基本户 | D15: =IFERROR(INDEX(基础资料!$F$4:$F$23,MATCH($C15,基础资料!$E$4:$E$23,0)),IF($C15="","","未匹配账户")) -> 财兴通 | E15: 期初余额 | J15: 期初余额 | M15: 174172.53 | R15: ★请填入该账户实际期初余额 | S15: =IF($B15="","",--TEXT($B15,"yyyymm")) -> 202601 | T15: =IF($B15="","",IF($P15="",$S15,IFERROR($P15*1,$P15))) -> 202601 | U15: =IF($B15="","",IF($T15=$S15,"","跨期")) | V15: =IF(AND($B15<>"",$F15<>"",$F15=项目明细账!$C$2),N(V14)+1,N(V14)) -> 0 | W15: =IF($H15<>"","项目成本",IFERROR(INDEX(基础资料!$W$4:$W$49,MATCH($I15,基础资料!$V$4:$V$49,0)),"")) | X15: =IFERROR(INDEX(基础资料!$R$4:$R$17,MATCH($G15,基础资料!$Q$4:$Q$17,0)),"")
A16: =IF($B16="","",COUNTA($B$5:$B16)) -> 12 | B16: 46023 | C16: 鑫海特工行基本户 | D16: =IFERROR(INDEX(基础资料!$F$4:$F$23,MATCH($C16,基础资料!$E$4:$E$23,0)),IF($C16="","","未匹配账户")) -> 鑫海特 | E16: 期初余额 | J16: 期初余额 | M16: 3110.37 | R16: ★请填入该账户实际期初余额 | S16: =IF($B16="","",--TEXT($B16,"yyyymm")) -> 202601 | T16: =IF($B16="","",IF($P16="",$S16,IFERROR($P16*1,$P16))) -> 202601 | U16: =IF($B16="","",IF($T16=$S16,"","跨期")) | V16: =IF(AND($B16<>"",$F16<>"",$F16=项目明细账!$C$2),N(V15)+1,N(V15)) -> 0 | W16: =IF($H16<>"","项目成本",IFERROR(INDEX(基础资料!$W$4:$W$49,MATCH($I16,基础资料!$V$4:$V$49,0)),"")) | X16: =IFERROR(INDEX(基础资料!$R$4:$R$17,MATCH($G16,基础资料!$Q$4:$Q$17,0)),"")
... A24: =IF($B24="","",COUNTA($B$5:$B24)) -> 20 | B24: 46023 | C24: 备用10 | D24: =IFERROR(INDEX(基础资料!$F$4:$F$23,MATCH($C24,基础资料!$E$4:$E$23,0)),IF($C24="","","未匹配账户")) -> 0 | E24: 期初余额 | J24: 期初余额 | M24: 0 | R24: ★请填入该账户实际期初余额 | S24: =IF($B24="","",--TEXT($B24,"yyyymm")) -> 202601 | T24: =IF($B24="","",IF($P24="",$S24,IFERROR($P24*1,$P24))) -> 202601 | U24: =IF($B24="","",IF($T24=$S24,"","跨期")) | V24: =IF(AND($B24<>"",$F24<>"",$F24=项目明细账!$C$2),N(V23)+1,N(V23)) -> 0 | W24: =IF($H24<>"","项目成本",IFERROR(INDEX(基础资料!$W$4:$W$49,MATCH($I24,基础资料!$V$4:$V$49,0)),"")) | X24: =IFERROR(INDEX(基础资料!$R$4:$R$17,MATCH($G24,基础资料!$Q$4:$Q$17,0)),"")
A25: =IF($B25="","",COUNTA($B$5:$B25)) -> 21 | B25: 46023 | C25: 双思威基本户 | D25: =IFERROR(INDEX(基础资料!$F$4:$F$23,MATCH($C25,基础资料!$E$4:$E$23,0)),IF($C25="","","未匹配账户")) -> 双思威 | E25: 收入 | F25: 第二师铁门关市武安街消防站改造项目 | G25: 项目收入 | J25: 收中国电信股份有限公司新疆分公司货款 | K25: 286729.93 | M25: =IFERROR(VLOOKUP($C25,$C$5:$M$24,11,0)+SUMIF($C$25:$C25,$C25,$K$25:$K25)-SUMIF($C$25:$C25,$C25,$L$25:$L25),"") -> 1144600.2 | R25: 示例：由2026年6月原表导入 | S25: =IF($B25="","",--TEXT($B25,"yyyymm")) -> 202601 | T25: =IF($B25="","",IF($P25="",$S25,IFERROR($P25*1,$P25))) -> 202601 | U25: =IF($B25="","",IF($T25=$S25,"","跨期")) | V25: =IF(AND($B25<>"",$F25<>"",$F25=项目明细账!$C$2),N(V24)+1,N(V24)) -> 0 | W25: =IF($H25<>"","项目成本",IFERROR(INDEX(基础资料!$W$4:$W$49,MATCH($I25,基础资料!$V$4:$V$49,0)),"")) | X25: =IFERROR(INDEX(基础资料!$R$4:$R$17,MATCH($G25,基础资料!$Q$4:$Q$17,0)),"") -> 经营收入
A26: =IF($B26="","",COUNTA($B$5:$B26)) -> 22 | B26: 46048 | C26: 双思威基本户 | D26: =IFERROR(INDEX(基础资料!$F$4:$F$23,MATCH($C26,基础资料!$E$4:$E$23,0)),IF($C26="","","未匹配账户")) -> 双思威 | E26: 收入 | F26: 昌吉市中等职业学校教学设备采购项目(二标段) | G26: 项目收入 | J26: 收中移建设有限公司新疆分公司货款 | K26: 582712.28 | M26: =IFERROR(VLOOKUP($C26,$C$5:$M$24,11,0)+SUMIF($C$25:$C26,$C26,$K$25:$K26)-SUMIF($C$25:$C26,$C26,$L$25:$L26),"") -> 1727312.4 | R26: 示例：由2026年6月原表导入 | S26: =IF($B26="","",--TEXT($B26,"yyyymm")) -> 202601 | T26: =IF($B26="","",IF($P26="",$S26,IFERROR($P26*1,$P26))) -> 202601 | U26: =IF($B26="","",IF($T26=$S26,"","跨期")) | V26: =IF(AND($B26<>"",$F26<>"",$F26=项目明细账!$C$2),N(V25)+1,N(V25)) -> 0 | W26: =IF($H26<>"","项目成本",IFERROR(INDEX(基础资料!$W$4:$W$49,MATCH($I26,基础资料!$V$4:$V$49,0)),"")) | X26: =IFERROR(INDEX(基础资料!$R$4:$R$17,MATCH($G26,基础资料!$Q$4:$Q$17,0)),"") -> 经营收入
A27: =IF($B27="","",COUNTA($B$5:$B27)) -> 23 | B27: 46049 | C27: 双思威基本户 | D27: =IFERROR(INDEX(基础资料!$F$4:$F$23,MATCH($C27,基础资料!$E$4:$E$23,0)),IF($C27="","","未匹配账户")) -> 双思威 | E27: 收入 | F27: 中电信数智科技有限公司昌吉分公司2025年某学校智慧教室建设项目 | G27: 项目收入 | J27: 中电信数智科技有限公司昌吉分公司2025年某学校智慧教室建设项目 | K27: 236456 | M27: =IFERROR(VLOOKUP($C27,$C$5:$M$24,11,0)+SUMIF($C$25:$C27,$C27,$K$25:$K27)-SUMIF($C$25:$C27,$C27,$L$25:$L27),"") -> 1963768.4 | R27: 示例：由2026年6月原表导入 | S27: =IF($B27="","",--TEXT($B27,"yyyymm")) -> 202601 | T27: =IF($B27="","",IF($P27="",$S27,IFERROR($P27*1,$P27))) -> 202601 | U27: =IF($B27="","",IF($T27=$S27,"","跨期")) | V27: =IF(AND($B27<>"",$F27<>"",$F27=项目明细账!$C$2),N(V26)+1,N(V26)) -> 0 | W27: =IF($H27<>"","项目成本",IFERROR(INDEX(基础资料!$W$4:$W$49,MATCH($I27,基础资料!$V$4:$V$49,0)),"")) | X27: =IFERROR(INDEX(基础资料!$R$4:$R$17,MATCH($G27,基础资料!$Q$4:$Q$17,0)),"") -> 经营收入
A28: =IF($B28="","",COUNTA($B$5:$B28)) -> 24 | B28: 46049 | C28: 双思威基本户 | D28: =IFERROR(INDEX(基础资料!$F$4:$F$23,MATCH($C28,基础资料!$E$4:$E$23,0)),IF($C28="","","未匹配账户")) -> 双思威 | E28: 收入 | F28: 中国电信巴州分公司2025年某部幼儿园视频监控系统服务采购 | G28: 项目收入 | J28: 中国电信巴州分公司2025年某部幼儿园视频监控系统服务采购 | K28: 82000 | M28: =IFERROR(VLOOKUP($C28,$C$5:$M$24,11,0)+SUMIF($C$25:$C28,$C28,$K$25:$K28)-SUMIF($C$25:$C28,$C28,$L$25:$L28),"") -> 2045768.4 | R28: 示例：由2026年6月原表导入 | S28: =IF($B28="","",--TEXT($B28,"yyyymm")) -> 202601 | T28: =IF($B28="","",IF($P28="",$S28,IFERROR($P28*1,$P28))) -> 202601 | U28: =IF($B28="","",IF($T28=$S28,"","跨期")) | V28: =IF(AND($B28<>"",$F28<>"",$F28=项目明细账!$C$2),N(V27)+1,N(V27)) -> 0 | W28: =IF($H28<>"","项目成本",IFERROR(INDEX(基础资料!$W$4:$W$49,MATCH($I28,基础资料!$V$4:$V$49,0)),"")) | X28: =IFERROR(INDEX(基础资料!$R$4:$R$17,MATCH($G28,基础资料!$Q$4:$Q$17,0)),"") -> 经营收入
A29: =IF($B29="","",COUNTA($B$5:$B29)) -> 25 | B29: 46034 | C29: 双思威农商行一般户 | D29: =IFERROR(INDEX(基础资料!$F$4:$F$23,MATCH($C29,基础资料!$E$4:$E$23,0)),IF($C29="","","未匹配账户")) -> 双思威 | E29: 收入 | F29: 昌吉市中等职业学校教学设备采购项目（一标段） | G29: 项目收入 | J29: 收北京竞业达数码科技股份有限公司 | K29: 3122400 | M29: =IFERROR(VLOOKUP($C29,$C$5:$M$24,11,0)+SUMIF($C$25:$C29,$C29,$K$25:$K29)-SUMIF($C$25:$C29,$C29,$L$25:$L29),"") -> 4118721.1 | R29: 示例：由2026年6月原表导入 | S29: =IF($B29="","",--TEXT($B29,"yyyymm")) -> 202601 | T29: =IF($B29="","",IF($P29="",$S29,IFERROR($P29*1,$P29))) -> 202601 | U29: =IF($B29="","",IF($T29=$S29,"","跨期")) | V29: =IF(AND($B29<>"",$F29<>"",$F29=项目明细账!$C$2),N(V28)+1,N(V28)) -> 0 | W29: =IF($H29<>"","项目成本",IFERROR(INDEX(基础资料!$W$4:$W$49,MATCH($I29,基础资料!$V$4:$V$49,0)),"")) | X29: =IFERROR(INDEX(基础资料!$R$4:$R$17,MATCH($G29,基础资料!$Q$4:$Q$17,0)),"") -> 经营收入
A30: =IF($B30="","",COUNTA($B$5:$B30)) -> 26 | B30: 46051 | C30: 瑞盛天中行基本户 | D30: =IFERROR(INDEX(基础资料!$F$4:$F$23,MATCH($C30,基础资料!$E$4:$E$23,0)),IF($C30="","","未匹配账户")) -> 瑞盛天 | E30: 收入 | F30: 草湖标识标牌项目 | G30: 项目收入 | J30: 收新疆博创未来信息工程技术有限公司货款 | K30: 200000 | M30: =IFERROR(VLOOKUP($C30,$C$5:$M$24,11,0)+SUMIF($C$25:$C30,$C30,$K$25:$K30)-SUMIF($C$25:$C30,$C30,$L$25:$L30),"") -> 1532384.2 | R30: 示例：由2026年6月原表导入 | S30: =IF($B30="","",--TEXT($B30,"yyyymm")) -> 202601 | T30: =IF($B30="","",IF($P30="",$S30,IFERROR($P30*1,$P30))) -> 202601 | U30: =IF($B30="","",IF($T30=$S30,"","跨期")) | V30: =IF(AND($B30<>"",$F30<>"",$F30=项目明细账!$C$2),N(V29)+1,N(V29)) -> 0 | W30: =IF($H30<>"","项目成本",IFERROR(INDEX(基础资料!$W$4:$W$49,MATCH($I30,基础资料!$V$4:$V$49,0)),"")) | X30: =IFERROR(INDEX(基础资料!$R$4:$R$17,MATCH($G30,基础资料!$Q$4:$Q$17,0)),"") -> 经营收入
A31: =IF($B31="","",COUNTA($B$5:$B31)) -> 27 | B31: 46032 | C31: 双思威基本户 | D31: =IFERROR(INDEX(基础资料!$F$4:$F$23,MATCH($C31,基础资料!$E$4:$E$23,0)),IF($C31="","","未匹配账户")) -> 双思威 | E31: 支出 | I31: 银行手续费 | J31: 付款手续费 | L31: 4.05 | M31: =IFERROR(VLOOKUP($C31,$C$5:$M$24,11,0)+SUMIF($C$25:$C31,$C31,$K$25:$K31)-SUMIF($C$25:$C31,$C31,$L$25:$L31),"") -> 2045764.4 | R31: 示例：由2026年6月原表导入 | S31: =IF($B31="","",--TEXT($B31,"yyyymm")) -> 202601 | T31: =IF($B31="","",IF($P31="",$S31,IFERROR($P31*1,$P31))) -> 202601 | U31: =IF($B31="","",IF($T31=$S31,"","跨期")) | V31: =IF(AND($B31<>"",$F31<>"",$F31=项目明细账!$C$2),N(V30)+1,N(V30)) -> 0 | W31: =IF($H31<>"","项目成本",IFERROR(INDEX(基础资料!$W$4:$W$49,MATCH($I31,基础资料!$V$4:$V$49,0)),"")) -> 财务费用 | X31: =IFERROR(INDEX(基础资料!$R$4:$R$17,MATCH($G31,基础资料!$Q$4:$Q$17,0)),"")
A32: =IF($B32="","",COUNTA($B$5:$B32)) -> 28 | B32: 46035 | C32: 双思威基本户 | D32: =IFERROR(INDEX(基础资料!$F$4:$F$23,MATCH($C32,基础资料!$E$4:$E$23,0)),IF($C32="","","未匹配账户")) -> 双思威 | E32: 支出 | I32: 银行手续费 | J32: 付款手续费 | L32: 4.05 | M32: =IFERROR(VLOOKUP($C32,$C$5:$M$24,11,0)+SUMIF($C$25:$C32,$C32,$K$25:$K32)-SUMIF($C$25:$C32,$C32,$L$25:$L32),"") -> 2045760.3 | R32: 示例：由2026年6月原表导入 | S32: =IF($B32="","",--TEXT($B32,"yyyymm")) -> 202601 | T32: =IF($B32="","",IF($P32="",$S32,IFERROR($P32*1,$P32))) -> 202601 | U32: =IF($B32="","",IF($T32=$S32,"","跨期")) | V32: =IF(AND($B32<>"",$F32<>"",$F32=项目明细账!$C$2),N(V31)+1,N(V31)) -> 0 | W32: =IF($H32<>"","项目成本",IFERROR(INDEX(基础资料!$W$4:$W$49,MATCH($I32,基础资料!$V$4:$V$49,0)),"")) -> 财务费用 | X32: =IFERROR(INDEX(基础资料!$R$4:$R$17,MATCH($G32,基础资料!$Q$4:$Q$17,0)),"")
A33: =IF($B33="","",COUNTA($B$5:$B33)) -> 29 | B33: 46036 | C33: 双思威基本户 | D33: =IFERROR(INDEX(基础资料!$F$4:$F$23,MATCH($C33,基础资料!$E$4:$E$23,0)),IF($C33="","","未匹配账户")) -> 双思威 | E33: 支出 | I33: 工资 | J33: 年终奖 | L33: 250000 | M33: =IFERROR(VLOOKUP($C33,$C$5:$M$24,11,0)+SUMIF($C$25:$C33,$C33,$K$25:$K33)-SUMIF($C$25:$C33,$C33,$L$25:$L33),"") -> 1795760.3 | R33: 示例：由2026年6月原表导入 | S33: =IF($B33="","",--TEXT($B33,"yyyymm")) -> 202601 | T33: =IF($B33="","",IF($P33="",$S33,IFERROR($P33*1,$P33))) -> 202601 | U33: =IF($B33="","",IF($T33=$S33,"","跨期")) | V33: =IF(AND($B33<>"",$F33<>"",$F33=项目明细账!$C$2),N(V32)+1,N(V32)) -> 0 | W33: =IF($H33<>"","项目成本",IFERROR(INDEX(基础资料!$W$4:$W$49,MATCH($I33,基础资料!$V$4:$V$49,0)),"")) -> 人工社保 | X33: =IFERROR(INDEX(基础资料!$R$4:$R$17,MATCH($G33,基础资料!$Q$4:$Q$17,0)),"")
A34: =IF($B34="","",COUNTA($B$5:$B34)) -> 30 | B34: 46036 | C34: 双思威基本户 | D34: =IFERROR(INDEX(基础资料!$F$4:$F$23,MATCH($C34,基础资料!$E$4:$E$23,0)),IF($C34="","","未匹配账户")) -> 双思威 | E34: 支出 | I34: 银行手续费 | J34: 付款手续费 | L34: 200 | M34: =IFERROR(VLOOKUP($C34,$C$5:$M$24,11,0)+SUMIF($C$25:$C34,$C34,$K$25:$K34)-SUMIF($C$25:$C34,$C34,$L$25:$L34),"") -> 1795560.3 | R34: 示例：由2026年6月原表导入 | S34: =IF($B34="","",--TEXT($B34,"yyyymm")) -> 202601 | T34: =IF($B34="","",IF($P34="",$S34,IFERROR($P34*1,$P34))) -> 202601 | U34: =IF($B34="","",IF($T34=$S34,"","跨期")) | V34: =IF(AND($B34<>"",$F34<>"",$F34=项目明细账!$C$2),N(V33)+1,N(V33)) -> 0 | W34: =IF($H34<>"","项目成本",IFERROR(INDEX(基础资料!$W$4:$W$49,MATCH($I34,基础资料!$V$4:$V$49,0)),"")) -> 财务费用 | X34: =IFERROR(INDEX(基础资料!$R$4:$R$17,MATCH($G34,基础资料!$Q$4:$Q$17,0)),"")
A35: =IF($B35="","",COUNTA($B$5:$B35)) -> 31 | B35: 46036 | C35: 双思威基本户 | D35: =IFERROR(INDEX(基础资料!$F$4:$F$23,MATCH($C35,基础资料!$E$4:$E$23,0)),IF($C35="","","未匹配账户")) -> 双思威 | E35: 支出 | I35: 工资 | J35: 付季新军工资 | L35: 8582.47 | M35: =IFERROR(VLOOKUP($C35,$C$5:$M$24,11,0)+SUMIF($C$25:$C35,$C35,$K$25:$K35)-SUMIF($C$25:$C35,$C35,$L$25:$L35),"") -> 1786977.9 | R35: 示例：由2026年6月原表导入 | S35: =IF($B35="","",--TEXT($B35,"yyyymm")) -> 202601 | T35: =IF($B35="","",IF($P35="",$S35,IFERROR($P35*1,$P35))) -> 202601 | U35: =IF($B35="","",IF($T35=$S35,"","跨期")) | V35: =IF(AND($B35<>"",$F35<>"",$F35=项目明细账!$C$2),N(V34)+1,N(V34)) -> 0 | W35: =IF($H35<>"","项目成本",IFERROR(INDEX(基础资料!$W$4:$W$49,MATCH($I35,基础资料!$V$4:$V$49,0)),"")) -> 人工社保 | X35: =IFERROR(INDEX(基础资料!$R$4:$R$17,MATCH($G35,基础资料!$Q$4:$Q$17,0)),"")
A36: =IF($B36="","",COUNTA($B$5:$B36)) -> 32 | B36: 46036 | C36: 双思威基本户 | D36: =IFERROR(INDEX(基础资料!$F$4:$F$23,MATCH($C36,基础资料!$E$4:$E$23,0)),IF($C36="","","未匹配账户")) -> 双思威 | E36: 支出 | I36: 工资 | J36: 付席科工资 | L36: 3157.61 | M36: =IFERROR(VLOOKUP($C36,$C$5:$M$24,11,0)+SUMIF($C$25:$C36,$C36,$K$25:$K36)-SUMIF($C$25:$C36,$C36,$L$25:$L36),"") -> 1783820.3 | R36: 示例：由2026年6月原表导入 | S36: =IF($B36="","",--TEXT($B36,"yyyymm")) -> 202601 | T36: =IF($B36="","",IF($P36="",$S36,IFERROR($P36*1,$P36))) -> 202601 | U36: =IF($B36="","",IF($T36=$S36,"","跨期")) | V36: =IF(AND($B36<>"",$F36<>"",$F36=项目明细账!$C$2),N(V35)+1,N(V35)) -> 0 | W36: =IF($H36<>"","项目成本",IFERROR(INDEX(基础资料!$W$4:$W$49,MATCH($I36,基础资料!$V$4:$V$49,0)),"")) -> 人工社保 | X36: =IFERROR(INDEX(基础资料!$R$4:$R$17,MATCH($G36,基础资料!$Q$4:$Q$17,0)),"")
A37: =IF($B37="","",COUNTA($B$5:$B37)) -> 33 | B37: 46036 | C37: 双思威基本户 | D37: =IFERROR(INDEX(基础资料!$F$4:$F$23,MATCH($C37,基础资料!$E$4:$E$23,0)),IF($C37="","","未匹配账户")) -> 双思威 | E37: 支出 | I37: 工资 | J37: 付高愉工资 | L37: 3152.48 | M37: =IFERROR(VLOOKUP($C37,$C$5:$M$24,11,0)+SUMIF($C$25:$C37,$C37,$K$25:$K37)-SUMIF($C$25:$C37,$C37,$L$25:$L37),"") -> 1780667.8 | R37: 示例：由2026年6月原表导入 | S37: =IF($B37="","",--TEXT($B37,"yyyymm")) -> 202601 | T37: =IF($B37="","",IF($P37="",$S37,IFERROR($P37*1,$P37))) -> 202601 | U37: =IF($B37="","",IF($T37=$S37,"","跨期")) | V37: =IF(AND($B37<>"",$F37<>"",$F37=项目明细账!$C$2),N(V36)+1,N(V36)) -> 0 | W37: =IF($H37<>"","项目成本",IFERROR(INDEX(基础资料!$W$4:$W$49,MATCH($I37,基础资料!$V$4:$V$49,0)),"")) -> 人工社保 | X37: =IFERROR(INDEX(基础资料!$R$4:$R$17,MATCH($G37,基础资料!$Q$4:$Q$17,0)),"")
A38: =IF($B38="","",COUNTA($B$5:$B38)) -> 34 | B38: 46036 | C38: 双思威基本户 | D38: =IFERROR(INDEX(基础资料!$F$4:$F$23,MATCH($C38,基础资料!$E$4:$E$23,0)),IF($C38="","","未匹配账户")) -> 双思威 | E38: 支出 | I38: 工资 | J38: 付张宝婷工资 | L38: 6677.12 | M38: =IFERROR(VLOOKUP($C38,$C$5:$M$24,11,0)+SUMIF($C$25:$C38,$C38,$K$25:$K38)-SUMIF($C$25:$C38,$C38,$L$25:$L38),"") -> 1773990.7 | R38: 示例：由2026年6月原表导入 | S38: =IF($B38="","",--TEXT($B38,"yyyymm")) -> 202601 | T38: =IF($B38="","",IF($P38="",$S38,IFERROR($P38*1,$P38))) -> 202601 | U38: =IF($B38="","",IF($T38=$S38,"","跨期")) | V38: =IF(AND($B38<>"",$F38<>"",$F38=项目明细账!$C$2),N(V37)+1,N(V37)) -> 0 | W38: =IF($H38<>"","项目成本",IFERROR(INDEX(基础资料!$W$4:$W$49,MATCH($I38,基础资料!$V$4:$V$49,0)),"")) -> 人工社保 | X38: =IFERROR(INDEX(基础资料!$R$4:$R$17,MATCH($G38,基础资料!$Q$4:$Q$17,0)),"")
A39: =IF($B39="","",COUNTA($B$5:$B39)) -> 35 | B39: 46036 | C39: 双思威基本户 | D39: =IFERROR(INDEX(基础资料!$F$4:$F$23,MATCH($C39,基础资料!$E$4:$E$23,0)),IF($C39="","","未匹配账户")) -> 双思威 | E39: 支出 | I39: 工资 | J39: 付何春华工资 | L39: 2657.61 | M39: =IFERROR(VLOOKUP($C39,$C$5:$M$24,11,0)+SUMIF($C$25:$C39,$C39,$K$25:$K39)-SUMIF($C$25:$C39,$C39,$L$25:$L39),"") -> 1771333.1 | R39: 示例：由2026年6月原表导入 | S39: =IF($B39="","",--TEXT($B39,"yyyymm")) -> 202601 | T39: =IF($B39="","",IF($P39="",$S39,IFERROR($P39*1,$P39))) -> 202601 | U39: =IF($B39="","",IF($T39=$S39,"","跨期")) | V39: =IF(AND($B39<>"",$F39<>"",$F39=项目明细账!$C$2),N(V38)+1,N(V38)) -> 0 | W39: =IF($H39<>"","项目成本",IFERROR(INDEX(基础资料!$W$4:$W$49,MATCH($I39,基础资料!$V$4:$V$49,0)),"")) -> 人工社保 | X39: =IFERROR(INDEX(基础资料!$R$4:$R$17,MATCH($G39,基础资料!$Q$4:$Q$17,0)),"")
A40: =IF($B40="","",COUNTA($B$5:$B40)) -> 36 | B40: 46036 | C40: 双思威基本户 | D40: =IFERROR(INDEX(基础资料!$F$4:$F$23,MATCH($C40,基础资料!$E$4:$E$23,0)),IF($C40="","","未匹配账户")) -> 双思威 | E40: 支出 | I40: 工资 | J40: 付陈垒工资 | L40: 2657.61 | M40: =IFERROR(VLOOKUP($C40,$C$5:$M$24,11,0)+SUMIF($C$25:$C40,$C40,$K$25:$K40)-SUMIF($C$25:$C40,$C40,$L$25:$L40),"") -> 1768675.4 | R40: 示例：由2026年6月原表导入 | S40: =IF($B40="","",--TEXT($B40,"yyyymm")) -> 202601 | T40: =IF($B40="","",IF($P40="",$S40,IFERROR($P40*1,$P40))) -> 202601 | U40: =IF($B40="","",IF($T40=$S40,"","跨期")) | V40: =IF(AND($B40<>"",$F40<>"",$F40=项目明细账!$C$2),N(V39)+1,N(V39)) -> 0 | W40: =IF($H40<>"","项目成本",IFERROR(INDEX(基础资料!$W$4:$W$49,MATCH($I40,基础资料!$V$4:$V$49,0)),"")) -> 人工社保 | X40: =IFERROR(INDEX(基础资料!$R$4:$R$17,MATCH($G40,基础资料!$Q$4:$Q$17,0)),"")
A41: =IF($B41="","",COUNTA($B$5:$B41)) -> 37 | B41: 46036 | C41: 双思威基本户 | D41: =IFERROR(INDEX(基础资料!$F$4:$F$23,MATCH($C41,基础资料!$E$4:$E$23,0)),IF($C41="","","未匹配账户")) -> 双思威 | E41: 支出 | I41: 工资 | J41: 付叶创将工资 | L41: 2757.61 | M41: =IFERROR(VLOOKUP($C41,$C$5:$M$24,11,0)+SUMIF($C$25:$C41,$C41,$K$25:$K41)-SUMIF($C$25:$C41,$C41,$L$25:$L41),"") -> 1765917.8 | R41: 示例：由2026年6月原表导入 | S41: =IF($B41="","",--TEXT($B41,"yyyymm")) -> 202601 | T41: =IF($B41="","",IF($P41="",$S41,IFERROR($P41*1,$P41))) -> 202601 | U41: =IF($B41="","",IF($T41=$S41,"","跨期")) | V41: =IF(AND($B41<>"",$F41<>"",$F41=项目明细账!$C$2),N(V40)+1,N(V40)) -> 0 | W41: =IF($H41<>"","项目成本",IFERROR(INDEX(基础资料!$W$4:$W$49,MATCH($I41,基础资料!$V$4:$V$49,0)),"")) -> 人工社保 | X41: =IFERROR(INDEX(基础资料!$R$4:$R$17,MATCH($G41,基础资料!$Q$4:$Q$17,0)),"")
A42: =IF($B42="","",COUNTA($B$5:$B42)) -> 38 | B42: 46036 | C42: 双思威基本户 | D42: =IFERROR(INDEX(基础资料!$F$4:$F$23,MATCH($C42,基础资料!$E$4:$E$23,0)),IF($C42="","","未匹配账户")) -> 双思威 | E42: 支出 | I42: 工资 | J42: 付侯云霞工资 | L42: 1500 | M42: =IFERROR(VLOOKUP($C42,$C$5:$M$24,11,0)+SUMIF($C$25:$C42,$C42,$K$25:$K42)-SUMIF($C$25:$C42,$C42,$L$25:$L42),"") -> 1764417.8 | R42: 示例：由2026年6月原表导入 | S42: =IF($B42="","",--TEXT($B42,"yyyymm")) -> 202601 | T42: =IF($B42="","",IF($P42="",$S42,IFERROR($P42*1,$P42))) -> 202601 | U42: =IF($B42="","",IF($T42=$S42,"","跨期")) | V42: =IF(AND($B42<>"",$F42<>"",$F42=项目明细账!$C$2),N(V41)+1,N(V41)) -> 0 | W42: =IF($H42<>"","项目成本",IFERROR(INDEX(基础资料!$W$4:$W$49,MATCH($I42,基础资料!$V$4:$V$49,0)),"")) -> 人工社保 | X42: =IFERROR(INDEX(基础资料!$R$4:$R$17,MATCH($G42,基础资料!$Q$4:$Q$17,0)),"")
... A56: =IF($B56="","",COUNTA($B$5:$B56)) -> 52 | B56: 46036 | C56: 双思威基本户 | D56: =IFERROR(INDEX(基础资料!$F$4:$F$23,MATCH($C56,基础资料!$E$4:$E$23,0)),IF($C56="","","未匹配账户")) -> 双思威 | E56: 支出 | I56: 工资 | J56: 付叶创将业务执行费 | L56: 1700 | M56: =IFERROR(VLOOKUP($C56,$C$5:$M$24,11,0)+SUMIF($C$25:$C56,$C56,$K$25:$K56)-SUMIF($C$25:$C56,$C56,$L$25:$L56),"") -> 1740349.8 | R56: 示例：由2026年6月原表导入 | S56: =IF($B56="","",--TEXT($B56,"yyyymm")) -> 202601 | T56: =IF($B56="","",IF($P56="",$S56,IFERROR($P56*1,$P56))) -> 202601 | U56: =IF($B56="","",IF($T56=$S56,"","跨期")) | V56: =IF(AND($B56<>"",$F56<>"",$F56=项目明细账!$C$2),N(V55)+1,N(V55)) -> 0 | W56: =IF($H56<>"","项目成本",IFERROR(INDEX(基础资料!$W$4:$W$49,MATCH($I56,基础资料!$V$4:$V$49,0)),"")) -> 人工社保 | X56: =IFERROR(INDEX(基础资料!$R$4:$R$17,MATCH($G56,基础资料!$Q$4:$Q$17,0)),"")
