Workbook

Sheet 使用说明
A1: 更多财务实操模板，可自行搜索抖音/视频号：老财务的实操笔记
A3: 【老财务实操自用｜初级版财务台账模板】
A4: 作者：老财务的实操笔记
A5: ——————————————————————————
A6: 适用对象：小微企业、个体工商户、小规模纳税人、商贸服务类等
A7: 版本说明
A8: 本套为**通用基础初级版**，满足税务管理、费用报销、收支登记、票据管理等
A9: 可根据行业属性、业务规模、升级定制版。
A11: 模板清单，持续更新
A12: 1、应收账款风险预警表
A13: 2、日常经营情况汇总表
A14: 3、进项台帐自动查重表
... A47: 老财务自用模板｜禁止外传、倒卖、商用

Sheet 基础资料
A1: 账户 | B1: 收支类别 （无筛选） | C1: 收/支项目类别 | E1: 客户 | F1: 客户期初余额 | H1: 供应商 | I1: 供应商期初余额
A2: 金辉稠州 | C2: 借款本金 | E2: 曹泰宁 | H2: 供应商1
A3: 典当微信 | B3: 收入类 | C3: 借款利息 | E3: 曹玉洁 | H3: 供应商2
A4: 林总浦发 | B4: 收入类 | C4: 借款滞纳金 | E4: 曾光雄 | H4: 供应商3
A5: 吴姐建行 | B5: 收入类 | C5: 银行结息 | E5: 曾云 | H5: 供应商4
A6: 吴姐民生 | B6: 费用支出类 | C6: 员工工资 | E6: 常虹 | H6: 供应商5
A7: 吴建忠浦发 | B7: 费用支出类 | C7: 水电费 | E7: 陈滨 | H7: 供应商6
A8: 吴姐兴业 | B8: 费用支出类 | C8: 房租 | E8: 陈承辉 | H8: 供应商7
A9: 明道对公 | B9: 费用支出类 | C9: 办公费用 | E9: 陈大鑫 | H9: 供应商8
A10: 金辉对公 | B10: 费用支出类 | C10: 招待费 | E10: 陈东 | H10: 供应商9
A11: 吴姐微信 | B11: 费用支出类 | C11: 渠道费用 | E11: 陈福荣 | H11: 供应商10
A12: 备用1 | B12: 收入类 | C12: 手续费-收 | E12: 陈国宝 | H12: 供应商11
A13: 备用2 | C13: 过桥/解押本金 | E13: 陈建华 | H13: 供应商12
A14: 备用3 | B14: 往来款 | C14: 客户款项 | E14: 陈乐贵 | H14: 供应商13
A15: 备用4 | B15: 往来款 | C15: 调拔款 | E15: 陈立
B16: 费用支出类 | C16: 明道利息 | E16: 陈隆鑫
C17: 抵押物回收款 | E17: 陈敏峰
B18: 费用支出类 | C18: 律师诉讼费 | E18: 陈琴
B19: 费用支出类 | C19: 金辉利息 | E19: 陈庆生
B20: 费用支出类 | C20: 社医保 | E20: 陈守琴
B21: 往来款 | C21: 收入其他 | E21: 陈天敏
B22: 费用支出类 | C22: 个税 | E22: 陈跃飞
C23: 公积金 | E23: 陈征
C24: 金辉本金 | E24: 陈忠军
C25: 明道本金 | E25: 池鸿
E26: 典当微信
E27: 董智宇
E28: 杜若
E29: 段乐
E30: 方楚钰
E31: 方士雯
E32: 方秀全
E33: 高文玉
E34: 郭宝龙
E35: 郭联兵
E36: 何博文
E37: 胡建通
... E172: 朱俊良

Sheet 数据录入
A1: 多帐户收支登记表
F2: 收入总额 | G2: 支出总额 | H2: 账户余额
F3: =SUBTOTAL(109,$F$4:$F$5077) -> 38290244 | G3: =SUBTOTAL(109,$G$4:$G$5077) -> 36629662 | H3: =SUBTOTAL(109,$H$5:$H$18)+F3-G3 -> 2380462.6
A4: 序号 | B4: 日期 | C4: 公司账户 | D4: 收/支项目类别 | E4: 摘要内容 | F4: 收入 | G4: 支出 | H4: 账户余额 | I4: 客户 | J4: 供应商 | K4: 月份
A5: =IF(B5="","",COUNTA($B$5:B5)) -> 1 | B5: 46174 | C5: 金辉稠州 | E5: 期初余额 | H5: 219263.12 | K5: =IF($B5="","",--TEXT($B5,"yyyymm")) -> 202606
A6: =IF(B6="","",COUNTA($B$5:B6)) -> 2 | B6: 46174 | C6: 典当微信 | E6: 期初余额 | H6: 112326.39 | K6: =IF($B6="","",--TEXT($B6,"yyyymm")) -> 202606
A7: =IF(B7="","",COUNTA($B$5:B7)) -> 3 | B7: 46174 | C7: 林总浦发 | E7: 期初余额 | H7: 73513.15 | K7: =IF($B7="","",--TEXT($B7,"yyyymm")) -> 202606
A8: =IF(B8="","",COUNTA($B$5:B8)) -> 4 | B8: 46174 | C8: 吴姐建行 | E8: 期初余额 | H8: 90026.28 | K8: =IF($B8="","",--TEXT($B8,"yyyymm")) -> 202606
A9: =IF(B9="","",COUNTA($B$5:B9)) -> 5 | B9: 46174 | C9: 吴姐民生 | E9: 期初余额 | H9: 15829.44 | K9: =IF($B9="","",--TEXT($B9,"yyyymm")) -> 202606
A10: =IF(B10="","",COUNTA($B$5:B10)) -> 6 | B10: 46174 | C10: 吴建忠浦发 | E10: 期初余额 | H10: 208922.52 | K10: =IF($B10="","",--TEXT($B10,"yyyymm")) -> 202606
A11: =IF(B11="","",COUNTA($B$5:B11)) -> 7 | B11: 46174 | C11: 吴姐兴业 | E11: 期初余额 | H11: 0 | K11: =IF($B11="","",--TEXT($B11,"yyyymm")) -> 202606
A12: =IF(B12="","",COUNTA($B$5:B12)) -> 8 | B12: 46174 | C12: 明道对公 | E12: 期初余额 | H12: 0 | K12: =IF($B12="","",--TEXT($B12,"yyyymm")) -> 202606
A13: =IF(B13="","",COUNTA($B$5:B13)) -> 9 | B13: 46174 | C13: 金辉对公 | E13: 期初余额 | H13: 0 | K13: =IF($B13="","",--TEXT($B13,"yyyymm")) -> 202606
A14: =IF(B14="","",COUNTA($B$5:B14)) -> 10 | B14: 46174 | C14: 吴姐微信 | E14: 期初余额 | H14: 0 | K14: =IF($B14="","",--TEXT($B14,"yyyymm")) -> 202606
A15: =IF(B15="","",COUNTA($B$5:B15)) -> 11 | B15: 46174 | C15: 备用1 | E15: 期初余额 | H15: 0 | K15: =IF($B15="","",--TEXT($B15,"yyyymm")) -> 202606
A16: =IF(B16="","",COUNTA($B$5:B16)) -> 12 | B16: 46174 | C16: 备用2 | E16: 期初余额 | H16: 0 | K16: =IF($B16="","",--TEXT($B16,"yyyymm")) -> 202606
... A18: =IF(B18="","",COUNTA($B$5:B18)) -> 14 | B18: 46174 | C18: 备用4 | E18: 期初余额 | H18: 0 | K18: =IF($B18="","",--TEXT($B18,"yyyymm")) -> 202606
A19: =IF(B19="","",COUNTA($B$5:B19)) -> 15 | B19: 46204 | C19: 吴建忠浦发 | D19: 借款本金 | E19: 杨文昕转回款 | F19: 500000 | H19: =IFERROR(VLOOKUP($C19,$C$5:$H$18,6,0)+SUMIF($C$19:$C19,$C19,$F$19:$F19)-SUMIF($C$19:$C19,$C19,$G$19:$G19),"") -> 708922.52 | I19: 杨文昕 | K19: =IF($B19="","",--TEXT($B19,"yyyymm")) -> 202607
A20: =IF(B20="","",COUNTA($B$5:B20)) -> 16 | B20: 46204 | C20: 吴建忠浦发 | D20: 借款本金 | E20: 陈庆生回款 | F20: 500000 | H20: =IFERROR(VLOOKUP($C20,$C$5:$H$18,6,0)+SUMIF($C$19:$C20,$C20,$F$19:$F20)-SUMIF($C$19:$C20,$C20,$G$19:$G20),"") -> 1208922.5 | I20: 陈庆生 | K20: =IF($B20="","",--TEXT($B20,"yyyymm")) -> 202607
A21: =IF(B21="","",COUNTA($B$5:B21)) -> 17 | B21: 46204 | C21: 吴建忠浦发 | D21: 调拔款 | E21: 吴建忠浦发转林总浦发 | G21: 700000 | H21: =IFERROR(VLOOKUP($C21,$C$5:$H$18,6,0)+SUMIF($C$19:$C21,$C21,$F$19:$F21)-SUMIF($C$19:$C21,$C21,$G$19:$G21),"") -> 508922.52 | I21: 林总浦发 | K21: =IF($B21="","",--TEXT($B21,"yyyymm")) -> 202607
A22: =IF(B22="","",COUNTA($B$5:B22)) -> 18 | B22: 46204 | C22: 吴建忠浦发 | D22: 调拔款 | E22: 吴建忠浦发转林总浦发 | G22: 500000 | H22: =IFERROR(VLOOKUP($C22,$C$5:$H$18,6,0)+SUMIF($C$19:$C22,$C22,$F$19:$F22)-SUMIF($C$19:$C22,$C22,$G$19:$G22),"") -> 8922.52 | I22: 林总浦发 | K22: =IF($B22="","",--TEXT($B22,"yyyymm")) -> 202607
A23: =IF(B23="","",COUNTA($B$5:B23)) -> 19 | B23: 46205 | C23: 吴建忠浦发 | D23: 借款本金 | E23: 杨文昕回款 | F23: 500000 | H23: =IFERROR(VLOOKUP($C23,$C$5:$H$18,6,0)+SUMIF($C$19:$C23,$C23,$F$19:$F23)-SUMIF($C$19:$C23,$C23,$G$19:$G23),"") -> 508922.52 | I23: 杨文昕 | K23: =IF($B23="","",--TEXT($B23,"yyyymm")) -> 202607
A24: =IF(B24="","",COUNTA($B$5:B24)) -> 20 | B24: 46205 | C24: 吴建忠浦发 | D24: 调拔款 | E24: 吴建忠浦发转林总浦发 | G24: 500000 | H24: =IFERROR(VLOOKUP($C24,$C$5:$H$18,6,0)+SUMIF($C$19:$C24,$C24,$F$19:$F24)-SUMIF($C$19:$C24,$C24,$G$19:$G24),"") -> 8922.52 | I24: 林总浦发 | K24: =IF($B24="","",--TEXT($B24,"yyyymm")) -> 202607
A25: =IF(B25="","",COUNTA($B$5:B25)) -> 21 | B25: 46206 | C25: 吴建忠浦发 | D25: 借款本金 | E25: 收到杨文昕回款 | F25: 300000 | H25: =IFERROR(VLOOKUP($C25,$C$5:$H$18,6,0)+SUMIF($C$19:$C25,$C25,$F$19:$F25)-SUMIF($C$19:$C25,$C25,$G$19:$G25),"") -> 308922.52 | I25: 杨文昕 | K25: =IF($B25="","",--TEXT($B25,"yyyymm")) -> 202607
A26: =IF(B26="","",COUNTA($B$5:B26)) -> 22 | B26: 46207 | C26: 吴建忠浦发 | D26: 借款本金 | E26: 收到杨文昕回款 | F26: 100000 | H26: =IFERROR(VLOOKUP($C26,$C$5:$H$18,6,0)+SUMIF($C$19:$C26,$C26,$F$19:$F26)-SUMIF($C$19:$C26,$C26,$G$19:$G26),"") -> 408922.52 | I26: 杨文昕 | K26: =IF($B26="","",--TEXT($B26,"yyyymm")) -> 202607
A27: =IF(B27="","",COUNTA($B$5:B27)) -> 23 | B27: 46209 | C27: 吴建忠浦发 | D27: 借款本金 | E27: 收到杨文昕回款 | F27: 120000 | H27: =IFERROR(VLOOKUP($C27,$C$5:$H$18,6,0)+SUMIF($C$19:$C27,$C27,$F$19:$F27)-SUMIF($C$19:$C27,$C27,$G$19:$G27),"") -> 528922.52 | I27: 杨文昕 | K27: =IF($B27="","",--TEXT($B27,"yyyymm")) -> 202607
A28: =IF(B28="","",COUNTA($B$5:B28)) -> 24 | B28: 46209 | C28: 吴建忠浦发 | D28: 调拔款 | E28: 吴建忠浦发转林总浦发 | G28: 20000 | H28: =IFERROR(VLOOKUP($C28,$C$5:$H$18,6,0)+SUMIF($C$19:$C28,$C28,$F$19:$F28)-SUMIF($C$19:$C28,$C28,$G$19:$G28),"") -> 508922.52 | I28: 林总浦发 | K28: =IF($B28="","",--TEXT($B28,"yyyymm")) -> 202607
A29: =IF(B29="","",COUNTA($B$5:B29)) -> 25 | B29: 46209 | C29: 吴建忠浦发 | D29: 调拔款 | E29: 吴建忠浦发转吴姐建行 | G29: 300000 | H29: =IFERROR(VLOOKUP($C29,$C$5:$H$18,6,0)+SUMIF($C$19:$C29,$C29,$F$19:$F29)-SUMIF($C$19:$C29,$C29,$G$19:$G29),"") -> 208922.52 | I29: 吴姐建行 | K29: =IF($B29="","",--TEXT($B29,"yyyymm")) -> 202607
A30: =IF(B30="","",COUNTA($B$5:B30)) -> 26 | B30: 46209 | C30: 吴建忠浦发 | D30: 借款利息 | E30: 杜若利息 | F30: 72800 | H30: =IFERROR(VLOOKUP($C30,$C$5:$H$18,6,0)+SUMIF($C$19:$C30,$C30,$F$19:$F30)-SUMIF($C$19:$C30,$C30,$G$19:$G30),"") -> 281722.52 | I30: 杜若 | K30: =IF($B30="","",--TEXT($B30,"yyyymm")) -> 202607
A31: =IF(B31="","",COUNTA($B$5:B31)) -> 27 | B31: 46209 | C31: 吴建忠浦发 | D31: 借款本金 | E31: 林熙铭本金 | F31: 8333.33 | H31: =IFERROR(VLOOKUP($C31,$C$5:$H$18,6,0)+SUMIF($C$19:$C31,$C31,$F$19:$F31)-SUMIF($C$19:$C31,$C31,$G$19:$G31),"") -> 290055.85 | I31: 林熙铭 | K31: =IF($B31="","",--TEXT($B31,"yyyymm")) -> 202607
A32: =IF(B32="","",COUNTA($B$5:B32)) -> 28 | B32: 46209 | C32: 吴建忠浦发 | D32: 借款利息 | E32: 林熙铭利息 | F32: 6000 | H32: =IFERROR(VLOOKUP($C32,$C$5:$H$18,6,0)+SUMIF($C$19:$C32,$C32,$F$19:$F32)-SUMIF($C$19:$C32,$C32,$G$19:$G32),"") -> 296055.85 | I32: 林熙铭 | K32: =IF($B32="","",--TEXT($B32,"yyyymm")) -> 202607
A33: =IF(B33="","",COUNTA($B$5:B33)) -> 29 | B33: 46209 | C33: 吴建忠浦发 | D33: 明道利息 | E33: 代林熙铭还利息到明道对公 | G33: 4500 | H33: =IFERROR(VLOOKUP($C33,$C$5:$H$18,6,0)+SUMIF($C$19:$C33,$C33,$F$19:$F33)-SUMIF($C$19:$C33,$C33,$G$19:$G33),"") -> 291555.85 | I33: 林熙铭 | K33: =IF($B33="","",--TEXT($B33,"yyyymm")) -> 202607
A34: =IF(B34="","",COUNTA($B$5:B34)) -> 30 | B34: 46210 | C34: 吴建忠浦发 | D34: 调拔款 | E34: 吴建忠浦发转吴姐建行 | G34: 72800 | H34: =IFERROR(VLOOKUP($C34,$C$5:$H$18,6,0)+SUMIF($C$19:$C34,$C34,$F$19:$F34)-SUMIF($C$19:$C34,$C34,$G$19:$G34),"") -> 218755.85 | I34: 吴姐建行 | K34: =IF($B34="","",--TEXT($B34,"yyyymm")) -> 202607
A35: =IF(B35="","",COUNTA($B$5:B35)) -> 31 | B35: 46211 | C35: 吴建忠浦发 | D35: 借款本金 | E35: 潘敏回款 | F35: 900000 | H35: =IFERROR(VLOOKUP($C35,$C$5:$H$18,6,0)+SUMIF($C$19:$C35,$C35,$F$19:$F35)-SUMIF($C$19:$C35,$C35,$G$19:$G35),"") -> 1118755.9 | I35: 潘敏 | K35: =IF($B35="","",--TEXT($B35,"yyyymm")) -> 202607
A36: =IF(B36="","",COUNTA($B$5:B36)) -> 32 | B36: 46211 | C36: 吴建忠浦发 | D36: 手续费-收 | E36: 潘敏回款手续费 | F36: 4540 | H36: =IFERROR(VLOOKUP($C36,$C$5:$H$18,6,0)+SUMIF($C$19:$C36,$C36,$F$19:$F36)-SUMIF($C$19:$C36,$C36,$G$19:$G36),"") -> 1123295.9 | I36: 潘敏 | K36: =IF($B36="","",--TEXT($B36,"yyyymm")) -> 202607
A37: =IF(B37="","",COUNTA($B$5:B37)) -> 33 | B37: 46211 | C37: 吴建忠浦发 | D37: 渠道费用 | E37: 潘敏回款渠道费用 | F37: 5540 | H37: =IFERROR(VLOOKUP($C37,$C$5:$H$18,6,0)+SUMIF($C$19:$C37,$C37,$F$19:$F37)-SUMIF($C$19:$C37,$C37,$G$19:$G37),"") -> 1128835.9 | I37: 潘敏 | K37: =IF($B37="","",--TEXT($B37,"yyyymm")) -> 202607
A38: =IF(B38="","",COUNTA($B$5:B38)) -> 34 | B38: 46211 | C38: 吴建忠浦发 | D38: 客户款项 | E38: 潘敏余款 | F38: 89870 | H38: =IFERROR(VLOOKUP($C38,$C$5:$H$18,6,0)+SUMIF($C$19:$C38,$C38,$F$19:$F38)-SUMIF($C$19:$C38,$C38,$G$19:$G38),"") -> 1218705.9 | I38: 潘敏 | K38: =IF($B38="","",--TEXT($B38,"yyyymm")) -> 202607
A39: =IF(B39="","",COUNTA($B$5:B39)) -> 35 | B39: 46211 | C39: 吴建忠浦发 | D39: 调拔款 | E39: 吴建忠浦发转吴姐建行-潘敏回款 | G39: 900000 | H39: =IFERROR(VLOOKUP($C39,$C$5:$H$18,6,0)+SUMIF($C$19:$C39,$C39,$F$19:$F39)-SUMIF($C$19:$C39,$C39,$G$19:$G39),"") -> 318705.85 | I39: 吴姐建行 | K39: =IF($B39="","",--TEXT($B39,"yyyymm")) -> 202607
A40: =IF(B40="","",COUNTA($B$5:B40)) -> 36 | B40: 46211 | C40: 吴建忠浦发 | D40: 客户款项 | E40: 退潘敏余款 | G40: 89870 | H40: =IFERROR(VLOOKUP($C40,$C$5:$H$18,6,0)+SUMIF($C$19:$C40,$C40,$F$19:$F40)-SUMIF($C$19:$C40,$C40,$G$19:$G40),"") -> 228835.85 | I40: 潘敏 | K40: =IF($B40="","",--TEXT($B40,"yyyymm")) -> 202607
A41: =IF(B41="","",COUNTA($B$5:B41)) -> 37 | B41: 46211 | C41: 吴建忠浦发 | D41: 渠道费用 | E41: 转吴志鑫费用-潘敏回款 | G41: 5540 | H41: =IFERROR(VLOOKUP($C41,$C$5:$H$18,6,0)+SUMIF($C$19:$C41,$C41,$F$19:$F41)-SUMIF($C$19:$C41,$C41,$G$19:$G41),"") -> 223295.85 | I41: 潘敏 | K41: =IF($B41="","",--TEXT($B41,"yyyymm")) -> 202607
...

Sheet 汇报表
A1: 资金日报统计表（任意连续日期 / 单独一天查询）
A2: 起始日期 | B2: 46204 | D2: 截止日期 | E2: 46233 | G2: 查询天数 | H2: =IF(OR($B$2="",$E$2=""),"",IF($E$2<$B$2,"日期错误",IF($E$2-$B$2+1>31,"超过31天",$E$2-$B$2+1))) -> 30
A3: 提示：修改黄色日期即可查询；单独一天时起始日期=截止日期；默认展开31天，超过31天建议按月分段查询。
A4: 公司期初余额 | C4: 期间收款合计 | E4: 期间付款合计 | G4: 期末结余金额
B5: =SUM(B8:B21) -> 719880.9 | D5: =SUM(BM8:BM21) -> 13739232 | F5: =SUM(BN8:BN21) -> 13815171 | H5: =SUM(BO8:BO21) -> 643942.29
C6: =IF(1<=MIN($H$2,31),$B$2+0,"") -> 46204 | D6: =IF(1<=MIN($H$2,31),$B$2+0,"") -> 46204 | E6: =IF(2<=MIN($H$2,31),$B$2+1,"") -> 46205 | F6: =IF(2<=MIN($H$2,31),$B$2+1,"") -> 46205 | G6: =IF(3<=MIN($H$2,31),$B$2+2,"") -> 46206 | H6: =IF(3<=MIN($H$2,31),$B$2+2,"") -> 46206 | I6: =IF(4<=MIN($H$2,31),$B$2+3,"") -> 46207 | J6: =IF(4<=MIN($H$2,31),$B$2+3,"") -> 46207 | K6: =IF(5<=MIN($H$2,31),$B$2+4,"") -> 46208 | L6: =IF(5<=MIN($H$2,31),$B$2+4,"") -> 46208 | M6: =IF(6<=MIN($H$2,31),$B$2+5,"") -> 46209 | N6: =IF(6<=MIN($H$2,31),$B$2+5,"") -> 46209 | O6: =IF(7<=MIN($H$2,31),$B$2+6,"") -> 46210 | P6: =IF(7<=MIN($H$2,31),$B$2+6,"") -> 46210 | Q6: =IF(8<=MIN($H$2,31),$B$2+7,"") -> 46211 | R6: =IF(8<=MIN($H$2,31),$B$2+7,"") -> 46211 | S6: =IF(9<=MIN($H$2,31),$B$2+8,"") -> 46212 | T6: =IF(9<=MIN($H$2,31),$B$2+8,"") -> 46212 | U6: =IF(10<=MIN($H$2,31),$B$2+9,"") -> 46213 | V6: =IF(10<=MIN($H$2,31),$B$2+9,"") -> 46213 | W6: =IF(11<=MIN($H$2,31),$B$2+10,"") -> 46214 | X6: =IF(11<=MIN($H$2,31),$B$2+10,"") -> 46214 | Y6: =IF(12<=MIN($H$2,31),$B$2+11,"") -> 46215 | Z6: =IF(12<=MIN($H$2,31),$B$2+11,"") -> 46215 | AA6: =IF(13<=MIN($H$2,31),$B$2+12,"") -> 46216 | AB6: =IF(13<=MIN($H$2,31),$B$2+12,"") -> 46216 | AC6: =IF(14<=MIN($H$2,31),$B$2+13,"") -> 46217 | AD6: =IF(14<=MIN($H$2,31),$B$2+13,"") -> 46217 | AE6: =IF(15<=MIN($H$2,31),$B$2+14,"") -> 46218 | AF6: =IF(15<=MIN($H$2,31),$B$2+14,"") -> 46218 | AG6: =IF(16<=MIN($H$2,31),$B$2+15,"") -> 46219 | AH6: =IF(16<=MIN($H$2,31),$B$2+15,"") -> 46219 | AI6: =IF(17<=MIN($H$2,31),$B$2+16,"") -> 46220 | AJ6: =IF(17<=MIN($H$2,31),$B$2+16,"") -> 46220 | AK6: =IF(18<=MIN($H$2,31),$B$2+17,"") -> 46221 | AL6: =IF(18<=MIN($H$2,31),$B$2+17,"") -> 46221 | AM6: =IF(19<=MIN($H$2,31),$B$2+18,"") -> 46222 | AN6: =IF(19<=MIN($H$2,31),$B$2+18,"") -> 46222 | AO6: =IF(20<=MIN($H$2,31),$B$2+19,"") -> 46223 | AP6: =IF(20<=MIN($H$2,31),$B$2+19,"") -> 46223 | AQ6: =IF(21<=MIN($H$2,31),$B$2+20,"") -> 46224 | AR6: =IF(21<=MIN($H$2,31),$B$2+20,"") -> 46224 | AS6: =IF(22<=MIN($H$2,31),$B$2+21,"") -> 46225 | AT6: =IF(22<=MIN($H$2,31),$B$2+21,"") -> 46225 | AU6: =IF(23<=MIN($H$2,31),$B$2+22,"") -> 46226 | AV6: =IF(23<=MIN($H$2,31),$B$2+22,"") -> 46226 | AW6: =IF(24<=MIN($H$2,31),$B$2+23,"") -> 46227 | AX6: =IF(24<=MIN($H$2,31),$B$2+23,"") -> 46227 | AY6: =IF(25<=MIN($H$2,31),$B$2+24,"") -> 46228 | AZ6: =IF(25<=MIN($H$2,31),$B$2+24,"") -> 46228 | BA6: =IF(26<=MIN($H$2,31),$B$2+25,"") -> 46229 | BB6: =IF(26<=MIN($H$2,31),$B$2+25,"") -> 46229 | BC6: =IF(27<=MIN($H$2,31),$B$2+26,"") -> 46230 | BD6: =IF(27<=MIN($H$2,31),$B$2+26,"") -> 46230 | BE6: =IF(28<=MIN($H$2,31),$B$2+27,"") -> 46231 | BF6: =IF(28<=MIN($H$2,31),$B$2+27,"") -> 46231 | BG6: =IF(29<=MIN($H$2,31),$B$2+28,"") -> 46232 | BH6: =IF(29<=MIN($H$2,31),$B$2+28,"") -> 46232 | BI6: =IF(30<=MIN($H$2,31),$B$2+29,"") -> 46233 | BJ6: =IF(30<=MIN($H$2,31),$B$2+29,"") -> 46233 | BK6: =IF(31<=MIN($H$2,31),$B$2+30,"") | BL6: =IF(31<=MIN($H$2,31),$B$2+30,"")
A7: 账户 | B7: 期初余额 | C7: =IF(C$6="","","收款") -> 收款 | D7: =IF(D$6="","","付款") -> 付款 | E7: =IF(E$6="","","收款") -> 收款 | F7: =IF(F$6="","","付款") -> 付款 | G7: =IF(G$6="","","收款") -> 收款 | H7: =IF(H$6="","","付款") -> 付款 | I7: =IF(I$6="","","收款") -> 收款 | J7: =IF(J$6="","","付款") -> 付款 | K7: =IF(K$6="","","收款") -> 收款 | L7: =IF(L$6="","","付款") -> 付款 | M7: =IF(M$6="","","收款") -> 收款 | N7: =IF(N$6="","","付款") -> 付款 | O7: =IF(O$6="","","收款") -> 收款 | P7: =IF(P$6="","","付款") -> 付款 | Q7: =IF(Q$6="","","收款") -> 收款 | R7: =IF(R$6="","","付款") -> 付款 | S7: =IF(S$6="","","收款") -> 收款 | T7: =IF(T$6="","","付款") -> 付款 | U7: =IF(U$6="","","收款") -> 收款 | V7: =IF(V$6="","","付款") -> 付款 | W7: =IF(W$6="","","收款") -> 收款 | X7: =IF(X$6="","","付款") -> 付款 | Y7: =IF(Y$6="","","收款") -> 收款 | Z7: =IF(Z$6="","","付款") -> 付款 | AA7: =IF(AA$6="","","收款") -> 收款 | AB7: =IF(AB$6="","","付款") -> 付款 | AC7: =IF(AC$6="","","收款") -> 收款 | AD7: =IF(AD$6="","","付款") -> 付款 | AE7: =IF(AE$6="","","收款") -> 收款 | AF7: =IF(AF$6="","","付款") -> 付款 | AG7: =IF(AG$6="","","收款") -> 收款 | AH7: =IF(AH$6="","","付款") -> 付款 | AI7: =IF(AI$6="","","收款") -> 收款 | AJ7: =IF(AJ$6="","","付款") -> 付款 | AK7: =IF(AK$6="","","收款") -> 收款 | AL7: =IF(AL$6="","","付款") -> 付款 | AM7: =IF(AM$6="","","收款") -> 收款 | AN7: =IF(AN$6="","","付款") -> 付款 | AO7: =IF(AO$6="","","收款") -> 收款 | AP7: =IF(AP$6="","","付款") -> 付款 | AQ7: =IF(AQ$6="","","收款") -> 收款 | AR7: =IF(AR$6="","","付款") -> 付款 | AS7: =IF(AS$6="","","收款") -> 收款 | AT7: =IF(AT$6="","","付款") -> 付款 | AU7: =IF(AU$6="","","收款") -> 收款 | AV7: =IF(AV$6="","","付款") -> 付款 | AW7: =IF(AW$6="","","收款") -> 收款 | AX7: =IF(AX$6="","","付款") -> 付款 | AY7: =IF(AY$6="","","收款") -> 收款 | AZ7: =IF(AZ$6="","","付款") -> 付款 | BA7: =IF(BA$6="","","收款") -> 收款 | BB7: =IF(BB$6="","","付款") -> 付款 | BC7: =IF(BC$6="","","收款") -> 收款 | BD7: =IF(BD$6="","","付款") -> 付款 | BE7: =IF(BE$6="","","收款") -> 收款 | BF7: =IF(BF$6="","","付款") -> 付款 | BG7: =IF(BG$6="","","收款") -> 收款 | BH7: =IF(BH$6="","","付款") -> 付款 | BI7: =IF(BI$6="","","收款") -> 收款 | BJ7: =IF(BJ$6="","","付款") -> 付款 | BK7: =IF(BK$6="","","收款") | BL7: =IF(BL$6="","","付款") | BM7: 收款合计 | BN7: 付款合计 | BO7: 期末余额
A8: 金辉稠州 | B8: =IF(OR($A8="",NOT(ISNUMBER($H$2))),"",SUMIFS(数据录入!$H$5:$H$785,数据录入!$C$5:$C$785,$A8,数据录入!$E$5:$E$785,"期初余额",数据录入!$B$5:$B$785,"<="&$B$2)+SUMIFS(数据录入!$F$5:$F$785,数据录入!$C$5:$C$785,$A8,数据录入!$B$5:$B$785,"<"&$B$2)-SUMIFS(数据录入!$G$5:$G$785,数据录入!$C$5:$C$785,$A8,数据录入!$B$5:$B$785,"<"&$B$2)) -> 219263.12 | C8: =IF(OR($A8="",C$6="",NOT(ISNUMBER($H$2))),"",SUMIFS(数据录入!$F$5:$F$785,数据录入!$C$5:$C$785,$A8,数据录入!$B$5:$B$785,C$6)) -> 0 | D8: =IF(OR($A8="",D$6="",NOT(ISNUMBER($H$2))),"",SUMIFS(数据录入!$G$5:$G$785,数据录入!$C$5:$C$785,$A8,数据录入!$B$5:$B$785,D$6)) -> 596 | E8: =IF(OR($A8="",E$6="",NOT(ISNUMBER($H$2))),"",SUMIFS(数据录入!$F$5:$F$785,数据录入!$C$5:$C$785,$A8,数据录入!$B$5:$B$785,E$6)) -> 0 | F8: =IF(OR($A8="",F$6="",NOT(ISNUMBER($H$2))),"",SUMIFS(数据录入!$G$5:$G$785,数据录入!$C$5:$C$785,$A8,数据录入!$B$5:$B$785,F$6)) -> 0 | G8: =IF(OR($A8="",G$6="",NOT(ISNUMBER($H$2))),"",SUMIFS(数据录入!$F$5:$F$785,数据录入!$C$5:$C$785,$A8,数据录入!$B$5:$B$785,G$6)) -> 0 | H8: =IF(OR($A8="",H$6="",NOT(ISNUMBER($H$2))),"",SUMIFS(数据录入!$G$5:$G$785,数据录入!$C$5:$C$785,$A8,数据录入!$B$5:$B$785,H$6)) -> 5500 | I8: =IF(OR($A8="",I$6="",NOT(ISNUMBER($H$2))),"",SUMIFS(数据录入!$F$5:$F$785,数据录入!$C$5:$C$785,$A8,数据录入!$B$5:$B$785,I$6)) -> 0 | J8: =IF(OR($A8="",J$6="",NOT(ISNUMBER($H$2))),"",SUMIFS(数据录入!$G$5:$G$785,数据录入!$C$5:$C$785,$A8,数据录入!$B$5:$B$785,J$6)) -> 0 | K8: =IF(OR($A8="",K$6="",NOT(ISNUMBER($H$2))),"",SUMIFS(数据录入!$F$5:$F$785,数据录入!$C$5:$C$785,$A8,数据录入!$B$5:$B$785,K$6)) -> 0 | L8: =IF(OR($A8="",L$6="",NOT(ISNUMBER($H$2))),"",SUMIFS(数据录入!$G$5:$G$785,数据录入!$C$5:$C$785,$A8,数据录入!$B$5:$B$785,L$6)) -> 0 | M8: =IF(OR($A8="",M$6="",NOT(ISNUMBER($H$2))),"",SUMIFS(数据录入!$F$5:$F$785,数据录入!$C$5:$C$785,$A8,数据录入!$B$5:$B$785,M$6)) -> 2000 | N8: =IF(OR($A8="",N$6="",NOT(ISNUMBER($H$2))),"",SUMIFS(数据录入!$G$5:$G$785,数据录入!$C$5:$C$785,$A8,数据录入!$B$5:$B$785,N$6)) -> 0 | O8: =IF(OR($A8="",O$6="",NOT(ISNUMBER($H$2))),"",SUMIFS(数据录入!$F$5:$F$785,数据录入!$C$5:$C$785,$A8,数据录入!$B$5:$B$785,O$6)) -> 1000 | P8: =IF(OR($A8="",P$6="",NOT(ISNUMBER($H$2))),"",SUMIFS(数据录入!$G$5:$G$785,数据录入!$C$5:$C$785,$A8,数据录入!$B$5:$B$785,P$6)) -> 50000 | Q8: =IF(OR($A8="",Q$6="",NOT(ISNUMBER($H$2))),"",SUMIFS(数据录入!$F$5:$F$785,数据录入!$C$5:$C$785,$A8,数据录入!$B$5:$B$785,Q$6)) -> 9000 | R8: =IF(OR($A8="",R$6="",NOT(ISNUMBER($H$2))),"",SUMIFS(数据录入!$G$5:$G$785,数据录入!$C$5:$C$785,$A8,数据录入!$B$5:$B$785,R$6)) -> 0 | S8: =IF(OR($A8="",S$6="",NOT(ISNUMBER($H$2))),"",SUMIFS(数据录入!$F$5:$F$785,数据录入!$C$5:$C$785,$A8,数据录入!$B$5:$B$785,S$6)) -> 0 | T8: =IF(OR($A8="",T$6="",NOT(ISNUMBER($H$2))),"",SUMIFS(数据录入!$G$5:$G$785,数据录入!$C$5:$C$785,$A8,数据录入!$B$5:$B$785,T$6)) -> 150000 | U8: =IF(OR($A8="",U$6="",NOT(ISNUMBER($H$2))),"",SUMIFS(数据录入!$F$5:$F$785,数据录入!$C$5:$C$785,$A8,数据录入!$B$5:$B$785,U$6)) -> 90 | V8: =IF(OR($A8="",V$6="",NOT(ISNUMBER($H$2))),"",SUMIFS(数据录入!$G$5:$G$785,数据录入!$C$5:$C$785,$A8,数据录入!$B$5:$B$785,V$6)) -> 17.5 | W8: =IF(OR($A8="",W$6="",NOT(ISNUMBER($H$2))),"",SUMIFS(数据录入!$F$5:$F$785,数据录入!$C$5:$C$785,$A8,数据录入!$B$5:$B$785,W$6)) -> 0 | X8: =IF(OR($A8="",X$6="",NOT(ISNUMBER($H$2))),"",SUMIFS(数据录入!$G$5:$G$785,数据录入!$C$5:$C$785,$A8,数据录入!$B$5:$B$785,X$6)) -> 0 | Y8: =IF(OR($A8="",Y$6="",NOT(ISNUMBER($H$2))),"",SUMIFS(数据录入!$F$5:$F$785,数据录入!$C$5:$C$785,$A8,数据录入!$B$5:$B$785,Y$6)) -> 0 | Z8: =IF(OR($A8="",Z$6="",NOT(ISNUMBER($H$2))),"",SUMIFS(数据录入!$G$5:$G$785,数据录入!$C$5:$C$785,$A8,数据录入!$B$5:$B$785,Z$6)) -> 0 | AA8: =IF(OR($A8="",AA$6="",NOT(ISNUMBER($H$2))),"",SUMIFS(数据录入!$F$5:$F$785,数据录入!$C$5:$C$785,$A8,数据录入!$B$5:$B$785,AA$6)) -> 12500 | AB8: =IF(OR($A8="",AB$6="",NOT(ISNUMBER($H$2))),"",SUMIFS(数据录入!$G$5:$G$785,数据录入!$C$5:$C$785,$A8,数据录入!$B$5:$B$785,AB$6)) -> 0 | AC8: =IF(OR($A8="",AC$6="",NOT(ISNUMBER($H$2))),"",SUMIFS(数据录入!$F$5:$F$785,数据录入!$C$5:$C$785,$A8,数据录入!$B$5:$B$785,AC$6)) -> 5200 | AD8: =IF(OR($A8="",AD$6="",NOT(ISNUMBER($H$2))),"",SUMIFS(数据录入!$G$5:$G$785,数据录入!$C$5:$C$785,$A8,数据录入!$B$5:$B$785,AD$6)) -> 0 | AE8: =IF(OR($A8="",AE$6="",NOT(ISNUMBER($H$2))),"",SUMIFS(数据录入!$F$5:$F$785,数据录入!$C$5:$C$785,$A8,数据录入!$B$5:$B$785,AE$6)) -> 9380 | AF8: =IF(OR($A8="",AF$6="",NOT(ISNUMBER($H$2))),"",SUMIFS(数据录入!$G$5:$G$785,数据录入!$C$5:$C$785,$A8,数据录入!$B$5:$B$785,AF$6)) -> 29687.36 | AG8: =IF(OR($A8="",AG$6="",NOT(ISNUMBER($H$2))),"",SUMIFS(数据录入!$F$5:$F$785,数据录入!$C$5:$C$785,$A8,数据录入!$B$5:$B$785,AG$6)) -> 380000 | AH8: =IF(OR($A8="",AH$6="",NOT(ISNUMBER($H$2))),"",SUMIFS(数据录入!$G$5:$G$785,数据录入!$C$5:$C$785,$A8,数据录入!$B$5:$B$785,AH$6)) -> 400000 | AI8: =IF(OR($A8="",AI$6="",NOT(ISNUMBER($H$2))),"",SUMIFS(数据录入!$F$5:$F$785,数据录入!$C$5:$C$785,$A8,数据录入!$B$5:$B$785,AI$6)) -> 0 | AJ8: =IF(OR($A8="",AJ$6="",NOT(ISNUMBER($H$2))),"",SUMIFS(数据录入!$G$5:$G$785,数据录入!$C$5:$C$785,$A8,数据录入!$B$5:$B$785,AJ$6)) -> 0 | AK8: =IF(OR($A8="",AK$6="",NOT(ISNUMBER($H$2))),"",SUMIFS(数据录入!$F$5:$F$785,数据录入!$C$5:$C$785,$A8,数据录入!$B$5:$B$785,AK$6)) -> 0 | AL8: =IF(OR($A8="",AL$6="",NOT(ISNUMBER($H$2))),"",SUMIFS(数据录入!$G$5:$G$785,数据录入!$C$5:$C$785,$A8,数据录入!$B$5:$B$785,AL$6)) -> 0 | AM8: =IF(OR($A8="",AM$6="",NOT(ISNUMBER($H$2))),"",SUMIFS(数据录入!$F$5:$F$785,数据录入!$C$5:$C$785,$A8,数据录入!$B$5:$B$785,AM$6)) -> 0 | AN8: =IF(OR($A8="",AN$6="",NOT(ISNUMBER($H$2))),"",SUMIFS(数据录入!$G$5:$G$785,数据录入!$C$5:$C$785,$A8,数据录入!$B$5:$B$785,AN$6)) -> 0 | AO8: =IF(OR($A8="",AO$6="",NOT(ISNUMBER($H$2))),"",SUMIFS(数据录入!$F$5:$F$785,数据录入!$C$5:$C$785,$A8,数据录入!$B$5:$B$785,AO$6)) -> 230000 | AP8: =IF(OR($A8="",AP$6="",NOT(ISNUMBER($H$2))),"",SUMIFS(数据录入!$G$5:$G$785,数据录入!$C$5:$C$785,$A8,数据录入!$B$5:$B$785,AP$6)) -> 225000 | AQ8: =IF(OR($A8="",AQ$6="",NOT(ISNUMBER($H$2))),"",SUMIFS(数据录入!$F$5:$F$785,数据录入!$C$5:$C$785,$A8,数据录入!$B$5:$B$785,AQ$6)) -> 1000 | AR8: =IF(OR($A8="",AR$6="",NOT(ISNUMBER($H$2))),"",SUMIFS(数据录入!$G$5:$G$785,数据录入!$C$5:$C$785,$A8,数据录入!$B$5:$B$785,AR$6)) -> 6038.16 | AS8: =IF(OR($A8="",AS$6="",NOT(ISNUMBER($H$2))),"",SUMIFS(数据录入!$F$5:$F$785,数据录入!$C$5:$C$785,$A8,数据录入!$B$5:$B$785,AS$6)) -> 0 | AT8: =IF(OR($A8="",AT$6="",NOT(ISNUMBER($H$2))),"",SUMIFS(数据录入!$G$5:$G$785,数据录入!$C$5:$C$785,$A8,数据录入!$B$5:$B$785,AT$6)) -> 0 | AU8: =IF(OR($A8="",AU$6="",NOT(ISNUMBER($H$2))),"",SUMIFS(数据录入!$F$5:$F$785,数据录入!$C$5:$C$785,$A8,数据录入!$B$5:$B$785,AU$6)) -> 153125 | AV8: =IF(OR($A8="",AV$6="",NOT(ISNUMBER($H$2))),"",SUMIFS(数据录入!$G$5:$G$785,数据录入!$C$5:$C$785,$A8,数据录入!$B$5:$B$785,AV$6)) -> 17000 | AW8: =IF(OR($A8="",AW$6="",NOT(ISNUMBER($H$2))),"",SUMIFS(数据录入!$F$5:$F$785,数据录入!$C$5:$C$785,$A8,数据录入!$B$5:$B$785,AW$6)) -> 2500 | AX8: =IF(OR($A8="",AX$6="",NOT(ISNUMBER($H$2))),"",SUMIFS(数据录入!$G$5:$G$785,数据录入!$C$5:$C$785,$A8,数据录入!$B$5:$B$785,AX$6)) -> 0 | AY8: =IF(OR($A8="",AY$6="",NOT(ISNUMBER($H$2))),"",SUMIFS(数据录入!$F$5:$F$785,数据录入!$C$5:$C$785,$A8,数据录入!$B$5:$B$785,AY$6)) -> 0 | AZ8: =IF(OR($A8="",AZ$6="",NOT(ISNUMBER($H$2))),"",SUMIFS(数据录入!$G$5:$G$785,数据录入!$C$5:$C$785,$A8,数据录入!$B$5:$B$785,AZ$6)) -> 0 | BA8: =IF(OR($A8="",BA$6="",NOT(ISNUMBER($H$2))),"",SUMIFS(数据录入!$F$5:$F$785,数据录入!$C$5:$C$785,$A8,数据录入!$B$5:$B$785,BA$6)) -> 0 | BB8: =IF(OR($A8="",BB$6="",NOT(ISNUMBER($H$2))),"",SUMIFS(数据录入!$G$5:$G$785,数据录入!$C$5:$C$785,$A8,数据录入!$B$5:$B$785,BB$6)) -> 0 | BC8: =IF(OR($A8="",BC$6="",NOT(ISNUMBER($H$2))),"",SUMIFS(数据录入!$F$5:$F$785,数据录入!$C$5:$C$785,$A8,数据录入!$B$5:$B$785,BC$6)) -> 75033.34 | BD8: =IF(OR($A8="",BD$6="",NOT(ISNUMBER($H$2))),"",SUMIFS(数据录入!$G$5:$G$785,数据录入!$C$5:$C$785,$A8,数据录入!$B$5:$B$785,BD$6)) -> 200000 | BE8: =IF(OR($A8="",BE$6="",NOT(ISNUMBER($H$2))),"",SUMIFS(数据录入!$F$5:$F$785,数据录入!$C$5:$C$785,$A8,数据录入!$B$5:$B$785,BE$6)) -> 0 | BF8: =IF(OR($A8="",BF$6="",NOT(ISNUMBER($H$2))),"",SUMIFS(数据录入!$G$5:$G$785,数据录入!$C$5:$C$785,$A8,数据录入!$B$5:$B$785,BF$6)) -> 0 | BG8: =IF(OR($A8="",BG$6="",NOT(ISNUMBER($H$2))),"",SUMIFS(数据录入!$F$5:$F$785,数据录入!$C$5:$C$785,$A8,数据录入!$B$5:$B$785,BG$6)) -> 0 | BH8: =IF(OR($A8="",BH$6="",NOT(ISNUMBER($H$2))),"",SUMIFS(数据录入!$G$5:$G$785,数据录入!$C$5:$C$785,$A8,数据录入!$B$5:$B$785,BH$6)) -> 0 | BI8: =IF(OR($A8="",BI$6="",NOT(ISNUMBER($H$2))),"",SUMIFS(数据录入!$F$5:$F$785,数据录入!$C$5:$C$785,$A8,数据录入!$B$5:$B$785,BI$6)) -> 2000 | BJ8: =IF(OR($A8="",BJ$6="",NOT(ISNUMBER($H$2))),"",SUMIFS(数据录入!$G$5:$G$785,数据录入!$C$5:$C$785,$A8,数据录入!$B$5:$B$785,BJ$6)) -> 490.3 | BK8: =IF(OR($A8="",BK$6="",NOT(ISNUMBER($H$2))),"",SUMIFS(数据录入!$F$5:$F$785,数据录入!$C$5:$C$785,$A8,数据录入!$B$5:$B$785,BK$6)) | BL8: =IF(OR($A8="",BL$6="",NOT(ISNUMBER($H$2))),"",SUMIFS(数据录入!$G$5:$G$785,数据录入!$C$5:$C$785,$A8,数据录入!$B$5:$B$785,BL$6)) | BM8: =IF($A8="","",SUMIF($C$7:$BL$7,"收款",C8:BL8)) -> 882828.34 | BN8: =IF($A8="","",SUMIF($C$7:$BL$7,"付款",C8:BL8)) -> 1084329.3 | BO8: =IF($A8="","",B8+BM8-BN8) -> 17762.14
A9: 典当微信 | B9: =IF(OR($A9="",NOT(ISNUMBER($H$2))),"",SUMIFS(数据录入!$H$5:$H$785,数据录入!$C$5:$C$785,$A9,数据录入!$E$5:$E$785,"期初余额",数据录入!$B$5:$B$785,"<="&$B$2)+SUMIFS(数据录入!$F$5:$F$785,数据录入!$C$5:$C$785,$A9,数据录入!$B$5:$B$785,"<"&$B$2)-SUMIFS(数据录入!$G$5:$G$785,数据录入!$C$5:$C$785,$A9,数据录入!$B$5:$B$785,"<"&$B$2)) -> 112326.39 | C9: =IF(OR($A9="",C$6="",NOT(ISNUMBER($H$2))),"",SUMIFS(数据录入!$F$5:$F$785,数据录入!$C$5:$C$785,$A9,数据录入!$B$5:$B$785,C$6)) -> 2480 | D9: =IF(OR($A9="",D$6="",NOT(ISNUMBER($H$2))),"",SUMIFS(数据录入!$G$5:$G$785,数据录入!$C$5:$C$785,$A9,数据录入!$B$5:$B$785,D$6)) -> 52480 | E9: =IF(OR($A9="",E$6="",NOT(ISNUMBER($H$2))),"",SUMIFS(数据录入!$F$5:$F$785,数据录入!$C$5:$C$785,$A9,数据录入!$B$5:$B$785,E$6)) -> 0 | F9: =IF(OR($A9="",F$6="",NOT(ISNUMBER($H$2))),"",SUMIFS(数据录入!$G$5:$G$785,数据录入!$C$5:$C$785,$A9,数据录入!$B$5:$B$785,F$6)) -> 0 | G9: =IF(OR($A9="",G$6="",NOT(ISNUMBER($H$2))),"",SUMIFS(数据录入!$F$5:$F$785,数据录入!$C$5:$C$785,$A9,数据录入!$B$5:$B$785,G$6)) -> 400 | H9: =IF(OR($A9="",H$6="",NOT(ISNUMBER($H$2))),"",SUMIFS(数据录入!$G$5:$G$785,数据录入!$C$5:$C$785,$A9,数据录入!$B$5:$B$785,H$6)) -> 13000 | I9: =IF(OR($A9="",I$6="",NOT(ISNUMBER($H$2))),"",SUMIFS(数据录入!$F$5:$F$785,数据录入!$C$5:$C$785,$A9,数据录入!$B$5:$B$785,I$6)) -> 2250 | J9: =IF(OR($A9="",J$6="",NOT(ISNUMBER($H$2))),"",SUMIFS(数据录入!$G$5:$G$785,数据录入!$C$5:$C$785,$A9,数据录入!$B$5:$B$785,J$6)) -> 0 | K9: =IF(OR($A9="",K$6="",NOT(ISNUMBER($H$2))),"",SUMIFS(数据录入!$F$5:$F$785,数据录入!$C$5:$C$785,$A9,数据录入!$B$5:$B$785,K$6)) -> 1290 | L9: =IF(OR($A9="",L$6="",NOT(ISNUMBER($H$2))),"",SUMIFS(数据录入!$G$5:$G$785,数据录入!$C$5:$C$785,$A9,数据录入!$B$5:$B$785,L$6)) -> 0 | M9: =IF(OR($A9="",M$6="",NOT(ISNUMBER($H$2))),"",SUMIFS(数据录入!$F$5:$F$785,数据录入!$C$5:$C$785,$A9,数据录入!$B$5:$B$785,M$6)) -> 300 | N9: =IF(OR($A9="",N$6="",NOT(ISNUMBER($H$2))),"",SUMIFS(数据录入!$G$5:$G$785,数据录入!$C$5:$C$785,$A9,数据录入!$B$5:$B$785,N$6)) -> 3600 | O9: =IF(OR($A9="",O$6="",NOT(ISNUMBER($H$2))),"",SUMIFS(数据录入!$F$5:$F$785,数据录入!$C$5:$C$785,$A9,数据录入!$B$5:$B$785,O$6)) -> 850 | P9: =IF(OR($A9="",P$6="",NOT(ISNUMBER($H$2))),"",SUMIFS(数据录入!$G$5:$G$785,数据录入!$C$5:$C$785,$A9,数据录入!$B$5:$B$785,P$6)) -> 2143 | Q9: =IF(OR($A9="",Q$6="",NOT(ISNUMBER($H$2))),"",SUMIFS(数据录入!$F$5:$F$785,数据录入!$C$5:$C$785,$A9,数据录入!$B$5:$B$785,Q$6)) -> 8700 | R9: =IF(OR($A9="",R$6="",NOT(ISNUMBER($H$2))),"",SUMIFS(数据录入!$G$5:$G$785,数据录入!$C$5:$C$785,$A9,数据录入!$B$5:$B$785,R$6)) -> 0 | S9: =IF(OR($A9="",S$6="",NOT(ISNUMBER($H$2))),"",SUMIFS(数据录入!$F$5:$F$785,数据录入!$C$5:$C$785,$A9,数据录入!$B$5:$B$785,S$6)) -> 4200 | T9: =IF(OR($A9="",T$6="",NOT(ISNUMBER($H$2))),"",SUMIFS(数据录入!$G$5:$G$785,数据录入!$C$5:$C$785,$A9,数据录入!$B$5:$B$785,T$6)) -> 0 | U9: =IF(OR($A9="",U$6="",NOT(ISNUMBER($H$2))),"",SUMIFS(数据录入!$F$5:$F$785,数据录入!$C$5:$C$785,$A9,数据录入!$B$5:$B$785,U$6)) -> 12540 | V9: =IF(OR($A9="",V$6="",NOT(ISNUMBER($H$2))),"",SUMIFS(数据录入!$G$5:$G$785,数据录入!$C$5:$C$785,$A9,数据录入!$B$5:$B$785,V$6)) -> 0 | W9: =IF(OR($A9="",W$6="",NOT(ISNUMBER($H$2))),"",SUMIFS(数据录入!$F$5:$F$785,数据录入!$C$5:$C$785,$A9,数据录入!$B$5:$B$785,W$6)) -> 1650 | X9: =IF(OR($A9="",X$6="",NOT(ISNUMBER($H$2))),"",SUMIFS(数据录入!$G$5:$G$785,数据录入!$C$5:$C$785,$A9,数据录入!$B$5:$B$785,X$6)) -> 0 | Y9: =IF(OR($A9="",Y$6="",NOT(ISNUMBER($H$2))),"",SUMIFS(数据录入!$F$5:$F$785,数据录入!$C$5:$C$785,$A9,数据录入!$B$5:$B$785,Y$6)) -> 3000 | Z9: =IF(OR($A9="",Z$6="",NOT(ISNUMBER($H$2))),"",SUMIFS(数据录入!$G$5:$G$785,数据录入!$C$5:$C$785,$A9,数据录入!$B$5:$B$785,Z$6)) -> 0 | AA9: =IF(OR($A9="",AA$6="",NOT(ISNUMBER($H$2))),"",SUMIFS(数据录入!$F$5:$F$785,数据录入!$C$5:$C$785,$A9,数据录入!$B$5:$B$785,AA$6)) -> 19465 | AB9: =IF(OR($A9="",AB$6="",NOT(ISNUMBER($H$2))),"",SUMIFS(数据录入!$G$5:$G$785,数据录入!$C$5:$C$785,$A9,数据录入!$B$5:$B$785,AB$6)) -> 0 | AC9: =IF(OR($A9="",AC$6="",NOT(ISNUMBER($H$2))),"",SUMIFS(数据录入!$F$5:$F$785,数据录入!$C$5:$C$785,$A9,数据录入!$B$5:$B$785,AC$6)) -> 5015 | AD9: =IF(OR($A9="",AD$6="",NOT(ISNUMBER($H$2))),"",SUMIFS(数据录入!$G$5:$G$785,数据录入!$C$5:$C$785,$A9,数据录入!$B$5:$B$785,AD$6)) -> 1566 | AE9: =IF(OR($A9="",AE$6="",NOT(ISNUMBER($H$2))),"",SUMIFS(数据录入!$F$5:$F$785,数据录入!$C$5:$C$785,$A9,数据录入!$B$5:$B$785,AE$6)) -> 5500 | AF9: =IF(OR($A9="",AF$6="",NOT(ISNUMBER($H$2))),"",SUMIFS(数据录入!$G$5:$G$785,数据录入!$C$5:$C$785,$A9,数据录入!$B$5:$B$785,AF$6)) -> 0 | AG9: =IF(OR($A9="",AG$6="",NOT(ISNUMBER($H$2))),"",SUMIFS(数据录入!$F$5:$F$785,数据录入!$C$5:$C$785,$A9,数据录入!$B$5:$B$785,AG$6)) -> 150 | AH9: =IF(OR($A9="",AH$6="",NOT(ISNUMBER($H$2))),"",SUMIFS(数据录入!$G$5:$G$785,数据录入!$C$5:$C$785,$A9,数据录入!$B$5:$B$785,AH$6)) -> 0 | AI9: =IF(OR($A9="",AI$6="",NOT(ISNUMBER($H$2))),"",SUMIFS(数据录入!$F$5:$F$785,数据录入!$C$5:$C$785,$A9,数据录入!$B$5:$B$785,AI$6)) -> 2900 | AJ9: =IF(OR($A9="",AJ$6="",NOT(ISNUMBER($H$2))),"",SUMIFS(数据录入!$G$5:$G$785,数据录入!$C$5:$C$785,$A9,数据录入!$B$5:$B$785,AJ$6)) -> 0 | AK9: =IF(OR($A9="",AK$6="",NOT(ISNUMBER($H$2))),"",SUMIFS(数据录入!$F$5:$F$785,数据录入!$C$5:$C$785,$A9,数据录入!$B$5:$B$785,AK$6)) -> 4000 | AL9: =IF(OR($A9="",AL$6="",NOT(ISNUMBER($H$2))),"",SUMIFS(数据录入!$G$5:$G$785,数据录入!$C$5:$C$785,$A9,数据录入!$B$5:$B$785,AL$6)) -> 0 | AM9: =IF(OR($A9="",AM$6="",NOT(ISNUMBER($H$2))),"",SUMIFS(数据录入!$F$5:$F$785,数据录入!$C$5:$C$785,$A9,数据录入!$B$5:$B$785,AM$6)) -> 1125 | AN9: =IF(OR($A9="",AN$6="",NOT(ISNUMBER($H$2))),"",SUMIFS(数据录入!$G$5:$G$785,数据录入!$C$5:$C$785,$A9,数据录入!$B$5:$B$785,AN$6)) -> 0 | AO9: =IF(OR($A9="",AO$6="",NOT(ISNUMBER($H$2))),"",SUMIFS(数据录入!$F$5:$F$785,数据录入!$C$5:$C$785,$A9,数据录入!$B$5:$B$785,AO$6)) -> 7650 | AP9: =IF(OR($A9="",AP$6="",NOT(ISNUMBER($H$2))),"",SUMIFS(数据录入!$G$5:$G$785,数据录入!$C$5:$C$785,$A9,数据录入!$B$5:$B$785,AP$6)) -> 8880 | AQ9: =IF(OR($A9="",AQ$6="",NOT(ISNUMBER($H$2))),"",SUMIFS(数据录入!$F$5:$F$785,数据录入!$C$5:$C$785,$A9,数据录入!$B$5:$B$785,AQ$6)) -> 7500 | AR9: =IF(OR($A9="",AR$6="",NOT(ISNUMBER($H$2))),"",SUMIFS(数据录入!$G$5:$G$785,数据录入!$C$5:$C$785,$A9,数据录入!$B$5:$B$785,AR$6)) -> 0 | AS9: =IF(OR($A9="",AS$6="",NOT(ISNUMBER($H$2))),"",SUMIFS(数据录入!$F$5:$F$785,数据录入!$C$5:$C$785,$A9,数据录入!$B$5:$B$785,AS$6)) -> 970 | AT9: =IF(OR($A9="",AT$6="",NOT(ISNUMBER($H$2))),"",SUMIFS(数据录入!$G$5:$G$785,数据录入!$C$5:$C$785,$A9,数据录入!$B$5:$B$785,AT$6)) -> 0 | AU9: =IF(OR($A9="",AU$6="",NOT(ISNUMBER($H$2))),"",SUMIFS(数据录入!$F$5:$F$785,数据录入!$C$5:$C$785,$A9,数据录入!$B$5:$B$785,AU$6)) -> 2325 | AV9: =IF(OR($A9="",AV$6="",NOT(ISNUMBER($H$2))),"",SUMIFS(数据录入!$G$5:$G$785,数据录入!$C$5:$C$785,$A9,数据录入!$B$5:$B$785,AV$6)) -> 0 | AW9: =IF(OR($A9="",AW$6="",NOT(ISNUMBER($H$2))),"",SUMIFS(数据录入!$F$5:$F$785,数据录入!$C$5:$C$785,$A9,数据录入!$B$5:$B$785,AW$6)) -> 6630 | AX9: =IF(OR($A9="",AX$6="",NOT(ISNUMBER($H$2))),"",SUMIFS(数据录入!$G$5:$G$785,数据录入!$C$5:$C$785,$A9,数据录入!$B$5:$B$785,AX$6)) -> 0 | AY9: =IF(OR($A9="",AY$6="",NOT(ISNUMBER($H$2))),"",SUMIFS(数据录入!$F$5:$F$785,数据录入!$C$5:$C$785,$A9,数据录入!$B$5:$B$785,AY$6)) -> 0 | AZ9: =IF(OR($A9="",AZ$6="",NOT(ISNUMBER($H$2))),"",SUMIFS(数据录入!$G$5:$G$785,数据录入!$C$5:$C$785,$A9,数据录入!$B$5:$B$785,AZ$6)) -> 0 | BA9: =IF(OR($A9="",BA$6="",NOT(ISNUMBER($H$2))),"",SUMIFS(数据录入!$F$5:$F$785,数据录入!$C$5:$C$785,$A9,数据录入!$B$5:$B$785,BA$6)) -> 0 | BB9: =IF(OR($A9="",BB$6="",NOT(ISNUMBER($H$2))),"",SUMIFS(数据录入!$G$5:$G$785,数据录入!$C$5:$C$785,$A9,数据录入!$B$5:$B$785,BB$6)) -> 0 | BC9: =IF(OR($A9="",BC$6="",NOT(ISNUMBER($H$2))),"",SUMIFS(数据录入!$F$5:$F$785,数据录入!$C$5:$C$785,$A9,数据录入!$B$5:$B$785,BC$6)) -> 5275 | BD9: =IF(OR($A9="",BD$6="",NOT(ISNUMBER($H$2))),"",SUMIFS(数据录入!$G$5:$G$785,数据录入!$C$5:$C$785,$A9,数据录入!$B$5:$B$785,BD$6)) -> 16000 | BE9: =IF(OR($A9="",BE$6="",NOT(ISNUMBER($H$2))),"",SUMIFS(数据录入!$F$5:$F$785,数据录入!$C$5:$C$785,$A9,数据录入!$B$5:$B$785,BE$6)) -> 2575 | BF9: =IF(OR($A9="",BF$6="",NOT(ISNUMBER($H$2))),"",SUMIFS(数据录入!$G$5:$G$785,数据录入!$C$5:$C$785,$A9,数据录入!$B$5:$B$785,BF$6)) -> 0 | BG9: =IF(OR($A9="",BG$6="",NOT(ISNUMBER($H$2))),"",SUMIFS(数据录入!$F$5:$F$785,数据录入!$C$5:$C$785,$A9,数据录入!$B$5:$B$785,BG$6)) -> 0 | BH9: =IF(OR($A9="",BH$6="",NOT(ISNUMBER($H$2))),"",SUMIFS(数据录入!$G$5:$G$785,数据录入!$C$5:$C$785,$A9,数据录入!$B$5:$B$785,BH$6)) -> 0 | BI9: =IF(OR($A9="",BI$6="",NOT(ISNUMBER($H$2))),"",SUMIFS(数据录入!$F$5:$F$785,数据录入!$C$5:$C$785,$A9,数据录入!$B$5:$B$785,BI$6)) -> 6100 | BJ9: =IF(OR($A9="",BJ$6="",NOT(ISNUMBER($H$2))),"",SUMIFS(数据录入!$G$5:$G$785,数据录入!$C$5:$C$785,$A9,数据录入!$B$5:$B$785,BJ$6)) -> 30000 | BK9: =IF(OR($A9="",BK$6="",NOT(ISNUMBER($H$2))),"",SUMIFS(数据录入!$F$5:$F$785,数据录入!$C$5:$C$785,$A9,数据录入!$B$5:$B$785,BK$6)) | BL9: =IF(OR($A9="",BL$6="",NOT(ISNUMBER($H$2))),"",SUMIFS(数据录入!$G$5:$G$785,数据录入!$C$5:$C$785,$A9,数据录入!$B$5:$B$785,BL$6)) | BM9: =IF($A9="","",SUMIF($C$7:$BL$7,"收款",C9:BL9)) -> 114840 | BN9: =IF($A9="","",SUMIF($C$7:$BL$7,"付款",C9:BL9)) -> 127669 | BO9: =IF($A9="","",B9+BM9-BN9) -> 99497.39
A10: 林总浦发 | B10: =IF(OR($A10="",NOT(ISNUMBER($H$2))),"",SUMIFS(数据录入!$H$5:$H$785,数据录入!$C$5:$C$785,$A10,数据录入!$E$5:$E$785,"期初余额",数据录入!$B$5:$B$785,"<="&$B$2)+SUMIFS(数据录入!$F$5:$F$785,数据录入!$C$5:$C$785,$A10,数据录入!$B$5:$B$785,"<"&$B$2)-SUMIFS(数据录入!$G$5:$G$785,数据录入!$C$5:$C$785,$A10,数据录入!$B$5:$B$785,"<"&$B$2)) -> 73513.15 | C10: =IF(OR($A10="",C$6="",NOT(ISNUMBER($H$2))),"",SUMIFS(数据录入!$F$5:$F$785,数据录入!$C$5:$C$785,$A10,数据录入!$B$5:$B$785,C$6)) -> 2240000 | D10: =IF(OR($A10="",D$6="",NOT(ISNUMBER($H$2))),"",SUMIFS(数据录入!$G$5:$G$785,数据录入!$C$5:$C$785,$A10,数据录入!$B$5:$B$785,D$6)) -> 2300000 | E10: =IF(OR($A10="",E$6="",NOT(ISNUMBER($H$2))),"",SUMIFS(数据录入!$F$5:$F$785,数据录入!$C$5:$C$785,$A10,数据录入!$B$5:$B$785,E$6)) -> 515500 | F10: =IF(OR($A10="",F$6="",NOT(ISNUMBER($H$2))),"",SUMIFS(数据录入!$G$5:$G$785,数据录入!$C$5:$C$785,$A10,数据录入!$B$5:$B$785,F$6)) -> 520000 | G10: =IF(OR($A10="",G$6="",NOT(ISNUMBER($H$2))),"",SUMIFS(数据录入!$F$5:$F$785,数据录入!$C$5:$C$785,$A10,数据录入!$B$5:$B$785,G$6)) -> 0 | H10: =IF(OR($A10="",H$6="",NOT(ISNUMBER($H$2))),"",SUMIFS(数据录入!$G$5:$G$785,数据录入!$C$5:$C$785,$A10,数据录入!$B$5:$B$785,H$6)) -> 2400 | I10: =IF(OR($A10="",I$6="",NOT(ISNUMBER($H$2))),"",SUMIFS(数据录入!$F$5:$F$785,数据录入!$C$5:$C$785,$A10,数据录入!$B$5:$B$785,I$6)) -> 0 | J10: =IF(OR($A10="",J$6="",NOT(ISNUMBER($H$2))),"",SUMIFS(数据录入!$G$5:$G$785,数据录入!$C$5:$C$785,$A10,数据录入!$B$5:$B$785,J$6)) -> 0 | K10: =IF(OR($A10="",K$6="",NOT(ISNUMBER($H$2))),"",SUMIFS(数据录入!$F$5:$F$785,数据录入!$C$5:$C$785,$A10,数据录入!$B$5:$B$785,K$6)) -> 0 | L10: =IF(OR($A10="",L$6="",NOT(ISNUMBER($H$2))),"",SUMIFS(数据录入!$G$5:$G$785,数据录入!$C$5:$C$785,$A10,数据录入!$B$5:$B$785,L$6)) -> 0 | M10: =IF(OR($A10="",M$6="",NOT(ISNUMBER($H$2))),"",SUMIFS(数据录入!$F$5:$F$785,数据录入!$C$5:$C$785,$A10,数据录入!$B$5:$B$785,M$6)) -> 20000 | N10: =IF(OR($A10="",N$6="",NOT(ISNUMBER($H$2))),"",SUMIFS(数据录入!$G$5:$G$785,数据录入!$C$5:$C$785,$A10,数据录入!$B$5:$B$785,N$6)) -> 19100 | O10: =IF(OR($A10="",O$6="",NOT(ISNUMBER($H$2))),"",SUMIFS(数据录入!$F$5:$F$785,数据录入!$C$5:$C$785,$A10,数据录入!$B$5:$B$785,O$6)) -> 106333.33 | P10: =IF(OR($A10="",P$6="",NOT(ISNUMBER($H$2))),"",SUMIFS(数据录入!$G$5:$G$785,数据录入!$C$5:$C$785,$A10,数据录入!$B$5:$B$785,P$6)) -> 200000 | Q10: =IF(OR($A10="",Q$6="",NOT(ISNUMBER($H$2))),"",SUMIFS(数据录入!$F$5:$F$785,数据录入!$C$5:$C$785,$A10,数据录入!$B$5:$B$785,Q$6)) -> 200000 | R10: =IF(OR($A10="",R$6="",NOT(ISNUMBER($H$2))),"",SUMIFS(数据录入!$G$5:$G$785,数据录入!$C$5:$C$785,$A10,数据录入!$B$5:$B$785,R$6)) -> 0 | S10: =IF(OR($A10="",S$6="",NOT(ISNUMBER($H$2))),"",SUMIFS(数据录入!$F$5:$F$785,数据录入!$C$5:$C$785,$A10,数据录入!$B$5:$B$785,S$6)) -> 0 | T10: =IF(OR($A10="",T$6="",NOT(ISNUMBER($H$2))),"",SUMIFS(数据录入!$G$5:$G$785,数据录入!$C$5:$C$785,$A10,数据录入!$B$5:$B$785,T$6)) -> 30000 | U10: =IF(OR($A10="",U$6="",NOT(ISNUMBER($H$2))),"",SUMIFS(数据录入!$F$5:$F$785,数据录入!$C$5:$C$785,$A10,数据录入!$B$5:$B$785,U$6)) -> 90000 | V10: =IF(OR($A10="",V$6="",NOT(ISNUMBER($H$2))),"",SUMIFS(数据录入!$G$5:$G$785,数据录入!$C$5:$C$785,$A10,数据录入!$B$5:$B$785,V$6)) -> 154447 | W10: =IF(OR($A10="",W$6="",NOT(ISNUMBER($H$2))),"",SUMIFS(数据录入!$F$5:$F$785,数据录入!$C$5:$C$785,$A10,数据录入!$B$5:$B$785,W$6)) -> 0 | X10: =IF(OR($A10="",X$6="",NOT(ISNUMBER($H$2))),"",SUMIFS(数据录入!$G$5:$G$785,数据录入!$C$5:$C$785,$A10,数据录入!$B$5:$B$785,X$6)) -> 0 | Y10: =IF(OR($A10="",Y$6="",NOT(ISNUMBER($H$2))),"",SUMIFS(数据录入!$F$5:$F$785,数据录入!$C$5:$C$785,$A10,数据录入!$B$5:$B$785,Y$6)) -> 0 | Z10: =IF(OR($A10="",Z$6="",NOT(ISNUMBER($H$2))),"",SUMIFS(数据录入!$G$5:$G$785,数据录入!$C$5:$C$785,$A10,数据录入!$B$5:$B$785,Z$6)) -> 0 | AA10: =IF(OR($A10="",AA$6="",NOT(ISNUMBER($H$2))),"",SUMIFS(数据录入!$F$5:$F$785,数据录入!$C$5:$C$785,$A10,数据录入!$B$5:$B$785,AA$6)) -> 60000 | AB10: =IF(OR($A10="",AB$6="",NOT(ISNUMBER($H$2))),"",SUMIFS(数据录入!$G$5:$G$785,数据录入!$C$5:$C$785,$A10,数据录入!$B$5:$B$785,AB$6)) -> 55000 | AC10: =IF(OR($A10="",AC$6="",NOT(ISNUMBER($H$2))),"",SUMIFS(数据录入!$F$5:$F$785,数据录入!$C$5:$C$785,$A10,数据录入!$B$5:$B$785,AC$6)) -> 32735.47 | AD10: =IF(OR($A10="",AD$6="",NOT(ISNUMBER($H$2))),"",SUMIFS(数据录入!$G$5:$G$785,数据录入!$C$5:$C$785,$A10,数据录入!$B$5:$B$785,AD$6)) -> 0 | AE10: =IF(OR($A10="",AE$6="",NOT(ISNUMBER($H$2))),"",SUMIFS(数据录入!$F$5:$F$785,数据录入!$C$5:$C$785,$A10,数据录入!$B$5:$B$785,AE$6)) -> 0 | AF10: =IF(OR($A10="",AF$6="",NOT(ISNUMBER($H$2))),"",SUMIFS(数据录入!$G$5:$G$785,数据录入!$C$5:$C$785,$A10,数据录入!$B$5:$B$785,AF$6)) -> 500 | AG10: =IF(OR($A10="",AG$6="",NOT(ISNUMBER($H$2))),"",SUMIFS(数据录入!$F$5:$F$785,数据录入!$C$5:$C$785,$A10,数据录入!$B$5:$B$785,AG$6)) -> 330000 | AH10: =IF(OR($A10="",AH$6="",NOT(ISNUMBER($H$2))),"",SUMIFS(数据录入!$G$5:$G$785,数据录入!$C$5:$C$785,$A10,数据录入!$B$5:$B$785,AH$6)) -> 380000 | AI10: =IF(OR($A10="",AI$6="",NOT(ISNUMBER($H$2))),"",SUMIFS(数据录入!$F$5:$F$785,数据录入!$C$5:$C$785,$A10,数据录入!$B$5:$B$785,AI$6)) -> 7200 | AJ10: =IF(OR($A10="",AJ$6="",NOT(ISNUMBER($H$2))),"",SUMIFS(数据录入!$G$5:$G$785,数据录入!$C$5:$C$785,$A10,数据录入!$B$5:$B$785,AJ$6)) -> 0 | AK10: =IF(OR($A10="",AK$6="",NOT(ISNUMBER($H$2))),"",SUMIFS(数据录入!$F$5:$F$785,数据录入!$C$5:$C$785,$A10,数据录入!$B$5:$B$785,AK$6)) -> 0 | AL10: =IF(OR($A10="",AL$6="",NOT(ISNUMBER($H$2))),"",SUMIFS(数据录入!$G$5:$G$785,数据录入!$C$5:$C$785,$A10,数据录入!$B$5:$B$785,AL$6)) -> 10400 | AM10: =IF(OR($A10="",AM$6="",NOT(ISNUMBER($H$2))),"",SUMIFS(数据录入!$F$5:$F$785,数据录入!$C$5:$C$785,$A10,数据录入!$B$5:$B$785,AM$6)) -> 0 | AN10: =IF(OR($A10="",AN$6="",NOT(ISNUMBER($H$2))),"",SUMIFS(数据录入!$G$5:$G$785,数据录入!$C$5:$C$785,$A10,数据录入!$B$5:$B$785,AN$6)) -> 0 | AO10: =IF(OR($A10="",AO$6="",NOT(ISNUMBER($H$2))),"",SUMIFS(数据录入!$F$5:$F$785,数据录入!$C$5:$C$785,$A10,数据录入!$B$5:$B$785,AO$6)) -> 250000 | AP10: =IF(OR($A10="",AP$6="",NOT(ISNUMBER($H$2))),"",SUMIFS(数据录入!$G$5:$G$785,数据录入!$C$5:$C$785,$A10,数据录入!$B$5:$B$785,AP$6)) -> 103090 | AQ10: =IF(OR($A10="",AQ$6="",NOT(ISNUMBER($H$2))),"",SUMIFS(数据录入!$F$5:$F$785,数据录入!$C$5:$C$785,$A10,数据录入!$B$5:$B$785,AQ$6)) -> 1250 | AR10: =IF(OR($A10="",AR$6="",NOT(ISNUMBER($H$2))),"",SUMIFS(数据录入!$G$5:$G$785,数据录入!$C$5:$C$785,$A10,数据录入!$B$5:$B$785,AR$6)) -> 0 | AS10: =IF(OR($A10="",AS$6="",NOT(ISNUMBER($H$2))),"",SUMIFS(数据录入!$F$5:$F$785,数据录入!$C$5:$C$785,$A10,数据录入!$B$5:$B$785,AS$6)) -> 110000 | AT10: =IF(OR($A10="",AT$6="",NOT(ISNUMBER($H$2))),"",SUMIFS(数据录入!$G$5:$G$785,数据录入!$C$5:$C$785,$A10,数据录入!$B$5:$B$785,AT$6)) -> 220500 | AU10: =IF(OR($A10="",AU$6="",NOT(ISNUMBER($H$2))),"",SUMIFS(数据录入!$F$5:$F$785,数据录入!$C$5:$C$785,$A10,数据录入!$B$5:$B$785,AU$6)) -> 82700 | AV10: =IF(OR($A10="",AV$6="",NOT(ISNUMBER($H$2))),"",SUMIFS(数据录入!$G$5:$G$785,数据录入!$C$5:$C$785,$A10,数据录入!$B$5:$B$785,AV$6)) -> 99500 | AW10: =IF(OR($A10="",AW$6="",NOT(ISNUMBER($H$2))),"",SUMIFS(数据录入!$F$5:$F$785,数据录入!$C$5:$C$785,$A10,数据录入!$B$5:$B$785,AW$6)) -> 212000 | AX10: =IF(OR($A10="",AX$6="",NOT(ISNUMBER($H$2))),"",SUMIFS(数据录入!$G$5:$G$785,数据录入!$C$5:$C$785,$A10,数据录入!$B$5:$B$785,AX$6)) -> 120093.76 | AY10: =IF(OR($A10="",AY$6="",NOT(ISNUMBER($H$2))),"",SUMIFS(数据录入!$F$5:$F$785,数据录入!$C$5:$C$785,$A10,数据录入!$B$5:$B$785,AY$6)) -> 0 | AZ10: =IF(OR($A10="",AZ$6="",NOT(ISNUMBER($H$2))),"",SUMIFS(数据录入!$G$5:$G$785,数据录入!$C$5:$C$785,$A10,数据录入!$B$5:$B$785,AZ$6)) -> 0 | BA10: =IF(OR($A10="",BA$6="",NOT(ISNUMBER($H$2))),"",SUMIFS(数据录入!$F$5:$F$785,数据录入!$C$5:$C$785,$A10,数据录入!$B$5:$B$785,BA$6)) -> 0 | BB10: =IF(OR($A10="",BB$6="",NOT(ISNUMBER($H$2))),"",SUMIFS(数据录入!$G$5:$G$785,数据录入!$C$5:$C$785,$A10,数据录入!$B$5:$B$785,BB$6)) -> 0 | BC10: =IF(OR($A10="",BC$6="",NOT(ISNUMBER($H$2))),"",SUMIFS(数据录入!$F$5:$F$785,数据录入!$C$5:$C$785,$A10,数据录入!$B$5:$B$785,BC$6)) -> 1103600 | BD10: =IF(OR($A10="",BD$6="",NOT(ISNUMBER($H$2))),"",SUMIFS(数据录入!$G$5:$G$785,数据录入!$C$5:$C$785,$A10,数据录入!$B$5:$B$785,BD$6)) -> 1150033.3 | BE10: =IF(OR($A10="",BE$6="",NOT(ISNUMBER($H$2))),"",SUMIFS(数据录入!$F$5:$F$785,数据录入!$C$5:$C$785,$A10,数据录入!$B$5:$B$785,BE$6)) -> 340500 | BF10: =IF(OR($A10="",BF$6="",NOT(ISNUMBER($H$2))),"",SUMIFS(数据录入!$G$5:$G$785,数据录入!$C$5:$C$785,$A10,数据录入!$B$5:$B$785,BF$6)) -> 400000 | BG10: =IF(OR($A10="",BG$6="",NOT(ISNUMBER($H$2))),"",SUMIFS(数据录入!$F$5:$F$785,数据录入!$C$5:$C$785,$A10,数据录入!$B$5:$B$785,BG$6)) -> 24000 | BH10: =IF(OR($A10="",BH$6="",NOT(ISNUMBER($H$2))),"",SUMIFS(数据录入!$G$5:$G$785,数据录入!$C$5:$C$785,$A10,数据录入!$B$5:$B$785,BH$6)) -> 0 | BI10: =IF(OR($A10="",BI$6="",NOT(ISNUMBER($H$2))),"",SUMIFS(数据录入!$F$5:$F$785,数据录入!$C$5:$C$785,$A10,数据录入!$B$5:$B$785,BI$6)) -> 400000 | BJ10: =IF(OR($A10="",BJ$6="",NOT(ISNUMBER($H$2))),"",SUMIFS(数据录入!$G$5:$G$785,数据录入!$C$5:$C$785,$A10,数据录入!$B$5:$B$785,BJ$6)) -> 400000 | BK10: =IF(OR($A10="",BK$6="",NOT(ISNUMBER($H$2))),"",SUMIFS(数据录入!$F$5:$F$785,数据录入!$C$5:$C$785,$A10,数据录入!$B$5:$B$785,BK$6)) | BL10: =IF(OR($A10="",BL$6="",NOT(ISNUMBER($H$2))),"",SUMIFS(数据录入!$G$5:$G$785,数据录入!$C$5:$C$785,$A10,数据录入!$B$5:$B$785,BL$6)) | BM10: =IF($A10="","",SUMIF($C$7:$BL$7,"收款",C10:BL10)) -> 6125818.8 | BN10: =IF($A10="","",SUMIF($C$7:$BL$7,"付款",C10:BL10)) -> 6165064.1 | BO10: =IF($A10="","",B10+BM10-BN10) -> 34267.85
A11: 吴姐建行 | B11: =IF(OR($A11="",NOT(ISNUMBER($H$2))),"",SUMIFS(数据录入!$H$5:$H$785,数据录入!$C$5:$C$785,$A11,数据录入!$E$5:$E$785,"期初余额",数据录入!$B$5:$B$785,"<="&$B$2)+SUMIFS(数据录入!$F$5:$F$785,数据录入!$C$5:$C$785,$A11,数据录入!$B$5:$B$785,"<"&$B$2)-SUMIFS(数据录入!$G$5:$G$785,数据录入!$C$5:$C$785,$A11,数据录入!$B$5:$B$785,"<"&$B$2)) -> 90026.28 | C11: =IF(OR($A11="",C$6="",NOT(ISNUMBER($H$2))),"",SUMIFS(数据录入!$F$5:$F$785,数据录入!$C$5:$C$785,$A11,数据录入!$B$5:$B$785,C$6)) -> 56162.04 | D11: =IF(OR($A11="",D$6="",NOT(ISNUMBER($H$2))),"",SUMIFS(数据录入!$G$5:$G$785,数据录入!$C$5:$C$785,$A11,数据录入!$B$5:$B$785,D$6)) -> 130000 | E11: =IF(OR($A11="",E$6="",NOT(ISNUMBER($H$2))),"",SUMIFS(数据录入!$F$5:$F$785,数据录入!$C$5:$C$785,$A11,数据录入!$B$5:$B$785,E$6)) -> 0 | F11: =IF(OR($A11="",F$6="",NOT(ISNUMBER($H$2))),"",SUMIFS(数据录入!$G$5:$G$785,数据录入!$C$5:$C$785,$A11,数据录入!$B$5:$B$785,F$6)) -> 0 | G11: =IF(OR($A11="",G$6="",NOT(ISNUMBER($H$2))),"",SUMIFS(数据录入!$F$5:$F$785,数据录入!$C$5:$C$785,$A11,数据录入!$B$5:$B$785,G$6)) -> 100 | H11: =IF(OR($A11="",H$6="",NOT(ISNUMBER($H$2))),"",SUMIFS(数据录入!$G$5:$G$785,数据录入!$C$5:$C$785,$A11,数据录入!$B$5:$B$785,H$6)) -> 0 | I11: =IF(OR($A11="",I$6="",NOT(ISNUMBER($H$2))),"",SUMIFS(数据录入!$F$5:$F$785,数据录入!$C$5:$C$785,$A11,数据录入!$B$5:$B$785,I$6)) -> 800 | J11: =IF(OR($A11="",J$6="",NOT(ISNUMBER($H$2))),"",SUMIFS(数据录入!$G$5:$G$785,数据录入!$C$5:$C$785,$A11,数据录入!$B$5:$B$785,J$6)) -> 0 | K11: =IF(OR($A11="",K$6="",NOT(ISNUMBER($H$2))),"",SUMIFS(数据录入!$F$5:$F$785,数据录入!$C$5:$C$785,$A11,数据录入!$B$5:$B$785,K$6)) -> 0 | L11: =IF(OR($A11="",L$6="",NOT(ISNUMBER($H$2))),"",SUMIFS(数据录入!$G$5:$G$785,数据录入!$C$5:$C$785,$A11,数据录入!$B$5:$B$785,L$6)) -> 0 | M11: =IF(OR($A11="",M$6="",NOT(ISNUMBER($H$2))),"",SUMIFS(数据录入!$F$5:$F$785,数据录入!$C$5:$C$785,$A11,数据录入!$B$5:$B$785,M$6)) -> 300000 | N11: =IF(OR($A11="",N$6="",NOT(ISNUMBER($H$2))),"",SUMIFS(数据录入!$G$5:$G$785,数据录入!$C$5:$C$785,$A11,数据录入!$B$5:$B$785,N$6)) -> 0 | O11: =IF(OR($A11="",O$6="",NOT(ISNUMBER($H$2))),"",SUMIFS(数据录入!$F$5:$F$785,数据录入!$C$5:$C$785,$A11,数据录入!$B$5:$B$785,O$6)) -> 72800 | P11: =IF(OR($A11="",P$6="",NOT(ISNUMBER($H$2))),"",SUMIFS(数据录入!$G$5:$G$785,数据录入!$C$5:$C$785,$A11,数据录入!$B$5:$B$785,P$6)) -> 500 | Q11: =IF(OR($A11="",Q$6="",NOT(ISNUMBER($H$2))),"",SUMIFS(数据录入!$F$5:$F$785,数据录入!$C$5:$C$785,$A11,数据录入!$B$5:$B$785,Q$6)) -> 1100000 | R11: =IF(OR($A11="",R$6="",NOT(ISNUMBER($H$2))),"",SUMIFS(数据录入!$G$5:$G$785,数据录入!$C$5:$C$785,$A11,数据录入!$B$5:$B$785,R$6)) -> 0 | S11: =IF(OR($A11="",S$6="",NOT(ISNUMBER($H$2))),"",SUMIFS(数据录入!$F$5:$F$785,数据录入!$C$5:$C$785,$A11,数据录入!$B$5:$B$785,S$6)) -> 4533 | T11: =IF(OR($A11="",T$6="",NOT(ISNUMBER($H$2))),"",SUMIFS(数据录入!$G$5:$G$785,数据录入!$C$5:$C$785,$A11,数据录入!$B$5:$B$785,T$6)) -> 0 | U11: =IF(OR($A11="",U$6="",NOT(ISNUMBER($H$2))),"",SUMIFS(数据录入!$F$5:$F$785,数据录入!$C$5:$C$785,$A11,数据录入!$B$5:$B$785,U$6)) -> 184200 | V11: =IF(OR($A11="",V$6="",NOT(ISNUMBER($H$2))),"",SUMIFS(数据录入!$G$5:$G$785,数据录入!$C$5:$C$785,$A11,数据录入!$B$5:$B$785,V$6)) -> 200000 | W11: =IF(OR($A11="",W$6="",NOT(ISNUMBER($H$2))),"",SUMIFS(数据录入!$F$5:$F$785,数据录入!$C$5:$C$785,$A11,数据录入!$B$5:$B$785,W$6)) -> 0 | X11: =IF(OR($A11="",X$6="",NOT(ISNUMBER($H$2))),"",SUMIFS(数据录入!$G$5:$G$785,数据录入!$C$5:$C$785,$A11,数据录入!$B$5:$B$785,X$6)) -> 0 | Y11: =IF(OR($A11="",Y$6="",NOT(ISNUMBER($H$2))),"",SUMIFS(数据录入!$F$5:$F$785,数据录入!$C$5:$C$785,$A11,数据录入!$B$5:$B$785,Y$6)) -> 0 | Z11: =IF(OR($A11="",Z$6="",NOT(ISNUMBER($H$2))),"",SUMIFS(数据录入!$G$5:$G$785,数据录入!$C$5:$C$785,$A11,数据录入!$B$5:$B$785,Z$6)) -> 0 | AA11: =IF(OR($A11="",AA$6="",NOT(ISNUMBER($H$2))),"",SUMIFS(数据录入!$F$5:$F$785,数据录入!$C$5:$C$785,$A11,数据录入!$B$5:$B$785,AA$6)) -> 5500 | AB11: =IF(OR($A11="",AB$6="",NOT(ISNUMBER($H$2))),"",SUMIFS(数据录入!$G$5:$G$785,数据录入!$C$5:$C$785,$A11,数据录入!$B$5:$B$785,AB$6)) -> 60027.4 | AC11: =IF(OR($A11="",AC$6="",NOT(ISNUMBER($H$2))),"",SUMIFS(数据录入!$F$5:$F$785,数据录入!$C$5:$C$785,$A11,数据录入!$B$5:$B$785,AC$6)) -> 0 | AD11: =IF(OR($A11="",AD$6="",NOT(ISNUMBER($H$2))),"",SUMIFS(数据录入!$G$5:$G$785,数据录入!$C$5:$C$785,$A11,数据录入!$B$5:$B$785,AD$6)) -> 0 | AE11: =IF(OR($A11="",AE$6="",NOT(ISNUMBER($H$2))),"",SUMIFS(数据录入!$F$5:$F$785,数据录入!$C$5:$C$785,$A11,数据录入!$B$5:$B$785,AE$6)) -> 0 | AF11: =IF(OR($A11="",AF$6="",NOT(ISNUMBER($H$2))),"",SUMIFS(数据录入!$G$5:$G$785,数据录入!$C$5:$C$785,$A11,数据录入!$B$5:$B$785,AF$6)) -> 0 | AG11: =IF(OR($A11="",AG$6="",NOT(ISNUMBER($H$2))),"",SUMIFS(数据录入!$F$5:$F$785,数据录入!$C$5:$C$785,$A11,数据录入!$B$5:$B$785,AG$6)) -> 210 | AH11: =IF(OR($A11="",AH$6="",NOT(ISNUMBER($H$2))),"",SUMIFS(数据录入!$G$5:$G$785,数据录入!$C$5:$C$785,$A11,数据录入!$B$5:$B$785,AH$6)) -> 331000 | AI11: =IF(OR($A11="",AI$6="",NOT(ISNUMBER($H$2))),"",SUMIFS(数据录入!$F$5:$F$785,数据录入!$C$5:$C$785,$A11,数据录入!$B$5:$B$785,AI$6)) -> 200 | AJ11: =IF(OR($A11="",AJ$6="",NOT(ISNUMBER($H$2))),"",SUMIFS(数据录入!$G$5:$G$785,数据录入!$C$5:$C$785,$A11,数据录入!$B$5:$B$785,AJ$6)) -> 0 | AK11: =IF(OR($A11="",AK$6="",NOT(ISNUMBER($H$2))),"",SUMIFS(数据录入!$F$5:$F$785,数据录入!$C$5:$C$785,$A11,数据录入!$B$5:$B$785,AK$6)) -> 7171.67 | AL11: =IF(OR($A11="",AL$6="",NOT(ISNUMBER($H$2))),"",SUMIFS(数据录入!$G$5:$G$785,数据录入!$C$5:$C$785,$A11,数据录入!$B$5:$B$785,AL$6)) -> 158.97 | AM11: =IF(OR($A11="",AM$6="",NOT(ISNUMBER($H$2))),"",SUMIFS(数据录入!$F$5:$F$785,数据录入!$C$5:$C$785,$A11,数据录入!$B$5:$B$785,AM$6)) -> 0 | AN11: =IF(OR($A11="",AN$6="",NOT(ISNUMBER($H$2))),"",SUMIFS(数据录入!$G$5:$G$785,数据录入!$C$5:$C$785,$A11,数据录入!$B$5:$B$785,AN$6)) -> 0 | AO11: =IF(OR($A11="",AO$6="",NOT(ISNUMBER($H$2))),"",SUMIFS(数据录入!$F$5:$F$785,数据录入!$C$5:$C$785,$A11,数据录入!$B$5:$B$785,AO$6)) -> 4875 | AP11: =IF(OR($A11="",AP$6="",NOT(ISNUMBER($H$2))),"",SUMIFS(数据录入!$G$5:$G$785,数据录入!$C$5:$C$785,$A11,数据录入!$B$5:$B$785,AP$6)) -> 50000 | AQ11: =IF(OR($A11="",AQ$6="",NOT(ISNUMBER($H$2))),"",SUMIFS(数据录入!$F$5:$F$785,数据录入!$C$5:$C$785,$A11,数据录入!$B$5:$B$785,AQ$6)) -> 0 | AR11: =IF(OR($A11="",AR$6="",NOT(ISNUMBER($H$2))),"",SUMIFS(数据录入!$G$5:$G$785,数据录入!$C$5:$C$785,$A11,数据录入!$B$5:$B$785,AR$6)) -> 0 | AS11: =IF(OR($A11="",AS$6="",NOT(ISNUMBER($H$2))),"",SUMIFS(数据录入!$F$5:$F$785,数据录入!$C$5:$C$785,$A11,数据录入!$B$5:$B$785,AS$6)) -> 1500 | AT11: =IF(OR($A11="",AT$6="",NOT(ISNUMBER($H$2))),"",SUMIFS(数据录入!$G$5:$G$785,数据录入!$C$5:$C$785,$A11,数据录入!$B$5:$B$785,AT$6)) -> 0 | AU11: =IF(OR($A11="",AU$6="",NOT(ISNUMBER($H$2))),"",SUMIFS(数据录入!$F$5:$F$785,数据录入!$C$5:$C$785,$A11,数据录入!$B$5:$B$785,AU$6)) -> 0 | AV11: =IF(OR($A11="",AV$6="",NOT(ISNUMBER($H$2))),"",SUMIFS(数据录入!$G$5:$G$785,数据录入!$C$5:$C$785,$A11,数据录入!$B$5:$B$785,AV$6)) -> 0 | AW11: =IF(OR($A11="",AW$6="",NOT(ISNUMBER($H$2))),"",SUMIFS(数据录入!$F$5:$F$785,数据录入!$C$5:$C$785,$A11,数据录入!$B$5:$B$785,AW$6)) -> 250100 | AX11: =IF(OR($A11="",AX$6="",NOT(ISNUMBER($H$2))),"",SUMIFS(数据录入!$G$5:$G$785,数据录入!$C$5:$C$785,$A11,数据录入!$B$5:$B$785,AX$6)) -> 150000 | AY11: =IF(OR($A11="",AY$6="",NOT(ISNUMBER($H$2))),"",SUMIFS(数据录入!$F$5:$F$785,数据录入!$C$5:$C$785,$A11,数据录入!$B$5:$B$785,AY$6)) -> 0 | AZ11: =IF(OR($A11="",AZ$6="",NOT(ISNUMBER($H$2))),"",SUMIFS(数据录入!$G$5:$G$785,数据录入!$C$5:$C$785,$A11,数据录入!$B$5:$B$785,AZ$6)) -> 0 | BA11: =IF(OR($A11="",BA$6="",NOT(ISNUMBER($H$2))),"",SUMIFS(数据录入!$F$5:$F$785,数据录入!$C$5:$C$785,$A11,数据录入!$B$5:$B$785,BA$6)) -> 0 | BB11: =IF(OR($A11="",BB$6="",NOT(ISNUMBER($H$2))),"",SUMIFS(数据录入!$G$5:$G$785,数据录入!$C$5:$C$785,$A11,数据录入!$B$5:$B$785,BB$6)) -> 0 | BC11: =IF(OR($A11="",BC$6="",NOT(ISNUMBER($H$2))),"",SUMIFS(数据录入!$F$5:$F$785,数据录入!$C$5:$C$785,$A11,数据录入!$B$5:$B$785,BC$6)) -> 450 | BD11: =IF(OR($A11="",BD$6="",NOT(ISNUMBER($H$2))),"",SUMIFS(数据录入!$G$5:$G$785,数据录入!$C$5:$C$785,$A11,数据录入!$B$5:$B$785,BD$6)) -> 550000 | BE11: =IF(OR($A11="",BE$6="",NOT(ISNUMBER($H$2))),"",SUMIFS(数据录入!$F$5:$F$785,数据录入!$C$5:$C$785,$A11,数据录入!$B$5:$B$785,BE$6)) -> 552100 | BF11: =IF(OR($A11="",BF$6="",NOT(ISNUMBER($H$2))),"",SUMIFS(数据录入!$G$5:$G$785,数据录入!$C$5:$C$785,$A11,数据录入!$B$5:$B$785,BF$6)) -> 160000 | BG11: =IF(OR($A11="",BG$6="",NOT(ISNUMBER($H$2))),"",SUMIFS(数据录入!$F$5:$F$785,数据录入!$C$5:$C$785,$A11,数据录入!$B$5:$B$785,BG$6)) -> 18000 | BH11: =IF(OR($A11="",BH$6="",NOT(ISNUMBER($H$2))),"",SUMIFS(数据录入!$G$5:$G$785,数据录入!$C$5:$C$785,$A11,数据录入!$B$5:$B$785,BH$6)) -> 755858 | BI11: =IF(OR($A11="",BI$6="",NOT(ISNUMBER($H$2))),"",SUMIFS(数据录入!$F$5:$F$785,数据录入!$C$5:$C$785,$A11,数据录入!$B$5:$B$785,BI$6)) -> 0 | BJ11: =IF(OR($A11="",BJ$6="",NOT(ISNUMBER($H$2))),"",SUMIFS(数据录入!$G$5:$G$785,数据录入!$C$5:$C$785,$A11,数据录入!$B$5:$B$785,BJ$6)) -> 200000 | BK11: =IF(OR($A11="",BK$6="",NOT(ISNUMBER($H$2))),"",SUMIFS(数据录入!$F$5:$F$785,数据录入!$C$5:$C$785,$A11,数据录入!$B$5:$B$785,BK$6)) | BL11: =IF(OR($A11="",BL$6="",NOT(ISNUMBER($H$2))),"",SUMIFS(数据录入!$G$5:$G$785,数据录入!$C$5:$C$785,$A11,数据录入!$B$5:$B$785,BL$6)) | BM11: =IF($A11="","",SUMIF($C$7:$BL$7,"收款",C11:BL11)) -> 2558701.7 | BN11: =IF($A11="","",SUMIF($C$7:$BL$7,"付款",C11:BL11)) -> 2587544.4 | BO11: =IF($A11="","",B11+BM11-BN11) -> 61183.62
A12: 吴姐民生 | B12: =IF(OR($A12="",NOT(ISNUMBER($H$2))),"",SUMIFS(数据录入!$H$5:$H$785,数据录入!$C$5:$C$785,$A12,数据录入!$E$5:$E$785,"期初余额",数据录入!$B$5:$B$785,"<="&$B$2)+SUMIFS(数据录入!$F$5:$F$785,数据录入!$C$5:$C$785,$A12,数据录入!$B$5:$B$785,"<"&$B$2)-SUMIFS(数据录入!$G$5:$G$785,数据录入!$C$5:$C$785,$A12,数据录入!$B$5:$B$785,"<"&$B$2)) -> 15829.44 | C12: =IF(OR($A12="",C$6="",NOT(ISNUMBER($H$2))),"",SUMIFS(数据录入!$F$5:$F$785,数据录入!$C$5:$C$785,$A12,数据录入!$B$5:$B$785,C$6)) -> 0 | D12: =IF(OR($A12="",D$6="",NOT(ISNUMBER($H$2))),"",SUMIFS(数据录入!$G$5:$G$785,数据录入!$C$5:$C$785,$A12,数据录入!$B$5:$B$785,D$6)) -> 0 | E12: =IF(OR($A12="",E$6="",NOT(ISNUMBER($H$2))),"",SUMIFS(数据录入!$F$5:$F$785,数据录入!$C$5:$C$785,$A12,数据录入!$B$5:$B$785,E$6)) -> 5400 | F12: =IF(OR($A12="",F$6="",NOT(ISNUMBER($H$2))),"",SUMIFS(数据录入!$G$5:$G$785,数据录入!$C$5:$C$785,$A12,数据录入!$B$5:$B$785,F$6)) -> 0 | G12: =IF(OR($A12="",G$6="",NOT(ISNUMBER($H$2))),"",SUMIFS(数据录入!$F$5:$F$785,数据录入!$C$5:$C$785,$A12,数据录入!$B$5:$B$785,G$6)) -> 0 | H12: =IF(OR($A12="",H$6="",NOT(ISNUMBER($H$2))),"",SUMIFS(数据录入!$G$5:$G$785,数据录入!$C$5:$C$785,$A12,数据录入!$B$5:$B$785,H$6)) -> 0 | I12: =IF(OR($A12="",I$6="",NOT(ISNUMBER($H$2))),"",SUMIFS(数据录入!$F$5:$F$785,数据录入!$C$5:$C$785,$A12,数据录入!$B$5:$B$785,I$6)) -> 0 | J12: =IF(OR($A12="",J$6="",NOT(ISNUMBER($H$2))),"",SUMIFS(数据录入!$G$5:$G$785,数据录入!$C$5:$C$785,$A12,数据录入!$B$5:$B$785,J$6)) -> 0 | K12: =IF(OR($A12="",K$6="",NOT(ISNUMBER($H$2))),"",SUMIFS(数据录入!$F$5:$F$785,数据录入!$C$5:$C$785,$A12,数据录入!$B$5:$B$785,K$6)) -> 0 | L12: =IF(OR($A12="",L$6="",NOT(ISNUMBER($H$2))),"",SUMIFS(数据录入!$G$5:$G$785,数据录入!$C$5:$C$785,$A12,数据录入!$B$5:$B$785,L$6)) -> 0 | M12: =IF(OR($A12="",M$6="",NOT(ISNUMBER($H$2))),"",SUMIFS(数据录入!$F$5:$F$785,数据录入!$C$5:$C$785,$A12,数据录入!$B$5:$B$785,M$6)) -> 875 | N12: =IF(OR($A12="",N$6="",NOT(ISNUMBER($H$2))),"",SUMIFS(数据录入!$G$5:$G$785,数据录入!$C$5:$C$785,$A12,数据录入!$B$5:$B$785,N$6)) -> 0 | O12: =IF(OR($A12="",O$6="",NOT(ISNUMBER($H$2))),"",SUMIFS(数据录入!$F$5:$F$785,数据录入!$C$5:$C$785,$A12,数据录入!$B$5:$B$785,O$6)) -> 0 | P12: =IF(OR($A12="",P$6="",NOT(ISNUMBER($H$2))),"",SUMIFS(数据录入!$G$5:$G$785,数据录入!$C$5:$C$785,$A12,数据录入!$B$5:$B$785,P$6)) -> 0 | Q12: =IF(OR($A12="",Q$6="",NOT(ISNUMBER($H$2))),"",SUMIFS(数据录入!$F$5:$F$785,数据录入!$C$5:$C$785,$A12,数据录入!$B$5:$B$785,Q$6)) -> 0 | R12: =IF(OR($A12="",R$6="",NOT(ISNUMBER($H$2))),"",SUMIFS(数据录入!$G$5:$G$785,数据录入!$C$5:$C$785,$A12,数据录入!$B$5:$B$785,R$6)) -> 0 | S12: =IF(OR($A12="",S$6="",NOT(ISNUMBER($H$2))),"",SUMIFS(数据录入!$F$5:$F$785,数据录入!$C$5:$C$785,$A12,数据录入!$B$5:$B$785,S$6)) -> 0 | T12: =IF(OR($A12="",T$6="",NOT(ISNUMBER($H$2))),"",SUMIFS(数据录入!$G$5:$G$785,数据录入!$C$5:$C$785,$A12,数据录入!$B$5:$B$785,T$6)) -> 0 | U12: =IF(OR($A12="",U$6="",NOT(ISNUMBER($H$2))),"",SUMIFS(数据录入!$F$5:$F$785,数据录入!$C$5:$C$785,$A12,数据录入!$B$5:$B$785,U$6)) -> 0 | V12: =IF(OR($A12="",V$6="",NOT(ISNUMBER($H$2))),"",SUMIFS(数据录入!$G$5:$G$785,数据录入!$C$5:$C$785,$A12,数据录入!$B$5:$B$785,V$6)) -> 0 | W12: =IF(OR($A12="",W$6="",NOT(ISNUMBER($H$2))),"",SUMIFS(数据录入!$F$5:$F$785,数据录入!$C$5:$C$785,$A12,数据录入!$B$5:$B$785,W$6)) -> 0 | X12: =IF(OR($A12="",X$6="",NOT(ISNUMBER($H$2))),"",SUMIFS(数据录入!$G$5:$G$785,数据录入!$C$5:$C$785,$A12,数据录入!$B$5:$B$785,X$6)) -> 0 | Y12: =IF(OR($A12="",Y$6="",NOT(ISNUMBER($H$2))),"",SUMIFS(数据录入!$F$5:$F$785,数据录入!$C$5:$C$785,$A12,数据录入!$B$5:$B$785,Y$6)) -> 0 | Z12: =IF(OR($A12="",Z$6="",NOT(ISNUMBER($H$2))),"",SUMIFS(数据录入!$G$5:$G$785,数据录入!$C$5:$C$785,$A12,数据录入!$B$5:$B$785,Z$6)) -> 0 | AA12: =IF(OR($A12="",AA$6="",NOT(ISNUMBER($H$2))),"",SUMIFS(数据录入!$F$5:$F$785,数据录入!$C$5:$C$785,$A12,数据录入!$B$5:$B$785,AA$6)) -> 0 | AB12: =IF(OR($A12="",AB$6="",NOT(ISNUMBER($H$2))),"",SUMIFS(数据录入!$G$5:$G$785,数据录入!$C$5:$C$785,$A12,数据录入!$B$5:$B$785,AB$6)) -> 0 | AC12: =IF(OR($A12="",AC$6="",NOT(ISNUMBER($H$2))),"",SUMIFS(数据录入!$F$5:$F$785,数据录入!$C$5:$C$785,$A12,数据录入!$B$5:$B$785,AC$6)) -> 0 | AD12: =IF(OR($A12="",AD$6="",NOT(ISNUMBER($H$2))),"",SUMIFS(数据录入!$G$5:$G$785,数据录入!$C$5:$C$785,$A12,数据录入!$B$5:$B$785,AD$6)) -> 0 | AE12: =IF(OR($A12="",AE$6="",NOT(ISNUMBER($H$2))),"",SUMIFS(数据录入!$F$5:$F$785,数据录入!$C$5:$C$785,$A12,数据录入!$B$5:$B$785,AE$6)) -> 2500 | AF12: =IF(OR($A12="",AF$6="",NOT(ISNUMBER($H$2))),"",SUMIFS(数据录入!$G$5:$G$785,数据录入!$C$5:$C$785,$A12,数据录入!$B$5:$B$785,AF$6)) -> 0 | AG12: =IF(OR($A12="",AG$6="",NOT(ISNUMBER($H$2))),"",SUMIFS(数据录入!$F$5:$F$785,数据录入!$C$5:$C$785,$A12,数据录入!$B$5:$B$785,AG$6)) -> 0 | AH12: =IF(OR($A12="",AH$6="",NOT(ISNUMBER($H$2))),"",SUMIFS(数据录入!$G$5:$G$785,数据录入!$C$5:$C$785,$A12,数据录入!$B$5:$B$785,AH$6)) -> 0 | AI12: =IF(OR($A12="",AI$6="",NOT(ISNUMBER($H$2))),"",SUMIFS(数据录入!$F$5:$F$785,数据录入!$C$5:$C$785,$A12,数据录入!$B$5:$B$785,AI$6)) -> 800 | AJ12: =IF(OR($A12="",AJ$6="",NOT(ISNUMBER($H$2))),"",SUMIFS(数据录入!$G$5:$G$785,数据录入!$C$5:$C$785,$A12,数据录入!$B$5:$B$785,AJ$6)) -> 0 | AK12: =IF(OR($A12="",AK$6="",NOT(ISNUMBER($H$2))),"",SUMIFS(数据录入!$F$5:$F$785,数据录入!$C$5:$C$785,$A12,数据录入!$B$5:$B$785,AK$6)) -> 0 | AL12: =IF(OR($A12="",AL$6="",NOT(ISNUMBER($H$2))),"",SUMIFS(数据录入!$G$5:$G$785,数据录入!$C$5:$C$785,$A12,数据录入!$B$5:$B$785,AL$6)) -> 0 | AM12: =IF(OR($A12="",AM$6="",NOT(ISNUMBER($H$2))),"",SUMIFS(数据录入!$F$5:$F$785,数据录入!$C$5:$C$785,$A12,数据录入!$B$5:$B$785,AM$6)) -> 0 | AN12: =IF(OR($A12="",AN$6="",NOT(ISNUMBER($H$2))),"",SUMIFS(数据录入!$G$5:$G$785,数据录入!$C$5:$C$785,$A12,数据录入!$B$5:$B$785,AN$6)) -> 0 | AO12: =IF(OR($A12="",AO$6="",NOT(ISNUMBER($H$2))),"",SUMIFS(数据录入!$F$5:$F$785,数据录入!$C$5:$C$785,$A12,数据录入!$B$5:$B$785,AO$6)) -> 1010 | AP12: =IF(OR($A12="",AP$6="",NOT(ISNUMBER($H$2))),"",SUMIFS(数据录入!$G$5:$G$785,数据录入!$C$5:$C$785,$A12,数据录入!$B$5:$B$785,AP$6)) -> 0 | AQ12: =IF(OR($A12="",AQ$6="",NOT(ISNUMBER($H$2))),"",SUMIFS(数据录入!$F$5:$F$785,数据录入!$C$5:$C$785,$A12,数据录入!$B$5:$B$785,AQ$6)) -> 8500 | AR12: =IF(OR($A12="",AR$6="",NOT(ISNUMBER($H$2))),"",SUMIFS(数据录入!$G$5:$G$785,数据录入!$C$5:$C$785,$A12,数据录入!$B$5:$B$785,AR$6)) -> 0 | AS12: =IF(OR($A12="",AS$6="",NOT(ISNUMBER($H$2))),"",SUMIFS(数据录入!$F$5:$F$785,数据录入!$C$5:$C$785,$A12,数据录入!$B$5:$B$785,AS$6)) -> 0 | AT12: =IF(OR($A12="",AT$6="",NOT(ISNUMBER($H$2))),"",SUMIFS(数据录入!$G$5:$G$785,数据录入!$C$5:$C$785,$A12,数据录入!$B$5:$B$785,AT$6)) -> 0 | AU12: =IF(OR($A12="",AU$6="",NOT(ISNUMBER($H$2))),"",SUMIFS(数据录入!$F$5:$F$785,数据录入!$C$5:$C$785,$A12,数据录入!$B$5:$B$785,AU$6)) -> 0 | AV12: =IF(OR($A12="",AV$6="",NOT(ISNUMBER($H$2))),"",SUMIFS(数据录入!$G$5:$G$785,数据录入!$C$5:$C$785,$A12,数据录入!$B$5:$B$785,AV$6)) -> 0 | AW12: =IF(OR($A12="",AW$6="",NOT(ISNUMBER($H$2))),"",SUMIFS(数据录入!$F$5:$F$785,数据录入!$C$5:$C$785,$A12,数据录入!$B$5:$B$785,AW$6)) -> 0 | AX12: =IF(OR($A12="",AX$6="",NOT(ISNUMBER($H$2))),"",SUMIFS(数据录入!$G$5:$G$785,数据录入!$C$5:$C$785,$A12,数据录入!$B$5:$B$785,AX$6)) -> 0 | AY12: =IF(OR($A12="",AY$6="",NOT(ISNUMBER($H$2))),"",SUMIFS(数据录入!$F$5:$F$785,数据录入!$C$5:$C$785,$A12,数据录入!$B$5:$B$785,AY$6)) -> 0 | AZ12: =IF(OR($A12="",AZ$6="",NOT(ISNUMBER($H$2))),"",SUMIFS(数据录入!$G$5:$G$785,数据录入!$C$5:$C$785,$A12,数据录入!$B$5:$B$785,AZ$6)) -> 0 | BA12: =IF(OR($A12="",BA$6="",NOT(ISNUMBER($H$2))),"",SUMIFS(数据录入!$F$5:$F$785,数据录入!$C$5:$C$785,$A12,数据录入!$B$5:$B$785,BA$6)) -> 0 | BB12: =IF(OR($A12="",BB$6="",NOT(ISNUMBER($H$2))),"",SUMIFS(数据录入!$G$5:$G$785,数据录入!$C$5:$C$785,$A12,数据录入!$B$5:$B$785,BB$6)) -> 0 | BC12: =IF(OR($A12="",BC$6="",NOT(ISNUMBER($H$2))),"",SUMIFS(数据录入!$F$5:$F$785,数据录入!$C$5:$C$785,$A12,数据录入!$B$5:$B$785,BC$6)) -> 0 | BD12: =IF(OR($A12="",BD$6="",NOT(ISNUMBER($H$2))),"",SUMIFS(数据录入!$G$5:$G$785,数据录入!$C$5:$C$785,$A12,数据录入!$B$5:$B$785,BD$6)) -> 0 | BE12: =IF(OR($A12="",BE$6="",NOT(ISNUMBER($H$2))),"",SUMIFS(数据录入!$F$5:$F$785,数据录入!$C$5:$C$785,$A12,数据录入!$B$5:$B$785,BE$6)) -> 0 | BF12: =IF(OR($A12="",BF$6="",NOT(ISNUMBER($H$2))),"",SUMIFS(数据录入!$G$5:$G$785,数据录入!$C$5:$C$785,$A12,数据录入!$B$5:$B$785,BF$6)) -> 0 | BG12: =IF(OR($A12="",BG$6="",NOT(ISNUMBER($H$2))),"",SUMIFS(数据录入!$F$5:$F$785,数据录入!$C$5:$C$785,$A12,数据录入!$B$5:$B$785,BG$6)) -> 0 | BH12: =IF(OR($A12="",BH$6="",NOT(ISNUMBER($H$2))),"",SUMIFS(数据录入!$G$5:$G$785,数据录入!$C$5:$C$785,$A12,数据录入!$B$5:$B$785,BH$6)) -> 0 | BI12: =IF(OR($A12="",BI$6="",NOT(ISNUMBER($H$2))),"",SUMIFS(数据录入!$F$5:$F$785,数据录入!$C$5:$C$785,$A12,数据录入!$B$5:$B$785,BI$6)) -> 0 | BJ12: =IF(OR($A12="",BJ$6="",NOT(ISNUMBER($H$2))),"",SUMIFS(数据录入!$G$5:$G$785,数据录入!$C$5:$C$785,$A12,数据录入!$B$5:$B$785,BJ$6)) -> 0 | BK12: =IF(OR($A12="",BK$6="",NOT(ISNUMBER($H$2))),"",SUMIFS(数据录入!$F$5:$F$785,数据录入!$C$5:$C$785,$A12,数据录入!$B$5:$B$785,BK$6)) | BL12: =IF(OR($A12="",BL$6="",NOT(ISNUMBER($H$2))),"",SUMIFS(数据录入!$G$5:$G$785,数据录入!$C$5:$C$785,$A12,数据录入!$B$5:$B$785,BL$6)) | BM12: =IF($A12="","",SUMIF($C$7:$BL$7,"收款",C12:BL12)) -> 19085 | BN12: =IF($A12="","",SUMIF($C$7:$BL$7,"付款",C12:BL12)) -> 0 | BO12: =IF($A12="","",B12+BM12-BN12) -> 34914.44
