Workbook

Sheet 说明
B1: 记账凭证自动生成器
B3: 【每月只做 4 件事】
B4: 1. 把海典零售导出的“日报明细”整表（含表头）粘到 输入海典 页签的 A1（最后那行“总计”不要粘）；
B5: 2. 把聚合支付平台导出的门店汇总填到 输入聚合 （编码 / 交易金额 / 服务费）；
B6: 3. 把各店网银现金合计填到 输入现金 ；回款表填到 输入回款 ；报销单填到 输入报销 ；
B7: 4. 到 参数 页签改一下会计日期和摘要 —— 三套凭证就自动出来了。
B9: 【凭证在这三个页签】
B10: 凭证收入 凭证回款 凭证报销 （版式和你现在手写的记账凭证一致，每页 6 行分录，超过自动接下一页，合计只出现在最后一页）
B11: 每张凭证已设好分页符（A5 横向 = 标准凭证纸）：打印时选“页码范围 1 到 N”，N 见 参数 页签的“共几页”。
B13: 【换月份怎么做】
B14: 先把上个月的数据整行删掉（输入海典 / 输入聚合 / 输入现金 / 输入回款 / 输入报销 这 5 页），再粘新的；
B15: 删的时候选中行号右键“删除”，不要只按 Delete 键留下空行——留空行不影响结果，但看着乱。
... B70: 想改回“把号直接印出来”，到 参数 页把“凭证号是否打印”选成 是 就行。

Sheet 参数
A1: 参数设置
A2: 会计日期 | B2: 46234
A3: 收入凭证摘要 | B3: 7月收入
A4: 回款凭证摘要 | B4: 回款
A5: 报销凭证摘要（缺省） | B5: 报销费用 | C5: 输入报销里没写摘要时用这个
A6: 贷方科目1 | B6: 库存现金 | C6: 报销单“付款方式”可选项
A7: 贷方科目2 | B7: 银行存款
A8: 贷方科目3 | B8: 其他应付款
A9: 凭证号是否打印 | B9: 否 | C9: 选「否」＝凭证右上角留空，打印出来自己手写号；选「是」＝把自动排的号直接印出来
A10: 收入凭证 共几页 | B10: =助手收入!$V$1 -> 78 | C10: 打印时选：页码 1 到 这个数 | D10: =IF(助手收入!$V$1>280,"⚠ 凭证页不够，请找我加","")
A11: 回款凭证 共几页 | B11: =助手回款!$V$1 -> 46 | D11: =IF(助手回款!$V$1>210,"⚠ 凭证页不够，请找我加","")
A12: 报销凭证 共几页 | B12: =助手报销!$V$1 -> 39 | D12: =IF(助手报销!$V$1>200,"⚠ 凭证页不够，请找我加","")
A14: 粘进来的海典明细 最早会计日 | B14: =IFERROR(MIN(INDEX(输入海典!$A$1:$AN$20000,0,IFERROR(MATCH("会计日",输入海典!$1:$1,0),1))),"") -> 46204 | C14: ← 这两个日期要落在同一个月内，否则说明粘进去的不止一个月
A15: 粘进来的海典明细 最晚会计日 | B15: =IFERROR(MAX(INDEX(输入海典!$A$1:$AN$20000,0,IFERROR(MATCH("会计日",输入海典!$1:$1,0),1))),"") -> 46234
A17: 海典明细里“销售合计”列合计 | B17: =IFERROR(SUM(INDEX(输入海典!$A$1:$AN$20000,0,MATCH("销售合计",输入海典!$1:$1,0))),0) -> 2818376.6
A18: 按门店汇总后的合计 | B18: =ROUND(SUM(海典汇总!$AE$3:$AE$67),2) -> 2818376.6
A19: 差异（应为 0） | B19: =ROUND($B$17-$B$18,2) -> 0 | C19: 不为 0 常见两个原因：粘进来的明细带了“总计/合计”行；或者有门店没写进 门店对照

Sheet 门店对照
A1: 门店编码 | B1: 海典门店名称 | C1: 凭证简称 | D1: 启用(自动) | F1: 【备用门店位】灰色那 10 行是留给以后新开门店的。
A2: 2001 | B2: 柏人商城分店（1店） | C2: 柏人商城店 | D2: =IF(OR($A2="",$C2=""),0,IF(ISNUMBER(FIND("备用",$B2&$C2)),0,1)) -> 1 | F2: 名称里带“备用”两个字、或者门店编码是空的，启用列就是 0 —— 不出凭证、也不占凭证号。
A3: 2002 | B3: 新隆分店（2分店） | C3: 新隆店 | D3: =IF(OR($A3="",$C3=""),0,IF(ISNUMBER(FIND("备用",$B3&$C3)),0,1)) -> 1 | F3: 新开一家店：把其中一行的 门店编码 / 海典门店名称 / 凭证简称 三格改成真的，启用列会自动变 1。
A4: 2003 | B4: 康庄东路分店（3店） | C4: 康庄路店 | D4: =IF(OR($A4="",$C4=""),0,IF(ISNUMBER(FIND("备用",$B4&$C4)),0,1)) -> 1 | F4: 不用的老店想停掉：把凭证简称改成“备用X”，或者把门店编码清空就行。
A5: 2004 | B5: 东关分店（4分店） | C5: 东关店 | D5: =IF(OR($A5="",$C5=""),0,IF(ISNUMBER(FIND("备用",$B5&$C5)),0,1)) -> 1 | F5: 启用列是公式自动算的，不要手工改。
A6: 2005 | B6: 象城街分店（5店） | C6: 象城街店 | D6: =IF(OR($A6="",$C6=""),0,IF(ISNUMBER(FIND("备用",$B6&$C6)),0,1)) -> 1
A7: 2006 | B7: 博荣分店（6分店） | C7: 博荣店 | D7: =IF(OR($A7="",$C7=""),0,IF(ISNUMBER(FIND("备用",$B7&$C7)),0,1)) -> 1
A8: 2007 | B8: 华鑫分店（7店） | C8: 华鑫店 | D8: =IF(OR($A8="",$C8=""),0,IF(ISNUMBER(FIND("备用",$B8&$C8)),0,1)) -> 1
A9: 2008 | B9: 博昭分店（8分店） | C9: 博昭店 | D9: =IF(OR($A9="",$C9=""),0,IF(ISNUMBER(FIND("备用",$B9&$C9)),0,1)) -> 1
A10: 2009 | B10: 大霍分店（9分店） | C10: 大霍店 | D10: =IF(OR($A10="",$C10=""),0,IF(ISNUMBER(FIND("备用",$B10&$C10)),0,1)) -> 1
A11: 2010 | B11: 莲子镇分店(10分店) | C11: 莲子镇店 | D11: =IF(OR($A11="",$C11=""),0,IF(ISNUMBER(FIND("备用",$B11&$C11)),0,1)) -> 1
A12: 2011 | B12: 毛尔寨分店(11分店) | C12: 毛尔寨店 | D12: =IF(OR($A12="",$C12=""),0,IF(ISNUMBER(FIND("备用",$B12&$C12)),0,1)) -> 1
A13: 2012 | B13: 泽畔分店（12分店） | C13: 泽畔店 | D13: =IF(OR($A13="",$C13=""),0,IF(ISNUMBER(FIND("备用",$B13&$C13)),0,1)) -> 1
A14: 2014 | B14: 博桥分店（14分店） | C14: 博桥店 | D14: =IF(OR($A14="",$C14=""),0,IF(ISNUMBER(FIND("备用",$B14&$C14)),0,1)) -> 1
A15: 2015 | B15: 齐村分店（15分店） | C15: 齐村店 | D15: =IF(OR($A15="",$C15=""),0,IF(ISNUMBER(FIND("备用",$B15&$C15)),0,1)) -> 1
A16: 2017 | B16: 博天分店（17分店） | C16: 博天店 | D16: =IF(OR($A16="",$C16=""),0,IF(ISNUMBER(FIND("备用",$B16&$C16)),0,1)) -> 1
A17: 2018 | B17: 魏家庄分店（18分店） | C17: 魏家庄店 | D17: =IF(OR($A17="",$C17=""),0,IF(ISNUMBER(FIND("备用",$B17&$C17)),0,1)) -> 1
... A46: 2069 | B46: 博东分店（69店） | C46: 博东店 | D46: =IF(OR($A46="",$C46=""),0,IF(ISNUMBER(FIND("备用",$B46&$C46)),0,1)) -> 1
B47: 备用1 | C47: 备用1 | D47: =IF(OR($A47="",$C47=""),0,IF(ISNUMBER(FIND("备用",$B47&$C47)),0,1)) -> 0
B48: 备用2 | C48: 备用2 | D48: =IF(OR($A48="",$C48=""),0,IF(ISNUMBER(FIND("备用",$B48&$C48)),0,1)) -> 0
B49: 备用3 | C49: 备用3 | D49: =IF(OR($A49="",$C49=""),0,IF(ISNUMBER(FIND("备用",$B49&$C49)),0,1)) -> 0
B50: 备用4 | C50: 备用4 | D50: =IF(OR($A50="",$C50=""),0,IF(ISNUMBER(FIND("备用",$B50&$C50)),0,1)) -> 0
B51: 备用5 | C51: 备用5 | D51: =IF(OR($A51="",$C51=""),0,IF(ISNUMBER(FIND("备用",$B51&$C51)),0,1)) -> 0
B52: 备用6 | C52: 备用6 | D52: =IF(OR($A52="",$C52=""),0,IF(ISNUMBER(FIND("备用",$B52&$C52)),0,1)) -> 0
B53: 备用7 | C53: 备用7 | D53: =IF(OR($A53="",$C53=""),0,IF(ISNUMBER(FIND("备用",$B53&$C53)),0,1)) -> 0
B54: 备用8 | C54: 备用8 | D54: =IF(OR($A54="",$C54=""),0,IF(ISNUMBER(FIND("备用",$B54&$C54)),0,1)) -> 0
B55: 备用9 | C55: 备用9 | D55: =IF(OR($A55="",$C55=""),0,IF(ISNUMBER(FIND("备用",$B55&$C55)),0,1)) -> 0
B56: 备用10 | C56: 备用10 | D56: =IF(OR($A56="",$C56=""),0,IF(ISNUMBER(FIND("备用",$B56&$C56)),0,1)) -> 0
B57: 备用11 | C57: 备用11 | D57: =IF(OR($A57="",$C57=""),0,IF(ISNUMBER(FIND("备用",$B57&$C57)),0,1)) -> 0
B58: 备用12 | C58: 备用12 | D58: =IF(OR($A58="",$C58=""),0,IF(ISNUMBER(FIND("备用",$B58&$C58)),0,1)) -> 0
... B66: 备用20 | C66: 备用20 | D66: =IF(OR($A66="",$C66=""),0,IF(ISNUMBER(FIND("备用",$B66&$C66)),0,1)) -> 0

Sheet 科目对照收入
A1: 序 | B1: 项目 | C1: 总账科目 | D1: 明细科目 | E1: 取数来源 | F1: 海典列1 | G1: 海典列2 | H1: 海典列3 | I1: 海典列4 | J1: 海典列5 | K1: 海典列6 | L1: 负数时总账科目 | M1: 负数时明细科目 | O1: 【黄色 = 按平台金额入账】
A2: 1 | B2: 库存现金 | C2: 库存现金 | E2: 现金+补差 | O2: 海典列1 涂黄的这些渠道（医保、健e卡、医卡通、企健网、亲情卡、24小时、美团、饿了么、京东秒送、银联、小镇外卖、OMS、平安药卡），
A3: 2 | B3: 聚合支付 | C3: 应收账款 | D3: 聚合支付 | E3: 聚合净额 | O3: 凭证金额优先取 输入平台 页里你填的平台金额；那一行没填才回退到海典金额。平台和海典的差，仍旧走“少钱补现金 / 多钱记营业外”。
A4: 3 | B4: 医保 | C4: 应收账款 | D4: 医保 | E4: 平台优先 | F4: 医保 | G4: 医保统筹
A5: 4 | B5: 健e卡 | C5: 应收账款 | D5: 健e卡 | E5: 平台优先 | F5: 健e卡 | O5: 【负数时总账科目 / 负数时明细科目】
A6: 5 | B6: 医卡通 | C6: 应收账款 | D6: 医卡通 | E6: 平台优先 | F6: 医卡通 | O6: 填了这两格，金额算出来是负数时就换成这个科目、并记到贷方。
A7: 6 | B7: 企健网 | C7: 应收账款 | D7: 企健网 | E7: 平台优先 | F7: 企健网 | O7: 会员零钱包已按你的批注设好：正数 → 借 其他应收款—会员零钱包；负数 → 贷 其他应付款—会员零钱包。
A8: 7 | B8: 亲情卡 | C8: 应收账款 | D8: 亲情卡 | E8: 平台优先 | F8: 亲情卡
A9: 8 | B9: 24小时 | C9: 应收账款 | D9: 24小时 | E9: 平台优先 | F9: 二十四小时 | O9: 【促销费 / 积分】
A10: 9 | B10: 美团 | C10: 应收账款 | D10: 美团 | E10: 平台优先 | F10: 美团 | O10: 促销费 = 微信平台优惠券 + 微信平台礼品券 + 代金券；积分抵现 已单独拆成 销售费用—积分。
A11: 10 | B11: 饿了么 | C11: 应收账款 | D11: 饿了么 | E11: 平台优先 | F11: 饿了么 | O11: 京东LOC券、收银兑换损失 按你的批注去掉了，不再进促销费；万一某月有金额，核对 页会提醒你（想加回来就填进空的海典列里）。
A12: 11 | B12: 京东秒送 | C12: 应收账款 | D12: 京东秒送 | E12: 平台优先 | F12: 京东秒送
A13: 12 | B13: 银联 | C13: 应收账款 | D13: 银联 | E13: 平台优先 | F13: 银联 | O13: 总账科目 / 明细科目（黄底）可以直接改，改完凭证自动跟着变；取数来源和海典列是引擎用的，不要改。
A14: 13 | B14: 小镇外卖 | C14: 应收账款 | D14: 小镇外卖 | E14: 平台优先 | F14: 小镇外卖
A15: 14 | B15: OMS线上支付 | C15: 应收账款 | D15: OMS线上 | E15: 平台优先 | F15: OMS线上支付
A16: 15 | B16: 平安药卡 | C16: 应收账款 | D16: 平安 | E16: 平台优先 | F16: 平安药卡组合支付
A17: 16 | B17: 储值卡 | C17: 其他应收款 | D17: 储值卡 | E17: 海典 | F17: 储值卡
A18: 17 | B18: 会员零钱包 | C18: 其他应收款 | D18: 会员零钱包 | E18: 海典 | F18: 会员零钱包 | L18: 其他应付款 | M18: 会员零钱包
A19: 18 | B19: 促销费 | C19: 销售费用 | D19: 促销费 | E19: 海典 | F19: 微信平台优惠券 | G19: 微信平台礼品券 | H19: 代金券
A20: 19 | B20: 积分 | C20: 销售费用 | D20: 积分 | E20: 海典 | F20: 积分抵现
A21: 20 | B21: 手续费 | C21: 财务费用 | D21: 手续费 | E21: 聚合手续费
A22: 21 | B22: 主营业务收入 | C22: 主营业务收入 | E22: 销售合计
A23: 22 | B23: 营业外收入 | C23: 营业外收入 | E23: 差额

Sheet 科目对照回款
A1: 序 | B1: 项目 | C1: 总账科目 | D1: 明细科目 | E1: 方向 | F1: 收款方式别名1 | G1: 收款方式别名2 | H1: 收款方式别名3 | J1: “收款方式别名”＝ 输入回款 里你写的收款方式名称，写全就能自动归到同一个科目。
A2: 1 | B2: 库存现金 | C2: 库存现金 | E2: 借-回款合计
A3: 2 | B3: 手续费 | C3: 财务费用 | D3: 手续费 | E3: 借-手续费合计
A4: 3 | B4: 聚合支付 | C4: 应收账款 | D4: 聚合支付 | E4: 贷 | F4: 聚合支付
A5: 4 | B5: 医保 | C5: 应收账款 | D5: 医保 | E5: 贷 | F5: 医保 | G5: 医保即时拨付 | H5: 即时拨付
A6: 5 | B6: 美团 | C6: 应收账款 | D6: 美团 | E6: 贷 | F6: 美团
A7: 6 | B7: 饿了么 | C7: 应收账款 | D7: 饿了么 | E7: 贷 | F7: 饿了么
A8: 7 | B8: 24小时 | C8: 应收账款 | D8: 24小时 | E8: 贷 | F8: 24小时 | G8: 二十四小时
A9: 8 | B9: 健E卡 | C9: 应收账款 | D9: 健E卡 | E9: 贷 | F9: 健E卡
A10: 9 | B10: 医卡通 | C10: 应收账款 | D10: 医卡通 | E10: 贷 | F10: 医卡通
A11: 10 | B11: 企健网 | C11: 应收账款 | D11: 企健网 | E11: 贷 | F11: 企健网
A12: 11 | B12: 亲情卡 | C12: 应收账款 | D12: 亲情卡 | E12: 贷 | F12: 亲情卡
A13: 12 | B13: 银联 | C13: 应收账款 | D13: 银联 | E13: 贷 | F13: 银联
A14: 13 | B14: 代金券 | C14: 应收账款 | D14: 代金券 | E14: 贷 | F14: 代金券
A15: 14 | B15: 药机微信 | C15: 应收账款 | D15: 药机微信 | E15: 贷 | F15: 药机微信
A16: 15 | B16: 储值卡 | C16: 其他应收款 | D16: 储值卡 | E16: 贷 | F16: 储值卡

Sheet 输入海典
A1: 序 | B1: 门店代码 | C1: 门店名称 | D1: 会计日 | E1: 现金 | F1: 现11金 | G1: 海典聚合支付 | H1: 医保 | I1: 医保统筹 | J1: 健e卡 | K1: 医卡通 | L1: 企健网 | M1: 二十四小时 | N1: OMS线上支付 | O1: 美团 | P1: 饿了么 | Q1: 京东秒送 | R1: 会员零钱包 | S1: 储值卡 | T1: 积分抵现 | U1: 代金券 | V1: 微信平台礼品券 | W1: 微信平台优惠券 | X1: 银联 | Y1: 微信 | Z1: 支付宝 | AA1: 支付宝_老 | AB1: 亲情卡 | AC1: 京东LOC劵 | AD1: 平安药卡组合支付 | AE1: 小镇外卖 | AF1: 收银兑换损失 | AG1: 销售合计 | AH1: 合计 | AI1: 客流量
A2: 1 | B2: 2001 | C2: 柏人商城分店（1店） | D2: 46208 | E2: 179.2 | F2: 0 | G2: 362.3 | H2: 116 | I2: 0 | J2: 0 | K2: 0 | L2: 0 | M2: 0 | N2: 0 | O2: 0 | P2: 0 | Q2: 0 | R2: 0 | S2: 0 | T2: 0 | U2: 0 | V2: 0 | W2: 0 | X2: 0 | Y2: 0 | Z2: 0 | AA2: 0 | AB2: 0 | AC2: 0 | AD2: 0 | AE2: 0 | AF2: 0 | AG2: 657.5 | AH2: 657.5 | AI2: 20
A3: 2 | B3: 2001 | C3: 柏人商城分店（1店） | D3: 46233 | E3: 54.2 | F3: 0 | G3: 1159.2 | H3: 136 | I3: 0 | J3: 0 | K3: 0 | L3: 0 | M3: 0 | N3: 0 | O3: 0 | P3: 0 | Q3: 0 | R3: 0 | S3: 0 | T3: 0 | U3: 0 | V3: 9.9 | W3: 85.1 | X3: 0 | Y3: 0 | Z3: 0 | AA3: 0 | AB3: 0 | AC3: 0 | AD3: 0 | AE3: 0 | AF3: 0 | AG3: 1444.4 | AH3: 1444.4 | AI3: 26
A4: 3 | B4: 2001 | C4: 柏人商城分店（1店） | D4: 46232 | E4: 159.8 | F4: 0 | G4: 880.2 | H4: 126.4 | I4: 0 | J4: 0 | K4: 0 | L4: 0 | M4: 0 | N4: 0 | O4: 0 | P4: 0 | Q4: 0 | R4: 0 | S4: 0 | T4: 0 | U4: 0 | V4: 0 | W4: 65 | X4: 0 | Y4: 0 | Z4: 0 | AA4: 0 | AB4: 0 | AC4: 0 | AD4: 0 | AE4: 0 | AF4: 0 | AG4: 1231.4 | AH4: 1231.4 | AI4: 28
A5: 4 | B5: 2001 | C5: 柏人商城分店（1店） | D5: 46204 | E5: 840.31 | F5: 0 | G5: 631.81 | H5: 261.16 | I5: 0 | J5: 0 | K5: 0 | L5: 0 | M5: 0 | N5: 0 | O5: 0 | P5: 0 | Q5: 0 | R5: 0 | S5: 0 | T5: 0 | U5: 0 | V5: 3 | W5: 0 | X5: 0 | Y5: 0 | Z5: 0 | AA5: 0 | AB5: 0 | AC5: 0 | AD5: 0 | AE5: 0 | AF5: 0 | AG5: 1736.28 | AH5: 1736.28 | AI5: 37
A6: 5 | B6: 2001 | C6: 柏人商城分店（1店） | D6: 46234 | E6: 74.35 | F6: 0 | G6: 367.75 | H6: 448.9 | I6: 0 | J6: 0 | K6: 0 | L6: 0 | M6: 0 | N6: 0 | O6: 0 | P6: 0 | Q6: 0 | R6: 0 | S6: 0 | T6: 0 | U6: 0 | V6: 0 | W6: 40 | X6: 0 | Y6: 0 | Z6: 0 | AA6: 0 | AB6: 0 | AC6: 0 | AD6: 0 | AE6: 0 | AF6: 0 | AG6: 931 | AH6: 931 | AI6: 20
A7: 6 | B7: 2001 | C7: 柏人商城分店（1店） | D7: 46231 | E7: 127.4 | F7: 0 | G7: 574.05 | H7: 204.8 | I7: 0 | J7: 0 | K7: 0 | L7: 0 | M7: 0 | N7: 0 | O7: 0 | P7: 0 | Q7: 0 | R7: 0 | S7: 0 | T7: 0 | U7: 0 | V7: 0 | W7: 65 | X7: 0 | Y7: 0 | Z7: 0 | AA7: 0 | AB7: 0 | AC7: 0 | AD7: 0 | AE7: 0 | AF7: 0 | AG7: 971.25 | AH7: 971.25 | AI7: 21
A8: 7 | B8: 2001 | C8: 柏人商城分店（1店） | D8: 46220 | E8: 40.8 | F8: 0 | G8: 661.7 | H8: 47.8 | I8: 0 | J8: 0 | K8: 0 | L8: 0 | M8: 0 | N8: 0 | O8: 26 | P8: 0 | Q8: 0 | R8: 0 | S8: 0 | T8: 0 | U8: 0 | V8: 0 | W8: 5 | X8: 0 | Y8: 0 | Z8: 0 | AA8: 0 | AB8: 0 | AC8: 0 | AD8: 0 | AE8: 0 | AF8: 0 | AG8: 781.3 | AH8: 781.3 | AI8: 18
A9: 8 | B9: 2001 | C9: 柏人商城分店（1店） | D9: 46221 | E9: 138.3 | F9: 0 | G9: 510 | H9: 182 | I9: 0 | J9: 0 | K9: 0 | L9: 0 | M9: 0 | N9: 0 | O9: 0 | P9: 0 | Q9: 0 | R9: 0 | S9: 0 | T9: 0 | U9: 0 | V9: 0 | W9: 16 | X9: 0 | Y9: 0 | Z9: 0 | AA9: 0 | AB9: 0 | AC9: 0 | AD9: 0 | AE9: 0 | AF9: 0 | AG9: 846.3 | AH9: 846.3 | AI9: 19
A10: 9 | B10: 2001 | C10: 柏人商城分店（1店） | D10: 46209 | E10: 970.94 | F10: 0 | G10: 1261.58 | H10: 211.84 | I10: 0 | J10: 0 | K10: 0 | L10: 0 | M10: 0 | N10: 0 | O10: 0 | P10: 0 | Q10: 0 | R10: 0 | S10: 0 | T10: 0 | U10: 0 | V10: 3.8 | W10: 21 | X10: 0 | Y10: 0 | Z10: 0 | AA10: 0 | AB10: 0 | AC10: 0 | AD10: 0 | AE10: 0 | AF10: 0 | AG10: 2469.16 | AH10: 2469.16 | AI10: 40
A11: 10 | B11: 2001 | C11: 柏人商城分店（1店） | D11: 46212 | E11: 114.6 | F11: 0 | G11: 581.22 | H11: 35.6 | I11: 0 | J11: 0 | K11: 0 | L11: 0 | M11: 0 | N11: 0 | O11: 0 | P11: 0 | Q11: 0 | R11: 0 | S11: 0 | T11: 0 | U11: 0 | V11: 0 | W11: 0 | X11: 0 | Y11: 0 | Z11: 0 | AA11: 0 | AB11: 0 | AC11: 0 | AD11: 0 | AE11: 0 | AF11: 0 | AG11: 731.42 | AH11: 731.42 | AI11: 18
A12: 11 | B12: 2001 | C12: 柏人商城分店（1店） | D12: 46227 | E12: 253.4 | F12: 0 | G12: 570.5 | H12: 220 | I12: 0 | J12: 0 | K12: 0 | L12: 0 | M12: 0 | N12: 0 | O12: 0 | P12: 0 | Q12: 0 | R12: 0 | S12: 0 | T12: 0 | U12: 0 | V12: 0 | W12: 0 | X12: 0 | Y12: 0 | Z12: 0 | AA12: 0 | AB12: 0 | AC12: 0 | AD12: 0 | AE12: 0 | AF12: 0 | AG12: 1043.9 | AH12: 1043.9 | AI12: 26
A13: 12 | B13: 2001 | C13: 柏人商城分店（1店） | D13: 46222 | E13: 51 | F13: 0 | G13: 707.65 | H13: 194.5 | I13: 0 | J13: 0 | K13: 0 | L13: 0 | M13: 0 | N13: 0 | O13: 0 | P13: 0 | Q13: 0 | R13: 0 | S13: 0 | T13: 0 | U13: 0 | V13: 0 | W13: 5 | X13: 0 | Y13: 0 | Z13: 0 | AA13: 0 | AB13: 0 | AC13: 0 | AD13: 0 | AE13: 0 | AF13: 0 | AG13: 958.15 | AH13: 958.15 | AI13: 23
... A1305: 1304 | B1305: 2069 | C1305: 博东分店（69店） | D1305: 46227 | E1305: 0 | F1305: 0 | G1305: 0 | H1305: 0 | I1305: 0 | J1305: 0 | K1305: 0 | L1305: 0 | M1305: 0 | N1305: 0 | O1305: 0 | P1305: 0 | Q1305: 0 | R1305: 0 | S1305: 0 | T1305: 0 | U1305: 0 | V1305: 0 | W1305: 0 | X1305: 0 | Y1305: 0 | Z1305: 0 | AA1305: 0 | AB1305: 0 | AC1305: 0 | AD1305: 0 | AE1305: 0 | AF1305: 0 | AG1305: 0 | AH1305: 0 | AI1305: 3

Sheet 输入聚合
A1: 门店编码 | B1: 门店名称 | C1: 交易金额 | D1: 服务费 | F1: 聚合支付平台导出的门店汇总：交易金额＝含手续费的总额，服务费＝手续费。
A2: 2001 | B2: 柏人商城分店（1店） | C2: 22768.52 | D2: 61.48
A3: 2002 | B3: 新隆分店（2分店） | C3: 103203.75 | D3: 278.65
A4: 2003 | B4: 康庄东路分店（3店） | C4: 9808.79 | D4: 26.48
A5: 2004 | B5: 东关分店（4分店） | C5: 5004.6 | D5: 13.51
A6: 2005 | B6: 象城街分店（5店） | C6: 18036.9 | D6: 48.7
A7: 2006 | B7: 博荣分店（6分店） | C7: 33428.3 | D7: 90.26
A8: 2007 | B8: 华鑫分店（7店） | C8: 33811.43 | D8: 91.29
A9: 2008 | B9: 博昭分店（8分店） | C9: 53118.64 | D9: 143.42
A10: 2009 | B10: 大霍分店（9分店） | C10: 22410.18 | D10: 60.51
A11: 2010 | B11: 莲子镇分店(10分店) | C11: 67547.35 | D11: 182.38
A12: 2011 | B12: 毛尔寨分店(11分店) | C12: 14193.02 | D12: 38.32
A13: 2012 | B13: 泽畔分店（12分店） | C13: 20343.83 | D13: 54.93
... A42: 2068 | B42: 博山分店（68分店） | C42: 39370.79 | D42: 106.3

Sheet 输入平台
A1: 门店编码 | B1: 渠道 | C1: 平台金额 | D1: 海典金额(自动) | E1: 差额 平台−海典(自动) | F1: 校验 | H1: 【平台金额填这里】
D2: =IF(OR($A2="",$B2=""),"",ROUND(IFERROR(INDEX(海典汇总!$C$3:$AE$67,MATCH($A2,海典汇总!$A$3:$A$67,0),MATCH(INDEX(科目对照收入!$F$2:$F$23,MATCH($B2,科目对照收入!$B$2:$B$23,0)),海典汇总!$C$1:$AE$1,0)),0)+IFERROR(INDEX(海典汇总!$C$3:$AE$67,MATCH($A2,海典汇总!$A$3:$A$67,0),MATCH(INDEX(科目对照收入!$G$2:$G$23,MATCH($B2,科目对照收入!$B$2:$B$23,0)),海典汇总!$C$1:$AE$1,0)),0)+IFERROR(INDEX(海典汇总!$C$3:$AE$67,MATCH($A2,海典汇总!$A$3:$A$67,0),MATCH(INDEX(科目对照收入!$H$2:$H$23,MATCH($B2,科目对照收入!$B$2:$B$23,0)),海典汇总!$C$1:$AE$1,0)),0),2)) | E2: =IF($D2="","",ROUND($C2-$D2,2)) | F2: =IF($A2&$B2="","",IF(COUNTIF(门店对照!$A$2:$A$66,$A2)=0,"× 门店编码不对",IF(COUNTIF(科目对照收入!$B$2:$B$23,$B2)=0,"× 渠道名不对",IF(INDEX(科目对照收入!$E$2:$E$23,MATCH($B2,科目对照收入!$B$2:$B$23,0))<>"平台优先","× 该项目不按平台金额",IF(COUNTIFS($A$2:$A$601,$A2,$B$2:$B$601,$B2)>1,"× 同店同渠道重复","√"))))) | H2: 一行一个“门店＋渠道”。渠道点单元格有下拉框，只有走平台金额的那几个渠道能选。
D3: =IF(OR($A3="",$B3=""),"",ROUND(IFERROR(INDEX(海典汇总!$C$3:$AE$67,MATCH($A3,海典汇总!$A$3:$A$67,0),MATCH(INDEX(科目对照收入!$F$2:$F$23,MATCH($B3,科目对照收入!$B$2:$B$23,0)),海典汇总!$C$1:$AE$1,0)),0)+IFERROR(INDEX(海典汇总!$C$3:$AE$67,MATCH($A3,海典汇总!$A$3:$A$67,0),MATCH(INDEX(科目对照收入!$G$2:$G$23,MATCH($B3,科目对照收入!$B$2:$B$23,0)),海典汇总!$C$1:$AE$1,0)),0)+IFERROR(INDEX(海典汇总!$C$3:$AE$67,MATCH($A3,海典汇总!$A$3:$A$67,0),MATCH(INDEX(科目对照收入!$H$2:$H$23,MATCH($B3,科目对照收入!$B$2:$B$23,0)),海典汇总!$C$1:$AE$1,0)),0),2)) | E3: =IF($D3="","",ROUND($C3-$D3,2)) | F3: =IF($A3&$B3="","",IF(COUNTIF(门店对照!$A$2:$A$66,$A3)=0,"× 门店编码不对",IF(COUNTIF(科目对照收入!$B$2:$B$23,$B3)=0,"× 渠道名不对",IF(INDEX(科目对照收入!$E$2:$E$23,MATCH($B3,科目对照收入!$B$2:$B$23,0))<>"平台优先","× 该项目不按平台金额",IF(COUNTIFS($A$2:$A$601,$A3,$B$2:$B$601,$B3)>1,"× 同店同渠道重复","√"))))) | H3: 平台金额填“不扣手续费的总额”（美团填商品总价、饿了么填商品金额），手续费在回款时再冲。
D4: =IF(OR($A4="",$B4=""),"",ROUND(IFERROR(INDEX(海典汇总!$C$3:$AE$67,MATCH($A4,海典汇总!$A$3:$A$67,0),MATCH(INDEX(科目对照收入!$F$2:$F$23,MATCH($B4,科目对照收入!$B$2:$B$23,0)),海典汇总!$C$1:$AE$1,0)),0)+IFERROR(INDEX(海典汇总!$C$3:$AE$67,MATCH($A4,海典汇总!$A$3:$A$67,0),MATCH(INDEX(科目对照收入!$G$2:$G$23,MATCH($B4,科目对照收入!$B$2:$B$23,0)),海典汇总!$C$1:$AE$1,0)),0)+IFERROR(INDEX(海典汇总!$C$3:$AE$67,MATCH($A4,海典汇总!$A$3:$A$67,0),MATCH(INDEX(科目对照收入!$H$2:$H$23,MATCH($B4,科目对照收入!$B$2:$B$23,0)),海典汇总!$C$1:$AE$1,0)),0),2)) | E4: =IF($D4="","",ROUND($C4-$D4,2)) | F4: =IF($A4&$B4="","",IF(COUNTIF(门店对照!$A$2:$A$66,$A4)=0,"× 门店编码不对",IF(COUNTIF(科目对照收入!$B$2:$B$23,$B4)=0,"× 渠道名不对",IF(INDEX(科目对照收入!$E$2:$E$23,MATCH($B4,科目对照收入!$B$2:$B$23,0))<>"平台优先","× 该项目不按平台金额",IF(COUNTIFS($A$2:$A$601,$A4,$B$2:$B$601,$B4)>1,"× 同店同渠道重复","√"))))) | H4: 某个店某个渠道这里没填 → 凭证自动用海典金额，不会漏账。
D5: =IF(OR($A5="",$B5=""),"",ROUND(IFERROR(INDEX(海典汇总!$C$3:$AE$67,MATCH($A5,海典汇总!$A$3:$A$67,0),MATCH(INDEX(科目对照收入!$F$2:$F$23,MATCH($B5,科目对照收入!$B$2:$B$23,0)),海典汇总!$C$1:$AE$1,0)),0)+IFERROR(INDEX(海典汇总!$C$3:$AE$67,MATCH($A5,海典汇总!$A$3:$A$67,0),MATCH(INDEX(科目对照收入!$G$2:$G$23,MATCH($B5,科目对照收入!$B$2:$B$23,0)),海典汇总!$C$1:$AE$1,0)),0)+IFERROR(INDEX(海典汇总!$C$3:$AE$67,MATCH($A5,海典汇总!$A$3:$A$67,0),MATCH(INDEX(科目对照收入!$H$2:$H$23,MATCH($B5,科目对照收入!$B$2:$B$23,0)),海典汇总!$C$1:$AE$1,0)),0),2)) | E5: =IF($D5="","",ROUND($C5-$D5,2)) | F5: =IF($A5&$B5="","",IF(COUNTIF(门店对照!$A$2:$A$66,$A5)=0,"× 门店编码不对",IF(COUNTIF(科目对照收入!$B$2:$B$23,$B5)=0,"× 渠道名不对",IF(INDEX(科目对照收入!$E$2:$E$23,MATCH($B5,科目对照收入!$B$2:$B$23,0))<>"平台优先","× 该项目不按平台金额",IF(COUNTIFS($A$2:$A$601,$A5,$B$2:$B$601,$B5)>1,"× 同店同渠道重复","√"))))) | H5: 填 0 和不填不一样：填了 0 就按 0 入账（相当于本月这个渠道平台确认为 0）。
D6: =IF(OR($A6="",$B6=""),"",ROUND(IFERROR(INDEX(海典汇总!$C$3:$AE$67,MATCH($A6,海典汇总!$A$3:$A$67,0),MATCH(INDEX(科目对照收入!$F$2:$F$23,MATCH($B6,科目对照收入!$B$2:$B$23,0)),海典汇总!$C$1:$AE$1,0)),0)+IFERROR(INDEX(海典汇总!$C$3:$AE$67,MATCH($A6,海典汇总!$A$3:$A$67,0),MATCH(INDEX(科目对照收入!$G$2:$G$23,MATCH($B6,科目对照收入!$B$2:$B$23,0)),海典汇总!$C$1:$AE$1,0)),0)+IFERROR(INDEX(海典汇总!$C$3:$AE$67,MATCH($A6,海典汇总!$A$3:$A$67,0),MATCH(INDEX(科目对照收入!$H$2:$H$23,MATCH($B6,科目对照收入!$B$2:$B$23,0)),海典汇总!$C$1:$AE$1,0)),0),2)) | E6: =IF($D6="","",ROUND($C6-$D6,2)) | F6: =IF($A6&$B6="","",IF(COUNTIF(门店对照!$A$2:$A$66,$A6)=0,"× 门店编码不对",IF(COUNTIF(科目对照收入!$B$2:$B$23,$B6)=0,"× 渠道名不对",IF(INDEX(科目对照收入!$E$2:$E$23,MATCH($B6,科目对照收入!$B$2:$B$23,0))<>"平台优先","× 该项目不按平台金额",IF(COUNTIFS($A$2:$A$601,$A6,$B$2:$B$601,$B6)>1,"× 同店同渠道重复","√"))))) | H6: 右边两列会自动带出海典金额和差额，方便你核对；差额最后会走“少钱补现金 / 多钱记营业外”。
D7: =IF(OR($A7="",$B7=""),"",ROUND(IFERROR(INDEX(海典汇总!$C$3:$AE$67,MATCH($A7,海典汇总!$A$3:$A$67,0),MATCH(INDEX(科目对照收入!$F$2:$F$23,MATCH($B7,科目对照收入!$B$2:$B$23,0)),海典汇总!$C$1:$AE$1,0)),0)+IFERROR(INDEX(海典汇总!$C$3:$AE$67,MATCH($A7,海典汇总!$A$3:$A$67,0),MATCH(INDEX(科目对照收入!$G$2:$G$23,MATCH($B7,科目对照收入!$B$2:$B$23,0)),海典汇总!$C$1:$AE$1,0)),0)+IFERROR(INDEX(海典汇总!$C$3:$AE$67,MATCH($A7,海典汇总!$A$3:$A$67,0),MATCH(INDEX(科目对照收入!$H$2:$H$23,MATCH($B7,科目对照收入!$B$2:$B$23,0)),海典汇总!$C$1:$AE$1,0)),0),2)) | E7: =IF($D7="","",ROUND($C7-$D7,2)) | F7: =IF($A7&$B7="","",IF(COUNTIF(门店对照!$A$2:$A$66,$A7)=0,"× 门店编码不对",IF(COUNTIF(科目对照收入!$B$2:$B$23,$B7)=0,"× 渠道名不对",IF(INDEX(科目对照收入!$E$2:$E$23,MATCH($B7,科目对照收入!$B$2:$B$23,0))<>"平台优先","× 该项目不按平台金额",IF(COUNTIFS($A$2:$A$601,$A7,$B$2:$B$601,$B7)>1,"× 同店同渠道重复","√")))))
D8: =IF(OR($A8="",$B8=""),"",ROUND(IFERROR(INDEX(海典汇总!$C$3:$AE$67,MATCH($A8,海典汇总!$A$3:$A$67,0),MATCH(INDEX(科目对照收入!$F$2:$F$23,MATCH($B8,科目对照收入!$B$2:$B$23,0)),海典汇总!$C$1:$AE$1,0)),0)+IFERROR(INDEX(海典汇总!$C$3:$AE$67,MATCH($A8,海典汇总!$A$3:$A$67,0),MATCH(INDEX(科目对照收入!$G$2:$G$23,MATCH($B8,科目对照收入!$B$2:$B$23,0)),海典汇总!$C$1:$AE$1,0)),0)+IFERROR(INDEX(海典汇总!$C$3:$AE$67,MATCH($A8,海典汇总!$A$3:$A$67,0),MATCH(INDEX(科目对照收入!$H$2:$H$23,MATCH($B8,科目对照收入!$B$2:$B$23,0)),海典汇总!$C$1:$AE$1,0)),0),2)) | E8: =IF($D8="","",ROUND($C8-$D8,2)) | F8: =IF($A8&$B8="","",IF(COUNTIF(门店对照!$A$2:$A$66,$A8)=0,"× 门店编码不对",IF(COUNTIF(科目对照收入!$B$2:$B$23,$B8)=0,"× 渠道名不对",IF(INDEX(科目对照收入!$E$2:$E$23,MATCH($B8,科目对照收入!$B$2:$B$23,0))<>"平台优先","× 该项目不按平台金额",IF(COUNTIFS($A$2:$A$601,$A8,$B$2:$B$601,$B8)>1,"× 同店同渠道重复","√")))))
D9: =IF(OR($A9="",$B9=""),"",ROUND(IFERROR(INDEX(海典汇总!$C$3:$AE$67,MATCH($A9,海典汇总!$A$3:$A$67,0),MATCH(INDEX(科目对照收入!$F$2:$F$23,MATCH($B9,科目对照收入!$B$2:$B$23,0)),海典汇总!$C$1:$AE$1,0)),0)+IFERROR(INDEX(海典汇总!$C$3:$AE$67,MATCH($A9,海典汇总!$A$3:$A$67,0),MATCH(INDEX(科目对照收入!$G$2:$G$23,MATCH($B9,科目对照收入!$B$2:$B$23,0)),海典汇总!$C$1:$AE$1,0)),0)+IFERROR(INDEX(海典汇总!$C$3:$AE$67,MATCH($A9,海典汇总!$A$3:$A$67,0),MATCH(INDEX(科目对照收入!$H$2:$H$23,MATCH($B9,科目对照收入!$B$2:$B$23,0)),海典汇总!$C$1:$AE$1,0)),0),2)) | E9: =IF($D9="","",ROUND($C9-$D9,2)) | F9: =IF($A9&$B9="","",IF(COUNTIF(门店对照!$A$2:$A$66,$A9)=0,"× 门店编码不对",IF(COUNTIF(科目对照收入!$B$2:$B$23,$B9)=0,"× 渠道名不对",IF(INDEX(科目对照收入!$E$2:$E$23,MATCH($B9,科目对照收入!$B$2:$B$23,0))<>"平台优先","× 该项目不按平台金额",IF(COUNTIFS($A$2:$A$601,$A9,$B$2:$B$601,$B9)>1,"× 同店同渠道重复","√")))))
D10: =IF(OR($A10="",$B10=""),"",ROUND(IFERROR(INDEX(海典汇总!$C$3:$AE$67,MATCH($A10,海典汇总!$A$3:$A$67,0),MATCH(INDEX(科目对照收入!$F$2:$F$23,MATCH($B10,科目对照收入!$B$2:$B$23,0)),海典汇总!$C$1:$AE$1,0)),0)+IFERROR(INDEX(海典汇总!$C$3:$AE$67,MATCH($A10,海典汇总!$A$3:$A$67,0),MATCH(INDEX(科目对照收入!$G$2:$G$23,MATCH($B10,科目对照收入!$B$2:$B$23,0)),海典汇总!$C$1:$AE$1,0)),0)+IFERROR(INDEX(海典汇总!$C$3:$AE$67,MATCH($A10,海典汇总!$A$3:$A$67,0),MATCH(INDEX(科目对照收入!$H$2:$H$23,MATCH($B10,科目对照收入!$B$2:$B$23,0)),海典汇总!$C$1:$AE$1,0)),0),2)) | E10: =IF($D10="","",ROUND($C10-$D10,2)) | F10: =IF($A10&$B10="","",IF(COUNTIF(门店对照!$A$2:$A$66,$A10)=0,"× 门店编码不对",IF(COUNTIF(科目对照收入!$B$2:$B$23,$B10)=0,"× 渠道名不对",IF(INDEX(科目对照收入!$E$2:$E$23,MATCH($B10,科目对照收入!$B$2:$B$23,0))<>"平台优先","× 该项目不按平台金额",IF(COUNTIFS($A$2:$A$601,$A10,$B$2:$B$601,$B10)>1,"× 同店同渠道重复","√")))))
D11: =IF(OR($A11="",$B11=""),"",ROUND(IFERROR(INDEX(海典汇总!$C$3:$AE$67,MATCH($A11,海典汇总!$A$3:$A$67,0),MATCH(INDEX(科目对照收入!$F$2:$F$23,MATCH($B11,科目对照收入!$B$2:$B$23,0)),海典汇总!$C$1:$AE$1,0)),0)+IFERROR(INDEX(海典汇总!$C$3:$AE$67,MATCH($A11,海典汇总!$A$3:$A$67,0),MATCH(INDEX(科目对照收入!$G$2:$G$23,MATCH($B11,科目对照收入!$B$2:$B$23,0)),海典汇总!$C$1:$AE$1,0)),0)+IFERROR(INDEX(海典汇总!$C$3:$AE$67,MATCH($A11,海典汇总!$A$3:$A$67,0),MATCH(INDEX(科目对照收入!$H$2:$H$23,MATCH($B11,科目对照收入!$B$2:$B$23,0)),海典汇总!$C$1:$AE$1,0)),0),2)) | E11: =IF($D11="","",ROUND($C11-$D11,2)) | F11: =IF($A11&$B11="","",IF(COUNTIF(门店对照!$A$2:$A$66,$A11)=0,"× 门店编码不对",IF(COUNTIF(科目对照收入!$B$2:$B$23,$B11)=0,"× 渠道名不对",IF(INDEX(科目对照收入!$E$2:$E$23,MATCH($B11,科目对照收入!$B$2:$B$23,0))<>"平台优先","× 该项目不按平台金额",IF(COUNTIFS($A$2:$A$601,$A11,$B$2:$B$601,$B11)>1,"× 同店同渠道重复","√")))))
D12: =IF(OR($A12="",$B12=""),"",ROUND(IFERROR(INDEX(海典汇总!$C$3:$AE$67,MATCH($A12,海典汇总!$A$3:$A$67,0),MATCH(INDEX(科目对照收入!$F$2:$F$23,MATCH($B12,科目对照收入!$B$2:$B$23,0)),海典汇总!$C$1:$AE$1,0)),0)+IFERROR(INDEX(海典汇总!$C$3:$AE$67,MATCH($A12,海典汇总!$A$3:$A$67,0),MATCH(INDEX(科目对照收入!$G$2:$G$23,MATCH($B12,科目对照收入!$B$2:$B$23,0)),海典汇总!$C$1:$AE$1,0)),0)+IFERROR(INDEX(海典汇总!$C$3:$AE$67,MATCH($A12,海典汇总!$A$3:$A$67,0),MATCH(INDEX(科目对照收入!$H$2:$H$23,MATCH($B12,科目对照收入!$B$2:$B$23,0)),海典汇总!$C$1:$AE$1,0)),0),2)) | E12: =IF($D12="","",ROUND($C12-$D12,2)) | F12: =IF($A12&$B12="","",IF(COUNTIF(门店对照!$A$2:$A$66,$A12)=0,"× 门店编码不对",IF(COUNTIF(科目对照收入!$B$2:$B$23,$B12)=0,"× 渠道名不对",IF(INDEX(科目对照收入!$E$2:$E$23,MATCH($B12,科目对照收入!$B$2:$B$23,0))<>"平台优先","× 该项目不按平台金额",IF(COUNTIFS($A$2:$A$601,$A12,$B$2:$B$601,$B12)>1,"× 同店同渠道重复","√")))))
D13: =IF(OR($A13="",$B13=""),"",ROUND(IFERROR(INDEX(海典汇总!$C$3:$AE$67,MATCH($A13,海典汇总!$A$3:$A$67,0),MATCH(INDEX(科目对照收入!$F$2:$F$23,MATCH($B13,科目对照收入!$B$2:$B$23,0)),海典汇总!$C$1:$AE$1,0)),0)+IFERROR(INDEX(海典汇总!$C$3:$AE$67,MATCH($A13,海典汇总!$A$3:$A$67,0),MATCH(INDEX(科目对照收入!$G$2:$G$23,MATCH($B13,科目对照收入!$B$2:$B$23,0)),海典汇总!$C$1:$AE$1,0)),0)+IFERROR(INDEX(海典汇总!$C$3:$AE$67,MATCH($A13,海典汇总!$A$3:$A$67,0),MATCH(INDEX(科目对照收入!$H$2:$H$23,MATCH($B13,科目对照收入!$B$2:$B$23,0)),海典汇总!$C$1:$AE$1,0)),0),2)) | E13: =IF($D13="","",ROUND($C13-$D13,2)) | F13: =IF($A13&$B13="","",IF(COUNTIF(门店对照!$A$2:$A$66,$A13)=0,"× 门店编码不对",IF(COUNTIF(科目对照收入!$B$2:$B$23,$B13)=0,"× 渠道名不对",IF(INDEX(科目对照收入!$E$2:$E$23,MATCH($B13,科目对照收入!$B$2:$B$23,0))<>"平台优先","× 该项目不按平台金额",IF(COUNTIFS($A$2:$A$601,$A13,$B$2:$B$601,$B13)>1,"× 同店同渠道重复","√")))))
D14: =IF(OR($A14="",$B14=""),"",ROUND(IFERROR(INDEX(海典汇总!$C$3:$AE$67,MATCH($A14,海典汇总!$A$3:$A$67,0),MATCH(INDEX(科目对照收入!$F$2:$F$23,MATCH($B14,科目对照收入!$B$2:$B$23,0)),海典汇总!$C$1:$AE$1,0)),0)+IFERROR(INDEX(海典汇总!$C$3:$AE$67,MATCH($A14,海典汇总!$A$3:$A$67,0),MATCH(INDEX(科目对照收入!$G$2:$G$23,MATCH($B14,科目对照收入!$B$2:$B$23,0)),海典汇总!$C$1:$AE$1,0)),0)+IFERROR(INDEX(海典汇总!$C$3:$AE$67,MATCH($A14,海典汇总!$A$3:$A$67,0),MATCH(INDEX(科目对照收入!$H$2:$H$23,MATCH($B14,科目对照收入!$B$2:$B$23,0)),海典汇总!$C$1:$AE$1,0)),0),2)) | E14: =IF($D14="","",ROUND($C14-$D14,2)) | F14: =IF($A14&$B14="","",IF(COUNTIF(门店对照!$A$2:$A$66,$A14)=0,"× 门店编码不对",IF(COUNTIF(科目对照收入!$B$2:$B$23,$B14)=0,"× 渠道名不对",IF(INDEX(科目对照收入!$E$2:$E$23,MATCH($B14,科目对照收入!$B$2:$B$23,0))<>"平台优先","× 该项目不按平台金额",IF(COUNTIFS($A$2:$A$601,$A14,$B$2:$B$601,$B14)>1,"× 同店同渠道重复","√")))))
D15: =IF(OR($A15="",$B15=""),"",ROUND(IFERROR(INDEX(海典汇总!$C$3:$AE$67,MATCH($A15,海典汇总!$A$3:$A$67,0),MATCH(INDEX(科目对照收入!$F$2:$F$23,MATCH($B15,科目对照收入!$B$2:$B$23,0)),海典汇总!$C$1:$AE$1,0)),0)+IFERROR(INDEX(海典汇总!$C$3:$AE$67,MATCH($A15,海典汇总!$A$3:$A$67,0),MATCH(INDEX(科目对照收入!$G$2:$G$23,MATCH($B15,科目对照收入!$B$2:$B$23,0)),海典汇总!$C$1:$AE$1,0)),0)+IFERROR(INDEX(海典汇总!$C$3:$AE$67,MATCH($A15,海典汇总!$A$3:$A$67,0),MATCH(INDEX(科目对照收入!$H$2:$H$23,MATCH($B15,科目对照收入!$B$2:$B$23,0)),海典汇总!$C$1:$AE$1,0)),0),2)) | E15: =IF($D15="","",ROUND($C15-$D15,2)) | F15: =IF($A15&$B15="","",IF(COUNTIF(门店对照!$A$2:$A$66,$A15)=0,"× 门店编码不对",IF(COUNTIF(科目对照收入!$B$2:$B$23,$B15)=0,"× 渠道名不对",IF(INDEX(科目对照收入!$E$2:$E$23,MATCH($B15,科目对照收入!$B$2:$B$23,0))<>"平台优先","× 该项目不按平台金额",IF(COUNTIFS($A$2:$A$601,$A15,$B$2:$B$601,$B15)>1,"× 同店同渠道重复","√")))))
D16: =IF(OR($A16="",$B16=""),"",ROUND(IFERROR(INDEX(海典汇总!$C$3:$AE$67,MATCH($A16,海典汇总!$A$3:$A$67,0),MATCH(INDEX(科目对照收入!$F$2:$F$23,MATCH($B16,科目对照收入!$B$2:$B$23,0)),海典汇总!$C$1:$AE$1,0)),0)+IFERROR(INDEX(海典汇总!$C$3:$AE$67,MATCH($A16,海典汇总!$A$3:$A$67,0),MATCH(INDEX(科目对照收入!$G$2:$G$23,MATCH($B16,科目对照收入!$B$2:$B$23,0)),海典汇总!$C$1:$AE$1,0)),0)+IFERROR(INDEX(海典汇总!$C$3:$AE$67,MATCH($A16,海典汇总!$A$3:$A$67,0),MATCH(INDEX(科目对照收入!$H$2:$H$23,MATCH($B16,科目对照收入!$B$2:$B$23,0)),海典汇总!$C$1:$AE$1,0)),0),2)) | E16: =IF($D16="","",ROUND($C16-$D16,2)) | F16: =IF($A16&$B16="","",IF(COUNTIF(门店对照!$A$2:$A$66,$A16)=0,"× 门店编码不对",IF(COUNTIF(科目对照收入!$B$2:$B$23,$B16)=0,"× 渠道名不对",IF(INDEX(科目对照收入!$E$2:$E$23,MATCH($B16,科目对照收入!$B$2:$B$23,0))<>"平台优先","× 该项目不按平台金额",IF(COUNTIFS($A$2:$A$601,$A16,$B$2:$B$601,$B16)>1,"× 同店同渠道重复","√")))))
D17: =IF(OR($A17="",$B17=""),"",ROUND(IFERROR(INDEX(海典汇总!$C$3:$AE$67,MATCH($A17,海典汇总!$A$3:$A$67,0),MATCH(INDEX(科目对照收入!$F$2:$F$23,MATCH($B17,科目对照收入!$B$2:$B$23,0)),海典汇总!$C$1:$AE$1,0)),0)+IFERROR(INDEX(海典汇总!$C$3:$AE$67,MATCH($A17,海典汇总!$A$3:$A$67,0),MATCH(INDEX(科目对照收入!$G$2:$G$23,MATCH($B17,科目对照收入!$B$2:$B$23,0)),海典汇总!$C$1:$AE$1,0)),0)+IFERROR(INDEX(海典汇总!$C$3:$AE$67,MATCH($A17,海典汇总!$A$3:$A$67,0),MATCH(INDEX(科目对照收入!$H$2:$H$23,MATCH($B17,科目对照收入!$B$2:$B$23,0)),海典汇总!$C$1:$AE$1,0)),0),2)) | E17: =IF($D17="","",ROUND($C17-$D17,2)) | F17: =IF($A17&$B17="","",IF(COUNTIF(门店对照!$A$2:$A$66,$A17)=0,"× 门店编码不对",IF(COUNTIF(科目对照收入!$B$2:$B$23,$B17)=0,"× 渠道名不对",IF(INDEX(科目对照收入!$E$2:$E$23,MATCH($B17,科目对照收入!$B$2:$B$23,0))<>"平台优先","× 该项目不按平台金额",IF(COUNTIFS($A$2:$A$601,$A17,$B$2:$B$601,$B17)>1,"× 同店同渠道重复","√")))))
D18: =IF(OR($A18="",$B18=""),"",ROUND(IFERROR(INDEX(海典汇总!$C$3:$AE$67,MATCH($A18,海典汇总!$A$3:$A$67,0),MATCH(INDEX(科目对照收入!$F$2:$F$23,MATCH($B18,科目对照收入!$B$2:$B$23,0)),海典汇总!$C$1:$AE$1,0)),0)+IFERROR(INDEX(海典汇总!$C$3:$AE$67,MATCH($A18,海典汇总!$A$3:$A$67,0),MATCH(INDEX(科目对照收入!$G$2:$G$23,MATCH($B18,科目对照收入!$B$2:$B$23,0)),海典汇总!$C$1:$AE$1,0)),0)+IFERROR(INDEX(海典汇总!$C$3:$AE$67,MATCH($A18,海典汇总!$A$3:$A$67,0),MATCH(INDEX(科目对照收入!$H$2:$H$23,MATCH($B18,科目对照收入!$B$2:$B$23,0)),海典汇总!$C$1:$AE$1,0)),0),2)) | E18: =IF($D18="","",ROUND($C18-$D18,2)) | F18: =IF($A18&$B18="","",IF(COUNTIF(门店对照!$A$2:$A$66,$A18)=0,"× 门店编码不对",IF(COUNTIF(科目对照收入!$B$2:$B$23,$B18)=0,"× 渠道名不对",IF(INDEX(科目对照收入!$E$2:$E$23,MATCH($B18,科目对照收入!$B$2:$B$23,0))<>"平台优先","× 该项目不按平台金额",IF(COUNTIFS($A$2:$A$601,$A18,$B$2:$B$601,$B18)>1,"× 同店同渠道重复","√")))))
... D601: =IF(OR($A601="",$B601=""),"",ROUND(IFERROR(INDEX(海典汇总!$C$3:$AE$67,MATCH($A601,海典汇总!$A$3:$A$67,0),MATCH(INDEX(科目对照收入!$F$2:$F$23,MATCH($B601,科目对照收入!$B$2:$B$23,0)),海典汇总!$C$1:$AE$1,0)),0)+IFERROR(INDEX(海典汇总!$C$3:$AE$67,MATCH($A601,海典汇总!$A$3:$A$67,0),MATCH(INDEX(科目对照收入!$G$2:$G$23,MATCH($B601,科目对照收入!$B$2:$B$23,0)),海典汇总!$C$1:$AE$1,0)),0)+IFERROR(INDEX(海典汇总!$C$3:$AE$67,MATCH($A601,海典汇总!$A$3:$A$67,0),MATCH(INDEX(科目对照收入!$H$2:$H$23,MATCH($B601,科目对照收入!$B$2:$B$23,0)),海典汇总!$C$1:$AE$1,0)),0),2)) | E601: =IF($D601="","",ROUND($C601-$D601,2)) | F601: =IF($A601&$B601="","",IF(COUNTIF(门店对照!$A$2:$A$66,$A601)=0,"× 门店编码不对",IF(COUNTIF(科目对照收入!$B$2:$B$23,$B601)=0,"× 渠道名不对",IF(INDEX(科目对照收入!$E$2:$E$23,MATCH($B601,科目对照收入!$B$2:$B$23,0))<>"平台优先","× 该项目不按平台金额",IF(COUNTIFS($A$2:$A$601,$A601,$B$2:$B$601,$B601)>1,"× 同店同渠道重复","√")))))

Sheet 输入现金
A1: 门店编码 | B1: 网银现金合计 | C1: 备注 | E1: 各店本月网银（存款）合计。库存现金按这个数入账，差多少自动补现金。
A2: 2001 | B2: 6428.43 | C2: 示例数字，请换成本店网银合计
A3: 2002 | B3: 290970.85 | C3: 示例数字，请换成本店网银合计
A4: 2003 | B4: 50121.42 | C4: 示例数字，请换成本店网银合计
A5: 2004 | B5: 67171.51 | C5: 示例数字，请换成本店网银合计
A6: 2005 | B6: 63058.21 | C6: 示例数字，请换成本店网银合计
A7: 2006 | B7: 4575.05 | C7: 示例数字，请换成本店网银合计
A8: 2007 | B8: 12722.01 | C8: 示例数字，请换成本店网银合计
A9: 2008 | B9: 8028.82 | C9: 示例数字，请换成本店网银合计
A10: 2009 | B10: 9880.5 | C10: 示例数字，请换成本店网银合计
A11: 2010 | B11: 23656.79 | C11: 示例数字，请换成本店网银合计
A12: 2011 | B12: 24370.58 | C12: 示例数字，请换成本店网银合计
A13: 2012 | B13: 25649.6 | C13: 示例数字，请换成本店网银合计
... A56: 9010 | B56: 0 | C56: 示例数字，请换成本店网银合计

Sheet 输入回款
A1: 门店编码 | B1: 收款方式 | C1: 回款金额 | D1: 手续费 | E1: 备注 | F1: 识别 | G1: 一行一笔：哪个店、什么方式、收到多少（不含手续费的净额）、手续费多少。
A2: 2001 | B2: 聚合支付 | C2: 24279.15 | D2: 0 | F2: =IF($B2="","",IF(COUNTIF(科目对照回款!$F$2:$H$16,$B2)>0,"√","× 未识别")) -> √ | G2: 收款方式请写成 科目对照回款 里的别名，例如 聚合支付 / 医保 / 医保即时拨付 / 美团 / 健E卡 …
A3: 2001 | B3: 医保 | C3: 3786.22 | D3: 0 | F3: =IF($B3="","",IF(COUNTIF(科目对照回款!$F$2:$H$16,$B3)>0,"√","× 未识别")) -> √
A4: 2001 | B4: 医保即时拨付 | C4: 3757.87 | D4: 0 | F4: =IF($B4="","",IF(COUNTIF(科目对照回款!$F$2:$H$16,$B4)>0,"√","× 未识别")) -> √
A5: 2001 | B5: 美团 | C5: 227.07 | D5: 54.73 | F5: =IF($B5="","",IF(COUNTIF(科目对照回款!$F$2:$H$16,$B5)>0,"√","× 未识别")) -> √
A6: 2063 | B6: 聚合支付 | C6: 12424.88 | D6: 0 | F6: =IF($B6="","",IF(COUNTIF(科目对照回款!$F$2:$H$16,$B6)>0,"√","× 未识别")) -> √
A7: 2063 | B7: 医保 | C7: 14089.95 | D7: 0 | F7: =IF($B7="","",IF(COUNTIF(科目对照回款!$F$2:$H$16,$B7)>0,"√","× 未识别")) -> √
A8: 2063 | B8: 医保即时拨付 | C8: 16273.82 | D8: 0 | F8: =IF($B8="","",IF(COUNTIF(科目对照回款!$F$2:$H$16,$B8)>0,"√","× 未识别")) -> √
A9: 2063 | B9: 24小时 | C9: 2678.9 | D9: 244.7 | F9: =IF($B9="","",IF(COUNTIF(科目对照回款!$F$2:$H$16,$B9)>0,"√","× 未识别")) -> √
A10: 2063 | B10: 健E卡 | C10: 111102.61 | D10: 0 | F10: =IF($B10="","",IF(COUNTIF(科目对照回款!$F$2:$H$16,$B10)>0,"√","× 未识别")) -> √
A11: 2003 | B11: 聚合支付 | C11: 7997.23 | D11: 0 | F11: =IF($B11="","",IF(COUNTIF(科目对照回款!$F$2:$H$16,$B11)>0,"√","× 未识别")) -> √
A12: 2003 | B12: 医保 | C12: 15114.33 | D12: 0 | F12: =IF($B12="","",IF(COUNTIF(科目对照回款!$F$2:$H$16,$B12)>0,"√","× 未识别")) -> √
A13: 2003 | B13: 医保即时拨付 | C13: 14098.73 | D13: 0 | F13: =IF($B13="","",IF(COUNTIF(科目对照回款!$F$2:$H$16,$B13)>0,"√","× 未识别")) -> √
A14: 2003 | B14: 美团 | C14: 186.49 | D14: 51.51 | F14: =IF($B14="","",IF(COUNTIF(科目对照回款!$F$2:$H$16,$B14)>0,"√","× 未识别")) -> √
... A149: 2069 | B149: 聚合支付 | C149: 14270.85 | D149: 0 | F149: =IF($B149="","",IF(COUNTIF(科目对照回款!$F$2:$H$16,$B149)>0,"√","× 未识别")) -> √
F150: =IF($B150="","",IF(COUNTIF(科目对照回款!$F$2:$H$16,$B150)>0,"√","× 未识别"))
F151: =IF($B151="","",IF(COUNTIF(科目对照回款!$F$2:$H$16,$B151)>0,"√","× 未识别"))
F152: =IF($B152="","",IF(COUNTIF(科目对照回款!$F$2:$H$16,$B152)>0,"√","× 未识别"))
F153: =IF($B153="","",IF(COUNTIF(科目对照回款!$F$2:$H$16,$B153)>0,"√","× 未识别"))
F154: =IF($B154="","",IF(COUNTIF(科目对照回款!$F$2:$H$16,$B154)>0,"√","× 未识别"))
F155: =IF($B155="","",IF(COUNTIF(科目对照回款!$F$2:$H$16,$B155)>0,"√","× 未识别"))
F156: =IF($B156="","",IF(COUNTIF(科目对照回款!$F$2:$H$16,$B156)>0,"√","× 未识别"))
F157: =IF($B157="","",IF(COUNTIF(科目对照回款!$F$2:$H$16,$B157)>0,"√","× 未识别"))
F158: =IF($B158="","",IF(COUNTIF(科目对照回款!$F$2:$H$16,$B158)>0,"√","× 未识别"))
F159: =IF($B159="","",IF(COUNTIF(科目对照回款!$F$2:$H$16,$B159)>0,"√","× 未识别"))
F160: =IF($B160="","",IF(COUNTIF(科目对照回款!$F$2:$H$16,$B160)>0,"√","× 未识别"))
F161: =IF($B161="","",IF(COUNTIF(科目对照回款!$F$2:$H$16,$B161)>0,"√","× 未识别"))
... F619: =IF($B619="","",IF(COUNTIF(科目对照回款!$F$2:$H$16,$B619)>0,"√","× 未识别"))

Sheet 输入报销
A1: 单号 | B1: 日期 | C1: 门店简称 | D1: 摘要 | E1: 借方总账科目 | F1: 借方明细科目 | G1: 金额 | H1: 付款方式(贷方科目) | I1: 行序(自动) | J1: 键(自动) | K1: 校验 | L1: 同一张报销单用同一个单号；单号请从 1 开始连续编号。
A2: 1 | B2: 46265 | C2: 柏人商城店 | D2: 电费 | E2: 销售费用 | F2: 电费 | G2: 300 | H2: 库存现金 | I2: =IF($A2="","",COUNTIFS($A$2:$A2,$A2)) -> 1 | J2: =IF($A2="","",$A2&"-"&$I2) -> 1-1 | K2: =IF($A2="","",IF(COUNTIF(参数!$B$6:$B$8,$H2)=0,"× 付款方式","√")) -> √ | L2: 一行一个费用科目，金额填正数。付款方式填 库存现金 / 银行存款 / 其他应付款（见 参数 页签）。
A3: 1 | B3: 46265 | C3: 柏人商城店 | D3: 慢病用品 | E3: 销售费用 | F3: 办公费 | G3: 31.7 | H3: 库存现金 | I3: =IF($A3="","",COUNTIFS($A$2:$A3,$A3)) -> 2 | J3: =IF($A3="","",$A3&"-"&$I3) -> 1-2 | K3: =IF($A3="","",IF(COUNTIF(参数!$B$6:$B$8,$H3)=0,"× 付款方式","√")) -> √
A4: 1 | B4: 46265 | C4: 柏人商城店 | D4: 水费 | E4: 销售费用 | F4: 水费 | G4: 5 | H4: 库存现金 | I4: =IF($A4="","",COUNTIFS($A$2:$A4,$A4)) -> 3 | J4: =IF($A4="","",$A4&"-"&$I4) -> 1-3 | K4: =IF($A4="","",IF(COUNTIF(参数!$B$6:$B$8,$H4)=0,"× 付款方式","√")) -> √ | N4: 销售费用 | P4: 电费
A5: 2 | B5: 46265 | C5: 新隆店 | D5: 电费 | E5: 销售费用 | F5: 电费 | G5: 1000 | H5: 库存现金 | I5: =IF($A5="","",COUNTIFS($A$2:$A5,$A5)) -> 1 | J5: =IF($A5="","",$A5&"-"&$I5) -> 2-1 | K5: =IF($A5="","",IF(COUNTIF(参数!$B$6:$B$8,$H5)=0,"× 付款方式","√")) -> √ | N5: 财务费用 | P5: 办公费
A6: 2 | B6: 46265 | C6: 新隆店 | D6: 微信提现费 | E6: 财务费用 | F6: 手续费 | G6: 65 | H6: 库存现金 | I6: =IF($A6="","",COUNTIFS($A$2:$A6,$A6)) -> 2 | J6: =IF($A6="","",$A6&"-"&$I6) -> 2-2 | K6: =IF($A6="","",IF(COUNTIF(参数!$B$6:$B$8,$H6)=0,"× 付款方式","√")) -> √ | N6: 待摊费用 | P6: 水费
A7: 3 | B7: 46265 | C7: 康庄路店 | D7: 电费 | E7: 销售费用 | F7: 电费 | G7: 1000 | H7: 库存现金 | I7: =IF($A7="","",COUNTIFS($A$2:$A7,$A7)) -> 1 | J7: =IF($A7="","",$A7&"-"&$I7) -> 3-1 | K7: =IF($A7="","",IF(COUNTIF(参数!$B$6:$B$8,$H7)=0,"× 付款方式","√")) -> √ | P7: 手续费
A8: 3 | B8: 46265 | C8: 康庄路店 | D8: 灯锁胶布护套线 | E8: 销售费用 | F8: 办公费 | G8: =630+15+17 -> 662 | H8: 库存现金 | I8: =IF($A8="","",COUNTIFS($A$2:$A8,$A8)) -> 2 | J8: =IF($A8="","",$A8&"-"&$I8) -> 3-2 | K8: =IF($A8="","",IF(COUNTIF(参数!$B$6:$B$8,$H8)=0,"× 付款方式","√")) -> √ | P8: 物业费
A9: 3 | B9: 46265 | C9: 康庄路店 | D9: 微信提现费 | E9: 财务费用 | F9: 手续费 | G9: 43.38 | H9: 库存现金 | I9: =IF($A9="","",COUNTIFS($A$2:$A9,$A9)) -> 3 | J9: =IF($A9="","",$A9&"-"&$I9) -> 3-3 | K9: =IF($A9="","",IF(COUNTIF(参数!$B$6:$B$8,$H9)=0,"× 付款方式","√")) -> √ | P9: 电话费
A10: 4 | B10: 46265 | C10: 东关店 | D10: 色带慢病用品 | E10: 销售费用 | F10: 办公费 | G10: 99.7 | H10: 库存现金 | I10: =IF($A10="","",COUNTIFS($A$2:$A10,$A10)) -> 1 | J10: =IF($A10="","",$A10&"-"&$I10) -> 4-1 | K10: =IF($A10="","",IF(COUNTIF(参数!$B$6:$B$8,$H10)=0,"× 付款方式","√")) -> √ | P10: 促销费
A11: 4 | B11: 46265 | C11: 东关店 | D11: 微信提现费 | E11: 财务费用 | F11: 手续费 | G11: 48.05 | H11: 库存现金 | I11: =IF($A11="","",COUNTIFS($A$2:$A11,$A11)) -> 2 | J11: =IF($A11="","",$A11&"-"&$I11) -> 4-2 | K11: =IF($A11="","",IF(COUNTIF(参数!$B$6:$B$8,$H11)=0,"× 付款方式","√")) -> √ | P11: 福利费
A12: 5 | B12: 46265 | C12: 象城街店 | D12: 电费 | E12: 销售费用 | F12: 电费 | G12: 800 | H12: 库存现金 | I12: =IF($A12="","",COUNTIFS($A$2:$A12,$A12)) -> 1 | J12: =IF($A12="","",$A12&"-"&$I12) -> 5-1 | K12: =IF($A12="","",IF(COUNTIF(参数!$B$6:$B$8,$H12)=0,"× 付款方式","√")) -> √
A13: 5 | B13: 46265 | C13: 象城街店 | D13: 慢病用品 | E13: 销售费用 | F13: 办公费 | G13: 59.8 | H13: 库存现金 | I13: =IF($A13="","",COUNTIFS($A$2:$A13,$A13)) -> 2 | J13: =IF($A13="","",$A13&"-"&$I13) -> 5-2 | K13: =IF($A13="","",IF(COUNTIF(参数!$B$6:$B$8,$H13)=0,"× 付款方式","√")) -> √
A14: 5 | B14: 46265 | C14: 象城街店 | D14: 色带 | E14: 销售费用 | F14: 办公费 | G14: 10 | H14: 库存现金 | I14: =IF($A14="","",COUNTIFS($A$2:$A14,$A14)) -> 3 | J14: =IF($A14="","",$A14&"-"&$I14) -> 5-3 | K14: =IF($A14="","",IF(COUNTIF(参数!$B$6:$B$8,$H14)=0,"× 付款方式","√")) -> √
A15: 6 | B15: 46265 | C15: 博荣店 | D15: 电费 | E15: 销售费用 | F15: 电费 | G15: 500.48 | H15: 库存现金 | I15: =IF($A15="","",COUNTIFS($A$2:$A15,$A15)) -> 1 | J15: =IF($A15="","",$A15&"-"&$I15) -> 6-1 | K15: =IF($A15="","",IF(COUNTIF(参数!$B$6:$B$8,$H15)=0,"× 付款方式","√")) -> √
A16: 6 | B16: 46265 | C16: 博荣店 | D16: 物业费 | E16: 待摊费用 | F16: 物业费 | G16: 1314.7 | H16: 库存现金 | I16: =IF($A16="","",COUNTIFS($A$2:$A16,$A16)) -> 2 | J16: =IF($A16="","",$A16&"-"&$I16) -> 6-2 | K16: =IF($A16="","",IF(COUNTIF(参数!$B$6:$B$8,$H16)=0,"× 付款方式","√")) -> √
A17: 7 | B17: 46265 | C17: 华鑫店 | D17: 慢病用品 | E17: 销售费用 | F17: 办公费 | G17: 61.4 | H17: 库存现金 | I17: =IF($A17="","",COUNTIFS($A$2:$A17,$A17)) -> 1 | J17: =IF($A17="","",$A17&"-"&$I17) -> 7-1 | K17: =IF($A17="","",IF(COUNTIF(参数!$B$6:$B$8,$H17)=0,"× 付款方式","√")) -> √
A18: 7 | B18: 46265 | C18: 华鑫店 | D18: 水费 | E18: 销售费用 | F18: 水费 | G18: 20 | H18: 库存现金 | I18: =IF($A18="","",COUNTIFS($A$2:$A18,$A18)) -> 2 | J18: =IF($A18="","",$A18&"-"&$I18) -> 7-2 | K18: =IF($A18="","",IF(COUNTIF(参数!$B$6:$B$8,$H18)=0,"× 付款方式","√")) -> √
A19: 7 | B19: 46265 | C19: 华鑫店 | D19: 电费 | E19: 销售费用 | F19: 电费 | G19: 800 | H19: 库存现金 | I19: =IF($A19="","",COUNTIFS($A$2:$A19,$A19)) -> 3 | J19: =IF($A19="","",$A19&"-"&$I19) -> 7-3 | K19: =IF($A19="","",IF(COUNTIF(参数!$B$6:$B$8,$H19)=0,"× 付款方式","√")) -> √
A20: 8 | B20: 46265 | C20: 大霍店 | D20: 水费 | E20: 销售费用 | F20: 水费 | G20: 15 | H20: 库存现金 | I20: =IF($A20="","",COUNTIFS($A$2:$A20,$A20)) -> 1 | J20: =IF($A20="","",$A20&"-"&$I20) -> 8-1 | K20: =IF($A20="","",IF(COUNTIF(参数!$B$6:$B$8,$H20)=0,"× 付款方式","√")) -> √
A21: 9 | B21: 46265 | C21: 莲子镇店 | D21: 电费 | E21: 销售费用 | F21: 电费 | G21: 600 | H21: 库存现金 | I21: =IF($A21="","",COUNTIFS($A$2:$A21,$A21)) -> 1 | J21: =IF($A21="","",$A21&"-"&$I21) -> 9-1 | K21: =IF($A21="","",IF(COUNTIF(参数!$B$6:$B$8,$H21)=0,"× 付款方式","√")) -> √
A22: 9 | B22: 46265 | C22: 莲子镇店 | D22: 插排饮水机阀 | E22: 销售费用 | F22: 办公费 | G22: 50 | H22: 库存现金 | I22: =IF($A22="","",COUNTIFS($A$2:$A22,$A22)) -> 2 | J22: =IF($A22="","",$A22&"-"&$I22) -> 9-2 | K22: =IF($A22="","",IF(COUNTIF(参数!$B$6:$B$8,$H22)=0,"× 付款方式","√")) -> √
A23: 9 | B23: 46265 | C23: 莲子镇店 | D23: 水费 | E23: 销售费用 | F23: 水费 | G23: 40 | H23: 库存现金 | I23: =IF($A23="","",COUNTIFS($A$2:$A23,$A23)) -> 3 | J23: =IF($A23="","",$A23&"-"&$I23) -> 9-3 | K23: =IF($A23="","",IF(COUNTIF(参数!$B$6:$B$8,$H23)=0,"× 付款方式","√")) -> √
... A108: 37 | B108: 46265 | C108: 博山店 | D108: 电费 | E108: 销售费用 | F108: 电费 | G108: 4000 | H108: 库存现金 | I108: =IF($A108="","",COUNTIFS($A$2:$A108,$A108)) -> 1 | J108: =IF($A108="","",$A108&"-"&$I108) -> 37-1 | K108: =IF($A108="","",IF(COUNTIF(参数!$B$6:$B$8,$H108)=0,"× 付款方式","√")) -> √
A109: 37 | B109: 46265 | C109: 博山店 | D109: 慢病用品 | E109: 销售费用 | G109: 36.9 | H109: 库存现金 | I109: =IF($A109="","",COUNTIFS($A$2:$A109,$A109)) -> 2 | J109: =IF($A109="","",$A109&"-"&$I109) -> 37-2 | K109: =IF($A109="","",IF(COUNTIF(参数!$B$6:$B$8,$H109)=0,"× 付款方式","√")) -> √
I110: =IF($A110="","",COUNTIFS($A$2:$A110,$A110)) | J110: =IF($A110="","",$A110&"-"&$I110) | K110: =IF($A110="","",IF(COUNTIF(参数!$B$6:$B$8,$H110)=0,"× 付款方式","√"))
I111: =IF($A111="","",COUNTIFS($A$2:$A111,$A111)) | J111: =IF($A111="","",$A111&"-"&$I111) | K111: =IF($A111="","",IF(COUNTIF(参数!$B$6:$B$8,$H111)=0,"× 付款方式","√"))
I112: =IF($A112="","",COUNTIFS($A$2:$A112,$A112)) | J112: =IF($A112="","",$A112&"-"&$I112) | K112: =IF($A112="","",IF(COUNTIF(参数!$B$6:$B$8,$H112)=0,"× 付款方式","√"))
I113: =IF($A113="","",COUNTIFS($A$2:$A113,$A113)) | J113: =IF($A113="","",$A113&"-"&$I113) | K113: =IF($A113="","",IF(COUNTIF(参数!$B$6:$B$8,$H113)=0,"× 付款方式","√"))
I114: =IF($A114="","",COUNTIFS($A$2:$A114,$A114)) | J114: =IF($A114="","",$A114&"-"&$I114) | K114: =IF($A114="","",IF(COUNTIF(参数!$B$6:$B$8,$H114)=0,"× 付款方式","√"))
I115: =IF($A115="","",COUNTIFS($A$2:$A115,$A115)) | J115: =IF($A115="","",$A115&"-"&$I115) | K115: =IF($A115="","",IF(COUNTIF(参数!$B$6:$B$8,$H115)=0,"× 付款方式","√"))
I116: =IF($A116="","",COUNTIFS($A$2:$A116,$A116)) | J116: =IF($A116="","",$A116&"-"&$I116) | K116: =IF($A116="","",IF(COUNTIF(参数!$B$6:$B$8,$H116)=0,"× 付款方式","√"))
I117: =IF($A117="","",COUNTIFS($A$2:$A117,$A117)) | J117: =IF($A117="","",$A117&"-"&$I117) | K117: =IF($A117="","",IF(COUNTIF(参数!$B$6:$B$8,$H117)=0,"× 付款方式","√"))
I118: =IF($A118="","",COUNTIFS($A$2:$A118,$A118)) | J118: =IF($A118="","",$A118&"-"&$I118) | K118: =IF($A118="","",IF(COUNTIF(参数!$B$6:$B$8,$H118)=0,"× 付款方式","√"))
I119: =IF($A119="","",COUNTIFS($A$2:$A119,$A119)) | J119: =IF($A119="","",$A119&"-"&$I119) | K119: =IF($A119="","",IF(COUNTIF(参数!$B$6:$B$8,$H119)=0,"× 付款方式","√"))
I120: =IF($A120="","",COUNTIFS($A$2:$A120,$A120)) | J120: =IF($A120="","",$A120&"-"&$I120) | K120: =IF($A120="","",IF(COUNTIF(参数!$B$6:$B$8,$H120)=0,"× 付款方式","√"))
I121: =IF($A121="","",COUNTIFS($A$2:$A121,$A121)) | J121: =IF($A121="","",$A121&"-"&$I121) | K121: =IF($A121="","",IF(COUNTIF(参数!$B$6:$B$8,$H121)=0,"× 付款方式","√"))
... I1201: =IF($A1201="","",COUNTIFS($A$2:$A1201,$A1201)) | J1201: =IF($A1201="","",$A1201&"-"&$I1201) | K1201: =IF($A1201="","",IF(COUNTIF(参数!$B$6:$B$8,$H1201)=0,"× 付款方式","√"))

Sheet 海典汇总
A1: 门店编码 | B1: 门店名称 | C1: 现金 | D1: 现11金 | E1: 海典聚合支付 | F1: 医保 | G1: 医保统筹 | H1: 健e卡 | I1: 医卡通 | J1: 企健网 | K1: 二十四小时 | L1: OMS线上支付 | M1: 美团 | N1: 饿了么 | O1: 京东秒送 | P1: 会员零钱包 | Q1: 储值卡 | R1: 积分抵现 | S1: 代金券 | T1: 微信平台礼品券 | U1: 微信平台优惠券 | V1: 银联 | W1: 微信 | X1: 支付宝 | Y1: 支付宝_老 | Z1: 亲情卡 | AA1: 京东LOC劵 | AB1: 平安药卡组合支付 | AC1: 小镇外卖 | AD1: 收银兑换损失 | AE1: 销售合计
A2: =IFERROR(MATCH("门店代码",输入海典!$1:$1,0),0) -> 2 | B2: =IF($A$2=0,FALSE(),ISTEXT(INDEX(INDEX(输入海典!$A$1:$AN$20000,0,$A$2),2))) -> TRUE | C2: =IFERROR(MATCH(C$1,输入海典!$1:$1,0),0) -> 5 | D2: =IFERROR(MATCH(D$1,输入海典!$1:$1,0),0) -> 6 | E2: =IFERROR(MATCH(E$1,输入海典!$1:$1,0),0) -> 7 | F2: =IFERROR(MATCH(F$1,输入海典!$1:$1,0),0) -> 8 | G2: =IFERROR(MATCH(G$1,输入海典!$1:$1,0),0) -> 9 | H2: =IFERROR(MATCH(H$1,输入海典!$1:$1,0),0) -> 10 | I2: =IFERROR(MATCH(I$1,输入海典!$1:$1,0),0) -> 11 | J2: =IFERROR(MATCH(J$1,输入海典!$1:$1,0),0) -> 12 | ... AE2: =IFERROR(MATCH(AE$1,输入海典!$1:$1,0),0) -> 33
A3: =IF(门店对照!$D2=1,门店对照!$A2,"#未启用#") -> 2001 | B3: =IF(门店对照!$B2="","",门店对照!$B2) -> 柏人商城分店（1店） | C3: =IF(OR(C$2=0,$A$2=0),0,SUMIFS(INDEX(输入海典!$A$1:$AN$20000,0,C$2),INDEX(输入海典!$A$1:$AN$20000,0,$A$2),IF($B$2,""&$A3,$A3))) -> 6428.43 | D3: =IF(OR(D$2=0,$A$2=0),0,SUMIFS(INDEX(输入海典!$A$1:$AN$20000,0,D$2),INDEX(输入海典!$A$1:$AN$20000,0,$A$2),IF($B$2,""&$A3,$A3))) -> 0 | E3: =IF(OR(E$2=0,$A$2=0),0,SUMIFS(INDEX(输入海典!$A$1:$AN$20000,0,E$2),INDEX(输入海典!$A$1:$AN$20000,0,$A$2),IF($B$2,""&$A3,$A3))) -> 22768.52 | F3: =IF(OR(F$2=0,$A$2=0),0,SUMIFS(INDEX(输入海典!$A$1:$AN$20000,0,F$2),INDEX(输入海典!$A$1:$AN$20000,0,$A$2),IF($B$2,""&$A3,$A3))) -> 6716.34 | G3: =IF(OR(G$2=0,$A$2=0),0,SUMIFS(INDEX(输入海典!$A$1:$AN$20000,0,G$2),INDEX(输入海典!$A$1:$AN$20000,0,$A$2),IF($B$2,""&$A3,$A3))) -> 0 | H3: =IF(OR(H$2=0,$A$2=0),0,SUMIFS(INDEX(输入海典!$A$1:$AN$20000,0,H$2),INDEX(输入海典!$A$1:$AN$20000,0,$A$2),IF($B$2,""&$A3,$A3))) -> 0 | I3: =IF(OR(I$2=0,$A$2=0),0,SUMIFS(INDEX(输入海典!$A$1:$AN$20000,0,I$2),INDEX(输入海典!$A$1:$AN$20000,0,$A$2),IF($B$2,""&$A3,$A3))) -> 0 | J3: =IF(OR(J$2=0,$A$2=0),0,SUMIFS(INDEX(输入海典!$A$1:$AN$20000,0,J$2),INDEX(输入海典!$A$1:$AN$20000,0,$A$2),IF($B$2,""&$A3,$A3))) -> 0 | ... AE3: =IF(OR(AE$2=0,$A$2=0),0,SUMIFS(INDEX(输入海典!$A$1:$AN$20000,0,AE$2),INDEX(输入海典!$A$1:$AN$20000,0,$A$2),IF($B$2,""&$A3,$A3))) -> 36409.51
A4: =IF(门店对照!$D3=1,门店对照!$A3,"#未启用#") -> 2002 | B4: =IF(门店对照!$B3="","",门店对照!$B3) -> 新隆分店（2分店） | C4: =IF(OR(C$2=0,$A$2=0),0,SUMIFS(INDEX(输入海典!$A$1:$AN$20000,0,C$2),INDEX(输入海典!$A$1:$AN$20000,0,$A$2),IF($B$2,""&$A4,$A4))) -> 40649.83 | D4: =IF(OR(D$2=0,$A$2=0),0,SUMIFS(INDEX(输入海典!$A$1:$AN$20000,0,D$2),INDEX(输入海典!$A$1:$AN$20000,0,$A$2),IF($B$2,""&$A4,$A4))) -> 250321.02 | E4: =IF(OR(E$2=0,$A$2=0),0,SUMIFS(INDEX(输入海典!$A$1:$AN$20000,0,E$2),INDEX(输入海典!$A$1:$AN$20000,0,$A$2),IF($B$2,""&$A4,$A4))) -> 103203.75 | F4: =IF(OR(F$2=0,$A$2=0),0,SUMIFS(INDEX(输入海典!$A$1:$AN$20000,0,F$2),INDEX(输入海典!$A$1:$AN$20000,0,$A$2),IF($B$2,""&$A4,$A4))) -> 44535.92 | G4: =IF(OR(G$2=0,$A$2=0),0,SUMIFS(INDEX(输入海典!$A$1:$AN$20000,0,G$2),INDEX(输入海典!$A$1:$AN$20000,0,$A$2),IF($B$2,""&$A4,$A4))) -> 485.45 | H4: =IF(OR(H$2=0,$A$2=0),0,SUMIFS(INDEX(输入海典!$A$1:$AN$20000,0,H$2),INDEX(输入海典!$A$1:$AN$20000,0,$A$2),IF($B$2,""&$A4,$A4))) -> 0 | I4: =IF(OR(I$2=0,$A$2=0),0,SUMIFS(INDEX(输入海典!$A$1:$AN$20000,0,I$2),INDEX(输入海典!$A$1:$AN$20000,0,$A$2),IF($B$2,""&$A4,$A4))) -> 0 | J4: =IF(OR(J$2=0,$A$2=0),0,SUMIFS(INDEX(输入海典!$A$1:$AN$20000,0,J$2),INDEX(输入海典!$A$1:$AN$20000,0,$A$2),IF($B$2,""&$A4,$A4))) -> 0 | ... AE4: =IF(OR(AE$2=0,$A$2=0),0,SUMIFS(INDEX(输入海典!$A$1:$AN$20000,0,AE$2),INDEX(输入海典!$A$1:$AN$20000,0,$A$2),IF($B$2,""&$A4,$A4))) -> 444121.45
A5: =IF(门店对照!$D4=1,门店对照!$A4,"#未启用#") -> 2003 | B5: =IF(门店对照!$B4="","",门店对照!$B4) -> 康庄东路分店（3店） | C5: =IF(OR(C$2=0,$A$2=0),0,SUMIFS(INDEX(输入海典!$A$1:$AN$20000,0,C$2),INDEX(输入海典!$A$1:$AN$20000,0,$A$2),IF($B$2,""&$A5,$A5))) -> 10963.03 | D5: =IF(OR(D$2=0,$A$2=0),0,SUMIFS(INDEX(输入海典!$A$1:$AN$20000,0,D$2),INDEX(输入海典!$A$1:$AN$20000,0,$A$2),IF($B$2,""&$A5,$A5))) -> 39158.39 | E5: =IF(OR(E$2=0,$A$2=0),0,SUMIFS(INDEX(输入海典!$A$1:$AN$20000,0,E$2),INDEX(输入海典!$A$1:$AN$20000,0,$A$2),IF($B$2,""&$A5,$A5))) -> 9808.79 | F5: =IF(OR(F$2=0,$A$2=0),0,SUMIFS(INDEX(输入海典!$A$1:$AN$20000,0,F$2),INDEX(输入海典!$A$1:$AN$20000,0,$A$2),IF($B$2,""&$A5,$A5))) -> 30706.84 | G5: =IF(OR(G$2=0,$A$2=0),0,SUMIFS(INDEX(输入海典!$A$1:$AN$20000,0,G$2),INDEX(输入海典!$A$1:$AN$20000,0,$A$2),IF($B$2,""&$A5,$A5))) -> 144 | H5: =IF(OR(H$2=0,$A$2=0),0,SUMIFS(INDEX(输入海典!$A$1:$AN$20000,0,H$2),INDEX(输入海典!$A$1:$AN$20000,0,$A$2),IF($B$2,""&$A5,$A5))) -> 30700.31 | I5: =IF(OR(I$2=0,$A$2=0),0,SUMIFS(INDEX(输入海典!$A$1:$AN$20000,0,I$2),INDEX(输入海典!$A$1:$AN$20000,0,$A$2),IF($B$2,""&$A5,$A5))) -> 586.28 | J5: =IF(OR(J$2=0,$A$2=0),0,SUMIFS(INDEX(输入海典!$A$1:$AN$20000,0,J$2),INDEX(输入海典!$A$1:$AN$20000,0,$A$2),IF($B$2,""&$A5,$A5))) -> 0 | ... AE5: =IF(OR(AE$2=0,$A$2=0),0,SUMIFS(INDEX(输入海典!$A$1:$AN$20000,0,AE$2),INDEX(输入海典!$A$1:$AN$20000,0,$A$2),IF($B$2,""&$A5,$A5))) -> 128377.96
A6: =IF(门店对照!$D5=1,门店对照!$A5,"#未启用#") -> 2004 | B6: =IF(门店对照!$B5="","",门店对照!$B5) -> 东关分店（4分店） | C6: =IF(OR(C$2=0,$A$2=0),0,SUMIFS(INDEX(输入海典!$A$1:$AN$20000,0,C$2),INDEX(输入海典!$A$1:$AN$20000,0,$A$2),IF($B$2,""&$A6,$A6))) -> 13679.31 | D6: =IF(OR(D$2=0,$A$2=0),0,SUMIFS(INDEX(输入海典!$A$1:$AN$20000,0,D$2),INDEX(输入海典!$A$1:$AN$20000,0,$A$2),IF($B$2,""&$A6,$A6))) -> 53492.2 | E6: =IF(OR(E$2=0,$A$2=0),0,SUMIFS(INDEX(输入海典!$A$1:$AN$20000,0,E$2),INDEX(输入海典!$A$1:$AN$20000,0,$A$2),IF($B$2,""&$A6,$A6))) -> 5004.6 | F6: =IF(OR(F$2=0,$A$2=0),0,SUMIFS(INDEX(输入海典!$A$1:$AN$20000,0,F$2),INDEX(输入海典!$A$1:$AN$20000,0,$A$2),IF($B$2,""&$A6,$A6))) -> 21335.84 | G6: =IF(OR(G$2=0,$A$2=0),0,SUMIFS(INDEX(输入海典!$A$1:$AN$20000,0,G$2),INDEX(输入海典!$A$1:$AN$20000,0,$A$2),IF($B$2,""&$A6,$A6))) -> 0 | H6: =IF(OR(H$2=0,$A$2=0),0,SUMIFS(INDEX(输入海典!$A$1:$AN$20000,0,H$2),INDEX(输入海典!$A$1:$AN$20000,0,$A$2),IF($B$2,""&$A6,$A6))) -> 4415.97 | I6: =IF(OR(I$2=0,$A$2=0),0,SUMIFS(INDEX(输入海典!$A$1:$AN$20000,0,I$2),INDEX(输入海典!$A$1:$AN$20000,0,$A$2),IF($B$2,""&$A6,$A6))) -> 0 | J6: =IF(OR(J$2=0,$A$2=0),0,SUMIFS(INDEX(输入海典!$A$1:$AN$20000,0,J$2),INDEX(输入海典!$A$1:$AN$20000,0,$A$2),IF($B$2,""&$A6,$A6))) -> 0 | ... AE6: =IF(OR(AE$2=0,$A$2=0),0,SUMIFS(INDEX(输入海典!$A$1:$AN$20000,0,AE$2),INDEX(输入海典!$A$1:$AN$20000,0,$A$2),IF($B$2,""&$A6,$A6))) -> 108041.04
A7: =IF(门店对照!$D6=1,门店对照!$A6,"#未启用#") -> 2005 | B7: =IF(门店对照!$B6="","",门店对照!$B6) -> 象城街分店（5店） | C7: =IF(OR(C$2=0,$A$2=0),0,SUMIFS(INDEX(输入海典!$A$1:$AN$20000,0,C$2),INDEX(输入海典!$A$1:$AN$20000,0,$A$2),IF($B$2,""&$A7,$A7))) -> 12662.26 | D7: =IF(OR(D$2=0,$A$2=0),0,SUMIFS(INDEX(输入海典!$A$1:$AN$20000,0,D$2),INDEX(输入海典!$A$1:$AN$20000,0,$A$2),IF($B$2,""&$A7,$A7))) -> 50395.95 | E7: =IF(OR(E$2=0,$A$2=0),0,SUMIFS(INDEX(输入海典!$A$1:$AN$20000,0,E$2),INDEX(输入海典!$A$1:$AN$20000,0,$A$2),IF($B$2,""&$A7,$A7))) -> 18036.9 | F7: =IF(OR(F$2=0,$A$2=0),0,SUMIFS(INDEX(输入海典!$A$1:$AN$20000,0,F$2),INDEX(输入海典!$A$1:$AN$20000,0,$A$2),IF($B$2,""&$A7,$A7))) -> 28845.65 | G7: =IF(OR(G$2=0,$A$2=0),0,SUMIFS(INDEX(输入海典!$A$1:$AN$20000,0,G$2),INDEX(输入海典!$A$1:$AN$20000,0,$A$2),IF($B$2,""&$A7,$A7))) -> 0 | H7: =IF(OR(H$2=0,$A$2=0),0,SUMIFS(INDEX(输入海典!$A$1:$AN$20000,0,H$2),INDEX(输入海典!$A$1:$AN$20000,0,$A$2),IF($B$2,""&$A7,$A7))) -> 0 | I7: =IF(OR(I$2=0,$A$2=0),0,SUMIFS(INDEX(输入海典!$A$1:$AN$20000,0,I$2),INDEX(输入海典!$A$1:$AN$20000,0,$A$2),IF($B$2,""&$A7,$A7))) -> 2583.12 | J7: =IF(OR(J$2=0,$A$2=0),0,SUMIFS(INDEX(输入海典!$A$1:$AN$20000,0,J$2),INDEX(输入海典!$A$1:$AN$20000,0,$A$2),IF($B$2,""&$A7,$A7))) -> 0 | ... AE7: =IF(OR(AE$2=0,$A$2=0),0,SUMIFS(INDEX(输入海典!$A$1:$AN$20000,0,AE$2),INDEX(输入海典!$A$1:$AN$20000,0,$A$2),IF($B$2,""&$A7,$A7))) -> 116657.9
A8: =IF(门店对照!$D7=1,门店对照!$A7,"#未启用#") -> 2006 | B8: =IF(门店对照!$B7="","",门店对照!$B7) -> 博荣分店（6分店） | C8: =IF(OR(C$2=0,$A$2=0),0,SUMIFS(INDEX(输入海典!$A$1:$AN$20000,0,C$2),INDEX(输入海典!$A$1:$AN$20000,0,$A$2),IF($B$2,""&$A8,$A8))) -> 4575.05 | D8: =IF(OR(D$2=0,$A$2=0),0,SUMIFS(INDEX(输入海典!$A$1:$AN$20000,0,D$2),INDEX(输入海典!$A$1:$AN$20000,0,$A$2),IF($B$2,""&$A8,$A8))) -> 0 | E8: =IF(OR(E$2=0,$A$2=0),0,SUMIFS(INDEX(输入海典!$A$1:$AN$20000,0,E$2),INDEX(输入海典!$A$1:$AN$20000,0,$A$2),IF($B$2,""&$A8,$A8))) -> 33428.3 | F8: =IF(OR(F$2=0,$A$2=0),0,SUMIFS(INDEX(输入海典!$A$1:$AN$20000,0,F$2),INDEX(输入海典!$A$1:$AN$20000,0,$A$2),IF($B$2,""&$A8,$A8))) -> 21770.57 | G8: =IF(OR(G$2=0,$A$2=0),0,SUMIFS(INDEX(输入海典!$A$1:$AN$20000,0,G$2),INDEX(输入海典!$A$1:$AN$20000,0,$A$2),IF($B$2,""&$A8,$A8))) -> 291.52 | H8: =IF(OR(H$2=0,$A$2=0),0,SUMIFS(INDEX(输入海典!$A$1:$AN$20000,0,H$2),INDEX(输入海典!$A$1:$AN$20000,0,$A$2),IF($B$2,""&$A8,$A8))) -> 3402.37 | I8: =IF(OR(I$2=0,$A$2=0),0,SUMIFS(INDEX(输入海典!$A$1:$AN$20000,0,I$2),INDEX(输入海典!$A$1:$AN$20000,0,$A$2),IF($B$2,""&$A8,$A8))) -> 0 | J8: =IF(OR(J$2=0,$A$2=0),0,SUMIFS(INDEX(输入海典!$A$1:$AN$20000,0,J$2),INDEX(输入海典!$A$1:$AN$20000,0,$A$2),IF($B$2,""&$A8,$A8))) -> 0 | ... AE8: =IF(OR(AE$2=0,$A$2=0),0,SUMIFS(INDEX(输入海典!$A$1:$AN$20000,0,AE$2),INDEX(输入海典!$A$1:$AN$20000,0,$A$2),IF($B$2,""&$A8,$A8))) -> 65353.62
A9: =IF(门店对照!$D8=1,门店对照!$A8,"#未启用#") -> 2007 | B9: =IF(门店对照!$B8="","",门店对照!$B8) -> 华鑫分店（7店） | C9: =IF(OR(C$2=0,$A$2=0),0,SUMIFS(INDEX(输入海典!$A$1:$AN$20000,0,C$2),INDEX(输入海典!$A$1:$AN$20000,0,$A$2),IF($B$2,""&$A9,$A9))) -> 12722.01 | D9: =IF(OR(D$2=0,$A$2=0),0,SUMIFS(INDEX(输入海典!$A$1:$AN$20000,0,D$2),INDEX(输入海典!$A$1:$AN$20000,0,$A$2),IF($B$2,""&$A9,$A9))) -> 0 | E9: =IF(OR(E$2=0,$A$2=0),0,SUMIFS(INDEX(输入海典!$A$1:$AN$20000,0,E$2),INDEX(输入海典!$A$1:$AN$20000,0,$A$2),IF($B$2,""&$A9,$A9))) -> 33811.43 | F9: =IF(OR(F$2=0,$A$2=0),0,SUMIFS(INDEX(输入海典!$A$1:$AN$20000,0,F$2),INDEX(输入海典!$A$1:$AN$20000,0,$A$2),IF($B$2,""&$A9,$A9))) -> 11838.8 | G9: =IF(OR(G$2=0,$A$2=0),0,SUMIFS(INDEX(输入海典!$A$1:$AN$20000,0,G$2),INDEX(输入海典!$A$1:$AN$20000,0,$A$2),IF($B$2,""&$A9,$A9))) -> 0 | H9: =IF(OR(H$2=0,$A$2=0),0,SUMIFS(INDEX(输入海典!$A$1:$AN$20000,0,H$2),INDEX(输入海典!$A$1:$AN$20000,0,$A$2),IF($B$2,""&$A9,$A9))) -> 0 | I9: =IF(OR(I$2=0,$A$2=0),0,SUMIFS(INDEX(输入海典!$A$1:$AN$20000,0,I$2),INDEX(输入海典!$A$1:$AN$20000,0,$A$2),IF($B$2,""&$A9,$A9))) -> 0 | J9: =IF(OR(J$2=0,$A$2=0),0,SUMIFS(INDEX(输入海典!$A$1:$AN$20000,0,J$2),INDEX(输入海典!$A$1:$AN$20000,0,$A$2),IF($B$2,""&$A9,$A9))) -> 2189.3 | ... AE9: =IF(OR(AE$2=0,$A$2=0),0,SUMIFS(INDEX(输入海典!$A$1:$AN$20000,0,AE$2),INDEX(输入海典!$A$1:$AN$20000,0,$A$2),IF($B$2,""&$A9,$A9))) -> 64343.02
A10: =IF(门店对照!$D9=1,门店对照!$A9,"#未启用#") -> 2008 | B10: =IF(门店对照!$B9="","",门店对照!$B9) -> 博昭分店（8分店） | C10: =IF(OR(C$2=0,$A$2=0),0,SUMIFS(INDEX(输入海典!$A$1:$AN$20000,0,C$2),INDEX(输入海典!$A$1:$AN$20000,0,$A$2),IF($B$2,""&$A10,$A10))) -> 8028.82 | D10: =IF(OR(D$2=0,$A$2=0),0,SUMIFS(INDEX(输入海典!$A$1:$AN$20000,0,D$2),INDEX(输入海典!$A$1:$AN$20000,0,$A$2),IF($B$2,""&$A10,$A10))) -> 0 | E10: =IF(OR(E$2=0,$A$2=0),0,SUMIFS(INDEX(输入海典!$A$1:$AN$20000,0,E$2),INDEX(输入海典!$A$1:$AN$20000,0,$A$2),IF($B$2,""&$A10,$A10))) -> 53118.64 | F10: =IF(OR(F$2=0,$A$2=0),0,SUMIFS(INDEX(输入海典!$A$1:$AN$20000,0,F$2),INDEX(输入海典!$A$1:$AN$20000,0,$A$2),IF($B$2,""&$A10,$A10))) -> 10758.32 | G10: =IF(OR(G$2=0,$A$2=0),0,SUMIFS(INDEX(输入海典!$A$1:$AN$20000,0,G$2),INDEX(输入海典!$A$1:$AN$20000,0,$A$2),IF($B$2,""&$A10,$A10))) -> 0 | H10: =IF(OR(H$2=0,$A$2=0),0,SUMIFS(INDEX(输入海典!$A$1:$AN$20000,0,H$2),INDEX(输入海典!$A$1:$AN$20000,0,$A$2),IF($B$2,""&$A10,$A10))) -> 0 | I10: =IF(OR(I$2=0,$A$2=0),0,SUMIFS(INDEX(输入海典!$A$1:$AN$20000,0,I$2),INDEX(输入海典!$A$1:$AN$20000,0,$A$2),IF($B$2,""&$A10,$A10))) -> 0 | J10: =IF(OR(J$2=0,$A$2=0),0,SUMIFS(INDEX(输入海典!$A$1:$AN$20000,0,J$2),INDEX(输入海典!$A$1:$AN$20000,0,$A$2),IF($B$2,""&$A10,$A10))) -> 0 | ... AE10: =IF(OR(AE$2=0,$A$2=0),0,SUMIFS(INDEX(输入海典!$A$1:$AN$20000,0,AE$2),INDEX(输入海典!$A$1:$AN$20000,0,$A$2),IF($B$2,""&$A10,$A10))) -> 75943.14
A11: =IF(门店对照!$D10=1,门店对照!$A10,"#未启用#") -> 2009 | B11: =IF(门店对照!$B10="","",门店对照!$B10) -> 大霍分店（9分店） | C11: =IF(OR(C$2=0,$A$2=0),0,SUMIFS(INDEX(输入海典!$A$1:$AN$20000,0,C$2),INDEX(输入海典!$A$1:$AN$20000,0,$A$2),IF($B$2,""&$A11,$A11))) -> 9880.5 | D11: =IF(OR(D$2=0,$A$2=0),0,SUMIFS(INDEX(输入海典!$A$1:$AN$20000,0,D$2),INDEX(输入海典!$A$1:$AN$20000,0,$A$2),IF($B$2,""&$A11,$A11))) -> 0 | E11: =IF(OR(E$2=0,$A$2=0),0,SUMIFS(INDEX(输入海典!$A$1:$AN$20000,0,E$2),INDEX(输入海典!$A$1:$AN$20000,0,$A$2),IF($B$2,""&$A11,$A11))) -> 22410.18 | F11: =IF(OR(F$2=0,$A$2=0),0,SUMIFS(INDEX(输入海典!$A$1:$AN$20000,0,F$2),INDEX(输入海典!$A$1:$AN$20000,0,$A$2),IF($B$2,""&$A11,$A11))) -> 3361.43 | G11: =IF(OR(G$2=0,$A$2=0),0,SUMIFS(INDEX(输入海典!$A$1:$AN$20000,0,G$2),INDEX(输入海典!$A$1:$AN$20000,0,$A$2),IF($B$2,""&$A11,$A11))) -> 0 | H11: =IF(OR(H$2=0,$A$2=0),0,SUMIFS(INDEX(输入海典!$A$1:$AN$20000,0,H$2),INDEX(输入海典!$A$1:$AN$20000,0,$A$2),IF($B$2,""&$A11,$A11))) -> 0 | I11: =IF(OR(I$2=0,$A$2=0),0,SUMIFS(INDEX(输入海典!$A$1:$AN$20000,0,I$2),INDEX(输入海典!$A$1:$AN$20000,0,$A$2),IF($B$2,""&$A11,$A11))) -> 0 | J11: =IF(OR(J$2=0,$A$2=0),0,SUMIFS(INDEX(输入海典!$A$1:$AN$20000,0,J$2),INDEX(输入海典!$A$1:$AN$20000,0,$A$2),IF($B$2,""&$A11,$A11))) -> 0 | ... AE11: =IF(OR(AE$2=0,$A$2=0),0,SUMIFS(INDEX(输入海典!$A$1:$AN$20000,0,AE$2),INDEX(输入海典!$A$1:$AN$20000,0,$A$2),IF($B$2,""&$A11,$A11))) -> 36619.7
A12: =IF(门店对照!$D11=1,门店对照!$A11,"#未启用#") -> 2010 | B12: =IF(门店对照!$B11="","",门店对照!$B11) -> 莲子镇分店(10分店) | C12: =IF(OR(C$2=0,$A$2=0),0,SUMIFS(INDEX(输入海典!$A$1:$AN$20000,0,C$2),INDEX(输入海典!$A$1:$AN$20000,0,$A$2),IF($B$2,""&$A12,$A12))) -> 23656.79 | D12: =IF(OR(D$2=0,$A$2=0),0,SUMIFS(INDEX(输入海典!$A$1:$AN$20000,0,D$2),INDEX(输入海典!$A$1:$AN$20000,0,$A$2),IF($B$2,""&$A12,$A12))) -> 0 | E12: =IF(OR(E$2=0,$A$2=0),0,SUMIFS(INDEX(输入海典!$A$1:$AN$20000,0,E$2),INDEX(输入海典!$A$1:$AN$20000,0,$A$2),IF($B$2,""&$A12,$A12))) -> 67547.35 | F12: =IF(OR(F$2=0,$A$2=0),0,SUMIFS(INDEX(输入海典!$A$1:$AN$20000,0,F$2),INDEX(输入海典!$A$1:$AN$20000,0,$A$2),IF($B$2,""&$A12,$A12))) -> 14875.36 | G12: =IF(OR(G$2=0,$A$2=0),0,SUMIFS(INDEX(输入海典!$A$1:$AN$20000,0,G$2),INDEX(输入海典!$A$1:$AN$20000,0,$A$2),IF($B$2,""&$A12,$A12))) -> 0 | H12: =IF(OR(H$2=0,$A$2=0),0,SUMIFS(INDEX(输入海典!$A$1:$AN$20000,0,H$2),INDEX(输入海典!$A$1:$AN$20000,0,$A$2),IF($B$2,""&$A12,$A12))) -> 0 | I12: =IF(OR(I$2=0,$A$2=0),0,SUMIFS(INDEX(输入海典!$A$1:$AN$20000,0,I$2),INDEX(输入海典!$A$1:$AN$20000,0,$A$2),IF($B$2,""&$A12,$A12))) -> 0 | J12: =IF(OR(J$2=0,$A$2=0),0,SUMIFS(INDEX(输入海典!$A$1:$AN$20000,0,J$2),INDEX(输入海典!$A$1:$AN$20000,0,$A$2),IF($B$2,""&$A12,$A12))) -> 0 | ... AE12: =IF(OR(AE$2=0,$A$2=0),0,SUMIFS(INDEX(输入海典!$A$1:$AN$20000,0,AE$2),INDEX(输入海典!$A$1:$AN$20000,0,$A$2),IF($B$2,""&$A12,$A12))) -> 107280.2
A13: =IF(门店对照!$D12=1,门店对照!$A12,"#未启用#") -> 2011 | B13: =IF(门店对照!$B12="","",门店对照!$B12) -> 毛尔寨分店(11分店) | C13: =IF(OR(C$2=0,$A$2=0),0,SUMIFS(INDEX(输入海典!$A$1:$AN$20000,0,C$2),INDEX(输入海典!$A$1:$AN$20000,0,$A$2),IF($B$2,""&$A13,$A13))) -> 24370.58 | D13: =IF(OR(D$2=0,$A$2=0),0,SUMIFS(INDEX(输入海典!$A$1:$AN$20000,0,D$2),INDEX(输入海典!$A$1:$AN$20000,0,$A$2),IF($B$2,""&$A13,$A13))) -> 0 | E13: =IF(OR(E$2=0,$A$2=0),0,SUMIFS(INDEX(输入海典!$A$1:$AN$20000,0,E$2),INDEX(输入海典!$A$1:$AN$20000,0,$A$2),IF($B$2,""&$A13,$A13))) -> 14193.02 | F13: =IF(OR(F$2=0,$A$2=0),0,SUMIFS(INDEX(输入海典!$A$1:$AN$20000,0,F$2),INDEX(输入海典!$A$1:$AN$20000,0,$A$2),IF($B$2,""&$A13,$A13))) -> 2921.49 | G13: =IF(OR(G$2=0,$A$2=0),0,SUMIFS(INDEX(输入海典!$A$1:$AN$20000,0,G$2),INDEX(输入海典!$A$1:$AN$20000,0,$A$2),IF($B$2,""&$A13,$A13))) -> 0 | H13: =IF(OR(H$2=0,$A$2=0),0,SUMIFS(INDEX(输入海典!$A$1:$AN$20000,0,H$2),INDEX(输入海典!$A$1:$AN$20000,0,$A$2),IF($B$2,""&$A13,$A13))) -> 0 | I13: =IF(OR(I$2=0,$A$2=0),0,SUMIFS(INDEX(输入海典!$A$1:$AN$20000,0,I$2),INDEX(输入海典!$A$1:$AN$20000,0,$A$2),IF($B$2,""&$A13,$A13))) -> 0 | J13: =IF(OR(J$2=0,$A$2=0),0,SUMIFS(INDEX(输入海典!$A$1:$AN$20000,0,J$2),INDEX(输入海典!$A$1:$AN$20000,0,$A$2),IF($B$2,""&$A13,$A13))) -> 0 | ... AE13: =IF(OR(AE$2=0,$A$2=0),0,SUMIFS(INDEX(输入海典!$A$1:$AN$20000,0,AE$2),INDEX(输入海典!$A$1:$AN$20000,0,$A$2),IF($B$2,""&$A13,$A13))) -> 42823.36
A14: =IF(门店对照!$D13=1,门店对照!$A13,"#未启用#") -> 2012 | B14: =IF(门店对照!$B13="","",门店对照!$B13) -> 泽畔分店（12分店） | C14: =IF(OR(C$2=0,$A$2=0),0,SUMIFS(INDEX(输入海典!$A$1:$AN$20000,0,C$2),INDEX(输入海典!$A$1:$AN$20000,0,$A$2),IF($B$2,""&$A14,$A14))) -> 25649.6 | D14: =IF(OR(D$2=0,$A$2=0),0,SUMIFS(INDEX(输入海典!$A$1:$AN$20000,0,D$2),INDEX(输入海典!$A$1:$AN$20000,0,$A$2),IF($B$2,""&$A14,$A14))) -> 0 | E14: =IF(OR(E$2=0,$A$2=0),0,SUMIFS(INDEX(输入海典!$A$1:$AN$20000,0,E$2),INDEX(输入海典!$A$1:$AN$20000,0,$A$2),IF($B$2,""&$A14,$A14))) -> 20343.83 | F14: =IF(OR(F$2=0,$A$2=0),0,SUMIFS(INDEX(输入海典!$A$1:$AN$20000,0,F$2),INDEX(输入海典!$A$1:$AN$20000,0,$A$2),IF($B$2,""&$A14,$A14))) -> 3187.38 | G14: =IF(OR(G$2=0,$A$2=0),0,SUMIFS(INDEX(输入海典!$A$1:$AN$20000,0,G$2),INDEX(输入海典!$A$1:$AN$20000,0,$A$2),IF($B$2,""&$A14,$A14))) -> 0 | H14: =IF(OR(H$2=0,$A$2=0),0,SUMIFS(INDEX(输入海典!$A$1:$AN$20000,0,H$2),INDEX(输入海典!$A$1:$AN$20000,0,$A$2),IF($B$2,""&$A14,$A14))) -> 0 | I14: =IF(OR(I$2=0,$A$2=0),0,SUMIFS(INDEX(输入海典!$A$1:$AN$20000,0,I$2),INDEX(输入海典!$A$1:$AN$20000,0,$A$2),IF($B$2,""&$A14,$A14))) -> 0 | J14: =IF(OR(J$2=0,$A$2=0),0,SUMIFS(INDEX(输入海典!$A$1:$AN$20000,0,J$2),INDEX(输入海典!$A$1:$AN$20000,0,$A$2),IF($B$2,""&$A14,$A14))) -> 0 | ... AE14: =IF(OR(AE$2=0,$A$2=0),0,SUMIFS(INDEX(输入海典!$A$1:$AN$20000,0,AE$2),INDEX(输入海典!$A$1:$AN$20000,0,$A$2),IF($B$2,""&$A14,$A14))) -> 50656.25
... A67: =IF(门店对照!$D66=1,门店对照!$A66,"#未启用#") -> #未启用# | B67: =IF(门店对照!$B66="","",门店对照!$B66) -> 备用20 | C67: =IF(OR(C$2=0,$A$2=0),0,SUMIFS(INDEX(输入海典!$A$1:$AN$20000,0,C$2),INDEX(输入海典!$A$1:$AN$20000,0,$A$2),IF($B$2,""&$A67,$A67))) -> 0 | D67: =IF(OR(D$2=0,$A$2=0),0,SUMIFS(INDEX(输入海典!$A$1:$AN$20000,0,D$2),INDEX(输入海典!$A$1:$AN$20000,0,$A$2),IF($B$2,""&$A67,$A67))) -> 0 | E67: =IF(OR(E$2=0,$A$2=0),0,SUMIFS(INDEX(输入海典!$A$1:$AN$20000,0,E$2),INDEX(输入海典!$A$1:$AN$20000,0,$A$2),IF($B$2,""&$A67,$A67))) -> 0 | F67: =IF(OR(F$2=0,$A$2=0),0,SUMIFS(INDEX(输入海典!$A$1:$AN$20000,0,F$2),INDEX(输入海典!$A$1:$AN$20000,0,$A$2),IF($B$2,""&$A67,$A67))) -> 0 | G67: =IF(OR(G$2=0,$A$2=0),0,SUMIFS(INDEX(输入海典!$A$1:$AN$20000,0,G$2),INDEX(输入海典!$A$1:$AN$20000,0,$A$2),IF($B$2,""&$A67,$A67))) -> 0 | H67: =IF(OR(H$2=0,$A$2=0),0,SUMIFS(INDEX(输入海典!$A$1:$AN$20000,0,H$2),INDEX(输入海典!$A$1:$AN$20000,0,$A$2),IF($B$2,""&$A67,$A67))) -> 0 | I67: =IF(OR(I$2=0,$A$2=0),0,SUMIFS(INDEX(输入海典!$A$1:$AN$20000,0,I$2),INDEX(输入海典!$A$1:$AN$20000,0,$A$2),IF($B$2,""&$A67,$A67))) -> 0 | J67: =IF(OR(J$2=0,$A$2=0),0,SUMIFS(INDEX(输入海典!$A$1:$AN$20000,0,J$2),INDEX(输入海典!$A$1:$AN$20000,0,$A$2),IF($B$2,""&$A67,$A67))) -> 0 | ... AE67: =IF(OR(AE$2=0,$A$2=0),0,SUMIFS(INDEX(输入海典!$A$1:$AN$20000,0,AE$2),INDEX(输入海典!$A$1:$AN$20000,0,$A$2),IF($B$2,""&$A67,$A67))) -> 0

Sheet 分录收入
A1: 店序 | B1: 门店编码 | C1: 门店简称 | D1: 项目 | E1: 总账科目 | F1: 明细科目 | G1: 净额(+借-贷) | H1: 借方 | I1: 贷方 | J1: 有效 | K1: 店内序 | L1: 键 | M1: 摘要
A2: 1 | B2: =助手收入!$B2 -> 2001 | C2: =助手收入!$C2 -> 柏人商城店 | D2: =科目对照收入!$B2&"" -> 库存现金 | E2: =IF(AND(ROUND($G2,2)<0,科目对照收入!$L2<>""),科目对照收入!$L2,科目对照收入!$C2)&"" -> 库存现金 | F2: =IF(AND(ROUND($G2,2)<0,科目对照收入!$L2<>""),科目对照收入!$M2,科目对照收入!$D2)&"" | G2: =助手收入!$I2 -> 6428.43 | H2: =IF(ROUND($G2,2)>0,ROUND($G2,2),"") -> 6428.43 | I2: =IF(ROUND($G2,2)<0,-ROUND($G2,2),"") | J2: =IF(ROUND($G2,2)=0,0,1) -> 1 | K2: =IF($J2=0,"",SUM($J$2:$J2)) -> 1 | L2: =IF($K2="","",$A2*100+$K2) -> 101 | M2: =参数!$B$3 -> 7月收入
A3: 1 | B3: =助手收入!$B2 -> 2001 | C3: =助手收入!$C2 -> 柏人商城店 | D3: =科目对照收入!$B3&"" -> 聚合支付 | E3: =IF(AND(ROUND($G3,2)<0,科目对照收入!$L3<>""),科目对照收入!$L3,科目对照收入!$C3)&"" -> 应收账款 | F3: =IF(AND(ROUND($G3,2)<0,科目对照收入!$L3<>""),科目对照收入!$M3,科目对照收入!$D3)&"" -> 聚合支付 | G3: =ROUND(SUMIFS(输入聚合!$C:$C,输入聚合!$A:$A,助手收入!$X2)-SUMIFS(输入聚合!$D:$D,输入聚合!$A:$A,助手收入!$X2),2) -> 22707.04 | H3: =IF(ROUND($G3,2)>0,ROUND($G3,2),"") -> 22707.04 | I3: =IF(ROUND($G3,2)<0,-ROUND($G3,2),"") | J3: =IF(ROUND($G3,2)=0,0,1) -> 1 | K3: =IF($J3=0,"",SUM($J$2:$J3)) -> 2 | L3: =IF($K3="","",$A3*100+$K3) -> 102 | M3: =参数!$B$3 -> 7月收入
