Workbook
Name 账户表: 基础资料!$B$5:$B$34
Name 账户类型表: 基础资料!$C$5:$C$34
Name 账户期初: 基础资料!$D$5:$D$34
Name 账户启用: 基础资料!$E$5:$E$34
Name 类别表: 基础资料!$H$5:$H$44
Name 类别属性: 基础资料!$I$5:$I$44
Name 客户表: 基础资料!$K$5:$K$204
Name 供应商表: 基础资料!$M$5:$M$204
Name 项目表: 基础资料!$O$5:$O$54
Name 管理年度: 基础资料!$R$5
Name 流水日期: 数据录入!$B$5:$B$5004
Name 流水账户: 数据录入!$C$5:$C$5004
Name 流水类别: 数据录入!$D$5:$D$5004
Name 流水收入: 数据录入!$F$5:$F$5004
Name 流水支出: 数据录入!$G$5:$G$5004
Name 流水月份: 数据录入!$K$5:$K$5004
Name 流水属性: 数据录入!$L$5:$L$5004
Name 流水对方: 数据录入!$M$5:$M$5004
Name 流水客户: 数据录入!$I$5:$I$5004
Name 流水供应商: 数据录入!$J$5:$J$5004
Name 流水项目: 数据录入!$N$5:$N$5004
Name 流水核对: 数据录入!$P$5:$P$5004
Name 日报期末合计: 汇报表!$BO$38
Name 月报收入合计: 月度汇报表!$B$17
Name 月报支出合计: 月度汇报表!$C$17
Name 月报转入合计: 月度汇报表!$E$17
Name 月报转出合计: 月度汇报表!$F$17
Name 分类收入合计: 收支分类报表!$O$5
Name 分类支出合计: 收支分类报表!$O$6
Name 分类转账净额: 收支分类报表!$O$7
Name 报表收入总额: 收支报表!$O$4
Name 报表支出总额: 收支报表!$O$48

Sheet 使用说明
A1: 资金日报表 · 混合录入版 ｜ 使用说明（单币种：人民币）
A3: 一、两步就能用起来
A4: 第 1 步 | B4: 【基础资料】 | C4: 把账户档案改成你们真实的账户：账户名称、类型、期初余额。收支类别、客户、供应商、项目也在这一页维护。
A5: 第 2 步 | B5: 【数据录入】 | C5: 每天在这一张录。选账户 → 余额自动结；收入和支出分两列，只填一个。其余所有表全自动。
A7: 二、账户之间互转怎么录
A8: 录两行 | B8: 转出一行、转入一行 | C8: 转出账户记一笔「支出」，转入账户记一笔「收入」，两行的「收/支类别」都选「内部转账」。
A9: 写上对方 | B9: 「对方账户」列 | C9: 转出那行写转入账户名，转入那行写转出账户名。核对列会盯着你有没有写。
A10: 报表里怎么显示 | B10: 单列，不进合计 | C10: 【月度汇报表】和【汇报表】③ 各有「内部转入 / 内部转出」两列；【收支分类报表】单列一行「内部转账净额」。收入合计、支出合计里都不含它。
A11: 净额应该是 0 | B11: 不是 0 = 漏了一头 | C11: 同一笔转账两头金额相等，净额自然是 0。
A13: 三、界面说明
A14: 表名 | B14: 哪一块 | C14: 说明
A15: 汇报表 ① | B15: 资金日报统计表 | C15: 改上面两个日期，最多 31 天，每天两列「收款 / 付款」。这一块是「账户口径」：内部划转也算进收款付款，因为账户余额确实动了。
A16: 汇报表 ② | B16: 货币资金日报表 | C16: 指定某一天，各账户的昨日余额 / 本日收入 / 本日支出 / 本日余额。也是账户口径。
A17: 汇报表 ③ | B17: 多帐户资金汇总表 | C17: 按月，这一块是「经营口径」：本月收入 / 本月支出不含内部划转，内部转入 / 内部转出另开两列。
A18: 收支报表 | B18: 12 个月 | C18: 收入按客户、支出按收支类别，上下两块分开列
A19: 任意时间段收支报表 | B19: 任意起止日期 | C19: 左右两栏收支分列
A20: 账户子表 | B20: 每个账户一张（现在 14 张） | C20: 自动从【数据录入】拆，不用填。B2 是拆分依据。
A22: 四、加东西怎么加
A23: 加一个账户 | B23: 两步 | C23: ① 【基础资料】账户档案接着写一行（记得填期初余额）； ② 右键复制任意一张账户子表，改表名，把 B2 改成新账户名。【汇报表】三块会自动多出这一行。
A24: 加一个收支类别 | B24: 一步 | C24: 【基础资料】收支类别接着写，「属性一定要填」（收入 / 支出 / 内部转账）。【收支分类报表】自动多一行。
A25: 加客户 / 供应商 / 项目 | B25: 一步 | C25: 【基础资料】对应清单接着写。【收支报表】和【任意时间段收支报表】的清单是手填的，记得把新客户也补到那两张表的空行里（不补也不会少数，会落到「未列示」那一行）。
A26: 行数 | C26: 流水预留 5000 行、账户 30 个、收支类别 40 个、客户和供应商各 200 个、子表每张 600 行。
A28: 五、颜色和符号
A29: 淡黄色格子 | B29: 要你填 | C29: 这是人工输入区。
A30: 灰色格子 | B30: 公式自动算 | C30: 别手动改，改了就把公式顶掉了。
A31: ※ 红字 | B31: 是错，必须改 | C31: 账户不在档案、收支同时填、金额填了负数、类别不在清单……
A32: △ 琥珀字 | B32: 待补的数据 | C32: 内部转账没写对方账户、余额成负数……不影响公式，补齐了数才准。

Sheet 基础资料
A1: 基础资料 · 账户、收支类别、客户、供应商都在这里维护
A2: 淡黄色格子是要你填的，灰色是公式算的。账户名称必须唯一。「收支类别」多一列「属性」：收入 / 支出 / 内部转账 —— 属性填「内部转账」的，不计入收入合计和支出合计，账户之间互转就靠它。
A3: 一、账户档案 —— 加一个账户：这里接着写一行，再复制一张账户子表改 B2 | H3: 二、收支类别（属性 = 内部转账的不计入收支合计） | K3: 三、客户 | M3: 四、供应商 | O3: 五、项目 / 部门 | Q3: 六、参数
A4: 序号 | B4: 账户名称 ★（唯一） | C4: 账户类型 | D4: 期初余额 | E4: 启用日期 | F4: 核对 | H4: 收/支类别 ★ | I4: 属性 ★ | K4: 客户 | M4: 供应商 | O4: 项目 / 部门 | Q4: 参数 | R4: 值
A5: =IF($B5="","",COUNTA($B$5:$B5)) -> 1 | B5: 现金 | C5: 现金 | D5: 5000 | E5: 46174 | F5: =IF($B5="","",IF(COUNTIF($B$5:$B$34,$B5)>1,"※账户名称重复了，后面按名字取数会串",IF($D5="","※期初余额没填（没有就填 0）",IF(AND($E5<>"",COUNTIFS(流水账户,$B5,流水日期,"<"&$E5)>0),"※有流水的日期早于启用日期，期初余额会重复计算","")))) | H5: 销售回款 | I5: 收入 | K5: 客户1 | M5: 供应商1 | O5: 主营业务 | Q5: 管理年度 | R5: 2026 | S5: 按月的三张报表（月度汇报表 / 收支分类报表 / 收支报表）看哪一年，改这里
A6: =IF($B6="","",COUNTA($B$5:$B6)) -> 2 | B6: 微信 | C6: 微信 | D6: 6000 | E6: 46174 | F6: =IF($B6="","",IF(COUNTIF($B$5:$B$34,$B6)>1,"※账户名称重复了，后面按名字取数会串",IF($D6="","※期初余额没填（没有就填 0）",IF(AND($E6<>"",COUNTIFS(流水账户,$B6,流水日期,"<"&$E6)>0),"※有流水的日期早于启用日期，期初余额会重复计算","")))) | H6: 其他业务收入 | I6: 收入 | K6: 客户2 | M6: 供应商2 | O6: 其他业务 | Q6: 本位币 | R6: 人民币 | S6: 这套表是单币种的
A7: =IF($B7="","",COUNTA($B$5:$B7)) -> 3 | B7: 工行 | C7: 银行 | D7: 7000 | E7: 46174 | F7: =IF($B7="","",IF(COUNTIF($B$5:$B$34,$B7)>1,"※账户名称重复了，后面按名字取数会串",IF($D7="","※期初余额没填（没有就填 0）",IF(AND($E7<>"",COUNTIFS(流水账户,$B7,流水日期,"<"&$E7)>0),"※有流水的日期早于启用日期，期初余额会重复计算","")))) | H7: 投资款 | I7: 收入 | K7: 客户3 | M7: 供应商3 | O7: 行政
A8: =IF($B8="","",COUNTA($B$5:$B8)) -> 4 | B8: 民生 | C8: 银行 | D8: 8000 | E8: 46174 | F8: =IF($B8="","",IF(COUNTIF($B$5:$B$34,$B8)>1,"※账户名称重复了，后面按名字取数会串",IF($D8="","※期初余额没填（没有就填 0）",IF(AND($E8<>"",COUNTIFS(流水账户,$B8,流水日期,"<"&$E8)>0),"※有流水的日期早于启用日期，期初余额会重复计算","")))) | H8: 借款 | I8: 收入 | K8: 客户4 | M8: 供应商4 | O8: 融资
A9: =IF($B9="","",COUNTA($B$5:$B9)) -> 5 | B9: 建行 | C9: 银行 | D9: 9000 | E9: 46174 | F9: =IF($B9="","",IF(COUNTIF($B$5:$B$34,$B9)>1,"※账户名称重复了，后面按名字取数会串",IF($D9="","※期初余额没填（没有就填 0）",IF(AND($E9<>"",COUNTIFS(流水账户,$B9,流水日期,"<"&$E9)>0),"※有流水的日期早于启用日期，期初余额会重复计算","")))) | H9: 利息收入 | I9: 收入 | K9: 客户5 | M9: 供应商5 | O9: 内部调拨
A10: =IF($B10="","",COUNTA($B$5:$B10)) -> 6 | B10: 农行 | C10: 银行 | D10: 10000 | E10: 46174 | F10: =IF($B10="","",IF(COUNTIF($B$5:$B$34,$B10)>1,"※账户名称重复了，后面按名字取数会串",IF($D10="","※期初余额没填（没有就填 0）",IF(AND($E10<>"",COUNTIFS(流水账户,$B10,流水日期,"<"&$E10)>0),"※有流水的日期早于启用日期，期初余额会重复计算","")))) | H10: 退款收回 | I10: 收入 | K10: 客户6 | M10: 供应商6
A11: =IF($B11="","",COUNTA($B$5:$B11)) -> 7 | B11: 中行 | C11: 银行 | D11: 11000 | E11: 46174 | F11: =IF($B11="","",IF(COUNTIF($B$5:$B$34,$B11)>1,"※账户名称重复了，后面按名字取数会串",IF($D11="","※期初余额没填（没有就填 0）",IF(AND($E11<>"",COUNTIFS(流水账户,$B11,流水日期,"<"&$E11)>0),"※有流水的日期早于启用日期，期初余额会重复计算","")))) | H11: 政府补助 | I11: 收入 | K11: 客户7 | M11: 供应商7
A12: =IF($B12="","",COUNTA($B$5:$B12)) -> 8 | B12: 支付宝 | C12: 第三方 | D12: 12000 | E12: 46174 | F12: =IF($B12="","",IF(COUNTIF($B$5:$B$34,$B12)>1,"※账户名称重复了，后面按名字取数会串",IF($D12="","※期初余额没填（没有就填 0）",IF(AND($E12<>"",COUNTIFS(流水账户,$B12,流水日期,"<"&$E12)>0),"※有流水的日期早于启用日期，期初余额会重复计算","")))) | H12: 供应商 | I12: 支出 | K12: 客户8 | M12: 供应商8
A13: =IF($B13="","",COUNTA($B$5:$B13)) -> 9 | B13: 农商行 | C13: 银行 | D13: 13000 | E13: 46174 | F13: =IF($B13="","",IF(COUNTIF($B$5:$B$34,$B13)>1,"※账户名称重复了，后面按名字取数会串",IF($D13="","※期初余额没填（没有就填 0）",IF(AND($E13<>"",COUNTIFS(流水账户,$B13,流水日期,"<"&$E13)>0),"※有流水的日期早于启用日期，期初余额会重复计算","")))) | H13: 办公费 | I13: 支出 | K13: 客户9 | M13: 供应商9
A14: =IF($B14="","",COUNTA($B$5:$B14)) -> 10 | B14: 备用 | C14: 备用 | D14: 14000 | E14: 46174 | F14: =IF($B14="","",IF(COUNTIF($B$5:$B$34,$B14)>1,"※账户名称重复了，后面按名字取数会串",IF($D14="","※期初余额没填（没有就填 0）",IF(AND($E14<>"",COUNTIFS(流水账户,$B14,流水日期,"<"&$E14)>0),"※有流水的日期早于启用日期，期初余额会重复计算","")))) | H14: 水费 | I14: 支出 | K14: 客户10 | M14: 供应商10
A15: =IF($B15="","",COUNTA($B$5:$B15)) -> 11 | B15: 备用1 | C15: 备用 | D15: 15000 | E15: 46174 | F15: =IF($B15="","",IF(COUNTIF($B$5:$B$34,$B15)>1,"※账户名称重复了，后面按名字取数会串",IF($D15="","※期初余额没填（没有就填 0）",IF(AND($E15<>"",COUNTIFS(流水账户,$B15,流水日期,"<"&$E15)>0),"※有流水的日期早于启用日期，期初余额会重复计算","")))) | H15: 电费 | I15: 支出 | K15: 客户11 | M15: 供应商11
A16: =IF($B16="","",COUNTA($B$5:$B16)) -> 12 | B16: 备用2 | C16: 备用 | D16: 16000 | E16: 46174 | F16: =IF($B16="","",IF(COUNTIF($B$5:$B$34,$B16)>1,"※账户名称重复了，后面按名字取数会串",IF($D16="","※期初余额没填（没有就填 0）",IF(AND($E16<>"",COUNTIFS(流水账户,$B16,流水日期,"<"&$E16)>0),"※有流水的日期早于启用日期，期初余额会重复计算","")))) | H16: 伙食费 | I16: 支出 | K16: 客户12 | M16: 供应商12
A17: =IF($B17="","",COUNTA($B$5:$B17)) -> 13 | B17: 备用3 | C17: 备用 | D17: 17000 | E17: 46174 | F17: =IF($B17="","",IF(COUNTIF($B$5:$B$34,$B17)>1,"※账户名称重复了，后面按名字取数会串",IF($D17="","※期初余额没填（没有就填 0）",IF(AND($E17<>"",COUNTIFS(流水账户,$B17,流水日期,"<"&$E17)>0),"※有流水的日期早于启用日期，期初余额会重复计算","")))) | H17: 工资 | I17: 支出 | K17: 客户13 | M17: 供应商13
A18: =IF($B18="","",COUNTA($B$5:$B18)) -> 14 | B18: 备用4 | C18: 备用 | D18: 18000 | E18: 46174 | F18: =IF($B18="","",IF(COUNTIF($B$5:$B$34,$B18)>1,"※账户名称重复了，后面按名字取数会串",IF($D18="","※期初余额没填（没有就填 0）",IF(AND($E18<>"",COUNTIFS(流水账户,$B18,流水日期,"<"&$E18)>0),"※有流水的日期早于启用日期，期初余额会重复计算","")))) | H18: 租赁费 | I18: 支出
A19: =IF($B19="","",COUNTA($B$5:$B19)) | F19: =IF($B19="","",IF(COUNTIF($B$5:$B$34,$B19)>1,"※账户名称重复了，后面按名字取数会串",IF($D19="","※期初余额没填（没有就填 0）",IF(AND($E19<>"",COUNTIFS(流水账户,$B19,流水日期,"<"&$E19)>0),"※有流水的日期早于启用日期，期初余额会重复计算","")))) | H19: 差旅费 | I19: 支出
A20: =IF($B20="","",COUNTA($B$5:$B20)) | F20: =IF($B20="","",IF(COUNTIF($B$5:$B$34,$B20)>1,"※账户名称重复了，后面按名字取数会串",IF($D20="","※期初余额没填（没有就填 0）",IF(AND($E20<>"",COUNTIFS(流水账户,$B20,流水日期,"<"&$E20)>0),"※有流水的日期早于启用日期，期初余额会重复计算","")))) | H20: 业务招待费 | I20: 支出
A21: =IF($B21="","",COUNTA($B$5:$B21)) | F21: =IF($B21="","",IF(COUNTIF($B$5:$B$34,$B21)>1,"※账户名称重复了，后面按名字取数会串",IF($D21="","※期初余额没填（没有就填 0）",IF(AND($E21<>"",COUNTIFS(流水账户,$B21,流水日期,"<"&$E21)>0),"※有流水的日期早于启用日期，期初余额会重复计算","")))) | H21: 车辆费用 | I21: 支出
A22: =IF($B22="","",COUNTA($B$5:$B22)) | F22: =IF($B22="","",IF(COUNTIF($B$5:$B$34,$B22)>1,"※账户名称重复了，后面按名字取数会串",IF($D22="","※期初余额没填（没有就填 0）",IF(AND($E22<>"",COUNTIFS(流水账户,$B22,流水日期,"<"&$E22)>0),"※有流水的日期早于启用日期，期初余额会重复计算","")))) | H22: 银行手续费 | I22: 支出
A23: =IF($B23="","",COUNTA($B$5:$B23)) | F23: =IF($B23="","",IF(COUNTIF($B$5:$B$34,$B23)>1,"※账户名称重复了，后面按名字取数会串",IF($D23="","※期初余额没填（没有就填 0）",IF(AND($E23<>"",COUNTIFS(流水账户,$B23,流水日期,"<"&$E23)>0),"※有流水的日期早于启用日期，期初余额会重复计算","")))) | H23: 税费 | I23: 支出
A24: =IF($B24="","",COUNTA($B$5:$B24)) | F24: =IF($B24="","",IF(COUNTIF($B$5:$B$34,$B24)>1,"※账户名称重复了，后面按名字取数会串",IF($D24="","※期初余额没填（没有就填 0）",IF(AND($E24<>"",COUNTIFS(流水账户,$B24,流水日期,"<"&$E24)>0),"※有流水的日期早于启用日期，期初余额会重复计算","")))) | H24: 还款 | I24: 支出
A25: =IF($B25="","",COUNTA($B$5:$B25)) | F25: =IF($B25="","",IF(COUNTIF($B$5:$B$34,$B25)>1,"※账户名称重复了，后面按名字取数会串",IF($D25="","※期初余额没填（没有就填 0）",IF(AND($E25<>"",COUNTIFS(流水账户,$B25,流水日期,"<"&$E25)>0),"※有流水的日期早于启用日期，期初余额会重复计算","")))) | H25: 资产购买 | I25: 支出
A26: =IF($B26="","",COUNTA($B$5:$B26)) | F26: =IF($B26="","",IF(COUNTIF($B$5:$B$34,$B26)>1,"※账户名称重复了，后面按名字取数会串",IF($D26="","※期初余额没填（没有就填 0）",IF(AND($E26<>"",COUNTIFS(流水账户,$B26,流水日期,"<"&$E26)>0),"※有流水的日期早于启用日期，期初余额会重复计算","")))) | H26: 利息支出 | I26: 支出
A27: =IF($B27="","",COUNTA($B$5:$B27)) | F27: =IF($B27="","",IF(COUNTIF($B$5:$B$34,$B27)>1,"※账户名称重复了，后面按名字取数会串",IF($D27="","※期初余额没填（没有就填 0）",IF(AND($E27<>"",COUNTIFS(流水账户,$B27,流水日期,"<"&$E27)>0),"※有流水的日期早于启用日期，期初余额会重复计算","")))) | H27: 内部转账 | I27: 内部转账
A28: =IF($B28="","",COUNTA($B$5:$B28)) | F28: =IF($B28="","",IF(COUNTIF($B$5:$B$34,$B28)>1,"※账户名称重复了，后面按名字取数会串",IF($D28="","※期初余额没填（没有就填 0）",IF(AND($E28<>"",COUNTIFS(流水账户,$B28,流水日期,"<"&$E28)>0),"※有流水的日期早于启用日期，期初余额会重复计算","")))) | H28: 备用金调拨 | I28: 内部转账
A29: =IF($B29="","",COUNTA($B$5:$B29)) | F29: =IF($B29="","",IF(COUNTIF($B$5:$B$34,$B29)>1,"※账户名称重复了，后面按名字取数会串",IF($D29="","※期初余额没填（没有就填 0）",IF(AND($E29<>"",COUNTIFS(流水账户,$B29,流水日期,"<"&$E29)>0),"※有流水的日期早于启用日期，期初余额会重复计算",""))))
A30: =IF($B30="","",COUNTA($B$5:$B30)) | F30: =IF($B30="","",IF(COUNTIF($B$5:$B$34,$B30)>1,"※账户名称重复了，后面按名字取数会串",IF($D30="","※期初余额没填（没有就填 0）",IF(AND($E30<>"",COUNTIFS(流水账户,$B30,流水日期,"<"&$E30)>0),"※有流水的日期早于启用日期，期初余额会重复计算",""))))
A31: =IF($B31="","",COUNTA($B$5:$B31)) | F31: =IF($B31="","",IF(COUNTIF($B$5:$B$34,$B31)>1,"※账户名称重复了，后面按名字取数会串",IF($D31="","※期初余额没填（没有就填 0）",IF(AND($E31<>"",COUNTIFS(流水账户,$B31,流水日期,"<"&$E31)>0),"※有流水的日期早于启用日期，期初余额会重复计算",""))))
A32: =IF($B32="","",COUNTA($B$5:$B32)) | F32: =IF($B32="","",IF(COUNTIF($B$5:$B$34,$B32)>1,"※账户名称重复了，后面按名字取数会串",IF($D32="","※期初余额没填（没有就填 0）",IF(AND($E32<>"",COUNTIFS(流水账户,$B32,流水日期,"<"&$E32)>0),"※有流水的日期早于启用日期，期初余额会重复计算",""))))
A33: =IF($B33="","",COUNTA($B$5:$B33)) | F33: =IF($B33="","",IF(COUNTIF($B$5:$B$34,$B33)>1,"※账户名称重复了，后面按名字取数会串",IF($D33="","※期初余额没填（没有就填 0）",IF(AND($E33<>"",COUNTIFS(流水账户,$B33,流水日期,"<"&$E33)>0),"※有流水的日期早于启用日期，期初余额会重复计算",""))))
A34: =IF($B34="","",COUNTA($B$5:$B34)) | F34: =IF($B34="","",IF(COUNTIF($B$5:$B$34,$B34)>1,"※账户名称重复了，后面按名字取数会串",IF($D34="","※期初余额没填（没有就填 0）",IF(AND($E34<>"",COUNTIFS(流水账户,$B34,流水日期,"<"&$E34)>0),"※有流水的日期早于启用日期，期初余额会重复计算",""))))

Sheet 数据录入
A1: 数据录入 · 全套表只有这一张要填
A2: 选账户 → 余额自动结；收入和支出分两列，只填一个。账户之间互转：转出账户记一笔支出、转入账户记一笔收入，类别都选「内部转账」，在「对方账户」写上另一头 —— 这样它就不会被算进收入和支出合计。期初余额挪到【基础资料】了，这里只放真实流水。最后一列「核对」会自己挑毛病。
A3: 收入总额 | B3: =ROUND(SUMIFS(流水收入,流水属性,"<>内部转账"),2) -> 16800 | C3: 支出总额 | D3: =ROUND(SUMIFS(流水支出,流水属性,"<>内部转账"),2) -> 22190 | E3: 经营净额 | F3: =ROUND($B$3-$D$3,2) -> -5390 | G3: 内部转账净额 | H3: =ROUND(SUMIFS(流水收入,流水属性,"内部转账")-SUMIFS(流水支出,流水属性,"内部转账"),2) -> 0 | I3: 资金总额 | J3: =ROUND(SUM(账户期初)+SUM(流水收入)-SUM(流水支出),2) -> 155610 | K3: 已用行数 | L3: =COUNTA($C$5:$C$5004)&" / 5000" -> 25 / 5000 | M3: 收入总额、支出总额都不含内部转账；内部转账净额应该是 0，不为 0 就是有一头没录
A4: 序号 | B4: 日期 ★ | C4: 公司账户 ★ | D4: 收/支类别 ★ | E4: 摘要内容 | F4: 收入 | G4: 支出 | H4: 账户余额 | I4: 客户 | J4: 供应商 | K4: 月份 | L4: 类别属性 | M4: 对方账户 (内部转账填) | N4: 项目/部门 | O4: 备注 | P4: 核对
A5: =IF($C5="","",COUNTA($C$5:$C5)) -> 1 | B5: 46175 | C5: 现金 | D5: 销售回款 | F5: 2000 | H5: =IFERROR(ROUND(VLOOKUP($C5,基础资料!$B$5:$E$34,3,0)+SUMIF($C$5:$C5,$C5,$F$5:$F5)-SUMIF($C$5:$C5,$C5,$G$5:$G5),2),"") -> 7000 | I5: 客户1 | K5: =IF(OR($B5="",NOT(ISNUMBER($B5))),"",--TEXT($B5,"yyyymm")) -> 202606 | L5: =IF($D5="","",IFERROR(INDEX(类别属性,MATCH($D5,类别表,0)),"")) -> 收入 | N5: 主营业务 | P5: =IF($C5="","",IF(ISNA(MATCH($C5,账户表,0)),"※这个账户不在【基础资料】的账户档案里",IF($B5="","※没填日期，这一笔不会进任何月份的报表",IF(NOT(ISNUMBER($B5)),"※日期是文本不是日期（像 2026.6.28 这种），按日期取数的报表全会漏掉这一笔",IF(AND($F5<>"",$G5<>""),"※收入和支出不能同时填",IF(AND(N($F5)=0,N($G5)=0),"※收入和支出都没填",IF(OR(N($F5)<0,N($G5)<0),"※金额不能填负数，方向反了就换一列填",IF($D5="","※没填收支类别，分类报表会漏掉这一笔",IF(ISNA(MATCH($D5,类别表,0)),"※收支类别不在【基础资料】的清单里",IF(AND($L5="内部转账",$M5=""),"△内部转账要在「对方账户」写上另一头",IF(AND($L5="内部转账",$M5=$C5),"※对方账户跟本账户是同一个",IF(AND($L5<>"内部转账",$M5<>""),"△填了对方账户，但类别不是内部转账",IF(YEAR($B5)<>管理年度,"△不是管理年度的单据，按月的三张报表里看不到",IF($H5<0,"△这一笔之后该账户余额成负数了，核一下",""))))))))))))))
A6: =IF($C6="","",COUNTA($C$5:$C6)) -> 2 | B6: 46176 | C6: 微信 | D6: 办公费 | G6: 200 | H6: =IFERROR(ROUND(VLOOKUP($C6,基础资料!$B$5:$E$34,3,0)+SUMIF($C$5:$C6,$C6,$F$5:$F6)-SUMIF($C$5:$C6,$C6,$G$5:$G6),2),"") -> 5800 | K6: =IF(OR($B6="",NOT(ISNUMBER($B6))),"",--TEXT($B6,"yyyymm")) -> 202606 | L6: =IF($D6="","",IFERROR(INDEX(类别属性,MATCH($D6,类别表,0)),"")) -> 支出 | N6: 行政 | P6: =IF($C6="","",IF(ISNA(MATCH($C6,账户表,0)),"※这个账户不在【基础资料】的账户档案里",IF($B6="","※没填日期，这一笔不会进任何月份的报表",IF(NOT(ISNUMBER($B6)),"※日期是文本不是日期（像 2026.6.28 这种），按日期取数的报表全会漏掉这一笔",IF(AND($F6<>"",$G6<>""),"※收入和支出不能同时填",IF(AND(N($F6)=0,N($G6)=0),"※收入和支出都没填",IF(OR(N($F6)<0,N($G6)<0),"※金额不能填负数，方向反了就换一列填",IF($D6="","※没填收支类别，分类报表会漏掉这一笔",IF(ISNA(MATCH($D6,类别表,0)),"※收支类别不在【基础资料】的清单里",IF(AND($L6="内部转账",$M6=""),"△内部转账要在「对方账户」写上另一头",IF(AND($L6="内部转账",$M6=$C6),"※对方账户跟本账户是同一个",IF(AND($L6<>"内部转账",$M6<>""),"△填了对方账户，但类别不是内部转账",IF(YEAR($B6)<>管理年度,"△不是管理年度的单据，按月的三张报表里看不到",IF($H6<0,"△这一笔之后该账户余额成负数了，核一下",""))))))))))))))
A7: =IF($C7="","",COUNTA($C$5:$C7)) -> 3 | B7: 46178 | C7: 工行 | D7: 电费 | G7: 300 | H7: =IFERROR(ROUND(VLOOKUP($C7,基础资料!$B$5:$E$34,3,0)+SUMIF($C$5:$C7,$C7,$F$5:$F7)-SUMIF($C$5:$C7,$C7,$G$5:$G7),2),"") -> 6700 | K7: =IF(OR($B7="",NOT(ISNUMBER($B7))),"",--TEXT($B7,"yyyymm")) -> 202606 | L7: =IF($D7="","",IFERROR(INDEX(类别属性,MATCH($D7,类别表,0)),"")) -> 支出 | N7: 行政 | P7: =IF($C7="","",IF(ISNA(MATCH($C7,账户表,0)),"※这个账户不在【基础资料】的账户档案里",IF($B7="","※没填日期，这一笔不会进任何月份的报表",IF(NOT(ISNUMBER($B7)),"※日期是文本不是日期（像 2026.6.28 这种），按日期取数的报表全会漏掉这一笔",IF(AND($F7<>"",$G7<>""),"※收入和支出不能同时填",IF(AND(N($F7)=0,N($G7)=0),"※收入和支出都没填",IF(OR(N($F7)<0,N($G7)<0),"※金额不能填负数，方向反了就换一列填",IF($D7="","※没填收支类别，分类报表会漏掉这一笔",IF(ISNA(MATCH($D7,类别表,0)),"※收支类别不在【基础资料】的清单里",IF(AND($L7="内部转账",$M7=""),"△内部转账要在「对方账户」写上另一头",IF(AND($L7="内部转账",$M7=$C7),"※对方账户跟本账户是同一个",IF(AND($L7<>"内部转账",$M7<>""),"△填了对方账户，但类别不是内部转账",IF(YEAR($B7)<>管理年度,"△不是管理年度的单据，按月的三张报表里看不到",IF($H7<0,"△这一笔之后该账户余额成负数了，核一下",""))))))))))))))
A8: =IF($C8="","",COUNTA($C$5:$C8)) -> 4 | B8: 46179 | C8: 民生 | D8: 差旅费 | G8: 500 | H8: =IFERROR(ROUND(VLOOKUP($C8,基础资料!$B$5:$E$34,3,0)+SUMIF($C$5:$C8,$C8,$F$5:$F8)-SUMIF($C$5:$C8,$C8,$G$5:$G8),2),"") -> 7500 | K8: =IF(OR($B8="",NOT(ISNUMBER($B8))),"",--TEXT($B8,"yyyymm")) -> 202606 | L8: =IF($D8="","",IFERROR(INDEX(类别属性,MATCH($D8,类别表,0)),"")) -> 支出 | N8: 行政 | P8: =IF($C8="","",IF(ISNA(MATCH($C8,账户表,0)),"※这个账户不在【基础资料】的账户档案里",IF($B8="","※没填日期，这一笔不会进任何月份的报表",IF(NOT(ISNUMBER($B8)),"※日期是文本不是日期（像 2026.6.28 这种），按日期取数的报表全会漏掉这一笔",IF(AND($F8<>"",$G8<>""),"※收入和支出不能同时填",IF(AND(N($F8)=0,N($G8)=0),"※收入和支出都没填",IF(OR(N($F8)<0,N($G8)<0),"※金额不能填负数，方向反了就换一列填",IF($D8="","※没填收支类别，分类报表会漏掉这一笔",IF(ISNA(MATCH($D8,类别表,0)),"※收支类别不在【基础资料】的清单里",IF(AND($L8="内部转账",$M8=""),"△内部转账要在「对方账户」写上另一头",IF(AND($L8="内部转账",$M8=$C8),"※对方账户跟本账户是同一个",IF(AND($L8<>"内部转账",$M8<>""),"△填了对方账户，但类别不是内部转账",IF(YEAR($B8)<>管理年度,"△不是管理年度的单据，按月的三张报表里看不到",IF($H8<0,"△这一笔之后该账户余额成负数了，核一下",""))))))))))))))
A9: =IF($C9="","",COUNTA($C$5:$C9)) -> 5 | B9: 46183 | C9: 建行 | D9: 销售回款 | F9: 2600 | H9: =IFERROR(ROUND(VLOOKUP($C9,基础资料!$B$5:$E$34,3,0)+SUMIF($C$5:$C9,$C9,$F$5:$F9)-SUMIF($C$5:$C9,$C9,$G$5:$G9),2),"") -> 11600 | I9: 客户2 | K9: =IF(OR($B9="",NOT(ISNUMBER($B9))),"",--TEXT($B9,"yyyymm")) -> 202606 | L9: =IF($D9="","",IFERROR(INDEX(类别属性,MATCH($D9,类别表,0)),"")) -> 收入 | N9: 主营业务 | P9: =IF($C9="","",IF(ISNA(MATCH($C9,账户表,0)),"※这个账户不在【基础资料】的账户档案里",IF($B9="","※没填日期，这一笔不会进任何月份的报表",IF(NOT(ISNUMBER($B9)),"※日期是文本不是日期（像 2026.6.28 这种），按日期取数的报表全会漏掉这一笔",IF(AND($F9<>"",$G9<>""),"※收入和支出不能同时填",IF(AND(N($F9)=0,N($G9)=0),"※收入和支出都没填",IF(OR(N($F9)<0,N($G9)<0),"※金额不能填负数，方向反了就换一列填",IF($D9="","※没填收支类别，分类报表会漏掉这一笔",IF(ISNA(MATCH($D9,类别表,0)),"※收支类别不在【基础资料】的清单里",IF(AND($L9="内部转账",$M9=""),"△内部转账要在「对方账户」写上另一头",IF(AND($L9="内部转账",$M9=$C9),"※对方账户跟本账户是同一个",IF(AND($L9<>"内部转账",$M9<>""),"△填了对方账户，但类别不是内部转账",IF(YEAR($B9)<>管理年度,"△不是管理年度的单据，按月的三张报表里看不到",IF($H9<0,"△这一笔之后该账户余额成负数了，核一下",""))))))))))))))
A10: =IF($C10="","",COUNTA($C$5:$C10)) -> 6 | B10: 46185 | C10: 农行 | D10: 供应商 | G10: 5000 | H10: =IFERROR(ROUND(VLOOKUP($C10,基础资料!$B$5:$E$34,3,0)+SUMIF($C$5:$C10,$C10,$F$5:$F10)-SUMIF($C$5:$C10,$C10,$G$5:$G10),2),"") -> 5000 | J10: 供应商1 | K10: =IF(OR($B10="",NOT(ISNUMBER($B10))),"",--TEXT($B10,"yyyymm")) -> 202606 | L10: =IF($D10="","",IFERROR(INDEX(类别属性,MATCH($D10,类别表,0)),"")) -> 支出 | N10: 主营业务 | P10: =IF($C10="","",IF(ISNA(MATCH($C10,账户表,0)),"※这个账户不在【基础资料】的账户档案里",IF($B10="","※没填日期，这一笔不会进任何月份的报表",IF(NOT(ISNUMBER($B10)),"※日期是文本不是日期（像 2026.6.28 这种），按日期取数的报表全会漏掉这一笔",IF(AND($F10<>"",$G10<>""),"※收入和支出不能同时填",IF(AND(N($F10)=0,N($G10)=0),"※收入和支出都没填",IF(OR(N($F10)<0,N($G10)<0),"※金额不能填负数，方向反了就换一列填",IF($D10="","※没填收支类别，分类报表会漏掉这一笔",IF(ISNA(MATCH($D10,类别表,0)),"※收支类别不在【基础资料】的清单里",IF(AND($L10="内部转账",$M10=""),"△内部转账要在「对方账户」写上另一头",IF(AND($L10="内部转账",$M10=$C10),"※对方账户跟本账户是同一个",IF(AND($L10<>"内部转账",$M10<>""),"△填了对方账户，但类别不是内部转账",IF(YEAR($B10)<>管理年度,"△不是管理年度的单据，按月的三张报表里看不到",IF($H10<0,"△这一笔之后该账户余额成负数了，核一下",""))))))))))))))
A11: =IF($C11="","",COUNTA($C$5:$C11)) -> 7 | B11: 46193 | C11: 中行 | D11: 伙食费 | G11: 200 | H11: =IFERROR(ROUND(VLOOKUP($C11,基础资料!$B$5:$E$34,3,0)+SUMIF($C$5:$C11,$C11,$F$5:$F11)-SUMIF($C$5:$C11,$C11,$G$5:$G11),2),"") -> 10800 | K11: =IF(OR($B11="",NOT(ISNUMBER($B11))),"",--TEXT($B11,"yyyymm")) -> 202606 | L11: =IF($D11="","",IFERROR(INDEX(类别属性,MATCH($D11,类别表,0)),"")) -> 支出 | N11: 行政 | P11: =IF($C11="","",IF(ISNA(MATCH($C11,账户表,0)),"※这个账户不在【基础资料】的账户档案里",IF($B11="","※没填日期，这一笔不会进任何月份的报表",IF(NOT(ISNUMBER($B11)),"※日期是文本不是日期（像 2026.6.28 这种），按日期取数的报表全会漏掉这一笔",IF(AND($F11<>"",$G11<>""),"※收入和支出不能同时填",IF(AND(N($F11)=0,N($G11)=0),"※收入和支出都没填",IF(OR(N($F11)<0,N($G11)<0),"※金额不能填负数，方向反了就换一列填",IF($D11="","※没填收支类别，分类报表会漏掉这一笔",IF(ISNA(MATCH($D11,类别表,0)),"※收支类别不在【基础资料】的清单里",IF(AND($L11="内部转账",$M11=""),"△内部转账要在「对方账户」写上另一头",IF(AND($L11="内部转账",$M11=$C11),"※对方账户跟本账户是同一个",IF(AND($L11<>"内部转账",$M11<>""),"△填了对方账户，但类别不是内部转账",IF(YEAR($B11)<>管理年度,"△不是管理年度的单据，按月的三张报表里看不到",IF($H11<0,"△这一笔之后该账户余额成负数了，核一下",""))))))))))))))
A12: =IF($C12="","",COUNTA($C$5:$C12)) -> 8 | B12: 46196 | C12: 支付宝 | D12: 办公费 | G12: 10 | H12: =IFERROR(ROUND(VLOOKUP($C12,基础资料!$B$5:$E$34,3,0)+SUMIF($C$5:$C12,$C12,$F$5:$F12)-SUMIF($C$5:$C12,$C12,$G$5:$G12),2),"") -> 11990 | K12: =IF(OR($B12="",NOT(ISNUMBER($B12))),"",--TEXT($B12,"yyyymm")) -> 202606 | L12: =IF($D12="","",IFERROR(INDEX(类别属性,MATCH($D12,类别表,0)),"")) -> 支出 | N12: 行政 | P12: =IF($C12="","",IF(ISNA(MATCH($C12,账户表,0)),"※这个账户不在【基础资料】的账户档案里",IF($B12="","※没填日期，这一笔不会进任何月份的报表",IF(NOT(ISNUMBER($B12)),"※日期是文本不是日期（像 2026.6.28 这种），按日期取数的报表全会漏掉这一笔",IF(AND($F12<>"",$G12<>""),"※收入和支出不能同时填",IF(AND(N($F12)=0,N($G12)=0),"※收入和支出都没填",IF(OR(N($F12)<0,N($G12)<0),"※金额不能填负数，方向反了就换一列填",IF($D12="","※没填收支类别，分类报表会漏掉这一笔",IF(ISNA(MATCH($D12,类别表,0)),"※收支类别不在【基础资料】的清单里",IF(AND($L12="内部转账",$M12=""),"△内部转账要在「对方账户」写上另一头",IF(AND($L12="内部转账",$M12=$C12),"※对方账户跟本账户是同一个",IF(AND($L12<>"内部转账",$M12<>""),"△填了对方账户，但类别不是内部转账",IF(YEAR($B12)<>管理年度,"△不是管理年度的单据，按月的三张报表里看不到",IF($H12<0,"△这一笔之后该账户余额成负数了，核一下",""))))))))))))))
A13: =IF($C13="","",COUNTA($C$5:$C13)) -> 9 | B13: 46197 | C13: 农商行 | D13: 车辆费用 | G13: 50 | H13: =IFERROR(ROUND(VLOOKUP($C13,基础资料!$B$5:$E$34,3,0)+SUMIF($C$5:$C13,$C13,$F$5:$F13)-SUMIF($C$5:$C13,$C13,$G$5:$G13),2),"") -> 12950 | K13: =IF(OR($B13="",NOT(ISNUMBER($B13))),"",--TEXT($B13,"yyyymm")) -> 202606 | L13: =IF($D13="","",IFERROR(INDEX(类别属性,MATCH($D13,类别表,0)),"")) -> 支出 | N13: 行政 | P13: =IF($C13="","",IF(ISNA(MATCH($C13,账户表,0)),"※这个账户不在【基础资料】的账户档案里",IF($B13="","※没填日期，这一笔不会进任何月份的报表",IF(NOT(ISNUMBER($B13)),"※日期是文本不是日期（像 2026.6.28 这种），按日期取数的报表全会漏掉这一笔",IF(AND($F13<>"",$G13<>""),"※收入和支出不能同时填",IF(AND(N($F13)=0,N($G13)=0),"※收入和支出都没填",IF(OR(N($F13)<0,N($G13)<0),"※金额不能填负数，方向反了就换一列填",IF($D13="","※没填收支类别，分类报表会漏掉这一笔",IF(ISNA(MATCH($D13,类别表,0)),"※收支类别不在【基础资料】的清单里",IF(AND($L13="内部转账",$M13=""),"△内部转账要在「对方账户」写上另一头",IF(AND($L13="内部转账",$M13=$C13),"※对方账户跟本账户是同一个",IF(AND($L13<>"内部转账",$M13<>""),"△填了对方账户，但类别不是内部转账",IF(YEAR($B13)<>管理年度,"△不是管理年度的单据，按月的三张报表里看不到",IF($H13<0,"△这一笔之后该账户余额成负数了，核一下",""))))))))))))))
A14: =IF($C14="","",COUNTA($C$5:$C14)) -> 10 | B14: 46198 | C14: 备用 | D14: 销售回款 | F14: 2100 | H14: =IFERROR(ROUND(VLOOKUP($C14,基础资料!$B$5:$E$34,3,0)+SUMIF($C$5:$C14,$C14,$F$5:$F14)-SUMIF($C$5:$C14,$C14,$G$5:$G14),2),"") -> 16100 | I14: 客户3 | K14: =IF(OR($B14="",NOT(ISNUMBER($B14))),"",--TEXT($B14,"yyyymm")) -> 202606 | L14: =IF($D14="","",IFERROR(INDEX(类别属性,MATCH($D14,类别表,0)),"")) -> 收入 | N14: 主营业务 | P14: =IF($C14="","",IF(ISNA(MATCH($C14,账户表,0)),"※这个账户不在【基础资料】的账户档案里",IF($B14="","※没填日期，这一笔不会进任何月份的报表",IF(NOT(ISNUMBER($B14)),"※日期是文本不是日期（像 2026.6.28 这种），按日期取数的报表全会漏掉这一笔",IF(AND($F14<>"",$G14<>""),"※收入和支出不能同时填",IF(AND(N($F14)=0,N($G14)=0),"※收入和支出都没填",IF(OR(N($F14)<0,N($G14)<0),"※金额不能填负数，方向反了就换一列填",IF($D14="","※没填收支类别，分类报表会漏掉这一笔",IF(ISNA(MATCH($D14,类别表,0)),"※收支类别不在【基础资料】的清单里",IF(AND($L14="内部转账",$M14=""),"△内部转账要在「对方账户」写上另一头",IF(AND($L14="内部转账",$M14=$C14),"※对方账户跟本账户是同一个",IF(AND($L14<>"内部转账",$M14<>""),"△填了对方账户，但类别不是内部转账",IF(YEAR($B14)<>管理年度,"△不是管理年度的单据，按月的三张报表里看不到",IF($H14<0,"△这一笔之后该账户余额成负数了，核一下",""))))))))))))))
A15: =IF($C15="","",COUNTA($C$5:$C15)) -> 11 | B15: 46198 | C15: 备用1 | D15: 租赁费 | G15: 2000 | H15: =IFERROR(ROUND(VLOOKUP($C15,基础资料!$B$5:$E$34,3,0)+SUMIF($C$5:$C15,$C15,$F$5:$F15)-SUMIF($C$5:$C15,$C15,$G$5:$G15),2),"") -> 13000 | K15: =IF(OR($B15="",NOT(ISNUMBER($B15))),"",--TEXT($B15,"yyyymm")) -> 202606 | L15: =IF($D15="","",IFERROR(INDEX(类别属性,MATCH($D15,类别表,0)),"")) -> 支出 | N15: 行政 | P15: =IF($C15="","",IF(ISNA(MATCH($C15,账户表,0)),"※这个账户不在【基础资料】的账户档案里",IF($B15="","※没填日期，这一笔不会进任何月份的报表",IF(NOT(ISNUMBER($B15)),"※日期是文本不是日期（像 2026.6.28 这种），按日期取数的报表全会漏掉这一笔",IF(AND($F15<>"",$G15<>""),"※收入和支出不能同时填",IF(AND(N($F15)=0,N($G15)=0),"※收入和支出都没填",IF(OR(N($F15)<0,N($G15)<0),"※金额不能填负数，方向反了就换一列填",IF($D15="","※没填收支类别，分类报表会漏掉这一笔",IF(ISNA(MATCH($D15,类别表,0)),"※收支类别不在【基础资料】的清单里",IF(AND($L15="内部转账",$M15=""),"△内部转账要在「对方账户」写上另一头",IF(AND($L15="内部转账",$M15=$C15),"※对方账户跟本账户是同一个",IF(AND($L15<>"内部转账",$M15<>""),"△填了对方账户，但类别不是内部转账",IF(YEAR($B15)<>管理年度,"△不是管理年度的单据，按月的三张报表里看不到",IF($H15<0,"△这一笔之后该账户余额成负数了，核一下",""))))))))))))))
A16: =IF($C16="","",COUNTA($C$5:$C16)) -> 12 | B16: 46198 | C16: 现金 | D16: 业务招待费 | G16: 200 | H16: =IFERROR(ROUND(VLOOKUP($C16,基础资料!$B$5:$E$34,3,0)+SUMIF($C$5:$C16,$C16,$F$5:$F16)-SUMIF($C$5:$C16,$C16,$G$5:$G16),2),"") -> 6800 | K16: =IF(OR($B16="",NOT(ISNUMBER($B16))),"",--TEXT($B16,"yyyymm")) -> 202606 | L16: =IF($D16="","",IFERROR(INDEX(类别属性,MATCH($D16,类别表,0)),"")) -> 支出 | N16: 行政 | P16: =IF($C16="","",IF(ISNA(MATCH($C16,账户表,0)),"※这个账户不在【基础资料】的账户档案里",IF($B16="","※没填日期，这一笔不会进任何月份的报表",IF(NOT(ISNUMBER($B16)),"※日期是文本不是日期（像 2026.6.28 这种），按日期取数的报表全会漏掉这一笔",IF(AND($F16<>"",$G16<>""),"※收入和支出不能同时填",IF(AND(N($F16)=0,N($G16)=0),"※收入和支出都没填",IF(OR(N($F16)<0,N($G16)<0),"※金额不能填负数，方向反了就换一列填",IF($D16="","※没填收支类别，分类报表会漏掉这一笔",IF(ISNA(MATCH($D16,类别表,0)),"※收支类别不在【基础资料】的清单里",IF(AND($L16="内部转账",$M16=""),"△内部转账要在「对方账户」写上另一头",IF(AND($L16="内部转账",$M16=$C16),"※对方账户跟本账户是同一个",IF(AND($L16<>"内部转账",$M16<>""),"△填了对方账户，但类别不是内部转账",IF(YEAR($B16)<>管理年度,"△不是管理年度的单据，按月的三张报表里看不到",IF($H16<0,"△这一笔之后该账户余额成负数了，核一下",""))))))))))))))
A17: =IF($C17="","",COUNTA($C$5:$C17)) -> 13 | B17: 46199 | C17: 备用2 | D17: 销售回款 | F17: 3000 | H17: =IFERROR(ROUND(VLOOKUP($C17,基础资料!$B$5:$E$34,3,0)+SUMIF($C$5:$C17,$C17,$F$5:$F17)-SUMIF($C$5:$C17,$C17,$G$5:$G17),2),"") -> 19000 | I17: 客户4 | K17: =IF(OR($B17="",NOT(ISNUMBER($B17))),"",--TEXT($B17,"yyyymm")) -> 202606 | L17: =IF($D17="","",IFERROR(INDEX(类别属性,MATCH($D17,类别表,0)),"")) -> 收入 | N17: 主营业务 | P17: =IF($C17="","",IF(ISNA(MATCH($C17,账户表,0)),"※这个账户不在【基础资料】的账户档案里",IF($B17="","※没填日期，这一笔不会进任何月份的报表",IF(NOT(ISNUMBER($B17)),"※日期是文本不是日期（像 2026.6.28 这种），按日期取数的报表全会漏掉这一笔",IF(AND($F17<>"",$G17<>""),"※收入和支出不能同时填",IF(AND(N($F17)=0,N($G17)=0),"※收入和支出都没填",IF(OR(N($F17)<0,N($G17)<0),"※金额不能填负数，方向反了就换一列填",IF($D17="","※没填收支类别，分类报表会漏掉这一笔",IF(ISNA(MATCH($D17,类别表,0)),"※收支类别不在【基础资料】的清单里",IF(AND($L17="内部转账",$M17=""),"△内部转账要在「对方账户」写上另一头",IF(AND($L17="内部转账",$M17=$C17),"※对方账户跟本账户是同一个",IF(AND($L17<>"内部转账",$M17<>""),"△填了对方账户，但类别不是内部转账",IF(YEAR($B17)<>管理年度,"△不是管理年度的单据，按月的三张报表里看不到",IF($H17<0,"△这一笔之后该账户余额成负数了，核一下",""))))))))))))))
A18: =IF($C18="","",COUNTA($C$5:$C18)) -> 14 | B18: 46199 | C18: 备用3 | D18: 工资 | G18: 8000 | H18: =IFERROR(ROUND(VLOOKUP($C18,基础资料!$B$5:$E$34,3,0)+SUMIF($C$5:$C18,$C18,$F$5:$F18)-SUMIF($C$5:$C18,$C18,$G$5:$G18),2),"") -> 9000 | K18: =IF(OR($B18="",NOT(ISNUMBER($B18))),"",--TEXT($B18,"yyyymm")) -> 202606 | L18: =IF($D18="","",IFERROR(INDEX(类别属性,MATCH($D18,类别表,0)),"")) -> 支出 | N18: 行政 | P18: =IF($C18="","",IF(ISNA(MATCH($C18,账户表,0)),"※这个账户不在【基础资料】的账户档案里",IF($B18="","※没填日期，这一笔不会进任何月份的报表",IF(NOT(ISNUMBER($B18)),"※日期是文本不是日期（像 2026.6.28 这种），按日期取数的报表全会漏掉这一笔",IF(AND($F18<>"",$G18<>""),"※收入和支出不能同时填",IF(AND(N($F18)=0,N($G18)=0),"※收入和支出都没填",IF(OR(N($F18)<0,N($G18)<0),"※金额不能填负数，方向反了就换一列填",IF($D18="","※没填收支类别，分类报表会漏掉这一笔",IF(ISNA(MATCH($D18,类别表,0)),"※收支类别不在【基础资料】的清单里",IF(AND($L18="内部转账",$M18=""),"△内部转账要在「对方账户」写上另一头",IF(AND($L18="内部转账",$M18=$C18),"※对方账户跟本账户是同一个",IF(AND($L18<>"内部转账",$M18<>""),"△填了对方账户，但类别不是内部转账",IF(YEAR($B18)<>管理年度,"△不是管理年度的单据，按月的三张报表里看不到",IF($H18<0,"△这一笔之后该账户余额成负数了，核一下",""))))))))))))))
A19: =IF($C19="","",COUNTA($C$5:$C19)) -> 15 | B19: 46200 | C19: 备用4 | D19: 销售回款 | F19: 1500 | H19: =IFERROR(ROUND(VLOOKUP($C19,基础资料!$B$5:$E$34,3,0)+SUMIF($C$5:$C19,$C19,$F$5:$F19)-SUMIF($C$5:$C19,$C19,$G$5:$G19),2),"") -> 19500 | I19: 客户5 | K19: =IF(OR($B19="",NOT(ISNUMBER($B19))),"",--TEXT($B19,"yyyymm")) -> 202606 | L19: =IF($D19="","",IFERROR(INDEX(类别属性,MATCH($D19,类别表,0)),"")) -> 收入 | N19: 主营业务 | P19: =IF($C19="","",IF(ISNA(MATCH($C19,账户表,0)),"※这个账户不在【基础资料】的账户档案里",IF($B19="","※没填日期，这一笔不会进任何月份的报表",IF(NOT(ISNUMBER($B19)),"※日期是文本不是日期（像 2026.6.28 这种），按日期取数的报表全会漏掉这一笔",IF(AND($F19<>"",$G19<>""),"※收入和支出不能同时填",IF(AND(N($F19)=0,N($G19)=0),"※收入和支出都没填",IF(OR(N($F19)<0,N($G19)<0),"※金额不能填负数，方向反了就换一列填",IF($D19="","※没填收支类别，分类报表会漏掉这一笔",IF(ISNA(MATCH($D19,类别表,0)),"※收支类别不在【基础资料】的清单里",IF(AND($L19="内部转账",$M19=""),"△内部转账要在「对方账户」写上另一头",IF(AND($L19="内部转账",$M19=$C19),"※对方账户跟本账户是同一个",IF(AND($L19<>"内部转账",$M19<>""),"△填了对方账户，但类别不是内部转账",IF(YEAR($B19)<>管理年度,"△不是管理年度的单据，按月的三张报表里看不到",IF($H19<0,"△这一笔之后该账户余额成负数了，核一下",""))))))))))))))
A20: =IF($C20="","",COUNTA($C$5:$C20)) -> 16 | B20: 46201 | C20: 工行 | D20: 供应商 | G20: 3000 | H20: =IFERROR(ROUND(VLOOKUP($C20,基础资料!$B$5:$E$34,3,0)+SUMIF($C$5:$C20,$C20,$F$5:$F20)-SUMIF($C$5:$C20,$C20,$G$5:$G20),2),"") -> 3700 | J20: 供应商2 | K20: =IF(OR($B20="",NOT(ISNUMBER($B20))),"",--TEXT($B20,"yyyymm")) -> 202606 | L20: =IF($D20="","",IFERROR(INDEX(类别属性,MATCH($D20,类别表,0)),"")) -> 支出 | N20: 主营业务 | P20: =IF($C20="","",IF(ISNA(MATCH($C20,账户表,0)),"※这个账户不在【基础资料】的账户档案里",IF($B20="","※没填日期，这一笔不会进任何月份的报表",IF(NOT(ISNUMBER($B20)),"※日期是文本不是日期（像 2026.6.28 这种），按日期取数的报表全会漏掉这一笔",IF(AND($F20<>"",$G20<>""),"※收入和支出不能同时填",IF(AND(N($F20)=0,N($G20)=0),"※收入和支出都没填",IF(OR(N($F20)<0,N($G20)<0),"※金额不能填负数，方向反了就换一列填",IF($D20="","※没填收支类别，分类报表会漏掉这一笔",IF(ISNA(MATCH($D20,类别表,0)),"※收支类别不在【基础资料】的清单里",IF(AND($L20="内部转账",$M20=""),"△内部转账要在「对方账户」写上另一头",IF(AND($L20="内部转账",$M20=$C20),"※对方账户跟本账户是同一个",IF(AND($L20<>"内部转账",$M20<>""),"△填了对方账户，但类别不是内部转账",IF(YEAR($B20)<>管理年度,"△不是管理年度的单据，按月的三张报表里看不到",IF($H20<0,"△这一笔之后该账户余额成负数了，核一下",""))))))))))))))
A21: =IF($C21="","",COUNTA($C$5:$C21)) -> 17 | B21: 46201 | C21: 微信 | D21: 销售回款 | F21: 800 | H21: =IFERROR(ROUND(VLOOKUP($C21,基础资料!$B$5:$E$34,3,0)+SUMIF($C$5:$C21,$C21,$F$5:$F21)-SUMIF($C$5:$C21,$C21,$G$5:$G21),2),"") -> 6600 | I21: 客户6 | K21: =IF(OR($B21="",NOT(ISNUMBER($B21))),"",--TEXT($B21,"yyyymm")) -> 202606 | L21: =IF($D21="","",IFERROR(INDEX(类别属性,MATCH($D21,类别表,0)),"")) -> 收入 | N21: 主营业务 | P21: =IF($C21="","",IF(ISNA(MATCH($C21,账户表,0)),"※这个账户不在【基础资料】的账户档案里",IF($B21="","※没填日期，这一笔不会进任何月份的报表",IF(NOT(ISNUMBER($B21)),"※日期是文本不是日期（像 2026.6.28 这种），按日期取数的报表全会漏掉这一笔",IF(AND($F21<>"",$G21<>""),"※收入和支出不能同时填",IF(AND(N($F21)=0,N($G21)=0),"※收入和支出都没填",IF(OR(N($F21)<0,N($G21)<0),"※金额不能填负数，方向反了就换一列填",IF($D21="","※没填收支类别，分类报表会漏掉这一笔",IF(ISNA(MATCH($D21,类别表,0)),"※收支类别不在【基础资料】的清单里",IF(AND($L21="内部转账",$M21=""),"△内部转账要在「对方账户」写上另一头",IF(AND($L21="内部转账",$M21=$C21),"※对方账户跟本账户是同一个",IF(AND($L21<>"内部转账",$M21<>""),"△填了对方账户，但类别不是内部转账",IF(YEAR($B21)<>管理年度,"△不是管理年度的单据，按月的三张报表里看不到",IF($H21<0,"△这一笔之后该账户余额成负数了，核一下",""))))))))))))))
A22: =IF($C22="","",COUNTA($C$5:$C22)) -> 18 | B22: 46202 | C22: 民生 | D22: 水费 | G22: 120 | H22: =IFERROR(ROUND(VLOOKUP($C22,基础资料!$B$5:$E$34,3,0)+SUMIF($C$5:$C22,$C22,$F$5:$F22)-SUMIF($C$5:$C22,$C22,$G$5:$G22),2),"") -> 7380 | K22: =IF(OR($B22="",NOT(ISNUMBER($B22))),"",--TEXT($B22,"yyyymm")) -> 202606 | L22: =IF($D22="","",IFERROR(INDEX(类别属性,MATCH($D22,类别表,0)),"")) -> 支出 | N22: 行政 | P22: =IF($C22="","",IF(ISNA(MATCH($C22,账户表,0)),"※这个账户不在【基础资料】的账户档案里",IF($B22="","※没填日期，这一笔不会进任何月份的报表",IF(NOT(ISNUMBER($B22)),"※日期是文本不是日期（像 2026.6.28 这种），按日期取数的报表全会漏掉这一笔",IF(AND($F22<>"",$G22<>""),"※收入和支出不能同时填",IF(AND(N($F22)=0,N($G22)=0),"※收入和支出都没填",IF(OR(N($F22)<0,N($G22)<0),"※金额不能填负数，方向反了就换一列填",IF($D22="","※没填收支类别，分类报表会漏掉这一笔",IF(ISNA(MATCH($D22,类别表,0)),"※收支类别不在【基础资料】的清单里",IF(AND($L22="内部转账",$M22=""),"△内部转账要在「对方账户」写上另一头",IF(AND($L22="内部转账",$M22=$C22),"※对方账户跟本账户是同一个",IF(AND($L22<>"内部转账",$M22<>""),"△填了对方账户，但类别不是内部转账",IF(YEAR($B22)<>管理年度,"△不是管理年度的单据，按月的三张报表里看不到",IF($H22<0,"△这一笔之后该账户余额成负数了，核一下",""))))))))))))))
A23: =IF($C23="","",COUNTA($C$5:$C23)) -> 19 | B23: 46202 | C23: 建行 | D23: 银行手续费 | G23: 30 | H23: =IFERROR(ROUND(VLOOKUP($C23,基础资料!$B$5:$E$34,3,0)+SUMIF($C$5:$C23,$C23,$F$5:$F23)-SUMIF($C$5:$C23,$C23,$G$5:$G23),2),"") -> 11570 | K23: =IF(OR($B23="",NOT(ISNUMBER($B23))),"",--TEXT($B23,"yyyymm")) -> 202606 | L23: =IF($D23="","",IFERROR(INDEX(类别属性,MATCH($D23,类别表,0)),"")) -> 支出 | N23: 行政 | P23: =IF($C23="","",IF(ISNA(MATCH($C23,账户表,0)),"※这个账户不在【基础资料】的账户档案里",IF($B23="","※没填日期，这一笔不会进任何月份的报表",IF(NOT(ISNUMBER($B23)),"※日期是文本不是日期（像 2026.6.28 这种），按日期取数的报表全会漏掉这一笔",IF(AND($F23<>"",$G23<>""),"※收入和支出不能同时填",IF(AND(N($F23)=0,N($G23)=0),"※收入和支出都没填",IF(OR(N($F23)<0,N($G23)<0),"※金额不能填负数，方向反了就换一列填",IF($D23="","※没填收支类别，分类报表会漏掉这一笔",IF(ISNA(MATCH($D23,类别表,0)),"※收支类别不在【基础资料】的清单里",IF(AND($L23="内部转账",$M23=""),"△内部转账要在「对方账户」写上另一头",IF(AND($L23="内部转账",$M23=$C23),"※对方账户跟本账户是同一个",IF(AND($L23<>"内部转账",$M23<>""),"△填了对方账户，但类别不是内部转账",IF(YEAR($B23)<>管理年度,"△不是管理年度的单据，按月的三张报表里看不到",IF($H23<0,"△这一笔之后该账户余额成负数了，核一下",""))))))))))))))
A24: =IF($C24="","",COUNTA($C$5:$C24)) -> 20 | B24: 46203 | C24: 农行 | D24: 销售回款 | F24: 4200 | H24: =IFERROR(ROUND(VLOOKUP($C24,基础资料!$B$5:$E$34,3,0)+SUMIF($C$5:$C24,$C24,$F$5:$F24)-SUMIF($C$5:$C24,$C24,$G$5:$G24),2),"") -> 9200 | I24: 客户7 | K24: =IF(OR($B24="",NOT(ISNUMBER($B24))),"",--TEXT($B24,"yyyymm")) -> 202606 | L24: =IF($D24="","",IFERROR(INDEX(类别属性,MATCH($D24,类别表,0)),"")) -> 收入 | N24: 主营业务 | P24: =IF($C24="","",IF(ISNA(MATCH($C24,账户表,0)),"※这个账户不在【基础资料】的账户档案里",IF($B24="","※没填日期，这一笔不会进任何月份的报表",IF(NOT(ISNUMBER($B24)),"※日期是文本不是日期（像 2026.6.28 这种），按日期取数的报表全会漏掉这一笔",IF(AND($F24<>"",$G24<>""),"※收入和支出不能同时填",IF(AND(N($F24)=0,N($G24)=0),"※收入和支出都没填",IF(OR(N($F24)<0,N($G24)<0),"※金额不能填负数，方向反了就换一列填",IF($D24="","※没填收支类别，分类报表会漏掉这一笔",IF(ISNA(MATCH($D24,类别表,0)),"※收支类别不在【基础资料】的清单里",IF(AND($L24="内部转账",$M24=""),"△内部转账要在「对方账户」写上另一头",IF(AND($L24="内部转账",$M24=$C24),"※对方账户跟本账户是同一个",IF(AND($L24<>"内部转账",$M24<>""),"△填了对方账户，但类别不是内部转账",IF(YEAR($B24)<>管理年度,"△不是管理年度的单据，按月的三张报表里看不到",IF($H24<0,"△这一笔之后该账户余额成负数了，核一下",""))))))))))))))
A25: =IF($C25="","",COUNTA($C$5:$C25)) -> 21 | B25: 46203 | C25: 中行 | D25: 供应商 | G25: 2500 | H25: =IFERROR(ROUND(VLOOKUP($C25,基础资料!$B$5:$E$34,3,0)+SUMIF($C$5:$C25,$C25,$F$5:$F25)-SUMIF($C$5:$C25,$C25,$G$5:$G25),2),"") -> 8300 | J25: 供应商3 | K25: =IF(OR($B25="",NOT(ISNUMBER($B25))),"",--TEXT($B25,"yyyymm")) -> 202606 | L25: =IF($D25="","",IFERROR(INDEX(类别属性,MATCH($D25,类别表,0)),"")) -> 支出 | N25: 主营业务 | P25: =IF($C25="","",IF(ISNA(MATCH($C25,账户表,0)),"※这个账户不在【基础资料】的账户档案里",IF($B25="","※没填日期，这一笔不会进任何月份的报表",IF(NOT(ISNUMBER($B25)),"※日期是文本不是日期（像 2026.6.28 这种），按日期取数的报表全会漏掉这一笔",IF(AND($F25<>"",$G25<>""),"※收入和支出不能同时填",IF(AND(N($F25)=0,N($G25)=0),"※收入和支出都没填",IF(OR(N($F25)<0,N($G25)<0),"※金额不能填负数，方向反了就换一列填",IF($D25="","※没填收支类别，分类报表会漏掉这一笔",IF(ISNA(MATCH($D25,类别表,0)),"※收支类别不在【基础资料】的清单里",IF(AND($L25="内部转账",$M25=""),"△内部转账要在「对方账户」写上另一头",IF(AND($L25="内部转账",$M25=$C25),"※对方账户跟本账户是同一个",IF(AND($L25<>"内部转账",$M25<>""),"△填了对方账户，但类别不是内部转账",IF(YEAR($B25)<>管理年度,"△不是管理年度的单据，按月的三张报表里看不到",IF($H25<0,"△这一笔之后该账户余额成负数了，核一下",""))))))))))))))
A26: =IF($C26="","",COUNTA($C$5:$C26)) -> 22 | B26: 46203 | C26: 支付宝 | D26: 销售回款 | F26: 600 | H26: =IFERROR(ROUND(VLOOKUP($C26,基础资料!$B$5:$E$34,3,0)+SUMIF($C$5:$C26,$C26,$F$5:$F26)-SUMIF($C$5:$C26,$C26,$G$5:$G26),2),"") -> 12590 | I26: 客户8 | K26: =IF(OR($B26="",NOT(ISNUMBER($B26))),"",--TEXT($B26,"yyyymm")) -> 202606 | L26: =IF($D26="","",IFERROR(INDEX(类别属性,MATCH($D26,类别表,0)),"")) -> 收入 | N26: 主营业务 | P26: =IF($C26="","",IF(ISNA(MATCH($C26,账户表,0)),"※这个账户不在【基础资料】的账户档案里",IF($B26="","※没填日期，这一笔不会进任何月份的报表",IF(NOT(ISNUMBER($B26)),"※日期是文本不是日期（像 2026.6.28 这种），按日期取数的报表全会漏掉这一笔",IF(AND($F26<>"",$G26<>""),"※收入和支出不能同时填",IF(AND(N($F26)=0,N($G26)=0),"※收入和支出都没填",IF(OR(N($F26)<0,N($G26)<0),"※金额不能填负数，方向反了就换一列填",IF($D26="","※没填收支类别，分类报表会漏掉这一笔",IF(ISNA(MATCH($D26,类别表,0)),"※收支类别不在【基础资料】的清单里",IF(AND($L26="内部转账",$M26=""),"△内部转账要在「对方账户」写上另一头",IF(AND($L26="内部转账",$M26=$C26),"※对方账户跟本账户是同一个",IF(AND($L26<>"内部转账",$M26<>""),"△填了对方账户，但类别不是内部转账",IF(YEAR($B26)<>管理年度,"△不是管理年度的单据，按月的三张报表里看不到",IF($H26<0,"△这一笔之后该账户余额成负数了，核一下",""))))))))))))))
A27: =IF($C27="","",COUNTA($C$5:$C27)) -> 23 | B27: 46203 | C27: 农商行 | D27: 办公费 | G27: 80 | H27: =IFERROR(ROUND(VLOOKUP($C27,基础资料!$B$5:$E$34,3,0)+SUMIF($C$5:$C27,$C27,$F$5:$F27)-SUMIF($C$5:$C27,$C27,$G$5:$G27),2),"") -> 12870 | K27: =IF(OR($B27="",NOT(ISNUMBER($B27))),"",--TEXT($B27,"yyyymm")) -> 202606 | L27: =IF($D27="","",IFERROR(INDEX(类别属性,MATCH($D27,类别表,0)),"")) -> 支出 | N27: 行政 | P27: =IF($C27="","",IF(ISNA(MATCH($C27,账户表,0)),"※这个账户不在【基础资料】的账户档案里",IF($B27="","※没填日期，这一笔不会进任何月份的报表",IF(NOT(ISNUMBER($B27)),"※日期是文本不是日期（像 2026.6.28 这种），按日期取数的报表全会漏掉这一笔",IF(AND($F27<>"",$G27<>""),"※收入和支出不能同时填",IF(AND(N($F27)=0,N($G27)=0),"※收入和支出都没填",IF(OR(N($F27)<0,N($G27)<0),"※金额不能填负数，方向反了就换一列填",IF($D27="","※没填收支类别，分类报表会漏掉这一笔",IF(ISNA(MATCH($D27,类别表,0)),"※收支类别不在【基础资料】的清单里",IF(AND($L27="内部转账",$M27=""),"△内部转账要在「对方账户」写上另一头",IF(AND($L27="内部转账",$M27=$C27),"※对方账户跟本账户是同一个",IF(AND($L27<>"内部转账",$M27<>""),"△填了对方账户，但类别不是内部转账",IF(YEAR($B27)<>管理年度,"△不是管理年度的单据，按月的三张报表里看不到",IF($H27<0,"△这一笔之后该账户余额成负数了，核一下",""))))))))))))))
A28: =IF($C28="","",COUNTA($C$5:$C28)) -> 24 | B28: 46203 | C28: 工行 | D28: 内部转账 | E28: 工行转现金备用 | G28: 2000 | H28: =IFERROR(ROUND(VLOOKUP($C28,基础资料!$B$5:$E$34,3,0)+SUMIF($C$5:$C28,$C28,$F$5:$F28)-SUMIF($C$5:$C28,$C28,$G$5:$G28),2),"") -> 1700 | K28: =IF(OR($B28="",NOT(ISNUMBER($B28))),"",--TEXT($B28,"yyyymm")) -> 202606 | L28: =IF($D28="","",IFERROR(INDEX(类别属性,MATCH($D28,类别表,0)),"")) -> 内部转账 | M28: 现金 | N28: 内部调拨 | P28: =IF($C28="","",IF(ISNA(MATCH($C28,账户表,0)),"※这个账户不在【基础资料】的账户档案里",IF($B28="","※没填日期，这一笔不会进任何月份的报表",IF(NOT(ISNUMBER($B28)),"※日期是文本不是日期（像 2026.6.28 这种），按日期取数的报表全会漏掉这一笔",IF(AND($F28<>"",$G28<>""),"※收入和支出不能同时填",IF(AND(N($F28)=0,N($G28)=0),"※收入和支出都没填",IF(OR(N($F28)<0,N($G28)<0),"※金额不能填负数，方向反了就换一列填",IF($D28="","※没填收支类别，分类报表会漏掉这一笔",IF(ISNA(MATCH($D28,类别表,0)),"※收支类别不在【基础资料】的清单里",IF(AND($L28="内部转账",$M28=""),"△内部转账要在「对方账户」写上另一头",IF(AND($L28="内部转账",$M28=$C28),"※对方账户跟本账户是同一个",IF(AND($L28<>"内部转账",$M28<>""),"△填了对方账户，但类别不是内部转账",IF(YEAR($B28)<>管理年度,"△不是管理年度的单据，按月的三张报表里看不到",IF($H28<0,"△这一笔之后该账户余额成负数了，核一下",""))))))))))))))
A29: =IF($C29="","",COUNTA($C$5:$C29)) -> 25 | B29: 46203 | C29: 现金 | D29: 内部转账 | E29: 收到工行转入 | F29: 2000 | H29: =IFERROR(ROUND(VLOOKUP($C29,基础资料!$B$5:$E$34,3,0)+SUMIF($C$5:$C29,$C29,$F$5:$F29)-SUMIF($C$5:$C29,$C29,$G$5:$G29),2),"") -> 8800 | K29: =IF(OR($B29="",NOT(ISNUMBER($B29))),"",--TEXT($B29,"yyyymm")) -> 202606 | L29: =IF($D29="","",IFERROR(INDEX(类别属性,MATCH($D29,类别表,0)),"")) -> 内部转账 | M29: 工行 | N29: 内部调拨 | P29: =IF($C29="","",IF(ISNA(MATCH($C29,账户表,0)),"※这个账户不在【基础资料】的账户档案里",IF($B29="","※没填日期，这一笔不会进任何月份的报表",IF(NOT(ISNUMBER($B29)),"※日期是文本不是日期（像 2026.6.28 这种），按日期取数的报表全会漏掉这一笔",IF(AND($F29<>"",$G29<>""),"※收入和支出不能同时填",IF(AND(N($F29)=0,N($G29)=0),"※收入和支出都没填",IF(OR(N($F29)<0,N($G29)<0),"※金额不能填负数，方向反了就换一列填",IF($D29="","※没填收支类别，分类报表会漏掉这一笔",IF(ISNA(MATCH($D29,类别表,0)),"※收支类别不在【基础资料】的清单里",IF(AND($L29="内部转账",$M29=""),"△内部转账要在「对方账户」写上另一头",IF(AND($L29="内部转账",$M29=$C29),"※对方账户跟本账户是同一个",IF(AND($L29<>"内部转账",$M29<>""),"△填了对方账户，但类别不是内部转账",IF(YEAR($B29)<>管理年度,"△不是管理年度的单据，按月的三张报表里看不到",IF($H29<0,"△这一笔之后该账户余额成负数了，核一下",""))))))))))))))
A30: =IF($C30="","",COUNTA($C$5:$C30)) | H30: =IFERROR(ROUND(VLOOKUP($C30,基础资料!$B$5:$E$34,3,0)+SUMIF($C$5:$C30,$C30,$F$5:$F30)-SUMIF($C$5:$C30,$C30,$G$5:$G30),2),"") | K30: =IF(OR($B30="",NOT(ISNUMBER($B30))),"",--TEXT($B30,"yyyymm")) | L30: =IF($D30="","",IFERROR(INDEX(类别属性,MATCH($D30,类别表,0)),"")) | P30: =IF($C30="","",IF(ISNA(MATCH($C30,账户表,0)),"※这个账户不在【基础资料】的账户档案里",IF($B30="","※没填日期，这一笔不会进任何月份的报表",IF(NOT(ISNUMBER($B30)),"※日期是文本不是日期（像 2026.6.28 这种），按日期取数的报表全会漏掉这一笔",IF(AND($F30<>"",$G30<>""),"※收入和支出不能同时填",IF(AND(N($F30)=0,N($G30)=0),"※收入和支出都没填",IF(OR(N($F30)<0,N($G30)<0),"※金额不能填负数，方向反了就换一列填",IF($D30="","※没填收支类别，分类报表会漏掉这一笔",IF(ISNA(MATCH($D30,类别表,0)),"※收支类别不在【基础资料】的清单里",IF(AND($L30="内部转账",$M30=""),"△内部转账要在「对方账户」写上另一头",IF(AND($L30="内部转账",$M30=$C30),"※对方账户跟本账户是同一个",IF(AND($L30<>"内部转账",$M30<>""),"△填了对方账户，但类别不是内部转账",IF(YEAR($B30)<>管理年度,"△不是管理年度的单据，按月的三张报表里看不到",IF($H30<0,"△这一笔之后该账户余额成负数了，核一下",""))))))))))))))
A31: =IF($C31="","",COUNTA($C$5:$C31)) | H31: =IFERROR(ROUND(VLOOKUP($C31,基础资料!$B$5:$E$34,3,0)+SUMIF($C$5:$C31,$C31,$F$5:$F31)-SUMIF($C$5:$C31,$C31,$G$5:$G31),2),"") | K31: =IF(OR($B31="",NOT(ISNUMBER($B31))),"",--TEXT($B31,"yyyymm")) | L31: =IF($D31="","",IFERROR(INDEX(类别属性,MATCH($D31,类别表,0)),"")) | P31: =IF($C31="","",IF(ISNA(MATCH($C31,账户表,0)),"※这个账户不在【基础资料】的账户档案里",IF($B31="","※没填日期，这一笔不会进任何月份的报表",IF(NOT(ISNUMBER($B31)),"※日期是文本不是日期（像 2026.6.28 这种），按日期取数的报表全会漏掉这一笔",IF(AND($F31<>"",$G31<>""),"※收入和支出不能同时填",IF(AND(N($F31)=0,N($G31)=0),"※收入和支出都没填",IF(OR(N($F31)<0,N($G31)<0),"※金额不能填负数，方向反了就换一列填",IF($D31="","※没填收支类别，分类报表会漏掉这一笔",IF(ISNA(MATCH($D31,类别表,0)),"※收支类别不在【基础资料】的清单里",IF(AND($L31="内部转账",$M31=""),"△内部转账要在「对方账户」写上另一头",IF(AND($L31="内部转账",$M31=$C31),"※对方账户跟本账户是同一个",IF(AND($L31<>"内部转账",$M31<>""),"△填了对方账户，但类别不是内部转账",IF(YEAR($B31)<>管理年度,"△不是管理年度的单据，按月的三张报表里看不到",IF($H31<0,"△这一笔之后该账户余额成负数了，核一下",""))))))))))))))
A32: =IF($C32="","",COUNTA($C$5:$C32)) | H32: =IFERROR(ROUND(VLOOKUP($C32,基础资料!$B$5:$E$34,3,0)+SUMIF($C$5:$C32,$C32,$F$5:$F32)-SUMIF($C$5:$C32,$C32,$G$5:$G32),2),"") | K32: =IF(OR($B32="",NOT(ISNUMBER($B32))),"",--TEXT($B32,"yyyymm")) | L32: =IF($D32="","",IFERROR(INDEX(类别属性,MATCH($D32,类别表,0)),"")) | P32: =IF($C32="","",IF(ISNA(MATCH($C32,账户表,0)),"※这个账户不在【基础资料】的账户档案里",IF($B32="","※没填日期，这一笔不会进任何月份的报表",IF(NOT(ISNUMBER($B32)),"※日期是文本不是日期（像 2026.6.28 这种），按日期取数的报表全会漏掉这一笔",IF(AND($F32<>"",$G32<>""),"※收入和支出不能同时填",IF(AND(N($F32)=0,N($G32)=0),"※收入和支出都没填",IF(OR(N($F32)<0,N($G32)<0),"※金额不能填负数，方向反了就换一列填",IF($D32="","※没填收支类别，分类报表会漏掉这一笔",IF(ISNA(MATCH($D32,类别表,0)),"※收支类别不在【基础资料】的清单里",IF(AND($L32="内部转账",$M32=""),"△内部转账要在「对方账户」写上另一头",IF(AND($L32="内部转账",$M32=$C32),"※对方账户跟本账户是同一个",IF(AND($L32<>"内部转账",$M32<>""),"△填了对方账户，但类别不是内部转账",IF(YEAR($B32)<>管理年度,"△不是管理年度的单据，按月的三张报表里看不到",IF($H32<0,"△这一笔之后该账户余额成负数了，核一下",""))))))))))))))
A33: =IF($C33="","",COUNTA($C$5:$C33)) | H33: =IFERROR(ROUND(VLOOKUP($C33,基础资料!$B$5:$E$34,3,0)+SUMIF($C$5:$C33,$C33,$F$5:$F33)-SUMIF($C$5:$C33,$C33,$G$5:$G33),2),"") | K33: =IF(OR($B33="",NOT(ISNUMBER($B33))),"",--TEXT($B33,"yyyymm")) | L33: =IF($D33="","",IFERROR(INDEX(类别属性,MATCH($D33,类别表,0)),"")) | P33: =IF($C33="","",IF(ISNA(MATCH($C33,账户表,0)),"※这个账户不在【基础资料】的账户档案里",IF($B33="","※没填日期，这一笔不会进任何月份的报表",IF(NOT(ISNUMBER($B33)),"※日期是文本不是日期（像 2026.6.28 这种），按日期取数的报表全会漏掉这一笔",IF(AND($F33<>"",$G33<>""),"※收入和支出不能同时填",IF(AND(N($F33)=0,N($G33)=0),"※收入和支出都没填",IF(OR(N($F33)<0,N($G33)<0),"※金额不能填负数，方向反了就换一列填",IF($D33="","※没填收支类别，分类报表会漏掉这一笔",IF(ISNA(MATCH($D33,类别表,0)),"※收支类别不在【基础资料】的清单里",IF(AND($L33="内部转账",$M33=""),"△内部转账要在「对方账户」写上另一头",IF(AND($L33="内部转账",$M33=$C33),"※对方账户跟本账户是同一个",IF(AND($L33<>"内部转账",$M33<>""),"△填了对方账户，但类别不是内部转账",IF(YEAR($B33)<>管理年度,"△不是管理年度的单据，按月的三张报表里看不到",IF($H33<0,"△这一笔之后该账户余额成负数了，核一下",""))))))))))))))
A34: =IF($C34="","",COUNTA($C$5:$C34)) | H34: =IFERROR(ROUND(VLOOKUP($C34,基础资料!$B$5:$E$34,3,0)+SUMIF($C$5:$C34,$C34,$F$5:$F34)-SUMIF($C$5:$C34,$C34,$G$5:$G34),2),"") | K34: =IF(OR($B34="",NOT(ISNUMBER($B34))),"",--TEXT($B34,"yyyymm")) | L34: =IF($D34="","",IFERROR(INDEX(类别属性,MATCH($D34,类别表,0)),"")) | P34: =IF($C34="","",IF(ISNA(MATCH($C34,账户表,0)),"※这个账户不在【基础资料】的账户档案里",IF($B34="","※没填日期，这一笔不会进任何月份的报表",IF(NOT(ISNUMBER($B34)),"※日期是文本不是日期（像 2026.6.28 这种），按日期取数的报表全会漏掉这一笔",IF(AND($F34<>"",$G34<>""),"※收入和支出不能同时填",IF(AND(N($F34)=0,N($G34)=0),"※收入和支出都没填",IF(OR(N($F34)<0,N($G34)<0),"※金额不能填负数，方向反了就换一列填",IF($D34="","※没填收支类别，分类报表会漏掉这一笔",IF(ISNA(MATCH($D34,类别表,0)),"※收支类别不在【基础资料】的清单里",IF(AND($L34="内部转账",$M34=""),"△内部转账要在「对方账户」写上另一头",IF(AND($L34="内部转账",$M34=$C34),"※对方账户跟本账户是同一个",IF(AND($L34<>"内部转账",$M34<>""),"△填了对方账户，但类别不是内部转账",IF(YEAR($B34)<>管理年度,"△不是管理年度的单据，按月的三张报表里看不到",IF($H34<0,"△这一笔之后该账户余额成负数了，核一下",""))))))))))))))
A35: =IF($C35="","",COUNTA($C$5:$C35)) | H35: =IFERROR(ROUND(VLOOKUP($C35,基础资料!$B$5:$E$34,3,0)+SUMIF($C$5:$C35,$C35,$F$5:$F35)-SUMIF($C$5:$C35,$C35,$G$5:$G35),2),"") | K35: =IF(OR($B35="",NOT(ISNUMBER($B35))),"",--TEXT($B35,"yyyymm")) | L35: =IF($D35="","",IFERROR(INDEX(类别属性,MATCH($D35,类别表,0)),"")) | P35: =IF($C35="","",IF(ISNA(MATCH($C35,账户表,0)),"※这个账户不在【基础资料】的账户档案里",IF($B35="","※没填日期，这一笔不会进任何月份的报表",IF(NOT(ISNUMBER($B35)),"※日期是文本不是日期（像 2026.6.28 这种），按日期取数的报表全会漏掉这一笔",IF(AND($F35<>"",$G35<>""),"※收入和支出不能同时填",IF(AND(N($F35)=0,N($G35)=0),"※收入和支出都没填",IF(OR(N($F35)<0,N($G35)<0),"※金额不能填负数，方向反了就换一列填",IF($D35="","※没填收支类别，分类报表会漏掉这一笔",IF(ISNA(MATCH($D35,类别表,0)),"※收支类别不在【基础资料】的清单里",IF(AND($L35="内部转账",$M35=""),"△内部转账要在「对方账户」写上另一头",IF(AND($L35="内部转账",$M35=$C35),"※对方账户跟本账户是同一个",IF(AND($L35<>"内部转账",$M35<>""),"△填了对方账户，但类别不是内部转账",IF(YEAR($B35)<>管理年度,"△不是管理年度的单据，按月的三张报表里看不到",IF($H35<0,"△这一笔之后该账户余额成负数了，核一下",""))))))))))))))
A36: =IF($C36="","",COUNTA($C$5:$C36)) | H36: =IFERROR(ROUND(VLOOKUP($C36,基础资料!$B$5:$E$34,3,0)+SUMIF($C$5:$C36,$C36,$F$5:$F36)-SUMIF($C$5:$C36,$C36,$G$5:$G36),2),"") | K36: =IF(OR($B36="",NOT(ISNUMBER($B36))),"",--TEXT($B36,"yyyymm")) | L36: =IF($D36="","",IFERROR(INDEX(类别属性,MATCH($D36,类别表,0)),"")) | P36: =IF($C36="","",IF(ISNA(MATCH($C36,账户表,0)),"※这个账户不在【基础资料】的账户档案里",IF($B36="","※没填日期，这一笔不会进任何月份的报表",IF(NOT(ISNUMBER($B36)),"※日期是文本不是日期（像 2026.6.28 这种），按日期取数的报表全会漏掉这一笔",IF(AND($F36<>"",$G36<>""),"※收入和支出不能同时填",IF(AND(N($F36)=0,N($G36)=0),"※收入和支出都没填",IF(OR(N($F36)<0,N($G36)<0),"※金额不能填负数，方向反了就换一列填",IF($D36="","※没填收支类别，分类报表会漏掉这一笔",IF(ISNA(MATCH($D36,类别表,0)),"※收支类别不在【基础资料】的清单里",IF(AND($L36="内部转账",$M36=""),"△内部转账要在「对方账户」写上另一头",IF(AND($L36="内部转账",$M36=$C36),"※对方账户跟本账户是同一个",IF(AND($L36<>"内部转账",$M36<>""),"△填了对方账户，但类别不是内部转账",IF(YEAR($B36)<>管理年度,"△不是管理年度的单据，按月的三张报表里看不到",IF($H36<0,"△这一笔之后该账户余额成负数了，核一下",""))))))))))))))
A37: =IF($C37="","",COUNTA($C$5:$C37)) | H37: =IFERROR(ROUND(VLOOKUP($C37,基础资料!$B$5:$E$34,3,0)+SUMIF($C$5:$C37,$C37,$F$5:$F37)-SUMIF($C$5:$C37,$C37,$G$5:$G37),2),"") | K37: =IF(OR($B37="",NOT(ISNUMBER($B37))),"",--TEXT($B37,"yyyymm")) | L37: =IF($D37="","",IFERROR(INDEX(类别属性,MATCH($D37,类别表,0)),"")) | P37: =IF($C37="","",IF(ISNA(MATCH($C37,账户表,0)),"※这个账户不在【基础资料】的账户档案里",IF($B37="","※没填日期，这一笔不会进任何月份的报表",IF(NOT(ISNUMBER($B37)),"※日期是文本不是日期（像 2026.6.28 这种），按日期取数的报表全会漏掉这一笔",IF(AND($F37<>"",$G37<>""),"※收入和支出不能同时填",IF(AND(N($F37)=0,N($G37)=0),"※收入和支出都没填",IF(OR(N($F37)<0,N($G37)<0),"※金额不能填负数，方向反了就换一列填",IF($D37="","※没填收支类别，分类报表会漏掉这一笔",IF(ISNA(MATCH($D37,类别表,0)),"※收支类别不在【基础资料】的清单里",IF(AND($L37="内部转账",$M37=""),"△内部转账要在「对方账户」写上另一头",IF(AND($L37="内部转账",$M37=$C37),"※对方账户跟本账户是同一个",IF(AND($L37<>"内部转账",$M37<>""),"△填了对方账户，但类别不是内部转账",IF(YEAR($B37)<>管理年度,"△不是管理年度的单据，按月的三张报表里看不到",IF($H37<0,"△这一笔之后该账户余额成负数了，核一下",""))))))))))))))
A38: =IF($C38="","",COUNTA($C$5:$C38)) | H38: =IFERROR(ROUND(VLOOKUP($C38,基础资料!$B$5:$E$34,3,0)+SUMIF($C$5:$C38,$C38,$F$5:$F38)-SUMIF($C$5:$C38,$C38,$G$5:$G38),2),"") | K38: =IF(OR($B38="",NOT(ISNUMBER($B38))),"",--TEXT($B38,"yyyymm")) | L38: =IF($D38="","",IFERROR(INDEX(类别属性,MATCH($D38,类别表,0)),"")) | P38: =IF($C38="","",IF(ISNA(MATCH($C38,账户表,0)),"※这个账户不在【基础资料】的账户档案里",IF($B38="","※没填日期，这一笔不会进任何月份的报表",IF(NOT(ISNUMBER($B38)),"※日期是文本不是日期（像 2026.6.28 这种），按日期取数的报表全会漏掉这一笔",IF(AND($F38<>"",$G38<>""),"※收入和支出不能同时填",IF(AND(N($F38)=0,N($G38)=0),"※收入和支出都没填",IF(OR(N($F38)<0,N($G38)<0),"※金额不能填负数，方向反了就换一列填",IF($D38="","※没填收支类别，分类报表会漏掉这一笔",IF(ISNA(MATCH($D38,类别表,0)),"※收支类别不在【基础资料】的清单里",IF(AND($L38="内部转账",$M38=""),"△内部转账要在「对方账户」写上另一头",IF(AND($L38="内部转账",$M38=$C38),"※对方账户跟本账户是同一个",IF(AND($L38<>"内部转账",$M38<>""),"△填了对方账户，但类别不是内部转账",IF(YEAR($B38)<>管理年度,"△不是管理年度的单据，按月的三张报表里看不到",IF($H38<0,"△这一笔之后该账户余额成负数了，核一下",""))))))))))))))
A39: =IF($C39="","",COUNTA($C$5:$C39)) | H39: =IFERROR(ROUND(VLOOKUP($C39,基础资料!$B$5:$E$34,3,0)+SUMIF($C$5:$C39,$C39,$F$5:$F39)-SUMIF($C$5:$C39,$C39,$G$5:$G39),2),"") | K39: =IF(OR($B39="",NOT(ISNUMBER($B39))),"",--TEXT($B39,"yyyymm")) | L39: =IF($D39="","",IFERROR(INDEX(类别属性,MATCH($D39,类别表,0)),"")) | P39: =IF($C39="","",IF(ISNA(MATCH($C39,账户表,0)),"※这个账户不在【基础资料】的账户档案里",IF($B39="","※没填日期，这一笔不会进任何月份的报表",IF(NOT(ISNUMBER($B39)),"※日期是文本不是日期（像 2026.6.28 这种），按日期取数的报表全会漏掉这一笔",IF(AND($F39<>"",$G39<>""),"※收入和支出不能同时填",IF(AND(N($F39)=0,N($G39)=0),"※收入和支出都没填",IF(OR(N($F39)<0,N($G39)<0),"※金额不能填负数，方向反了就换一列填",IF($D39="","※没填收支类别，分类报表会漏掉这一笔",IF(ISNA(MATCH($D39,类别表,0)),"※收支类别不在【基础资料】的清单里",IF(AND($L39="内部转账",$M39=""),"△内部转账要在「对方账户」写上另一头",IF(AND($L39="内部转账",$M39=$C39),"※对方账户跟本账户是同一个",IF(AND($L39<>"内部转账",$M39<>""),"△填了对方账户，但类别不是内部转账",IF(YEAR($B39)<>管理年度,"△不是管理年度的单据，按月的三张报表里看不到",IF($H39<0,"△这一笔之后该账户余额成负数了，核一下",""))))))))))))))
A40: =IF($C40="","",COUNTA($C$5:$C40)) | H40: =IFERROR(ROUND(VLOOKUP($C40,基础资料!$B$5:$E$34,3,0)+SUMIF($C$5:$C40,$C40,$F$5:$F40)-SUMIF($C$5:$C40,$C40,$G$5:$G40),2),"") | K40: =IF(OR($B40="",NOT(ISNUMBER($B40))),"",--TEXT($B40,"yyyymm")) | L40: =IF($D40="","",IFERROR(INDEX(类别属性,MATCH($D40,类别表,0)),"")) | P40: =IF($C40="","",IF(ISNA(MATCH($C40,账户表,0)),"※这个账户不在【基础资料】的账户档案里",IF($B40="","※没填日期，这一笔不会进任何月份的报表",IF(NOT(ISNUMBER($B40)),"※日期是文本不是日期（像 2026.6.28 这种），按日期取数的报表全会漏掉这一笔",IF(AND($F40<>"",$G40<>""),"※收入和支出不能同时填",IF(AND(N($F40)=0,N($G40)=0),"※收入和支出都没填",IF(OR(N($F40)<0,N($G40)<0),"※金额不能填负数，方向反了就换一列填",IF($D40="","※没填收支类别，分类报表会漏掉这一笔",IF(ISNA(MATCH($D40,类别表,0)),"※收支类别不在【基础资料】的清单里",IF(AND($L40="内部转账",$M40=""),"△内部转账要在「对方账户」写上另一头",IF(AND($L40="内部转账",$M40=$C40),"※对方账户跟本账户是同一个",IF(AND($L40<>"内部转账",$M40<>""),"△填了对方账户，但类别不是内部转账",IF(YEAR($B40)<>管理年度,"△不是管理年度的单据，按月的三张报表里看不到",IF($H40<0,"△这一笔之后该账户余额成负数了，核一下",""))))))))))))))
...

Sheet 汇报表
A1: 汇报表 · 三块老界面原样保留（账户清单改成自动长，加账户不用再改三处）
A2: ① 资金日报统计表：改上面两个日期就行，最多 31 天。这一块是「账户口径」 ——收款/付款按钱进出账户算，内部划转也算在里面（因为账户余额确实动了）。② 货币资金日报表：指定某一天。③ 多帐户资金汇总表：按月，这一块是「经营口径」，内部转入/转出单独两列，不混进本月收入和本月支出。
A3: 起始日期 | B3: 46174 | D3: 截止日期 | E3: 46203 | G3: 查询天数 | H3: =IF(OR($B$3="",$E$3=""),"",IF($E$3<$B$3,"※截止早于起始",IF($E$3-$B$3+1>31,"※超过 31 天，请分段查",$E$3-$B$3+1))) -> 30
A4: 公司期初余额 | C4: 期间收款合计 | E4: 期间付款合计 | G4: 期末结余金额
B5: =ROUND(SUM(B8:B37),2) -> 161000 | D5: =ROUND(SUM(BM8:BM37),2) -> 18800 | F5: =ROUND(SUM(BN8:BN37),2) -> 24190 | H5: =ROUND(SUM(BO8:BO37),2) -> 155610
A6: ① 资金日报统计表（账户口径，含内部划转） | C6: =IF(NOT(ISNUMBER($H$3)),"",IF(1<=MIN($H$3,31),$B$3+0,"")) -> 46174 | D6: =IF(NOT(ISNUMBER($H$3)),"",IF(1<=MIN($H$3,31),$B$3+0,"")) -> 46174 | E6: =IF(NOT(ISNUMBER($H$3)),"",IF(2<=MIN($H$3,31),$B$3+1,"")) -> 46175 | F6: =IF(NOT(ISNUMBER($H$3)),"",IF(2<=MIN($H$3,31),$B$3+1,"")) -> 46175 | G6: =IF(NOT(ISNUMBER($H$3)),"",IF(3<=MIN($H$3,31),$B$3+2,"")) -> 46176 | H6: =IF(NOT(ISNUMBER($H$3)),"",IF(3<=MIN($H$3,31),$B$3+2,"")) -> 46176 | I6: =IF(NOT(ISNUMBER($H$3)),"",IF(4<=MIN($H$3,31),$B$3+3,"")) -> 46177 | J6: =IF(NOT(ISNUMBER($H$3)),"",IF(4<=MIN($H$3,31),$B$3+3,"")) -> 46177 | K6: =IF(NOT(ISNUMBER($H$3)),"",IF(5<=MIN($H$3,31),$B$3+4,"")) -> 46178 | L6: =IF(NOT(ISNUMBER($H$3)),"",IF(5<=MIN($H$3,31),$B$3+4,"")) -> 46178 | M6: =IF(NOT(ISNUMBER($H$3)),"",IF(6<=MIN($H$3,31),$B$3+5,"")) -> 46179 | N6: =IF(NOT(ISNUMBER($H$3)),"",IF(6<=MIN($H$3,31),$B$3+5,"")) -> 46179 | O6: =IF(NOT(ISNUMBER($H$3)),"",IF(7<=MIN($H$3,31),$B$3+6,"")) -> 46180 | P6: =IF(NOT(ISNUMBER($H$3)),"",IF(7<=MIN($H$3,31),$B$3+6,"")) -> 46180 | Q6: =IF(NOT(ISNUMBER($H$3)),"",IF(8<=MIN($H$3,31),$B$3+7,"")) -> 46181 | R6: =IF(NOT(ISNUMBER($H$3)),"",IF(8<=MIN($H$3,31),$B$3+7,"")) -> 46181 | S6: =IF(NOT(ISNUMBER($H$3)),"",IF(9<=MIN($H$3,31),$B$3+8,"")) -> 46182 | T6: =IF(NOT(ISNUMBER($H$3)),"",IF(9<=MIN($H$3,31),$B$3+8,"")) -> 46182 | U6: =IF(NOT(ISNUMBER($H$3)),"",IF(10<=MIN($H$3,31),$B$3+9,"")) -> 46183 | V6: =IF(NOT(ISNUMBER($H$3)),"",IF(10<=MIN($H$3,31),$B$3+9,"")) -> 46183 | W6: =IF(NOT(ISNUMBER($H$3)),"",IF(11<=MIN($H$3,31),$B$3+10,"")) -> 46184 | X6: =IF(NOT(ISNUMBER($H$3)),"",IF(11<=MIN($H$3,31),$B$3+10,"")) -> 46184 | Y6: =IF(NOT(ISNUMBER($H$3)),"",IF(12<=MIN($H$3,31),$B$3+11,"")) -> 46185 | Z6: =IF(NOT(ISNUMBER($H$3)),"",IF(12<=MIN($H$3,31),$B$3+11,"")) -> 46185 | AA6: =IF(NOT(ISNUMBER($H$3)),"",IF(13<=MIN($H$3,31),$B$3+12,"")) -> 46186 | AB6: =IF(NOT(ISNUMBER($H$3)),"",IF(13<=MIN($H$3,31),$B$3+12,"")) -> 46186 | AC6: =IF(NOT(ISNUMBER($H$3)),"",IF(14<=MIN($H$3,31),$B$3+13,"")) -> 46187 | AD6: =IF(NOT(ISNUMBER($H$3)),"",IF(14<=MIN($H$3,31),$B$3+13,"")) -> 46187 | AE6: =IF(NOT(ISNUMBER($H$3)),"",IF(15<=MIN($H$3,31),$B$3+14,"")) -> 46188 | AF6: =IF(NOT(ISNUMBER($H$3)),"",IF(15<=MIN($H$3,31),$B$3+14,"")) -> 46188 | AG6: =IF(NOT(ISNUMBER($H$3)),"",IF(16<=MIN($H$3,31),$B$3+15,"")) -> 46189 | AH6: =IF(NOT(ISNUMBER($H$3)),"",IF(16<=MIN($H$3,31),$B$3+15,"")) -> 46189 | AI6: =IF(NOT(ISNUMBER($H$3)),"",IF(17<=MIN($H$3,31),$B$3+16,"")) -> 46190 | AJ6: =IF(NOT(ISNUMBER($H$3)),"",IF(17<=MIN($H$3,31),$B$3+16,"")) -> 46190 | AK6: =IF(NOT(ISNUMBER($H$3)),"",IF(18<=MIN($H$3,31),$B$3+17,"")) -> 46191 | AL6: =IF(NOT(ISNUMBER($H$3)),"",IF(18<=MIN($H$3,31),$B$3+17,"")) -> 46191 | AM6: =IF(NOT(ISNUMBER($H$3)),"",IF(19<=MIN($H$3,31),$B$3+18,"")) -> 46192 | AN6: =IF(NOT(ISNUMBER($H$3)),"",IF(19<=MIN($H$3,31),$B$3+18,"")) -> 46192 | AO6: =IF(NOT(ISNUMBER($H$3)),"",IF(20<=MIN($H$3,31),$B$3+19,"")) -> 46193 | AP6: =IF(NOT(ISNUMBER($H$3)),"",IF(20<=MIN($H$3,31),$B$3+19,"")) -> 46193 | AQ6: =IF(NOT(ISNUMBER($H$3)),"",IF(21<=MIN($H$3,31),$B$3+20,"")) -> 46194 | AR6: =IF(NOT(ISNUMBER($H$3)),"",IF(21<=MIN($H$3,31),$B$3+20,"")) -> 46194 | AS6: =IF(NOT(ISNUMBER($H$3)),"",IF(22<=MIN($H$3,31),$B$3+21,"")) -> 46195 | AT6: =IF(NOT(ISNUMBER($H$3)),"",IF(22<=MIN($H$3,31),$B$3+21,"")) -> 46195 | AU6: =IF(NOT(ISNUMBER($H$3)),"",IF(23<=MIN($H$3,31),$B$3+22,"")) -> 46196 | AV6: =IF(NOT(ISNUMBER($H$3)),"",IF(23<=MIN($H$3,31),$B$3+22,"")) -> 46196 | AW6: =IF(NOT(ISNUMBER($H$3)),"",IF(24<=MIN($H$3,31),$B$3+23,"")) -> 46197 | AX6: =IF(NOT(ISNUMBER($H$3)),"",IF(24<=MIN($H$3,31),$B$3+23,"")) -> 46197 | AY6: =IF(NOT(ISNUMBER($H$3)),"",IF(25<=MIN($H$3,31),$B$3+24,"")) -> 46198 | AZ6: =IF(NOT(ISNUMBER($H$3)),"",IF(25<=MIN($H$3,31),$B$3+24,"")) -> 46198 | BA6: =IF(NOT(ISNUMBER($H$3)),"",IF(26<=MIN($H$3,31),$B$3+25,"")) -> 46199 | BB6: =IF(NOT(ISNUMBER($H$3)),"",IF(26<=MIN($H$3,31),$B$3+25,"")) -> 46199 | BC6: =IF(NOT(ISNUMBER($H$3)),"",IF(27<=MIN($H$3,31),$B$3+26,"")) -> 46200 | BD6: =IF(NOT(ISNUMBER($H$3)),"",IF(27<=MIN($H$3,31),$B$3+26,"")) -> 46200 | BE6: =IF(NOT(ISNUMBER($H$3)),"",IF(28<=MIN($H$3,31),$B$3+27,"")) -> 46201 | BF6: =IF(NOT(ISNUMBER($H$3)),"",IF(28<=MIN($H$3,31),$B$3+27,"")) -> 46201 | BG6: =IF(NOT(ISNUMBER($H$3)),"",IF(29<=MIN($H$3,31),$B$3+28,"")) -> 46202 | BH6: =IF(NOT(ISNUMBER($H$3)),"",IF(29<=MIN($H$3,31),$B$3+28,"")) -> 46202 | BI6: =IF(NOT(ISNUMBER($H$3)),"",IF(30<=MIN($H$3,31),$B$3+29,"")) -> 46203 | BJ6: =IF(NOT(ISNUMBER($H$3)),"",IF(30<=MIN($H$3,31),$B$3+29,"")) -> 46203 | BK6: =IF(NOT(ISNUMBER($H$3)),"",IF(31<=MIN($H$3,31),$B$3+30,"")) | BL6: =IF(NOT(ISNUMBER($H$3)),"",IF(31<=MIN($H$3,31),$B$3+30,""))
A7: 账户 | B7: 期初余额 | C7: =IF(C$6="","","收款") -> 收款 | D7: =IF(D$6="","","付款") -> 付款 | E7: =IF(E$6="","","收款") -> 收款 | F7: =IF(F$6="","","付款") -> 付款 | G7: =IF(G$6="","","收款") -> 收款 | H7: =IF(H$6="","","付款") -> 付款 | I7: =IF(I$6="","","收款") -> 收款 | J7: =IF(J$6="","","付款") -> 付款 | K7: =IF(K$6="","","收款") -> 收款 | L7: =IF(L$6="","","付款") -> 付款 | M7: =IF(M$6="","","收款") -> 收款 | N7: =IF(N$6="","","付款") -> 付款 | O7: =IF(O$6="","","收款") -> 收款 | P7: =IF(P$6="","","付款") -> 付款 | Q7: =IF(Q$6="","","收款") -> 收款 | R7: =IF(R$6="","","付款") -> 付款 | S7: =IF(S$6="","","收款") -> 收款 | T7: =IF(T$6="","","付款") -> 付款 | U7: =IF(U$6="","","收款") -> 收款 | V7: =IF(V$6="","","付款") -> 付款 | W7: =IF(W$6="","","收款") -> 收款 | X7: =IF(X$6="","","付款") -> 付款 | Y7: =IF(Y$6="","","收款") -> 收款 | Z7: =IF(Z$6="","","付款") -> 付款 | AA7: =IF(AA$6="","","收款") -> 收款 | AB7: =IF(AB$6="","","付款") -> 付款 | AC7: =IF(AC$6="","","收款") -> 收款 | AD7: =IF(AD$6="","","付款") -> 付款 | AE7: =IF(AE$6="","","收款") -> 收款 | AF7: =IF(AF$6="","","付款") -> 付款 | AG7: =IF(AG$6="","","收款") -> 收款 | AH7: =IF(AH$6="","","付款") -> 付款 | AI7: =IF(AI$6="","","收款") -> 收款 | AJ7: =IF(AJ$6="","","付款") -> 付款 | AK7: =IF(AK$6="","","收款") -> 收款 | AL7: =IF(AL$6="","","付款") -> 付款 | AM7: =IF(AM$6="","","收款") -> 收款 | AN7: =IF(AN$6="","","付款") -> 付款 | AO7: =IF(AO$6="","","收款") -> 收款 | AP7: =IF(AP$6="","","付款") -> 付款 | AQ7: =IF(AQ$6="","","收款") -> 收款 | AR7: =IF(AR$6="","","付款") -> 付款 | AS7: =IF(AS$6="","","收款") -> 收款 | AT7: =IF(AT$6="","","付款") -> 付款 | AU7: =IF(AU$6="","","收款") -> 收款 | AV7: =IF(AV$6="","","付款") -> 付款 | AW7: =IF(AW$6="","","收款") -> 收款 | AX7: =IF(AX$6="","","付款") -> 付款 | AY7: =IF(AY$6="","","收款") -> 收款 | AZ7: =IF(AZ$6="","","付款") -> 付款 | BA7: =IF(BA$6="","","收款") -> 收款 | BB7: =IF(BB$6="","","付款") -> 付款 | BC7: =IF(BC$6="","","收款") -> 收款 | BD7: =IF(BD$6="","","付款") -> 付款 | BE7: =IF(BE$6="","","收款") -> 收款 | BF7: =IF(BF$6="","","付款") -> 付款 | BG7: =IF(BG$6="","","收款") -> 收款 | BH7: =IF(BH$6="","","付款") -> 付款 | BI7: =IF(BI$6="","","收款") -> 收款 | BJ7: =IF(BJ$6="","","付款") -> 付款 | BK7: =IF(BK$6="","","收款") | BL7: =IF(BL$6="","","付款") | BM7: 期间收款 | BN7: 期间付款 | BO7: 期末余额
A8: =IF(基础资料!$B$5="","",基础资料!$B$5) -> 现金 | B8: =IF(OR($A8="",NOT(ISNUMBER($H$3))),"",ROUND(SUMIF(账户表,$A8,账户期初)+SUMIFS(流水收入,流水账户,$A8,流水日期,"<"&$B$3)-SUMIFS(流水支出,流水账户,$A8,流水日期,"<"&$B$3),2)) -> 5000 | C8: =IF(OR($A8="",C$6=""),"",ROUND(SUMIFS(流水收入,流水账户,$A8,流水日期,C$6),2)) -> 0 | D8: =IF(OR($A8="",D$6=""),"",ROUND(SUMIFS(流水支出,流水账户,$A8,流水日期,D$6),2)) -> 0 | E8: =IF(OR($A8="",E$6=""),"",ROUND(SUMIFS(流水收入,流水账户,$A8,流水日期,E$6),2)) -> 2000 | F8: =IF(OR($A8="",F$6=""),"",ROUND(SUMIFS(流水支出,流水账户,$A8,流水日期,F$6),2)) -> 0 | G8: =IF(OR($A8="",G$6=""),"",ROUND(SUMIFS(流水收入,流水账户,$A8,流水日期,G$6),2)) -> 0 | H8: =IF(OR($A8="",H$6=""),"",ROUND(SUMIFS(流水支出,流水账户,$A8,流水日期,H$6),2)) -> 0 | I8: =IF(OR($A8="",I$6=""),"",ROUND(SUMIFS(流水收入,流水账户,$A8,流水日期,I$6),2)) -> 0 | J8: =IF(OR($A8="",J$6=""),"",ROUND(SUMIFS(流水支出,流水账户,$A8,流水日期,J$6),2)) -> 0 | K8: =IF(OR($A8="",K$6=""),"",ROUND(SUMIFS(流水收入,流水账户,$A8,流水日期,K$6),2)) -> 0 | L8: =IF(OR($A8="",L$6=""),"",ROUND(SUMIFS(流水支出,流水账户,$A8,流水日期,L$6),2)) -> 0 | M8: =IF(OR($A8="",M$6=""),"",ROUND(SUMIFS(流水收入,流水账户,$A8,流水日期,M$6),2)) -> 0 | N8: =IF(OR($A8="",N$6=""),"",ROUND(SUMIFS(流水支出,流水账户,$A8,流水日期,N$6),2)) -> 0 | O8: =IF(OR($A8="",O$6=""),"",ROUND(SUMIFS(流水收入,流水账户,$A8,流水日期,O$6),2)) -> 0 | P8: =IF(OR($A8="",P$6=""),"",ROUND(SUMIFS(流水支出,流水账户,$A8,流水日期,P$6),2)) -> 0 | Q8: =IF(OR($A8="",Q$6=""),"",ROUND(SUMIFS(流水收入,流水账户,$A8,流水日期,Q$6),2)) -> 0 | R8: =IF(OR($A8="",R$6=""),"",ROUND(SUMIFS(流水支出,流水账户,$A8,流水日期,R$6),2)) -> 0 | S8: =IF(OR($A8="",S$6=""),"",ROUND(SUMIFS(流水收入,流水账户,$A8,流水日期,S$6),2)) -> 0 | T8: =IF(OR($A8="",T$6=""),"",ROUND(SUMIFS(流水支出,流水账户,$A8,流水日期,T$6),2)) -> 0 | U8: =IF(OR($A8="",U$6=""),"",ROUND(SUMIFS(流水收入,流水账户,$A8,流水日期,U$6),2)) -> 0 | V8: =IF(OR($A8="",V$6=""),"",ROUND(SUMIFS(流水支出,流水账户,$A8,流水日期,V$6),2)) -> 0 | W8: =IF(OR($A8="",W$6=""),"",ROUND(SUMIFS(流水收入,流水账户,$A8,流水日期,W$6),2)) -> 0 | X8: =IF(OR($A8="",X$6=""),"",ROUND(SUMIFS(流水支出,流水账户,$A8,流水日期,X$6),2)) -> 0 | Y8: =IF(OR($A8="",Y$6=""),"",ROUND(SUMIFS(流水收入,流水账户,$A8,流水日期,Y$6),2)) -> 0 | Z8: =IF(OR($A8="",Z$6=""),"",ROUND(SUMIFS(流水支出,流水账户,$A8,流水日期,Z$6),2)) -> 0 | AA8: =IF(OR($A8="",AA$6=""),"",ROUND(SUMIFS(流水收入,流水账户,$A8,流水日期,AA$6),2)) -> 0 | AB8: =IF(OR($A8="",AB$6=""),"",ROUND(SUMIFS(流水支出,流水账户,$A8,流水日期,AB$6),2)) -> 0 | AC8: =IF(OR($A8="",AC$6=""),"",ROUND(SUMIFS(流水收入,流水账户,$A8,流水日期,AC$6),2)) -> 0 | AD8: =IF(OR($A8="",AD$6=""),"",ROUND(SUMIFS(流水支出,流水账户,$A8,流水日期,AD$6),2)) -> 0 | AE8: =IF(OR($A8="",AE$6=""),"",ROUND(SUMIFS(流水收入,流水账户,$A8,流水日期,AE$6),2)) -> 0 | AF8: =IF(OR($A8="",AF$6=""),"",ROUND(SUMIFS(流水支出,流水账户,$A8,流水日期,AF$6),2)) -> 0 | AG8: =IF(OR($A8="",AG$6=""),"",ROUND(SUMIFS(流水收入,流水账户,$A8,流水日期,AG$6),2)) -> 0 | AH8: =IF(OR($A8="",AH$6=""),"",ROUND(SUMIFS(流水支出,流水账户,$A8,流水日期,AH$6),2)) -> 0 | AI8: =IF(OR($A8="",AI$6=""),"",ROUND(SUMIFS(流水收入,流水账户,$A8,流水日期,AI$6),2)) -> 0 | AJ8: =IF(OR($A8="",AJ$6=""),"",ROUND(SUMIFS(流水支出,流水账户,$A8,流水日期,AJ$6),2)) -> 0 | AK8: =IF(OR($A8="",AK$6=""),"",ROUND(SUMIFS(流水收入,流水账户,$A8,流水日期,AK$6),2)) -> 0 | AL8: =IF(OR($A8="",AL$6=""),"",ROUND(SUMIFS(流水支出,流水账户,$A8,流水日期,AL$6),2)) -> 0 | AM8: =IF(OR($A8="",AM$6=""),"",ROUND(SUMIFS(流水收入,流水账户,$A8,流水日期,AM$6),2)) -> 0 | AN8: =IF(OR($A8="",AN$6=""),"",ROUND(SUMIFS(流水支出,流水账户,$A8,流水日期,AN$6),2)) -> 0 | AO8: =IF(OR($A8="",AO$6=""),"",ROUND(SUMIFS(流水收入,流水账户,$A8,流水日期,AO$6),2)) -> 0 | AP8: =IF(OR($A8="",AP$6=""),"",ROUND(SUMIFS(流水支出,流水账户,$A8,流水日期,AP$6),2)) -> 0 | AQ8: =IF(OR($A8="",AQ$6=""),"",ROUND(SUMIFS(流水收入,流水账户,$A8,流水日期,AQ$6),2)) -> 0 | AR8: =IF(OR($A8="",AR$6=""),"",ROUND(SUMIFS(流水支出,流水账户,$A8,流水日期,AR$6),2)) -> 0 | AS8: =IF(OR($A8="",AS$6=""),"",ROUND(SUMIFS(流水收入,流水账户,$A8,流水日期,AS$6),2)) -> 0 | AT8: =IF(OR($A8="",AT$6=""),"",ROUND(SUMIFS(流水支出,流水账户,$A8,流水日期,AT$6),2)) -> 0 | AU8: =IF(OR($A8="",AU$6=""),"",ROUND(SUMIFS(流水收入,流水账户,$A8,流水日期,AU$6),2)) -> 0 | AV8: =IF(OR($A8="",AV$6=""),"",ROUND(SUMIFS(流水支出,流水账户,$A8,流水日期,AV$6),2)) -> 0 | AW8: =IF(OR($A8="",AW$6=""),"",ROUND(SUMIFS(流水收入,流水账户,$A8,流水日期,AW$6),2)) -> 0 | AX8: =IF(OR($A8="",AX$6=""),"",ROUND(SUMIFS(流水支出,流水账户,$A8,流水日期,AX$6),2)) -> 0 | AY8: =IF(OR($A8="",AY$6=""),"",ROUND(SUMIFS(流水收入,流水账户,$A8,流水日期,AY$6),2)) -> 0 | AZ8: =IF(OR($A8="",AZ$6=""),"",ROUND(SUMIFS(流水支出,流水账户,$A8,流水日期,AZ$6),2)) -> 200 | BA8: =IF(OR($A8="",BA$6=""),"",ROUND(SUMIFS(流水收入,流水账户,$A8,流水日期,BA$6),2)) -> 0 | BB8: =IF(OR($A8="",BB$6=""),"",ROUND(SUMIFS(流水支出,流水账户,$A8,流水日期,BB$6),2)) -> 0 | BC8: =IF(OR($A8="",BC$6=""),"",ROUND(SUMIFS(流水收入,流水账户,$A8,流水日期,BC$6),2)) -> 0 | BD8: =IF(OR($A8="",BD$6=""),"",ROUND(SUMIFS(流水支出,流水账户,$A8,流水日期,BD$6),2)) -> 0 | BE8: =IF(OR($A8="",BE$6=""),"",ROUND(SUMIFS(流水收入,流水账户,$A8,流水日期,BE$6),2)) -> 0 | BF8: =IF(OR($A8="",BF$6=""),"",ROUND(SUMIFS(流水支出,流水账户,$A8,流水日期,BF$6),2)) -> 0 | BG8: =IF(OR($A8="",BG$6=""),"",ROUND(SUMIFS(流水收入,流水账户,$A8,流水日期,BG$6),2)) -> 0 | BH8: =IF(OR($A8="",BH$6=""),"",ROUND(SUMIFS(流水支出,流水账户,$A8,流水日期,BH$6),2)) -> 0 | BI8: =IF(OR($A8="",BI$6=""),"",ROUND(SUMIFS(流水收入,流水账户,$A8,流水日期,BI$6),2)) -> 2000 | BJ8: =IF(OR($A8="",BJ$6=""),"",ROUND(SUMIFS(流水支出,流水账户,$A8,流水日期,BJ$6),2)) -> 0 | BK8: =IF(OR($A8="",BK$6=""),"",ROUND(SUMIFS(流水收入,流水账户,$A8,流水日期,BK$6),2)) | BL8: =IF(OR($A8="",BL$6=""),"",ROUND(SUMIFS(流水支出,流水账户,$A8,流水日期,BL$6),2)) | BM8: =IF($A8="","",ROUND(SUMIF($C$7:$BL$7,"收款",C8:BL8),2)) -> 4000 | BN8: =IF($A8="","",ROUND(SUMIF($C$7:$BL$7,"付款",C8:BL8),2)) -> 200 | BO8: =IF($A8="","",ROUND(N($B8)+N(BM8)-N(BN8),2)) -> 8800
