Workbook
Name 本位币: 参数设置!$B$4
Name 管理年度: 参数设置!$B$5
Name 报表月份: 参数设置!$B$6
Name 重估基准日: 参数设置!$B$7
Name 账户银行: 参数设置!$B$11:$B$40
Name 账户名: 参数设置!$C$11:$C$40
Name 账户币种: 参数设置!$E$11:$E$40
Name 账户期初: 参数设置!$G$11:$G$40
Name 账户期初本位: 参数设置!$I$11:$I$40
Name 币种表: 参数设置!$L$11:$L$18
Name 类别表: 参数设置!$O$11:$O$40
Name 类别属性: 参数设置!$P$11:$P$40
Name 项目表: 参数设置!$R$11:$R$50
Name 单位表: 参数设置!$T$11:$T$210
Name 汇率月份: 月度汇率!$A$6:$A$17
Name 记账汇率区: 月度汇率!$B$6:$I$17
Name 汇率币种头: 月度汇率!$B$5:$I$5
Name 月末汇率区: 月度汇率!$K$6:$R$17
Name 流水日期: 流水录入!$A$6:$A$2005
Name 流水账户: 流水录入!$B$6:$B$2005
Name 流水币种: 流水录入!$D$6:$D$2005
Name 流水类别: 流水录入!$E$6:$E$2005
Name 流水属性: 流水录入!$F$6:$F$2005
Name 流水收入: 流水录入!$G$6:$G$2005
Name 流水支出: 流水录入!$H$6:$H$2005
Name 流水净额: 流水录入!$K$6:$K$2005
Name 流水本位: 流水录入!$L$6:$L$2005
Name 流水项目: 流水录入!$P$6:$P$2005
Name 流水单位: 流水录入!$Q$6:$Q$2005
Name 资金总额本位: 账户余额表!$J$36
Name 月报收入合计: 月度汇报表!$B$18
Name 月报支出合计: 月度汇报表!$C$18
Name 分类收入合计: 收支分类报表!$O$5
Name 分类支出合计: 收支分类报表!$O$6
Name 汇率填写数: 月度汇率!$T$6:$T$17
Name 外币流水数: 月度汇率!$U$6:$U$17
Name 汇率列计数: 月度汇率!$B$18:$I$18
Name 流水核对: 流水录入!$S$6:$S$2005
Name 档案核对: 参数设置!$J$11:$J$40

Sheet 使用说明
A1: 外汇资金台账 · 使用说明（本位币：人民币）
A3: 一、三步就能用起来
A4: 第 1 步 | B4: 【参数设置】 | C4: 把账户档案改成你们真实的账户：银行、账户名称（唯一）、币种、期初余额。外币账户把「期初汇率」也填上 —— 那是这笔期初余额当初入账的汇率。
A5: 第 2 步 | B5: 【月度汇率】 | C5: 每月填一次当月记账汇率。只填你们在用的币种（美元、港币、欧元）就行。
A6: 第 3 步 | B6: 【流水录入】 | C6: 每天在这一张录。选账户名称 → 银行、币种、汇率自动带出来；收入和支出分两列，只填一个。其余所有表全自动。
A8: 二、表都干什么用
A9: 表名 | B9: 谁用 | C9: 干什么
A10: 参数设置 | B10: 管理员 | C10: 账户档案、币种、收支类别、项目、往来单位。这一页改了，后面全部跟着变。
A11: 月度汇率 | B11: 财务 | C11: 每月一行。左边记账汇率（流水折人民币用），右边月末汇率（月末重估用，空着=用左边）。
A12: 流水录入 | B12: 出纳 | C12: ★ 全套表唯一要填的一张。最后一列「核对」会自己挑毛病。
A13: 银行子表（每账户一张） | B13: 看 | C13: 自动从流水拆出来，不用填。表头 B2 是拆分依据。
A14: 账户余额表 | B14: 财务 | C14: 每账户一行：期末原币、期末人民币、账面成本、汇兑损益；下面还有按币种小计。
A15: 月度汇报表 | B15: 老板 | C15: 按月的人民币收入/支出/净流入/月末资金总额；下半张是报表月份的各账户明细。
A16: 收支分类报表 | B16: 老板 | C16: 收支类别 × 12 个月，人民币。支出显示成正数，好读。
A17: 资金日报表 | B17: 出纳/老板 | C17: 上半张按日走势（最多 31 天），下半张是某一天的出纳日报。
A18: 区间查询 | B18: 财务 | C18: 任意起止日期 → 按类别、按项目、按币种、按往来单位四块。
A19: 核对表 | B19: 所有人 | C19: 录完看这一张就够了。勾稽必须全 0，待办是数据没填齐。
A21: 三、汇率是怎么取的（这是外汇台账的核心）
A22: 优先级 1 | B22: 实际成交汇率 | C22: 流水里填了「实际成交汇率」就用它。购汇、结汇、银行有实际成交价的都填这个。
A23: 优先级 2 | B23: 当月记账汇率 | C23: 按交易日期所在的月份，去【月度汇率】取。
A24: 优先级 3 | B24: 往前最近一个月 | C24: 当月还没填？自动往前找最近一个填过的月份
A26: 四、两套人民币口径，各算各的，千万别混着加
A27: 账面人民币成本 | B27: 历史成本 | C27: ＝期初人民币成本 + 每一笔原币 × 该笔当时的汇率。钱进来时值多少就是多少，以后汇率怎么变都不动它。
A28: 期末人民币(重估) | B28: 现在值多少 | C28: ＝期末原币余额 × 期末汇率。
A29: 汇兑损益 | B29: 两者之差 | C29: ＝重估 − 账面成本。外币放着不动，汇率涨了就是赚、跌了就是亏，这一栏就是那个数。
A31: 五、内部转账不算收入也不算支出
A32: 怎么录 | B32: 两头都录 | C32: 转出账户记一笔支出，转入账户记一笔收入，类别都选「内部转账」。购汇结汇选「购汇/结汇」，也是内部转账属性。
A33: 报表里怎么处理 | B33: 单列，不进合计 | C33: 月度汇报表单列「内部转入 / 内部转出」两列；分类报表单列一行「内部转账净额」。收入合计、支出合计里都不含它。
A34: 净额不是 0 怎么办 | B34: 那是换汇价差 | C34: 同币种之间调头寸净额应该是 0。购汇结汇跨币种，净额就是买卖价差，正常。
A36: 六、加东西怎么加
A37: 加一个账户 | B37: 两步 | C37: ① 在【参数设置】账户档案接着写一行；② 右键复制任意一张银行子表，改表名，把 B2 改成新账户名
A38: 加一个币种 | B38: 一步 | C38: 在【参数设置】币种清单加一行，再去【月度汇率】填它的汇率。（汇率表预留了 8 个币种的列）
A39: 加类别 / 项目 / 往来单位 | B39: 一步 | C39: 在【参数设置】对应清单接着写，所有报表自动跟着长。注意别写重复
A40: 预留行数 | C40: 流水预留 2000 行、账户 30 个。
A42: 七、颜色和符号
A43: 淡黄色格子 | B43: 要你填 | C43: 这是人工输入区。
A44: 灰色格子 | B44: 公式自动算 | C44: 别手动改，改了就把公式顶掉了。
A45: ※ 红字 | B45: 是错，必须改 | C45: 账户不在档案、收支同时填、类别不在清单……
A46: △ 琥珀字 | B46: 待补的数据 | C46: 汇率没填、内部转账没写对方账户……不影响公式，补齐了数才准。
A48: 八、示例数据
...

Sheet 参数设置
A1: 参数设置 · 账户、币种、类别、项目都在这里维护
A2: 淡黄色格子是要你填的，灰色是公式算的。账户名称必须唯一，建议写成「银行 + 用途 + 账号尾号」。这一页改了，后面所有表跟着变。
A4: 本位币 | B4: CNY | C4: 所有汇报表都折算成它。改成别的币种，整套跟着走。
A5: 管理年度 | B5: 2026 | C5: 【月度汇率】和各张年报按这个年度展开。
A6: 报表月份 | B6: 46235 | C6: 汇报表默认看哪个月。填该月 1 号。
A7: 期末重估基准日 | B7: =IF($B$6="","",EOMONTH($B$6,0)) -> 46265 | C7: 自动 = 报表月份的月末。外币余额按这一天的汇率重估。
A9: 一、账户档案 —— 加一个账户：在这里接着写一行，再复制一张银行子表改 B2 | L9: 二、币种 | O9: 三、收支类别（属性=内部转账的，不计入收入/支出合计） | R9: 四、项目 | T9: 五、往来单位
A10: 序号 | B10: 银行 ★ | C10: 账户名称 ★（唯一） | D10: 账号（可不填） | E10: 币种 ★ | F10: 账户类型 | G10: 期初余额(原币) | H10: 期初汇率 | I10: 期初人民币成本 | J10: 核对 | L10: 币种代码 | M10: 币种名称 | O10: 收/支类别 | P10: 属性 ★ | R10: 项目 / 业务 | T10: 往来单位
A11: =IF($C11="","",COUNTA($C$11:$C11)) -> 1 | B11: 工商银行 | C11: 工商银行基本户-8888 | D11: 1202...8888 | E11: CNY | F11: 基本户 | G11: 500000 | I11: =IF($C11="","",IFERROR(ROUND(N($G11)*IF($H11<>"",$H11,IF($E11=本位币,1,IFERROR(LOOKUP(2,1/((汇率月份<=重估基准日)*(INDEX(月末汇率区,0,MATCH($E11,汇率币种头,0))<>"")),INDEX(月末汇率区,0,MATCH($E11,汇率币种头,0))),IFERROR(LOOKUP(2,1/((汇率月份<=重估基准日)*(INDEX(记账汇率区,0,MATCH($E11,汇率币种头,0))<>"")),INDEX(记账汇率区,0,MATCH($E11,汇率币种头,0))),"")))),2),"")) -> 500000 | J11: =IF($C11="","",IF(COUNTIF($C$11:$C$40,$C11)>1,"※账户名称重复了，后面按名字取数会串",IF(AND($E11<>"",COUNTIF(币种表,$E11)=0),"※币种不在右边币种清单里",IF($G11="","※期初余额没填（没有就填 0）",IF(AND($E11<>本位币,$H11="",$I11=""),"△这个币种一个汇率都没填，期初人民币成本算不出来",IF(AND($E11<>本位币,$H11=""),"△没填期初汇率，先拿期末汇率折的","")))))) | L11: CNY | M11: 人民币 | O11: 销售回款 | P11: 收入 | R11: 项目A | T11: 华东客户A
A12: =IF($C12="","",COUNTA($C$11:$C12)) -> 2 | B12: 中国银行 | C12: 中国银行美元结算户-6688 | D12: 4567...6688 | E12: USD | F12: 外币结算户 | G12: 800000 | H12: 7.15 | I12: =IF($C12="","",IFERROR(ROUND(N($G12)*IF($H12<>"",$H12,IF($E12=本位币,1,IFERROR(LOOKUP(2,1/((汇率月份<=重估基准日)*(INDEX(月末汇率区,0,MATCH($E12,汇率币种头,0))<>"")),INDEX(月末汇率区,0,MATCH($E12,汇率币种头,0))),IFERROR(LOOKUP(2,1/((汇率月份<=重估基准日)*(INDEX(记账汇率区,0,MATCH($E12,汇率币种头,0))<>"")),INDEX(记账汇率区,0,MATCH($E12,汇率币种头,0))),"")))),2),"")) -> 5720000 | J12: =IF($C12="","",IF(COUNTIF($C$11:$C$40,$C12)>1,"※账户名称重复了，后面按名字取数会串",IF(AND($E12<>"",COUNTIF(币种表,$E12)=0),"※币种不在右边币种清单里",IF($G12="","※期初余额没填（没有就填 0）",IF(AND($E12<>本位币,$H12="",$I12=""),"△这个币种一个汇率都没填，期初人民币成本算不出来",IF(AND($E12<>本位币,$H12=""),"△没填期初汇率，先拿期末汇率折的","")))))) | L12: USD | M12: 美元 | O12: 其他业务收入 | P12: 收入 | R12: 出口业务 | T12: Overseas Client A
A13: =IF($C13="","",COUNTA($C$11:$C13)) -> 3 | B13: 汇丰银行 | C13: 汇丰银行港币结算户-5566 | D13: 0048...5566 | E13: HKD | F13: 外币结算户 | G13: 300000 | H13: 0.915 | I13: =IF($C13="","",IFERROR(ROUND(N($G13)*IF($H13<>"",$H13,IF($E13=本位币,1,IFERROR(LOOKUP(2,1/((汇率月份<=重估基准日)*(INDEX(月末汇率区,0,MATCH($E13,汇率币种头,0))<>"")),INDEX(月末汇率区,0,MATCH($E13,汇率币种头,0))),IFERROR(LOOKUP(2,1/((汇率月份<=重估基准日)*(INDEX(记账汇率区,0,MATCH($E13,汇率币种头,0))<>"")),INDEX(记账汇率区,0,MATCH($E13,汇率币种头,0))),"")))),2),"")) -> 274500 | J13: =IF($C13="","",IF(COUNTIF($C$11:$C$40,$C13)>1,"※账户名称重复了，后面按名字取数会串",IF(AND($E13<>"",COUNTIF(币种表,$E13)=0),"※币种不在右边币种清单里",IF($G13="","※期初余额没填（没有就填 0）",IF(AND($E13<>本位币,$H13="",$I13=""),"△这个币种一个汇率都没填，期初人民币成本算不出来",IF(AND($E13<>本位币,$H13=""),"△没填期初汇率，先拿期末汇率折的","")))))) | L13: HKD | M13: 港币 | O13: 投资款 | P13: 收入 | R13: 进口业务 | T13: Overseas Client C
A14: =IF($C14="","",COUNTA($C$11:$C14)) -> 4 | B14: 招商银行 | C14: 招商银行一般户-2388 | D14: 7712...2388 | E14: CNY | F14: 一般户 | G14: 200000 | I14: =IF($C14="","",IFERROR(ROUND(N($G14)*IF($H14<>"",$H14,IF($E14=本位币,1,IFERROR(LOOKUP(2,1/((汇率月份<=重估基准日)*(INDEX(月末汇率区,0,MATCH($E14,汇率币种头,0))<>"")),INDEX(月末汇率区,0,MATCH($E14,汇率币种头,0))),IFERROR(LOOKUP(2,1/((汇率月份<=重估基准日)*(INDEX(记账汇率区,0,MATCH($E14,汇率币种头,0))<>"")),INDEX(记账汇率区,0,MATCH($E14,汇率币种头,0))),"")))),2),"")) -> 200000 | J14: =IF($C14="","",IF(COUNTIF($C$11:$C$40,$C14)>1,"※账户名称重复了，后面按名字取数会串",IF(AND($E14<>"",COUNTIF(币种表,$E14)=0),"※币种不在右边币种清单里",IF($G14="","※期初余额没填（没有就填 0）",IF(AND($E14<>本位币,$H14="",$I14=""),"△这个币种一个汇率都没填，期初人民币成本算不出来",IF(AND($E14<>本位币,$H14=""),"△没填期初汇率，先拿期末汇率折的","")))))) | L14: EUR | M14: 欧元 | O14: 借款 | P14: 收入 | R14: 香港业务 | T14: 香港客户B
A15: =IF($C15="","",COUNTA($C$11:$C15)) -> 5 | B15: 汇丰银行 | C15: 汇丰银行美元结算户-7788 | D15: 0048...7788 | E15: USD | F15: 外币结算户 | G15: 500000 | H15: 7.15 | I15: =IF($C15="","",IFERROR(ROUND(N($G15)*IF($H15<>"",$H15,IF($E15=本位币,1,IFERROR(LOOKUP(2,1/((汇率月份<=重估基准日)*(INDEX(月末汇率区,0,MATCH($E15,汇率币种头,0))<>"")),INDEX(月末汇率区,0,MATCH($E15,汇率币种头,0))),IFERROR(LOOKUP(2,1/((汇率月份<=重估基准日)*(INDEX(记账汇率区,0,MATCH($E15,汇率币种头,0))<>"")),INDEX(记账汇率区,0,MATCH($E15,汇率币种头,0))),"")))),2),"")) -> 3575000 | J15: =IF($C15="","",IF(COUNTIF($C$11:$C$40,$C15)>1,"※账户名称重复了，后面按名字取数会串",IF(AND($E15<>"",COUNTIF(币种表,$E15)=0),"※币种不在右边币种清单里",IF($G15="","※期初余额没填（没有就填 0）",IF(AND($E15<>本位币,$H15="",$I15=""),"△这个币种一个汇率都没填，期初人民币成本算不出来",IF(AND($E15<>本位币,$H15=""),"△没填期初汇率，先拿期末汇率折的","")))))) | L15: JPY | M15: 日元 | O15: 利息收入 | P15: 收入 | R15: 欧洲业务 | T15: 欧洲客户D
A16: =IF($C16="","",COUNTA($C$11:$C16)) -> 6 | B16: 中国银行 | C16: 中国银行欧元结算户-9900 | D16: 4567...9900 | E16: EUR | F16: 外币结算户 | G16: 120000 | I16: =IF($C16="","",IFERROR(ROUND(N($G16)*IF($H16<>"",$H16,IF($E16=本位币,1,IFERROR(LOOKUP(2,1/((汇率月份<=重估基准日)*(INDEX(月末汇率区,0,MATCH($E16,汇率币种头,0))<>"")),INDEX(月末汇率区,0,MATCH($E16,汇率币种头,0))),IFERROR(LOOKUP(2,1/((汇率月份<=重估基准日)*(INDEX(记账汇率区,0,MATCH($E16,汇率币种头,0))<>"")),INDEX(记账汇率区,0,MATCH($E16,汇率币种头,0))),"")))),2),"")) -> 922800 | J16: =IF($C16="","",IF(COUNTIF($C$11:$C$40,$C16)>1,"※账户名称重复了，后面按名字取数会串",IF(AND($E16<>"",COUNTIF(币种表,$E16)=0),"※币种不在右边币种清单里",IF($G16="","※期初余额没填（没有就填 0）",IF(AND($E16<>本位币,$H16="",$I16=""),"△这个币种一个汇率都没填，期初人民币成本算不出来",IF(AND($E16<>本位币,$H16=""),"△没填期初汇率，先拿期末汇率折的","")))))) -> △没填期初汇率，先拿期末汇率折的 | L16: GBP | M16: 英镑 | O16: 退款收回 | P16: 收入 | R16: 融资 | T16: 香港供应商A
A17: =IF($C17="","",COUNTA($C$11:$C17)) | I17: =IF($C17="","",IFERROR(ROUND(N($G17)*IF($H17<>"",$H17,IF($E17=本位币,1,IFERROR(LOOKUP(2,1/((汇率月份<=重估基准日)*(INDEX(月末汇率区,0,MATCH($E17,汇率币种头,0))<>"")),INDEX(月末汇率区,0,MATCH($E17,汇率币种头,0))),IFERROR(LOOKUP(2,1/((汇率月份<=重估基准日)*(INDEX(记账汇率区,0,MATCH($E17,汇率币种头,0))<>"")),INDEX(记账汇率区,0,MATCH($E17,汇率币种头,0))),"")))),2),"")) | J17: =IF($C17="","",IF(COUNTIF($C$11:$C$40,$C17)>1,"※账户名称重复了，后面按名字取数会串",IF(AND($E17<>"",COUNTIF(币种表,$E17)=0),"※币种不在右边币种清单里",IF($G17="","※期初余额没填（没有就填 0）",IF(AND($E17<>本位币,$H17="",$I17=""),"△这个币种一个汇率都没填，期初人民币成本算不出来",IF(AND($E17<>本位币,$H17=""),"△没填期初汇率，先拿期末汇率折的","")))))) | L17: SGD | M17: 新加坡元 | O17: 采购付款 | P17: 支出 | R17: 行政 | T17: Overseas Supplier B
A18: =IF($C18="","",COUNTA($C$11:$C18)) | I18: =IF($C18="","",IFERROR(ROUND(N($G18)*IF($H18<>"",$H18,IF($E18=本位币,1,IFERROR(LOOKUP(2,1/((汇率月份<=重估基准日)*(INDEX(月末汇率区,0,MATCH($E18,汇率币种头,0))<>"")),INDEX(月末汇率区,0,MATCH($E18,汇率币种头,0))),IFERROR(LOOKUP(2,1/((汇率月份<=重估基准日)*(INDEX(记账汇率区,0,MATCH($E18,汇率币种头,0))<>"")),INDEX(记账汇率区,0,MATCH($E18,汇率币种头,0))),"")))),2),"")) | J18: =IF($C18="","",IF(COUNTIF($C$11:$C$40,$C18)>1,"※账户名称重复了，后面按名字取数会串",IF(AND($E18<>"",COUNTIF(币种表,$E18)=0),"※币种不在右边币种清单里",IF($G18="","※期初余额没填（没有就填 0）",IF(AND($E18<>本位币,$H18="",$I18=""),"△这个币种一个汇率都没填，期初人民币成本算不出来",IF(AND($E18<>本位币,$H18=""),"△没填期初汇率，先拿期末汇率折的","")))))) | L18: AUD | M18: 澳元 | O18: 工资 | P18: 支出 | R18: 税务 | T18: 欧洲供应商E
A19: =IF($C19="","",COUNTA($C$11:$C19)) | I19: =IF($C19="","",IFERROR(ROUND(N($G19)*IF($H19<>"",$H19,IF($E19=本位币,1,IFERROR(LOOKUP(2,1/((汇率月份<=重估基准日)*(INDEX(月末汇率区,0,MATCH($E19,汇率币种头,0))<>"")),INDEX(月末汇率区,0,MATCH($E19,汇率币种头,0))),IFERROR(LOOKUP(2,1/((汇率月份<=重估基准日)*(INDEX(记账汇率区,0,MATCH($E19,汇率币种头,0))<>"")),INDEX(记账汇率区,0,MATCH($E19,汇率币种头,0))),"")))),2),"")) | J19: =IF($C19="","",IF(COUNTIF($C$11:$C$40,$C19)>1,"※账户名称重复了，后面按名字取数会串",IF(AND($E19<>"",COUNTIF(币种表,$E19)=0),"※币种不在右边币种清单里",IF($G19="","※期初余额没填（没有就填 0）",IF(AND($E19<>本位币,$H19="",$I19=""),"△这个币种一个汇率都没填，期初人民币成本算不出来",IF(AND($E19<>本位币,$H19=""),"△没填期初汇率，先拿期末汇率折的","")))))) | O19: 运营费用 | P19: 支出 | R19: 海外服务 | T19: 员工薪酬
A20: =IF($C20="","",COUNTA($C$11:$C20)) | I20: =IF($C20="","",IFERROR(ROUND(N($G20)*IF($H20<>"",$H20,IF($E20=本位币,1,IFERROR(LOOKUP(2,1/((汇率月份<=重估基准日)*(INDEX(月末汇率区,0,MATCH($E20,汇率币种头,0))<>"")),INDEX(月末汇率区,0,MATCH($E20,汇率币种头,0))),IFERROR(LOOKUP(2,1/((汇率月份<=重估基准日)*(INDEX(记账汇率区,0,MATCH($E20,汇率币种头,0))<>"")),INDEX(记账汇率区,0,MATCH($E20,汇率币种头,0))),"")))),2),"")) | J20: =IF($C20="","",IF(COUNTIF($C$11:$C$40,$C20)>1,"※账户名称重复了，后面按名字取数会串",IF(AND($E20<>"",COUNTIF(币种表,$E20)=0),"※币种不在右边币种清单里",IF($G20="","※期初余额没填（没有就填 0）",IF(AND($E20<>本位币,$H20="",$I20=""),"△这个币种一个汇率都没填，期初人民币成本算不出来",IF(AND($E20<>本位币,$H20=""),"△没填期初汇率，先拿期末汇率折的","")))))) | O20: 税费 | P20: 支出 | R20: 内部调拨 | T20: 税务机关
A21: =IF($C21="","",COUNTA($C$11:$C21)) | I21: =IF($C21="","",IFERROR(ROUND(N($G21)*IF($H21<>"",$H21,IF($E21=本位币,1,IFERROR(LOOKUP(2,1/((汇率月份<=重估基准日)*(INDEX(月末汇率区,0,MATCH($E21,汇率币种头,0))<>"")),INDEX(月末汇率区,0,MATCH($E21,汇率币种头,0))),IFERROR(LOOKUP(2,1/((汇率月份<=重估基准日)*(INDEX(记账汇率区,0,MATCH($E21,汇率币种头,0))<>"")),INDEX(记账汇率区,0,MATCH($E21,汇率币种头,0))),"")))),2),"")) | J21: =IF($C21="","",IF(COUNTIF($C$11:$C$40,$C21)>1,"※账户名称重复了，后面按名字取数会串",IF(AND($E21<>"",COUNTIF(币种表,$E21)=0),"※币种不在右边币种清单里",IF($G21="","※期初余额没填（没有就填 0）",IF(AND($E21<>本位币,$H21="",$I21=""),"△这个币种一个汇率都没填，期初人民币成本算不出来",IF(AND($E21<>本位币,$H21=""),"△没填期初汇率，先拿期末汇率折的","")))))) | O21: 手续费 | P21: 支出 | R21: 其他业务 | T21: 银行借款
A22: =IF($C22="","",COUNTA($C$11:$C22)) | I22: =IF($C22="","",IFERROR(ROUND(N($G22)*IF($H22<>"",$H22,IF($E22=本位币,1,IFERROR(LOOKUP(2,1/((汇率月份<=重估基准日)*(INDEX(月末汇率区,0,MATCH($E22,汇率币种头,0))<>"")),INDEX(月末汇率区,0,MATCH($E22,汇率币种头,0))),IFERROR(LOOKUP(2,1/((汇率月份<=重估基准日)*(INDEX(记账汇率区,0,MATCH($E22,汇率币种头,0))<>"")),INDEX(记账汇率区,0,MATCH($E22,汇率币种头,0))),"")))),2),"")) | J22: =IF($C22="","",IF(COUNTIF($C$11:$C$40,$C22)>1,"※账户名称重复了，后面按名字取数会串",IF(AND($E22<>"",COUNTIF(币种表,$E22)=0),"※币种不在右边币种清单里",IF($G22="","※期初余额没填（没有就填 0）",IF(AND($E22<>本位币,$H22="",$I22=""),"△这个币种一个汇率都没填，期初人民币成本算不出来",IF(AND($E22<>本位币,$H22=""),"△没填期初汇率，先拿期末汇率折的","")))))) | O22: 利息支出 | P22: 支出 | T22: 股东A
A23: =IF($C23="","",COUNTA($C$11:$C23)) | I23: =IF($C23="","",IFERROR(ROUND(N($G23)*IF($H23<>"",$H23,IF($E23=本位币,1,IFERROR(LOOKUP(2,1/((汇率月份<=重估基准日)*(INDEX(月末汇率区,0,MATCH($E23,汇率币种头,0))<>"")),INDEX(月末汇率区,0,MATCH($E23,汇率币种头,0))),IFERROR(LOOKUP(2,1/((汇率月份<=重估基准日)*(INDEX(记账汇率区,0,MATCH($E23,汇率币种头,0))<>"")),INDEX(记账汇率区,0,MATCH($E23,汇率币种头,0))),"")))),2),"")) | J23: =IF($C23="","",IF(COUNTIF($C$11:$C$40,$C23)>1,"※账户名称重复了，后面按名字取数会串",IF(AND($E23<>"",COUNTIF(币种表,$E23)=0),"※币种不在右边币种清单里",IF($G23="","※期初余额没填（没有就填 0）",IF(AND($E23<>本位币,$H23="",$I23=""),"△这个币种一个汇率都没填，期初人民币成本算不出来",IF(AND($E23<>本位币,$H23=""),"△没填期初汇率，先拿期末汇率折的","")))))) | O23: 还款 | P23: 支出 | T23: Service Provider
A24: =IF($C24="","",COUNTA($C$11:$C24)) | I24: =IF($C24="","",IFERROR(ROUND(N($G24)*IF($H24<>"",$H24,IF($E24=本位币,1,IFERROR(LOOKUP(2,1/((汇率月份<=重估基准日)*(INDEX(月末汇率区,0,MATCH($E24,汇率币种头,0))<>"")),INDEX(月末汇率区,0,MATCH($E24,汇率币种头,0))),IFERROR(LOOKUP(2,1/((汇率月份<=重估基准日)*(INDEX(记账汇率区,0,MATCH($E24,汇率币种头,0))<>"")),INDEX(记账汇率区,0,MATCH($E24,汇率币种头,0))),"")))),2),"")) | J24: =IF($C24="","",IF(COUNTIF($C$11:$C$40,$C24)>1,"※账户名称重复了，后面按名字取数会串",IF(AND($E24<>"",COUNTIF(币种表,$E24)=0),"※币种不在右边币种清单里",IF($G24="","※期初余额没填（没有就填 0）",IF(AND($E24<>本位币,$H24="",$I24=""),"△这个币种一个汇率都没填，期初人民币成本算不出来",IF(AND($E24<>本位币,$H24=""),"△没填期初汇率，先拿期末汇率折的","")))))) | O24: 资产购买 | P24: 支出 | T24: 香港办公室
A25: =IF($C25="","",COUNTA($C$11:$C25)) | I25: =IF($C25="","",IFERROR(ROUND(N($G25)*IF($H25<>"",$H25,IF($E25=本位币,1,IFERROR(LOOKUP(2,1/((汇率月份<=重估基准日)*(INDEX(月末汇率区,0,MATCH($E25,汇率币种头,0))<>"")),INDEX(月末汇率区,0,MATCH($E25,汇率币种头,0))),IFERROR(LOOKUP(2,1/((汇率月份<=重估基准日)*(INDEX(记账汇率区,0,MATCH($E25,汇率币种头,0))<>"")),INDEX(记账汇率区,0,MATCH($E25,汇率币种头,0))),"")))),2),"")) | J25: =IF($C25="","",IF(COUNTIF($C$11:$C$40,$C25)>1,"※账户名称重复了，后面按名字取数会串",IF(AND($E25<>"",COUNTIF(币种表,$E25)=0),"※币种不在右边币种清单里",IF($G25="","※期初余额没填（没有就填 0）",IF(AND($E25<>本位币,$H25="",$I25=""),"△这个币种一个汇率都没填，期初人民币成本算不出来",IF(AND($E25<>本位币,$H25=""),"△没填期初汇率，先拿期末汇率折的","")))))) | O25: 股利分配 | P25: 支出 | T25: 其他客户
A26: =IF($C26="","",COUNTA($C$11:$C26)) | I26: =IF($C26="","",IFERROR(ROUND(N($G26)*IF($H26<>"",$H26,IF($E26=本位币,1,IFERROR(LOOKUP(2,1/((汇率月份<=重估基准日)*(INDEX(月末汇率区,0,MATCH($E26,汇率币种头,0))<>"")),INDEX(月末汇率区,0,MATCH($E26,汇率币种头,0))),IFERROR(LOOKUP(2,1/((汇率月份<=重估基准日)*(INDEX(记账汇率区,0,MATCH($E26,汇率币种头,0))<>"")),INDEX(记账汇率区,0,MATCH($E26,汇率币种头,0))),"")))),2),"")) | J26: =IF($C26="","",IF(COUNTIF($C$11:$C$40,$C26)>1,"※账户名称重复了，后面按名字取数会串",IF(AND($E26<>"",COUNTIF(币种表,$E26)=0),"※币种不在右边币种清单里",IF($G26="","※期初余额没填（没有就填 0）",IF(AND($E26<>本位币,$H26="",$I26=""),"△这个币种一个汇率都没填，期初人民币成本算不出来",IF(AND($E26<>本位币,$H26=""),"△没填期初汇率，先拿期末汇率折的","")))))) | O26: 内部转账 | P26: 内部转账
A27: =IF($C27="","",COUNTA($C$11:$C27)) | I27: =IF($C27="","",IFERROR(ROUND(N($G27)*IF($H27<>"",$H27,IF($E27=本位币,1,IFERROR(LOOKUP(2,1/((汇率月份<=重估基准日)*(INDEX(月末汇率区,0,MATCH($E27,汇率币种头,0))<>"")),INDEX(月末汇率区,0,MATCH($E27,汇率币种头,0))),IFERROR(LOOKUP(2,1/((汇率月份<=重估基准日)*(INDEX(记账汇率区,0,MATCH($E27,汇率币种头,0))<>"")),INDEX(记账汇率区,0,MATCH($E27,汇率币种头,0))),"")))),2),"")) | J27: =IF($C27="","",IF(COUNTIF($C$11:$C$40,$C27)>1,"※账户名称重复了，后面按名字取数会串",IF(AND($E27<>"",COUNTIF(币种表,$E27)=0),"※币种不在右边币种清单里",IF($G27="","※期初余额没填（没有就填 0）",IF(AND($E27<>本位币,$H27="",$I27=""),"△这个币种一个汇率都没填，期初人民币成本算不出来",IF(AND($E27<>本位币,$H27=""),"△没填期初汇率，先拿期末汇率折的","")))))) | O27: 购汇/结汇 | P27: 内部转账
A28: =IF($C28="","",COUNTA($C$11:$C28)) | I28: =IF($C28="","",IFERROR(ROUND(N($G28)*IF($H28<>"",$H28,IF($E28=本位币,1,IFERROR(LOOKUP(2,1/((汇率月份<=重估基准日)*(INDEX(月末汇率区,0,MATCH($E28,汇率币种头,0))<>"")),INDEX(月末汇率区,0,MATCH($E28,汇率币种头,0))),IFERROR(LOOKUP(2,1/((汇率月份<=重估基准日)*(INDEX(记账汇率区,0,MATCH($E28,汇率币种头,0))<>"")),INDEX(记账汇率区,0,MATCH($E28,汇率币种头,0))),"")))),2),"")) | J28: =IF($C28="","",IF(COUNTIF($C$11:$C$40,$C28)>1,"※账户名称重复了，后面按名字取数会串",IF(AND($E28<>"",COUNTIF(币种表,$E28)=0),"※币种不在右边币种清单里",IF($G28="","※期初余额没填（没有就填 0）",IF(AND($E28<>本位币,$H28="",$I28=""),"△这个币种一个汇率都没填，期初人民币成本算不出来",IF(AND($E28<>本位币,$H28=""),"△没填期初汇率，先拿期末汇率折的",""))))))
A29: =IF($C29="","",COUNTA($C$11:$C29)) | I29: =IF($C29="","",IFERROR(ROUND(N($G29)*IF($H29<>"",$H29,IF($E29=本位币,1,IFERROR(LOOKUP(2,1/((汇率月份<=重估基准日)*(INDEX(月末汇率区,0,MATCH($E29,汇率币种头,0))<>"")),INDEX(月末汇率区,0,MATCH($E29,汇率币种头,0))),IFERROR(LOOKUP(2,1/((汇率月份<=重估基准日)*(INDEX(记账汇率区,0,MATCH($E29,汇率币种头,0))<>"")),INDEX(记账汇率区,0,MATCH($E29,汇率币种头,0))),"")))),2),"")) | J29: =IF($C29="","",IF(COUNTIF($C$11:$C$40,$C29)>1,"※账户名称重复了，后面按名字取数会串",IF(AND($E29<>"",COUNTIF(币种表,$E29)=0),"※币种不在右边币种清单里",IF($G29="","※期初余额没填（没有就填 0）",IF(AND($E29<>本位币,$H29="",$I29=""),"△这个币种一个汇率都没填，期初人民币成本算不出来",IF(AND($E29<>本位币,$H29=""),"△没填期初汇率，先拿期末汇率折的",""))))))
A30: =IF($C30="","",COUNTA($C$11:$C30)) | I30: =IF($C30="","",IFERROR(ROUND(N($G30)*IF($H30<>"",$H30,IF($E30=本位币,1,IFERROR(LOOKUP(2,1/((汇率月份<=重估基准日)*(INDEX(月末汇率区,0,MATCH($E30,汇率币种头,0))<>"")),INDEX(月末汇率区,0,MATCH($E30,汇率币种头,0))),IFERROR(LOOKUP(2,1/((汇率月份<=重估基准日)*(INDEX(记账汇率区,0,MATCH($E30,汇率币种头,0))<>"")),INDEX(记账汇率区,0,MATCH($E30,汇率币种头,0))),"")))),2),"")) | J30: =IF($C30="","",IF(COUNTIF($C$11:$C$40,$C30)>1,"※账户名称重复了，后面按名字取数会串",IF(AND($E30<>"",COUNTIF(币种表,$E30)=0),"※币种不在右边币种清单里",IF($G30="","※期初余额没填（没有就填 0）",IF(AND($E30<>本位币,$H30="",$I30=""),"△这个币种一个汇率都没填，期初人民币成本算不出来",IF(AND($E30<>本位币,$H30=""),"△没填期初汇率，先拿期末汇率折的",""))))))
A31: =IF($C31="","",COUNTA($C$11:$C31)) | I31: =IF($C31="","",IFERROR(ROUND(N($G31)*IF($H31<>"",$H31,IF($E31=本位币,1,IFERROR(LOOKUP(2,1/((汇率月份<=重估基准日)*(INDEX(月末汇率区,0,MATCH($E31,汇率币种头,0))<>"")),INDEX(月末汇率区,0,MATCH($E31,汇率币种头,0))),IFERROR(LOOKUP(2,1/((汇率月份<=重估基准日)*(INDEX(记账汇率区,0,MATCH($E31,汇率币种头,0))<>"")),INDEX(记账汇率区,0,MATCH($E31,汇率币种头,0))),"")))),2),"")) | J31: =IF($C31="","",IF(COUNTIF($C$11:$C$40,$C31)>1,"※账户名称重复了，后面按名字取数会串",IF(AND($E31<>"",COUNTIF(币种表,$E31)=0),"※币种不在右边币种清单里",IF($G31="","※期初余额没填（没有就填 0）",IF(AND($E31<>本位币,$H31="",$I31=""),"△这个币种一个汇率都没填，期初人民币成本算不出来",IF(AND($E31<>本位币,$H31=""),"△没填期初汇率，先拿期末汇率折的",""))))))
A32: =IF($C32="","",COUNTA($C$11:$C32)) | I32: =IF($C32="","",IFERROR(ROUND(N($G32)*IF($H32<>"",$H32,IF($E32=本位币,1,IFERROR(LOOKUP(2,1/((汇率月份<=重估基准日)*(INDEX(月末汇率区,0,MATCH($E32,汇率币种头,0))<>"")),INDEX(月末汇率区,0,MATCH($E32,汇率币种头,0))),IFERROR(LOOKUP(2,1/((汇率月份<=重估基准日)*(INDEX(记账汇率区,0,MATCH($E32,汇率币种头,0))<>"")),INDEX(记账汇率区,0,MATCH($E32,汇率币种头,0))),"")))),2),"")) | J32: =IF($C32="","",IF(COUNTIF($C$11:$C$40,$C32)>1,"※账户名称重复了，后面按名字取数会串",IF(AND($E32<>"",COUNTIF(币种表,$E32)=0),"※币种不在右边币种清单里",IF($G32="","※期初余额没填（没有就填 0）",IF(AND($E32<>本位币,$H32="",$I32=""),"△这个币种一个汇率都没填，期初人民币成本算不出来",IF(AND($E32<>本位币,$H32=""),"△没填期初汇率，先拿期末汇率折的",""))))))
A33: =IF($C33="","",COUNTA($C$11:$C33)) | I33: =IF($C33="","",IFERROR(ROUND(N($G33)*IF($H33<>"",$H33,IF($E33=本位币,1,IFERROR(LOOKUP(2,1/((汇率月份<=重估基准日)*(INDEX(月末汇率区,0,MATCH($E33,汇率币种头,0))<>"")),INDEX(月末汇率区,0,MATCH($E33,汇率币种头,0))),IFERROR(LOOKUP(2,1/((汇率月份<=重估基准日)*(INDEX(记账汇率区,0,MATCH($E33,汇率币种头,0))<>"")),INDEX(记账汇率区,0,MATCH($E33,汇率币种头,0))),"")))),2),"")) | J33: =IF($C33="","",IF(COUNTIF($C$11:$C$40,$C33)>1,"※账户名称重复了，后面按名字取数会串",IF(AND($E33<>"",COUNTIF(币种表,$E33)=0),"※币种不在右边币种清单里",IF($G33="","※期初余额没填（没有就填 0）",IF(AND($E33<>本位币,$H33="",$I33=""),"△这个币种一个汇率都没填，期初人民币成本算不出来",IF(AND($E33<>本位币,$H33=""),"△没填期初汇率，先拿期末汇率折的",""))))))
A34: =IF($C34="","",COUNTA($C$11:$C34)) | I34: =IF($C34="","",IFERROR(ROUND(N($G34)*IF($H34<>"",$H34,IF($E34=本位币,1,IFERROR(LOOKUP(2,1/((汇率月份<=重估基准日)*(INDEX(月末汇率区,0,MATCH($E34,汇率币种头,0))<>"")),INDEX(月末汇率区,0,MATCH($E34,汇率币种头,0))),IFERROR(LOOKUP(2,1/((汇率月份<=重估基准日)*(INDEX(记账汇率区,0,MATCH($E34,汇率币种头,0))<>"")),INDEX(记账汇率区,0,MATCH($E34,汇率币种头,0))),"")))),2),"")) | J34: =IF($C34="","",IF(COUNTIF($C$11:$C$40,$C34)>1,"※账户名称重复了，后面按名字取数会串",IF(AND($E34<>"",COUNTIF(币种表,$E34)=0),"※币种不在右边币种清单里",IF($G34="","※期初余额没填（没有就填 0）",IF(AND($E34<>本位币,$H34="",$I34=""),"△这个币种一个汇率都没填，期初人民币成本算不出来",IF(AND($E34<>本位币,$H34=""),"△没填期初汇率，先拿期末汇率折的",""))))))
A35: =IF($C35="","",COUNTA($C$11:$C35)) | I35: =IF($C35="","",IFERROR(ROUND(N($G35)*IF($H35<>"",$H35,IF($E35=本位币,1,IFERROR(LOOKUP(2,1/((汇率月份<=重估基准日)*(INDEX(月末汇率区,0,MATCH($E35,汇率币种头,0))<>"")),INDEX(月末汇率区,0,MATCH($E35,汇率币种头,0))),IFERROR(LOOKUP(2,1/((汇率月份<=重估基准日)*(INDEX(记账汇率区,0,MATCH($E35,汇率币种头,0))<>"")),INDEX(记账汇率区,0,MATCH($E35,汇率币种头,0))),"")))),2),"")) | J35: =IF($C35="","",IF(COUNTIF($C$11:$C$40,$C35)>1,"※账户名称重复了，后面按名字取数会串",IF(AND($E35<>"",COUNTIF(币种表,$E35)=0),"※币种不在右边币种清单里",IF($G35="","※期初余额没填（没有就填 0）",IF(AND($E35<>本位币,$H35="",$I35=""),"△这个币种一个汇率都没填，期初人民币成本算不出来",IF(AND($E35<>本位币,$H35=""),"△没填期初汇率，先拿期末汇率折的",""))))))
A36: =IF($C36="","",COUNTA($C$11:$C36)) | I36: =IF($C36="","",IFERROR(ROUND(N($G36)*IF($H36<>"",$H36,IF($E36=本位币,1,IFERROR(LOOKUP(2,1/((汇率月份<=重估基准日)*(INDEX(月末汇率区,0,MATCH($E36,汇率币种头,0))<>"")),INDEX(月末汇率区,0,MATCH($E36,汇率币种头,0))),IFERROR(LOOKUP(2,1/((汇率月份<=重估基准日)*(INDEX(记账汇率区,0,MATCH($E36,汇率币种头,0))<>"")),INDEX(记账汇率区,0,MATCH($E36,汇率币种头,0))),"")))),2),"")) | J36: =IF($C36="","",IF(COUNTIF($C$11:$C$40,$C36)>1,"※账户名称重复了，后面按名字取数会串",IF(AND($E36<>"",COUNTIF(币种表,$E36)=0),"※币种不在右边币种清单里",IF($G36="","※期初余额没填（没有就填 0）",IF(AND($E36<>本位币,$H36="",$I36=""),"△这个币种一个汇率都没填，期初人民币成本算不出来",IF(AND($E36<>本位币,$H36=""),"△没填期初汇率，先拿期末汇率折的",""))))))
A37: =IF($C37="","",COUNTA($C$11:$C37)) | I37: =IF($C37="","",IFERROR(ROUND(N($G37)*IF($H37<>"",$H37,IF($E37=本位币,1,IFERROR(LOOKUP(2,1/((汇率月份<=重估基准日)*(INDEX(月末汇率区,0,MATCH($E37,汇率币种头,0))<>"")),INDEX(月末汇率区,0,MATCH($E37,汇率币种头,0))),IFERROR(LOOKUP(2,1/((汇率月份<=重估基准日)*(INDEX(记账汇率区,0,MATCH($E37,汇率币种头,0))<>"")),INDEX(记账汇率区,0,MATCH($E37,汇率币种头,0))),"")))),2),"")) | J37: =IF($C37="","",IF(COUNTIF($C$11:$C$40,$C37)>1,"※账户名称重复了，后面按名字取数会串",IF(AND($E37<>"",COUNTIF(币种表,$E37)=0),"※币种不在右边币种清单里",IF($G37="","※期初余额没填（没有就填 0）",IF(AND($E37<>本位币,$H37="",$I37=""),"△这个币种一个汇率都没填，期初人民币成本算不出来",IF(AND($E37<>本位币,$H37=""),"△没填期初汇率，先拿期末汇率折的",""))))))
A38: =IF($C38="","",COUNTA($C$11:$C38)) | I38: =IF($C38="","",IFERROR(ROUND(N($G38)*IF($H38<>"",$H38,IF($E38=本位币,1,IFERROR(LOOKUP(2,1/((汇率月份<=重估基准日)*(INDEX(月末汇率区,0,MATCH($E38,汇率币种头,0))<>"")),INDEX(月末汇率区,0,MATCH($E38,汇率币种头,0))),IFERROR(LOOKUP(2,1/((汇率月份<=重估基准日)*(INDEX(记账汇率区,0,MATCH($E38,汇率币种头,0))<>"")),INDEX(记账汇率区,0,MATCH($E38,汇率币种头,0))),"")))),2),"")) | J38: =IF($C38="","",IF(COUNTIF($C$11:$C$40,$C38)>1,"※账户名称重复了，后面按名字取数会串",IF(AND($E38<>"",COUNTIF(币种表,$E38)=0),"※币种不在右边币种清单里",IF($G38="","※期初余额没填（没有就填 0）",IF(AND($E38<>本位币,$H38="",$I38=""),"△这个币种一个汇率都没填，期初人民币成本算不出来",IF(AND($E38<>本位币,$H38=""),"△没填期初汇率，先拿期末汇率折的",""))))))
A39: =IF($C39="","",COUNTA($C$11:$C39)) | I39: =IF($C39="","",IFERROR(ROUND(N($G39)*IF($H39<>"",$H39,IF($E39=本位币,1,IFERROR(LOOKUP(2,1/((汇率月份<=重估基准日)*(INDEX(月末汇率区,0,MATCH($E39,汇率币种头,0))<>"")),INDEX(月末汇率区,0,MATCH($E39,汇率币种头,0))),IFERROR(LOOKUP(2,1/((汇率月份<=重估基准日)*(INDEX(记账汇率区,0,MATCH($E39,汇率币种头,0))<>"")),INDEX(记账汇率区,0,MATCH($E39,汇率币种头,0))),"")))),2),"")) | J39: =IF($C39="","",IF(COUNTIF($C$11:$C$40,$C39)>1,"※账户名称重复了，后面按名字取数会串",IF(AND($E39<>"",COUNTIF(币种表,$E39)=0),"※币种不在右边币种清单里",IF($G39="","※期初余额没填（没有就填 0）",IF(AND($E39<>本位币,$H39="",$I39=""),"△这个币种一个汇率都没填，期初人民币成本算不出来",IF(AND($E39<>本位币,$H39=""),"△没填期初汇率，先拿期末汇率折的",""))))))
A40: =IF($C40="","",COUNTA($C$11:$C40)) | I40: =IF($C40="","",IFERROR(ROUND(N($G40)*IF($H40<>"",$H40,IF($E40=本位币,1,IFERROR(LOOKUP(2,1/((汇率月份<=重估基准日)*(INDEX(月末汇率区,0,MATCH($E40,汇率币种头,0))<>"")),INDEX(月末汇率区,0,MATCH($E40,汇率币种头,0))),IFERROR(LOOKUP(2,1/((汇率月份<=重估基准日)*(INDEX(记账汇率区,0,MATCH($E40,汇率币种头,0))<>"")),INDEX(记账汇率区,0,MATCH($E40,汇率币种头,0))),"")))),2),"")) | J40: =IF($C40="","",IF(COUNTIF($C$11:$C$40,$C40)>1,"※账户名称重复了，后面按名字取数会串",IF(AND($E40<>"",COUNTIF(币种表,$E40)=0),"※币种不在右边币种清单里",IF($G40="","※期初余额没填（没有就填 0）",IF(AND($E40<>本位币,$H40="",$I40=""),"△这个币种一个汇率都没填，期初人民币成本算不出来",IF(AND($E40<>本位币,$H40=""),"△没填期初汇率，先拿期末汇率折的",""))))))

Sheet 月度汇率
A1: 月度汇率 · 每月填一次，填了就不用再动
A2: 左边【记账汇率】是流水折人民币用的；右边【月末汇率】是月末重估用的，空着就自动用左边那个。某月没填？自动往前找最近一个填过的月份，并在核对表点名。
A4: 记账汇率 —— 流水按「交易日期所在月」自动匹配 | K4: 月末汇率 —— 月末重估用；空着=用左边记账汇率
A5: 月份 | B5: CNY | C5: USD | D5: HKD | E5: EUR | F5: JPY | G5: GBP | H5: SGD | I5: AUD | K5: CNY | L5: USD | M5: HKD | N5: EUR | O5: JPY | P5: GBP | Q5: SGD | R5: AUD | T5: 这一列别删：给核对表数「哪几个月还没填」用的 | U5: 本月外币流水笔数
A6: =DATE(管理年度,1,1) -> 46023 | B6: 1 | K6: 1 | T6: =IF($A6="","",COUNTA($C6:$I6)) -> 0 | U6: =IF($A6="","",COUNTIFS(流水日期,">="&$A6,流水日期,"<="&EOMONTH($A6,0),流水币种,"<>"&本位币)) -> 0
A7: =EDATE(A6,1) -> 46054 | B7: 1 | K7: 1 | T7: =IF($A7="","",COUNTA($C7:$I7)) -> 0 | U7: =IF($A7="","",COUNTIFS(流水日期,">="&$A7,流水日期,"<="&EOMONTH($A7,0),流水币种,"<>"&本位币)) -> 0
A8: =EDATE(A7,1) -> 46082 | B8: 1 | K8: 1 | T8: =IF($A8="","",COUNTA($C8:$I8)) -> 0 | U8: =IF($A8="","",COUNTIFS(流水日期,">="&$A8,流水日期,"<="&EOMONTH($A8,0),流水币种,"<>"&本位币)) -> 0
A9: =EDATE(A8,1) -> 46113 | B9: 1 | K9: 1 | T9: =IF($A9="","",COUNTA($C9:$I9)) -> 0 | U9: =IF($A9="","",COUNTIFS(流水日期,">="&$A9,流水日期,"<="&EOMONTH($A9,0),流水币种,"<>"&本位币)) -> 0
A10: =EDATE(A9,1) -> 46143 | B10: 1 | K10: 1 | T10: =IF($A10="","",COUNTA($C10:$I10)) -> 0 | U10: =IF($A10="","",COUNTIFS(流水日期,">="&$A10,流水日期,"<="&EOMONTH($A10,0),流水币种,"<>"&本位币)) -> 0
A11: =EDATE(A10,1) -> 46174 | B11: 1 | K11: 1 | T11: =IF($A11="","",COUNTA($C11:$I11)) -> 0 | U11: =IF($A11="","",COUNTIFS(流水日期,">="&$A11,流水日期,"<="&EOMONTH($A11,0),流水币种,"<>"&本位币)) -> 0
A12: =EDATE(A11,1) -> 46204 | B12: 1 | K12: 1 | T12: =IF($A12="","",COUNTA($C12:$I12)) -> 0 | U12: =IF($A12="","",COUNTIFS(流水日期,">="&$A12,流水日期,"<="&EOMONTH($A12,0),流水币种,"<>"&本位币)) -> 0
A13: =EDATE(A12,1) -> 46235 | B13: 1 | C13: 7.18 | D13: 0.92 | E13: 7.69 | K13: 1 | T13: =IF($A13="","",COUNTA($C13:$I13)) -> 3 | U13: =IF($A13="","",COUNTIFS(流水日期,">="&$A13,流水日期,"<="&EOMONTH($A13,0),流水币种,"<>"&本位币)) -> 10
A14: =EDATE(A13,1) -> 46266 | B14: 1 | K14: 1 | T14: =IF($A14="","",COUNTA($C14:$I14)) -> 0 | U14: =IF($A14="","",COUNTIFS(流水日期,">="&$A14,流水日期,"<="&EOMONTH($A14,0),流水币种,"<>"&本位币)) -> 0
A15: =EDATE(A14,1) -> 46296 | B15: 1 | K15: 1 | T15: =IF($A15="","",COUNTA($C15:$I15)) -> 0 | U15: =IF($A15="","",COUNTIFS(流水日期,">="&$A15,流水日期,"<="&EOMONTH($A15,0),流水币种,"<>"&本位币)) -> 0
A16: =EDATE(A15,1) -> 46327 | B16: 1 | K16: 1 | T16: =IF($A16="","",COUNTA($C16:$I16)) -> 0 | U16: =IF($A16="","",COUNTIFS(流水日期,">="&$A16,流水日期,"<="&EOMONTH($A16,0),流水币种,"<>"&本位币)) -> 0
A17: =EDATE(A16,1) -> 46357 | B17: 1 | K17: 1 | T17: =IF($A17="","",COUNTA($C17:$I17)) -> 0 | U17: =IF($A17="","",COUNTIFS(流水日期,">="&$A17,流水日期,"<="&EOMONTH($A17,0),流水币种,"<>"&本位币)) -> 0
A18: 全年填了几个月 | B18: =COUNT(B6:B17) -> 12 | C18: =COUNT(C6:C17) -> 1 | D18: =COUNT(D6:D17) -> 1 | E18: =COUNT(E6:E17) -> 1 | F18: =COUNT(F6:F17) -> 0 | G18: =COUNT(G6:G17) -> 0 | H18: =COUNT(H6:H17) -> 0 | I18: =COUNT(I6:I17) -> 0

Sheet 流水录入
A1: 流水录入 · 全套表只有这一张要填
A2: 选账户名称 → 银行、币种、汇率自动带出来；收入和支出分两列，只填一个。银行有实际成交价（购汇、结汇）就填「实际成交汇率」，它优先于当月记账汇率。最后一列「核对」会自己挑毛病，红字是错、琥珀字是待办。
A5: 日期 ★ | B5: 账户名称 ★ | C5: 银行 | D5: 币种 | E5: 收/支类别 ★ | F5: 类别属性 | G5: 收入金额(原币) | H5: 支出金额(原币) | I5: 实际成交汇率 (选填) | J5: 应用汇率 | K5: 原币净额 | L5: 折人民币 | M5: 账户余额(原币) | N5: 账面人民币余额 | O5: 摘要 | P5: 项目/业务 | Q5: 往来单位 | R5: 备注 | S5: 核对
A6: 46237 | B6: 工商银行基本户-8888 | C6: =IF($B6="","",IFERROR(INDEX(账户银行,MATCH($B6,账户名,0)),"")) -> 工商银行 | D6: =IF($B6="","",IFERROR(INDEX(账户币种,MATCH($B6,账户名,0)),"")) -> CNY | E6: 销售回款 | F6: =IF($E6="","",IFERROR(INDEX(类别属性,MATCH($E6,类别表,0)),"")) -> 收入 | G6: 120000 | J6: =IF(OR($A6="",$B6=""),"",IF($I6<>"",$I6,IF($D6=本位币,1,IFERROR(LOOKUP(2,1/((汇率月份<=$A6)*(INDEX(记账汇率区,0,MATCH($D6,汇率币种头,0))<>"")),INDEX(记账汇率区,0,MATCH($D6,汇率币种头,0))),"")))) -> 1 | K6: =IF(AND($G6="",$H6=""),"",ROUND(N($G6)-N($H6),2)) -> 120000 | L6: =IF(OR($K6="",$J6=""),"",ROUND($K6*$J6,2)) -> 120000 | M6: =IF($B6="","",ROUND(SUMIF(账户名,$B6,账户期初)+SUMIFS($K$6:K6,$B$6:B6,$B6),2)) -> 620000 | N6: =IF($B6="","",IFERROR(ROUND(INDEX(账户期初本位,MATCH($B6,账户名,0))+SUMIFS($L$6:L6,$B$6:B6,$B6),2),"")) -> 620000 | O6: 销售回款 | P6: 项目A | Q6: 华东客户A | S6: =IF($B6="","",IF(ISNA(MATCH($B6,账户名,0)),"※这个账户不在【参数设置】的账户档案里",IF($A6="","※没填日期，这一笔不会进任何月份的报表",IF(AND($G6<>"",$H6<>""),"※收入和支出不能同时填",IF(AND(N($G6)=0,N($H6)=0),"※收入和支出都没填",IF($E6="","※没填收支类别，分类报表会漏掉这一笔",IF(ISNA(MATCH($E6,类别表,0)),"※收支类别不在【参数设置】的清单里",IF($J6="","△"&$D6&" 还没填汇率，去【月度汇率】补上就自动算了",IF(YEAR($A6)<>管理年度,"△不是管理年度的单据，年报里看不到",IF(AND($F6="内部转账",$Q6=""),"△内部转账建议在「往来单位」写上对方账户",IF($M6<0,"△这一笔之后该账户余额成负数了，核一下","")))))))))))
A7: 46238 | B7: 中国银行美元结算户-6688 | C7: =IF($B7="","",IFERROR(INDEX(账户银行,MATCH($B7,账户名,0)),"")) -> 中国银行 | D7: =IF($B7="","",IFERROR(INDEX(账户币种,MATCH($B7,账户名,0)),"")) -> USD | E7: 销售回款 | F7: =IF($E7="","",IFERROR(INDEX(类别属性,MATCH($E7,类别表,0)),"")) -> 收入 | G7: 25000 | J7: =IF(OR($A7="",$B7=""),"",IF($I7<>"",$I7,IF($D7=本位币,1,IFERROR(LOOKUP(2,1/((汇率月份<=$A7)*(INDEX(记账汇率区,0,MATCH($D7,汇率币种头,0))<>"")),INDEX(记账汇率区,0,MATCH($D7,汇率币种头,0))),"")))) -> 7.18 | K7: =IF(AND($G7="",$H7=""),"",ROUND(N($G7)-N($H7),2)) -> 25000 | L7: =IF(OR($K7="",$J7=""),"",ROUND($K7*$J7,2)) -> 179500 | M7: =IF($B7="","",ROUND(SUMIF(账户名,$B7,账户期初)+SUMIFS($K$6:K7,$B$6:B7,$B7),2)) -> 825000 | N7: =IF($B7="","",IFERROR(ROUND(INDEX(账户期初本位,MATCH($B7,账户名,0))+SUMIFS($L$6:L7,$B$6:B7,$B7),2),"")) -> 5899500 | O7: 美元货款 | P7: 出口业务 | Q7: Overseas Client A | S7: =IF($B7="","",IF(ISNA(MATCH($B7,账户名,0)),"※这个账户不在【参数设置】的账户档案里",IF($A7="","※没填日期，这一笔不会进任何月份的报表",IF(AND($G7<>"",$H7<>""),"※收入和支出不能同时填",IF(AND(N($G7)=0,N($H7)=0),"※收入和支出都没填",IF($E7="","※没填收支类别，分类报表会漏掉这一笔",IF(ISNA(MATCH($E7,类别表,0)),"※收支类别不在【参数设置】的清单里",IF($J7="","△"&$D7&" 还没填汇率，去【月度汇率】补上就自动算了",IF(YEAR($A7)<>管理年度,"△不是管理年度的单据，年报里看不到",IF(AND($F7="内部转账",$Q7=""),"△内部转账建议在「往来单位」写上对方账户",IF($M7<0,"△这一笔之后该账户余额成负数了，核一下","")))))))))))
A8: 46239 | B8: 汇丰银行港币结算户-5566 | C8: =IF($B8="","",IFERROR(INDEX(账户银行,MATCH($B8,账户名,0)),"")) -> 汇丰银行 | D8: =IF($B8="","",IFERROR(INDEX(账户币种,MATCH($B8,账户名,0)),"")) -> HKD | E8: 采购付款 | F8: =IF($E8="","",IFERROR(INDEX(类别属性,MATCH($E8,类别表,0)),"")) -> 支出 | H8: 4500 | J8: =IF(OR($A8="",$B8=""),"",IF($I8<>"",$I8,IF($D8=本位币,1,IFERROR(LOOKUP(2,1/((汇率月份<=$A8)*(INDEX(记账汇率区,0,MATCH($D8,汇率币种头,0))<>"")),INDEX(记账汇率区,0,MATCH($D8,汇率币种头,0))),"")))) -> 0.92 | K8: =IF(AND($G8="",$H8=""),"",ROUND(N($G8)-N($H8),2)) -> -4500 | L8: =IF(OR($K8="",$J8=""),"",ROUND($K8*$J8,2)) -> -4140 | M8: =IF($B8="","",ROUND(SUMIF(账户名,$B8,账户期初)+SUMIFS($K$6:K8,$B$6:B8,$B8),2)) -> 295500 | N8: =IF($B8="","",IFERROR(ROUND(INDEX(账户期初本位,MATCH($B8,账户名,0))+SUMIFS($L$6:L8,$B$6:B8,$B8),2),"")) -> 270360 | O8: 港币采购付款 | P8: 进口业务 | Q8: 香港供应商A | S8: =IF($B8="","",IF(ISNA(MATCH($B8,账户名,0)),"※这个账户不在【参数设置】的账户档案里",IF($A8="","※没填日期，这一笔不会进任何月份的报表",IF(AND($G8<>"",$H8<>""),"※收入和支出不能同时填",IF(AND(N($G8)=0,N($H8)=0),"※收入和支出都没填",IF($E8="","※没填收支类别，分类报表会漏掉这一笔",IF(ISNA(MATCH($E8,类别表,0)),"※收支类别不在【参数设置】的清单里",IF($J8="","△"&$D8&" 还没填汇率，去【月度汇率】补上就自动算了",IF(YEAR($A8)<>管理年度,"△不是管理年度的单据，年报里看不到",IF(AND($F8="内部转账",$Q8=""),"△内部转账建议在「往来单位」写上对方账户",IF($M8<0,"△这一笔之后该账户余额成负数了，核一下","")))))))))))
A9: 46240 | B9: 招商银行一般户-2388 | C9: =IF($B9="","",IFERROR(INDEX(账户银行,MATCH($B9,账户名,0)),"")) -> 招商银行 | D9: =IF($B9="","",IFERROR(INDEX(账户币种,MATCH($B9,账户名,0)),"")) -> CNY | E9: 工资 | F9: =IF($E9="","",IFERROR(INDEX(类别属性,MATCH($E9,类别表,0)),"")) -> 支出 | H9: 30000 | J9: =IF(OR($A9="",$B9=""),"",IF($I9<>"",$I9,IF($D9=本位币,1,IFERROR(LOOKUP(2,1/((汇率月份<=$A9)*(INDEX(记账汇率区,0,MATCH($D9,汇率币种头,0))<>"")),INDEX(记账汇率区,0,MATCH($D9,汇率币种头,0))),"")))) -> 1 | K9: =IF(AND($G9="",$H9=""),"",ROUND(N($G9)-N($H9),2)) -> -30000 | L9: =IF(OR($K9="",$J9=""),"",ROUND($K9*$J9,2)) -> -30000 | M9: =IF($B9="","",ROUND(SUMIF(账户名,$B9,账户期初)+SUMIFS($K$6:K9,$B$6:B9,$B9),2)) -> 170000 | N9: =IF($B9="","",IFERROR(ROUND(INDEX(账户期初本位,MATCH($B9,账户名,0))+SUMIFS($L$6:L9,$B$6:B9,$B9),2),"")) -> 170000 | O9: 工资发放 | P9: 行政 | Q9: 员工薪酬 | S9: =IF($B9="","",IF(ISNA(MATCH($B9,账户名,0)),"※这个账户不在【参数设置】的账户档案里",IF($A9="","※没填日期，这一笔不会进任何月份的报表",IF(AND($G9<>"",$H9<>""),"※收入和支出不能同时填",IF(AND(N($G9)=0,N($H9)=0),"※收入和支出都没填",IF($E9="","※没填收支类别，分类报表会漏掉这一笔",IF(ISNA(MATCH($E9,类别表,0)),"※收支类别不在【参数设置】的清单里",IF($J9="","△"&$D9&" 还没填汇率，去【月度汇率】补上就自动算了",IF(YEAR($A9)<>管理年度,"△不是管理年度的单据，年报里看不到",IF(AND($F9="内部转账",$Q9=""),"△内部转账建议在「往来单位」写上对方账户",IF($M9<0,"△这一笔之后该账户余额成负数了，核一下","")))))))))))
A10: 46241 | B10: 汇丰银行美元结算户-7788 | C10: =IF($B10="","",IFERROR(INDEX(账户银行,MATCH($B10,账户名,0)),"")) -> 汇丰银行 | D10: =IF($B10="","",IFERROR(INDEX(账户币种,MATCH($B10,账户名,0)),"")) -> USD | E10: 投资款 | F10: =IF($E10="","",IFERROR(INDEX(类别属性,MATCH($E10,类别表,0)),"")) -> 收入 | G10: 12000 | J10: =IF(OR($A10="",$B10=""),"",IF($I10<>"",$I10,IF($D10=本位币,1,IFERROR(LOOKUP(2,1/((汇率月份<=$A10)*(INDEX(记账汇率区,0,MATCH($D10,汇率币种头,0))<>"")),INDEX(记账汇率区,0,MATCH($D10,汇率币种头,0))),"")))) -> 7.18 | K10: =IF(AND($G10="",$H10=""),"",ROUND(N($G10)-N($H10),2)) -> 12000 | L10: =IF(OR($K10="",$J10=""),"",ROUND($K10*$J10,2)) -> 86160 | M10: =IF($B10="","",ROUND(SUMIF(账户名,$B10,账户期初)+SUMIFS($K$6:K10,$B$6:B10,$B10),2)) -> 512000 | N10: =IF($B10="","",IFERROR(ROUND(INDEX(账户期初本位,MATCH($B10,账户名,0))+SUMIFS($L$6:L10,$B$6:B10,$B10),2),"")) -> 3661160 | O10: 美元投资款 | P10: 融资 | Q10: 股东A | S10: =IF($B10="","",IF(ISNA(MATCH($B10,账户名,0)),"※这个账户不在【参数设置】的账户档案里",IF($A10="","※没填日期，这一笔不会进任何月份的报表",IF(AND($G10<>"",$H10<>""),"※收入和支出不能同时填",IF(AND(N($G10)=0,N($H10)=0),"※收入和支出都没填",IF($E10="","※没填收支类别，分类报表会漏掉这一笔",IF(ISNA(MATCH($E10,类别表,0)),"※收支类别不在【参数设置】的清单里",IF($J10="","△"&$D10&" 还没填汇率，去【月度汇率】补上就自动算了",IF(YEAR($A10)<>管理年度,"△不是管理年度的单据，年报里看不到",IF(AND($F10="内部转账",$Q10=""),"△内部转账建议在「往来单位」写上对方账户",IF($M10<0,"△这一笔之后该账户余额成负数了，核一下","")))))))))))
A11: 46242 | B11: 工商银行基本户-8888 | C11: =IF($B11="","",IFERROR(INDEX(账户银行,MATCH($B11,账户名,0)),"")) -> 工商银行 | D11: =IF($B11="","",IFERROR(INDEX(账户币种,MATCH($B11,账户名,0)),"")) -> CNY | E11: 税费 | F11: =IF($E11="","",IFERROR(INDEX(类别属性,MATCH($E11,类别表,0)),"")) -> 支出 | H11: 18000 | J11: =IF(OR($A11="",$B11=""),"",IF($I11<>"",$I11,IF($D11=本位币,1,IFERROR(LOOKUP(2,1/((汇率月份<=$A11)*(INDEX(记账汇率区,0,MATCH($D11,汇率币种头,0))<>"")),INDEX(记账汇率区,0,MATCH($D11,汇率币种头,0))),"")))) -> 1 | K11: =IF(AND($G11="",$H11=""),"",ROUND(N($G11)-N($H11),2)) -> -18000 | L11: =IF(OR($K11="",$J11=""),"",ROUND($K11*$J11,2)) -> -18000 | M11: =IF($B11="","",ROUND(SUMIF(账户名,$B11,账户期初)+SUMIFS($K$6:K11,$B$6:B11,$B11),2)) -> 602000 | N11: =IF($B11="","",IFERROR(ROUND(INDEX(账户期初本位,MATCH($B11,账户名,0))+SUMIFS($L$6:L11,$B$6:B11,$B11),2),"")) -> 602000 | O11: 税费缴纳 | P11: 税务 | Q11: 税务机关 | S11: =IF($B11="","",IF(ISNA(MATCH($B11,账户名,0)),"※这个账户不在【参数设置】的账户档案里",IF($A11="","※没填日期，这一笔不会进任何月份的报表",IF(AND($G11<>"",$H11<>""),"※收入和支出不能同时填",IF(AND(N($G11)=0,N($H11)=0),"※收入和支出都没填",IF($E11="","※没填收支类别，分类报表会漏掉这一笔",IF(ISNA(MATCH($E11,类别表,0)),"※收支类别不在【参数设置】的清单里",IF($J11="","△"&$D11&" 还没填汇率，去【月度汇率】补上就自动算了",IF(YEAR($A11)<>管理年度,"△不是管理年度的单据，年报里看不到",IF(AND($F11="内部转账",$Q11=""),"△内部转账建议在「往来单位」写上对方账户",IF($M11<0,"△这一笔之后该账户余额成负数了，核一下","")))))))))))
A12: 46244 | B12: 中国银行美元结算户-6688 | C12: =IF($B12="","",IFERROR(INDEX(账户银行,MATCH($B12,账户名,0)),"")) -> 中国银行 | D12: =IF($B12="","",IFERROR(INDEX(账户币种,MATCH($B12,账户名,0)),"")) -> USD | E12: 采购付款 | F12: =IF($E12="","",IFERROR(INDEX(类别属性,MATCH($E12,类别表,0)),"")) -> 支出 | H12: 8000 | I12: 7.16 | J12: =IF(OR($A12="",$B12=""),"",IF($I12<>"",$I12,IF($D12=本位币,1,IFERROR(LOOKUP(2,1/((汇率月份<=$A12)*(INDEX(记账汇率区,0,MATCH($D12,汇率币种头,0))<>"")),INDEX(记账汇率区,0,MATCH($D12,汇率币种头,0))),"")))) -> 7.16 | K12: =IF(AND($G12="",$H12=""),"",ROUND(N($G12)-N($H12),2)) -> -8000 | L12: =IF(OR($K12="",$J12=""),"",ROUND($K12*$J12,2)) -> -57280 | M12: =IF($B12="","",ROUND(SUMIF(账户名,$B12,账户期初)+SUMIFS($K$6:K12,$B$6:B12,$B12),2)) -> 817000 | N12: =IF($B12="","",IFERROR(ROUND(INDEX(账户期初本位,MATCH($B12,账户名,0))+SUMIFS($L$6:L12,$B$6:B12,$B12),2),"")) -> 5842220 | O12: 美元采购款（银行实际成交价） | P12: 进口业务 | Q12: Overseas Supplier B | S12: =IF($B12="","",IF(ISNA(MATCH($B12,账户名,0)),"※这个账户不在【参数设置】的账户档案里",IF($A12="","※没填日期，这一笔不会进任何月份的报表",IF(AND($G12<>"",$H12<>""),"※收入和支出不能同时填",IF(AND(N($G12)=0,N($H12)=0),"※收入和支出都没填",IF($E12="","※没填收支类别，分类报表会漏掉这一笔",IF(ISNA(MATCH($E12,类别表,0)),"※收支类别不在【参数设置】的清单里",IF($J12="","△"&$D12&" 还没填汇率，去【月度汇率】补上就自动算了",IF(YEAR($A12)<>管理年度,"△不是管理年度的单据，年报里看不到",IF(AND($F12="内部转账",$Q12=""),"△内部转账建议在「往来单位」写上对方账户",IF($M12<0,"△这一笔之后该账户余额成负数了，核一下","")))))))))))
A13: 46245 | B13: 汇丰银行港币结算户-5566 | C13: =IF($B13="","",IFERROR(INDEX(账户银行,MATCH($B13,账户名,0)),"")) -> 汇丰银行 | D13: =IF($B13="","",IFERROR(INDEX(账户币种,MATCH($B13,账户名,0)),"")) -> HKD | E13: 销售回款 | F13: =IF($E13="","",IFERROR(INDEX(类别属性,MATCH($E13,类别表,0)),"")) -> 收入 | G13: 80000 | J13: =IF(OR($A13="",$B13=""),"",IF($I13<>"",$I13,IF($D13=本位币,1,IFERROR(LOOKUP(2,1/((汇率月份<=$A13)*(INDEX(记账汇率区,0,MATCH($D13,汇率币种头,0))<>"")),INDEX(记账汇率区,0,MATCH($D13,汇率币种头,0))),"")))) -> 0.92 | K13: =IF(AND($G13="",$H13=""),"",ROUND(N($G13)-N($H13),2)) -> 80000 | L13: =IF(OR($K13="",$J13=""),"",ROUND($K13*$J13,2)) -> 73600 | M13: =IF($B13="","",ROUND(SUMIF(账户名,$B13,账户期初)+SUMIFS($K$6:K13,$B$6:B13,$B13),2)) -> 375500 | N13: =IF($B13="","",IFERROR(ROUND(INDEX(账户期初本位,MATCH($B13,账户名,0))+SUMIFS($L$6:L13,$B$6:B13,$B13),2),"")) -> 343960 | O13: 港币销售回款 | P13: 香港业务 | Q13: 香港客户B | S13: =IF($B13="","",IF(ISNA(MATCH($B13,账户名,0)),"※这个账户不在【参数设置】的账户档案里",IF($A13="","※没填日期，这一笔不会进任何月份的报表",IF(AND($G13<>"",$H13<>""),"※收入和支出不能同时填",IF(AND(N($G13)=0,N($H13)=0),"※收入和支出都没填",IF($E13="","※没填收支类别，分类报表会漏掉这一笔",IF(ISNA(MATCH($E13,类别表,0)),"※收支类别不在【参数设置】的清单里",IF($J13="","△"&$D13&" 还没填汇率，去【月度汇率】补上就自动算了",IF(YEAR($A13)<>管理年度,"△不是管理年度的单据，年报里看不到",IF(AND($F13="内部转账",$Q13=""),"△内部转账建议在「往来单位」写上对方账户",IF($M13<0,"△这一笔之后该账户余额成负数了，核一下","")))))))))))
A14: 46246 | B14: 招商银行一般户-2388 | C14: =IF($B14="","",IFERROR(INDEX(账户银行,MATCH($B14,账户名,0)),"")) -> 招商银行 | D14: =IF($B14="","",IFERROR(INDEX(账户币种,MATCH($B14,账户名,0)),"")) -> CNY | E14: 借款 | F14: =IF($E14="","",IFERROR(INDEX(类别属性,MATCH($E14,类别表,0)),"")) -> 收入 | G14: 60000 | J14: =IF(OR($A14="",$B14=""),"",IF($I14<>"",$I14,IF($D14=本位币,1,IFERROR(LOOKUP(2,1/((汇率月份<=$A14)*(INDEX(记账汇率区,0,MATCH($D14,汇率币种头,0))<>"")),INDEX(记账汇率区,0,MATCH($D14,汇率币种头,0))),"")))) -> 1 | K14: =IF(AND($G14="",$H14=""),"",ROUND(N($G14)-N($H14),2)) -> 60000 | L14: =IF(OR($K14="",$J14=""),"",ROUND($K14*$J14,2)) -> 60000 | M14: =IF($B14="","",ROUND(SUMIF(账户名,$B14,账户期初)+SUMIFS($K$6:K14,$B$6:B14,$B14),2)) -> 230000 | N14: =IF($B14="","",IFERROR(ROUND(INDEX(账户期初本位,MATCH($B14,账户名,0))+SUMIFS($L$6:L14,$B$6:B14,$B14),2),"")) -> 230000 | O14: 短期借款到账 | P14: 融资 | Q14: 银行借款 | S14: =IF($B14="","",IF(ISNA(MATCH($B14,账户名,0)),"※这个账户不在【参数设置】的账户档案里",IF($A14="","※没填日期，这一笔不会进任何月份的报表",IF(AND($G14<>"",$H14<>""),"※收入和支出不能同时填",IF(AND(N($G14)=0,N($H14)=0),"※收入和支出都没填",IF($E14="","※没填收支类别，分类报表会漏掉这一笔",IF(ISNA(MATCH($E14,类别表,0)),"※收支类别不在【参数设置】的清单里",IF($J14="","△"&$D14&" 还没填汇率，去【月度汇率】补上就自动算了",IF(YEAR($A14)<>管理年度,"△不是管理年度的单据，年报里看不到",IF(AND($F14="内部转账",$Q14=""),"△内部转账建议在「往来单位」写上对方账户",IF($M14<0,"△这一笔之后该账户余额成负数了，核一下","")))))))))))
A15: 46247 | B15: 汇丰银行美元结算户-7788 | C15: =IF($B15="","",IFERROR(INDEX(账户银行,MATCH($B15,账户名,0)),"")) -> 汇丰银行 | D15: =IF($B15="","",IFERROR(INDEX(账户币种,MATCH($B15,账户名,0)),"")) -> USD | E15: 运营费用 | F15: =IF($E15="","",IFERROR(INDEX(类别属性,MATCH($E15,类别表,0)),"")) -> 支出 | H15: 5000 | J15: =IF(OR($A15="",$B15=""),"",IF($I15<>"",$I15,IF($D15=本位币,1,IFERROR(LOOKUP(2,1/((汇率月份<=$A15)*(INDEX(记账汇率区,0,MATCH($D15,汇率币种头,0))<>"")),INDEX(记账汇率区,0,MATCH($D15,汇率币种头,0))),"")))) -> 7.18 | K15: =IF(AND($G15="",$H15=""),"",ROUND(N($G15)-N($H15),2)) -> -5000 | L15: =IF(OR($K15="",$J15=""),"",ROUND($K15*$J15,2)) -> -35900 | M15: =IF($B15="","",ROUND(SUMIF(账户名,$B15,账户期初)+SUMIFS($K$6:K15,$B$6:B15,$B15),2)) -> 507000 | N15: =IF($B15="","",IFERROR(ROUND(INDEX(账户期初本位,MATCH($B15,账户名,0))+SUMIFS($L$6:L15,$B$6:B15,$B15),2),"")) -> 3625260 | O15: 美元服务费 | P15: 海外服务 | Q15: Service Provider | S15: =IF($B15="","",IF(ISNA(MATCH($B15,账户名,0)),"※这个账户不在【参数设置】的账户档案里",IF($A15="","※没填日期，这一笔不会进任何月份的报表",IF(AND($G15<>"",$H15<>""),"※收入和支出不能同时填",IF(AND(N($G15)=0,N($H15)=0),"※收入和支出都没填",IF($E15="","※没填收支类别，分类报表会漏掉这一笔",IF(ISNA(MATCH($E15,类别表,0)),"※收支类别不在【参数设置】的清单里",IF($J15="","△"&$D15&" 还没填汇率，去【月度汇率】补上就自动算了",IF(YEAR($A15)<>管理年度,"△不是管理年度的单据，年报里看不到",IF(AND($F15="内部转账",$Q15=""),"△内部转账建议在「往来单位」写上对方账户",IF($M15<0,"△这一笔之后该账户余额成负数了，核一下","")))))))))))
A16: 46248 | B16: 工商银行基本户-8888 | C16: =IF($B16="","",IFERROR(INDEX(账户银行,MATCH($B16,账户名,0)),"")) -> 工商银行 | D16: =IF($B16="","",IFERROR(INDEX(账户币种,MATCH($B16,账户名,0)),"")) -> CNY | E16: 内部转账 | F16: =IF($E16="","",IFERROR(INDEX(类别属性,MATCH($E16,类别表,0)),"")) -> 内部转账 | H16: 50000 | J16: =IF(OR($A16="",$B16=""),"",IF($I16<>"",$I16,IF($D16=本位币,1,IFERROR(LOOKUP(2,1/((汇率月份<=$A16)*(INDEX(记账汇率区,0,MATCH($D16,汇率币种头,0))<>"")),INDEX(记账汇率区,0,MATCH($D16,汇率币种头,0))),"")))) -> 1 | K16: =IF(AND($G16="",$H16=""),"",ROUND(N($G16)-N($H16),2)) -> -50000 | L16: =IF(OR($K16="",$J16=""),"",ROUND($K16*$J16,2)) -> -50000 | M16: =IF($B16="","",ROUND(SUMIF(账户名,$B16,账户期初)+SUMIFS($K$6:K16,$B$6:B16,$B16),2)) -> 552000 | N16: =IF($B16="","",IFERROR(ROUND(INDEX(账户期初本位,MATCH($B16,账户名,0))+SUMIFS($L$6:L16,$B$6:B16,$B16),2),"")) -> 552000 | O16: 转至招商银行 | P16: 内部调拨 | Q16: 招商银行一般户-2388 | S16: =IF($B16="","",IF(ISNA(MATCH($B16,账户名,0)),"※这个账户不在【参数设置】的账户档案里",IF($A16="","※没填日期，这一笔不会进任何月份的报表",IF(AND($G16<>"",$H16<>""),"※收入和支出不能同时填",IF(AND(N($G16)=0,N($H16)=0),"※收入和支出都没填",IF($E16="","※没填收支类别，分类报表会漏掉这一笔",IF(ISNA(MATCH($E16,类别表,0)),"※收支类别不在【参数设置】的清单里",IF($J16="","△"&$D16&" 还没填汇率，去【月度汇率】补上就自动算了",IF(YEAR($A16)<>管理年度,"△不是管理年度的单据，年报里看不到",IF(AND($F16="内部转账",$Q16=""),"△内部转账建议在「往来单位」写上对方账户",IF($M16<0,"△这一笔之后该账户余额成负数了，核一下","")))))))))))
A17: 46248 | B17: 招商银行一般户-2388 | C17: =IF($B17="","",IFERROR(INDEX(账户银行,MATCH($B17,账户名,0)),"")) -> 招商银行 | D17: =IF($B17="","",IFERROR(INDEX(账户币种,MATCH($B17,账户名,0)),"")) -> CNY | E17: 内部转账 | F17: =IF($E17="","",IFERROR(INDEX(类别属性,MATCH($E17,类别表,0)),"")) -> 内部转账 | G17: 50000 | J17: =IF(OR($A17="",$B17=""),"",IF($I17<>"",$I17,IF($D17=本位币,1,IFERROR(LOOKUP(2,1/((汇率月份<=$A17)*(INDEX(记账汇率区,0,MATCH($D17,汇率币种头,0))<>"")),INDEX(记账汇率区,0,MATCH($D17,汇率币种头,0))),"")))) -> 1 | K17: =IF(AND($G17="",$H17=""),"",ROUND(N($G17)-N($H17),2)) -> 50000 | L17: =IF(OR($K17="",$J17=""),"",ROUND($K17*$J17,2)) -> 50000 | M17: =IF($B17="","",ROUND(SUMIF(账户名,$B17,账户期初)+SUMIFS($K$6:K17,$B$6:B17,$B17),2)) -> 280000 | N17: =IF($B17="","",IFERROR(ROUND(INDEX(账户期初本位,MATCH($B17,账户名,0))+SUMIFS($L$6:L17,$B$6:B17,$B17),2),"")) -> 280000 | O17: 收到工商银行转入 | P17: 内部调拨 | Q17: 工商银行基本户-8888 | S17: =IF($B17="","",IF(ISNA(MATCH($B17,账户名,0)),"※这个账户不在【参数设置】的账户档案里",IF($A17="","※没填日期，这一笔不会进任何月份的报表",IF(AND($G17<>"",$H17<>""),"※收入和支出不能同时填",IF(AND(N($G17)=0,N($H17)=0),"※收入和支出都没填",IF($E17="","※没填收支类别，分类报表会漏掉这一笔",IF(ISNA(MATCH($E17,类别表,0)),"※收支类别不在【参数设置】的清单里",IF($J17="","△"&$D17&" 还没填汇率，去【月度汇率】补上就自动算了",IF(YEAR($A17)<>管理年度,"△不是管理年度的单据，年报里看不到",IF(AND($F17="内部转账",$Q17=""),"△内部转账建议在「往来单位」写上对方账户",IF($M17<0,"△这一笔之后该账户余额成负数了，核一下","")))))))))))
A18: 46252 | B18: 中国银行美元结算户-6688 | C18: =IF($B18="","",IFERROR(INDEX(账户银行,MATCH($B18,账户名,0)),"")) -> 中国银行 | D18: =IF($B18="","",IFERROR(INDEX(账户币种,MATCH($B18,账户名,0)),"")) -> USD | E18: 销售回款 | F18: =IF($E18="","",IFERROR(INDEX(类别属性,MATCH($E18,类别表,0)),"")) -> 收入 | G18: 15000 | J18: =IF(OR($A18="",$B18=""),"",IF($I18<>"",$I18,IF($D18=本位币,1,IFERROR(LOOKUP(2,1/((汇率月份<=$A18)*(INDEX(记账汇率区,0,MATCH($D18,汇率币种头,0))<>"")),INDEX(记账汇率区,0,MATCH($D18,汇率币种头,0))),"")))) -> 7.18 | K18: =IF(AND($G18="",$H18=""),"",ROUND(N($G18)-N($H18),2)) -> 15000 | L18: =IF(OR($K18="",$J18=""),"",ROUND($K18*$J18,2)) -> 107700 | M18: =IF($B18="","",ROUND(SUMIF(账户名,$B18,账户期初)+SUMIFS($K$6:K18,$B$6:B18,$B18),2)) -> 832000 | N18: =IF($B18="","",IFERROR(ROUND(INDEX(账户期初本位,MATCH($B18,账户名,0))+SUMIFS($L$6:L18,$B$6:B18,$B18),2),"")) -> 5949920 | O18: 第二笔美元回款 | P18: 出口业务 | Q18: Overseas Client C | S18: =IF($B18="","",IF(ISNA(MATCH($B18,账户名,0)),"※这个账户不在【参数设置】的账户档案里",IF($A18="","※没填日期，这一笔不会进任何月份的报表",IF(AND($G18<>"",$H18<>""),"※收入和支出不能同时填",IF(AND(N($G18)=0,N($H18)=0),"※收入和支出都没填",IF($E18="","※没填收支类别，分类报表会漏掉这一笔",IF(ISNA(MATCH($E18,类别表,0)),"※收支类别不在【参数设置】的清单里",IF($J18="","△"&$D18&" 还没填汇率，去【月度汇率】补上就自动算了",IF(YEAR($A18)<>管理年度,"△不是管理年度的单据，年报里看不到",IF(AND($F18="内部转账",$Q18=""),"△内部转账建议在「往来单位」写上对方账户",IF($M18<0,"△这一笔之后该账户余额成负数了，核一下","")))))))))))
A19: 46253 | B19: 汇丰银行港币结算户-5566 | C19: =IF($B19="","",IFERROR(INDEX(账户银行,MATCH($B19,账户名,0)),"")) -> 汇丰银行 | D19: =IF($B19="","",IFERROR(INDEX(账户币种,MATCH($B19,账户名,0)),"")) -> HKD | E19: 运营费用 | F19: =IF($E19="","",IFERROR(INDEX(类别属性,MATCH($E19,类别表,0)),"")) -> 支出 | H19: 20000 | J19: =IF(OR($A19="",$B19=""),"",IF($I19<>"",$I19,IF($D19=本位币,1,IFERROR(LOOKUP(2,1/((汇率月份<=$A19)*(INDEX(记账汇率区,0,MATCH($D19,汇率币种头,0))<>"")),INDEX(记账汇率区,0,MATCH($D19,汇率币种头,0))),"")))) -> 0.92 | K19: =IF(AND($G19="",$H19=""),"",ROUND(N($G19)-N($H19),2)) -> -20000 | L19: =IF(OR($K19="",$J19=""),"",ROUND($K19*$J19,2)) -> -18400 | M19: =IF($B19="","",ROUND(SUMIF(账户名,$B19,账户期初)+SUMIFS($K$6:K19,$B$6:B19,$B19),2)) -> 355500 | N19: =IF($B19="","",IFERROR(ROUND(INDEX(账户期初本位,MATCH($B19,账户名,0))+SUMIFS($L$6:L19,$B$6:B19,$B19),2),"")) -> 325560 | O19: 香港运营费 | P19: 行政 | Q19: 香港办公室 | S19: =IF($B19="","",IF(ISNA(MATCH($B19,账户名,0)),"※这个账户不在【参数设置】的账户档案里",IF($A19="","※没填日期，这一笔不会进任何月份的报表",IF(AND($G19<>"",$H19<>""),"※收入和支出不能同时填",IF(AND(N($G19)=0,N($H19)=0),"※收入和支出都没填",IF($E19="","※没填收支类别，分类报表会漏掉这一笔",IF(ISNA(MATCH($E19,类别表,0)),"※收支类别不在【参数设置】的清单里",IF($J19="","△"&$D19&" 还没填汇率，去【月度汇率】补上就自动算了",IF(YEAR($A19)<>管理年度,"△不是管理年度的单据，年报里看不到",IF(AND($F19="内部转账",$Q19=""),"△内部转账建议在「往来单位」写上对方账户",IF($M19<0,"△这一笔之后该账户余额成负数了，核一下","")))))))))))
A20: 46254 | B20: 中国银行欧元结算户-9900 | C20: =IF($B20="","",IFERROR(INDEX(账户银行,MATCH($B20,账户名,0)),"")) -> 中国银行 | D20: =IF($B20="","",IFERROR(INDEX(账户币种,MATCH($B20,账户名,0)),"")) -> EUR | E20: 销售回款 | F20: =IF($E20="","",IFERROR(INDEX(类别属性,MATCH($E20,类别表,0)),"")) -> 收入 | G20: 30000 | J20: =IF(OR($A20="",$B20=""),"",IF($I20<>"",$I20,IF($D20=本位币,1,IFERROR(LOOKUP(2,1/((汇率月份<=$A20)*(INDEX(记账汇率区,0,MATCH($D20,汇率币种头,0))<>"")),INDEX(记账汇率区,0,MATCH($D20,汇率币种头,0))),"")))) -> 7.69 | K20: =IF(AND($G20="",$H20=""),"",ROUND(N($G20)-N($H20),2)) -> 30000 | L20: =IF(OR($K20="",$J20=""),"",ROUND($K20*$J20,2)) -> 230700 | M20: =IF($B20="","",ROUND(SUMIF(账户名,$B20,账户期初)+SUMIFS($K$6:K20,$B$6:B20,$B20),2)) -> 150000 | N20: =IF($B20="","",IFERROR(ROUND(INDEX(账户期初本位,MATCH($B20,账户名,0))+SUMIFS($L$6:L20,$B$6:B20,$B20),2),"")) -> 1153500 | O20: 欧元货款（欧元汇率还没填，看核对列） | P20: 欧洲业务 | Q20: 欧洲客户D | S20: =IF($B20="","",IF(ISNA(MATCH($B20,账户名,0)),"※这个账户不在【参数设置】的账户档案里",IF($A20="","※没填日期，这一笔不会进任何月份的报表",IF(AND($G20<>"",$H20<>""),"※收入和支出不能同时填",IF(AND(N($G20)=0,N($H20)=0),"※收入和支出都没填",IF($E20="","※没填收支类别，分类报表会漏掉这一笔",IF(ISNA(MATCH($E20,类别表,0)),"※收支类别不在【参数设置】的清单里",IF($J20="","△"&$D20&" 还没填汇率，去【月度汇率】补上就自动算了",IF(YEAR($A20)<>管理年度,"△不是管理年度的单据，年报里看不到",IF(AND($F20="内部转账",$Q20=""),"△内部转账建议在「往来单位」写上对方账户",IF($M20<0,"△这一笔之后该账户余额成负数了，核一下","")))))))))))
A21: 46255 | B21: 工商银行基本户-8888 | C21: =IF($B21="","",IFERROR(INDEX(账户银行,MATCH($B21,账户名,0)),"")) -> 工商银行 | D21: =IF($B21="","",IFERROR(INDEX(账户币种,MATCH($B21,账户名,0)),"")) -> CNY | E21: 其他业务收入 | F21: =IF($E21="","",IFERROR(INDEX(类别属性,MATCH($E21,类别表,0)),"")) -> 收入 | G21: 35000 | J21: =IF(OR($A21="",$B21=""),"",IF($I21<>"",$I21,IF($D21=本位币,1,IFERROR(LOOKUP(2,1/((汇率月份<=$A21)*(INDEX(记账汇率区,0,MATCH($D21,汇率币种头,0))<>"")),INDEX(记账汇率区,0,MATCH($D21,汇率币种头,0))),"")))) -> 1 | K21: =IF(AND($G21="",$H21=""),"",ROUND(N($G21)-N($H21),2)) -> 35000 | L21: =IF(OR($K21="",$J21=""),"",ROUND($K21*$J21,2)) -> 35000 | M21: =IF($B21="","",ROUND(SUMIF(账户名,$B21,账户期初)+SUMIFS($K$6:K21,$B$6:B21,$B21),2)) -> 587000 | N21: =IF($B21="","",IFERROR(ROUND(INDEX(账户期初本位,MATCH($B21,账户名,0))+SUMIFS($L$6:L21,$B$6:B21,$B21),2),"")) -> 587000 | O21: 其他经营收入 | P21: 其他业务 | Q21: 其他客户 | S21: =IF($B21="","",IF(ISNA(MATCH($B21,账户名,0)),"※这个账户不在【参数设置】的账户档案里",IF($A21="","※没填日期，这一笔不会进任何月份的报表",IF(AND($G21<>"",$H21<>""),"※收入和支出不能同时填",IF(AND(N($G21)=0,N($H21)=0),"※收入和支出都没填",IF($E21="","※没填收支类别，分类报表会漏掉这一笔",IF(ISNA(MATCH($E21,类别表,0)),"※收支类别不在【参数设置】的清单里",IF($J21="","△"&$D21&" 还没填汇率，去【月度汇率】补上就自动算了",IF(YEAR($A21)<>管理年度,"△不是管理年度的单据，年报里看不到",IF(AND($F21="内部转账",$Q21=""),"△内部转账建议在「往来单位」写上对方账户",IF($M21<0,"△这一笔之后该账户余额成负数了，核一下","")))))))))))
A22: 46259 | B22: 中国银行美元结算户-6688 | C22: =IF($B22="","",IFERROR(INDEX(账户银行,MATCH($B22,账户名,0)),"")) -> 中国银行 | D22: =IF($B22="","",IFERROR(INDEX(账户币种,MATCH($B22,账户名,0)),"")) -> USD | E22: 购汇/结汇 | F22: =IF($E22="","",IFERROR(INDEX(类别属性,MATCH($E22,类别表,0)),"")) -> 内部转账 | H22: 20000 | I22: 7.17 | J22: =IF(OR($A22="",$B22=""),"",IF($I22<>"",$I22,IF($D22=本位币,1,IFERROR(LOOKUP(2,1/((汇率月份<=$A22)*(INDEX(记账汇率区,0,MATCH($D22,汇率币种头,0))<>"")),INDEX(记账汇率区,0,MATCH($D22,汇率币种头,0))),"")))) -> 7.17 | K22: =IF(AND($G22="",$H22=""),"",ROUND(N($G22)-N($H22),2)) -> -20000 | L22: =IF(OR($K22="",$J22=""),"",ROUND($K22*$J22,2)) -> -143400 | M22: {=IF($B22="","",ROUND(SUMIF(账户名,$B22,账户期初)+SUMIFS($K$6:K22,$B$6:B22,$B22),2))} -> 812000 | N22: =IF($B22="","",IFERROR(ROUND(INDEX(账户期初本位,MATCH($B22,账户名,0))+SUMIFS($L$6:L22,$B$6:B22,$B22),2),"")) -> 5806520 | O22: 结汇：美元转出 | P22: 内部调拨 | Q22: 工商银行基本户-8888 | S22: =IF($B22="","",IF(ISNA(MATCH($B22,账户名,0)),"※这个账户不在【参数设置】的账户档案里",IF($A22="","※没填日期，这一笔不会进任何月份的报表",IF(AND($G22<>"",$H22<>""),"※收入和支出不能同时填",IF(AND(N($G22)=0,N($H22)=0),"※收入和支出都没填",IF($E22="","※没填收支类别，分类报表会漏掉这一笔",IF(ISNA(MATCH($E22,类别表,0)),"※收支类别不在【参数设置】的清单里",IF($J22="","△"&$D22&" 还没填汇率，去【月度汇率】补上就自动算了",IF(YEAR($A22)<>管理年度,"△不是管理年度的单据，年报里看不到",IF(AND($F22="内部转账",$Q22=""),"△内部转账建议在「往来单位」写上对方账户",IF($M22<0,"△这一笔之后该账户余额成负数了，核一下","")))))))))))
A23: 46259 | B23: 工商银行基本户-8888 | C23: =IF($B23="","",IFERROR(INDEX(账户银行,MATCH($B23,账户名,0)),"")) -> 工商银行 | D23: =IF($B23="","",IFERROR(INDEX(账户币种,MATCH($B23,账户名,0)),"")) -> CNY | E23: 购汇/结汇 | F23: =IF($E23="","",IFERROR(INDEX(类别属性,MATCH($E23,类别表,0)),"")) -> 内部转账 | G23: 143400 | J23: =IF(OR($A23="",$B23=""),"",IF($I23<>"",$I23,IF($D23=本位币,1,IFERROR(LOOKUP(2,1/((汇率月份<=$A23)*(INDEX(记账汇率区,0,MATCH($D23,汇率币种头,0))<>"")),INDEX(记账汇率区,0,MATCH($D23,汇率币种头,0))),"")))) -> 1 | K23: =IF(AND($G23="",$H23=""),"",ROUND(N($G23)-N($H23),2)) -> 143400 | L23: =IF(OR($K23="",$J23=""),"",ROUND($K23*$J23,2)) -> 143400 | M23: =IF($B23="","",ROUND(SUMIF(账户名,$B23,账户期初)+SUMIFS($K$6:K23,$B$6:B23,$B23),2)) -> 730400 | N23: =IF($B23="","",IFERROR(ROUND(INDEX(账户期初本位,MATCH($B23,账户名,0))+SUMIFS($L$6:L23,$B$6:B23,$B23),2),"")) -> 730400 | O23: 结汇：人民币到账 | P23: 内部调拨 | Q23: 中国银行美元结算户-6688 | S23: =IF($B23="","",IF(ISNA(MATCH($B23,账户名,0)),"※这个账户不在【参数设置】的账户档案里",IF($A23="","※没填日期，这一笔不会进任何月份的报表",IF(AND($G23<>"",$H23<>""),"※收入和支出不能同时填",IF(AND(N($G23)=0,N($H23)=0),"※收入和支出都没填",IF($E23="","※没填收支类别，分类报表会漏掉这一笔",IF(ISNA(MATCH($E23,类别表,0)),"※收支类别不在【参数设置】的清单里",IF($J23="","△"&$D23&" 还没填汇率，去【月度汇率】补上就自动算了",IF(YEAR($A23)<>管理年度,"△不是管理年度的单据，年报里看不到",IF(AND($F23="内部转账",$Q23=""),"△内部转账建议在「往来单位」写上对方账户",IF($M23<0,"△这一笔之后该账户余额成负数了，核一下","")))))))))))
C24: =IF($B24="","",IFERROR(INDEX(账户银行,MATCH($B24,账户名,0)),"")) | D24: =IF($B24="","",IFERROR(INDEX(账户币种,MATCH($B24,账户名,0)),"")) | F24: =IF($E24="","",IFERROR(INDEX(类别属性,MATCH($E24,类别表,0)),"")) | J24: =IF(OR($A24="",$B24=""),"",IF($I24<>"",$I24,IF($D24=本位币,1,IFERROR(LOOKUP(2,1/((汇率月份<=$A24)*(INDEX(记账汇率区,0,MATCH($D24,汇率币种头,0))<>"")),INDEX(记账汇率区,0,MATCH($D24,汇率币种头,0))),"")))) | K24: =IF(AND($G24="",$H24=""),"",ROUND(N($G24)-N($H24),2)) | L24: =IF(OR($K24="",$J24=""),"",ROUND($K24*$J24,2)) | M24: =IF($B24="","",ROUND(SUMIF(账户名,$B24,账户期初)+SUMIFS($K$6:K24,$B$6:B24,$B24),2)) | N24: =IF($B24="","",IFERROR(ROUND(INDEX(账户期初本位,MATCH($B24,账户名,0))+SUMIFS($L$6:L24,$B$6:B24,$B24),2),"")) | S24: =IF($B24="","",IF(ISNA(MATCH($B24,账户名,0)),"※这个账户不在【参数设置】的账户档案里",IF($A24="","※没填日期，这一笔不会进任何月份的报表",IF(AND($G24<>"",$H24<>""),"※收入和支出不能同时填",IF(AND(N($G24)=0,N($H24)=0),"※收入和支出都没填",IF($E24="","※没填收支类别，分类报表会漏掉这一笔",IF(ISNA(MATCH($E24,类别表,0)),"※收支类别不在【参数设置】的清单里",IF($J24="","△"&$D24&" 还没填汇率，去【月度汇率】补上就自动算了",IF(YEAR($A24)<>管理年度,"△不是管理年度的单据，年报里看不到",IF(AND($F24="内部转账",$Q24=""),"△内部转账建议在「往来单位」写上对方账户",IF($M24<0,"△这一笔之后该账户余额成负数了，核一下","")))))))))))
C25: =IF($B25="","",IFERROR(INDEX(账户银行,MATCH($B25,账户名,0)),"")) | D25: =IF($B25="","",IFERROR(INDEX(账户币种,MATCH($B25,账户名,0)),"")) | F25: =IF($E25="","",IFERROR(INDEX(类别属性,MATCH($E25,类别表,0)),"")) | J25: =IF(OR($A25="",$B25=""),"",IF($I25<>"",$I25,IF($D25=本位币,1,IFERROR(LOOKUP(2,1/((汇率月份<=$A25)*(INDEX(记账汇率区,0,MATCH($D25,汇率币种头,0))<>"")),INDEX(记账汇率区,0,MATCH($D25,汇率币种头,0))),"")))) | K25: =IF(AND($G25="",$H25=""),"",ROUND(N($G25)-N($H25),2)) | L25: =IF(OR($K25="",$J25=""),"",ROUND($K25*$J25,2)) | M25: =IF($B25="","",ROUND(SUMIF(账户名,$B25,账户期初)+SUMIFS($K$6:K25,$B$6:B25,$B25),2)) | N25: =IF($B25="","",IFERROR(ROUND(INDEX(账户期初本位,MATCH($B25,账户名,0))+SUMIFS($L$6:L25,$B$6:B25,$B25),2),"")) | S25: =IF($B25="","",IF(ISNA(MATCH($B25,账户名,0)),"※这个账户不在【参数设置】的账户档案里",IF($A25="","※没填日期，这一笔不会进任何月份的报表",IF(AND($G25<>"",$H25<>""),"※收入和支出不能同时填",IF(AND(N($G25)=0,N($H25)=0),"※收入和支出都没填",IF($E25="","※没填收支类别，分类报表会漏掉这一笔",IF(ISNA(MATCH($E25,类别表,0)),"※收支类别不在【参数设置】的清单里",IF($J25="","△"&$D25&" 还没填汇率，去【月度汇率】补上就自动算了",IF(YEAR($A25)<>管理年度,"△不是管理年度的单据，年报里看不到",IF(AND($F25="内部转账",$Q25=""),"△内部转账建议在「往来单位」写上对方账户",IF($M25<0,"△这一笔之后该账户余额成负数了，核一下","")))))))))))
C26: =IF($B26="","",IFERROR(INDEX(账户银行,MATCH($B26,账户名,0)),"")) | D26: =IF($B26="","",IFERROR(INDEX(账户币种,MATCH($B26,账户名,0)),"")) | F26: =IF($E26="","",IFERROR(INDEX(类别属性,MATCH($E26,类别表,0)),"")) | J26: =IF(OR($A26="",$B26=""),"",IF($I26<>"",$I26,IF($D26=本位币,1,IFERROR(LOOKUP(2,1/((汇率月份<=$A26)*(INDEX(记账汇率区,0,MATCH($D26,汇率币种头,0))<>"")),INDEX(记账汇率区,0,MATCH($D26,汇率币种头,0))),"")))) | K26: =IF(AND($G26="",$H26=""),"",ROUND(N($G26)-N($H26),2)) | L26: =IF(OR($K26="",$J26=""),"",ROUND($K26*$J26,2)) | M26: =IF($B26="","",ROUND(SUMIF(账户名,$B26,账户期初)+SUMIFS($K$6:K26,$B$6:B26,$B26),2)) | N26: =IF($B26="","",IFERROR(ROUND(INDEX(账户期初本位,MATCH($B26,账户名,0))+SUMIFS($L$6:L26,$B$6:B26,$B26),2),"")) | S26: =IF($B26="","",IF(ISNA(MATCH($B26,账户名,0)),"※这个账户不在【参数设置】的账户档案里",IF($A26="","※没填日期，这一笔不会进任何月份的报表",IF(AND($G26<>"",$H26<>""),"※收入和支出不能同时填",IF(AND(N($G26)=0,N($H26)=0),"※收入和支出都没填",IF($E26="","※没填收支类别，分类报表会漏掉这一笔",IF(ISNA(MATCH($E26,类别表,0)),"※收支类别不在【参数设置】的清单里",IF($J26="","△"&$D26&" 还没填汇率，去【月度汇率】补上就自动算了",IF(YEAR($A26)<>管理年度,"△不是管理年度的单据，年报里看不到",IF(AND($F26="内部转账",$Q26=""),"△内部转账建议在「往来单位」写上对方账户",IF($M26<0,"△这一笔之后该账户余额成负数了，核一下","")))))))))))
C27: =IF($B27="","",IFERROR(INDEX(账户银行,MATCH($B27,账户名,0)),"")) | D27: =IF($B27="","",IFERROR(INDEX(账户币种,MATCH($B27,账户名,0)),"")) | F27: =IF($E27="","",IFERROR(INDEX(类别属性,MATCH($E27,类别表,0)),"")) | J27: =IF(OR($A27="",$B27=""),"",IF($I27<>"",$I27,IF($D27=本位币,1,IFERROR(LOOKUP(2,1/((汇率月份<=$A27)*(INDEX(记账汇率区,0,MATCH($D27,汇率币种头,0))<>"")),INDEX(记账汇率区,0,MATCH($D27,汇率币种头,0))),"")))) | K27: =IF(AND($G27="",$H27=""),"",ROUND(N($G27)-N($H27),2)) | L27: =IF(OR($K27="",$J27=""),"",ROUND($K27*$J27,2)) | M27: =IF($B27="","",ROUND(SUMIF(账户名,$B27,账户期初)+SUMIFS($K$6:K27,$B$6:B27,$B27),2)) | N27: =IF($B27="","",IFERROR(ROUND(INDEX(账户期初本位,MATCH($B27,账户名,0))+SUMIFS($L$6:L27,$B$6:B27,$B27),2),"")) | S27: =IF($B27="","",IF(ISNA(MATCH($B27,账户名,0)),"※这个账户不在【参数设置】的账户档案里",IF($A27="","※没填日期，这一笔不会进任何月份的报表",IF(AND($G27<>"",$H27<>""),"※收入和支出不能同时填",IF(AND(N($G27)=0,N($H27)=0),"※收入和支出都没填",IF($E27="","※没填收支类别，分类报表会漏掉这一笔",IF(ISNA(MATCH($E27,类别表,0)),"※收支类别不在【参数设置】的清单里",IF($J27="","△"&$D27&" 还没填汇率，去【月度汇率】补上就自动算了",IF(YEAR($A27)<>管理年度,"△不是管理年度的单据，年报里看不到",IF(AND($F27="内部转账",$Q27=""),"△内部转账建议在「往来单位」写上对方账户",IF($M27<0,"△这一笔之后该账户余额成负数了，核一下","")))))))))))
C28: =IF($B28="","",IFERROR(INDEX(账户银行,MATCH($B28,账户名,0)),"")) | D28: =IF($B28="","",IFERROR(INDEX(账户币种,MATCH($B28,账户名,0)),"")) | F28: =IF($E28="","",IFERROR(INDEX(类别属性,MATCH($E28,类别表,0)),"")) | J28: =IF(OR($A28="",$B28=""),"",IF($I28<>"",$I28,IF($D28=本位币,1,IFERROR(LOOKUP(2,1/((汇率月份<=$A28)*(INDEX(记账汇率区,0,MATCH($D28,汇率币种头,0))<>"")),INDEX(记账汇率区,0,MATCH($D28,汇率币种头,0))),"")))) | K28: =IF(AND($G28="",$H28=""),"",ROUND(N($G28)-N($H28),2)) | L28: =IF(OR($K28="",$J28=""),"",ROUND($K28*$J28,2)) | M28: =IF($B28="","",ROUND(SUMIF(账户名,$B28,账户期初)+SUMIFS($K$6:K28,$B$6:B28,$B28),2)) | N28: =IF($B28="","",IFERROR(ROUND(INDEX(账户期初本位,MATCH($B28,账户名,0))+SUMIFS($L$6:L28,$B$6:B28,$B28),2),"")) | S28: =IF($B28="","",IF(ISNA(MATCH($B28,账户名,0)),"※这个账户不在【参数设置】的账户档案里",IF($A28="","※没填日期，这一笔不会进任何月份的报表",IF(AND($G28<>"",$H28<>""),"※收入和支出不能同时填",IF(AND(N($G28)=0,N($H28)=0),"※收入和支出都没填",IF($E28="","※没填收支类别，分类报表会漏掉这一笔",IF(ISNA(MATCH($E28,类别表,0)),"※收支类别不在【参数设置】的清单里",IF($J28="","△"&$D28&" 还没填汇率，去【月度汇率】补上就自动算了",IF(YEAR($A28)<>管理年度,"△不是管理年度的单据，年报里看不到",IF(AND($F28="内部转账",$Q28=""),"△内部转账建议在「往来单位」写上对方账户",IF($M28<0,"△这一笔之后该账户余额成负数了，核一下","")))))))))))
C29: =IF($B29="","",IFERROR(INDEX(账户银行,MATCH($B29,账户名,0)),"")) | D29: =IF($B29="","",IFERROR(INDEX(账户币种,MATCH($B29,账户名,0)),"")) | F29: =IF($E29="","",IFERROR(INDEX(类别属性,MATCH($E29,类别表,0)),"")) | J29: =IF(OR($A29="",$B29=""),"",IF($I29<>"",$I29,IF($D29=本位币,1,IFERROR(LOOKUP(2,1/((汇率月份<=$A29)*(INDEX(记账汇率区,0,MATCH($D29,汇率币种头,0))<>"")),INDEX(记账汇率区,0,MATCH($D29,汇率币种头,0))),"")))) | K29: =IF(AND($G29="",$H29=""),"",ROUND(N($G29)-N($H29),2)) | L29: =IF(OR($K29="",$J29=""),"",ROUND($K29*$J29,2)) | M29: =IF($B29="","",ROUND(SUMIF(账户名,$B29,账户期初)+SUMIFS($K$6:K29,$B$6:B29,$B29),2)) | N29: =IF($B29="","",IFERROR(ROUND(INDEX(账户期初本位,MATCH($B29,账户名,0))+SUMIFS($L$6:L29,$B$6:B29,$B29),2),"")) | S29: =IF($B29="","",IF(ISNA(MATCH($B29,账户名,0)),"※这个账户不在【参数设置】的账户档案里",IF($A29="","※没填日期，这一笔不会进任何月份的报表",IF(AND($G29<>"",$H29<>""),"※收入和支出不能同时填",IF(AND(N($G29)=0,N($H29)=0),"※收入和支出都没填",IF($E29="","※没填收支类别，分类报表会漏掉这一笔",IF(ISNA(MATCH($E29,类别表,0)),"※收支类别不在【参数设置】的清单里",IF($J29="","△"&$D29&" 还没填汇率，去【月度汇率】补上就自动算了",IF(YEAR($A29)<>管理年度,"△不是管理年度的单据，年报里看不到",IF(AND($F29="内部转账",$Q29=""),"△内部转账建议在「往来单位」写上对方账户",IF($M29<0,"△这一笔之后该账户余额成负数了，核一下","")))))))))))
C30: =IF($B30="","",IFERROR(INDEX(账户银行,MATCH($B30,账户名,0)),"")) | D30: =IF($B30="","",IFERROR(INDEX(账户币种,MATCH($B30,账户名,0)),"")) | F30: =IF($E30="","",IFERROR(INDEX(类别属性,MATCH($E30,类别表,0)),"")) | J30: =IF(OR($A30="",$B30=""),"",IF($I30<>"",$I30,IF($D30=本位币,1,IFERROR(LOOKUP(2,1/((汇率月份<=$A30)*(INDEX(记账汇率区,0,MATCH($D30,汇率币种头,0))<>"")),INDEX(记账汇率区,0,MATCH($D30,汇率币种头,0))),"")))) | K30: =IF(AND($G30="",$H30=""),"",ROUND(N($G30)-N($H30),2)) | L30: =IF(OR($K30="",$J30=""),"",ROUND($K30*$J30,2)) | M30: =IF($B30="","",ROUND(SUMIF(账户名,$B30,账户期初)+SUMIFS($K$6:K30,$B$6:B30,$B30),2)) | N30: =IF($B30="","",IFERROR(ROUND(INDEX(账户期初本位,MATCH($B30,账户名,0))+SUMIFS($L$6:L30,$B$6:B30,$B30),2),"")) | S30: =IF($B30="","",IF(ISNA(MATCH($B30,账户名,0)),"※这个账户不在【参数设置】的账户档案里",IF($A30="","※没填日期，这一笔不会进任何月份的报表",IF(AND($G30<>"",$H30<>""),"※收入和支出不能同时填",IF(AND(N($G30)=0,N($H30)=0),"※收入和支出都没填",IF($E30="","※没填收支类别，分类报表会漏掉这一笔",IF(ISNA(MATCH($E30,类别表,0)),"※收支类别不在【参数设置】的清单里",IF($J30="","△"&$D30&" 还没填汇率，去【月度汇率】补上就自动算了",IF(YEAR($A30)<>管理年度,"△不是管理年度的单据，年报里看不到",IF(AND($F30="内部转账",$Q30=""),"△内部转账建议在「往来单位」写上对方账户",IF($M30<0,"△这一笔之后该账户余额成负数了，核一下","")))))))))))
C31: =IF($B31="","",IFERROR(INDEX(账户银行,MATCH($B31,账户名,0)),"")) | D31: =IF($B31="","",IFERROR(INDEX(账户币种,MATCH($B31,账户名,0)),"")) | F31: =IF($E31="","",IFERROR(INDEX(类别属性,MATCH($E31,类别表,0)),"")) | J31: =IF(OR($A31="",$B31=""),"",IF($I31<>"",$I31,IF($D31=本位币,1,IFERROR(LOOKUP(2,1/((汇率月份<=$A31)*(INDEX(记账汇率区,0,MATCH($D31,汇率币种头,0))<>"")),INDEX(记账汇率区,0,MATCH($D31,汇率币种头,0))),"")))) | K31: =IF(AND($G31="",$H31=""),"",ROUND(N($G31)-N($H31),2)) | L31: =IF(OR($K31="",$J31=""),"",ROUND($K31*$J31,2)) | M31: =IF($B31="","",ROUND(SUMIF(账户名,$B31,账户期初)+SUMIFS($K$6:K31,$B$6:B31,$B31),2)) | N31: =IF($B31="","",IFERROR(ROUND(INDEX(账户期初本位,MATCH($B31,账户名,0))+SUMIFS($L$6:L31,$B$6:B31,$B31),2),"")) | S31: =IF($B31="","",IF(ISNA(MATCH($B31,账户名,0)),"※这个账户不在【参数设置】的账户档案里",IF($A31="","※没填日期，这一笔不会进任何月份的报表",IF(AND($G31<>"",$H31<>""),"※收入和支出不能同时填",IF(AND(N($G31)=0,N($H31)=0),"※收入和支出都没填",IF($E31="","※没填收支类别，分类报表会漏掉这一笔",IF(ISNA(MATCH($E31,类别表,0)),"※收支类别不在【参数设置】的清单里",IF($J31="","△"&$D31&" 还没填汇率，去【月度汇率】补上就自动算了",IF(YEAR($A31)<>管理年度,"△不是管理年度的单据，年报里看不到",IF(AND($F31="内部转账",$Q31=""),"△内部转账建议在「往来单位」写上对方账户",IF($M31<0,"△这一笔之后该账户余额成负数了，核一下","")))))))))))
