Workbook

Sheet 主页
A1: 03 财 务 账 套 与 报 表
A2: 小企业会计准则 ｜ 全部按含税金额记账 ｜ 与 01、02 两本业务册跨文件自动联动 ｜ 点下面蓝色表名可直接跳转
A3: =IF(N(对接源_01水果!$T$1)+N(对接源_02物料!$T$1)=0,"联动状态：★★ 两本业务册的数据都没接进来 —— 请打开对接源表按提示修复链接",IF(N(对接源_01水果!$T$4)*N(对接源_02物料!$T$4)*N(对接源_01入库吨位!$V$4)=0,"联动状态：⚠ 有业务册在用【应急备份】数据（不是实时数），请尽快修复链接","联动状态：✔ 正常 —— 01水果 "&N(对接源_01水果!$T$1)&" 行 ＋ 02物料 "&N(对接源_02物料!$T$1)&" 行 ＋ 01入库吨位 "&N(对接源_01入库吨位!$V$1)&" 行已自动接入")) -> 联动状态：✔ 正常 —— 01水果 11 行 ＋ 02物料 5 行 ＋ 01入库吨位 22 行已自动接入
A5: 一、跨册对接（自动取数，勿手工填）
A6: 序号 | B6: 子表名称 | C6: 用途说明 | D6: 属性
A7: 1 | B7: 对接源_01水果 | C7: 跨文件取《01》财务取数接口（24 个月收入成本 ＋ 按客户往来） | D7: 自动
A8: 2 | B8: 对接源_02物料 | C8: 跨文件取《02》财务取数接口 | D8: 自动
A9: 3 | B9: 对接源_01入库吨位 | C9: 跨文件取《01》入库吨位汇总：周转打冷／仓储加工的筐数、总重、吨位 | D9: 自动
A10: 4 | B10: 进销存对接 | C10: 合并两张对接源，配科目；全部按含税金额记账 | D10: 自动
A12: 二、日常录入
A13: 序号 | B13: 子表名称 | C13: 用途说明 | D13: 属性
A14: 5 | B14: 原料入库计价 | C14: ★全展开：每个货主＋品种自动拆 周转打冷/仓储加工/装卸费 三行，只填计价方式与单价 | D14: 录入+自动
A15: 6 | B15: 资金日记账 | C15: 出纳每天记收付款（已去掉凭证字号/票据/经办人）；支出选费用项目就自动进成本 | D15: 录入
A16: 7 | B16: 成本费用登记表 | C16: 费用发生额与本单已付金额，差额＝应付账款 | D16: 录入
A17: 8 | B17: 对账补充行 | C17: 借款、还款、优惠、抹零等台账里没有、对账单要体现的行 | D17: 录入
A18: 9 | B18: 期初余额 | C18: 建账时填一次 | D18: 录入
A20: 三、账簿 · 往来 · 成本（全部自动）
A21: 序号 | B21: 子表名称 | C21: 用途说明 | D21: 属性
A22: 10 | B22: 记账凭证 | C22: 按进销存对接、资金日记账、成本费用表自动生成，手工区在 3010 行以后 | D22: 自动
A23: 11 | B23: 资金与往来余额表 | C23: 资金账户结存与往来单位余额 | D23: 自动
A24: 12 | B24: 应收应付汇总表 | C24: 每家单位的应收、应付、净往来 | D24: 自动
A25: 13 | B25: 收入月度汇总 | C25: ★按【资金日记账】往来单位 × 24 个月统计收入 | D25: 自动
A26: 14 | B26: 费用月度汇总 | C26: 成本项目 × 24 个月，含合计发生额、已付、应付余额 | D26: 自动
A27: 15 | B27: 应付账款明细 | C27: 按供应商/对象看发生额、已付、还欠多少 | D27: 自动
A28: 16 | B28: 往来对账单 | C28: ★50 行分项汇总：仓储费/周转费/装卸费/成品销售/筐子款/物料款 ＋ 购买果品款（负数抵扣） | D28: 录入+自动
A29: 17 | B29: 科目余额表 | C29: ★起止日期总开关：期初＋本期发生＋期末 | D29: 录入+自动
A30: 18 | B30: 资产负债表 | C30: 跟科目余额表的日期走 | D30: 自动
A31: 19 | B31: 利润表 | C31: 本期与本年累计两套日期 | D31: 录入+自动
A33: 四、规则与码表
A34: 序号 | B34: 子表名称 | C34: 用途说明 | D34: 属性
A35: 20 | B35: 自动规则 | C35: 业务类型 → 收付款科目 | D35: 码表
A36: 21 | B36: 收入成本映射 | C36: 项目 → 记账类别与借贷科目（税率一律 0%，全部含税记账） | D36: 码表
A37: 22 | B37: 科目表 | C37: 会计科目 ＋ 往来单位/业务类型/收入项目/费用项目/费用对应科目 | D37: 码表
A38: 23 | B38: 常用分录参考 | C38: 常见业务的借贷科目参考 | D38: 码表
A40: 图例：浅绿＝公式自动生成，请勿覆盖 ｜ 浅蓝＝需要手工录入 ｜ 浅黄＝码表/规则，偶尔维护
A42: 本 轮 新 增
A43: 序号 | B43: 子表名称 | C43: 用途说明 | D43: 属性
A44: 1 | B44: =HYPERLINK("#'对接源_01库存'!A1","对接源_01库存") -> 对接源_01库存 | C44: 跨文件取《01》库存等级接口 | D44: 自动
A45: 2 | B45: =HYPERLINK("#'库存价值与欠款比对'!A1","库存价值与欠款比对") -> 库存价值与欠款比对 | C45: ★下半部分按等级填单价算库存价值，上半部分按客户比对「库存价值 ↔ 应收款 ↔ 差额」 | D45: 录入+自动

Sheet 使用说明
A1: 财 务 账 套 与 报 表 使 用 说 明
A2: 口径：小企业会计准则 ｜ 一般纳税人（价税分离）｜ 与两本业务册跨文件自动联动
B4: 一、三个文件必须放在同一个文件夹
B6: 01_水果进销存台账模板.xlsx
B7: 02_物料与周转物台账模板.xlsx
B8: 03_财务账套与报表模板.xlsx
B9: 文件名一个字都不要改，也不要分开存放，否则链接会断，单元格会变成错误值。
B10: 万一断了：Excel 顶部菜单【数据】→【编辑链接】→【更改源】，重新指向那两个文件即可，只需修一次。
B12: 二、每次打开要点“更新”
B14: 打开本文件时 Excel/WPS 会问“是否更新链接”，点【更新】，两本业务册的数就进来了。
B15: 如果没弹窗：【数据】→【编辑链接】→【立即更新值】。三个文件都打开时会实时联动。
B17: 三、数据怎么自动进来的
B19: 业务册明细（仓管每天录）→ 业务册【财务取数接口】按月自动汇总
B20: → 本册【对接源_01水果】/【对接源_02物料】各自跨文件取一本册子，来源册不用手工区分
... B73: 押金是欠客户的钱，不算收入；只有客户明确不退筐、押金转成赔偿时，才手工做一笔转其他业务收入。
A75: ★ 本 次 更 新（2026-09）
A76: 1、新增【原料入库计价】：原料入库的单价放在本册。上半部「原料入库单价表」按 货主＋品种 填计价方式与单价（货主填「通用」表示该品种通用价）；下半部自动按《01》的入库筐数/总重算出入库金额。计价方式三选一：按筐数×单价、按总重KG×单价、按吨位×单价。
A77: 2、新增【对接源_01入库吨位】：跨文件取《01》的入库吨位汇总（货主＋品种的筐数、总重、吨位），供上表计价用，断链时同样有应急备份区。
A78: 3、新增【对账补充行】：借款、还款、优惠、抹零、未退筐等台账里没有、但对账单要体现的行填在这里；金额自动＝数量×单价，也可用「金额手工覆盖」列直接写死（优惠、抹零填负数）。
A79: 4、【往来对账单】改成对账单版式：抬头＋客户/品类/电话，列为 日期｜摘要｜单位｜入库毛重｜单价｜金额（元）｜已付款｜备注；底部三行显示 对账日期／对账时段／是否含税 与 合计金额／已付款／应收款，最后一行黄底显示中文大写欠款金额，可直接打印。
A80: 5、对账单取数＝【原料入库计价】＋【资金日记账】＋【成本费用登记表】＋【对账补充行】四张表，按客户与起止日期自动筛选；「品类」栏自动汇总该客户的全部品种。
A82: ★ 本 次 更 新（2026-09 · 第三版）
A83: 1、【原料入库计价】重做：上表只填 货主/客户、品种、项目类别（周转打冷／仓储加工／装卸费／其他服务费）、计价方式，再填单价，数量与合计金额自动算；货主填「通用」＝该品种所有客户同价。下表按「货主＋品种＋项目类别」自动展开全部入库并套用单价，最下面还有按货主的汇总。
A84: 2、【对接源_01入库吨位】跟着 01 改版：新增「周转打冷入库总筐数」「仓储加工入库总筐数」以及两类各自的总重KG。
A85: 3、★应付账款怎么做：一切费用（工资、装卸费、电费、水费、差旅、维修、招待…）都在【成本费用登记表】登记，「价税合计」填本次发生额（＝成本），「本单已付金额」填已经付掉的钱，差额就是应付账款。例：本月电费 10000 元只付了 5000，就填 10000 和 5000，应付余额自动显示 5000。付款那笔现金流同时记到【资金日记账】。
A86: 4、★当场付清、不挂账的小额支出：可以只记【资金日记账】，在 W 列选「费用类别」、X 列填「否」，也会自动算进成本；如果这笔已经在成本费用表登记过，X 列填「是」，避免重复计算。
A87: 5、新增【费用月度汇总】：成本项目 × 24 个月的交叉表（只填 F2 起始年月），每月各项费用一目了然，右边还有合计发生额、其中已付、应付余额。
... A121: 5、装卸费怎么做账：收客户的那头在【原料入库计价】里按「装卸费」这一行填单价（比如 50 元/吨），自动进往来对账单的应收；付给装卸工的那头在【成本费用登记表】登记（费用项目＝装卸费，对象＝装卸队/员工，本单已付金额填实付），差额就是应付账款。两头都进【费用月度汇总】和利润表，毛利自动出来。

Sheet 对接源_01水果
A1: 对 接 源 · 01 水果进销存台账（跨文件自动取数 · 断链时自动改用应急备份） | S1: 有效行数 | T1: =MAX($Q$5:$Q$507) -> 11
A2: =IF($T$4=1,"✔ 链接正常，已自动取到 "&$T$1&" 行（只算有金额/数量的行） ｜ 本表 1:1 对应《01 水果进销存台账》的【财务取数接口】第 4～356 行，两本业务册必须和本文件放在同一个文件夹","★★ 链接没接上！当前取数来源："&$T$5&" → 见 S6 修复说明") -> ✔ 链接正常，已自动取到 11 行（只算有金额/数量的行） ｜ 本表 1:1 对应《01 水果进销存台账》的【财务取数接口】第 4～356 行，两本业务册必须和本文件放在同一个文件夹 | S2: 链接探针 | T2: =IFERROR(IF([1]财务取数接口!$C$4=0,"未更新",[1]财务取数接口!$C$4),"断开") -> 仓储费
A3: 一、实 际 使 用 值（链接正常时＝自动取数；链接断了自动切到右边备份） | I3: 二、应 急 备 份 区（手工粘贴数值） | P3: 状态 | S3: 备份行数 | T3: =COUNTIF($J$5:$J$507,"?*")-COUNTIF($J$5:$J$507,"项目") -> 0
A4: 源行 | B4: 年月 / 往来单位 | C4: 项目 | D4: 计费数量 / 应收发生额 | E4: 单位 / 应付发生额 | F4: 价税合计金额 | G4: 已收金额 | H4: 备注 | I4: 备份-年月 | J4: 备份-项目 | K4: 备份-数量 | L4: 备份-单位 | M4: 备份-金额 | N4: 备份-已收 | O4: 备份-备注 | P4: 有效 | Q4: 累计 | S4: 链接可用 | T4: =IF(OR($T$2="断开",$T$2="未更新"),0,1) -> 1
A5: 4 | B5: =IF($T$4=0,IF($I5="","",$I5),IFERROR(IF([1]财务取数接口!$B$4=0,"",[1]财务取数接口!$B$4),"")) -> 46235 | C5: =IF($T$4=0,IF($J5="","",$J5),IFERROR(IF([1]财务取数接口!$C$4=0,"",[1]财务取数接口!$C$4),"")) -> 仓储费 | D5: =IF($T$4=0,IF($K5="","",$K5),IFERROR(IF([1]财务取数接口!$D$4=0,"",[1]财务取数接口!$D$4),"")) | E5: =IF($T$4=0,IF($L5="","",$L5),IFERROR(IF([1]财务取数接口!$E$4=0,"",[1]财务取数接口!$E$4),"")) -> 筐 | F5: =IF($T$4=0,IF($M5="","",$M5),IFERROR(IF([1]财务取数接口!$G$4=0,"",[1]财务取数接口!$G$4),"")) | G5: =IF($T$4=0,IF($N5="","",$N5),IFERROR(IF([1]财务取数接口!$H$4=0,"",[1]财务取数接口!$H$4),"")) | H5: =IF($T$4=0,IF($O5="","",$O5),IFERROR(IF([1]财务取数接口!$I$4=0,"",[1]财务取数接口!$I$4),"")) | P5: =IF(AND($C5<>"",$C5<>"项目",OR(N($D5)<>0,N($E5)<>0,N($F5)<>0)),1,0) -> 0 | Q5: =N(Q4)+$P5 -> 0 | S5: 当前取数来源 | T5: =IF($T$4=1,"自动（跨文件链接）",IF($T$3>0,"应急备份","无数据")) -> 自动（跨文件链接）
A6: 5 | B6: =IF($T$4=0,IF($I6="","",$I6),IFERROR(IF([1]财务取数接口!$B$5=0,"",[1]财务取数接口!$B$5),"")) -> 46266 | C6: =IF($T$4=0,IF($J6="","",$J6),IFERROR(IF([1]财务取数接口!$C$5=0,"",[1]财务取数接口!$C$5),"")) -> 仓储费 | D6: =IF($T$4=0,IF($K6="","",$K6),IFERROR(IF([1]财务取数接口!$D$5=0,"",[1]财务取数接口!$D$5),"")) -> 20169 | E6: =IF($T$4=0,IF($L6="","",$L6),IFERROR(IF([1]财务取数接口!$E$5=0,"",[1]财务取数接口!$E$5),"")) -> 筐 | F6: =IF($T$4=0,IF($M6="","",$M6),IFERROR(IF([1]财务取数接口!$G$5=0,"",[1]财务取数接口!$G$5),"")) | G6: =IF($T$4=0,IF($N6="","",$N6),IFERROR(IF([1]财务取数接口!$H$5=0,"",[1]财务取数接口!$H$5),"")) | H6: =IF($T$4=0,IF($O6="","",$O6),IFERROR(IF([1]财务取数接口!$I$5=0,"",[1]财务取数接口!$I$5),"")) | P6: =IF(AND($C6<>"",$C6<>"项目",OR(N($D6)<>0,N($E6)<>0,N($F6)<>0)),1,0) -> 1 | Q6: =N(Q5)+$P6 -> 1 | S6: =IF($T$2="断开",IF($T$3>0,"✘ 链接已断开，正在用【应急备份区】的 "&$T$3&" 行数据出账（不是实时数）。修复：菜单【数据】→【编辑链接】→【更改源】，重新指向《01_水果进销存台账模板.xlsx》","✘ 链接已断开，而且应急备份区是空的，本册报表将缺少这本业务册的全部数据。修复：菜单【数据】→【编辑链接】→【更改源】，重新指向《01_水果进销存台账模板.xlsx》"),IF($T$2="未更新",IF($T$3>0,"★ 链接还没更新，或者那两个文件被改名、挪走了。正在用【应急备份区】的 "&$T$3&" 行数据出账（不是实时数）。修复：菜单【数据】→【编辑链接】→先点【立即更新值】；还是取不到数就点【更改源】重新指向《01_水果进销存台账模板.xlsx》","★ 链接还没更新，或者那两个文件被改名、挪走了，而且没有应急备份，本册报表会缺少这本业务册的全部数据。修复：菜单【数据】→【编辑链接】→先点【立即更新值】；还是取不到数就点【更改源】重新指向《01_水果进销存台账模板.xlsx》"),"✔ 链接正常，已自动取到 "&$T$1&" 行。备份区现有 "&$T$3&" 行。建议每月底把 B5:H168 复制→选择性粘贴【数值】到 I5，作为断链时的兜底")) -> ✔ 链接正常，已自动取到 11 行。备份区现有 0 行。建议每月底把 B5:H168 复制→选择性粘贴【数值】到 I5，作为断链时的兜底
A7: 6 | B7: =IF($T$4=0,IF($I7="","",$I7),IFERROR(IF([1]财务取数接口!$B$6=0,"",[1]财务取数接口!$B$6),"")) -> 46296 | C7: =IF($T$4=0,IF($J7="","",$J7),IFERROR(IF([1]财务取数接口!$C$6=0,"",[1]财务取数接口!$C$6),"")) -> 仓储费 | D7: =IF($T$4=0,IF($K7="","",$K7),IFERROR(IF([1]财务取数接口!$D$6=0,"",[1]财务取数接口!$D$6),"")) | E7: =IF($T$4=0,IF($L7="","",$L7),IFERROR(IF([1]财务取数接口!$E$6=0,"",[1]财务取数接口!$E$6),"")) -> 筐 | F7: =IF($T$4=0,IF($M7="","",$M7),IFERROR(IF([1]财务取数接口!$G$6=0,"",[1]财务取数接口!$G$6),"")) | G7: =IF($T$4=0,IF($N7="","",$N7),IFERROR(IF([1]财务取数接口!$H$6=0,"",[1]财务取数接口!$H$6),"")) | H7: =IF($T$4=0,IF($O7="","",$O7),IFERROR(IF([1]财务取数接口!$I$6=0,"",[1]财务取数接口!$I$6),"")) | P7: =IF(AND($C7<>"",$C7<>"项目",OR(N($D7)<>0,N($E7)<>0,N($F7)<>0)),1,0) -> 0 | Q7: =N(Q6)+$P7 -> 1
A8: 7 | B8: =IF($T$4=0,IF($I8="","",$I8),IFERROR(IF([1]财务取数接口!$B$7=0,"",[1]财务取数接口!$B$7),"")) -> 46327 | C8: =IF($T$4=0,IF($J8="","",$J8),IFERROR(IF([1]财务取数接口!$C$7=0,"",[1]财务取数接口!$C$7),"")) -> 仓储费 | D8: =IF($T$4=0,IF($K8="","",$K8),IFERROR(IF([1]财务取数接口!$D$7=0,"",[1]财务取数接口!$D$7),"")) | E8: =IF($T$4=0,IF($L8="","",$L8),IFERROR(IF([1]财务取数接口!$E$7=0,"",[1]财务取数接口!$E$7),"")) -> 筐 | F8: =IF($T$4=0,IF($M8="","",$M8),IFERROR(IF([1]财务取数接口!$G$7=0,"",[1]财务取数接口!$G$7),"")) | G8: =IF($T$4=0,IF($N8="","",$N8),IFERROR(IF([1]财务取数接口!$H$7=0,"",[1]财务取数接口!$H$7),"")) | H8: =IF($T$4=0,IF($O8="","",$O8),IFERROR(IF([1]财务取数接口!$I$7=0,"",[1]财务取数接口!$I$7),"")) | P8: =IF(AND($C8<>"",$C8<>"项目",OR(N($D8)<>0,N($E8)<>0,N($F8)<>0)),1,0) -> 0 | Q8: =N(Q7)+$P8 -> 1
A9: 8 | B9: =IF($T$4=0,IF($I9="","",$I9),IFERROR(IF([1]财务取数接口!$B$8=0,"",[1]财务取数接口!$B$8),"")) -> 46357 | C9: =IF($T$4=0,IF($J9="","",$J9),IFERROR(IF([1]财务取数接口!$C$8=0,"",[1]财务取数接口!$C$8),"")) -> 仓储费 | D9: =IF($T$4=0,IF($K9="","",$K9),IFERROR(IF([1]财务取数接口!$D$8=0,"",[1]财务取数接口!$D$8),"")) | E9: =IF($T$4=0,IF($L9="","",$L9),IFERROR(IF([1]财务取数接口!$E$8=0,"",[1]财务取数接口!$E$8),"")) -> 筐 | F9: =IF($T$4=0,IF($M9="","",$M9),IFERROR(IF([1]财务取数接口!$G$8=0,"",[1]财务取数接口!$G$8),"")) | G9: =IF($T$4=0,IF($N9="","",$N9),IFERROR(IF([1]财务取数接口!$H$8=0,"",[1]财务取数接口!$H$8),"")) | H9: =IF($T$4=0,IF($O9="","",$O9),IFERROR(IF([1]财务取数接口!$I$8=0,"",[1]财务取数接口!$I$8),"")) | P9: =IF(AND($C9<>"",$C9<>"项目",OR(N($D9)<>0,N($E9)<>0,N($F9)<>0)),1,0) -> 0 | Q9: =N(Q8)+$P9 -> 1
A10: 9 | B10: =IF($T$4=0,IF($I10="","",$I10),IFERROR(IF([1]财务取数接口!$B$9=0,"",[1]财务取数接口!$B$9),"")) -> 46388 | C10: =IF($T$4=0,IF($J10="","",$J10),IFERROR(IF([1]财务取数接口!$C$9=0,"",[1]财务取数接口!$C$9),"")) -> 仓储费 | D10: =IF($T$4=0,IF($K10="","",$K10),IFERROR(IF([1]财务取数接口!$D$9=0,"",[1]财务取数接口!$D$9),"")) | E10: =IF($T$4=0,IF($L10="","",$L10),IFERROR(IF([1]财务取数接口!$E$9=0,"",[1]财务取数接口!$E$9),"")) -> 筐 | F10: =IF($T$4=0,IF($M10="","",$M10),IFERROR(IF([1]财务取数接口!$G$9=0,"",[1]财务取数接口!$G$9),"")) | G10: =IF($T$4=0,IF($N10="","",$N10),IFERROR(IF([1]财务取数接口!$H$9=0,"",[1]财务取数接口!$H$9),"")) | H10: =IF($T$4=0,IF($O10="","",$O10),IFERROR(IF([1]财务取数接口!$I$9=0,"",[1]财务取数接口!$I$9),"")) | P10: =IF(AND($C10<>"",$C10<>"项目",OR(N($D10)<>0,N($E10)<>0,N($F10)<>0)),1,0) -> 0 | Q10: =N(Q9)+$P10 -> 1
A11: 10 | B11: =IF($T$4=0,IF($I11="","",$I11),IFERROR(IF([1]财务取数接口!$B$10=0,"",[1]财务取数接口!$B$10),"")) -> 46419 | C11: =IF($T$4=0,IF($J11="","",$J11),IFERROR(IF([1]财务取数接口!$C$10=0,"",[1]财务取数接口!$C$10),"")) -> 仓储费 | D11: =IF($T$4=0,IF($K11="","",$K11),IFERROR(IF([1]财务取数接口!$D$10=0,"",[1]财务取数接口!$D$10),"")) | E11: =IF($T$4=0,IF($L11="","",$L11),IFERROR(IF([1]财务取数接口!$E$10=0,"",[1]财务取数接口!$E$10),"")) -> 筐 | F11: =IF($T$4=0,IF($M11="","",$M11),IFERROR(IF([1]财务取数接口!$G$10=0,"",[1]财务取数接口!$G$10),"")) | G11: =IF($T$4=0,IF($N11="","",$N11),IFERROR(IF([1]财务取数接口!$H$10=0,"",[1]财务取数接口!$H$10),"")) | H11: =IF($T$4=0,IF($O11="","",$O11),IFERROR(IF([1]财务取数接口!$I$10=0,"",[1]财务取数接口!$I$10),"")) | P11: =IF(AND($C11<>"",$C11<>"项目",OR(N($D11)<>0,N($E11)<>0,N($F11)<>0)),1,0) -> 0 | Q11: =N(Q10)+$P11 -> 1
A12: 11 | B12: =IF($T$4=0,IF($I12="","",$I12),IFERROR(IF([1]财务取数接口!$B$11=0,"",[1]财务取数接口!$B$11),"")) -> 46447 | C12: =IF($T$4=0,IF($J12="","",$J12),IFERROR(IF([1]财务取数接口!$C$11=0,"",[1]财务取数接口!$C$11),"")) -> 仓储费 | D12: =IF($T$4=0,IF($K12="","",$K12),IFERROR(IF([1]财务取数接口!$D$11=0,"",[1]财务取数接口!$D$11),"")) | E12: =IF($T$4=0,IF($L12="","",$L12),IFERROR(IF([1]财务取数接口!$E$11=0,"",[1]财务取数接口!$E$11),"")) -> 筐 | F12: =IF($T$4=0,IF($M12="","",$M12),IFERROR(IF([1]财务取数接口!$G$11=0,"",[1]财务取数接口!$G$11),"")) | G12: =IF($T$4=0,IF($N12="","",$N12),IFERROR(IF([1]财务取数接口!$H$11=0,"",[1]财务取数接口!$H$11),"")) | H12: =IF($T$4=0,IF($O12="","",$O12),IFERROR(IF([1]财务取数接口!$I$11=0,"",[1]财务取数接口!$I$11),"")) | P12: =IF(AND($C12<>"",$C12<>"项目",OR(N($D12)<>0,N($E12)<>0,N($F12)<>0)),1,0) -> 0 | Q12: =N(Q11)+$P12 -> 1
A13: 12 | B13: =IF($T$4=0,IF($I13="","",$I13),IFERROR(IF([1]财务取数接口!$B$12=0,"",[1]财务取数接口!$B$12),"")) -> 46478 | C13: =IF($T$4=0,IF($J13="","",$J13),IFERROR(IF([1]财务取数接口!$C$12=0,"",[1]财务取数接口!$C$12),"")) -> 仓储费 | D13: =IF($T$4=0,IF($K13="","",$K13),IFERROR(IF([1]财务取数接口!$D$12=0,"",[1]财务取数接口!$D$12),"")) | E13: =IF($T$4=0,IF($L13="","",$L13),IFERROR(IF([1]财务取数接口!$E$12=0,"",[1]财务取数接口!$E$12),"")) -> 筐 | F13: =IF($T$4=0,IF($M13="","",$M13),IFERROR(IF([1]财务取数接口!$G$12=0,"",[1]财务取数接口!$G$12),"")) | G13: =IF($T$4=0,IF($N13="","",$N13),IFERROR(IF([1]财务取数接口!$H$12=0,"",[1]财务取数接口!$H$12),"")) | H13: =IF($T$4=0,IF($O13="","",$O13),IFERROR(IF([1]财务取数接口!$I$12=0,"",[1]财务取数接口!$I$12),"")) | P13: =IF(AND($C13<>"",$C13<>"项目",OR(N($D13)<>0,N($E13)<>0,N($F13)<>0)),1,0) -> 0 | Q13: =N(Q12)+$P13 -> 1
A14: 13 | B14: =IF($T$4=0,IF($I14="","",$I14),IFERROR(IF([1]财务取数接口!$B$13=0,"",[1]财务取数接口!$B$13),"")) -> 46508 | C14: =IF($T$4=0,IF($J14="","",$J14),IFERROR(IF([1]财务取数接口!$C$13=0,"",[1]财务取数接口!$C$13),"")) -> 仓储费 | D14: =IF($T$4=0,IF($K14="","",$K14),IFERROR(IF([1]财务取数接口!$D$13=0,"",[1]财务取数接口!$D$13),"")) | E14: =IF($T$4=0,IF($L14="","",$L14),IFERROR(IF([1]财务取数接口!$E$13=0,"",[1]财务取数接口!$E$13),"")) -> 筐 | F14: =IF($T$4=0,IF($M14="","",$M14),IFERROR(IF([1]财务取数接口!$G$13=0,"",[1]财务取数接口!$G$13),"")) | G14: =IF($T$4=0,IF($N14="","",$N14),IFERROR(IF([1]财务取数接口!$H$13=0,"",[1]财务取数接口!$H$13),"")) | H14: =IF($T$4=0,IF($O14="","",$O14),IFERROR(IF([1]财务取数接口!$I$13=0,"",[1]财务取数接口!$I$13),"")) | P14: =IF(AND($C14<>"",$C14<>"项目",OR(N($D14)<>0,N($E14)<>0,N($F14)<>0)),1,0) -> 0 | Q14: =N(Q13)+$P14 -> 1
A15: 14 | B15: =IF($T$4=0,IF($I15="","",$I15),IFERROR(IF([1]财务取数接口!$B$14=0,"",[1]财务取数接口!$B$14),"")) -> 46539 | C15: =IF($T$4=0,IF($J15="","",$J15),IFERROR(IF([1]财务取数接口!$C$14=0,"",[1]财务取数接口!$C$14),"")) -> 仓储费 | D15: =IF($T$4=0,IF($K15="","",$K15),IFERROR(IF([1]财务取数接口!$D$14=0,"",[1]财务取数接口!$D$14),"")) | E15: =IF($T$4=0,IF($L15="","",$L15),IFERROR(IF([1]财务取数接口!$E$14=0,"",[1]财务取数接口!$E$14),"")) -> 筐 | F15: =IF($T$4=0,IF($M15="","",$M15),IFERROR(IF([1]财务取数接口!$G$14=0,"",[1]财务取数接口!$G$14),"")) | G15: =IF($T$4=0,IF($N15="","",$N15),IFERROR(IF([1]财务取数接口!$H$14=0,"",[1]财务取数接口!$H$14),"")) | H15: =IF($T$4=0,IF($O15="","",$O15),IFERROR(IF([1]财务取数接口!$I$14=0,"",[1]财务取数接口!$I$14),"")) | P15: =IF(AND($C15<>"",$C15<>"项目",OR(N($D15)<>0,N($E15)<>0,N($F15)<>0)),1,0) -> 0 | Q15: =N(Q14)+$P15 -> 1
A16: 15 | B16: =IF($T$4=0,IF($I16="","",$I16),IFERROR(IF([1]财务取数接口!$B$15=0,"",[1]财务取数接口!$B$15),"")) -> 46569 | C16: =IF($T$4=0,IF($J16="","",$J16),IFERROR(IF([1]财务取数接口!$C$15=0,"",[1]财务取数接口!$C$15),"")) -> 仓储费 | D16: =IF($T$4=0,IF($K16="","",$K16),IFERROR(IF([1]财务取数接口!$D$15=0,"",[1]财务取数接口!$D$15),"")) | E16: =IF($T$4=0,IF($L16="","",$L16),IFERROR(IF([1]财务取数接口!$E$15=0,"",[1]财务取数接口!$E$15),"")) -> 筐 | F16: =IF($T$4=0,IF($M16="","",$M16),IFERROR(IF([1]财务取数接口!$G$15=0,"",[1]财务取数接口!$G$15),"")) | G16: =IF($T$4=0,IF($N16="","",$N16),IFERROR(IF([1]财务取数接口!$H$15=0,"",[1]财务取数接口!$H$15),"")) | H16: =IF($T$4=0,IF($O16="","",$O16),IFERROR(IF([1]财务取数接口!$I$15=0,"",[1]财务取数接口!$I$15),"")) | P16: =IF(AND($C16<>"",$C16<>"项目",OR(N($D16)<>0,N($E16)<>0,N($F16)<>0)),1,0) -> 0 | Q16: =N(Q15)+$P16 -> 1
A17: 16 | B17: =IF($T$4=0,IF($I17="","",$I17),IFERROR(IF([1]财务取数接口!$B$16=0,"",[1]财务取数接口!$B$16),"")) -> 46600 | C17: =IF($T$4=0,IF($J17="","",$J17),IFERROR(IF([1]财务取数接口!$C$16=0,"",[1]财务取数接口!$C$16),"")) -> 仓储费 | D17: =IF($T$4=0,IF($K17="","",$K17),IFERROR(IF([1]财务取数接口!$D$16=0,"",[1]财务取数接口!$D$16),"")) | E17: =IF($T$4=0,IF($L17="","",$L17),IFERROR(IF([1]财务取数接口!$E$16=0,"",[1]财务取数接口!$E$16),"")) -> 筐 | F17: =IF($T$4=0,IF($M17="","",$M17),IFERROR(IF([1]财务取数接口!$G$16=0,"",[1]财务取数接口!$G$16),"")) | G17: =IF($T$4=0,IF($N17="","",$N17),IFERROR(IF([1]财务取数接口!$H$16=0,"",[1]财务取数接口!$H$16),"")) | H17: =IF($T$4=0,IF($O17="","",$O17),IFERROR(IF([1]财务取数接口!$I$16=0,"",[1]财务取数接口!$I$16),"")) | P17: =IF(AND($C17<>"",$C17<>"项目",OR(N($D17)<>0,N($E17)<>0,N($F17)<>0)),1,0) -> 0 | Q17: =N(Q16)+$P17 -> 1
A18: 17 | B18: =IF($T$4=0,IF($I18="","",$I18),IFERROR(IF([1]财务取数接口!$B$17=0,"",[1]财务取数接口!$B$17),"")) -> 46631 | C18: =IF($T$4=0,IF($J18="","",$J18),IFERROR(IF([1]财务取数接口!$C$17=0,"",[1]财务取数接口!$C$17),"")) -> 仓储费 | D18: =IF($T$4=0,IF($K18="","",$K18),IFERROR(IF([1]财务取数接口!$D$17=0,"",[1]财务取数接口!$D$17),"")) | E18: =IF($T$4=0,IF($L18="","",$L18),IFERROR(IF([1]财务取数接口!$E$17=0,"",[1]财务取数接口!$E$17),"")) -> 筐 | F18: =IF($T$4=0,IF($M18="","",$M18),IFERROR(IF([1]财务取数接口!$G$17=0,"",[1]财务取数接口!$G$17),"")) | G18: =IF($T$4=0,IF($N18="","",$N18),IFERROR(IF([1]财务取数接口!$H$17=0,"",[1]财务取数接口!$H$17),"")) | H18: =IF($T$4=0,IF($O18="","",$O18),IFERROR(IF([1]财务取数接口!$I$17=0,"",[1]财务取数接口!$I$17),"")) | P18: =IF(AND($C18<>"",$C18<>"项目",OR(N($D18)<>0,N($E18)<>0,N($F18)<>0)),1,0) -> 0 | Q18: =N(Q17)+$P18 -> 1
A19: 18 | B19: =IF($T$4=0,IF($I19="","",$I19),IFERROR(IF([1]财务取数接口!$B$18=0,"",[1]财务取数接口!$B$18),"")) -> 46661 | C19: =IF($T$4=0,IF($J19="","",$J19),IFERROR(IF([1]财务取数接口!$C$18=0,"",[1]财务取数接口!$C$18),"")) -> 仓储费 | D19: =IF($T$4=0,IF($K19="","",$K19),IFERROR(IF([1]财务取数接口!$D$18=0,"",[1]财务取数接口!$D$18),"")) | E19: =IF($T$4=0,IF($L19="","",$L19),IFERROR(IF([1]财务取数接口!$E$18=0,"",[1]财务取数接口!$E$18),"")) -> 筐 | F19: =IF($T$4=0,IF($M19="","",$M19),IFERROR(IF([1]财务取数接口!$G$18=0,"",[1]财务取数接口!$G$18),"")) | G19: =IF($T$4=0,IF($N19="","",$N19),IFERROR(IF([1]财务取数接口!$H$18=0,"",[1]财务取数接口!$H$18),"")) | H19: =IF($T$4=0,IF($O19="","",$O19),IFERROR(IF([1]财务取数接口!$I$18=0,"",[1]财务取数接口!$I$18),"")) | P19: =IF(AND($C19<>"",$C19<>"项目",OR(N($D19)<>0,N($E19)<>0,N($F19)<>0)),1,0) -> 0 | Q19: =N(Q18)+$P19 -> 1
A20: 19 | B20: =IF($T$4=0,IF($I20="","",$I20),IFERROR(IF([1]财务取数接口!$B$19=0,"",[1]财务取数接口!$B$19),"")) -> 46692 | C20: =IF($T$4=0,IF($J20="","",$J20),IFERROR(IF([1]财务取数接口!$C$19=0,"",[1]财务取数接口!$C$19),"")) -> 仓储费 | D20: =IF($T$4=0,IF($K20="","",$K20),IFERROR(IF([1]财务取数接口!$D$19=0,"",[1]财务取数接口!$D$19),"")) | E20: =IF($T$4=0,IF($L20="","",$L20),IFERROR(IF([1]财务取数接口!$E$19=0,"",[1]财务取数接口!$E$19),"")) -> 筐 | F20: =IF($T$4=0,IF($M20="","",$M20),IFERROR(IF([1]财务取数接口!$G$19=0,"",[1]财务取数接口!$G$19),"")) | G20: =IF($T$4=0,IF($N20="","",$N20),IFERROR(IF([1]财务取数接口!$H$19=0,"",[1]财务取数接口!$H$19),"")) | H20: =IF($T$4=0,IF($O20="","",$O20),IFERROR(IF([1]财务取数接口!$I$19=0,"",[1]财务取数接口!$I$19),"")) | P20: =IF(AND($C20<>"",$C20<>"项目",OR(N($D20)<>0,N($E20)<>0,N($F20)<>0)),1,0) -> 0 | Q20: =N(Q19)+$P20 -> 1
A21: 20 | B21: =IF($T$4=0,IF($I21="","",$I21),IFERROR(IF([1]财务取数接口!$B$20=0,"",[1]财务取数接口!$B$20),"")) -> 46722 | C21: =IF($T$4=0,IF($J21="","",$J21),IFERROR(IF([1]财务取数接口!$C$20=0,"",[1]财务取数接口!$C$20),"")) -> 仓储费 | D21: =IF($T$4=0,IF($K21="","",$K21),IFERROR(IF([1]财务取数接口!$D$20=0,"",[1]财务取数接口!$D$20),"")) | E21: =IF($T$4=0,IF($L21="","",$L21),IFERROR(IF([1]财务取数接口!$E$20=0,"",[1]财务取数接口!$E$20),"")) -> 筐 | F21: =IF($T$4=0,IF($M21="","",$M21),IFERROR(IF([1]财务取数接口!$G$20=0,"",[1]财务取数接口!$G$20),"")) | G21: =IF($T$4=0,IF($N21="","",$N21),IFERROR(IF([1]财务取数接口!$H$20=0,"",[1]财务取数接口!$H$20),"")) | H21: =IF($T$4=0,IF($O21="","",$O21),IFERROR(IF([1]财务取数接口!$I$20=0,"",[1]财务取数接口!$I$20),"")) | P21: =IF(AND($C21<>"",$C21<>"项目",OR(N($D21)<>0,N($E21)<>0,N($F21)<>0)),1,0) -> 0 | Q21: =N(Q20)+$P21 -> 1
A22: 21 | B22: =IF($T$4=0,IF($I22="","",$I22),IFERROR(IF([1]财务取数接口!$B$21=0,"",[1]财务取数接口!$B$21),"")) -> 46753 | C22: =IF($T$4=0,IF($J22="","",$J22),IFERROR(IF([1]财务取数接口!$C$21=0,"",[1]财务取数接口!$C$21),"")) -> 仓储费 | D22: =IF($T$4=0,IF($K22="","",$K22),IFERROR(IF([1]财务取数接口!$D$21=0,"",[1]财务取数接口!$D$21),"")) | E22: =IF($T$4=0,IF($L22="","",$L22),IFERROR(IF([1]财务取数接口!$E$21=0,"",[1]财务取数接口!$E$21),"")) -> 筐 | F22: =IF($T$4=0,IF($M22="","",$M22),IFERROR(IF([1]财务取数接口!$G$21=0,"",[1]财务取数接口!$G$21),"")) | G22: =IF($T$4=0,IF($N22="","",$N22),IFERROR(IF([1]财务取数接口!$H$21=0,"",[1]财务取数接口!$H$21),"")) | H22: =IF($T$4=0,IF($O22="","",$O22),IFERROR(IF([1]财务取数接口!$I$21=0,"",[1]财务取数接口!$I$21),"")) | P22: =IF(AND($C22<>"",$C22<>"项目",OR(N($D22)<>0,N($E22)<>0,N($F22)<>0)),1,0) -> 0 | Q22: =N(Q21)+$P22 -> 1
A23: 22 | B23: =IF($T$4=0,IF($I23="","",$I23),IFERROR(IF([1]财务取数接口!$B$22=0,"",[1]财务取数接口!$B$22),"")) -> 46784 | C23: =IF($T$4=0,IF($J23="","",$J23),IFERROR(IF([1]财务取数接口!$C$22=0,"",[1]财务取数接口!$C$22),"")) -> 仓储费 | D23: =IF($T$4=0,IF($K23="","",$K23),IFERROR(IF([1]财务取数接口!$D$22=0,"",[1]财务取数接口!$D$22),"")) | E23: =IF($T$4=0,IF($L23="","",$L23),IFERROR(IF([1]财务取数接口!$E$22=0,"",[1]财务取数接口!$E$22),"")) -> 筐 | F23: =IF($T$4=0,IF($M23="","",$M23),IFERROR(IF([1]财务取数接口!$G$22=0,"",[1]财务取数接口!$G$22),"")) | G23: =IF($T$4=0,IF($N23="","",$N23),IFERROR(IF([1]财务取数接口!$H$22=0,"",[1]财务取数接口!$H$22),"")) | H23: =IF($T$4=0,IF($O23="","",$O23),IFERROR(IF([1]财务取数接口!$I$22=0,"",[1]财务取数接口!$I$22),"")) | P23: =IF(AND($C23<>"",$C23<>"项目",OR(N($D23)<>0,N($E23)<>0,N($F23)<>0)),1,0) -> 0 | Q23: =N(Q22)+$P23 -> 1
A24: 23 | B24: =IF($T$4=0,IF($I24="","",$I24),IFERROR(IF([1]财务取数接口!$B$23=0,"",[1]财务取数接口!$B$23),"")) -> 46813 | C24: =IF($T$4=0,IF($J24="","",$J24),IFERROR(IF([1]财务取数接口!$C$23=0,"",[1]财务取数接口!$C$23),"")) -> 仓储费 | D24: =IF($T$4=0,IF($K24="","",$K24),IFERROR(IF([1]财务取数接口!$D$23=0,"",[1]财务取数接口!$D$23),"")) | E24: =IF($T$4=0,IF($L24="","",$L24),IFERROR(IF([1]财务取数接口!$E$23=0,"",[1]财务取数接口!$E$23),"")) -> 筐 | F24: =IF($T$4=0,IF($M24="","",$M24),IFERROR(IF([1]财务取数接口!$G$23=0,"",[1]财务取数接口!$G$23),"")) | G24: =IF($T$4=0,IF($N24="","",$N24),IFERROR(IF([1]财务取数接口!$H$23=0,"",[1]财务取数接口!$H$23),"")) | H24: =IF($T$4=0,IF($O24="","",$O24),IFERROR(IF([1]财务取数接口!$I$23=0,"",[1]财务取数接口!$I$23),"")) | P24: =IF(AND($C24<>"",$C24<>"项目",OR(N($D24)<>0,N($E24)<>0,N($F24)<>0)),1,0) -> 0 | Q24: =N(Q23)+$P24 -> 1
A25: 24 | B25: =IF($T$4=0,IF($I25="","",$I25),IFERROR(IF([1]财务取数接口!$B$24=0,"",[1]财务取数接口!$B$24),"")) -> 46844 | C25: =IF($T$4=0,IF($J25="","",$J25),IFERROR(IF([1]财务取数接口!$C$24=0,"",[1]财务取数接口!$C$24),"")) -> 仓储费 | D25: =IF($T$4=0,IF($K25="","",$K25),IFERROR(IF([1]财务取数接口!$D$24=0,"",[1]财务取数接口!$D$24),"")) | E25: =IF($T$4=0,IF($L25="","",$L25),IFERROR(IF([1]财务取数接口!$E$24=0,"",[1]财务取数接口!$E$24),"")) -> 筐 | F25: =IF($T$4=0,IF($M25="","",$M25),IFERROR(IF([1]财务取数接口!$G$24=0,"",[1]财务取数接口!$G$24),"")) | G25: =IF($T$4=0,IF($N25="","",$N25),IFERROR(IF([1]财务取数接口!$H$24=0,"",[1]财务取数接口!$H$24),"")) | H25: =IF($T$4=0,IF($O25="","",$O25),IFERROR(IF([1]财务取数接口!$I$24=0,"",[1]财务取数接口!$I$24),"")) | P25: =IF(AND($C25<>"",$C25<>"项目",OR(N($D25)<>0,N($E25)<>0,N($F25)<>0)),1,0) -> 0 | Q25: =N(Q24)+$P25 -> 1
A26: 25 | B26: =IF($T$4=0,IF($I26="","",$I26),IFERROR(IF([1]财务取数接口!$B$25=0,"",[1]财务取数接口!$B$25),"")) -> 46874 | C26: =IF($T$4=0,IF($J26="","",$J26),IFERROR(IF([1]财务取数接口!$C$25=0,"",[1]财务取数接口!$C$25),"")) -> 仓储费 | D26: =IF($T$4=0,IF($K26="","",$K26),IFERROR(IF([1]财务取数接口!$D$25=0,"",[1]财务取数接口!$D$25),"")) | E26: =IF($T$4=0,IF($L26="","",$L26),IFERROR(IF([1]财务取数接口!$E$25=0,"",[1]财务取数接口!$E$25),"")) -> 筐 | F26: =IF($T$4=0,IF($M26="","",$M26),IFERROR(IF([1]财务取数接口!$G$25=0,"",[1]财务取数接口!$G$25),"")) | G26: =IF($T$4=0,IF($N26="","",$N26),IFERROR(IF([1]财务取数接口!$H$25=0,"",[1]财务取数接口!$H$25),"")) | H26: =IF($T$4=0,IF($O26="","",$O26),IFERROR(IF([1]财务取数接口!$I$25=0,"",[1]财务取数接口!$I$25),"")) | P26: =IF(AND($C26<>"",$C26<>"项目",OR(N($D26)<>0,N($E26)<>0,N($F26)<>0)),1,0) -> 0 | Q26: =N(Q25)+$P26 -> 1
A27: 26 | B27: =IF($T$4=0,IF($I27="","",$I27),IFERROR(IF([1]财务取数接口!$B$26=0,"",[1]财务取数接口!$B$26),"")) -> 46905 | C27: =IF($T$4=0,IF($J27="","",$J27),IFERROR(IF([1]财务取数接口!$C$26=0,"",[1]财务取数接口!$C$26),"")) -> 仓储费 | D27: =IF($T$4=0,IF($K27="","",$K27),IFERROR(IF([1]财务取数接口!$D$26=0,"",[1]财务取数接口!$D$26),"")) | E27: =IF($T$4=0,IF($L27="","",$L27),IFERROR(IF([1]财务取数接口!$E$26=0,"",[1]财务取数接口!$E$26),"")) -> 筐 | F27: =IF($T$4=0,IF($M27="","",$M27),IFERROR(IF([1]财务取数接口!$G$26=0,"",[1]财务取数接口!$G$26),"")) | G27: =IF($T$4=0,IF($N27="","",$N27),IFERROR(IF([1]财务取数接口!$H$26=0,"",[1]财务取数接口!$H$26),"")) | H27: =IF($T$4=0,IF($O27="","",$O27),IFERROR(IF([1]财务取数接口!$I$26=0,"",[1]财务取数接口!$I$26),"")) | P27: =IF(AND($C27<>"",$C27<>"项目",OR(N($D27)<>0,N($E27)<>0,N($F27)<>0)),1,0) -> 0 | Q27: =N(Q26)+$P27 -> 1
A28: 27 | B28: =IF($T$4=0,IF($I28="","",$I28),IFERROR(IF([1]财务取数接口!$B$27=0,"",[1]财务取数接口!$B$27),"")) -> 46935 | C28: =IF($T$4=0,IF($J28="","",$J28),IFERROR(IF([1]财务取数接口!$C$27=0,"",[1]财务取数接口!$C$27),"")) -> 仓储费 | D28: =IF($T$4=0,IF($K28="","",$K28),IFERROR(IF([1]财务取数接口!$D$27=0,"",[1]财务取数接口!$D$27),"")) | E28: =IF($T$4=0,IF($L28="","",$L28),IFERROR(IF([1]财务取数接口!$E$27=0,"",[1]财务取数接口!$E$27),"")) -> 筐 | F28: =IF($T$4=0,IF($M28="","",$M28),IFERROR(IF([1]财务取数接口!$G$27=0,"",[1]财务取数接口!$G$27),"")) | G28: =IF($T$4=0,IF($N28="","",$N28),IFERROR(IF([1]财务取数接口!$H$27=0,"",[1]财务取数接口!$H$27),"")) | H28: =IF($T$4=0,IF($O28="","",$O28),IFERROR(IF([1]财务取数接口!$I$27=0,"",[1]财务取数接口!$I$27),"")) | P28: =IF(AND($C28<>"",$C28<>"项目",OR(N($D28)<>0,N($E28)<>0,N($F28)<>0)),1,0) -> 0 | Q28: =N(Q27)+$P28 -> 1
A29: 28 | B29: =IF($T$4=0,IF($I29="","",$I29),IFERROR(IF([1]财务取数接口!$B$28=0,"",[1]财务取数接口!$B$28),"")) -> 46235 | C29: =IF($T$4=0,IF($J29="","",$J29),IFERROR(IF([1]财务取数接口!$C$28=0,"",[1]财务取数接口!$C$28),"")) -> 周转费 | D29: =IF($T$4=0,IF($K29="","",$K29),IFERROR(IF([1]财务取数接口!$D$28=0,"",[1]财务取数接口!$D$28),"")) -> 13104 | E29: =IF($T$4=0,IF($L29="","",$L29),IFERROR(IF([1]财务取数接口!$E$28=0,"",[1]财务取数接口!$E$28),"")) -> 筐 | F29: =IF($T$4=0,IF($M29="","",$M29),IFERROR(IF([1]财务取数接口!$G$28=0,"",[1]财务取数接口!$G$28),"")) | G29: =IF($T$4=0,IF($N29="","",$N29),IFERROR(IF([1]财务取数接口!$H$28=0,"",[1]财务取数接口!$H$28),"")) | H29: =IF($T$4=0,IF($O29="","",$O29),IFERROR(IF([1]财务取数接口!$I$28=0,"",[1]财务取数接口!$I$28),"")) | P29: =IF(AND($C29<>"",$C29<>"项目",OR(N($D29)<>0,N($E29)<>0,N($F29)<>0)),1,0) -> 1 | Q29: =N(Q28)+$P29 -> 2
A30: 29 | B30: =IF($T$4=0,IF($I30="","",$I30),IFERROR(IF([1]财务取数接口!$B$29=0,"",[1]财务取数接口!$B$29),"")) -> 46266 | C30: =IF($T$4=0,IF($J30="","",$J30),IFERROR(IF([1]财务取数接口!$C$29=0,"",[1]财务取数接口!$C$29),"")) -> 周转费 | D30: =IF($T$4=0,IF($K30="","",$K30),IFERROR(IF([1]财务取数接口!$D$29=0,"",[1]财务取数接口!$D$29),"")) -> 5597 | E30: =IF($T$4=0,IF($L30="","",$L30),IFERROR(IF([1]财务取数接口!$E$29=0,"",[1]财务取数接口!$E$29),"")) -> 筐 | F30: =IF($T$4=0,IF($M30="","",$M30),IFERROR(IF([1]财务取数接口!$G$29=0,"",[1]财务取数接口!$G$29),"")) | G30: =IF($T$4=0,IF($N30="","",$N30),IFERROR(IF([1]财务取数接口!$H$29=0,"",[1]财务取数接口!$H$29),"")) | H30: =IF($T$4=0,IF($O30="","",$O30),IFERROR(IF([1]财务取数接口!$I$29=0,"",[1]财务取数接口!$I$29),"")) | P30: =IF(AND($C30<>"",$C30<>"项目",OR(N($D30)<>0,N($E30)<>0,N($F30)<>0)),1,0) -> 1 | Q30: =N(Q29)+$P30 -> 3
A31: 30 | B31: =IF($T$4=0,IF($I31="","",$I31),IFERROR(IF([1]财务取数接口!$B$30=0,"",[1]财务取数接口!$B$30),"")) -> 46296 | C31: =IF($T$4=0,IF($J31="","",$J31),IFERROR(IF([1]财务取数接口!$C$30=0,"",[1]财务取数接口!$C$30),"")) -> 周转费 | D31: =IF($T$4=0,IF($K31="","",$K31),IFERROR(IF([1]财务取数接口!$D$30=0,"",[1]财务取数接口!$D$30),"")) | E31: =IF($T$4=0,IF($L31="","",$L31),IFERROR(IF([1]财务取数接口!$E$30=0,"",[1]财务取数接口!$E$30),"")) -> 筐 | F31: =IF($T$4=0,IF($M31="","",$M31),IFERROR(IF([1]财务取数接口!$G$30=0,"",[1]财务取数接口!$G$30),"")) | G31: =IF($T$4=0,IF($N31="","",$N31),IFERROR(IF([1]财务取数接口!$H$30=0,"",[1]财务取数接口!$H$30),"")) | H31: =IF($T$4=0,IF($O31="","",$O31),IFERROR(IF([1]财务取数接口!$I$30=0,"",[1]财务取数接口!$I$30),"")) | P31: =IF(AND($C31<>"",$C31<>"项目",OR(N($D31)<>0,N($E31)<>0,N($F31)<>0)),1,0) -> 0 | Q31: =N(Q30)+$P31 -> 3
A32: 31 | B32: =IF($T$4=0,IF($I32="","",$I32),IFERROR(IF([1]财务取数接口!$B$31=0,"",[1]财务取数接口!$B$31),"")) -> 46327 | C32: =IF($T$4=0,IF($J32="","",$J32),IFERROR(IF([1]财务取数接口!$C$31=0,"",[1]财务取数接口!$C$31),"")) -> 周转费 | D32: =IF($T$4=0,IF($K32="","",$K32),IFERROR(IF([1]财务取数接口!$D$31=0,"",[1]财务取数接口!$D$31),"")) | E32: =IF($T$4=0,IF($L32="","",$L32),IFERROR(IF([1]财务取数接口!$E$31=0,"",[1]财务取数接口!$E$31),"")) -> 筐 | F32: =IF($T$4=0,IF($M32="","",$M32),IFERROR(IF([1]财务取数接口!$G$31=0,"",[1]财务取数接口!$G$31),"")) | G32: =IF($T$4=0,IF($N32="","",$N32),IFERROR(IF([1]财务取数接口!$H$31=0,"",[1]财务取数接口!$H$31),"")) | H32: =IF($T$4=0,IF($O32="","",$O32),IFERROR(IF([1]财务取数接口!$I$31=0,"",[1]财务取数接口!$I$31),"")) | P32: =IF(AND($C32<>"",$C32<>"项目",OR(N($D32)<>0,N($E32)<>0,N($F32)<>0)),1,0) -> 0 | Q32: =N(Q31)+$P32 -> 3
A33: 32 | B33: =IF($T$4=0,IF($I33="","",$I33),IFERROR(IF([1]财务取数接口!$B$32=0,"",[1]财务取数接口!$B$32),"")) -> 46357 | C33: =IF($T$4=0,IF($J33="","",$J33),IFERROR(IF([1]财务取数接口!$C$32=0,"",[1]财务取数接口!$C$32),"")) -> 周转费 | D33: =IF($T$4=0,IF($K33="","",$K33),IFERROR(IF([1]财务取数接口!$D$32=0,"",[1]财务取数接口!$D$32),"")) | E33: =IF($T$4=0,IF($L33="","",$L33),IFERROR(IF([1]财务取数接口!$E$32=0,"",[1]财务取数接口!$E$32),"")) -> 筐 | F33: =IF($T$4=0,IF($M33="","",$M33),IFERROR(IF([1]财务取数接口!$G$32=0,"",[1]财务取数接口!$G$32),"")) | G33: =IF($T$4=0,IF($N33="","",$N33),IFERROR(IF([1]财务取数接口!$H$32=0,"",[1]财务取数接口!$H$32),"")) | H33: =IF($T$4=0,IF($O33="","",$O33),IFERROR(IF([1]财务取数接口!$I$32=0,"",[1]财务取数接口!$I$32),"")) | P33: =IF(AND($C33<>"",$C33<>"项目",OR(N($D33)<>0,N($E33)<>0,N($F33)<>0)),1,0) -> 0 | Q33: =N(Q32)+$P33 -> 3
A34: 33 | B34: =IF($T$4=0,IF($I34="","",$I34),IFERROR(IF([1]财务取数接口!$B$33=0,"",[1]财务取数接口!$B$33),"")) -> 46388 | C34: =IF($T$4=0,IF($J34="","",$J34),IFERROR(IF([1]财务取数接口!$C$33=0,"",[1]财务取数接口!$C$33),"")) -> 周转费 | D34: =IF($T$4=0,IF($K34="","",$K34),IFERROR(IF([1]财务取数接口!$D$33=0,"",[1]财务取数接口!$D$33),"")) | E34: =IF($T$4=0,IF($L34="","",$L34),IFERROR(IF([1]财务取数接口!$E$33=0,"",[1]财务取数接口!$E$33),"")) -> 筐 | F34: =IF($T$4=0,IF($M34="","",$M34),IFERROR(IF([1]财务取数接口!$G$33=0,"",[1]财务取数接口!$G$33),"")) | G34: =IF($T$4=0,IF($N34="","",$N34),IFERROR(IF([1]财务取数接口!$H$33=0,"",[1]财务取数接口!$H$33),"")) | H34: =IF($T$4=0,IF($O34="","",$O34),IFERROR(IF([1]财务取数接口!$I$33=0,"",[1]财务取数接口!$I$33),"")) | P34: =IF(AND($C34<>"",$C34<>"项目",OR(N($D34)<>0,N($E34)<>0,N($F34)<>0)),1,0) -> 0 | Q34: =N(Q33)+$P34 -> 3
A35: 34 | B35: =IF($T$4=0,IF($I35="","",$I35),IFERROR(IF([1]财务取数接口!$B$34=0,"",[1]财务取数接口!$B$34),"")) -> 46419 | C35: =IF($T$4=0,IF($J35="","",$J35),IFERROR(IF([1]财务取数接口!$C$34=0,"",[1]财务取数接口!$C$34),"")) -> 周转费 | D35: =IF($T$4=0,IF($K35="","",$K35),IFERROR(IF([1]财务取数接口!$D$34=0,"",[1]财务取数接口!$D$34),"")) | E35: =IF($T$4=0,IF($L35="","",$L35),IFERROR(IF([1]财务取数接口!$E$34=0,"",[1]财务取数接口!$E$34),"")) -> 筐 | F35: =IF($T$4=0,IF($M35="","",$M35),IFERROR(IF([1]财务取数接口!$G$34=0,"",[1]财务取数接口!$G$34),"")) | G35: =IF($T$4=0,IF($N35="","",$N35),IFERROR(IF([1]财务取数接口!$H$34=0,"",[1]财务取数接口!$H$34),"")) | H35: =IF($T$4=0,IF($O35="","",$O35),IFERROR(IF([1]财务取数接口!$I$34=0,"",[1]财务取数接口!$I$34),"")) | P35: =IF(AND($C35<>"",$C35<>"项目",OR(N($D35)<>0,N($E35)<>0,N($F35)<>0)),1,0) -> 0 | Q35: =N(Q34)+$P35 -> 3
A36: 35 | B36: =IF($T$4=0,IF($I36="","",$I36),IFERROR(IF([1]财务取数接口!$B$35=0,"",[1]财务取数接口!$B$35),"")) -> 46447 | C36: =IF($T$4=0,IF($J36="","",$J36),IFERROR(IF([1]财务取数接口!$C$35=0,"",[1]财务取数接口!$C$35),"")) -> 周转费 | D36: =IF($T$4=0,IF($K36="","",$K36),IFERROR(IF([1]财务取数接口!$D$35=0,"",[1]财务取数接口!$D$35),"")) | E36: =IF($T$4=0,IF($L36="","",$L36),IFERROR(IF([1]财务取数接口!$E$35=0,"",[1]财务取数接口!$E$35),"")) -> 筐 | F36: =IF($T$4=0,IF($M36="","",$M36),IFERROR(IF([1]财务取数接口!$G$35=0,"",[1]财务取数接口!$G$35),"")) | G36: =IF($T$4=0,IF($N36="","",$N36),IFERROR(IF([1]财务取数接口!$H$35=0,"",[1]财务取数接口!$H$35),"")) | H36: =IF($T$4=0,IF($O36="","",$O36),IFERROR(IF([1]财务取数接口!$I$35=0,"",[1]财务取数接口!$I$35),"")) | P36: =IF(AND($C36<>"",$C36<>"项目",OR(N($D36)<>0,N($E36)<>0,N($F36)<>0)),1,0) -> 0 | Q36: =N(Q35)+$P36 -> 3
A37: 36 | B37: =IF($T$4=0,IF($I37="","",$I37),IFERROR(IF([1]财务取数接口!$B$36=0,"",[1]财务取数接口!$B$36),"")) -> 46478 | C37: =IF($T$4=0,IF($J37="","",$J37),IFERROR(IF([1]财务取数接口!$C$36=0,"",[1]财务取数接口!$C$36),"")) -> 周转费 | D37: =IF($T$4=0,IF($K37="","",$K37),IFERROR(IF([1]财务取数接口!$D$36=0,"",[1]财务取数接口!$D$36),"")) | E37: =IF($T$4=0,IF($L37="","",$L37),IFERROR(IF([1]财务取数接口!$E$36=0,"",[1]财务取数接口!$E$36),"")) -> 筐 | F37: =IF($T$4=0,IF($M37="","",$M37),IFERROR(IF([1]财务取数接口!$G$36=0,"",[1]财务取数接口!$G$36),"")) | G37: =IF($T$4=0,IF($N37="","",$N37),IFERROR(IF([1]财务取数接口!$H$36=0,"",[1]财务取数接口!$H$36),"")) | H37: =IF($T$4=0,IF($O37="","",$O37),IFERROR(IF([1]财务取数接口!$I$36=0,"",[1]财务取数接口!$I$36),"")) | P37: =IF(AND($C37<>"",$C37<>"项目",OR(N($D37)<>0,N($E37)<>0,N($F37)<>0)),1,0) -> 0 | Q37: =N(Q36)+$P37 -> 3
A38: 37 | B38: =IF($T$4=0,IF($I38="","",$I38),IFERROR(IF([1]财务取数接口!$B$37=0,"",[1]财务取数接口!$B$37),"")) -> 46508 | C38: =IF($T$4=0,IF($J38="","",$J38),IFERROR(IF([1]财务取数接口!$C$37=0,"",[1]财务取数接口!$C$37),"")) -> 周转费 | D38: =IF($T$4=0,IF($K38="","",$K38),IFERROR(IF([1]财务取数接口!$D$37=0,"",[1]财务取数接口!$D$37),"")) | E38: =IF($T$4=0,IF($L38="","",$L38),IFERROR(IF([1]财务取数接口!$E$37=0,"",[1]财务取数接口!$E$37),"")) -> 筐 | F38: =IF($T$4=0,IF($M38="","",$M38),IFERROR(IF([1]财务取数接口!$G$37=0,"",[1]财务取数接口!$G$37),"")) | G38: =IF($T$4=0,IF($N38="","",$N38),IFERROR(IF([1]财务取数接口!$H$37=0,"",[1]财务取数接口!$H$37),"")) | H38: =IF($T$4=0,IF($O38="","",$O38),IFERROR(IF([1]财务取数接口!$I$37=0,"",[1]财务取数接口!$I$37),"")) | P38: =IF(AND($C38<>"",$C38<>"项目",OR(N($D38)<>0,N($E38)<>0,N($F38)<>0)),1,0) -> 0 | Q38: =N(Q37)+$P38 -> 3
A39: 38 | B39: =IF($T$4=0,IF($I39="","",$I39),IFERROR(IF([1]财务取数接口!$B$38=0,"",[1]财务取数接口!$B$38),"")) -> 46539 | C39: =IF($T$4=0,IF($J39="","",$J39),IFERROR(IF([1]财务取数接口!$C$38=0,"",[1]财务取数接口!$C$38),"")) -> 周转费 | D39: =IF($T$4=0,IF($K39="","",$K39),IFERROR(IF([1]财务取数接口!$D$38=0,"",[1]财务取数接口!$D$38),"")) | E39: =IF($T$4=0,IF($L39="","",$L39),IFERROR(IF([1]财务取数接口!$E$38=0,"",[1]财务取数接口!$E$38),"")) -> 筐 | F39: =IF($T$4=0,IF($M39="","",$M39),IFERROR(IF([1]财务取数接口!$G$38=0,"",[1]财务取数接口!$G$38),"")) | G39: =IF($T$4=0,IF($N39="","",$N39),IFERROR(IF([1]财务取数接口!$H$38=0,"",[1]财务取数接口!$H$38),"")) | H39: =IF($T$4=0,IF($O39="","",$O39),IFERROR(IF([1]财务取数接口!$I$38=0,"",[1]财务取数接口!$I$38),"")) | P39: =IF(AND($C39<>"",$C39<>"项目",OR(N($D39)<>0,N($E39)<>0,N($F39)<>0)),1,0) -> 0 | Q39: =N(Q38)+$P39 -> 3
A40: 39 | B40: =IF($T$4=0,IF($I40="","",$I40),IFERROR(IF([1]财务取数接口!$B$39=0,"",[1]财务取数接口!$B$39),"")) -> 46569 | C40: =IF($T$4=0,IF($J40="","",$J40),IFERROR(IF([1]财务取数接口!$C$39=0,"",[1]财务取数接口!$C$39),"")) -> 周转费 | D40: =IF($T$4=0,IF($K40="","",$K40),IFERROR(IF([1]财务取数接口!$D$39=0,"",[1]财务取数接口!$D$39),"")) | E40: =IF($T$4=0,IF($L40="","",$L40),IFERROR(IF([1]财务取数接口!$E$39=0,"",[1]财务取数接口!$E$39),"")) -> 筐 | F40: =IF($T$4=0,IF($M40="","",$M40),IFERROR(IF([1]财务取数接口!$G$39=0,"",[1]财务取数接口!$G$39),"")) | G40: =IF($T$4=0,IF($N40="","",$N40),IFERROR(IF([1]财务取数接口!$H$39=0,"",[1]财务取数接口!$H$39),"")) | H40: =IF($T$4=0,IF($O40="","",$O40),IFERROR(IF([1]财务取数接口!$I$39=0,"",[1]财务取数接口!$I$39),"")) | P40: =IF(AND($C40<>"",$C40<>"项目",OR(N($D40)<>0,N($E40)<>0,N($F40)<>0)),1,0) -> 0 | Q40: =N(Q39)+$P40 -> 3
...

Sheet 对接源_02物料
A1: 对 接 源 · 02 物料与周转物台账（跨文件自动取数 · 断链时自动改用应急备份） | S1: 有效行数 | T1: =MAX($Q$5:$Q$460) -> 5
A2: =IF($T$4=1,"✔ 链接正常，已自动取到 "&$T$1&" 行（只算有金额/数量的行） ｜ 本表 1:1 对应《02 物料与周转物台账》的【财务取数接口】第 4～309 行","★★ 链接没接上！当前取数来源："&$T$5&" → 见 S6 修复说明") -> ✔ 链接正常，已自动取到 5 行（只算有金额/数量的行） ｜ 本表 1:1 对应《02 物料与周转物台账》的【财务取数接口】第 4～309 行 | S2: 链接探针 | T2: =IFERROR(IF([2]财务取数接口!$C$4=0,"未更新",[2]财务取数接口!$C$4),"断开") -> 筐子销售
A3: 一、实 际 使 用 值（链接正常时＝自动取数；链接断了自动切到右边备份） | I3: 二、应 急 备 份 区（手工粘贴数值） | P3: 状态 | S3: 备份行数 | T3: =COUNTIF($J$5:$J$460,"?*")-COUNTIF($J$5:$J$460,"项目") -> 0
A4: 源行 | B4: 年月 / 往来单位 | C4: 项目 | D4: 计费数量 / 应收发生额 | E4: 单位 / 应付发生额 | F4: 价税合计金额 | G4: 已收金额 | H4: 备注 | I4: 备份-年月 | J4: 备份-项目 | K4: 备份-数量 | L4: 备份-单位 | M4: 备份-金额 | N4: 备份-已收 | O4: 备份-备注 | P4: 有效 | Q4: 累计 | S4: 链接可用 | T4: =IF(OR($T$2="断开",$T$2="未更新"),0,1) -> 1
A5: 4 | B5: =IF($T$4=0,IF($I5="","",$I5),IFERROR(IF([2]财务取数接口!$B$4=0,"",[2]财务取数接口!$B$4),"")) | C5: =IF($T$4=0,IF($J5="","",$J5),IFERROR(IF([2]财务取数接口!$C$4=0,"",[2]财务取数接口!$C$4),"")) -> 筐子销售 | D5: =IF($T$4=0,IF($K5="","",$K5),IFERROR(IF([2]财务取数接口!$D$4=0,"",[2]财务取数接口!$D$4),"")) | E5: =IF($T$4=0,IF($L5="","",$L5),IFERROR(IF([2]财务取数接口!$E$4=0,"",[2]财务取数接口!$E$4),"")) -> 个 | F5: =IF($T$4=0,IF($M5="","",$M5),IFERROR(IF([2]财务取数接口!$G$4=0,"",[2]财务取数接口!$G$4),"")) | G5: =IF($T$4=0,IF($N5="","",$N5),IFERROR(IF([2]财务取数接口!$H$4=0,"",[2]财务取数接口!$H$4),"")) | H5: =IF($T$4=0,IF($O5="","",$O5),IFERROR(IF([2]财务取数接口!$I$4=0,"",[2]财务取数接口!$I$4),"")) | P5: =IF(AND($C5<>"",$C5<>"项目",OR(N($D5)<>0,N($E5)<>0,N($F5)<>0)),1,0) -> 0 | Q5: =N(Q4)+$P5 -> 0 | S5: 当前取数来源 | T5: =IF($T$4=1,"自动（跨文件链接）",IF($T$3>0,"应急备份","无数据")) -> 自动（跨文件链接）
A6: 5 | B6: =IF($T$4=0,IF($I6="","",$I6),IFERROR(IF([2]财务取数接口!$B$5=0,"",[2]财务取数接口!$B$5),"")) | C6: =IF($T$4=0,IF($J6="","",$J6),IFERROR(IF([2]财务取数接口!$C$5=0,"",[2]财务取数接口!$C$5),"")) -> 筐子销售 | D6: =IF($T$4=0,IF($K6="","",$K6),IFERROR(IF([2]财务取数接口!$D$5=0,"",[2]财务取数接口!$D$5),"")) | E6: =IF($T$4=0,IF($L6="","",$L6),IFERROR(IF([2]财务取数接口!$E$5=0,"",[2]财务取数接口!$E$5),"")) -> 个 | F6: =IF($T$4=0,IF($M6="","",$M6),IFERROR(IF([2]财务取数接口!$G$5=0,"",[2]财务取数接口!$G$5),"")) | G6: =IF($T$4=0,IF($N6="","",$N6),IFERROR(IF([2]财务取数接口!$H$5=0,"",[2]财务取数接口!$H$5),"")) | H6: =IF($T$4=0,IF($O6="","",$O6),IFERROR(IF([2]财务取数接口!$I$5=0,"",[2]财务取数接口!$I$5),"")) | P6: =IF(AND($C6<>"",$C6<>"项目",OR(N($D6)<>0,N($E6)<>0,N($F6)<>0)),1,0) -> 0 | Q6: =N(Q5)+$P6 -> 0 | S6: =IF($T$2="断开",IF($T$3>0,"✘ 链接已断开，正在用【应急备份区】的 "&$T$3&" 行数据出账（不是实时数）。修复：菜单【数据】→【编辑链接】→【更改源】，重新指向《02_物料与周转物台账模板.xlsx》","✘ 链接已断开，而且应急备份区是空的，本册报表将缺少这本业务册的全部数据。修复：菜单【数据】→【编辑链接】→【更改源】，重新指向《02_物料与周转物台账模板.xlsx》"),IF($T$2="未更新",IF($T$3>0,"★ 链接还没更新，或者那两个文件被改名、挪走了。正在用【应急备份区】的 "&$T$3&" 行数据出账（不是实时数）。修复：菜单【数据】→【编辑链接】→先点【立即更新值】；还是取不到数就点【更改源】重新指向《02_物料与周转物台账模板.xlsx》","★ 链接还没更新，或者那两个文件被改名、挪走了，而且没有应急备份，本册报表会缺少这本业务册的全部数据。修复：菜单【数据】→【编辑链接】→先点【立即更新值】；还是取不到数就点【更改源】重新指向《02_物料与周转物台账模板.xlsx》"),"✔ 链接正常，已自动取到 "&$T$1&" 行。备份区现有 "&$T$3&" 行。建议每月底把 B5:H156 复制→选择性粘贴【数值】到 I5，作为断链时的兜底")) -> ✔ 链接正常，已自动取到 5 行。备份区现有 0 行。建议每月底把 B5:H156 复制→选择性粘贴【数值】到 I5，作为断链时的兜底
A7: 6 | B7: =IF($T$4=0,IF($I7="","",$I7),IFERROR(IF([2]财务取数接口!$B$6=0,"",[2]财务取数接口!$B$6),"")) | C7: =IF($T$4=0,IF($J7="","",$J7),IFERROR(IF([2]财务取数接口!$C$6=0,"",[2]财务取数接口!$C$6),"")) -> 筐子销售 | D7: =IF($T$4=0,IF($K7="","",$K7),IFERROR(IF([2]财务取数接口!$D$6=0,"",[2]财务取数接口!$D$6),"")) | E7: =IF($T$4=0,IF($L7="","",$L7),IFERROR(IF([2]财务取数接口!$E$6=0,"",[2]财务取数接口!$E$6),"")) -> 个 | F7: =IF($T$4=0,IF($M7="","",$M7),IFERROR(IF([2]财务取数接口!$G$6=0,"",[2]财务取数接口!$G$6),"")) | G7: =IF($T$4=0,IF($N7="","",$N7),IFERROR(IF([2]财务取数接口!$H$6=0,"",[2]财务取数接口!$H$6),"")) | H7: =IF($T$4=0,IF($O7="","",$O7),IFERROR(IF([2]财务取数接口!$I$6=0,"",[2]财务取数接口!$I$6),"")) | P7: =IF(AND($C7<>"",$C7<>"项目",OR(N($D7)<>0,N($E7)<>0,N($F7)<>0)),1,0) -> 0 | Q7: =N(Q6)+$P7 -> 0
A8: 7 | B8: =IF($T$4=0,IF($I8="","",$I8),IFERROR(IF([2]财务取数接口!$B$7=0,"",[2]财务取数接口!$B$7),"")) | C8: =IF($T$4=0,IF($J8="","",$J8),IFERROR(IF([2]财务取数接口!$C$7=0,"",[2]财务取数接口!$C$7),"")) -> 筐子销售 | D8: =IF($T$4=0,IF($K8="","",$K8),IFERROR(IF([2]财务取数接口!$D$7=0,"",[2]财务取数接口!$D$7),"")) | E8: =IF($T$4=0,IF($L8="","",$L8),IFERROR(IF([2]财务取数接口!$E$7=0,"",[2]财务取数接口!$E$7),"")) -> 个 | F8: =IF($T$4=0,IF($M8="","",$M8),IFERROR(IF([2]财务取数接口!$G$7=0,"",[2]财务取数接口!$G$7),"")) | G8: =IF($T$4=0,IF($N8="","",$N8),IFERROR(IF([2]财务取数接口!$H$7=0,"",[2]财务取数接口!$H$7),"")) | H8: =IF($T$4=0,IF($O8="","",$O8),IFERROR(IF([2]财务取数接口!$I$7=0,"",[2]财务取数接口!$I$7),"")) | P8: =IF(AND($C8<>"",$C8<>"项目",OR(N($D8)<>0,N($E8)<>0,N($F8)<>0)),1,0) -> 0 | Q8: =N(Q7)+$P8 -> 0
A9: 8 | B9: =IF($T$4=0,IF($I9="","",$I9),IFERROR(IF([2]财务取数接口!$B$8=0,"",[2]财务取数接口!$B$8),"")) | C9: =IF($T$4=0,IF($J9="","",$J9),IFERROR(IF([2]财务取数接口!$C$8=0,"",[2]财务取数接口!$C$8),"")) -> 筐子销售 | D9: =IF($T$4=0,IF($K9="","",$K9),IFERROR(IF([2]财务取数接口!$D$8=0,"",[2]财务取数接口!$D$8),"")) | E9: =IF($T$4=0,IF($L9="","",$L9),IFERROR(IF([2]财务取数接口!$E$8=0,"",[2]财务取数接口!$E$8),"")) -> 个 | F9: =IF($T$4=0,IF($M9="","",$M9),IFERROR(IF([2]财务取数接口!$G$8=0,"",[2]财务取数接口!$G$8),"")) | G9: =IF($T$4=0,IF($N9="","",$N9),IFERROR(IF([2]财务取数接口!$H$8=0,"",[2]财务取数接口!$H$8),"")) | H9: =IF($T$4=0,IF($O9="","",$O9),IFERROR(IF([2]财务取数接口!$I$8=0,"",[2]财务取数接口!$I$8),"")) | P9: =IF(AND($C9<>"",$C9<>"项目",OR(N($D9)<>0,N($E9)<>0,N($F9)<>0)),1,0) -> 0 | Q9: =N(Q8)+$P9 -> 0
A10: 9 | B10: =IF($T$4=0,IF($I10="","",$I10),IFERROR(IF([2]财务取数接口!$B$9=0,"",[2]财务取数接口!$B$9),"")) | C10: =IF($T$4=0,IF($J10="","",$J10),IFERROR(IF([2]财务取数接口!$C$9=0,"",[2]财务取数接口!$C$9),"")) -> 筐子销售 | D10: =IF($T$4=0,IF($K10="","",$K10),IFERROR(IF([2]财务取数接口!$D$9=0,"",[2]财务取数接口!$D$9),"")) | E10: =IF($T$4=0,IF($L10="","",$L10),IFERROR(IF([2]财务取数接口!$E$9=0,"",[2]财务取数接口!$E$9),"")) -> 个 | F10: =IF($T$4=0,IF($M10="","",$M10),IFERROR(IF([2]财务取数接口!$G$9=0,"",[2]财务取数接口!$G$9),"")) | G10: =IF($T$4=0,IF($N10="","",$N10),IFERROR(IF([2]财务取数接口!$H$9=0,"",[2]财务取数接口!$H$9),"")) | H10: =IF($T$4=0,IF($O10="","",$O10),IFERROR(IF([2]财务取数接口!$I$9=0,"",[2]财务取数接口!$I$9),"")) | P10: =IF(AND($C10<>"",$C10<>"项目",OR(N($D10)<>0,N($E10)<>0,N($F10)<>0)),1,0) -> 0 | Q10: =N(Q9)+$P10 -> 0
A11: 10 | B11: =IF($T$4=0,IF($I11="","",$I11),IFERROR(IF([2]财务取数接口!$B$10=0,"",[2]财务取数接口!$B$10),"")) | C11: =IF($T$4=0,IF($J11="","",$J11),IFERROR(IF([2]财务取数接口!$C$10=0,"",[2]财务取数接口!$C$10),"")) -> 筐子销售 | D11: =IF($T$4=0,IF($K11="","",$K11),IFERROR(IF([2]财务取数接口!$D$10=0,"",[2]财务取数接口!$D$10),"")) | E11: =IF($T$4=0,IF($L11="","",$L11),IFERROR(IF([2]财务取数接口!$E$10=0,"",[2]财务取数接口!$E$10),"")) -> 个 | F11: =IF($T$4=0,IF($M11="","",$M11),IFERROR(IF([2]财务取数接口!$G$10=0,"",[2]财务取数接口!$G$10),"")) | G11: =IF($T$4=0,IF($N11="","",$N11),IFERROR(IF([2]财务取数接口!$H$10=0,"",[2]财务取数接口!$H$10),"")) | H11: =IF($T$4=0,IF($O11="","",$O11),IFERROR(IF([2]财务取数接口!$I$10=0,"",[2]财务取数接口!$I$10),"")) | P11: =IF(AND($C11<>"",$C11<>"项目",OR(N($D11)<>0,N($E11)<>0,N($F11)<>0)),1,0) -> 0 | Q11: =N(Q10)+$P11 -> 0
A12: 11 | B12: =IF($T$4=0,IF($I12="","",$I12),IFERROR(IF([2]财务取数接口!$B$11=0,"",[2]财务取数接口!$B$11),"")) | C12: =IF($T$4=0,IF($J12="","",$J12),IFERROR(IF([2]财务取数接口!$C$11=0,"",[2]财务取数接口!$C$11),"")) -> 筐子销售 | D12: =IF($T$4=0,IF($K12="","",$K12),IFERROR(IF([2]财务取数接口!$D$11=0,"",[2]财务取数接口!$D$11),"")) | E12: =IF($T$4=0,IF($L12="","",$L12),IFERROR(IF([2]财务取数接口!$E$11=0,"",[2]财务取数接口!$E$11),"")) -> 个 | F12: =IF($T$4=0,IF($M12="","",$M12),IFERROR(IF([2]财务取数接口!$G$11=0,"",[2]财务取数接口!$G$11),"")) | G12: =IF($T$4=0,IF($N12="","",$N12),IFERROR(IF([2]财务取数接口!$H$11=0,"",[2]财务取数接口!$H$11),"")) | H12: =IF($T$4=0,IF($O12="","",$O12),IFERROR(IF([2]财务取数接口!$I$11=0,"",[2]财务取数接口!$I$11),"")) | P12: =IF(AND($C12<>"",$C12<>"项目",OR(N($D12)<>0,N($E12)<>0,N($F12)<>0)),1,0) -> 0 | Q12: =N(Q11)+$P12 -> 0
A13: 12 | B13: =IF($T$4=0,IF($I13="","",$I13),IFERROR(IF([2]财务取数接口!$B$12=0,"",[2]财务取数接口!$B$12),"")) | C13: =IF($T$4=0,IF($J13="","",$J13),IFERROR(IF([2]财务取数接口!$C$12=0,"",[2]财务取数接口!$C$12),"")) -> 筐子销售 | D13: =IF($T$4=0,IF($K13="","",$K13),IFERROR(IF([2]财务取数接口!$D$12=0,"",[2]财务取数接口!$D$12),"")) | E13: =IF($T$4=0,IF($L13="","",$L13),IFERROR(IF([2]财务取数接口!$E$12=0,"",[2]财务取数接口!$E$12),"")) -> 个 | F13: =IF($T$4=0,IF($M13="","",$M13),IFERROR(IF([2]财务取数接口!$G$12=0,"",[2]财务取数接口!$G$12),"")) | G13: =IF($T$4=0,IF($N13="","",$N13),IFERROR(IF([2]财务取数接口!$H$12=0,"",[2]财务取数接口!$H$12),"")) | H13: =IF($T$4=0,IF($O13="","",$O13),IFERROR(IF([2]财务取数接口!$I$12=0,"",[2]财务取数接口!$I$12),"")) | P13: =IF(AND($C13<>"",$C13<>"项目",OR(N($D13)<>0,N($E13)<>0,N($F13)<>0)),1,0) -> 0 | Q13: =N(Q12)+$P13 -> 0
A14: 13 | B14: =IF($T$4=0,IF($I14="","",$I14),IFERROR(IF([2]财务取数接口!$B$13=0,"",[2]财务取数接口!$B$13),"")) | C14: =IF($T$4=0,IF($J14="","",$J14),IFERROR(IF([2]财务取数接口!$C$13=0,"",[2]财务取数接口!$C$13),"")) -> 筐子销售 | D14: =IF($T$4=0,IF($K14="","",$K14),IFERROR(IF([2]财务取数接口!$D$13=0,"",[2]财务取数接口!$D$13),"")) | E14: =IF($T$4=0,IF($L14="","",$L14),IFERROR(IF([2]财务取数接口!$E$13=0,"",[2]财务取数接口!$E$13),"")) -> 个 | F14: =IF($T$4=0,IF($M14="","",$M14),IFERROR(IF([2]财务取数接口!$G$13=0,"",[2]财务取数接口!$G$13),"")) | G14: =IF($T$4=0,IF($N14="","",$N14),IFERROR(IF([2]财务取数接口!$H$13=0,"",[2]财务取数接口!$H$13),"")) | H14: =IF($T$4=0,IF($O14="","",$O14),IFERROR(IF([2]财务取数接口!$I$13=0,"",[2]财务取数接口!$I$13),"")) | P14: =IF(AND($C14<>"",$C14<>"项目",OR(N($D14)<>0,N($E14)<>0,N($F14)<>0)),1,0) -> 0 | Q14: =N(Q13)+$P14 -> 0
A15: 14 | B15: =IF($T$4=0,IF($I15="","",$I15),IFERROR(IF([2]财务取数接口!$B$14=0,"",[2]财务取数接口!$B$14),"")) | C15: =IF($T$4=0,IF($J15="","",$J15),IFERROR(IF([2]财务取数接口!$C$14=0,"",[2]财务取数接口!$C$14),"")) -> 筐子销售 | D15: =IF($T$4=0,IF($K15="","",$K15),IFERROR(IF([2]财务取数接口!$D$14=0,"",[2]财务取数接口!$D$14),"")) | E15: =IF($T$4=0,IF($L15="","",$L15),IFERROR(IF([2]财务取数接口!$E$14=0,"",[2]财务取数接口!$E$14),"")) -> 个 | F15: =IF($T$4=0,IF($M15="","",$M15),IFERROR(IF([2]财务取数接口!$G$14=0,"",[2]财务取数接口!$G$14),"")) | G15: =IF($T$4=0,IF($N15="","",$N15),IFERROR(IF([2]财务取数接口!$H$14=0,"",[2]财务取数接口!$H$14),"")) | H15: =IF($T$4=0,IF($O15="","",$O15),IFERROR(IF([2]财务取数接口!$I$14=0,"",[2]财务取数接口!$I$14),"")) | P15: =IF(AND($C15<>"",$C15<>"项目",OR(N($D15)<>0,N($E15)<>0,N($F15)<>0)),1,0) -> 0 | Q15: =N(Q14)+$P15 -> 0
A16: 15 | B16: =IF($T$4=0,IF($I16="","",$I16),IFERROR(IF([2]财务取数接口!$B$15=0,"",[2]财务取数接口!$B$15),"")) | C16: =IF($T$4=0,IF($J16="","",$J16),IFERROR(IF([2]财务取数接口!$C$15=0,"",[2]财务取数接口!$C$15),"")) -> 筐子销售 | D16: =IF($T$4=0,IF($K16="","",$K16),IFERROR(IF([2]财务取数接口!$D$15=0,"",[2]财务取数接口!$D$15),"")) | E16: =IF($T$4=0,IF($L16="","",$L16),IFERROR(IF([2]财务取数接口!$E$15=0,"",[2]财务取数接口!$E$15),"")) -> 个 | F16: =IF($T$4=0,IF($M16="","",$M16),IFERROR(IF([2]财务取数接口!$G$15=0,"",[2]财务取数接口!$G$15),"")) | G16: =IF($T$4=0,IF($N16="","",$N16),IFERROR(IF([2]财务取数接口!$H$15=0,"",[2]财务取数接口!$H$15),"")) | H16: =IF($T$4=0,IF($O16="","",$O16),IFERROR(IF([2]财务取数接口!$I$15=0,"",[2]财务取数接口!$I$15),"")) | P16: =IF(AND($C16<>"",$C16<>"项目",OR(N($D16)<>0,N($E16)<>0,N($F16)<>0)),1,0) -> 0 | Q16: =N(Q15)+$P16 -> 0
A17: 16 | B17: =IF($T$4=0,IF($I17="","",$I17),IFERROR(IF([2]财务取数接口!$B$16=0,"",[2]财务取数接口!$B$16),"")) | C17: =IF($T$4=0,IF($J17="","",$J17),IFERROR(IF([2]财务取数接口!$C$16=0,"",[2]财务取数接口!$C$16),"")) -> 筐子销售 | D17: =IF($T$4=0,IF($K17="","",$K17),IFERROR(IF([2]财务取数接口!$D$16=0,"",[2]财务取数接口!$D$16),"")) | E17: =IF($T$4=0,IF($L17="","",$L17),IFERROR(IF([2]财务取数接口!$E$16=0,"",[2]财务取数接口!$E$16),"")) -> 个 | F17: =IF($T$4=0,IF($M17="","",$M17),IFERROR(IF([2]财务取数接口!$G$16=0,"",[2]财务取数接口!$G$16),"")) | G17: =IF($T$4=0,IF($N17="","",$N17),IFERROR(IF([2]财务取数接口!$H$16=0,"",[2]财务取数接口!$H$16),"")) | H17: =IF($T$4=0,IF($O17="","",$O17),IFERROR(IF([2]财务取数接口!$I$16=0,"",[2]财务取数接口!$I$16),"")) | P17: =IF(AND($C17<>"",$C17<>"项目",OR(N($D17)<>0,N($E17)<>0,N($F17)<>0)),1,0) -> 0 | Q17: =N(Q16)+$P17 -> 0
A18: 17 | B18: =IF($T$4=0,IF($I18="","",$I18),IFERROR(IF([2]财务取数接口!$B$17=0,"",[2]财务取数接口!$B$17),"")) | C18: =IF($T$4=0,IF($J18="","",$J18),IFERROR(IF([2]财务取数接口!$C$17=0,"",[2]财务取数接口!$C$17),"")) -> 筐子销售 | D18: =IF($T$4=0,IF($K18="","",$K18),IFERROR(IF([2]财务取数接口!$D$17=0,"",[2]财务取数接口!$D$17),"")) | E18: =IF($T$4=0,IF($L18="","",$L18),IFERROR(IF([2]财务取数接口!$E$17=0,"",[2]财务取数接口!$E$17),"")) -> 个 | F18: =IF($T$4=0,IF($M18="","",$M18),IFERROR(IF([2]财务取数接口!$G$17=0,"",[2]财务取数接口!$G$17),"")) | G18: =IF($T$4=0,IF($N18="","",$N18),IFERROR(IF([2]财务取数接口!$H$17=0,"",[2]财务取数接口!$H$17),"")) | H18: =IF($T$4=0,IF($O18="","",$O18),IFERROR(IF([2]财务取数接口!$I$17=0,"",[2]财务取数接口!$I$17),"")) | P18: =IF(AND($C18<>"",$C18<>"项目",OR(N($D18)<>0,N($E18)<>0,N($F18)<>0)),1,0) -> 0 | Q18: =N(Q17)+$P18 -> 0
A19: 18 | B19: =IF($T$4=0,IF($I19="","",$I19),IFERROR(IF([2]财务取数接口!$B$18=0,"",[2]财务取数接口!$B$18),"")) | C19: =IF($T$4=0,IF($J19="","",$J19),IFERROR(IF([2]财务取数接口!$C$18=0,"",[2]财务取数接口!$C$18),"")) -> 筐子销售 | D19: =IF($T$4=0,IF($K19="","",$K19),IFERROR(IF([2]财务取数接口!$D$18=0,"",[2]财务取数接口!$D$18),"")) | E19: =IF($T$4=0,IF($L19="","",$L19),IFERROR(IF([2]财务取数接口!$E$18=0,"",[2]财务取数接口!$E$18),"")) -> 个 | F19: =IF($T$4=0,IF($M19="","",$M19),IFERROR(IF([2]财务取数接口!$G$18=0,"",[2]财务取数接口!$G$18),"")) | G19: =IF($T$4=0,IF($N19="","",$N19),IFERROR(IF([2]财务取数接口!$H$18=0,"",[2]财务取数接口!$H$18),"")) | H19: =IF($T$4=0,IF($O19="","",$O19),IFERROR(IF([2]财务取数接口!$I$18=0,"",[2]财务取数接口!$I$18),"")) | P19: =IF(AND($C19<>"",$C19<>"项目",OR(N($D19)<>0,N($E19)<>0,N($F19)<>0)),1,0) -> 0 | Q19: =N(Q18)+$P19 -> 0
A20: 19 | B20: =IF($T$4=0,IF($I20="","",$I20),IFERROR(IF([2]财务取数接口!$B$19=0,"",[2]财务取数接口!$B$19),"")) | C20: =IF($T$4=0,IF($J20="","",$J20),IFERROR(IF([2]财务取数接口!$C$19=0,"",[2]财务取数接口!$C$19),"")) -> 筐子销售 | D20: =IF($T$4=0,IF($K20="","",$K20),IFERROR(IF([2]财务取数接口!$D$19=0,"",[2]财务取数接口!$D$19),"")) | E20: =IF($T$4=0,IF($L20="","",$L20),IFERROR(IF([2]财务取数接口!$E$19=0,"",[2]财务取数接口!$E$19),"")) -> 个 | F20: =IF($T$4=0,IF($M20="","",$M20),IFERROR(IF([2]财务取数接口!$G$19=0,"",[2]财务取数接口!$G$19),"")) | G20: =IF($T$4=0,IF($N20="","",$N20),IFERROR(IF([2]财务取数接口!$H$19=0,"",[2]财务取数接口!$H$19),"")) | H20: =IF($T$4=0,IF($O20="","",$O20),IFERROR(IF([2]财务取数接口!$I$19=0,"",[2]财务取数接口!$I$19),"")) | P20: =IF(AND($C20<>"",$C20<>"项目",OR(N($D20)<>0,N($E20)<>0,N($F20)<>0)),1,0) -> 0 | Q20: =N(Q19)+$P20 -> 0
A21: 20 | B21: =IF($T$4=0,IF($I21="","",$I21),IFERROR(IF([2]财务取数接口!$B$20=0,"",[2]财务取数接口!$B$20),"")) | C21: =IF($T$4=0,IF($J21="","",$J21),IFERROR(IF([2]财务取数接口!$C$20=0,"",[2]财务取数接口!$C$20),"")) -> 筐子销售 | D21: =IF($T$4=0,IF($K21="","",$K21),IFERROR(IF([2]财务取数接口!$D$20=0,"",[2]财务取数接口!$D$20),"")) | E21: =IF($T$4=0,IF($L21="","",$L21),IFERROR(IF([2]财务取数接口!$E$20=0,"",[2]财务取数接口!$E$20),"")) -> 个 | F21: =IF($T$4=0,IF($M21="","",$M21),IFERROR(IF([2]财务取数接口!$G$20=0,"",[2]财务取数接口!$G$20),"")) | G21: =IF($T$4=0,IF($N21="","",$N21),IFERROR(IF([2]财务取数接口!$H$20=0,"",[2]财务取数接口!$H$20),"")) | H21: =IF($T$4=0,IF($O21="","",$O21),IFERROR(IF([2]财务取数接口!$I$20=0,"",[2]财务取数接口!$I$20),"")) | P21: =IF(AND($C21<>"",$C21<>"项目",OR(N($D21)<>0,N($E21)<>0,N($F21)<>0)),1,0) -> 0 | Q21: =N(Q20)+$P21 -> 0
A22: 21 | B22: =IF($T$4=0,IF($I22="","",$I22),IFERROR(IF([2]财务取数接口!$B$21=0,"",[2]财务取数接口!$B$21),"")) | C22: =IF($T$4=0,IF($J22="","",$J22),IFERROR(IF([2]财务取数接口!$C$21=0,"",[2]财务取数接口!$C$21),"")) -> 筐子销售 | D22: =IF($T$4=0,IF($K22="","",$K22),IFERROR(IF([2]财务取数接口!$D$21=0,"",[2]财务取数接口!$D$21),"")) | E22: =IF($T$4=0,IF($L22="","",$L22),IFERROR(IF([2]财务取数接口!$E$21=0,"",[2]财务取数接口!$E$21),"")) -> 个 | F22: =IF($T$4=0,IF($M22="","",$M22),IFERROR(IF([2]财务取数接口!$G$21=0,"",[2]财务取数接口!$G$21),"")) | G22: =IF($T$4=0,IF($N22="","",$N22),IFERROR(IF([2]财务取数接口!$H$21=0,"",[2]财务取数接口!$H$21),"")) | H22: =IF($T$4=0,IF($O22="","",$O22),IFERROR(IF([2]财务取数接口!$I$21=0,"",[2]财务取数接口!$I$21),"")) | P22: =IF(AND($C22<>"",$C22<>"项目",OR(N($D22)<>0,N($E22)<>0,N($F22)<>0)),1,0) -> 0 | Q22: =N(Q21)+$P22 -> 0
A23: 22 | B23: =IF($T$4=0,IF($I23="","",$I23),IFERROR(IF([2]财务取数接口!$B$22=0,"",[2]财务取数接口!$B$22),"")) | C23: =IF($T$4=0,IF($J23="","",$J23),IFERROR(IF([2]财务取数接口!$C$22=0,"",[2]财务取数接口!$C$22),"")) -> 筐子销售 | D23: =IF($T$4=0,IF($K23="","",$K23),IFERROR(IF([2]财务取数接口!$D$22=0,"",[2]财务取数接口!$D$22),"")) | E23: =IF($T$4=0,IF($L23="","",$L23),IFERROR(IF([2]财务取数接口!$E$22=0,"",[2]财务取数接口!$E$22),"")) -> 个 | F23: =IF($T$4=0,IF($M23="","",$M23),IFERROR(IF([2]财务取数接口!$G$22=0,"",[2]财务取数接口!$G$22),"")) | G23: =IF($T$4=0,IF($N23="","",$N23),IFERROR(IF([2]财务取数接口!$H$22=0,"",[2]财务取数接口!$H$22),"")) | H23: =IF($T$4=0,IF($O23="","",$O23),IFERROR(IF([2]财务取数接口!$I$22=0,"",[2]财务取数接口!$I$22),"")) | P23: =IF(AND($C23<>"",$C23<>"项目",OR(N($D23)<>0,N($E23)<>0,N($F23)<>0)),1,0) -> 0 | Q23: =N(Q22)+$P23 -> 0
A24: 23 | B24: =IF($T$4=0,IF($I24="","",$I24),IFERROR(IF([2]财务取数接口!$B$23=0,"",[2]财务取数接口!$B$23),"")) | C24: =IF($T$4=0,IF($J24="","",$J24),IFERROR(IF([2]财务取数接口!$C$23=0,"",[2]财务取数接口!$C$23),"")) -> 筐子销售 | D24: =IF($T$4=0,IF($K24="","",$K24),IFERROR(IF([2]财务取数接口!$D$23=0,"",[2]财务取数接口!$D$23),"")) | E24: =IF($T$4=0,IF($L24="","",$L24),IFERROR(IF([2]财务取数接口!$E$23=0,"",[2]财务取数接口!$E$23),"")) -> 个 | F24: =IF($T$4=0,IF($M24="","",$M24),IFERROR(IF([2]财务取数接口!$G$23=0,"",[2]财务取数接口!$G$23),"")) | G24: =IF($T$4=0,IF($N24="","",$N24),IFERROR(IF([2]财务取数接口!$H$23=0,"",[2]财务取数接口!$H$23),"")) | H24: =IF($T$4=0,IF($O24="","",$O24),IFERROR(IF([2]财务取数接口!$I$23=0,"",[2]财务取数接口!$I$23),"")) | P24: =IF(AND($C24<>"",$C24<>"项目",OR(N($D24)<>0,N($E24)<>0,N($F24)<>0)),1,0) -> 0 | Q24: =N(Q23)+$P24 -> 0
A25: 24 | B25: =IF($T$4=0,IF($I25="","",$I25),IFERROR(IF([2]财务取数接口!$B$24=0,"",[2]财务取数接口!$B$24),"")) | C25: =IF($T$4=0,IF($J25="","",$J25),IFERROR(IF([2]财务取数接口!$C$24=0,"",[2]财务取数接口!$C$24),"")) -> 筐子销售 | D25: =IF($T$4=0,IF($K25="","",$K25),IFERROR(IF([2]财务取数接口!$D$24=0,"",[2]财务取数接口!$D$24),"")) | E25: =IF($T$4=0,IF($L25="","",$L25),IFERROR(IF([2]财务取数接口!$E$24=0,"",[2]财务取数接口!$E$24),"")) -> 个 | F25: =IF($T$4=0,IF($M25="","",$M25),IFERROR(IF([2]财务取数接口!$G$24=0,"",[2]财务取数接口!$G$24),"")) | G25: =IF($T$4=0,IF($N25="","",$N25),IFERROR(IF([2]财务取数接口!$H$24=0,"",[2]财务取数接口!$H$24),"")) | H25: =IF($T$4=0,IF($O25="","",$O25),IFERROR(IF([2]财务取数接口!$I$24=0,"",[2]财务取数接口!$I$24),"")) | P25: =IF(AND($C25<>"",$C25<>"项目",OR(N($D25)<>0,N($E25)<>0,N($F25)<>0)),1,0) -> 0 | Q25: =N(Q24)+$P25 -> 0
A26: 25 | B26: =IF($T$4=0,IF($I26="","",$I26),IFERROR(IF([2]财务取数接口!$B$25=0,"",[2]财务取数接口!$B$25),"")) | C26: =IF($T$4=0,IF($J26="","",$J26),IFERROR(IF([2]财务取数接口!$C$25=0,"",[2]财务取数接口!$C$25),"")) -> 筐子销售 | D26: =IF($T$4=0,IF($K26="","",$K26),IFERROR(IF([2]财务取数接口!$D$25=0,"",[2]财务取数接口!$D$25),"")) | E26: =IF($T$4=0,IF($L26="","",$L26),IFERROR(IF([2]财务取数接口!$E$25=0,"",[2]财务取数接口!$E$25),"")) -> 个 | F26: =IF($T$4=0,IF($M26="","",$M26),IFERROR(IF([2]财务取数接口!$G$25=0,"",[2]财务取数接口!$G$25),"")) | G26: =IF($T$4=0,IF($N26="","",$N26),IFERROR(IF([2]财务取数接口!$H$25=0,"",[2]财务取数接口!$H$25),"")) | H26: =IF($T$4=0,IF($O26="","",$O26),IFERROR(IF([2]财务取数接口!$I$25=0,"",[2]财务取数接口!$I$25),"")) | P26: =IF(AND($C26<>"",$C26<>"项目",OR(N($D26)<>0,N($E26)<>0,N($F26)<>0)),1,0) -> 0 | Q26: =N(Q25)+$P26 -> 0
A27: 26 | B27: =IF($T$4=0,IF($I27="","",$I27),IFERROR(IF([2]财务取数接口!$B$26=0,"",[2]财务取数接口!$B$26),"")) | C27: =IF($T$4=0,IF($J27="","",$J27),IFERROR(IF([2]财务取数接口!$C$26=0,"",[2]财务取数接口!$C$26),"")) -> 筐子销售 | D27: =IF($T$4=0,IF($K27="","",$K27),IFERROR(IF([2]财务取数接口!$D$26=0,"",[2]财务取数接口!$D$26),"")) | E27: =IF($T$4=0,IF($L27="","",$L27),IFERROR(IF([2]财务取数接口!$E$26=0,"",[2]财务取数接口!$E$26),"")) -> 个 | F27: =IF($T$4=0,IF($M27="","",$M27),IFERROR(IF([2]财务取数接口!$G$26=0,"",[2]财务取数接口!$G$26),"")) | G27: =IF($T$4=0,IF($N27="","",$N27),IFERROR(IF([2]财务取数接口!$H$26=0,"",[2]财务取数接口!$H$26),"")) | H27: =IF($T$4=0,IF($O27="","",$O27),IFERROR(IF([2]财务取数接口!$I$26=0,"",[2]财务取数接口!$I$26),"")) | P27: =IF(AND($C27<>"",$C27<>"项目",OR(N($D27)<>0,N($E27)<>0,N($F27)<>0)),1,0) -> 0 | Q27: =N(Q26)+$P27 -> 0
A28: 27 | B28: =IF($T$4=0,IF($I28="","",$I28),IFERROR(IF([2]财务取数接口!$B$27=0,"",[2]财务取数接口!$B$27),"")) | C28: =IF($T$4=0,IF($J28="","",$J28),IFERROR(IF([2]财务取数接口!$C$27=0,"",[2]财务取数接口!$C$27),"")) -> 筐子销售 | D28: =IF($T$4=0,IF($K28="","",$K28),IFERROR(IF([2]财务取数接口!$D$27=0,"",[2]财务取数接口!$D$27),"")) | E28: =IF($T$4=0,IF($L28="","",$L28),IFERROR(IF([2]财务取数接口!$E$27=0,"",[2]财务取数接口!$E$27),"")) -> 个 | F28: =IF($T$4=0,IF($M28="","",$M28),IFERROR(IF([2]财务取数接口!$G$27=0,"",[2]财务取数接口!$G$27),"")) | G28: =IF($T$4=0,IF($N28="","",$N28),IFERROR(IF([2]财务取数接口!$H$27=0,"",[2]财务取数接口!$H$27),"")) | H28: =IF($T$4=0,IF($O28="","",$O28),IFERROR(IF([2]财务取数接口!$I$27=0,"",[2]财务取数接口!$I$27),"")) | P28: =IF(AND($C28<>"",$C28<>"项目",OR(N($D28)<>0,N($E28)<>0,N($F28)<>0)),1,0) -> 0 | Q28: =N(Q27)+$P28 -> 0
A29: 28 | B29: =IF($T$4=0,IF($I29="","",$I29),IFERROR(IF([2]财务取数接口!$B$28=0,"",[2]财务取数接口!$B$28),"")) | C29: =IF($T$4=0,IF($J29="","",$J29),IFERROR(IF([2]财务取数接口!$C$28=0,"",[2]财务取数接口!$C$28),"")) -> 物料销售 | D29: =IF($T$4=0,IF($K29="","",$K29),IFERROR(IF([2]财务取数接口!$D$28=0,"",[2]财务取数接口!$D$28),"")) | E29: =IF($T$4=0,IF($L29="","",$L29),IFERROR(IF([2]财务取数接口!$E$28=0,"",[2]财务取数接口!$E$28),"")) -> 包 | F29: =IF($T$4=0,IF($M29="","",$M29),IFERROR(IF([2]财务取数接口!$G$28=0,"",[2]财务取数接口!$G$28),"")) | G29: =IF($T$4=0,IF($N29="","",$N29),IFERROR(IF([2]财务取数接口!$H$28=0,"",[2]财务取数接口!$H$28),"")) | H29: =IF($T$4=0,IF($O29="","",$O29),IFERROR(IF([2]财务取数接口!$I$28=0,"",[2]财务取数接口!$I$28),"")) | P29: =IF(AND($C29<>"",$C29<>"项目",OR(N($D29)<>0,N($E29)<>0,N($F29)<>0)),1,0) -> 0 | Q29: =N(Q28)+$P29 -> 0
A30: 29 | B30: =IF($T$4=0,IF($I30="","",$I30),IFERROR(IF([2]财务取数接口!$B$29=0,"",[2]财务取数接口!$B$29),"")) | C30: =IF($T$4=0,IF($J30="","",$J30),IFERROR(IF([2]财务取数接口!$C$29=0,"",[2]财务取数接口!$C$29),"")) -> 物料销售 | D30: =IF($T$4=0,IF($K30="","",$K30),IFERROR(IF([2]财务取数接口!$D$29=0,"",[2]财务取数接口!$D$29),"")) | E30: =IF($T$4=0,IF($L30="","",$L30),IFERROR(IF([2]财务取数接口!$E$29=0,"",[2]财务取数接口!$E$29),"")) -> 包 | F30: =IF($T$4=0,IF($M30="","",$M30),IFERROR(IF([2]财务取数接口!$G$29=0,"",[2]财务取数接口!$G$29),"")) | G30: =IF($T$4=0,IF($N30="","",$N30),IFERROR(IF([2]财务取数接口!$H$29=0,"",[2]财务取数接口!$H$29),"")) | H30: =IF($T$4=0,IF($O30="","",$O30),IFERROR(IF([2]财务取数接口!$I$29=0,"",[2]财务取数接口!$I$29),"")) | P30: =IF(AND($C30<>"",$C30<>"项目",OR(N($D30)<>0,N($E30)<>0,N($F30)<>0)),1,0) -> 0 | Q30: =N(Q29)+$P30 -> 0
A31: 30 | B31: =IF($T$4=0,IF($I31="","",$I31),IFERROR(IF([2]财务取数接口!$B$30=0,"",[2]财务取数接口!$B$30),"")) | C31: =IF($T$4=0,IF($J31="","",$J31),IFERROR(IF([2]财务取数接口!$C$30=0,"",[2]财务取数接口!$C$30),"")) -> 物料销售 | D31: =IF($T$4=0,IF($K31="","",$K31),IFERROR(IF([2]财务取数接口!$D$30=0,"",[2]财务取数接口!$D$30),"")) | E31: =IF($T$4=0,IF($L31="","",$L31),IFERROR(IF([2]财务取数接口!$E$30=0,"",[2]财务取数接口!$E$30),"")) -> 包 | F31: =IF($T$4=0,IF($M31="","",$M31),IFERROR(IF([2]财务取数接口!$G$30=0,"",[2]财务取数接口!$G$30),"")) | G31: =IF($T$4=0,IF($N31="","",$N31),IFERROR(IF([2]财务取数接口!$H$30=0,"",[2]财务取数接口!$H$30),"")) | H31: =IF($T$4=0,IF($O31="","",$O31),IFERROR(IF([2]财务取数接口!$I$30=0,"",[2]财务取数接口!$I$30),"")) | P31: =IF(AND($C31<>"",$C31<>"项目",OR(N($D31)<>0,N($E31)<>0,N($F31)<>0)),1,0) -> 0 | Q31: =N(Q30)+$P31 -> 0
A32: 31 | B32: =IF($T$4=0,IF($I32="","",$I32),IFERROR(IF([2]财务取数接口!$B$31=0,"",[2]财务取数接口!$B$31),"")) | C32: =IF($T$4=0,IF($J32="","",$J32),IFERROR(IF([2]财务取数接口!$C$31=0,"",[2]财务取数接口!$C$31),"")) -> 物料销售 | D32: =IF($T$4=0,IF($K32="","",$K32),IFERROR(IF([2]财务取数接口!$D$31=0,"",[2]财务取数接口!$D$31),"")) | E32: =IF($T$4=0,IF($L32="","",$L32),IFERROR(IF([2]财务取数接口!$E$31=0,"",[2]财务取数接口!$E$31),"")) -> 包 | F32: =IF($T$4=0,IF($M32="","",$M32),IFERROR(IF([2]财务取数接口!$G$31=0,"",[2]财务取数接口!$G$31),"")) | G32: =IF($T$4=0,IF($N32="","",$N32),IFERROR(IF([2]财务取数接口!$H$31=0,"",[2]财务取数接口!$H$31),"")) | H32: =IF($T$4=0,IF($O32="","",$O32),IFERROR(IF([2]财务取数接口!$I$31=0,"",[2]财务取数接口!$I$31),"")) | P32: =IF(AND($C32<>"",$C32<>"项目",OR(N($D32)<>0,N($E32)<>0,N($F32)<>0)),1,0) -> 0 | Q32: =N(Q31)+$P32 -> 0
A33: 32 | B33: =IF($T$4=0,IF($I33="","",$I33),IFERROR(IF([2]财务取数接口!$B$32=0,"",[2]财务取数接口!$B$32),"")) | C33: =IF($T$4=0,IF($J33="","",$J33),IFERROR(IF([2]财务取数接口!$C$32=0,"",[2]财务取数接口!$C$32),"")) -> 物料销售 | D33: =IF($T$4=0,IF($K33="","",$K33),IFERROR(IF([2]财务取数接口!$D$32=0,"",[2]财务取数接口!$D$32),"")) | E33: =IF($T$4=0,IF($L33="","",$L33),IFERROR(IF([2]财务取数接口!$E$32=0,"",[2]财务取数接口!$E$32),"")) -> 包 | F33: =IF($T$4=0,IF($M33="","",$M33),IFERROR(IF([2]财务取数接口!$G$32=0,"",[2]财务取数接口!$G$32),"")) | G33: =IF($T$4=0,IF($N33="","",$N33),IFERROR(IF([2]财务取数接口!$H$32=0,"",[2]财务取数接口!$H$32),"")) | H33: =IF($T$4=0,IF($O33="","",$O33),IFERROR(IF([2]财务取数接口!$I$32=0,"",[2]财务取数接口!$I$32),"")) | P33: =IF(AND($C33<>"",$C33<>"项目",OR(N($D33)<>0,N($E33)<>0,N($F33)<>0)),1,0) -> 0 | Q33: =N(Q32)+$P33 -> 0
A34: 33 | B34: =IF($T$4=0,IF($I34="","",$I34),IFERROR(IF([2]财务取数接口!$B$33=0,"",[2]财务取数接口!$B$33),"")) | C34: =IF($T$4=0,IF($J34="","",$J34),IFERROR(IF([2]财务取数接口!$C$33=0,"",[2]财务取数接口!$C$33),"")) -> 物料销售 | D34: =IF($T$4=0,IF($K34="","",$K34),IFERROR(IF([2]财务取数接口!$D$33=0,"",[2]财务取数接口!$D$33),"")) | E34: =IF($T$4=0,IF($L34="","",$L34),IFERROR(IF([2]财务取数接口!$E$33=0,"",[2]财务取数接口!$E$33),"")) -> 包 | F34: =IF($T$4=0,IF($M34="","",$M34),IFERROR(IF([2]财务取数接口!$G$33=0,"",[2]财务取数接口!$G$33),"")) | G34: =IF($T$4=0,IF($N34="","",$N34),IFERROR(IF([2]财务取数接口!$H$33=0,"",[2]财务取数接口!$H$33),"")) | H34: =IF($T$4=0,IF($O34="","",$O34),IFERROR(IF([2]财务取数接口!$I$33=0,"",[2]财务取数接口!$I$33),"")) | P34: =IF(AND($C34<>"",$C34<>"项目",OR(N($D34)<>0,N($E34)<>0,N($F34)<>0)),1,0) -> 0 | Q34: =N(Q33)+$P34 -> 0
A35: 34 | B35: =IF($T$4=0,IF($I35="","",$I35),IFERROR(IF([2]财务取数接口!$B$34=0,"",[2]财务取数接口!$B$34),"")) | C35: =IF($T$4=0,IF($J35="","",$J35),IFERROR(IF([2]财务取数接口!$C$34=0,"",[2]财务取数接口!$C$34),"")) -> 物料销售 | D35: =IF($T$4=0,IF($K35="","",$K35),IFERROR(IF([2]财务取数接口!$D$34=0,"",[2]财务取数接口!$D$34),"")) | E35: =IF($T$4=0,IF($L35="","",$L35),IFERROR(IF([2]财务取数接口!$E$34=0,"",[2]财务取数接口!$E$34),"")) -> 包 | F35: =IF($T$4=0,IF($M35="","",$M35),IFERROR(IF([2]财务取数接口!$G$34=0,"",[2]财务取数接口!$G$34),"")) | G35: =IF($T$4=0,IF($N35="","",$N35),IFERROR(IF([2]财务取数接口!$H$34=0,"",[2]财务取数接口!$H$34),"")) | H35: =IF($T$4=0,IF($O35="","",$O35),IFERROR(IF([2]财务取数接口!$I$34=0,"",[2]财务取数接口!$I$34),"")) | P35: =IF(AND($C35<>"",$C35<>"项目",OR(N($D35)<>0,N($E35)<>0,N($F35)<>0)),1,0) -> 0 | Q35: =N(Q34)+$P35 -> 0
A36: 35 | B36: =IF($T$4=0,IF($I36="","",$I36),IFERROR(IF([2]财务取数接口!$B$35=0,"",[2]财务取数接口!$B$35),"")) | C36: =IF($T$4=0,IF($J36="","",$J36),IFERROR(IF([2]财务取数接口!$C$35=0,"",[2]财务取数接口!$C$35),"")) -> 物料销售 | D36: =IF($T$4=0,IF($K36="","",$K36),IFERROR(IF([2]财务取数接口!$D$35=0,"",[2]财务取数接口!$D$35),"")) | E36: =IF($T$4=0,IF($L36="","",$L36),IFERROR(IF([2]财务取数接口!$E$35=0,"",[2]财务取数接口!$E$35),"")) -> 包 | F36: =IF($T$4=0,IF($M36="","",$M36),IFERROR(IF([2]财务取数接口!$G$35=0,"",[2]财务取数接口!$G$35),"")) | G36: =IF($T$4=0,IF($N36="","",$N36),IFERROR(IF([2]财务取数接口!$H$35=0,"",[2]财务取数接口!$H$35),"")) | H36: =IF($T$4=0,IF($O36="","",$O36),IFERROR(IF([2]财务取数接口!$I$35=0,"",[2]财务取数接口!$I$35),"")) | P36: =IF(AND($C36<>"",$C36<>"项目",OR(N($D36)<>0,N($E36)<>0,N($F36)<>0)),1,0) -> 0 | Q36: =N(Q35)+$P36 -> 0
