Workbook

Sheet 资金日记账
A1: 出 纳 资 金 日 记 账（泓普 · 仟茂 · 现金 混合录入）
A2: 期初余额 | B2: 泓普 | C2: 3656.12 | D2: 仟茂 | E2: 4754.58 | F2: 现金 | G2: 3981.49 | H2: 三个账户混在一起、按日期顺着往下录。淡黄色格子是你要填的，灰色的自动算。 录完怎么交回财务：选中 B 列到 J 列这一整块 → 复制 → 打开主册《建筑挂靠业务核算系统》的【资金日记账】→ 点到第一行空白行的 B 列 → 右键「选择性粘贴 → 数值」；有工程回款的，再把 M 列同样粘一次。两边列序完全一样，不用对列。
A3: ↓ 淡黄色 = 出纳要填的 | K3: ↓ 灰色 = 自动算的，别手工改
A4: 序号 | B4: 日期 | C4: 资金账户 | D4: 项目编号 | E4: 费用类型 | F4: 往来单位 | G4: 经办人 | H4: 摘要 | I4: 收入 | J4: 支出 | K4: 该账户余额 | L4: 三账户合计 | M4: 工程 回款 | N4: 校验 | O4: 项目简称 | P4: 年月 | Q4: 年度
A5: =IF($B5="","",ROW()-4) | K5: =IF($B5="","",IF($C5="泓普",$C$2,IF($C5="仟茂",$E$2,IF($C5="现金",$G$2,0)))+SUMIFS($I$5:$I5,$C$5:$C5,$C5)-SUMIFS($J$5:$J5,$C$5:$C5,$C5)) | L5: =IF($B5="","",$C$2+$E$2+$G$2+SUM($I$5:$I5)-SUM($J$5:$J5)) | N5: =IF($B5="","",IF(NOT(ISNUMBER($B5)),"日期格式不对",IF($C5="","未选资金账户",IF(AND(N($I5)=0,N($J5)=0),"收支都为空",IF(AND(N($I5)>0,N($J5)>0),"收支不能同时填",IF(AND($D5<>"",LEFT($O5,1)="⚠"),"项目编号不存在",IF(AND($M5="是",$F5=""),"工程回款必须填往来单位","√"))))))) | O5: =IF($D5="","",IFERROR(INDEX(对照清单!$B$5:$B$60,MATCH($D5,对照清单!$A$5:$A$60,0)),"⚠编号不存在")) | P5: =IF($B5="","",IF(ISNUMBER($B5),TEXT($B5,"yyyy-mm"),"日期非法")) | Q5: =IF($B5="","",IF(ISNUMBER($B5),YEAR($B5),"日期非法"))
A6: =IF($B6="","",ROW()-4) | K6: =IF($B6="","",IF($C6="泓普",$C$2,IF($C6="仟茂",$E$2,IF($C6="现金",$G$2,0)))+SUMIFS($I$5:$I6,$C$5:$C6,$C6)-SUMIFS($J$5:$J6,$C$5:$C6,$C6)) | L6: =IF($B6="","",$C$2+$E$2+$G$2+SUM($I$5:$I6)-SUM($J$5:$J6)) | N6: =IF($B6="","",IF(NOT(ISNUMBER($B6)),"日期格式不对",IF($C6="","未选资金账户",IF(AND(N($I6)=0,N($J6)=0),"收支都为空",IF(AND(N($I6)>0,N($J6)>0),"收支不能同时填",IF(AND($D6<>"",LEFT($O6,1)="⚠"),"项目编号不存在",IF(AND($M6="是",$F6=""),"工程回款必须填往来单位","√"))))))) | O6: =IF($D6="","",IFERROR(INDEX(对照清单!$B$5:$B$60,MATCH($D6,对照清单!$A$5:$A$60,0)),"⚠编号不存在")) | P6: =IF($B6="","",IF(ISNUMBER($B6),TEXT($B6,"yyyy-mm"),"日期非法")) | Q6: =IF($B6="","",IF(ISNUMBER($B6),YEAR($B6),"日期非法"))
A7: =IF($B7="","",ROW()-4) | K7: =IF($B7="","",IF($C7="泓普",$C$2,IF($C7="仟茂",$E$2,IF($C7="现金",$G$2,0)))+SUMIFS($I$5:$I7,$C$5:$C7,$C7)-SUMIFS($J$5:$J7,$C$5:$C7,$C7)) | L7: =IF($B7="","",$C$2+$E$2+$G$2+SUM($I$5:$I7)-SUM($J$5:$J7)) | N7: =IF($B7="","",IF(NOT(ISNUMBER($B7)),"日期格式不对",IF($C7="","未选资金账户",IF(AND(N($I7)=0,N($J7)=0),"收支都为空",IF(AND(N($I7)>0,N($J7)>0),"收支不能同时填",IF(AND($D7<>"",LEFT($O7,1)="⚠"),"项目编号不存在",IF(AND($M7="是",$F7=""),"工程回款必须填往来单位","√"))))))) | O7: =IF($D7="","",IFERROR(INDEX(对照清单!$B$5:$B$60,MATCH($D7,对照清单!$A$5:$A$60,0)),"⚠编号不存在")) | P7: =IF($B7="","",IF(ISNUMBER($B7),TEXT($B7,"yyyy-mm"),"日期非法")) | Q7: =IF($B7="","",IF(ISNUMBER($B7),YEAR($B7),"日期非法"))
A8: =IF($B8="","",ROW()-4) | K8: =IF($B8="","",IF($C8="泓普",$C$2,IF($C8="仟茂",$E$2,IF($C8="现金",$G$2,0)))+SUMIFS($I$5:$I8,$C$5:$C8,$C8)-SUMIFS($J$5:$J8,$C$5:$C8,$C8)) | L8: =IF($B8="","",$C$2+$E$2+$G$2+SUM($I$5:$I8)-SUM($J$5:$J8)) | N8: =IF($B8="","",IF(NOT(ISNUMBER($B8)),"日期格式不对",IF($C8="","未选资金账户",IF(AND(N($I8)=0,N($J8)=0),"收支都为空",IF(AND(N($I8)>0,N($J8)>0),"收支不能同时填",IF(AND($D8<>"",LEFT($O8,1)="⚠"),"项目编号不存在",IF(AND($M8="是",$F8=""),"工程回款必须填往来单位","√"))))))) | O8: =IF($D8="","",IFERROR(INDEX(对照清单!$B$5:$B$60,MATCH($D8,对照清单!$A$5:$A$60,0)),"⚠编号不存在")) | P8: =IF($B8="","",IF(ISNUMBER($B8),TEXT($B8,"yyyy-mm"),"日期非法")) | Q8: =IF($B8="","",IF(ISNUMBER($B8),YEAR($B8),"日期非法"))
A9: =IF($B9="","",ROW()-4) | K9: =IF($B9="","",IF($C9="泓普",$C$2,IF($C9="仟茂",$E$2,IF($C9="现金",$G$2,0)))+SUMIFS($I$5:$I9,$C$5:$C9,$C9)-SUMIFS($J$5:$J9,$C$5:$C9,$C9)) | L9: =IF($B9="","",$C$2+$E$2+$G$2+SUM($I$5:$I9)-SUM($J$5:$J9)) | N9: =IF($B9="","",IF(NOT(ISNUMBER($B9)),"日期格式不对",IF($C9="","未选资金账户",IF(AND(N($I9)=0,N($J9)=0),"收支都为空",IF(AND(N($I9)>0,N($J9)>0),"收支不能同时填",IF(AND($D9<>"",LEFT($O9,1)="⚠"),"项目编号不存在",IF(AND($M9="是",$F9=""),"工程回款必须填往来单位","√"))))))) | O9: =IF($D9="","",IFERROR(INDEX(对照清单!$B$5:$B$60,MATCH($D9,对照清单!$A$5:$A$60,0)),"⚠编号不存在")) | P9: =IF($B9="","",IF(ISNUMBER($B9),TEXT($B9,"yyyy-mm"),"日期非法")) | Q9: =IF($B9="","",IF(ISNUMBER($B9),YEAR($B9),"日期非法"))
A10: =IF($B10="","",ROW()-4) | K10: =IF($B10="","",IF($C10="泓普",$C$2,IF($C10="仟茂",$E$2,IF($C10="现金",$G$2,0)))+SUMIFS($I$5:$I10,$C$5:$C10,$C10)-SUMIFS($J$5:$J10,$C$5:$C10,$C10)) | L10: =IF($B10="","",$C$2+$E$2+$G$2+SUM($I$5:$I10)-SUM($J$5:$J10)) | N10: =IF($B10="","",IF(NOT(ISNUMBER($B10)),"日期格式不对",IF($C10="","未选资金账户",IF(AND(N($I10)=0,N($J10)=0),"收支都为空",IF(AND(N($I10)>0,N($J10)>0),"收支不能同时填",IF(AND($D10<>"",LEFT($O10,1)="⚠"),"项目编号不存在",IF(AND($M10="是",$F10=""),"工程回款必须填往来单位","√"))))))) | O10: =IF($D10="","",IFERROR(INDEX(对照清单!$B$5:$B$60,MATCH($D10,对照清单!$A$5:$A$60,0)),"⚠编号不存在")) | P10: =IF($B10="","",IF(ISNUMBER($B10),TEXT($B10,"yyyy-mm"),"日期非法")) | Q10: =IF($B10="","",IF(ISNUMBER($B10),YEAR($B10),"日期非法"))
A11: =IF($B11="","",ROW()-4) | K11: =IF($B11="","",IF($C11="泓普",$C$2,IF($C11="仟茂",$E$2,IF($C11="现金",$G$2,0)))+SUMIFS($I$5:$I11,$C$5:$C11,$C11)-SUMIFS($J$5:$J11,$C$5:$C11,$C11)) | L11: =IF($B11="","",$C$2+$E$2+$G$2+SUM($I$5:$I11)-SUM($J$5:$J11)) | N11: =IF($B11="","",IF(NOT(ISNUMBER($B11)),"日期格式不对",IF($C11="","未选资金账户",IF(AND(N($I11)=0,N($J11)=0),"收支都为空",IF(AND(N($I11)>0,N($J11)>0),"收支不能同时填",IF(AND($D11<>"",LEFT($O11,1)="⚠"),"项目编号不存在",IF(AND($M11="是",$F11=""),"工程回款必须填往来单位","√"))))))) | O11: =IF($D11="","",IFERROR(INDEX(对照清单!$B$5:$B$60,MATCH($D11,对照清单!$A$5:$A$60,0)),"⚠编号不存在")) | P11: =IF($B11="","",IF(ISNUMBER($B11),TEXT($B11,"yyyy-mm"),"日期非法")) | Q11: =IF($B11="","",IF(ISNUMBER($B11),YEAR($B11),"日期非法"))
A12: =IF($B12="","",ROW()-4) | K12: =IF($B12="","",IF($C12="泓普",$C$2,IF($C12="仟茂",$E$2,IF($C12="现金",$G$2,0)))+SUMIFS($I$5:$I12,$C$5:$C12,$C12)-SUMIFS($J$5:$J12,$C$5:$C12,$C12)) | L12: =IF($B12="","",$C$2+$E$2+$G$2+SUM($I$5:$I12)-SUM($J$5:$J12)) | N12: =IF($B12="","",IF(NOT(ISNUMBER($B12)),"日期格式不对",IF($C12="","未选资金账户",IF(AND(N($I12)=0,N($J12)=0),"收支都为空",IF(AND(N($I12)>0,N($J12)>0),"收支不能同时填",IF(AND($D12<>"",LEFT($O12,1)="⚠"),"项目编号不存在",IF(AND($M12="是",$F12=""),"工程回款必须填往来单位","√"))))))) | O12: =IF($D12="","",IFERROR(INDEX(对照清单!$B$5:$B$60,MATCH($D12,对照清单!$A$5:$A$60,0)),"⚠编号不存在")) | P12: =IF($B12="","",IF(ISNUMBER($B12),TEXT($B12,"yyyy-mm"),"日期非法")) | Q12: =IF($B12="","",IF(ISNUMBER($B12),YEAR($B12),"日期非法"))
A13: =IF($B13="","",ROW()-4) | K13: =IF($B13="","",IF($C13="泓普",$C$2,IF($C13="仟茂",$E$2,IF($C13="现金",$G$2,0)))+SUMIFS($I$5:$I13,$C$5:$C13,$C13)-SUMIFS($J$5:$J13,$C$5:$C13,$C13)) | L13: =IF($B13="","",$C$2+$E$2+$G$2+SUM($I$5:$I13)-SUM($J$5:$J13)) | N13: =IF($B13="","",IF(NOT(ISNUMBER($B13)),"日期格式不对",IF($C13="","未选资金账户",IF(AND(N($I13)=0,N($J13)=0),"收支都为空",IF(AND(N($I13)>0,N($J13)>0),"收支不能同时填",IF(AND($D13<>"",LEFT($O13,1)="⚠"),"项目编号不存在",IF(AND($M13="是",$F13=""),"工程回款必须填往来单位","√"))))))) | O13: =IF($D13="","",IFERROR(INDEX(对照清单!$B$5:$B$60,MATCH($D13,对照清单!$A$5:$A$60,0)),"⚠编号不存在")) | P13: =IF($B13="","",IF(ISNUMBER($B13),TEXT($B13,"yyyy-mm"),"日期非法")) | Q13: =IF($B13="","",IF(ISNUMBER($B13),YEAR($B13),"日期非法"))
A14: =IF($B14="","",ROW()-4) | K14: =IF($B14="","",IF($C14="泓普",$C$2,IF($C14="仟茂",$E$2,IF($C14="现金",$G$2,0)))+SUMIFS($I$5:$I14,$C$5:$C14,$C14)-SUMIFS($J$5:$J14,$C$5:$C14,$C14)) | L14: =IF($B14="","",$C$2+$E$2+$G$2+SUM($I$5:$I14)-SUM($J$5:$J14)) | N14: =IF($B14="","",IF(NOT(ISNUMBER($B14)),"日期格式不对",IF($C14="","未选资金账户",IF(AND(N($I14)=0,N($J14)=0),"收支都为空",IF(AND(N($I14)>0,N($J14)>0),"收支不能同时填",IF(AND($D14<>"",LEFT($O14,1)="⚠"),"项目编号不存在",IF(AND($M14="是",$F14=""),"工程回款必须填往来单位","√"))))))) | O14: =IF($D14="","",IFERROR(INDEX(对照清单!$B$5:$B$60,MATCH($D14,对照清单!$A$5:$A$60,0)),"⚠编号不存在")) | P14: =IF($B14="","",IF(ISNUMBER($B14),TEXT($B14,"yyyy-mm"),"日期非法")) | Q14: =IF($B14="","",IF(ISNUMBER($B14),YEAR($B14),"日期非法"))
A15: =IF($B15="","",ROW()-4) | K15: =IF($B15="","",IF($C15="泓普",$C$2,IF($C15="仟茂",$E$2,IF($C15="现金",$G$2,0)))+SUMIFS($I$5:$I15,$C$5:$C15,$C15)-SUMIFS($J$5:$J15,$C$5:$C15,$C15)) | L15: =IF($B15="","",$C$2+$E$2+$G$2+SUM($I$5:$I15)-SUM($J$5:$J15)) | N15: =IF($B15="","",IF(NOT(ISNUMBER($B15)),"日期格式不对",IF($C15="","未选资金账户",IF(AND(N($I15)=0,N($J15)=0),"收支都为空",IF(AND(N($I15)>0,N($J15)>0),"收支不能同时填",IF(AND($D15<>"",LEFT($O15,1)="⚠"),"项目编号不存在",IF(AND($M15="是",$F15=""),"工程回款必须填往来单位","√"))))))) | O15: =IF($D15="","",IFERROR(INDEX(对照清单!$B$5:$B$60,MATCH($D15,对照清单!$A$5:$A$60,0)),"⚠编号不存在")) | P15: =IF($B15="","",IF(ISNUMBER($B15),TEXT($B15,"yyyy-mm"),"日期非法")) | Q15: =IF($B15="","",IF(ISNUMBER($B15),YEAR($B15),"日期非法"))
A16: =IF($B16="","",ROW()-4) | K16: =IF($B16="","",IF($C16="泓普",$C$2,IF($C16="仟茂",$E$2,IF($C16="现金",$G$2,0)))+SUMIFS($I$5:$I16,$C$5:$C16,$C16)-SUMIFS($J$5:$J16,$C$5:$C16,$C16)) | L16: =IF($B16="","",$C$2+$E$2+$G$2+SUM($I$5:$I16)-SUM($J$5:$J16)) | N16: =IF($B16="","",IF(NOT(ISNUMBER($B16)),"日期格式不对",IF($C16="","未选资金账户",IF(AND(N($I16)=0,N($J16)=0),"收支都为空",IF(AND(N($I16)>0,N($J16)>0),"收支不能同时填",IF(AND($D16<>"",LEFT($O16,1)="⚠"),"项目编号不存在",IF(AND($M16="是",$F16=""),"工程回款必须填往来单位","√"))))))) | O16: =IF($D16="","",IFERROR(INDEX(对照清单!$B$5:$B$60,MATCH($D16,对照清单!$A$5:$A$60,0)),"⚠编号不存在")) | P16: =IF($B16="","",IF(ISNUMBER($B16),TEXT($B16,"yyyy-mm"),"日期非法")) | Q16: =IF($B16="","",IF(ISNUMBER($B16),YEAR($B16),"日期非法"))
... A804: =IF($B804="","",ROW()-4) | K804: =IF($B804="","",IF($C804="泓普",$C$2,IF($C804="仟茂",$E$2,IF($C804="现金",$G$2,0)))+SUMIFS($I$5:$I804,$C$5:$C804,$C804)-SUMIFS($J$5:$J804,$C$5:$C804,$C804)) | L804: =IF($B804="","",$C$2+$E$2+$G$2+SUM($I$5:$I804)-SUM($J$5:$J804)) | N804: =IF($B804="","",IF(NOT(ISNUMBER($B804)),"日期格式不对",IF($C804="","未选资金账户",IF(AND(N($I804)=0,N($J804)=0),"收支都为空",IF(AND(N($I804)>0,N($J804)>0),"收支不能同时填",IF(AND($D804<>"",LEFT($O804,1)="⚠"),"项目编号不存在",IF(AND($M804="是",$F804=""),"工程回款必须填往来单位","√"))))))) | O804: =IF($D804="","",IFERROR(INDEX(对照清单!$B$5:$B$60,MATCH($D804,对照清单!$A$5:$A$60,0)),"⚠编号不存在")) | P804: =IF($B804="","",IF(ISNUMBER($B804),TEXT($B804,"yyyy-mm"),"日期非法")) | Q804: =IF($B804="","",IF(ISNUMBER($B804),YEAR($B804),"日期非法"))
A806: 交回财务的步骤：① 选中 B5:J804 整块 → 复制；② 打开主册《建筑挂靠业务核算系统》的【资金日记账】，点到第一行空白行的 B 列 → 右键「选择性粘贴 → 数值」；③ 有工程回款的，再把 M5:M804 同样粘到主册 M 列对应位置；④ 粘完在主册上看一眼「校验」列全是 √ 就完事。⑤ 本册不参与主册的任何汇总，主册只认它自己那张【资金日记账】，所以不会重复算。

Sheet 对照清单
A1: 对 照 清 单（从主册抄过来的死值，出纳不用改）
A2: ★ 这张表只是给左边【资金日记账】的下拉用的。主册那边加了新项目或新单位，让财务重新发一本给你，或者直接在这里照着补一行。
A4: 项目编号 | B4: 项目简称 | C4: 项目全称 | D4: 往来单位 | E4: 费用类型 | F4: 资金账户
A5: A001 | B5: 平双线(德誉嘉) | C5: 重庆铜梁10kV平双线新建联络工程 | D5: 民能 | E5: 工程回款 | F5: 泓普
A6: A002 | B6: 水羊线金鸡3（4）社 | C6: 重庆铜梁10kV水羊线金鸡3(4)社台区重过载治理工程 | D6: 铜梁供电 | E6: 货款 | F6: 仟茂
A7: A003 | B7: 龙羊线七佛4社 | C7: 重庆铜梁10kV龙羊线七佛4社台区重过载治理工程 | D7: 德誉嘉 | E7: 借款 | F7: 现金
A8: A004 | B8: 少柏线池塘4社 | C8: 重庆铜梁10kV少柏线池塘4社柱台区电压越限治理工程 | D8: 迅驰 | E8: 还借款
A9: A005 | B9: 少柏线团山7.6.11社 | C9: 重庆铜梁10kV少柏线团山7.6.11社台区电压越限治理工程 | D9: 华城 | E9: 工资
A10: A006 | B10: 平凉线惠丰9社 | C10: 重庆铜梁10kV平凉线惠丰9社等4个台区重过载治理工程 | D10: 金沁 | E10: 社保
A11: A007 | B11: 平滩所何银强(德誉嘉) | C11: 重庆德誉佳实业有限公司2025-2026年度工程用特种设备租赁服务框架采购-铜梁公司2025年成本类优化营商环境项目(平滩所何银强等5个低压业扩工程) | D11: 湖南锦泰 | E11: 材料费
A12: A008 | B12: 金湖东西线(德誉嘉) | C12: 重庆德誉佳实业有限公司2025-2026年度工程用施工机具等租赁服务框架采购(国网重庆铜梁公司110kV金湖东西电缆改造) | D12: 康欣 | E12: 运费
A13: A009 | B13: 侣新线铜安1社(德誉嘉) | C13: 重庆铜梁10kV梧桐村4.5.6社台区重过载治理工程等23个项目(2025年配网6批、业扩5批德誉佳施工)(重庆铜梁10kV侣新线铜安1社台区重过载治理工程) | D13: 安锐 | E13: 餐费
A14: A010 | B14: 侣新线铜安9社(德誉嘉) | C14: 重庆铜梁10kV梧桐村4.5.6社台区重过载治理工程等23个项目(2025年配网6批、业扩5批德誉佳施工)(重庆铜梁10kV侣新线铜安9社台区重过载治理工程) | D14: 杰华 | E14: 耗材费
A15: A011 | B15: 平双线群益7社(德誉嘉) | C15: 重庆铜梁10kV梧桐村4.5.6社台区重过载治理工程等23个项目(2025年配网6批、业扩5批德誉佳施工)(重庆铜梁10kV平双线群益7社台区重过载治理工程) | D15: 泓普 | E15: 办公费用
A16: A012 | B16: 平镇线新桥社(德誉嘉) | C16: 重庆铜梁10kV梧桐村4.5.6社台区重过载治理工程等23个项目(2025年配网6批、业扩5批德誉佳施工)(重庆铜梁10kV平镇线新桥社台区重过载治理工程) | D16: 仟茂 | E16: 维修费
A17: A013 | B17: 侣新线凤飞7社(德誉嘉) | C17: 重庆铜梁10kV梧桐村4.5.6社台区重过载治理工程等23个项目(2025年配网6批、业扩5批德誉佳施工)(重庆铜梁10kV侣新线凤飞7社台区重过载治理工程) | D17: 税局 | E17: 青苗费
A18: A014 | B18: 黄荆4社 | C18: 铜梁公司2026年配电专业应急抢修抢险等外包项目(黄荆4社等台区4个隐患治理项目、三湾1.2社等台区2个应急抢修项目) | D18: 管理费率 / 返现率已取消：请到【业务流水】的「管理费率」「返现率」两列逐笔填（淡黄色格子）。历史 3xx 行已按你那份《对账明细》逐笔写死，一分没动。 这里的税率参数只驱动【业务流水】最右边那一列「税费参考试算」，供录入时对照，不参与任何汇总：税差法＝上游销项税−我方成本票进项税；全额销项法＝开票额÷(1+上游税率)×上游税率；预征率法＝开票额÷(1+上游税率)×预征率。真正入账的税费在【业务流水】O~R 四列按实际逐笔录。 | E18: 饮用水费用
A19: A015 | B19: 永嘉所许家3社(德誉嘉) | C19: 重庆民能实业有限公司2025-2026年度工程用特种设备租赁服务框架采购(铜梁公司2026年配电专业应急抢修抢险等外包项目(永嘉所许家3社1等台区2个隐患治理项目)) | E19: 转备用金
A20: A016 | B20: 永嘉所高丰3社(德誉嘉) | C20: 重庆民能实业有限公司2025-2026年度工程用特种设备租赁服务框架采购(铜梁公司2026年配电专业应急抢修抢险等外包项目(永嘉所高丰3社等台区4个应急抢修项目)) | E20: 手续费
A21: A017 | B21: 永嘉所义和8社(德誉嘉) | C21: 重庆民能实业有限公司2025-2026年度工程用特种设备租赁服务框架采购(铜梁公司2026年配电专业应急抢修抢险等外包项目(永嘉所义和8社等台区3个对地不足隐患治理项目)) | E21: 燃油费
A22: A018 | B22: 输电运检中心线路接地隐患消除(德誉嘉) | C22: 重庆民能实业有限公司2025-2026年度工程用特种设备租赁服务框架采购(铜梁公司2026年35kV输电专业应急抢修检修外包项目(输电运检中心2026年35kV线路接地隐患消除等3个项目)) | E22: 税费
A23: A019 | B23: 少盘线哨楼村支线(德誉嘉) | C23: 重庆民能实业有限公司2025-2026年度工程用特种设备租赁服务框架采购(10kV少盘线哨楼村支线#1杆线路迁改工程) | E23: 管理费
A24: A020 | B24: 大太线 | C24: 2025-2026年度工程用施工机具等租赁服务(重庆铜梁10kV大太线老旧线路改造工程) | E24: 租赁费
A25: A021 | B25: 平滩农光互补项目 | C25: 重庆民能实业有限公司2025-2026年度工程用特种设备租赁服务框架采购(华润电力重庆能源铜梁平滩农光互补项目220kV升压站PC工程) | E25: 考核款
A26: A022 | B26: 充电桩新装用电工程 | C26: 重庆民能实业有限公司2025-2026年度工程用特种设备租赁服务框架采购(重庆稷博汇物流有限公司10kV充电桩新装用电工程) | E26: 账户年费
A27: A023 | B27: 永嘉所10kV西新线(德誉嘉) | C27: 重庆民能实业有限公司2025-2026年度工程用特种设备租赁服务框架采购(铜梁公司2026年配电专业应急抢修抢险等外包项目(永嘉所10kV西新线等2条线路综合检修项目)) | E27: 其他应收收回
A28: A024 | B28: 少柏线社田1.6.7社 | C28: 重庆铜梁10kV少柏线社田1.6.7社台区重过载治理工程(机械费) | E28: 其他应付支付
A29: A025 | B29: 大科新建联络工程 | C29: 重庆铜梁10kV大科新建联络工程(机械费) | E29: 其他
A30: A026 | B30: 大岭线新建联络工程 | C30: 重庆铜梁10kV大岭线新建联络工程(机械费)
A31: A027 | B31: 物华天宝镀膜科技 | C31: 重庆铜梁重庆物华天宝镀膜科技有限公司10kV业扩配套工程(机械费)
A32: A028 | B32: 虎泉线 | C32: 虎泉线
A33: A029 | B33: 安居所张绍华 | C33: 重庆民能实业有限公司2025-2026年度工程用特种设备租赁服务框架采购(铜梁公司2025年成本类优化营商环境项目(安居所张绍华等10个低压业扩项目)(机械费)
A34: A030 | B34: 围塘5社 | C34: 重庆民能实业有限公司2025-2026年度工程用特种设备租赁服务框架采购、铜梁公司2026年配电专业应急抢修抢险等外包项目(围塘5社等台区3个隐患治理项目。大桥7.8社等台区3个应急抢修项目)机械费
A35: A031 | B35: 峰盛模具箱变拆除 | C35: 2025-2026年度工程用特种设备租赁服务框架采购、峰盛模具ZBW-250KVA箱变拆除工程(机械费)
A36: A032 | B36: 金湖东西线(迅驰) | C36: 重庆民能实业有限公司2025-2026年度工程用施工机具等租赁服务框架采购(国网重庆铜梁公司110kV金湖东西电缆改造)
A37: A033 | B37: 少盘线哨楼村支线(迅驰) | C37: 2025-2026年度工程用特种设备租赁服务框架采购(10kV少盘线哨楼村支线#1杆线路迁改工程)
A38: A034 | B38: 平双线(华城) | C38: 重庆铜梁11kV平双线新建联络工程
A39: A035 | B39: 永嘉所许家3社(华城) | C39: 铜梁公司2026年配电专业应急抢修抢险等外包项目(永嘉所许家3社1等台区2个隐患治理项目)
A40: A036 | B40: 永嘉所义和8社(华城) | C40: 铜梁公司2026年配电专业应急抢修抢险等外包项目(永嘉所义和8社等台区3个对地不足隐患治理项目)
A41: A037 | B41: 永嘉所高丰3社(华城) | C41: 铜梁公司2026年配电专业应急抢修抢险等外包项目(永嘉所高丰3社等台区4个应急抢修项目)
...
