Workbook

Sheet 使用说明
A1: 更多财务实操模板，可自行搜索抖音/视频号：老财务的实操笔记
A3: 【老财务实操自用｜初级版财务台账模板】
A4: 作者：老财务的实操笔记
A5: ——————————————————————————
A6: 适用对象：小微企业、个体工商户、小规模纳税人、商贸服务类等
A7: 版本说明
A8: 本套为**通用基础初级版**，满足税务管理、费用报销、收支登记、票据管理等
A9: 可根据行业属性、业务规模、升级定制版。
A11: 模板清单，持续更新
A12: 1、应收账款风险预警表
A13: 2、日常经营情况汇总表
A14: 3、进项台帐自动查重表
... A47: 老财务自用模板｜禁止外传、倒卖、商用

Sheet 基础资料
A1: 账户 | B1: 产品 | C1: 支出类别 | E1: 客户 | G1: 供应商
A2: 现金 | B2: 红曲 | C2: 供应商 | E2: 丁爱妹 | G2: 羊奶供货商
A3: 微信 | B3: 胚脑 | E3: 方建宏 | G3: 乳铁供货商
A4: 支付宝 | B4: 胚优 | C4: 办公费 | E4: 傅荣姣
A5: 杭州 | B5: 乳铁 | C5: 水费 | E5: 郭志伟
A6: 农商 | B6: 羊奶 | C6: 电费 | E6: 过承祁
A7: 备用 | B7: 益生菌 | C7: 伙食费 | E7: 洪宗邦
A8: 备用1 | C8: 工资 | E8: 姜蓉兰
A9: 备用2 | C9: 租赁费 | E9: 姜志鸿
A10: 备用3 | C10: 差旅费 | E10: 李小琴
A11: 备用4 | C11: 业务招待费 | E11: 李晓春
A12: 备用5 | C12: 车辆费用 | E12: 李玉娟
A13: 备用6 | C13: 银行手续费 | E13: 林永来
A14: 备用7 | E14: 陆玉英
A15: 备用8 | E15: 罗理华
E16: 马珍珠
E17: 邵国新
E18: 沈祖模
E19: 唐鑫红
E20: 童炳寿
E21: 王秀娟
E22: 邬香花
E23: 吴亮
E24: 吴旭红
E25: 吴兆香
E26: 谢爱琴
E27: 徐德彪
... E38: 杨建云

Sheet 数据录入
A1: 多帐户收支登记表
F2: 收入总额 | G2: 支出总额 | H2: 账户余额
F3: =SUBTOTAL(109,$F$4:$F$9999) | G3: =SUBTOTAL(109,$G$4:$G$9999) | H3: =SUBTOTAL(109,$H$5:$H$18)+F3-G3
A4: 序号 | B4: 日期 | C4: 公司账户 | D4: 支出类别 | E4: 摘要内容 | F4: 收入 | G4: 支出 | H4: 账户余额 | I4: 产品 | J4: 客户 | K4: 供应商 | L4: 客户生日 | M4: 月份
A5: =IF(B5="","",COUNTA($B$5:B5)) | B5: 46266 | C5: 现金 | E5: 期初余额 | H5: 0 | M5: =IF($B5="","",--TEXT($B5,"yyyymm"))
A6: =IF(B6="","",COUNTA($B$5:B6)) | B6: 46266 | C6: 微信 | E6: 期初余额 | H6: 0 | M6: =IF($B6="","",--TEXT($B6,"yyyymm"))
A7: =IF(B7="","",COUNTA($B$5:B7)) | B7: 46266 | C7: 支付宝 | E7: 期初余额 | H7: 0 | M7: =IF($B7="","",--TEXT($B7,"yyyymm"))
A8: =IF(B8="","",COUNTA($B$5:B8)) | B8: 46266 | C8: 杭州 | E8: 期初余额 | H8: 0 | M8: =IF($B8="","",--TEXT($B8,"yyyymm"))
A9: =IF(B9="","",COUNTA($B$5:B9)) | B9: 46266 | C9: 农商 | E9: 期初余额 | H9: 0 | M9: =IF($B9="","",--TEXT($B9,"yyyymm"))
A10: =IF(B10="","",COUNTA($B$5:B10)) | B10: 46266 | C10: 备用 | E10: 期初余额 | H10: 0 | M10: =IF($B10="","",--TEXT($B10,"yyyymm"))
A11: =IF(B11="","",COUNTA($B$5:B11)) | B11: 46266 | C11: 备用1 | E11: 期初余额 | H11: 0 | M11: =IF($B11="","",--TEXT($B11,"yyyymm"))
A12: =IF(B12="","",COUNTA($B$5:B12)) | B12: 46266 | C12: 备用2 | E12: 期初余额 | H12: 0 | M12: =IF($B12="","",--TEXT($B12,"yyyymm"))
A13: =IF(B13="","",COUNTA($B$5:B13)) | B13: 46266 | C13: 备用3 | E13: 期初余额 | H13: 0 | M13: =IF($B13="","",--TEXT($B13,"yyyymm"))
A14: =IF(B14="","",COUNTA($B$5:B14)) | B14: 46266 | C14: 备用4 | E14: 期初余额 | H14: 0 | M14: =IF($B14="","",--TEXT($B14,"yyyymm"))
A15: =IF(B15="","",COUNTA($B$5:B15)) | B15: 46266 | C15: 备用5 | E15: 期初余额 | H15: 0 | M15: =IF($B15="","",--TEXT($B15,"yyyymm"))
A16: =IF(B16="","",COUNTA($B$5:B16)) | B16: 46266 | C16: 备用6 | E16: 期初余额 | H16: 0 | M16: =IF($B16="","",--TEXT($B16,"yyyymm"))
... A18: =IF(B18="","",COUNTA($B$5:B18)) | B18: 46266 | C18: 备用8 | E18: 期初余额 | H18: 0 | M18: =IF($B18="","",--TEXT($B18,"yyyymm"))
A19: =IF(B19="","",COUNTA($B$5:B19)) | B19: 46266 | C19: 现金 | F19: 2000 | H19: =IFERROR(VLOOKUP($C19,$C$5:$H$18,6,0)+SUMIF($C$19:$C19,$C19,$F$19:$F19)-SUMIF($C$19:$C19,$C19,$G$19:$G19),"") | I19: 红曲 | J19: 丁爱妹 | M19: =IF($B19="","",--TEXT($B19,"yyyymm"))
A20: =IF(B20="","",COUNTA($B$5:B20)) | B20: 46266 | C20: 微信 | D20: 办公费 | G20: 200 | H20: =IFERROR(VLOOKUP($C20,$C$5:$H$18,6,0)+SUMIF($C$19:$C20,$C20,$F$19:$F20)-SUMIF($C$19:$C20,$C20,$G$19:$G20),"") | M20: =IF($B20="","",--TEXT($B20,"yyyymm"))
A21: =IF(B21="","",COUNTA($B$5:B21)) | B21: 46266 | C21: 支付宝 | D21: 电费 | G21: 300 | H21: =IFERROR(VLOOKUP($C21,$C$5:$H$18,6,0)+SUMIF($C$19:$C21,$C21,$F$19:$F21)-SUMIF($C$19:$C21,$C21,$G$19:$G21),"") | M21: =IF($B21="","",--TEXT($B21,"yyyymm"))
A22: =IF(B22="","",COUNTA($B$5:B22)) | B22: 46266 | C22: 杭州 | D22: 差旅费 | G22: 500 | H22: =IFERROR(VLOOKUP($C22,$C$5:$H$18,6,0)+SUMIF($C$19:$C22,$C22,$F$19:$F22)-SUMIF($C$19:$C22,$C22,$G$19:$G22),"") | M22: =IF($B22="","",--TEXT($B22,"yyyymm"))
A23: =IF(B23="","",COUNTA($B$5:B23)) | B23: 46266 | C23: 农商 | F23: 2600 | H23: =IFERROR(VLOOKUP($C23,$C$5:$H$18,6,0)+SUMIF($C$19:$C23,$C23,$F$19:$F23)-SUMIF($C$19:$C23,$C23,$G$19:$G23),"") | M23: =IF($B23="","",--TEXT($B23,"yyyymm"))
A24: =IF(B24="","",COUNTA($B$5:B24)) | B24: 46266 | C24: 备用 | D24: 供应商 | G24: 5000 | H24: =IFERROR(VLOOKUP($C24,$C$5:$H$18,6,0)+SUMIF($C$19:$C24,$C24,$F$19:$F24)-SUMIF($C$19:$C24,$C24,$G$19:$G24),"") | K24: 羊奶供货商 | M24: =IF($B24="","",--TEXT($B24,"yyyymm"))
A25: =IF(B25="","",COUNTA($B$5:B25)) | B25: 46266 | C25: 备用1 | D25: 伙食费 | G25: 200 | H25: =IFERROR(VLOOKUP($C25,$C$5:$H$18,6,0)+SUMIF($C$19:$C25,$C25,$F$19:$F25)-SUMIF($C$19:$C25,$C25,$G$19:$G25),"") | M25: =IF($B25="","",--TEXT($B25,"yyyymm"))
A26: =IF(B26="","",COUNTA($B$5:B26)) | B26: 46266 | C26: 备用2 | D26: 办公费 | G26: 10 | H26: =IFERROR(VLOOKUP($C26,$C$5:$H$18,6,0)+SUMIF($C$19:$C26,$C26,$F$19:$F26)-SUMIF($C$19:$C26,$C26,$G$19:$G26),"") | M26: =IF($B26="","",--TEXT($B26,"yyyymm"))
A27: =IF(B27="","",COUNTA($B$5:B27)) | B27: 46266 | C27: 备用3 | D27: 车辆费用 | G27: 50 | H27: =IFERROR(VLOOKUP($C27,$C$5:$H$18,6,0)+SUMIF($C$19:$C27,$C27,$F$19:$F27)-SUMIF($C$19:$C27,$C27,$G$19:$G27),"") | M27: =IF($B27="","",--TEXT($B27,"yyyymm"))
A28: =IF(B28="","",COUNTA($B$5:B28)) | B28: 46266 | C28: 备用4 | F28: 2100 | H28: =IFERROR(VLOOKUP($C28,$C$5:$H$18,6,0)+SUMIF($C$19:$C28,$C28,$F$19:$F28)-SUMIF($C$19:$C28,$C28,$G$19:$G28),"") | M28: =IF($B28="","",--TEXT($B28,"yyyymm"))
A29: =IF(B29="","",COUNTA($B$5:B29)) | B29: 46266 | C29: 备用5 | D29: 租赁费 | G29: 2000 | H29: =IFERROR(VLOOKUP($C29,$C$5:$H$18,6,0)+SUMIF($C$19:$C29,$C29,$F$19:$F29)-SUMIF($C$19:$C29,$C29,$G$19:$G29),"") | M29: =IF($B29="","",--TEXT($B29,"yyyymm"))
A30: =IF(B30="","",COUNTA($B$5:B30)) | B30: 46266 | C30: 备用6 | D30: 伙食费 | G30: 200 | H30: =IFERROR(VLOOKUP($C30,$C$5:$H$18,6,0)+SUMIF($C$19:$C30,$C30,$F$19:$F30)-SUMIF($C$19:$C30,$C30,$G$19:$G30),"") | M30: =IF($B30="","",--TEXT($B30,"yyyymm"))
A31: =IF(B31="","",COUNTA($B$5:B31)) | B31: 46266 | C31: 备用7 | D31: 差旅费 | G31: 500 | H31: =IFERROR(VLOOKUP($C31,$C$5:$H$18,6,0)+SUMIF($C$19:$C31,$C31,$F$19:$F31)-SUMIF($C$19:$C31,$C31,$G$19:$G31),"") | M31: =IF($B31="","",--TEXT($B31,"yyyymm"))
A32: =IF(B32="","",COUNTA($B$5:B32)) | B32: 46266 | C32: 备用8 | D32: 供应商 | G32: 1000 | H32: =IFERROR(VLOOKUP($C32,$C$5:$H$18,6,0)+SUMIF($C$19:$C32,$C32,$F$19:$F32)-SUMIF($C$19:$C32,$C32,$G$19:$G32),"") | M32: =IF($B32="","",--TEXT($B32,"yyyymm"))
A33: =IF(B33="","",COUNTA($B$5:B33)) | B33: 46266 | C33: 现金 | D33: 业务招待费 | G33: 200 | H33: =IFERROR(VLOOKUP($C33,$C$5:$H$18,6,0)+SUMIF($C$19:$C33,$C33,$F$19:$F33)-SUMIF($C$19:$C33,$C33,$G$19:$G33),"") | M33: =IF($B33="","",--TEXT($B33,"yyyymm"))
A34: =IF(B34="","",COUNTA($B$5:B34)) | B34: 46266 | C34: 微信 | D34: 车辆费用 | G34: 500 | H34: =IFERROR(VLOOKUP($C34,$C$5:$H$18,6,0)+SUMIF($C$19:$C34,$C34,$F$19:$F34)-SUMIF($C$19:$C34,$C34,$G$19:$G34),"") | M34: =IF($B34="","",--TEXT($B34,"yyyymm"))
A35: =IF(B35="","",COUNTA($B$5:B35)) | B35: 46266 | C35: 支付宝 | D35: 伙食费 | G35: 500 | H35: =IFERROR(VLOOKUP($C35,$C$5:$H$18,6,0)+SUMIF($C$19:$C35,$C35,$F$19:$F35)-SUMIF($C$19:$C35,$C35,$G$19:$G35),"") | M35: =IF($B35="","",--TEXT($B35,"yyyymm"))
A36: =IF(B36="","",COUNTA($B$5:B36)) | B36: 46266 | C36: 杭州 | F36: 5000 | H36: =IFERROR(VLOOKUP($C36,$C$5:$H$18,6,0)+SUMIF($C$19:$C36,$C36,$F$19:$F36)-SUMIF($C$19:$C36,$C36,$G$19:$G36),"") | M36: =IF($B36="","",--TEXT($B36,"yyyymm"))
A37: =IF(B37="","",COUNTA($B$5:B37)) | B37: 46266 | C37: 农商 | F37: 500 | H37: =IFERROR(VLOOKUP($C37,$C$5:$H$18,6,0)+SUMIF($C$19:$C37,$C37,$F$19:$F37)-SUMIF($C$19:$C37,$C37,$G$19:$G37),"") | M37: =IF($B37="","",--TEXT($B37,"yyyymm"))
A38: =IF(B38="","",COUNTA($B$5:B38)) | B38: 46266 | C38: 备用 | D38: 电费 | G38: 500 | H38: =IFERROR(VLOOKUP($C38,$C$5:$H$18,6,0)+SUMIF($C$19:$C38,$C38,$F$19:$F38)-SUMIF($C$19:$C38,$C38,$G$19:$G38),"") | M38: =IF($B38="","",--TEXT($B38,"yyyymm"))
A39: =IF(B39="","",COUNTA($B$5:B39)) | B39: 46266 | C39: 备用1 | F39: 10000 | H39: =IFERROR(VLOOKUP($C39,$C$5:$H$18,6,0)+SUMIF($C$19:$C39,$C39,$F$19:$F39)-SUMIF($C$19:$C39,$C39,$G$19:$G39),"") | M39: =IF($B39="","",--TEXT($B39,"yyyymm"))
A40: =IF(B40="","",COUNTA($B$5:B40)) | B40: 46266 | C40: 备用2 | E40: 工行转民生 | F40: 1000 | H40: =IFERROR(VLOOKUP($C40,$C$5:$H$18,6,0)+SUMIF($C$19:$C40,$C40,$F$19:$F40)-SUMIF($C$19:$C40,$C40,$G$19:$G40),"") | M40: =IF($B40="","",--TEXT($B40,"yyyymm"))
A41: =IF(B41="","",COUNTA($B$5:B41)) | B41: 46266 | C41: 备用3 | E41: 工行转民生 | F41: -1000 | H41: =IFERROR(VLOOKUP($C41,$C$5:$H$18,6,0)+SUMIF($C$19:$C41,$C41,$F$19:$F41)-SUMIF($C$19:$C41,$C41,$G$19:$G41),"") | M41: =IF($B41="","",--TEXT($B41,"yyyymm"))
...

Sheet 往来款跟进
A2: 填写说明：淡黄色格子是你要填的 —— 日期、客户名称、销售产品、销售金额、销售费用(赠送券)、支付方式、备注，以及右边应付侧的供货商、购货款。 淡灰色格子全部自动算，不要手动改：已收款、尚欠款、未收总计、已付款、尚欠款总计。 「已收款」「已付款」自动从【数据录入】取：在数据录入里按日记流水记账时，把「客户」或「供应商」那一列选上，这里就自动认领。 数据录入里还没记到某个客户的回款之前，这里沿用你原来手工填的数（存在隐藏的 T 列），最右边「核对」列会提示是哪一种。 | L2: 总销售金额 | M2: =ROUND(SUM($F$11:$F$510),2) | N2: 应收账款 | O2: 应收款项 | P2: =ROUND(SUM($F$11:$F$510)-SUM($J$11:$J$510),2) | Q2: 应付账款 | R2: 购货款 | S2: =ROUND(SUM($O$11:$O$510),2)
L3: 购货款 | M3: =ROUND(SUM($O$11:$O$510),2) | O3: 已收款 | P3: =ROUND(SUM($G$11:$G$510),2) | R3: 已付款 | S3: =ROUND(SUM($P$11:$P$510),2)
L4: 销售费用 | M4: =ROUND(SUM($J$11:$J$510),2) | O4: 尚欠款 | P4: =ROUND($P$2-$P$3,2) | R4: 尚欠款 | S4: =ROUND($S$2-$S$3,2)
L5: 毛 利 | M5: =ROUND($M$2-$M$3-$M$4,2) | R5: 应收-应付 | S5: =ROUND($P$4-$S$4,2)
A8: 单位名称：百跃羊奶 | S8: 单位：元
A9: 序号 | B9: 日期 | C9: 客户生日 | D9: 应收账款 | M9: 应付账款 | T9: 已收款 (原手工记录) | U9: 本行应收 | V9: 同客户累计应收 | W9: 该客户回款·数据录入 | X9: 已付款 (原手工记录) | Y9: 同供货商累计购货 | Z9: 该供货商付款·数据录入 | AA9: 核 对
D10: 客户名称 | E10: 销售产品 | F10: 销售金额 | G10: 已收款 | H10: 尚欠款 | I10: 未收总计 | J10: 销售费用 | K10: 支付方式 | L10: 备注 | M10: 日期 | N10: 供货商 | O10: 购货款 | P10: 已付款 | Q10: 尚欠款 | R10: 尚欠款总计 | S10: 备注 | T10: 你原来手工填在「已收款」里的数。 数据录入里还没记这个客户的回款时，左边就用这个数顶着。 | U10: 销售金额 − 销售费用 | V10: 这个客户到本行为止一共该收多少 | W10: 从【数据录入】按客户名汇总的收入 | X10: 同上，应付侧的手工备份 | Y10: 同供货商累计购货 | Z10: 从【数据录入】按供货商汇总的支出 | AA10: 这一行有没有填错、名字对不对得上
A11: =IF(AND($D11="",$N11=""),"",MAX($A$10:A10)+1) | B11: 46269 | C11: 46113 | D11: 沈祖模 | E11: 羊奶 | F11: 3280 | G11: =IF($D11="","",IF(COUNTIF(数据录入!$J$5:$J$4999,$D11)=0,N($T11),ROUND(MIN(MAX(0,N($W11)-(N($V11)-N($U11))),N($U11)),2))) | H11: =IF($D11="","",ROUND(N($F11)-N($G11)-N($J11),2)) | I11: =IF($D11="","",ROUND(SUM($H$11:H11),2)) | J11: 0 | K11: 支付宝 | L11: 货款 | M11: 43971 | N11: 羊奶供货商 | P11: =IF($N11="","",IF(COUNTIF(数据录入!$K$5:$K$4999,$N11)=0,N($X11),ROUND(MIN(MAX(0,N($Z11)-(N($Y11)-N($O11))),N($O11)),2))) | Q11: =IF($N11="","",ROUND(N($O11)-N($P11),2)) | R11: =IF($N11="","",ROUND(SUM($Q$11:Q11),2)) | S11: 采购 | T11: 3280 | U11: =IF($D11="","",ROUND(N($F11)-N($J11),2)) | V11: =IF($D11="","",ROUND(SUMIFS($F$11:F11,$D$11:D11,$D11)-SUMIFS($J$11:J11,$D$11:D11,$D11),2)) | W11: =IF($D11="","",ROUND(SUMIFS(数据录入!$F$5:$F$4999,数据录入!$J$5:$J$4999,$D11),2)) | Y11: =IF($N11="","",ROUND(SUMIFS($O$11:O11,$N$11:N11,$N11),2)) | Z11: =IF($N11="","",ROUND(SUMIFS(数据录入!$G$5:$G$4999,数据录入!$K$5:$K$4999,$N11),2)) | AA11: =IF(AND($D11="",$N11=""),"",IF(AND($D11<>"",COUNTIF(基础资料!$E:$E,$D11)=0),"客户名不在基础资料里",IF(AND($E11<>"",COUNTIF(基础资料!$B:$B,$E11)=0),"产品名不在基础资料里",IF(AND($N11<>"",COUNTIF(基础资料!$G:$G,$N11)=0),"供货商不在基础资料里",IF(AND($C11<>"",ISNUMBER($C11),$C11<10000),"客户生日填得不对（不是日期）",IF(N($J11)>N($F11),"销售费用大于销售金额",IF(AND($D11<>"",COUNTIF(数据录入!$J$5:$J$4999,$D11)=0,N($T11)<>0),"用的还是原手工已收款",IF(AND($D11<>"",COUNTIF(数据录入!$J$5:$J$4999,$D11)>0,ROUND(N($G11)-N($T11),2)<>0,N($T11)<>0),"自动算的已收款和原手工数对不上","√"))))))))
A12: =IF(AND($D12="",$N12=""),"",MAX($A$10:A11)+1) | B12: 46269 | C12: 46113 | D12: 沈祖模 | E12: 乳铁蛋白 | F12: 3980 | G12: =IF($D12="","",IF(COUNTIF(数据录入!$J$5:$J$4999,$D12)=0,N($T12),ROUND(MIN(MAX(0,N($W12)-(N($V12)-N($U12))),N($U12)),2))) | H12: =IF($D12="","",ROUND(N($F12)-N($G12)-N($J12),2)) | I12: =IF($D12="","",ROUND(SUM($H$11:H12),2)) | J12: 0 | K12: 支付宝 | L12: 货款 | N12: 乳铁供货商 | P12: =IF($N12="","",IF(COUNTIF(数据录入!$K$5:$K$4999,$N12)=0,N($X12),ROUND(MIN(MAX(0,N($Z12)-(N($Y12)-N($O12))),N($O12)),2))) | Q12: =IF($N12="","",ROUND(N($O12)-N($P12),2)) | R12: =IF($N12="","",ROUND(SUM($Q$11:Q12),2)) | S12: 采购 | T12: 3980 | U12: =IF($D12="","",ROUND(N($F12)-N($J12),2)) | V12: =IF($D12="","",ROUND(SUMIFS($F$11:F12,$D$11:D12,$D12)-SUMIFS($J$11:J12,$D$11:D12,$D12),2)) | W12: =IF($D12="","",ROUND(SUMIFS(数据录入!$F$5:$F$4999,数据录入!$J$5:$J$4999,$D12),2)) | Y12: =IF($N12="","",ROUND(SUMIFS($O$11:O12,$N$11:N12,$N12),2)) | Z12: =IF($N12="","",ROUND(SUMIFS(数据录入!$G$5:$G$4999,数据录入!$K$5:$K$4999,$N12),2)) | AA12: =IF(AND($D12="",$N12=""),"",IF(AND($D12<>"",COUNTIF(基础资料!$E:$E,$D12)=0),"客户名不在基础资料里",IF(AND($E12<>"",COUNTIF(基础资料!$B:$B,$E12)=0),"产品名不在基础资料里",IF(AND($N12<>"",COUNTIF(基础资料!$G:$G,$N12)=0),"供货商不在基础资料里",IF(AND($C12<>"",ISNUMBER($C12),$C12<10000),"客户生日填得不对（不是日期）",IF(N($J12)>N($F12),"销售费用大于销售金额",IF(AND($D12<>"",COUNTIF(数据录入!$J$5:$J$4999,$D12)=0,N($T12)<>0),"用的还是原手工已收款",IF(AND($D12<>"",COUNTIF(数据录入!$J$5:$J$4999,$D12)>0,ROUND(N($G12)-N($T12),2)<>0,N($T12)<>0),"自动算的已收款和原手工数对不上","√"))))))))
A13: =IF(AND($D13="",$N13=""),"",MAX($A$10:A12)+1) | B13: 46272 | C13: 46300 | D13: 谢爱琴 | E13: 羊奶 | F13: 3280 | G13: =IF($D13="","",IF(COUNTIF(数据录入!$J$5:$J$4999,$D13)=0,N($T13),ROUND(MIN(MAX(0,N($W13)-(N($V13)-N($U13))),N($U13)),2))) | H13: =IF($D13="","",ROUND(N($F13)-N($G13)-N($J13),2)) | I13: =IF($D13="","",ROUND(SUM($H$11:H13),2)) | J13: 300 | K13: 微信 | L13: 货款 | P13: =IF($N13="","",IF(COUNTIF(数据录入!$K$5:$K$4999,$N13)=0,N($X13),ROUND(MIN(MAX(0,N($Z13)-(N($Y13)-N($O13))),N($O13)),2))) | Q13: =IF($N13="","",ROUND(N($O13)-N($P13),2)) | R13: =IF($N13="","",ROUND(SUM($Q$11:Q13),2)) | S13: 采购 | T13: 2980 | U13: =IF($D13="","",ROUND(N($F13)-N($J13),2)) | V13: =IF($D13="","",ROUND(SUMIFS($F$11:F13,$D$11:D13,$D13)-SUMIFS($J$11:J13,$D$11:D13,$D13),2)) | W13: =IF($D13="","",ROUND(SUMIFS(数据录入!$F$5:$F$4999,数据录入!$J$5:$J$4999,$D13),2)) | Y13: =IF($N13="","",ROUND(SUMIFS($O$11:O13,$N$11:N13,$N13),2)) | Z13: =IF($N13="","",ROUND(SUMIFS(数据录入!$G$5:$G$4999,数据录入!$K$5:$K$4999,$N13),2)) | AA13: =IF(AND($D13="",$N13=""),"",IF(AND($D13<>"",COUNTIF(基础资料!$E:$E,$D13)=0),"客户名不在基础资料里",IF(AND($E13<>"",COUNTIF(基础资料!$B:$B,$E13)=0),"产品名不在基础资料里",IF(AND($N13<>"",COUNTIF(基础资料!$G:$G,$N13)=0),"供货商不在基础资料里",IF(AND($C13<>"",ISNUMBER($C13),$C13<10000),"客户生日填得不对（不是日期）",IF(N($J13)>N($F13),"销售费用大于销售金额",IF(AND($D13<>"",COUNTIF(数据录入!$J$5:$J$4999,$D13)=0,N($T13)<>0),"用的还是原手工已收款",IF(AND($D13<>"",COUNTIF(数据录入!$J$5:$J$4999,$D13)>0,ROUND(N($G13)-N($T13),2)<>0,N($T13)<>0),"自动算的已收款和原手工数对不上","√"))))))))
A14: =IF(AND($D14="",$N14=""),"",MAX($A$10:A13)+1) | B14: 46272 | C14: 46300 | D14: 谢爱琴 | E14: 益生菌 | F14: 3280 | G14: =IF($D14="","",IF(COUNTIF(数据录入!$J$5:$J$4999,$D14)=0,N($T14),ROUND(MIN(MAX(0,N($W14)-(N($V14)-N($U14))),N($U14)),2))) | H14: =IF($D14="","",ROUND(N($F14)-N($G14)-N($J14),2)) | I14: =IF($D14="","",ROUND(SUM($H$11:H14),2)) | J14: 300 | K14: 微信 | L14: 货款 | P14: =IF($N14="","",IF(COUNTIF(数据录入!$K$5:$K$4999,$N14)=0,N($X14),ROUND(MIN(MAX(0,N($Z14)-(N($Y14)-N($O14))),N($O14)),2))) | Q14: =IF($N14="","",ROUND(N($O14)-N($P14),2)) | R14: =IF($N14="","",ROUND(SUM($Q$11:Q14),2)) | T14: 2980 | U14: =IF($D14="","",ROUND(N($F14)-N($J14),2)) | V14: =IF($D14="","",ROUND(SUMIFS($F$11:F14,$D$11:D14,$D14)-SUMIFS($J$11:J14,$D$11:D14,$D14),2)) | W14: =IF($D14="","",ROUND(SUMIFS(数据录入!$F$5:$F$4999,数据录入!$J$5:$J$4999,$D14),2)) | Y14: =IF($N14="","",ROUND(SUMIFS($O$11:O14,$N$11:N14,$N14),2)) | Z14: =IF($N14="","",ROUND(SUMIFS(数据录入!$G$5:$G$4999,数据录入!$K$5:$K$4999,$N14),2)) | AA14: =IF(AND($D14="",$N14=""),"",IF(AND($D14<>"",COUNTIF(基础资料!$E:$E,$D14)=0),"客户名不在基础资料里",IF(AND($E14<>"",COUNTIF(基础资料!$B:$B,$E14)=0),"产品名不在基础资料里",IF(AND($N14<>"",COUNTIF(基础资料!$G:$G,$N14)=0),"供货商不在基础资料里",IF(AND($C14<>"",ISNUMBER($C14),$C14<10000),"客户生日填得不对（不是日期）",IF(N($J14)>N($F14),"销售费用大于销售金额",IF(AND($D14<>"",COUNTIF(数据录入!$J$5:$J$4999,$D14)=0,N($T14)<>0),"用的还是原手工已收款",IF(AND($D14<>"",COUNTIF(数据录入!$J$5:$J$4999,$D14)>0,ROUND(N($G14)-N($T14),2)<>0,N($T14)<>0),"自动算的已收款和原手工数对不上","√"))))))))
A15: =IF(AND($D15="",$N15=""),"",MAX($A$10:A14)+1) | B15: 46272 | C15: 46272 | D15: 罗理华 | E15: 羊奶 | F15: 3280 | G15: =IF($D15="","",IF(COUNTIF(数据录入!$J$5:$J$4999,$D15)=0,N($T15),ROUND(MIN(MAX(0,N($W15)-(N($V15)-N($U15))),N($U15)),2))) | H15: =IF($D15="","",ROUND(N($F15)-N($G15)-N($J15),2)) | I15: =IF($D15="","",ROUND(SUM($H$11:H15),2)) | J15: 0 | K15: 支付宝 | L15: 货款 | P15: =IF($N15="","",IF(COUNTIF(数据录入!$K$5:$K$4999,$N15)=0,N($X15),ROUND(MIN(MAX(0,N($Z15)-(N($Y15)-N($O15))),N($O15)),2))) | Q15: =IF($N15="","",ROUND(N($O15)-N($P15),2)) | R15: =IF($N15="","",ROUND(SUM($Q$11:Q15),2)) | T15: 1640 | U15: =IF($D15="","",ROUND(N($F15)-N($J15),2)) | V15: =IF($D15="","",ROUND(SUMIFS($F$11:F15,$D$11:D15,$D15)-SUMIFS($J$11:J15,$D$11:D15,$D15),2)) | W15: =IF($D15="","",ROUND(SUMIFS(数据录入!$F$5:$F$4999,数据录入!$J$5:$J$4999,$D15),2)) | Y15: =IF($N15="","",ROUND(SUMIFS($O$11:O15,$N$11:N15,$N15),2)) | Z15: =IF($N15="","",ROUND(SUMIFS(数据录入!$G$5:$G$4999,数据录入!$K$5:$K$4999,$N15),2)) | AA15: =IF(AND($D15="",$N15=""),"",IF(AND($D15<>"",COUNTIF(基础资料!$E:$E,$D15)=0),"客户名不在基础资料里",IF(AND($E15<>"",COUNTIF(基础资料!$B:$B,$E15)=0),"产品名不在基础资料里",IF(AND($N15<>"",COUNTIF(基础资料!$G:$G,$N15)=0),"供货商不在基础资料里",IF(AND($C15<>"",ISNUMBER($C15),$C15<10000),"客户生日填得不对（不是日期）",IF(N($J15)>N($F15),"销售费用大于销售金额",IF(AND($D15<>"",COUNTIF(数据录入!$J$5:$J$4999,$D15)=0,N($T15)<>0),"用的还是原手工已收款",IF(AND($D15<>"",COUNTIF(数据录入!$J$5:$J$4999,$D15)>0,ROUND(N($G15)-N($T15),2)<>0,N($T15)<>0),"自动算的已收款和原手工数对不上","√"))))))))
A16: =IF(AND($D16="",$N16=""),"",MAX($A$10:A15)+1) | B16: 46274 | C16: 46134 | D16: 马珍珠 | E16: 羊奶 | F16: 3280 | G16: =IF($D16="","",IF(COUNTIF(数据录入!$J$5:$J$4999,$D16)=0,N($T16),ROUND(MIN(MAX(0,N($W16)-(N($V16)-N($U16))),N($U16)),2))) | H16: =IF($D16="","",ROUND(N($F16)-N($G16)-N($J16),2)) | I16: =IF($D16="","",ROUND(SUM($H$11:H16),2)) | J16: 0 | K16: 微信 | L16: 货款 | P16: =IF($N16="","",IF(COUNTIF(数据录入!$K$5:$K$4999,$N16)=0,N($X16),ROUND(MIN(MAX(0,N($Z16)-(N($Y16)-N($O16))),N($O16)),2))) | Q16: =IF($N16="","",ROUND(N($O16)-N($P16),2)) | R16: =IF($N16="","",ROUND(SUM($Q$11:Q16),2)) | T16: 1000 | U16: =IF($D16="","",ROUND(N($F16)-N($J16),2)) | V16: =IF($D16="","",ROUND(SUMIFS($F$11:F16,$D$11:D16,$D16)-SUMIFS($J$11:J16,$D$11:D16,$D16),2)) | W16: =IF($D16="","",ROUND(SUMIFS(数据录入!$F$5:$F$4999,数据录入!$J$5:$J$4999,$D16),2)) | Y16: =IF($N16="","",ROUND(SUMIFS($O$11:O16,$N$11:N16,$N16),2)) | Z16: =IF($N16="","",ROUND(SUMIFS(数据录入!$G$5:$G$4999,数据录入!$K$5:$K$4999,$N16),2)) | AA16: =IF(AND($D16="",$N16=""),"",IF(AND($D16<>"",COUNTIF(基础资料!$E:$E,$D16)=0),"客户名不在基础资料里",IF(AND($E16<>"",COUNTIF(基础资料!$B:$B,$E16)=0),"产品名不在基础资料里",IF(AND($N16<>"",COUNTIF(基础资料!$G:$G,$N16)=0),"供货商不在基础资料里",IF(AND($C16<>"",ISNUMBER($C16),$C16<10000),"客户生日填得不对（不是日期）",IF(N($J16)>N($F16),"销售费用大于销售金额",IF(AND($D16<>"",COUNTIF(数据录入!$J$5:$J$4999,$D16)=0,N($T16)<>0),"用的还是原手工已收款",IF(AND($D16<>"",COUNTIF(数据录入!$J$5:$J$4999,$D16)>0,ROUND(N($G16)-N($T16),2)<>0,N($T16)<>0),"自动算的已收款和原手工数对不上","√"))))))))
A17: =IF(AND($D17="",$N17=""),"",MAX($A$10:A16)+1) | B17: 46277 | C17: 46333 | D17: 徐江英 | E17: 羊奶 | F17: 3280 | G17: =IF($D17="","",IF(COUNTIF(数据录入!$J$5:$J$4999,$D17)=0,N($T17),ROUND(MIN(MAX(0,N($W17)-(N($V17)-N($U17))),N($U17)),2))) | H17: =IF($D17="","",ROUND(N($F17)-N($G17)-N($J17),2)) | I17: =IF($D17="","",ROUND(SUM($H$11:H17),2)) | J17: 0 | K17: 微信 | L17: 货款 | P17: =IF($N17="","",IF(COUNTIF(数据录入!$K$5:$K$4999,$N17)=0,N($X17),ROUND(MIN(MAX(0,N($Z17)-(N($Y17)-N($O17))),N($O17)),2))) | Q17: =IF($N17="","",ROUND(N($O17)-N($P17),2)) | R17: =IF($N17="","",ROUND(SUM($Q$11:Q17),2)) | T17: 3280 | U17: =IF($D17="","",ROUND(N($F17)-N($J17),2)) | V17: =IF($D17="","",ROUND(SUMIFS($F$11:F17,$D$11:D17,$D17)-SUMIFS($J$11:J17,$D$11:D17,$D17),2)) | W17: =IF($D17="","",ROUND(SUMIFS(数据录入!$F$5:$F$4999,数据录入!$J$5:$J$4999,$D17),2)) | Y17: =IF($N17="","",ROUND(SUMIFS($O$11:O17,$N$11:N17,$N17),2)) | Z17: =IF($N17="","",ROUND(SUMIFS(数据录入!$G$5:$G$4999,数据录入!$K$5:$K$4999,$N17),2)) | AA17: =IF(AND($D17="",$N17=""),"",IF(AND($D17<>"",COUNTIF(基础资料!$E:$E,$D17)=0),"客户名不在基础资料里",IF(AND($E17<>"",COUNTIF(基础资料!$B:$B,$E17)=0),"产品名不在基础资料里",IF(AND($N17<>"",COUNTIF(基础资料!$G:$G,$N17)=0),"供货商不在基础资料里",IF(AND($C17<>"",ISNUMBER($C17),$C17<10000),"客户生日填得不对（不是日期）",IF(N($J17)>N($F17),"销售费用大于销售金额",IF(AND($D17<>"",COUNTIF(数据录入!$J$5:$J$4999,$D17)=0,N($T17)<>0),"用的还是原手工已收款",IF(AND($D17<>"",COUNTIF(数据录入!$J$5:$J$4999,$D17)>0,ROUND(N($G17)-N($T17),2)<>0,N($T17)<>0),"自动算的已收款和原手工数对不上","√"))))))))
A18: =IF(AND($D18="",$N18=""),"",MAX($A$10:A17)+1) | C18: 46148 | D18: 邵国新 | G18: =IF($D18="","",IF(COUNTIF(数据录入!$J$5:$J$4999,$D18)=0,N($T18),ROUND(MIN(MAX(0,N($W18)-(N($V18)-N($U18))),N($U18)),2))) | H18: =IF($D18="","",ROUND(N($F18)-N($G18)-N($J18),2)) | I18: =IF($D18="","",ROUND(SUM($H$11:H18),2)) | P18: =IF($N18="","",IF(COUNTIF(数据录入!$K$5:$K$4999,$N18)=0,N($X18),ROUND(MIN(MAX(0,N($Z18)-(N($Y18)-N($O18))),N($O18)),2))) | Q18: =IF($N18="","",ROUND(N($O18)-N($P18),2)) | R18: =IF($N18="","",ROUND(SUM($Q$11:Q18),2)) | U18: =IF($D18="","",ROUND(N($F18)-N($J18),2)) | V18: =IF($D18="","",ROUND(SUMIFS($F$11:F18,$D$11:D18,$D18)-SUMIFS($J$11:J18,$D$11:D18,$D18),2)) | W18: =IF($D18="","",ROUND(SUMIFS(数据录入!$F$5:$F$4999,数据录入!$J$5:$J$4999,$D18),2)) | Y18: =IF($N18="","",ROUND(SUMIFS($O$11:O18,$N$11:N18,$N18),2)) | Z18: =IF($N18="","",ROUND(SUMIFS(数据录入!$G$5:$G$4999,数据录入!$K$5:$K$4999,$N18),2)) | AA18: =IF(AND($D18="",$N18=""),"",IF(AND($D18<>"",COUNTIF(基础资料!$E:$E,$D18)=0),"客户名不在基础资料里",IF(AND($E18<>"",COUNTIF(基础资料!$B:$B,$E18)=0),"产品名不在基础资料里",IF(AND($N18<>"",COUNTIF(基础资料!$G:$G,$N18)=0),"供货商不在基础资料里",IF(AND($C18<>"",ISNUMBER($C18),$C18<10000),"客户生日填得不对（不是日期）",IF(N($J18)>N($F18),"销售费用大于销售金额",IF(AND($D18<>"",COUNTIF(数据录入!$J$5:$J$4999,$D18)=0,N($T18)<>0),"用的还是原手工已收款",IF(AND($D18<>"",COUNTIF(数据录入!$J$5:$J$4999,$D18)>0,ROUND(N($G18)-N($T18),2)<>0,N($T18)<>0),"自动算的已收款和原手工数对不上","√"))))))))
A19: =IF(AND($D19="",$N19=""),"",MAX($A$10:A18)+1) | C19: 46140 | D19: 李晓春 | G19: =IF($D19="","",IF(COUNTIF(数据录入!$J$5:$J$4999,$D19)=0,N($T19),ROUND(MIN(MAX(0,N($W19)-(N($V19)-N($U19))),N($U19)),2))) | H19: =IF($D19="","",ROUND(N($F19)-N($G19)-N($J19),2)) | I19: =IF($D19="","",ROUND(SUM($H$11:H19),2)) | P19: =IF($N19="","",IF(COUNTIF(数据录入!$K$5:$K$4999,$N19)=0,N($X19),ROUND(MIN(MAX(0,N($Z19)-(N($Y19)-N($O19))),N($O19)),2))) | Q19: =IF($N19="","",ROUND(N($O19)-N($P19),2)) | R19: =IF($N19="","",ROUND(SUM($Q$11:Q19),2)) | U19: =IF($D19="","",ROUND(N($F19)-N($J19),2)) | V19: =IF($D19="","",ROUND(SUMIFS($F$11:F19,$D$11:D19,$D19)-SUMIFS($J$11:J19,$D$11:D19,$D19),2)) | W19: =IF($D19="","",ROUND(SUMIFS(数据录入!$F$5:$F$4999,数据录入!$J$5:$J$4999,$D19),2)) | Y19: =IF($N19="","",ROUND(SUMIFS($O$11:O19,$N$11:N19,$N19),2)) | Z19: =IF($N19="","",ROUND(SUMIFS(数据录入!$G$5:$G$4999,数据录入!$K$5:$K$4999,$N19),2)) | AA19: =IF(AND($D19="",$N19=""),"",IF(AND($D19<>"",COUNTIF(基础资料!$E:$E,$D19)=0),"客户名不在基础资料里",IF(AND($E19<>"",COUNTIF(基础资料!$B:$B,$E19)=0),"产品名不在基础资料里",IF(AND($N19<>"",COUNTIF(基础资料!$G:$G,$N19)=0),"供货商不在基础资料里",IF(AND($C19<>"",ISNUMBER($C19),$C19<10000),"客户生日填得不对（不是日期）",IF(N($J19)>N($F19),"销售费用大于销售金额",IF(AND($D19<>"",COUNTIF(数据录入!$J$5:$J$4999,$D19)=0,N($T19)<>0),"用的还是原手工已收款",IF(AND($D19<>"",COUNTIF(数据录入!$J$5:$J$4999,$D19)>0,ROUND(N($G19)-N($T19),2)<>0,N($T19)<>0),"自动算的已收款和原手工数对不上","√"))))))))
A20: =IF(AND($D20="",$N20=""),"",MAX($A$10:A19)+1) | C20: 46154 | D20: 李玉娟 | G20: =IF($D20="","",IF(COUNTIF(数据录入!$J$5:$J$4999,$D20)=0,N($T20),ROUND(MIN(MAX(0,N($W20)-(N($V20)-N($U20))),N($U20)),2))) | H20: =IF($D20="","",ROUND(N($F20)-N($G20)-N($J20),2)) | I20: =IF($D20="","",ROUND(SUM($H$11:H20),2)) | P20: =IF($N20="","",IF(COUNTIF(数据录入!$K$5:$K$4999,$N20)=0,N($X20),ROUND(MIN(MAX(0,N($Z20)-(N($Y20)-N($O20))),N($O20)),2))) | Q20: =IF($N20="","",ROUND(N($O20)-N($P20),2)) | R20: =IF($N20="","",ROUND(SUM($Q$11:Q20),2)) | U20: =IF($D20="","",ROUND(N($F20)-N($J20),2)) | V20: =IF($D20="","",ROUND(SUMIFS($F$11:F20,$D$11:D20,$D20)-SUMIFS($J$11:J20,$D$11:D20,$D20),2)) | W20: =IF($D20="","",ROUND(SUMIFS(数据录入!$F$5:$F$4999,数据录入!$J$5:$J$4999,$D20),2)) | Y20: =IF($N20="","",ROUND(SUMIFS($O$11:O20,$N$11:N20,$N20),2)) | Z20: =IF($N20="","",ROUND(SUMIFS(数据录入!$G$5:$G$4999,数据录入!$K$5:$K$4999,$N20),2)) | AA20: =IF(AND($D20="",$N20=""),"",IF(AND($D20<>"",COUNTIF(基础资料!$E:$E,$D20)=0),"客户名不在基础资料里",IF(AND($E20<>"",COUNTIF(基础资料!$B:$B,$E20)=0),"产品名不在基础资料里",IF(AND($N20<>"",COUNTIF(基础资料!$G:$G,$N20)=0),"供货商不在基础资料里",IF(AND($C20<>"",ISNUMBER($C20),$C20<10000),"客户生日填得不对（不是日期）",IF(N($J20)>N($F20),"销售费用大于销售金额",IF(AND($D20<>"",COUNTIF(数据录入!$J$5:$J$4999,$D20)=0,N($T20)<>0),"用的还是原手工已收款",IF(AND($D20<>"",COUNTIF(数据录入!$J$5:$J$4999,$D20)>0,ROUND(N($G20)-N($T20),2)<>0,N($T20)<>0),"自动算的已收款和原手工数对不上","√"))))))))
A21: =IF(AND($D21="",$N21=""),"",MAX($A$10:A20)+1) | C21: 46174 | D21: 徐德彪 | G21: =IF($D21="","",IF(COUNTIF(数据录入!$J$5:$J$4999,$D21)=0,N($T21),ROUND(MIN(MAX(0,N($W21)-(N($V21)-N($U21))),N($U21)),2))) | H21: =IF($D21="","",ROUND(N($F21)-N($G21)-N($J21),2)) | I21: =IF($D21="","",ROUND(SUM($H$11:H21),2)) | P21: =IF($N21="","",IF(COUNTIF(数据录入!$K$5:$K$4999,$N21)=0,N($X21),ROUND(MIN(MAX(0,N($Z21)-(N($Y21)-N($O21))),N($O21)),2))) | Q21: =IF($N21="","",ROUND(N($O21)-N($P21),2)) | R21: =IF($N21="","",ROUND(SUM($Q$11:Q21),2)) | U21: =IF($D21="","",ROUND(N($F21)-N($J21),2)) | V21: =IF($D21="","",ROUND(SUMIFS($F$11:F21,$D$11:D21,$D21)-SUMIFS($J$11:J21,$D$11:D21,$D21),2)) | W21: =IF($D21="","",ROUND(SUMIFS(数据录入!$F$5:$F$4999,数据录入!$J$5:$J$4999,$D21),2)) | Y21: =IF($N21="","",ROUND(SUMIFS($O$11:O21,$N$11:N21,$N21),2)) | Z21: =IF($N21="","",ROUND(SUMIFS(数据录入!$G$5:$G$4999,数据录入!$K$5:$K$4999,$N21),2)) | AA21: =IF(AND($D21="",$N21=""),"",IF(AND($D21<>"",COUNTIF(基础资料!$E:$E,$D21)=0),"客户名不在基础资料里",IF(AND($E21<>"",COUNTIF(基础资料!$B:$B,$E21)=0),"产品名不在基础资料里",IF(AND($N21<>"",COUNTIF(基础资料!$G:$G,$N21)=0),"供货商不在基础资料里",IF(AND($C21<>"",ISNUMBER($C21),$C21<10000),"客户生日填得不对（不是日期）",IF(N($J21)>N($F21),"销售费用大于销售金额",IF(AND($D21<>"",COUNTIF(数据录入!$J$5:$J$4999,$D21)=0,N($T21)<>0),"用的还是原手工已收款",IF(AND($D21<>"",COUNTIF(数据录入!$J$5:$J$4999,$D21)>0,ROUND(N($G21)-N($T21),2)<>0,N($T21)<>0),"自动算的已收款和原手工数对不上","√"))))))))
A22: =IF(AND($D22="",$N22=""),"",MAX($A$10:A21)+1) | C22: 46188 | D22: 邬香花 方建宏 | G22: =IF($D22="","",IF(COUNTIF(数据录入!$J$5:$J$4999,$D22)=0,N($T22),ROUND(MIN(MAX(0,N($W22)-(N($V22)-N($U22))),N($U22)),2))) | H22: =IF($D22="","",ROUND(N($F22)-N($G22)-N($J22),2)) | I22: =IF($D22="","",ROUND(SUM($H$11:H22),2)) | P22: =IF($N22="","",IF(COUNTIF(数据录入!$K$5:$K$4999,$N22)=0,N($X22),ROUND(MIN(MAX(0,N($Z22)-(N($Y22)-N($O22))),N($O22)),2))) | Q22: =IF($N22="","",ROUND(N($O22)-N($P22),2)) | R22: =IF($N22="","",ROUND(SUM($Q$11:Q22),2)) | U22: =IF($D22="","",ROUND(N($F22)-N($J22),2)) | V22: =IF($D22="","",ROUND(SUMIFS($F$11:F22,$D$11:D22,$D22)-SUMIFS($J$11:J22,$D$11:D22,$D22),2)) | W22: =IF($D22="","",ROUND(SUMIFS(数据录入!$F$5:$F$4999,数据录入!$J$5:$J$4999,$D22),2)) | Y22: =IF($N22="","",ROUND(SUMIFS($O$11:O22,$N$11:N22,$N22),2)) | Z22: =IF($N22="","",ROUND(SUMIFS(数据录入!$G$5:$G$4999,数据录入!$K$5:$K$4999,$N22),2)) | AA22: =IF(AND($D22="",$N22=""),"",IF(AND($D22<>"",COUNTIF(基础资料!$E:$E,$D22)=0),"客户名不在基础资料里",IF(AND($E22<>"",COUNTIF(基础资料!$B:$B,$E22)=0),"产品名不在基础资料里",IF(AND($N22<>"",COUNTIF(基础资料!$G:$G,$N22)=0),"供货商不在基础资料里",IF(AND($C22<>"",ISNUMBER($C22),$C22<10000),"客户生日填得不对（不是日期）",IF(N($J22)>N($F22),"销售费用大于销售金额",IF(AND($D22<>"",COUNTIF(数据录入!$J$5:$J$4999,$D22)=0,N($T22)<>0),"用的还是原手工已收款",IF(AND($D22<>"",COUNTIF(数据录入!$J$5:$J$4999,$D22)>0,ROUND(N($G22)-N($T22),2)<>0,N($T22)<>0),"自动算的已收款和原手工数对不上","√"))))))))
A23: =IF(AND($D23="",$N23=""),"",MAX($A$10:A22)+1) | B23: 46235 | C23: 6月17日 3月4日 | D23: 林永来 杨建云 | G23: =IF($D23="","",IF(COUNTIF(数据录入!$J$5:$J$4999,$D23)=0,N($T23),ROUND(MIN(MAX(0,N($W23)-(N($V23)-N($U23))),N($U23)),2))) | H23: =IF($D23="","",ROUND(N($F23)-N($G23)-N($J23),2)) | I23: =IF($D23="","",ROUND(SUM($H$11:H23),2)) | P23: =IF($N23="","",IF(COUNTIF(数据录入!$K$5:$K$4999,$N23)=0,N($X23),ROUND(MIN(MAX(0,N($Z23)-(N($Y23)-N($O23))),N($O23)),2))) | Q23: =IF($N23="","",ROUND(N($O23)-N($P23),2)) | R23: =IF($N23="","",ROUND(SUM($Q$11:Q23),2)) | U23: =IF($D23="","",ROUND(N($F23)-N($J23),2)) | V23: =IF($D23="","",ROUND(SUMIFS($F$11:F23,$D$11:D23,$D23)-SUMIFS($J$11:J23,$D$11:D23,$D23),2)) | W23: =IF($D23="","",ROUND(SUMIFS(数据录入!$F$5:$F$4999,数据录入!$J$5:$J$4999,$D23),2)) | Y23: =IF($N23="","",ROUND(SUMIFS($O$11:O23,$N$11:N23,$N23),2)) | Z23: =IF($N23="","",ROUND(SUMIFS(数据录入!$G$5:$G$4999,数据录入!$K$5:$K$4999,$N23),2)) | AA23: =IF(AND($D23="",$N23=""),"",IF(AND($D23<>"",COUNTIF(基础资料!$E:$E,$D23)=0),"客户名不在基础资料里",IF(AND($E23<>"",COUNTIF(基础资料!$B:$B,$E23)=0),"产品名不在基础资料里",IF(AND($N23<>"",COUNTIF(基础资料!$G:$G,$N23)=0),"供货商不在基础资料里",IF(AND($C23<>"",ISNUMBER($C23),$C23<10000),"客户生日填得不对（不是日期）",IF(N($J23)>N($F23),"销售费用大于销售金额",IF(AND($D23<>"",COUNTIF(数据录入!$J$5:$J$4999,$D23)=0,N($T23)<>0),"用的还是原手工已收款",IF(AND($D23<>"",COUNTIF(数据录入!$J$5:$J$4999,$D23)>0,ROUND(N($G23)-N($T23),2)<>0,N($T23)<>0),"自动算的已收款和原手工数对不上","√"))))))))
A24: =IF(AND($D24="",$N24=""),"",MAX($A$10:A23)+1) | C24: 46220 | D24: 郭志伟 | G24: =IF($D24="","",IF(COUNTIF(数据录入!$J$5:$J$4999,$D24)=0,N($T24),ROUND(MIN(MAX(0,N($W24)-(N($V24)-N($U24))),N($U24)),2))) | H24: =IF($D24="","",ROUND(N($F24)-N($G24)-N($J24),2)) | I24: =IF($D24="","",ROUND(SUM($H$11:H24),2)) | P24: =IF($N24="","",IF(COUNTIF(数据录入!$K$5:$K$4999,$N24)=0,N($X24),ROUND(MIN(MAX(0,N($Z24)-(N($Y24)-N($O24))),N($O24)),2))) | Q24: =IF($N24="","",ROUND(N($O24)-N($P24),2)) | R24: =IF($N24="","",ROUND(SUM($Q$11:Q24),2)) | U24: =IF($D24="","",ROUND(N($F24)-N($J24),2)) | V24: =IF($D24="","",ROUND(SUMIFS($F$11:F24,$D$11:D24,$D24)-SUMIFS($J$11:J24,$D$11:D24,$D24),2)) | W24: =IF($D24="","",ROUND(SUMIFS(数据录入!$F$5:$F$4999,数据录入!$J$5:$J$4999,$D24),2)) | Y24: =IF($N24="","",ROUND(SUMIFS($O$11:O24,$N$11:N24,$N24),2)) | Z24: =IF($N24="","",ROUND(SUMIFS(数据录入!$G$5:$G$4999,数据录入!$K$5:$K$4999,$N24),2)) | AA24: =IF(AND($D24="",$N24=""),"",IF(AND($D24<>"",COUNTIF(基础资料!$E:$E,$D24)=0),"客户名不在基础资料里",IF(AND($E24<>"",COUNTIF(基础资料!$B:$B,$E24)=0),"产品名不在基础资料里",IF(AND($N24<>"",COUNTIF(基础资料!$G:$G,$N24)=0),"供货商不在基础资料里",IF(AND($C24<>"",ISNUMBER($C24),$C24<10000),"客户生日填得不对（不是日期）",IF(N($J24)>N($F24),"销售费用大于销售金额",IF(AND($D24<>"",COUNTIF(数据录入!$J$5:$J$4999,$D24)=0,N($T24)<>0),"用的还是原手工已收款",IF(AND($D24<>"",COUNTIF(数据录入!$J$5:$J$4999,$D24)>0,ROUND(N($G24)-N($T24),2)<>0,N($T24)<>0),"自动算的已收款和原手工数对不上","√"))))))))
A25: =IF(AND($D25="",$N25=""),"",MAX($A$10:A24)+1) | C25: 46225 | D25: 吴亮 | G25: =IF($D25="","",IF(COUNTIF(数据录入!$J$5:$J$4999,$D25)=0,N($T25),ROUND(MIN(MAX(0,N($W25)-(N($V25)-N($U25))),N($U25)),2))) | H25: =IF($D25="","",ROUND(N($F25)-N($G25)-N($J25),2)) | I25: =IF($D25="","",ROUND(SUM($H$11:H25),2)) | P25: =IF($N25="","",IF(COUNTIF(数据录入!$K$5:$K$4999,$N25)=0,N($X25),ROUND(MIN(MAX(0,N($Z25)-(N($Y25)-N($O25))),N($O25)),2))) | Q25: =IF($N25="","",ROUND(N($O25)-N($P25),2)) | R25: =IF($N25="","",ROUND(SUM($Q$11:Q25),2)) | U25: =IF($D25="","",ROUND(N($F25)-N($J25),2)) | V25: =IF($D25="","",ROUND(SUMIFS($F$11:F25,$D$11:D25,$D25)-SUMIFS($J$11:J25,$D$11:D25,$D25),2)) | W25: =IF($D25="","",ROUND(SUMIFS(数据录入!$F$5:$F$4999,数据录入!$J$5:$J$4999,$D25),2)) | Y25: =IF($N25="","",ROUND(SUMIFS($O$11:O25,$N$11:N25,$N25),2)) | Z25: =IF($N25="","",ROUND(SUMIFS(数据录入!$G$5:$G$4999,数据录入!$K$5:$K$4999,$N25),2)) | AA25: =IF(AND($D25="",$N25=""),"",IF(AND($D25<>"",COUNTIF(基础资料!$E:$E,$D25)=0),"客户名不在基础资料里",IF(AND($E25<>"",COUNTIF(基础资料!$B:$B,$E25)=0),"产品名不在基础资料里",IF(AND($N25<>"",COUNTIF(基础资料!$G:$G,$N25)=0),"供货商不在基础资料里",IF(AND($C25<>"",ISNUMBER($C25),$C25<10000),"客户生日填得不对（不是日期）",IF(N($J25)>N($F25),"销售费用大于销售金额",IF(AND($D25<>"",COUNTIF(数据录入!$J$5:$J$4999,$D25)=0,N($T25)<>0),"用的还是原手工已收款",IF(AND($D25<>"",COUNTIF(数据录入!$J$5:$J$4999,$D25)>0,ROUND(N($G25)-N($T25),2)<>0,N($T25)<>0),"自动算的已收款和原手工数对不上","√"))))))))
A26: =IF(AND($D26="",$N26=""),"",MAX($A$10:A25)+1) | C26: 46232 | D26: 吴兆香 | G26: =IF($D26="","",IF(COUNTIF(数据录入!$J$5:$J$4999,$D26)=0,N($T26),ROUND(MIN(MAX(0,N($W26)-(N($V26)-N($U26))),N($U26)),2))) | H26: =IF($D26="","",ROUND(N($F26)-N($G26)-N($J26),2)) | I26: =IF($D26="","",ROUND(SUM($H$11:H26),2)) | P26: =IF($N26="","",IF(COUNTIF(数据录入!$K$5:$K$4999,$N26)=0,N($X26),ROUND(MIN(MAX(0,N($Z26)-(N($Y26)-N($O26))),N($O26)),2))) | Q26: =IF($N26="","",ROUND(N($O26)-N($P26),2)) | R26: =IF($N26="","",ROUND(SUM($Q$11:Q26),2)) | U26: =IF($D26="","",ROUND(N($F26)-N($J26),2)) | V26: =IF($D26="","",ROUND(SUMIFS($F$11:F26,$D$11:D26,$D26)-SUMIFS($J$11:J26,$D$11:D26,$D26),2)) | W26: =IF($D26="","",ROUND(SUMIFS(数据录入!$F$5:$F$4999,数据录入!$J$5:$J$4999,$D26),2)) | Y26: =IF($N26="","",ROUND(SUMIFS($O$11:O26,$N$11:N26,$N26),2)) | Z26: =IF($N26="","",ROUND(SUMIFS(数据录入!$G$5:$G$4999,数据录入!$K$5:$K$4999,$N26),2)) | AA26: =IF(AND($D26="",$N26=""),"",IF(AND($D26<>"",COUNTIF(基础资料!$E:$E,$D26)=0),"客户名不在基础资料里",IF(AND($E26<>"",COUNTIF(基础资料!$B:$B,$E26)=0),"产品名不在基础资料里",IF(AND($N26<>"",COUNTIF(基础资料!$G:$G,$N26)=0),"供货商不在基础资料里",IF(AND($C26<>"",ISNUMBER($C26),$C26<10000),"客户生日填得不对（不是日期）",IF(N($J26)>N($F26),"销售费用大于销售金额",IF(AND($D26<>"",COUNTIF(数据录入!$J$5:$J$4999,$D26)=0,N($T26)<>0),"用的还是原手工已收款",IF(AND($D26<>"",COUNTIF(数据录入!$J$5:$J$4999,$D26)>0,ROUND(N($G26)-N($T26),2)<>0,N($T26)<>0),"自动算的已收款和原手工数对不上","√"))))))))
A27: =IF(AND($D27="",$N27=""),"",MAX($A$10:A26)+1) | C27: 46242 | D27: 郑玉英 | G27: =IF($D27="","",IF(COUNTIF(数据录入!$J$5:$J$4999,$D27)=0,N($T27),ROUND(MIN(MAX(0,N($W27)-(N($V27)-N($U27))),N($U27)),2))) | H27: =IF($D27="","",ROUND(N($F27)-N($G27)-N($J27),2)) | I27: =IF($D27="","",ROUND(SUM($H$11:H27),2)) | P27: =IF($N27="","",IF(COUNTIF(数据录入!$K$5:$K$4999,$N27)=0,N($X27),ROUND(MIN(MAX(0,N($Z27)-(N($Y27)-N($O27))),N($O27)),2))) | Q27: =IF($N27="","",ROUND(N($O27)-N($P27),2)) | R27: =IF($N27="","",ROUND(SUM($Q$11:Q27),2)) | U27: =IF($D27="","",ROUND(N($F27)-N($J27),2)) | V27: =IF($D27="","",ROUND(SUMIFS($F$11:F27,$D$11:D27,$D27)-SUMIFS($J$11:J27,$D$11:D27,$D27),2)) | W27: =IF($D27="","",ROUND(SUMIFS(数据录入!$F$5:$F$4999,数据录入!$J$5:$J$4999,$D27),2)) | Y27: =IF($N27="","",ROUND(SUMIFS($O$11:O27,$N$11:N27,$N27),2)) | Z27: =IF($N27="","",ROUND(SUMIFS(数据录入!$G$5:$G$4999,数据录入!$K$5:$K$4999,$N27),2)) | AA27: =IF(AND($D27="",$N27=""),"",IF(AND($D27<>"",COUNTIF(基础资料!$E:$E,$D27)=0),"客户名不在基础资料里",IF(AND($E27<>"",COUNTIF(基础资料!$B:$B,$E27)=0),"产品名不在基础资料里",IF(AND($N27<>"",COUNTIF(基础资料!$G:$G,$N27)=0),"供货商不在基础资料里",IF(AND($C27<>"",ISNUMBER($C27),$C27<10000),"客户生日填得不对（不是日期）",IF(N($J27)>N($F27),"销售费用大于销售金额",IF(AND($D27<>"",COUNTIF(数据录入!$J$5:$J$4999,$D27)=0,N($T27)<>0),"用的还是原手工已收款",IF(AND($D27<>"",COUNTIF(数据录入!$J$5:$J$4999,$D27)>0,ROUND(N($G27)-N($T27),2)<>0,N($T27)<>0),"自动算的已收款和原手工数对不上","√"))))))))
A28: =IF(AND($D28="",$N28=""),"",MAX($A$10:A27)+1) | C28: 46274 | D28: 唐鑫红 | G28: =IF($D28="","",IF(COUNTIF(数据录入!$J$5:$J$4999,$D28)=0,N($T28),ROUND(MIN(MAX(0,N($W28)-(N($V28)-N($U28))),N($U28)),2))) | H28: =IF($D28="","",ROUND(N($F28)-N($G28)-N($J28),2)) | I28: =IF($D28="","",ROUND(SUM($H$11:H28),2)) | P28: =IF($N28="","",IF(COUNTIF(数据录入!$K$5:$K$4999,$N28)=0,N($X28),ROUND(MIN(MAX(0,N($Z28)-(N($Y28)-N($O28))),N($O28)),2))) | Q28: =IF($N28="","",ROUND(N($O28)-N($P28),2)) | R28: =IF($N28="","",ROUND(SUM($Q$11:Q28),2)) | U28: =IF($D28="","",ROUND(N($F28)-N($J28),2)) | V28: =IF($D28="","",ROUND(SUMIFS($F$11:F28,$D$11:D28,$D28)-SUMIFS($J$11:J28,$D$11:D28,$D28),2)) | W28: =IF($D28="","",ROUND(SUMIFS(数据录入!$F$5:$F$4999,数据录入!$J$5:$J$4999,$D28),2)) | Y28: =IF($N28="","",ROUND(SUMIFS($O$11:O28,$N$11:N28,$N28),2)) | Z28: =IF($N28="","",ROUND(SUMIFS(数据录入!$G$5:$G$4999,数据录入!$K$5:$K$4999,$N28),2)) | AA28: =IF(AND($D28="",$N28=""),"",IF(AND($D28<>"",COUNTIF(基础资料!$E:$E,$D28)=0),"客户名不在基础资料里",IF(AND($E28<>"",COUNTIF(基础资料!$B:$B,$E28)=0),"产品名不在基础资料里",IF(AND($N28<>"",COUNTIF(基础资料!$G:$G,$N28)=0),"供货商不在基础资料里",IF(AND($C28<>"",ISNUMBER($C28),$C28<10000),"客户生日填得不对（不是日期）",IF(N($J28)>N($F28),"销售费用大于销售金额",IF(AND($D28<>"",COUNTIF(数据录入!$J$5:$J$4999,$D28)=0,N($T28)<>0),"用的还是原手工已收款",IF(AND($D28<>"",COUNTIF(数据录入!$J$5:$J$4999,$D28)>0,ROUND(N($G28)-N($T28),2)<>0,N($T28)<>0),"自动算的已收款和原手工数对不上","√"))))))))
A29: =IF(AND($D29="",$N29=""),"",MAX($A$10:A28)+1) | C29: 46285 | D29: 叶芬 | G29: =IF($D29="","",IF(COUNTIF(数据录入!$J$5:$J$4999,$D29)=0,N($T29),ROUND(MIN(MAX(0,N($W29)-(N($V29)-N($U29))),N($U29)),2))) | H29: =IF($D29="","",ROUND(N($F29)-N($G29)-N($J29),2)) | I29: =IF($D29="","",ROUND(SUM($H$11:H29),2)) | P29: =IF($N29="","",IF(COUNTIF(数据录入!$K$5:$K$4999,$N29)=0,N($X29),ROUND(MIN(MAX(0,N($Z29)-(N($Y29)-N($O29))),N($O29)),2))) | Q29: =IF($N29="","",ROUND(N($O29)-N($P29),2)) | R29: =IF($N29="","",ROUND(SUM($Q$11:Q29),2)) | U29: =IF($D29="","",ROUND(N($F29)-N($J29),2)) | V29: =IF($D29="","",ROUND(SUMIFS($F$11:F29,$D$11:D29,$D29)-SUMIFS($J$11:J29,$D$11:D29,$D29),2)) | W29: =IF($D29="","",ROUND(SUMIFS(数据录入!$F$5:$F$4999,数据录入!$J$5:$J$4999,$D29),2)) | Y29: =IF($N29="","",ROUND(SUMIFS($O$11:O29,$N$11:N29,$N29),2)) | Z29: =IF($N29="","",ROUND(SUMIFS(数据录入!$G$5:$G$4999,数据录入!$K$5:$K$4999,$N29),2)) | AA29: =IF(AND($D29="",$N29=""),"",IF(AND($D29<>"",COUNTIF(基础资料!$E:$E,$D29)=0),"客户名不在基础资料里",IF(AND($E29<>"",COUNTIF(基础资料!$B:$B,$E29)=0),"产品名不在基础资料里",IF(AND($N29<>"",COUNTIF(基础资料!$G:$G,$N29)=0),"供货商不在基础资料里",IF(AND($C29<>"",ISNUMBER($C29),$C29<10000),"客户生日填得不对（不是日期）",IF(N($J29)>N($F29),"销售费用大于销售金额",IF(AND($D29<>"",COUNTIF(数据录入!$J$5:$J$4999,$D29)=0,N($T29)<>0),"用的还是原手工已收款",IF(AND($D29<>"",COUNTIF(数据录入!$J$5:$J$4999,$D29)>0,ROUND(N($G29)-N($T29),2)<>0,N($T29)<>0),"自动算的已收款和原手工数对不上","√"))))))))
A30: =IF(AND($D30="",$N30=""),"",MAX($A$10:A29)+1) | C30: 46288 | D30: 童炳寿 王秀娟 | G30: =IF($D30="","",IF(COUNTIF(数据录入!$J$5:$J$4999,$D30)=0,N($T30),ROUND(MIN(MAX(0,N($W30)-(N($V30)-N($U30))),N($U30)),2))) | H30: =IF($D30="","",ROUND(N($F30)-N($G30)-N($J30),2)) | I30: =IF($D30="","",ROUND(SUM($H$11:H30),2)) | P30: =IF($N30="","",IF(COUNTIF(数据录入!$K$5:$K$4999,$N30)=0,N($X30),ROUND(MIN(MAX(0,N($Z30)-(N($Y30)-N($O30))),N($O30)),2))) | Q30: =IF($N30="","",ROUND(N($O30)-N($P30),2)) | R30: =IF($N30="","",ROUND(SUM($Q$11:Q30),2)) | U30: =IF($D30="","",ROUND(N($F30)-N($J30),2)) | V30: =IF($D30="","",ROUND(SUMIFS($F$11:F30,$D$11:D30,$D30)-SUMIFS($J$11:J30,$D$11:D30,$D30),2)) | W30: =IF($D30="","",ROUND(SUMIFS(数据录入!$F$5:$F$4999,数据录入!$J$5:$J$4999,$D30),2)) | Y30: =IF($N30="","",ROUND(SUMIFS($O$11:O30,$N$11:N30,$N30),2)) | Z30: =IF($N30="","",ROUND(SUMIFS(数据录入!$G$5:$G$4999,数据录入!$K$5:$K$4999,$N30),2)) | AA30: =IF(AND($D30="",$N30=""),"",IF(AND($D30<>"",COUNTIF(基础资料!$E:$E,$D30)=0),"客户名不在基础资料里",IF(AND($E30<>"",COUNTIF(基础资料!$B:$B,$E30)=0),"产品名不在基础资料里",IF(AND($N30<>"",COUNTIF(基础资料!$G:$G,$N30)=0),"供货商不在基础资料里",IF(AND($C30<>"",ISNUMBER($C30),$C30<10000),"客户生日填得不对（不是日期）",IF(N($J30)>N($F30),"销售费用大于销售金额",IF(AND($D30<>"",COUNTIF(数据录入!$J$5:$J$4999,$D30)=0,N($T30)<>0),"用的还是原手工已收款",IF(AND($D30<>"",COUNTIF(数据录入!$J$5:$J$4999,$D30)>0,ROUND(N($G30)-N($T30),2)<>0,N($T30)<>0),"自动算的已收款和原手工数对不上","√"))))))))
A31: =IF(AND($D31="",$N31=""),"",MAX($A$10:A30)+1) | C31: 46299 | D31: 郑爱月 | G31: =IF($D31="","",IF(COUNTIF(数据录入!$J$5:$J$4999,$D31)=0,N($T31),ROUND(MIN(MAX(0,N($W31)-(N($V31)-N($U31))),N($U31)),2))) | H31: =IF($D31="","",ROUND(N($F31)-N($G31)-N($J31),2)) | I31: =IF($D31="","",ROUND(SUM($H$11:H31),2)) | P31: =IF($N31="","",IF(COUNTIF(数据录入!$K$5:$K$4999,$N31)=0,N($X31),ROUND(MIN(MAX(0,N($Z31)-(N($Y31)-N($O31))),N($O31)),2))) | Q31: =IF($N31="","",ROUND(N($O31)-N($P31),2)) | R31: =IF($N31="","",ROUND(SUM($Q$11:Q31),2)) | U31: =IF($D31="","",ROUND(N($F31)-N($J31),2)) | V31: =IF($D31="","",ROUND(SUMIFS($F$11:F31,$D$11:D31,$D31)-SUMIFS($J$11:J31,$D$11:D31,$D31),2)) | W31: =IF($D31="","",ROUND(SUMIFS(数据录入!$F$5:$F$4999,数据录入!$J$5:$J$4999,$D31),2)) | Y31: =IF($N31="","",ROUND(SUMIFS($O$11:O31,$N$11:N31,$N31),2)) | Z31: =IF($N31="","",ROUND(SUMIFS(数据录入!$G$5:$G$4999,数据录入!$K$5:$K$4999,$N31),2)) | AA31: =IF(AND($D31="",$N31=""),"",IF(AND($D31<>"",COUNTIF(基础资料!$E:$E,$D31)=0),"客户名不在基础资料里",IF(AND($E31<>"",COUNTIF(基础资料!$B:$B,$E31)=0),"产品名不在基础资料里",IF(AND($N31<>"",COUNTIF(基础资料!$G:$G,$N31)=0),"供货商不在基础资料里",IF(AND($C31<>"",ISNUMBER($C31),$C31<10000),"客户生日填得不对（不是日期）",IF(N($J31)>N($F31),"销售费用大于销售金额",IF(AND($D31<>"",COUNTIF(数据录入!$J$5:$J$4999,$D31)=0,N($T31)<>0),"用的还是原手工已收款",IF(AND($D31<>"",COUNTIF(数据录入!$J$5:$J$4999,$D31)>0,ROUND(N($G31)-N($T31),2)<>0,N($T31)<>0),"自动算的已收款和原手工数对不上","√"))))))))
A32: =IF(AND($D32="",$N32=""),"",MAX($A$10:A31)+1) | C32: 46309 | D32: 李小琴 | G32: =IF($D32="","",IF(COUNTIF(数据录入!$J$5:$J$4999,$D32)=0,N($T32),ROUND(MIN(MAX(0,N($W32)-(N($V32)-N($U32))),N($U32)),2))) | H32: =IF($D32="","",ROUND(N($F32)-N($G32)-N($J32),2)) | I32: =IF($D32="","",ROUND(SUM($H$11:H32),2)) | P32: =IF($N32="","",IF(COUNTIF(数据录入!$K$5:$K$4999,$N32)=0,N($X32),ROUND(MIN(MAX(0,N($Z32)-(N($Y32)-N($O32))),N($O32)),2))) | Q32: =IF($N32="","",ROUND(N($O32)-N($P32),2)) | R32: =IF($N32="","",ROUND(SUM($Q$11:Q32),2)) | U32: =IF($D32="","",ROUND(N($F32)-N($J32),2)) | V32: =IF($D32="","",ROUND(SUMIFS($F$11:F32,$D$11:D32,$D32)-SUMIFS($J$11:J32,$D$11:D32,$D32),2)) | W32: =IF($D32="","",ROUND(SUMIFS(数据录入!$F$5:$F$4999,数据录入!$J$5:$J$4999,$D32),2)) | Y32: =IF($N32="","",ROUND(SUMIFS($O$11:O32,$N$11:N32,$N32),2)) | Z32: =IF($N32="","",ROUND(SUMIFS(数据录入!$G$5:$G$4999,数据录入!$K$5:$K$4999,$N32),2)) | AA32: =IF(AND($D32="",$N32=""),"",IF(AND($D32<>"",COUNTIF(基础资料!$E:$E,$D32)=0),"客户名不在基础资料里",IF(AND($E32<>"",COUNTIF(基础资料!$B:$B,$E32)=0),"产品名不在基础资料里",IF(AND($N32<>"",COUNTIF(基础资料!$G:$G,$N32)=0),"供货商不在基础资料里",IF(AND($C32<>"",ISNUMBER($C32),$C32<10000),"客户生日填得不对（不是日期）",IF(N($J32)>N($F32),"销售费用大于销售金额",IF(AND($D32<>"",COUNTIF(数据录入!$J$5:$J$4999,$D32)=0,N($T32)<>0),"用的还是原手工已收款",IF(AND($D32<>"",COUNTIF(数据录入!$J$5:$J$4999,$D32)>0,ROUND(N($G32)-N($T32),2)<>0,N($T32)<>0),"自动算的已收款和原手工数对不上","√"))))))))
A33: =IF(AND($D33="",$N33=""),"",MAX($A$10:A32)+1) | C33: 46318 | D33: 郁建红 | G33: =IF($D33="","",IF(COUNTIF(数据录入!$J$5:$J$4999,$D33)=0,N($T33),ROUND(MIN(MAX(0,N($W33)-(N($V33)-N($U33))),N($U33)),2))) | H33: =IF($D33="","",ROUND(N($F33)-N($G33)-N($J33),2)) | I33: =IF($D33="","",ROUND(SUM($H$11:H33),2)) | P33: =IF($N33="","",IF(COUNTIF(数据录入!$K$5:$K$4999,$N33)=0,N($X33),ROUND(MIN(MAX(0,N($Z33)-(N($Y33)-N($O33))),N($O33)),2))) | Q33: =IF($N33="","",ROUND(N($O33)-N($P33),2)) | R33: =IF($N33="","",ROUND(SUM($Q$11:Q33),2)) | U33: =IF($D33="","",ROUND(N($F33)-N($J33),2)) | V33: =IF($D33="","",ROUND(SUMIFS($F$11:F33,$D$11:D33,$D33)-SUMIFS($J$11:J33,$D$11:D33,$D33),2)) | W33: =IF($D33="","",ROUND(SUMIFS(数据录入!$F$5:$F$4999,数据录入!$J$5:$J$4999,$D33),2)) | Y33: =IF($N33="","",ROUND(SUMIFS($O$11:O33,$N$11:N33,$N33),2)) | Z33: =IF($N33="","",ROUND(SUMIFS(数据录入!$G$5:$G$4999,数据录入!$K$5:$K$4999,$N33),2)) | AA33: =IF(AND($D33="",$N33=""),"",IF(AND($D33<>"",COUNTIF(基础资料!$E:$E,$D33)=0),"客户名不在基础资料里",IF(AND($E33<>"",COUNTIF(基础资料!$B:$B,$E33)=0),"产品名不在基础资料里",IF(AND($N33<>"",COUNTIF(基础资料!$G:$G,$N33)=0),"供货商不在基础资料里",IF(AND($C33<>"",ISNUMBER($C33),$C33<10000),"客户生日填得不对（不是日期）",IF(N($J33)>N($F33),"销售费用大于销售金额",IF(AND($D33<>"",COUNTIF(数据录入!$J$5:$J$4999,$D33)=0,N($T33)<>0),"用的还是原手工已收款",IF(AND($D33<>"",COUNTIF(数据录入!$J$5:$J$4999,$D33)>0,ROUND(N($G33)-N($T33),2)<>0,N($T33)<>0),"自动算的已收款和原手工数对不上","√"))))))))
A34: =IF(AND($D34="",$N34=""),"",MAX($A$10:A33)+1) | C34: 10月30日 2月3日 | D34: 姜蓉兰 洪宗邦 | G34: =IF($D34="","",IF(COUNTIF(数据录入!$J$5:$J$4999,$D34)=0,N($T34),ROUND(MIN(MAX(0,N($W34)-(N($V34)-N($U34))),N($U34)),2))) | H34: =IF($D34="","",ROUND(N($F34)-N($G34)-N($J34),2)) | I34: =IF($D34="","",ROUND(SUM($H$11:H34),2)) | P34: =IF($N34="","",IF(COUNTIF(数据录入!$K$5:$K$4999,$N34)=0,N($X34),ROUND(MIN(MAX(0,N($Z34)-(N($Y34)-N($O34))),N($O34)),2))) | Q34: =IF($N34="","",ROUND(N($O34)-N($P34),2)) | R34: =IF($N34="","",ROUND(SUM($Q$11:Q34),2)) | U34: =IF($D34="","",ROUND(N($F34)-N($J34),2)) | V34: =IF($D34="","",ROUND(SUMIFS($F$11:F34,$D$11:D34,$D34)-SUMIFS($J$11:J34,$D$11:D34,$D34),2)) | W34: =IF($D34="","",ROUND(SUMIFS(数据录入!$F$5:$F$4999,数据录入!$J$5:$J$4999,$D34),2)) | Y34: =IF($N34="","",ROUND(SUMIFS($O$11:O34,$N$11:N34,$N34),2)) | Z34: =IF($N34="","",ROUND(SUMIFS(数据录入!$G$5:$G$4999,数据录入!$K$5:$K$4999,$N34),2)) | AA34: =IF(AND($D34="",$N34=""),"",IF(AND($D34<>"",COUNTIF(基础资料!$E:$E,$D34)=0),"客户名不在基础资料里",IF(AND($E34<>"",COUNTIF(基础资料!$B:$B,$E34)=0),"产品名不在基础资料里",IF(AND($N34<>"",COUNTIF(基础资料!$G:$G,$N34)=0),"供货商不在基础资料里",IF(AND($C34<>"",ISNUMBER($C34),$C34<10000),"客户生日填得不对（不是日期）",IF(N($J34)>N($F34),"销售费用大于销售金额",IF(AND($D34<>"",COUNTIF(数据录入!$J$5:$J$4999,$D34)=0,N($T34)<>0),"用的还是原手工已收款",IF(AND($D34<>"",COUNTIF(数据录入!$J$5:$J$4999,$D34)>0,ROUND(N($G34)-N($T34),2)<>0,N($T34)<>0),"自动算的已收款和原手工数对不上","√"))))))))
A35: =IF(AND($D35="",$N35=""),"",MAX($A$10:A34)+1) | C35: 46329 | D35: 过承祁 | G35: =IF($D35="","",IF(COUNTIF(数据录入!$J$5:$J$4999,$D35)=0,N($T35),ROUND(MIN(MAX(0,N($W35)-(N($V35)-N($U35))),N($U35)),2))) | H35: =IF($D35="","",ROUND(N($F35)-N($G35)-N($J35),2)) | I35: =IF($D35="","",ROUND(SUM($H$11:H35),2)) | P35: =IF($N35="","",IF(COUNTIF(数据录入!$K$5:$K$4999,$N35)=0,N($X35),ROUND(MIN(MAX(0,N($Z35)-(N($Y35)-N($O35))),N($O35)),2))) | Q35: =IF($N35="","",ROUND(N($O35)-N($P35),2)) | R35: =IF($N35="","",ROUND(SUM($Q$11:Q35),2)) | U35: =IF($D35="","",ROUND(N($F35)-N($J35),2)) | V35: =IF($D35="","",ROUND(SUMIFS($F$11:F35,$D$11:D35,$D35)-SUMIFS($J$11:J35,$D$11:D35,$D35),2)) | W35: =IF($D35="","",ROUND(SUMIFS(数据录入!$F$5:$F$4999,数据录入!$J$5:$J$4999,$D35),2)) | Y35: =IF($N35="","",ROUND(SUMIFS($O$11:O35,$N$11:N35,$N35),2)) | Z35: =IF($N35="","",ROUND(SUMIFS(数据录入!$G$5:$G$4999,数据录入!$K$5:$K$4999,$N35),2)) | AA35: =IF(AND($D35="",$N35=""),"",IF(AND($D35<>"",COUNTIF(基础资料!$E:$E,$D35)=0),"客户名不在基础资料里",IF(AND($E35<>"",COUNTIF(基础资料!$B:$B,$E35)=0),"产品名不在基础资料里",IF(AND($N35<>"",COUNTIF(基础资料!$G:$G,$N35)=0),"供货商不在基础资料里",IF(AND($C35<>"",ISNUMBER($C35),$C35<10000),"客户生日填得不对（不是日期）",IF(N($J35)>N($F35),"销售费用大于销售金额",IF(AND($D35<>"",COUNTIF(数据录入!$J$5:$J$4999,$D35)=0,N($T35)<>0),"用的还是原手工已收款",IF(AND($D35<>"",COUNTIF(数据录入!$J$5:$J$4999,$D35)>0,ROUND(N($G35)-N($T35),2)<>0,N($T35)<>0),"自动算的已收款和原手工数对不上","√"))))))))
A36: =IF(AND($D36="",$N36=""),"",MAX($A$10:A35)+1) | C36: 46330 | D36: 郑江宏 | G36: =IF($D36="","",IF(COUNTIF(数据录入!$J$5:$J$4999,$D36)=0,N($T36),ROUND(MIN(MAX(0,N($W36)-(N($V36)-N($U36))),N($U36)),2))) | H36: =IF($D36="","",ROUND(N($F36)-N($G36)-N($J36),2)) | I36: =IF($D36="","",ROUND(SUM($H$11:H36),2)) | P36: =IF($N36="","",IF(COUNTIF(数据录入!$K$5:$K$4999,$N36)=0,N($X36),ROUND(MIN(MAX(0,N($Z36)-(N($Y36)-N($O36))),N($O36)),2))) | Q36: =IF($N36="","",ROUND(N($O36)-N($P36),2)) | R36: =IF($N36="","",ROUND(SUM($Q$11:Q36),2)) | U36: =IF($D36="","",ROUND(N($F36)-N($J36),2)) | V36: =IF($D36="","",ROUND(SUMIFS($F$11:F36,$D$11:D36,$D36)-SUMIFS($J$11:J36,$D$11:D36,$D36),2)) | W36: =IF($D36="","",ROUND(SUMIFS(数据录入!$F$5:$F$4999,数据录入!$J$5:$J$4999,$D36),2)) | Y36: =IF($N36="","",ROUND(SUMIFS($O$11:O36,$N$11:N36,$N36),2)) | Z36: =IF($N36="","",ROUND(SUMIFS(数据录入!$G$5:$G$4999,数据录入!$K$5:$K$4999,$N36),2)) | AA36: =IF(AND($D36="",$N36=""),"",IF(AND($D36<>"",COUNTIF(基础资料!$E:$E,$D36)=0),"客户名不在基础资料里",IF(AND($E36<>"",COUNTIF(基础资料!$B:$B,$E36)=0),"产品名不在基础资料里",IF(AND($N36<>"",COUNTIF(基础资料!$G:$G,$N36)=0),"供货商不在基础资料里",IF(AND($C36<>"",ISNUMBER($C36),$C36<10000),"客户生日填得不对（不是日期）",IF(N($J36)>N($F36),"销售费用大于销售金额",IF(AND($D36<>"",COUNTIF(数据录入!$J$5:$J$4999,$D36)=0,N($T36)<>0),"用的还是原手工已收款",IF(AND($D36<>"",COUNTIF(数据录入!$J$5:$J$4999,$D36)>0,ROUND(N($G36)-N($T36),2)<>0,N($T36)<>0),"自动算的已收款和原手工数对不上","√"))))))))
A37: =IF(AND($D37="",$N37=""),"",MAX($A$10:A36)+1) | C37: 46338 | D37: 姜志鸿 | G37: =IF($D37="","",IF(COUNTIF(数据录入!$J$5:$J$4999,$D37)=0,N($T37),ROUND(MIN(MAX(0,N($W37)-(N($V37)-N($U37))),N($U37)),2))) | H37: =IF($D37="","",ROUND(N($F37)-N($G37)-N($J37),2)) | I37: =IF($D37="","",ROUND(SUM($H$11:H37),2)) | P37: =IF($N37="","",IF(COUNTIF(数据录入!$K$5:$K$4999,$N37)=0,N($X37),ROUND(MIN(MAX(0,N($Z37)-(N($Y37)-N($O37))),N($O37)),2))) | Q37: =IF($N37="","",ROUND(N($O37)-N($P37),2)) | R37: =IF($N37="","",ROUND(SUM($Q$11:Q37),2)) | U37: =IF($D37="","",ROUND(N($F37)-N($J37),2)) | V37: =IF($D37="","",ROUND(SUMIFS($F$11:F37,$D$11:D37,$D37)-SUMIFS($J$11:J37,$D$11:D37,$D37),2)) | W37: =IF($D37="","",ROUND(SUMIFS(数据录入!$F$5:$F$4999,数据录入!$J$5:$J$4999,$D37),2)) | Y37: =IF($N37="","",ROUND(SUMIFS($O$11:O37,$N$11:N37,$N37),2)) | Z37: =IF($N37="","",ROUND(SUMIFS(数据录入!$G$5:$G$4999,数据录入!$K$5:$K$4999,$N37),2)) | AA37: =IF(AND($D37="",$N37=""),"",IF(AND($D37<>"",COUNTIF(基础资料!$E:$E,$D37)=0),"客户名不在基础资料里",IF(AND($E37<>"",COUNTIF(基础资料!$B:$B,$E37)=0),"产品名不在基础资料里",IF(AND($N37<>"",COUNTIF(基础资料!$G:$G,$N37)=0),"供货商不在基础资料里",IF(AND($C37<>"",ISNUMBER($C37),$C37<10000),"客户生日填得不对（不是日期）",IF(N($J37)>N($F37),"销售费用大于销售金额",IF(AND($D37<>"",COUNTIF(数据录入!$J$5:$J$4999,$D37)=0,N($T37)<>0),"用的还是原手工已收款",IF(AND($D37<>"",COUNTIF(数据录入!$J$5:$J$4999,$D37)>0,ROUND(N($G37)-N($T37),2)<>0,N($T37)<>0),"自动算的已收款和原手工数对不上","√"))))))))
A38: =IF(AND($D38="",$N38=""),"",MAX($A$10:A37)+1) | C38: 46338 | D38: 吴旭红 | G38: =IF($D38="","",IF(COUNTIF(数据录入!$J$5:$J$4999,$D38)=0,N($T38),ROUND(MIN(MAX(0,N($W38)-(N($V38)-N($U38))),N($U38)),2))) | H38: =IF($D38="","",ROUND(N($F38)-N($G38)-N($J38),2)) | I38: =IF($D38="","",ROUND(SUM($H$11:H38),2)) | P38: =IF($N38="","",IF(COUNTIF(数据录入!$K$5:$K$4999,$N38)=0,N($X38),ROUND(MIN(MAX(0,N($Z38)-(N($Y38)-N($O38))),N($O38)),2))) | Q38: =IF($N38="","",ROUND(N($O38)-N($P38),2)) | R38: =IF($N38="","",ROUND(SUM($Q$11:Q38),2)) | U38: =IF($D38="","",ROUND(N($F38)-N($J38),2)) | V38: =IF($D38="","",ROUND(SUMIFS($F$11:F38,$D$11:D38,$D38)-SUMIFS($J$11:J38,$D$11:D38,$D38),2)) | W38: =IF($D38="","",ROUND(SUMIFS(数据录入!$F$5:$F$4999,数据录入!$J$5:$J$4999,$D38),2)) | Y38: =IF($N38="","",ROUND(SUMIFS($O$11:O38,$N$11:N38,$N38),2)) | Z38: =IF($N38="","",ROUND(SUMIFS(数据录入!$G$5:$G$4999,数据录入!$K$5:$K$4999,$N38),2)) | AA38: =IF(AND($D38="",$N38=""),"",IF(AND($D38<>"",COUNTIF(基础资料!$E:$E,$D38)=0),"客户名不在基础资料里",IF(AND($E38<>"",COUNTIF(基础资料!$B:$B,$E38)=0),"产品名不在基础资料里",IF(AND($N38<>"",COUNTIF(基础资料!$G:$G,$N38)=0),"供货商不在基础资料里",IF(AND($C38<>"",ISNUMBER($C38),$C38<10000),"客户生日填得不对（不是日期）",IF(N($J38)>N($F38),"销售费用大于销售金额",IF(AND($D38<>"",COUNTIF(数据录入!$J$5:$J$4999,$D38)=0,N($T38)<>0),"用的还是原手工已收款",IF(AND($D38<>"",COUNTIF(数据录入!$J$5:$J$4999,$D38)>0,ROUND(N($G38)-N($T38),2)<>0,N($T38)<>0),"自动算的已收款和原手工数对不上","√"))))))))
A39: =IF(AND($D39="",$N39=""),"",MAX($A$10:A38)+1) | C39: 46342 | D39: 丁爱妹 | G39: =IF($D39="","",IF(COUNTIF(数据录入!$J$5:$J$4999,$D39)=0,N($T39),ROUND(MIN(MAX(0,N($W39)-(N($V39)-N($U39))),N($U39)),2))) | H39: =IF($D39="","",ROUND(N($F39)-N($G39)-N($J39),2)) | I39: =IF($D39="","",ROUND(SUM($H$11:H39),2)) | P39: =IF($N39="","",IF(COUNTIF(数据录入!$K$5:$K$4999,$N39)=0,N($X39),ROUND(MIN(MAX(0,N($Z39)-(N($Y39)-N($O39))),N($O39)),2))) | Q39: =IF($N39="","",ROUND(N($O39)-N($P39),2)) | R39: =IF($N39="","",ROUND(SUM($Q$11:Q39),2)) | U39: =IF($D39="","",ROUND(N($F39)-N($J39),2)) | V39: =IF($D39="","",ROUND(SUMIFS($F$11:F39,$D$11:D39,$D39)-SUMIFS($J$11:J39,$D$11:D39,$D39),2)) | W39: =IF($D39="","",ROUND(SUMIFS(数据录入!$F$5:$F$4999,数据录入!$J$5:$J$4999,$D39),2)) | Y39: =IF($N39="","",ROUND(SUMIFS($O$11:O39,$N$11:N39,$N39),2)) | Z39: =IF($N39="","",ROUND(SUMIFS(数据录入!$G$5:$G$4999,数据录入!$K$5:$K$4999,$N39),2)) | AA39: =IF(AND($D39="",$N39=""),"",IF(AND($D39<>"",COUNTIF(基础资料!$E:$E,$D39)=0),"客户名不在基础资料里",IF(AND($E39<>"",COUNTIF(基础资料!$B:$B,$E39)=0),"产品名不在基础资料里",IF(AND($N39<>"",COUNTIF(基础资料!$G:$G,$N39)=0),"供货商不在基础资料里",IF(AND($C39<>"",ISNUMBER($C39),$C39<10000),"客户生日填得不对（不是日期）",IF(N($J39)>N($F39),"销售费用大于销售金额",IF(AND($D39<>"",COUNTIF(数据录入!$J$5:$J$4999,$D39)=0,N($T39)<>0),"用的还是原手工已收款",IF(AND($D39<>"",COUNTIF(数据录入!$J$5:$J$4999,$D39)>0,ROUND(N($G39)-N($T39),2)<>0,N($T39)<>0),"自动算的已收款和原手工数对不上","√"))))))))
A40: =IF(AND($D40="",$N40=""),"",MAX($A$10:A39)+1) | C40: 46351 | D40: 鄢桂香 | G40: =IF($D40="","",IF(COUNTIF(数据录入!$J$5:$J$4999,$D40)=0,N($T40),ROUND(MIN(MAX(0,N($W40)-(N($V40)-N($U40))),N($U40)),2))) | H40: =IF($D40="","",ROUND(N($F40)-N($G40)-N($J40),2)) | I40: =IF($D40="","",ROUND(SUM($H$11:H40),2)) | P40: =IF($N40="","",IF(COUNTIF(数据录入!$K$5:$K$4999,$N40)=0,N($X40),ROUND(MIN(MAX(0,N($Z40)-(N($Y40)-N($O40))),N($O40)),2))) | Q40: =IF($N40="","",ROUND(N($O40)-N($P40),2)) | R40: =IF($N40="","",ROUND(SUM($Q$11:Q40),2)) | U40: =IF($D40="","",ROUND(N($F40)-N($J40),2)) | V40: =IF($D40="","",ROUND(SUMIFS($F$11:F40,$D$11:D40,$D40)-SUMIFS($J$11:J40,$D$11:D40,$D40),2)) | W40: =IF($D40="","",ROUND(SUMIFS(数据录入!$F$5:$F$4999,数据录入!$J$5:$J$4999,$D40),2)) | Y40: =IF($N40="","",ROUND(SUMIFS($O$11:O40,$N$11:N40,$N40),2)) | Z40: =IF($N40="","",ROUND(SUMIFS(数据录入!$G$5:$G$4999,数据录入!$K$5:$K$4999,$N40),2)) | AA40: =IF(AND($D40="",$N40=""),"",IF(AND($D40<>"",COUNTIF(基础资料!$E:$E,$D40)=0),"客户名不在基础资料里",IF(AND($E40<>"",COUNTIF(基础资料!$B:$B,$E40)=0),"产品名不在基础资料里",IF(AND($N40<>"",COUNTIF(基础资料!$G:$G,$N40)=0),"供货商不在基础资料里",IF(AND($C40<>"",ISNUMBER($C40),$C40<10000),"客户生日填得不对（不是日期）",IF(N($J40)>N($F40),"销售费用大于销售金额",IF(AND($D40<>"",COUNTIF(数据录入!$J$5:$J$4999,$D40)=0,N($T40)<>0),"用的还是原手工已收款",IF(AND($D40<>"",COUNTIF(数据录入!$J$5:$J$4999,$D40)>0,ROUND(N($G40)-N($T40),2)<>0,N($T40)<>0),"自动算的已收款和原手工数对不上","√"))))))))
A41: =IF(AND($D41="",$N41=""),"",MAX($A$10:A40)+1) | C41: 46353 | D41: 傅荣姣 | G41: =IF($D41="","",IF(COUNTIF(数据录入!$J$5:$J$4999,$D41)=0,N($T41),ROUND(MIN(MAX(0,N($W41)-(N($V41)-N($U41))),N($U41)),2))) | H41: =IF($D41="","",ROUND(N($F41)-N($G41)-N($J41),2)) | I41: =IF($D41="","",ROUND(SUM($H$11:H41),2)) | P41: =IF($N41="","",IF(COUNTIF(数据录入!$K$5:$K$4999,$N41)=0,N($X41),ROUND(MIN(MAX(0,N($Z41)-(N($Y41)-N($O41))),N($O41)),2))) | Q41: =IF($N41="","",ROUND(N($O41)-N($P41),2)) | R41: =IF($N41="","",ROUND(SUM($Q$11:Q41),2)) | U41: =IF($D41="","",ROUND(N($F41)-N($J41),2)) | V41: =IF($D41="","",ROUND(SUMIFS($F$11:F41,$D$11:D41,$D41)-SUMIFS($J$11:J41,$D$11:D41,$D41),2)) | W41: =IF($D41="","",ROUND(SUMIFS(数据录入!$F$5:$F$4999,数据录入!$J$5:$J$4999,$D41),2)) | Y41: =IF($N41="","",ROUND(SUMIFS($O$11:O41,$N$11:N41,$N41),2)) | Z41: =IF($N41="","",ROUND(SUMIFS(数据录入!$G$5:$G$4999,数据录入!$K$5:$K$4999,$N41),2)) | AA41: =IF(AND($D41="",$N41=""),"",IF(AND($D41<>"",COUNTIF(基础资料!$E:$E,$D41)=0),"客户名不在基础资料里",IF(AND($E41<>"",COUNTIF(基础资料!$B:$B,$E41)=0),"产品名不在基础资料里",IF(AND($N41<>"",COUNTIF(基础资料!$G:$G,$N41)=0),"供货商不在基础资料里",IF(AND($C41<>"",ISNUMBER($C41),$C41<10000),"客户生日填得不对（不是日期）",IF(N($J41)>N($F41),"销售费用大于销售金额",IF(AND($D41<>"",COUNTIF(数据录入!$J$5:$J$4999,$D41)=0,N($T41)<>0),"用的还是原手工已收款",IF(AND($D41<>"",COUNTIF(数据录入!$J$5:$J$4999,$D41)>0,ROUND(N($G41)-N($T41),2)<>0,N($T41)<>0),"自动算的已收款和原手工数对不上","√"))))))))
A42: =IF(AND($D42="",$N42=""),"",MAX($A$10:A41)+1) | C42: 46354 | D42: 陆玉英 | G42: =IF($D42="","",IF(COUNTIF(数据录入!$J$5:$J$4999,$D42)=0,N($T42),ROUND(MIN(MAX(0,N($W42)-(N($V42)-N($U42))),N($U42)),2))) | H42: =IF($D42="","",ROUND(N($F42)-N($G42)-N($J42),2)) | I42: =IF($D42="","",ROUND(SUM($H$11:H42),2)) | P42: =IF($N42="","",IF(COUNTIF(数据录入!$K$5:$K$4999,$N42)=0,N($X42),ROUND(MIN(MAX(0,N($Z42)-(N($Y42)-N($O42))),N($O42)),2))) | Q42: =IF($N42="","",ROUND(N($O42)-N($P42),2)) | R42: =IF($N42="","",ROUND(SUM($Q$11:Q42),2)) | U42: =IF($D42="","",ROUND(N($F42)-N($J42),2)) | V42: =IF($D42="","",ROUND(SUMIFS($F$11:F42,$D$11:D42,$D42)-SUMIFS($J$11:J42,$D$11:D42,$D42),2)) | W42: =IF($D42="","",ROUND(SUMIFS(数据录入!$F$5:$F$4999,数据录入!$J$5:$J$4999,$D42),2)) | Y42: =IF($N42="","",ROUND(SUMIFS($O$11:O42,$N$11:N42,$N42),2)) | Z42: =IF($N42="","",ROUND(SUMIFS(数据录入!$G$5:$G$4999,数据录入!$K$5:$K$4999,$N42),2)) | AA42: =IF(AND($D42="",$N42=""),"",IF(AND($D42<>"",COUNTIF(基础资料!$E:$E,$D42)=0),"客户名不在基础资料里",IF(AND($E42<>"",COUNTIF(基础资料!$B:$B,$E42)=0),"产品名不在基础资料里",IF(AND($N42<>"",COUNTIF(基础资料!$G:$G,$N42)=0),"供货商不在基础资料里",IF(AND($C42<>"",ISNUMBER($C42),$C42<10000),"客户生日填得不对（不是日期）",IF(N($J42)>N($F42),"销售费用大于销售金额",IF(AND($D42<>"",COUNTIF(数据录入!$J$5:$J$4999,$D42)=0,N($T42)<>0),"用的还是原手工已收款",IF(AND($D42<>"",COUNTIF(数据录入!$J$5:$J$4999,$D42)>0,ROUND(N($G42)-N($T42),2)<>0,N($T42)<>0),"自动算的已收款和原手工数对不上","√"))))))))
A43: =IF(AND($D43="",$N43=""),"",MAX($A$10:A42)+1) | C43: 46361 | D43: 祝晓琳 | G43: =IF($D43="","",IF(COUNTIF(数据录入!$J$5:$J$4999,$D43)=0,N($T43),ROUND(MIN(MAX(0,N($W43)-(N($V43)-N($U43))),N($U43)),2))) | H43: =IF($D43="","",ROUND(N($F43)-N($G43)-N($J43),2)) | I43: =IF($D43="","",ROUND(SUM($H$11:H43),2)) | P43: =IF($N43="","",IF(COUNTIF(数据录入!$K$5:$K$4999,$N43)=0,N($X43),ROUND(MIN(MAX(0,N($Z43)-(N($Y43)-N($O43))),N($O43)),2))) | Q43: =IF($N43="","",ROUND(N($O43)-N($P43),2)) | R43: =IF($N43="","",ROUND(SUM($Q$11:Q43),2)) | U43: =IF($D43="","",ROUND(N($F43)-N($J43),2)) | V43: =IF($D43="","",ROUND(SUMIFS($F$11:F43,$D$11:D43,$D43)-SUMIFS($J$11:J43,$D$11:D43,$D43),2)) | W43: =IF($D43="","",ROUND(SUMIFS(数据录入!$F$5:$F$4999,数据录入!$J$5:$J$4999,$D43),2)) | Y43: =IF($N43="","",ROUND(SUMIFS($O$11:O43,$N$11:N43,$N43),2)) | Z43: =IF($N43="","",ROUND(SUMIFS(数据录入!$G$5:$G$4999,数据录入!$K$5:$K$4999,$N43),2)) | AA43: =IF(AND($D43="",$N43=""),"",IF(AND($D43<>"",COUNTIF(基础资料!$E:$E,$D43)=0),"客户名不在基础资料里",IF(AND($E43<>"",COUNTIF(基础资料!$B:$B,$E43)=0),"产品名不在基础资料里",IF(AND($N43<>"",COUNTIF(基础资料!$G:$G,$N43)=0),"供货商不在基础资料里",IF(AND($C43<>"",ISNUMBER($C43),$C43<10000),"客户生日填得不对（不是日期）",IF(N($J43)>N($F43),"销售费用大于销售金额",IF(AND($D43<>"",COUNTIF(数据录入!$J$5:$J$4999,$D43)=0,N($T43)<>0),"用的还是原手工已收款",IF(AND($D43<>"",COUNTIF(数据录入!$J$5:$J$4999,$D43)>0,ROUND(N($G43)-N($T43),2)<>0,N($T43)<>0),"自动算的已收款和原手工数对不上","√"))))))))
...

Sheet 客户供应商往来对账
A1: 客户 · 供货商 往来对账表
A2: ★ 全自动，不用填。左半边「该收/该付」来自【往来款跟进】，右半边「实收/实付」来自【数据录入】。 差额 ≠ 0，说明两张表没对上：要么【数据录入】那笔回款没选客户名，要么【往来款跟进】的已收款还是原来的手工数。 客户和供货商名单直接跟着【基础资料】走，你在基础资料里加一个客户，这里自动多一行。
A4: 一、按客户：应收款对账
A5: 序号 | B5: 客户 | C5: 销售金额 | D5: 销售费用 (赠送券) | E5: 应收款 | F5: 已收款 (往来款跟进) | G5: 已收款 (数据录入) | H5: 尚欠款 | I5: 差额 | J5: 提 示
A6: =IF($B6="","",MAX($A$5:A5)+1) | B6: =IF(基础资料!$E2="","",基础资料!$E2) | C6: =IF($B6="","",ROUND(SUMIFS('往来款跟进'!$F$11:$F$510,'往来款跟进'!$D$11:$D$510,$B6),2)) | D6: =IF($B6="","",ROUND(SUMIFS('往来款跟进'!$J$11:$J$510,'往来款跟进'!$D$11:$D$510,$B6),2)) | E6: =IF($B6="","",ROUND(N($C6)-N($D6),2)) | F6: =IF($B6="","",ROUND(SUMIFS('往来款跟进'!$G$11:$G$510,'往来款跟进'!$D$11:$D$510,$B6),2)) | G6: =IF($B6="","",ROUND(SUMIFS(数据录入!$F$5:$F$4999,数据录入!$J$5:$J$4999,$B6),2)) | H6: =IF($B6="","",ROUND(N($E6)-N($F6),2)) | I6: =IF($B6="","",ROUND(N($F6)-N($G6),2)) | J6: =IF($B6="","",IF(AND(N($E6)=0,N($G6)=0),"没有往来",IF(ROUND(N($I6),2)<>0,"差 "&TEXT(N($I6),"0.00")&" 元：【数据录入】里这个客户的回款还没记全，或者没选客户名",IF(N($H6)>0,"还欠 "&TEXT(N($H6),"0.00")&" 元","已结清"))))
A7: =IF($B7="","",MAX($A$5:A6)+1) | B7: =IF(基础资料!$E3="","",基础资料!$E3) | C7: =IF($B7="","",ROUND(SUMIFS('往来款跟进'!$F$11:$F$510,'往来款跟进'!$D$11:$D$510,$B7),2)) | D7: =IF($B7="","",ROUND(SUMIFS('往来款跟进'!$J$11:$J$510,'往来款跟进'!$D$11:$D$510,$B7),2)) | E7: =IF($B7="","",ROUND(N($C7)-N($D7),2)) | F7: =IF($B7="","",ROUND(SUMIFS('往来款跟进'!$G$11:$G$510,'往来款跟进'!$D$11:$D$510,$B7),2)) | G7: =IF($B7="","",ROUND(SUMIFS(数据录入!$F$5:$F$4999,数据录入!$J$5:$J$4999,$B7),2)) | H7: =IF($B7="","",ROUND(N($E7)-N($F7),2)) | I7: =IF($B7="","",ROUND(N($F7)-N($G7),2)) | J7: =IF($B7="","",IF(AND(N($E7)=0,N($G7)=0),"没有往来",IF(ROUND(N($I7),2)<>0,"差 "&TEXT(N($I7),"0.00")&" 元：【数据录入】里这个客户的回款还没记全，或者没选客户名",IF(N($H7)>0,"还欠 "&TEXT(N($H7),"0.00")&" 元","已结清"))))
A8: =IF($B8="","",MAX($A$5:A7)+1) | B8: =IF(基础资料!$E4="","",基础资料!$E4) | C8: =IF($B8="","",ROUND(SUMIFS('往来款跟进'!$F$11:$F$510,'往来款跟进'!$D$11:$D$510,$B8),2)) | D8: =IF($B8="","",ROUND(SUMIFS('往来款跟进'!$J$11:$J$510,'往来款跟进'!$D$11:$D$510,$B8),2)) | E8: =IF($B8="","",ROUND(N($C8)-N($D8),2)) | F8: =IF($B8="","",ROUND(SUMIFS('往来款跟进'!$G$11:$G$510,'往来款跟进'!$D$11:$D$510,$B8),2)) | G8: =IF($B8="","",ROUND(SUMIFS(数据录入!$F$5:$F$4999,数据录入!$J$5:$J$4999,$B8),2)) | H8: =IF($B8="","",ROUND(N($E8)-N($F8),2)) | I8: =IF($B8="","",ROUND(N($F8)-N($G8),2)) | J8: =IF($B8="","",IF(AND(N($E8)=0,N($G8)=0),"没有往来",IF(ROUND(N($I8),2)<>0,"差 "&TEXT(N($I8),"0.00")&" 元：【数据录入】里这个客户的回款还没记全，或者没选客户名",IF(N($H8)>0,"还欠 "&TEXT(N($H8),"0.00")&" 元","已结清"))))
A9: =IF($B9="","",MAX($A$5:A8)+1) | B9: =IF(基础资料!$E5="","",基础资料!$E5) | C9: =IF($B9="","",ROUND(SUMIFS('往来款跟进'!$F$11:$F$510,'往来款跟进'!$D$11:$D$510,$B9),2)) | D9: =IF($B9="","",ROUND(SUMIFS('往来款跟进'!$J$11:$J$510,'往来款跟进'!$D$11:$D$510,$B9),2)) | E9: =IF($B9="","",ROUND(N($C9)-N($D9),2)) | F9: =IF($B9="","",ROUND(SUMIFS('往来款跟进'!$G$11:$G$510,'往来款跟进'!$D$11:$D$510,$B9),2)) | G9: =IF($B9="","",ROUND(SUMIFS(数据录入!$F$5:$F$4999,数据录入!$J$5:$J$4999,$B9),2)) | H9: =IF($B9="","",ROUND(N($E9)-N($F9),2)) | I9: =IF($B9="","",ROUND(N($F9)-N($G9),2)) | J9: =IF($B9="","",IF(AND(N($E9)=0,N($G9)=0),"没有往来",IF(ROUND(N($I9),2)<>0,"差 "&TEXT(N($I9),"0.00")&" 元：【数据录入】里这个客户的回款还没记全，或者没选客户名",IF(N($H9)>0,"还欠 "&TEXT(N($H9),"0.00")&" 元","已结清"))))
