Workbook

Sheet 使用说明
A1: 更多财务实操模板，可自行搜索抖音/视频号：老财务的实操笔记
A3: 【老财务实操自用｜初级版财务台账模板】
A4: 作者：老财务的实操笔记
A5: ——————————————————————————
A6: 适用对象：小微企业、个体工商户、小规模纳税人、商贸服务类等
A7: 版本说明
A8: 本套为**通用基础初级版**，满足税务管理、费用报销、收支登记、票据管理等
A9: 可根据行业属性、业务规模、升级定制版。
A11: 模板清单，持续更新
A12: 1、应收账款风险预警表
A13: 2、日常经营情况汇总表
A14: 3、进项台帐自动查重表
... A47: 老财务自用模板｜禁止外传、倒卖、商用

Sheet 基础资料
A1: 账户 | B1: 产品 | C1: 支出类别 | E1: 客户 | G1: 供应商
A2: 现金 | B2: 红曲 | C2: 供应商 | E2: 丁爱妹 | G2: 羊奶供货商
A3: 微信 | B3: 胚脑 | E3: 方建宏 | G3: 乳铁供货商
A4: 支付宝 | B4: 胚优 | C4: 办公费 | E4: 傅荣姣
A5: 杭州 | B5: 乳铁 | C5: 水费 | E5: 郭志伟
A6: 农商 | B6: 羊奶 | C6: 电费 | E6: 过承祁
A7: 备用 | B7: 益生菌 | C7: 伙食费 | E7: 洪宗邦
A8: 备用1 | C8: 工资 | E8: 姜蓉兰
A9: 备用2 | C9: 租赁费 | E9: 姜志鸿
A10: 备用3 | C10: 差旅费 | E10: 李小琴
A11: 备用4 | C11: 业务招待费 | E11: 李晓春
A12: 备用5 | C12: 车辆费用 | E12: 李玉娟
A13: 备用6 | C13: 银行手续费 | E13: 林永来
A14: 备用7 | E14: 陆玉英
A15: 备用8 | E15: 罗理华
E16: 马珍珠
E17: 邵国新
E18: 沈祖模
E19: 唐鑫红
E20: 童炳寿
E21: 王秀娟
E22: 邬香花
E23: 吴亮
E24: 吴旭红
E25: 吴兆香
E26: 谢爱琴
E27: 徐德彪
... E38: 杨建云

Sheet 数据录入
A1: 多帐户收支登记表
F2: 收入总额 | G2: 支出总额 | H2: 账户余额
F3: =SUBTOTAL(109,$F$4:$F$9999) -> 22200 | G3: =SUBTOTAL(109,$G$4:$G$9999) -> 11660 | H3: =SUBTOTAL(109,$H$5:$H$18)+F3-G3 -> 10540
A4: 序号 | B4: 日期 | C4: 公司账户 | D4: 支出类别 | E4: 摘要内容 | F4: 收入 | G4: 支出 | H4: 账户余额 | I4: 产品 | J4: 客户 | K4: 供应商 | L4: 客户生日 | M4: 月份
A5: =IF(B5="","",COUNTA($B$5:B5)) -> 1 | B5: 46266 | C5: 现金 | E5: 期初余额 | H5: 0 | M5: =IF($B5="","",--TEXT($B5,"yyyymm")) -> 202609
A6: =IF(B6="","",COUNTA($B$5:B6)) -> 2 | B6: 46266 | C6: 微信 | E6: 期初余额 | H6: 0 | M6: =IF($B6="","",--TEXT($B6,"yyyymm")) -> 202609
A7: =IF(B7="","",COUNTA($B$5:B7)) -> 3 | B7: 46266 | C7: 支付宝 | E7: 期初余额 | H7: 0 | M7: =IF($B7="","",--TEXT($B7,"yyyymm")) -> 202609
A8: =IF(B8="","",COUNTA($B$5:B8)) -> 4 | B8: 46266 | C8: 杭州 | E8: 期初余额 | H8: 0 | M8: =IF($B8="","",--TEXT($B8,"yyyymm")) -> 202609
A9: =IF(B9="","",COUNTA($B$5:B9)) -> 5 | B9: 46266 | C9: 农商 | E9: 期初余额 | H9: 0 | M9: =IF($B9="","",--TEXT($B9,"yyyymm")) -> 202609
A10: =IF(B10="","",COUNTA($B$5:B10)) -> 6 | B10: 46266 | C10: 备用 | E10: 期初余额 | H10: 0 | M10: =IF($B10="","",--TEXT($B10,"yyyymm")) -> 202609
A11: =IF(B11="","",COUNTA($B$5:B11)) -> 7 | B11: 46266 | C11: 备用1 | E11: 期初余额 | H11: 0 | M11: =IF($B11="","",--TEXT($B11,"yyyymm")) -> 202609
A12: =IF(B12="","",COUNTA($B$5:B12)) -> 8 | B12: 46266 | C12: 备用2 | E12: 期初余额 | H12: 0 | M12: =IF($B12="","",--TEXT($B12,"yyyymm")) -> 202609
A13: =IF(B13="","",COUNTA($B$5:B13)) -> 9 | B13: 46266 | C13: 备用3 | E13: 期初余额 | H13: 0 | M13: =IF($B13="","",--TEXT($B13,"yyyymm")) -> 202609
A14: =IF(B14="","",COUNTA($B$5:B14)) -> 10 | B14: 46266 | C14: 备用4 | E14: 期初余额 | H14: 0 | M14: =IF($B14="","",--TEXT($B14,"yyyymm")) -> 202609
A15: =IF(B15="","",COUNTA($B$5:B15)) -> 11 | B15: 46266 | C15: 备用5 | E15: 期初余额 | H15: 0 | M15: =IF($B15="","",--TEXT($B15,"yyyymm")) -> 202609
A16: =IF(B16="","",COUNTA($B$5:B16)) -> 12 | B16: 46266 | C16: 备用6 | E16: 期初余额 | H16: 0 | M16: =IF($B16="","",--TEXT($B16,"yyyymm")) -> 202609
... A18: =IF(B18="","",COUNTA($B$5:B18)) -> 14 | B18: 46266 | C18: 备用8 | E18: 期初余额 | H18: 0 | M18: =IF($B18="","",--TEXT($B18,"yyyymm")) -> 202609
A19: =IF(B19="","",COUNTA($B$5:B19)) -> 15 | B19: 46266 | C19: 现金 | F19: 2000 | H19: =IFERROR(VLOOKUP($C19,$C$5:$H$18,6,0)+SUMIF($C$19:$C19,$C19,$F$19:$F19)-SUMIF($C$19:$C19,$C19,$G$19:$G19),"") -> 2000 | I19: 红曲 | J19: 丁爱妹 | M19: =IF($B19="","",--TEXT($B19,"yyyymm")) -> 202609
A20: =IF(B20="","",COUNTA($B$5:B20)) -> 16 | B20: 46266 | C20: 微信 | D20: 办公费 | G20: 200 | H20: =IFERROR(VLOOKUP($C20,$C$5:$H$18,6,0)+SUMIF($C$19:$C20,$C20,$F$19:$F20)-SUMIF($C$19:$C20,$C20,$G$19:$G20),"") -> -200 | M20: =IF($B20="","",--TEXT($B20,"yyyymm")) -> 202609
A21: =IF(B21="","",COUNTA($B$5:B21)) -> 17 | B21: 46266 | C21: 支付宝 | D21: 电费 | G21: 300 | H21: =IFERROR(VLOOKUP($C21,$C$5:$H$18,6,0)+SUMIF($C$19:$C21,$C21,$F$19:$F21)-SUMIF($C$19:$C21,$C21,$G$19:$G21),"") -> -300 | M21: =IF($B21="","",--TEXT($B21,"yyyymm")) -> 202609
A22: =IF(B22="","",COUNTA($B$5:B22)) -> 18 | B22: 46266 | C22: 杭州 | D22: 差旅费 | G22: 500 | H22: =IFERROR(VLOOKUP($C22,$C$5:$H$18,6,0)+SUMIF($C$19:$C22,$C22,$F$19:$F22)-SUMIF($C$19:$C22,$C22,$G$19:$G22),"") -> -500 | M22: =IF($B22="","",--TEXT($B22,"yyyymm")) -> 202609
A23: =IF(B23="","",COUNTA($B$5:B23)) -> 19 | B23: 46266 | C23: 农商 | F23: 2600 | H23: =IFERROR(VLOOKUP($C23,$C$5:$H$18,6,0)+SUMIF($C$19:$C23,$C23,$F$19:$F23)-SUMIF($C$19:$C23,$C23,$G$19:$G23),"") -> 2600 | M23: =IF($B23="","",--TEXT($B23,"yyyymm")) -> 202609
A24: =IF(B24="","",COUNTA($B$5:B24)) -> 20 | B24: 46266 | C24: 备用 | D24: 供应商 | G24: 5000 | H24: =IFERROR(VLOOKUP($C24,$C$5:$H$18,6,0)+SUMIF($C$19:$C24,$C24,$F$19:$F24)-SUMIF($C$19:$C24,$C24,$G$19:$G24),"") -> -5000 | K24: 羊奶供货商 | M24: =IF($B24="","",--TEXT($B24,"yyyymm")) -> 202609
A25: =IF(B25="","",COUNTA($B$5:B25)) -> 21 | B25: 46266 | C25: 备用1 | D25: 伙食费 | G25: 200 | H25: =IFERROR(VLOOKUP($C25,$C$5:$H$18,6,0)+SUMIF($C$19:$C25,$C25,$F$19:$F25)-SUMIF($C$19:$C25,$C25,$G$19:$G25),"") -> -200 | M25: =IF($B25="","",--TEXT($B25,"yyyymm")) -> 202609
A26: =IF(B26="","",COUNTA($B$5:B26)) -> 22 | B26: 46266 | C26: 备用2 | D26: 办公费 | G26: 10 | H26: =IFERROR(VLOOKUP($C26,$C$5:$H$18,6,0)+SUMIF($C$19:$C26,$C26,$F$19:$F26)-SUMIF($C$19:$C26,$C26,$G$19:$G26),"") -> -10 | M26: =IF($B26="","",--TEXT($B26,"yyyymm")) -> 202609
A27: =IF(B27="","",COUNTA($B$5:B27)) -> 23 | B27: 46266 | C27: 备用3 | D27: 车辆费用 | G27: 50 | H27: =IFERROR(VLOOKUP($C27,$C$5:$H$18,6,0)+SUMIF($C$19:$C27,$C27,$F$19:$F27)-SUMIF($C$19:$C27,$C27,$G$19:$G27),"") -> -50 | M27: =IF($B27="","",--TEXT($B27,"yyyymm")) -> 202609
A28: =IF(B28="","",COUNTA($B$5:B28)) -> 24 | B28: 46266 | C28: 备用4 | F28: 2100 | H28: =IFERROR(VLOOKUP($C28,$C$5:$H$18,6,0)+SUMIF($C$19:$C28,$C28,$F$19:$F28)-SUMIF($C$19:$C28,$C28,$G$19:$G28),"") -> 2100 | M28: =IF($B28="","",--TEXT($B28,"yyyymm")) -> 202609
A29: =IF(B29="","",COUNTA($B$5:B29)) -> 25 | B29: 46266 | C29: 备用5 | D29: 租赁费 | G29: 2000 | H29: =IFERROR(VLOOKUP($C29,$C$5:$H$18,6,0)+SUMIF($C$19:$C29,$C29,$F$19:$F29)-SUMIF($C$19:$C29,$C29,$G$19:$G29),"") -> -2000 | M29: =IF($B29="","",--TEXT($B29,"yyyymm")) -> 202609
A30: =IF(B30="","",COUNTA($B$5:B30)) -> 26 | B30: 46266 | C30: 备用6 | D30: 伙食费 | G30: 200 | H30: =IFERROR(VLOOKUP($C30,$C$5:$H$18,6,0)+SUMIF($C$19:$C30,$C30,$F$19:$F30)-SUMIF($C$19:$C30,$C30,$G$19:$G30),"") -> -200 | M30: =IF($B30="","",--TEXT($B30,"yyyymm")) -> 202609
A31: =IF(B31="","",COUNTA($B$5:B31)) -> 27 | B31: 46266 | C31: 备用7 | D31: 差旅费 | G31: 500 | H31: =IFERROR(VLOOKUP($C31,$C$5:$H$18,6,0)+SUMIF($C$19:$C31,$C31,$F$19:$F31)-SUMIF($C$19:$C31,$C31,$G$19:$G31),"") -> -500 | M31: =IF($B31="","",--TEXT($B31,"yyyymm")) -> 202609
A32: =IF(B32="","",COUNTA($B$5:B32)) -> 28 | B32: 46266 | C32: 备用8 | D32: 供应商 | G32: 1000 | H32: =IFERROR(VLOOKUP($C32,$C$5:$H$18,6,0)+SUMIF($C$19:$C32,$C32,$F$19:$F32)-SUMIF($C$19:$C32,$C32,$G$19:$G32),"") -> -1000 | M32: =IF($B32="","",--TEXT($B32,"yyyymm")) -> 202609
A33: =IF(B33="","",COUNTA($B$5:B33)) -> 29 | B33: 46266 | C33: 现金 | D33: 业务招待费 | G33: 200 | H33: =IFERROR(VLOOKUP($C33,$C$5:$H$18,6,0)+SUMIF($C$19:$C33,$C33,$F$19:$F33)-SUMIF($C$19:$C33,$C33,$G$19:$G33),"") -> 1800 | M33: =IF($B33="","",--TEXT($B33,"yyyymm")) -> 202609
A34: =IF(B34="","",COUNTA($B$5:B34)) -> 30 | B34: 46266 | C34: 微信 | D34: 车辆费用 | G34: 500 | H34: =IFERROR(VLOOKUP($C34,$C$5:$H$18,6,0)+SUMIF($C$19:$C34,$C34,$F$19:$F34)-SUMIF($C$19:$C34,$C34,$G$19:$G34),"") -> -700 | M34: =IF($B34="","",--TEXT($B34,"yyyymm")) -> 202609
A35: =IF(B35="","",COUNTA($B$5:B35)) -> 31 | B35: 46266 | C35: 支付宝 | D35: 伙食费 | G35: 500 | H35: =IFERROR(VLOOKUP($C35,$C$5:$H$18,6,0)+SUMIF($C$19:$C35,$C35,$F$19:$F35)-SUMIF($C$19:$C35,$C35,$G$19:$G35),"") -> -800 | M35: =IF($B35="","",--TEXT($B35,"yyyymm")) -> 202609
A36: =IF(B36="","",COUNTA($B$5:B36)) -> 32 | B36: 46266 | C36: 杭州 | F36: 5000 | H36: =IFERROR(VLOOKUP($C36,$C$5:$H$18,6,0)+SUMIF($C$19:$C36,$C36,$F$19:$F36)-SUMIF($C$19:$C36,$C36,$G$19:$G36),"") -> 4500 | M36: =IF($B36="","",--TEXT($B36,"yyyymm")) -> 202609
A37: =IF(B37="","",COUNTA($B$5:B37)) -> 33 | B37: 46266 | C37: 农商 | F37: 500 | H37: =IFERROR(VLOOKUP($C37,$C$5:$H$18,6,0)+SUMIF($C$19:$C37,$C37,$F$19:$F37)-SUMIF($C$19:$C37,$C37,$G$19:$G37),"") -> 3100 | M37: =IF($B37="","",--TEXT($B37,"yyyymm")) -> 202609
A38: =IF(B38="","",COUNTA($B$5:B38)) -> 34 | B38: 46266 | C38: 备用 | D38: 电费 | G38: 500 | H38: =IFERROR(VLOOKUP($C38,$C$5:$H$18,6,0)+SUMIF($C$19:$C38,$C38,$F$19:$F38)-SUMIF($C$19:$C38,$C38,$G$19:$G38),"") -> -5500 | M38: =IF($B38="","",--TEXT($B38,"yyyymm")) -> 202609
A39: =IF(B39="","",COUNTA($B$5:B39)) -> 35 | B39: 46266 | C39: 备用1 | F39: 10000 | H39: =IFERROR(VLOOKUP($C39,$C$5:$H$18,6,0)+SUMIF($C$19:$C39,$C39,$F$19:$F39)-SUMIF($C$19:$C39,$C39,$G$19:$G39),"") -> 9800 | M39: =IF($B39="","",--TEXT($B39,"yyyymm")) -> 202609
A40: =IF(B40="","",COUNTA($B$5:B40)) -> 36 | B40: 46266 | C40: 备用2 | E40: 工行转民生 | F40: 1000 | H40: =IFERROR(VLOOKUP($C40,$C$5:$H$18,6,0)+SUMIF($C$19:$C40,$C40,$F$19:$F40)-SUMIF($C$19:$C40,$C40,$G$19:$G40),"") -> 990 | M40: =IF($B40="","",--TEXT($B40,"yyyymm")) -> 202609
A41: =IF(B41="","",COUNTA($B$5:B41)) -> 37 | B41: 46266 | C41: 备用3 | E41: 工行转民生 | F41: -1000 | H41: =IFERROR(VLOOKUP($C41,$C$5:$H$18,6,0)+SUMIF($C$19:$C41,$C41,$F$19:$F41)-SUMIF($C$19:$C41,$C41,$G$19:$G41),"") -> -1050 | M41: =IF($B41="","",--TEXT($B41,"yyyymm")) -> 202609
...

Sheet 往来款跟进
L2: 总销售金额 | M2: =SUMIF(F11:F2001,">0") -> 23660 | N2: 应收账款 | O2: 应收款项 | P2: =SUM(F11:F2000)-SUM(J11:J2000) -> 23060 | Q2: 应付账款 | R2: 供货商 | S2: 供货商2
L3: 购货款 | M3: =SUMIF(O11:O2001,">0") -> 0 | O3: 已收款 | P3: =SUM(G11:G2000) -> 19140 | R3: 购货款 | S3: =SUMIFS(O11:O1000,N11:N1000,S2) -> 0
L4: 销售费用 | M4: =SUM(J11:J1001) -> 600 | O4: 未收总计 | P4: =SUM(H11:H2000) -> 3920 | R4: 已付款 | S4: =SUMIFS(P11:P1000,N11:N1000,S2) -> 0
L5: 利润 | M5: =M2-M3-M4 -> 23060 | R5: 尚欠款 | S5: =S3-S4 -> 0
A8: 单位名称：百跃羊奶 | S8: 单位：元
A9: 序号 | B9: 日期 | C9: 客户生日 | D9: 应收账款 | M9: 应付账款
D10: 客户名称 | E10: 销售产品 | F10: 销售金额 | G10: 已收款 | H10: 尚欠款 | I10: 未收总计 | J10: 销售费用 | K10: 支付方式 | L10: 备注 | M10: 日期 | N10: 供货商 | O10: 购货款 | P10: 已付款 | Q10: 尚欠款 | R10: 尚欠款总计 | S10: 备注
A11: {=ROW(2:500)} -> 2 | B11: 46269 | C11: 46113 | D11: 沈祖模 | E11: 羊奶 | F11: 3280 | G11: 3280 | H11: =F11-G11 -> 0 | I11: =F11-G11 -> 0 | J11: 0 | K11: 支付宝 | L11: 货款 | M11: 43971 | N11: 羊奶供货商 | Q11: =O11-P11 -> 0 | R11: =Q11 -> 0 | S11: 采购
A12: 3 | B12: 46269 | C12: 46113 | D12: 沈祖模 | E12: 乳铁蛋白 | F12: 3980 | G12: 3980 | H12: =F12-G12 -> 0 | I12: =I11+H12 -> 0 | J12: 0 | K12: 支付宝 | L12: 货款 | N12: 乳铁供货商 | Q12: =O12-P12 -> 0 | R12: =R11+O12-P12 -> 0 | S12: 采购
A13: 4 | B13: 46272 | C13: 46300 | D13: 谢爱琴 | E13: 羊奶 | F13: 3280 | G13: 2980 | H13: 0 | I13: =I12+H13 -> 0 | J13: 300 | K13: 微信 | L13: 货款 | Q13: =O13-P13 -> 0 | R13: =R12+O13-P13 -> 0 | S13: 采购
A14: 5 | B14: 46272 | C14: 46300 | D14: 谢爱琴 | E14: 益生菌 | F14: 3280 | G14: 2980 | H14: 0 | I14: =I13+H14 -> 0 | J14: 300 | K14: 微信 | L14: 货款 | Q14: =O14-P14 -> 0 | R14: =R13+O14-P14 -> 0
A15: 6 | B15: 46272 | C15: 46272 | D15: 罗理华 | E15: 羊奶 | F15: 3280 | G15: 1640 | H15: 1640 | I15: =I14+H15 -> 1640 | J15: 0 | K15: 支付宝 | L15: 货款 | Q15: =O15-P15 -> 0 | R15: =R14+O15-P15 -> 0
A16: 7 | B16: 46274 | C16: 46134 | D16: 马珍珠 | E16: 羊奶 | F16: 3280 | G16: 1000 | H16: 2280 | I16: =I15+H16 -> 3920 | J16: 0 | K16: 微信 | L16: 货款 | Q16: =O16-P16 -> 0 | R16: =R15+O16-P16 -> 0
A17: 8 | B17: 46277 | C17: 46333 | D17: 徐江英 | E17: 羊奶 | F17: 3280 | G17: 3280 | H17: 0 | I17: =I16+H17 -> 3920 | J17: 0 | K17: 微信 | L17: 货款 | Q17: =O17-P17 -> 0 | R17: =R16+O17-P17 -> 0
A18: 9 | C18: 46148 | D18: 邵国新 | I18: =I17+H18 -> 3920 | Q18: =O18-P18 -> 0 | R18: =R17+O18-P18 -> 0
A19: 10 | C19: 46140 | D19: 李晓春 | I19: =I18+H19 -> 3920 | R19: =R18+O19-P19 -> 0
A20: 11 | C20: 46154 | D20: 李玉娟 | I20: =I19+H20 -> 3920 | Q20: =O20-P20 -> 0 | R20: =R19+O20-P20 -> 0
A21: 12 | C21: 46174 | D21: 徐德彪 | I21: =I20+H21 -> 3920 | Q21: =O21-P21 -> 0 | R21: =R20+O21-P21 -> 0
A22: 13 | C22: 46188 | D22: 邬香花 方建宏 | I22: =I21+H22 -> 3920 | Q22: =O22-P22 -> 0 | R22: =R21+O22-P22 -> 0
A23: 14 | B23: 46235 | C23: 6月17日 3月4日 | D23: 林永来 杨建云 | I23: =I22+H23 -> 3920 | Q23: =O23-P23 -> 0 | R23: =R22+O23-P23 -> 0
A24: 15 | C24: 46220 | D24: 郭志伟 | I24: =I23+H24 -> 3920 | Q24: =O24-P24 -> 0 | R24: =R23+O24-P24 -> 0
A25: 16 | C25: 46225 | D25: 吴亮 | I25: =I24+H25 -> 3920 | Q25: =O25-P25 -> 0 | R25: =R24+O25-P25 -> 0
A26: 17 | C26: 46232 | D26: 吴兆香 | I26: =I25+H26 -> 3920 | Q26: =O26-P26 -> 0 | R26: =R25+O26-P26 -> 0
A27: 18 | C27: 46242 | D27: 郑玉英 | I27: =I26+H27 -> 3920 | Q27: =O27-P27 -> 0 | R27: =R26+O27-P27 -> 0
A28: 19 | C28: 46274 | D28: 唐鑫红 | I28: =I27+H28 -> 3920 | Q28: =O28-P28 -> 0 | R28: =R27+O28-P28 -> 0
A29: 20 | C29: 46285 | D29: 叶芬 | I29: =I28+H29 -> 3920 | Q29: =O29-P29 -> 0 | R29: =R28+O29-P29 -> 0
A30: 21 | C30: 46288 | D30: 童炳寿 王秀娟 | I30: =I29+H30 -> 3920 | Q30: =O30-P30 -> 0 | R30: =R29+O30-P30 -> 0
A31: 22 | C31: 46299 | D31: 郑爱月 | I31: =I30+H31 -> 3920 | Q31: =O31-P31 -> 0 | R31: =R30+O31-P31 -> 0
A32: 23 | C32: 46309 | D32: 李小琴 | I32: =I31+H32 -> 3920 | Q32: =O32-P32 -> 0 | R32: =R31+O32-P32 -> 0
A33: 24 | C33: 46318 | D33: 郁建红 | I33: =I32+H33 -> 3920 | Q33: =O33-P33 -> 0 | R33: =R32+O33-P33 -> 0
A34: 25 | C34: 10月30日 2月3日 | D34: 姜蓉兰 洪宗邦 | I34: =I33+H34 -> 3920 | Q34: =O34-P34 -> 0 | R34: =R33+O34-P34 -> 0
A35: 26 | C35: 46329 | D35: 过承祁 | I35: =I34+H35 -> 3920 | Q35: =O35-P35 -> 0 | R35: =R34+O35-P35 -> 0
A36: 27 | C36: 46330 | D36: 郑江宏 | I36: =I35+H36 -> 3920 | Q36: =O36-P36 -> 0 | R36: =R35+O36-P36 -> 0
A37: 28 | C37: 46338 | D37: 姜志鸿 | I37: =I36+H37 -> 3920 | Q37: =O37-P37 -> 0 | R37: =R36+O37-P37 -> 0
A38: 29 | C38: 46338 | D38: 吴旭红 | I38: =I37+H38 -> 3920 | Q38: =O38-P38 -> 0 | R38: =R37+O38-P38 -> 0
A39: 30 | C39: 46342 | D39: 丁爱妹 | I39: =I38+H39 -> 3920 | Q39: =O39-P39 -> 0 | R39: =R38+O39-P39 -> 0
A40: 31 | C40: 46351 | D40: 鄢桂香 | I40: =I39+H40 -> 3920 | Q40: =O40-P40 -> 0 | R40: =R39+O40-P40 -> 0
A41: 32 | C41: 46353 | D41: 傅荣姣 | I41: =I40+H41 -> 3920 | Q41: =O41-P41 -> 0 | R41: =R40+O41-P41 -> 0
A42: 33 | C42: 46354 | D42: 陆玉英 | I42: =I41+H42 -> 3920 | Q42: =O42-P42 -> 0 | R42: =R41+O42-P42 -> 0
A43: 34 | C43: 46361 | D43: 祝晓琳 | I43: =I42+H43 -> 3920 | Q43: =O43-P43 -> 0 | R43: =R42+O43-P43 -> 0
...

Sheet 汇报表
A1: 资金日报统计表（任意连续日期 / 单独一天查询）
A2: 起始日期 | B2: 46266 | D2: 截止日期 | E2: 46295 | G2: 查询天数 | H2: =IF(OR($B$2="",$E$2=""),"",IF($E$2<$B$2,"日期错误",IF($E$2-$B$2+1>31,"超过31天",$E$2-$B$2+1))) -> 30
A3: 提示：修改黄色日期即可查询；单独一天时起始日期=截止日期；默认展开31天，超过31天建议按月分段查询。
A4: 公司期初余额 | C4: 期间收款合计 | E4: 期间付款合计 | G4: 期末结余金额
B5: =SUM(B8:B21) -> 0 | D5: =SUM(BM8:BM21) -> 22200 | F5: =SUM(BN8:BN21) -> 11660 | H5: =SUM(BO8:BO21) -> 10540
C6: =IF(1<=MIN($H$2,31),$B$2+0,"") -> 46266 | D6: =IF(1<=MIN($H$2,31),$B$2+0,"") -> 46266 | E6: =IF(2<=MIN($H$2,31),$B$2+1,"") -> 46267 | F6: =IF(2<=MIN($H$2,31),$B$2+1,"") -> 46267 | G6: =IF(3<=MIN($H$2,31),$B$2+2,"") -> 46268 | H6: =IF(3<=MIN($H$2,31),$B$2+2,"") -> 46268 | I6: =IF(4<=MIN($H$2,31),$B$2+3,"") -> 46269 | J6: =IF(4<=MIN($H$2,31),$B$2+3,"") -> 46269 | K6: =IF(5<=MIN($H$2,31),$B$2+4,"") -> 46270 | L6: =IF(5<=MIN($H$2,31),$B$2+4,"") -> 46270 | M6: =IF(6<=MIN($H$2,31),$B$2+5,"") -> 46271 | N6: =IF(6<=MIN($H$2,31),$B$2+5,"") -> 46271 | O6: =IF(7<=MIN($H$2,31),$B$2+6,"") -> 46272 | P6: =IF(7<=MIN($H$2,31),$B$2+6,"") -> 46272 | Q6: =IF(8<=MIN($H$2,31),$B$2+7,"") -> 46273 | R6: =IF(8<=MIN($H$2,31),$B$2+7,"") -> 46273 | S6: =IF(9<=MIN($H$2,31),$B$2+8,"") -> 46274 | T6: =IF(9<=MIN($H$2,31),$B$2+8,"") -> 46274 | U6: =IF(10<=MIN($H$2,31),$B$2+9,"") -> 46275 | V6: =IF(10<=MIN($H$2,31),$B$2+9,"") -> 46275 | W6: =IF(11<=MIN($H$2,31),$B$2+10,"") -> 46276 | X6: =IF(11<=MIN($H$2,31),$B$2+10,"") -> 46276 | Y6: =IF(12<=MIN($H$2,31),$B$2+11,"") -> 46277 | Z6: =IF(12<=MIN($H$2,31),$B$2+11,"") -> 46277 | AA6: =IF(13<=MIN($H$2,31),$B$2+12,"") -> 46278 | AB6: =IF(13<=MIN($H$2,31),$B$2+12,"") -> 46278 | AC6: =IF(14<=MIN($H$2,31),$B$2+13,"") -> 46279 | AD6: =IF(14<=MIN($H$2,31),$B$2+13,"") -> 46279 | AE6: =IF(15<=MIN($H$2,31),$B$2+14,"") -> 46280 | AF6: =IF(15<=MIN($H$2,31),$B$2+14,"") -> 46280 | AG6: =IF(16<=MIN($H$2,31),$B$2+15,"") -> 46281 | AH6: =IF(16<=MIN($H$2,31),$B$2+15,"") -> 46281 | AI6: =IF(17<=MIN($H$2,31),$B$2+16,"") -> 46282 | AJ6: =IF(17<=MIN($H$2,31),$B$2+16,"") -> 46282 | AK6: =IF(18<=MIN($H$2,31),$B$2+17,"") -> 46283 | AL6: =IF(18<=MIN($H$2,31),$B$2+17,"") -> 46283 | AM6: =IF(19<=MIN($H$2,31),$B$2+18,"") -> 46284 | AN6: =IF(19<=MIN($H$2,31),$B$2+18,"") -> 46284 | AO6: =IF(20<=MIN($H$2,31),$B$2+19,"") -> 46285 | AP6: =IF(20<=MIN($H$2,31),$B$2+19,"") -> 46285 | AQ6: =IF(21<=MIN($H$2,31),$B$2+20,"") -> 46286 | AR6: =IF(21<=MIN($H$2,31),$B$2+20,"") -> 46286 | AS6: =IF(22<=MIN($H$2,31),$B$2+21,"") -> 46287 | AT6: =IF(22<=MIN($H$2,31),$B$2+21,"") -> 46287 | AU6: =IF(23<=MIN($H$2,31),$B$2+22,"") -> 46288 | AV6: =IF(23<=MIN($H$2,31),$B$2+22,"") -> 46288 | AW6: =IF(24<=MIN($H$2,31),$B$2+23,"") -> 46289 | AX6: =IF(24<=MIN($H$2,31),$B$2+23,"") -> 46289 | AY6: =IF(25<=MIN($H$2,31),$B$2+24,"") -> 46290 | AZ6: =IF(25<=MIN($H$2,31),$B$2+24,"") -> 46290 | BA6: =IF(26<=MIN($H$2,31),$B$2+25,"") -> 46291 | BB6: =IF(26<=MIN($H$2,31),$B$2+25,"") -> 46291 | BC6: =IF(27<=MIN($H$2,31),$B$2+26,"") -> 46292 | BD6: =IF(27<=MIN($H$2,31),$B$2+26,"") -> 46292 | BE6: =IF(28<=MIN($H$2,31),$B$2+27,"") -> 46293 | BF6: =IF(28<=MIN($H$2,31),$B$2+27,"") -> 46293 | BG6: =IF(29<=MIN($H$2,31),$B$2+28,"") -> 46294 | BH6: =IF(29<=MIN($H$2,31),$B$2+28,"") -> 46294 | BI6: =IF(30<=MIN($H$2,31),$B$2+29,"") -> 46295 | BJ6: =IF(30<=MIN($H$2,31),$B$2+29,"") -> 46295 | BK6: =IF(31<=MIN($H$2,31),$B$2+30,"") | BL6: =IF(31<=MIN($H$2,31),$B$2+30,"")
A7: 账户 | B7: 期初余额 | C7: =IF(C$6="","","收款") -> 收款 | D7: =IF(D$6="","","付款") -> 付款 | E7: =IF(E$6="","","收款") -> 收款 | F7: =IF(F$6="","","付款") -> 付款 | G7: =IF(G$6="","","收款") -> 收款 | H7: =IF(H$6="","","付款") -> 付款 | I7: =IF(I$6="","","收款") -> 收款 | J7: =IF(J$6="","","付款") -> 付款 | K7: =IF(K$6="","","收款") -> 收款 | L7: =IF(L$6="","","付款") -> 付款 | M7: =IF(M$6="","","收款") -> 收款 | N7: =IF(N$6="","","付款") -> 付款 | O7: =IF(O$6="","","收款") -> 收款 | P7: =IF(P$6="","","付款") -> 付款 | Q7: =IF(Q$6="","","收款") -> 收款 | R7: =IF(R$6="","","付款") -> 付款 | S7: =IF(S$6="","","收款") -> 收款 | T7: =IF(T$6="","","付款") -> 付款 | U7: =IF(U$6="","","收款") -> 收款 | V7: =IF(V$6="","","付款") -> 付款 | W7: =IF(W$6="","","收款") -> 收款 | X7: =IF(X$6="","","付款") -> 付款 | Y7: =IF(Y$6="","","收款") -> 收款 | Z7: =IF(Z$6="","","付款") -> 付款 | AA7: =IF(AA$6="","","收款") -> 收款 | AB7: =IF(AB$6="","","付款") -> 付款 | AC7: =IF(AC$6="","","收款") -> 收款 | AD7: =IF(AD$6="","","付款") -> 付款 | AE7: =IF(AE$6="","","收款") -> 收款 | AF7: =IF(AF$6="","","付款") -> 付款 | AG7: =IF(AG$6="","","收款") -> 收款 | AH7: =IF(AH$6="","","付款") -> 付款 | AI7: =IF(AI$6="","","收款") -> 收款 | AJ7: =IF(AJ$6="","","付款") -> 付款 | AK7: =IF(AK$6="","","收款") -> 收款 | AL7: =IF(AL$6="","","付款") -> 付款 | AM7: =IF(AM$6="","","收款") -> 收款 | AN7: =IF(AN$6="","","付款") -> 付款 | AO7: =IF(AO$6="","","收款") -> 收款 | AP7: =IF(AP$6="","","付款") -> 付款 | AQ7: =IF(AQ$6="","","收款") -> 收款 | AR7: =IF(AR$6="","","付款") -> 付款 | AS7: =IF(AS$6="","","收款") -> 收款 | AT7: =IF(AT$6="","","付款") -> 付款 | AU7: =IF(AU$6="","","收款") -> 收款 | AV7: =IF(AV$6="","","付款") -> 付款 | AW7: =IF(AW$6="","","收款") -> 收款 | AX7: =IF(AX$6="","","付款") -> 付款 | AY7: =IF(AY$6="","","收款") -> 收款 | AZ7: =IF(AZ$6="","","付款") -> 付款 | BA7: =IF(BA$6="","","收款") -> 收款 | BB7: =IF(BB$6="","","付款") -> 付款 | BC7: =IF(BC$6="","","收款") -> 收款 | BD7: =IF(BD$6="","","付款") -> 付款 | BE7: =IF(BE$6="","","收款") -> 收款 | BF7: =IF(BF$6="","","付款") -> 付款 | BG7: =IF(BG$6="","","收款") -> 收款 | BH7: =IF(BH$6="","","付款") -> 付款 | BI7: =IF(BI$6="","","收款") -> 收款 | BJ7: =IF(BJ$6="","","付款") -> 付款 | BK7: =IF(BK$6="","","收款") | BL7: =IF(BL$6="","","付款") | BM7: 收款合计 | BN7: 付款合计 | BO7: 期末余额
A8: 现金 | B8: =IF(OR($A8="",NOT(ISNUMBER($H$2))),"",SUMIFS(数据录入!$H$5:$H$4999,数据录入!$C$5:$C$4999,$A8,数据录入!$E$5:$E$4999,"期初余额",数据录入!$B$5:$B$4999,"<="&$B$2)+SUMIFS(数据录入!$F$5:$F$4999,数据录入!$C$5:$C$4999,$A8,数据录入!$B$5:$B$4999,"<"&$B$2)-SUMIFS(数据录入!$G$5:$G$4999,数据录入!$C$5:$C$4999,$A8,数据录入!$B$5:$B$4999,"<"&$B$2)) -> 0 | C8: =IF(OR($A8="",C$6="",NOT(ISNUMBER($H$2))),"",SUMIFS(数据录入!$F$5:$F$4999,数据录入!$C$5:$C$4999,$A8,数据录入!$B$5:$B$4999,C$6)) -> 2000 | D8: =IF(OR($A8="",D$6="",NOT(ISNUMBER($H$2))),"",SUMIFS(数据录入!$G$5:$G$4999,数据录入!$C$5:$C$4999,$A8,数据录入!$B$5:$B$4999,D$6)) -> 200 | E8: =IF(OR($A8="",E$6="",NOT(ISNUMBER($H$2))),"",SUMIFS(数据录入!$F$5:$F$4999,数据录入!$C$5:$C$4999,$A8,数据录入!$B$5:$B$4999,E$6)) -> 0 | F8: =IF(OR($A8="",F$6="",NOT(ISNUMBER($H$2))),"",SUMIFS(数据录入!$G$5:$G$4999,数据录入!$C$5:$C$4999,$A8,数据录入!$B$5:$B$4999,F$6)) -> 0 | G8: =IF(OR($A8="",G$6="",NOT(ISNUMBER($H$2))),"",SUMIFS(数据录入!$F$5:$F$4999,数据录入!$C$5:$C$4999,$A8,数据录入!$B$5:$B$4999,G$6)) -> 0 | H8: =IF(OR($A8="",H$6="",NOT(ISNUMBER($H$2))),"",SUMIFS(数据录入!$G$5:$G$4999,数据录入!$C$5:$C$4999,$A8,数据录入!$B$5:$B$4999,H$6)) -> 0 | I8: =IF(OR($A8="",I$6="",NOT(ISNUMBER($H$2))),"",SUMIFS(数据录入!$F$5:$F$4999,数据录入!$C$5:$C$4999,$A8,数据录入!$B$5:$B$4999,I$6)) -> 0 | J8: =IF(OR($A8="",J$6="",NOT(ISNUMBER($H$2))),"",SUMIFS(数据录入!$G$5:$G$4999,数据录入!$C$5:$C$4999,$A8,数据录入!$B$5:$B$4999,J$6)) -> 0 | K8: =IF(OR($A8="",K$6="",NOT(ISNUMBER($H$2))),"",SUMIFS(数据录入!$F$5:$F$4999,数据录入!$C$5:$C$4999,$A8,数据录入!$B$5:$B$4999,K$6)) -> 0 | L8: =IF(OR($A8="",L$6="",NOT(ISNUMBER($H$2))),"",SUMIFS(数据录入!$G$5:$G$4999,数据录入!$C$5:$C$4999,$A8,数据录入!$B$5:$B$4999,L$6)) -> 0 | M8: =IF(OR($A8="",M$6="",NOT(ISNUMBER($H$2))),"",SUMIFS(数据录入!$F$5:$F$4999,数据录入!$C$5:$C$4999,$A8,数据录入!$B$5:$B$4999,M$6)) -> 0 | N8: =IF(OR($A8="",N$6="",NOT(ISNUMBER($H$2))),"",SUMIFS(数据录入!$G$5:$G$4999,数据录入!$C$5:$C$4999,$A8,数据录入!$B$5:$B$4999,N$6)) -> 0 | O8: =IF(OR($A8="",O$6="",NOT(ISNUMBER($H$2))),"",SUMIFS(数据录入!$F$5:$F$4999,数据录入!$C$5:$C$4999,$A8,数据录入!$B$5:$B$4999,O$6)) -> 0 | P8: =IF(OR($A8="",P$6="",NOT(ISNUMBER($H$2))),"",SUMIFS(数据录入!$G$5:$G$4999,数据录入!$C$5:$C$4999,$A8,数据录入!$B$5:$B$4999,P$6)) -> 0 | Q8: =IF(OR($A8="",Q$6="",NOT(ISNUMBER($H$2))),"",SUMIFS(数据录入!$F$5:$F$4999,数据录入!$C$5:$C$4999,$A8,数据录入!$B$5:$B$4999,Q$6)) -> 0 | R8: =IF(OR($A8="",R$6="",NOT(ISNUMBER($H$2))),"",SUMIFS(数据录入!$G$5:$G$4999,数据录入!$C$5:$C$4999,$A8,数据录入!$B$5:$B$4999,R$6)) -> 0 | S8: =IF(OR($A8="",S$6="",NOT(ISNUMBER($H$2))),"",SUMIFS(数据录入!$F$5:$F$4999,数据录入!$C$5:$C$4999,$A8,数据录入!$B$5:$B$4999,S$6)) -> 0 | T8: =IF(OR($A8="",T$6="",NOT(ISNUMBER($H$2))),"",SUMIFS(数据录入!$G$5:$G$4999,数据录入!$C$5:$C$4999,$A8,数据录入!$B$5:$B$4999,T$6)) -> 0 | U8: =IF(OR($A8="",U$6="",NOT(ISNUMBER($H$2))),"",SUMIFS(数据录入!$F$5:$F$4999,数据录入!$C$5:$C$4999,$A8,数据录入!$B$5:$B$4999,U$6)) -> 0 | V8: =IF(OR($A8="",V$6="",NOT(ISNUMBER($H$2))),"",SUMIFS(数据录入!$G$5:$G$4999,数据录入!$C$5:$C$4999,$A8,数据录入!$B$5:$B$4999,V$6)) -> 0 | W8: =IF(OR($A8="",W$6="",NOT(ISNUMBER($H$2))),"",SUMIFS(数据录入!$F$5:$F$4999,数据录入!$C$5:$C$4999,$A8,数据录入!$B$5:$B$4999,W$6)) -> 0 | X8: =IF(OR($A8="",X$6="",NOT(ISNUMBER($H$2))),"",SUMIFS(数据录入!$G$5:$G$4999,数据录入!$C$5:$C$4999,$A8,数据录入!$B$5:$B$4999,X$6)) -> 0 | Y8: =IF(OR($A8="",Y$6="",NOT(ISNUMBER($H$2))),"",SUMIFS(数据录入!$F$5:$F$4999,数据录入!$C$5:$C$4999,$A8,数据录入!$B$5:$B$4999,Y$6)) -> 0 | Z8: =IF(OR($A8="",Z$6="",NOT(ISNUMBER($H$2))),"",SUMIFS(数据录入!$G$5:$G$4999,数据录入!$C$5:$C$4999,$A8,数据录入!$B$5:$B$4999,Z$6)) -> 0 | AA8: =IF(OR($A8="",AA$6="",NOT(ISNUMBER($H$2))),"",SUMIFS(数据录入!$F$5:$F$4999,数据录入!$C$5:$C$4999,$A8,数据录入!$B$5:$B$4999,AA$6)) -> 0 | AB8: =IF(OR($A8="",AB$6="",NOT(ISNUMBER($H$2))),"",SUMIFS(数据录入!$G$5:$G$4999,数据录入!$C$5:$C$4999,$A8,数据录入!$B$5:$B$4999,AB$6)) -> 0 | AC8: =IF(OR($A8="",AC$6="",NOT(ISNUMBER($H$2))),"",SUMIFS(数据录入!$F$5:$F$4999,数据录入!$C$5:$C$4999,$A8,数据录入!$B$5:$B$4999,AC$6)) -> 0 | AD8: =IF(OR($A8="",AD$6="",NOT(ISNUMBER($H$2))),"",SUMIFS(数据录入!$G$5:$G$4999,数据录入!$C$5:$C$4999,$A8,数据录入!$B$5:$B$4999,AD$6)) -> 0 | AE8: =IF(OR($A8="",AE$6="",NOT(ISNUMBER($H$2))),"",SUMIFS(数据录入!$F$5:$F$4999,数据录入!$C$5:$C$4999,$A8,数据录入!$B$5:$B$4999,AE$6)) -> 0 | AF8: =IF(OR($A8="",AF$6="",NOT(ISNUMBER($H$2))),"",SUMIFS(数据录入!$G$5:$G$4999,数据录入!$C$5:$C$4999,$A8,数据录入!$B$5:$B$4999,AF$6)) -> 0 | AG8: =IF(OR($A8="",AG$6="",NOT(ISNUMBER($H$2))),"",SUMIFS(数据录入!$F$5:$F$4999,数据录入!$C$5:$C$4999,$A8,数据录入!$B$5:$B$4999,AG$6)) -> 0 | AH8: =IF(OR($A8="",AH$6="",NOT(ISNUMBER($H$2))),"",SUMIFS(数据录入!$G$5:$G$4999,数据录入!$C$5:$C$4999,$A8,数据录入!$B$5:$B$4999,AH$6)) -> 0 | AI8: =IF(OR($A8="",AI$6="",NOT(ISNUMBER($H$2))),"",SUMIFS(数据录入!$F$5:$F$4999,数据录入!$C$5:$C$4999,$A8,数据录入!$B$5:$B$4999,AI$6)) -> 0 | AJ8: =IF(OR($A8="",AJ$6="",NOT(ISNUMBER($H$2))),"",SUMIFS(数据录入!$G$5:$G$4999,数据录入!$C$5:$C$4999,$A8,数据录入!$B$5:$B$4999,AJ$6)) -> 0 | AK8: =IF(OR($A8="",AK$6="",NOT(ISNUMBER($H$2))),"",SUMIFS(数据录入!$F$5:$F$4999,数据录入!$C$5:$C$4999,$A8,数据录入!$B$5:$B$4999,AK$6)) -> 0 | AL8: =IF(OR($A8="",AL$6="",NOT(ISNUMBER($H$2))),"",SUMIFS(数据录入!$G$5:$G$4999,数据录入!$C$5:$C$4999,$A8,数据录入!$B$5:$B$4999,AL$6)) -> 0 | AM8: =IF(OR($A8="",AM$6="",NOT(ISNUMBER($H$2))),"",SUMIFS(数据录入!$F$5:$F$4999,数据录入!$C$5:$C$4999,$A8,数据录入!$B$5:$B$4999,AM$6)) -> 0 | AN8: =IF(OR($A8="",AN$6="",NOT(ISNUMBER($H$2))),"",SUMIFS(数据录入!$G$5:$G$4999,数据录入!$C$5:$C$4999,$A8,数据录入!$B$5:$B$4999,AN$6)) -> 0 | AO8: =IF(OR($A8="",AO$6="",NOT(ISNUMBER($H$2))),"",SUMIFS(数据录入!$F$5:$F$4999,数据录入!$C$5:$C$4999,$A8,数据录入!$B$5:$B$4999,AO$6)) -> 0 | AP8: =IF(OR($A8="",AP$6="",NOT(ISNUMBER($H$2))),"",SUMIFS(数据录入!$G$5:$G$4999,数据录入!$C$5:$C$4999,$A8,数据录入!$B$5:$B$4999,AP$6)) -> 0 | AQ8: =IF(OR($A8="",AQ$6="",NOT(ISNUMBER($H$2))),"",SUMIFS(数据录入!$F$5:$F$4999,数据录入!$C$5:$C$4999,$A8,数据录入!$B$5:$B$4999,AQ$6)) -> 0 | AR8: =IF(OR($A8="",AR$6="",NOT(ISNUMBER($H$2))),"",SUMIFS(数据录入!$G$5:$G$4999,数据录入!$C$5:$C$4999,$A8,数据录入!$B$5:$B$4999,AR$6)) -> 0 | AS8: =IF(OR($A8="",AS$6="",NOT(ISNUMBER($H$2))),"",SUMIFS(数据录入!$F$5:$F$4999,数据录入!$C$5:$C$4999,$A8,数据录入!$B$5:$B$4999,AS$6)) -> 0 | AT8: =IF(OR($A8="",AT$6="",NOT(ISNUMBER($H$2))),"",SUMIFS(数据录入!$G$5:$G$4999,数据录入!$C$5:$C$4999,$A8,数据录入!$B$5:$B$4999,AT$6)) -> 0 | AU8: =IF(OR($A8="",AU$6="",NOT(ISNUMBER($H$2))),"",SUMIFS(数据录入!$F$5:$F$4999,数据录入!$C$5:$C$4999,$A8,数据录入!$B$5:$B$4999,AU$6)) -> 0 | AV8: =IF(OR($A8="",AV$6="",NOT(ISNUMBER($H$2))),"",SUMIFS(数据录入!$G$5:$G$4999,数据录入!$C$5:$C$4999,$A8,数据录入!$B$5:$B$4999,AV$6)) -> 0 | AW8: =IF(OR($A8="",AW$6="",NOT(ISNUMBER($H$2))),"",SUMIFS(数据录入!$F$5:$F$4999,数据录入!$C$5:$C$4999,$A8,数据录入!$B$5:$B$4999,AW$6)) -> 0 | AX8: =IF(OR($A8="",AX$6="",NOT(ISNUMBER($H$2))),"",SUMIFS(数据录入!$G$5:$G$4999,数据录入!$C$5:$C$4999,$A8,数据录入!$B$5:$B$4999,AX$6)) -> 0 | AY8: =IF(OR($A8="",AY$6="",NOT(ISNUMBER($H$2))),"",SUMIFS(数据录入!$F$5:$F$4999,数据录入!$C$5:$C$4999,$A8,数据录入!$B$5:$B$4999,AY$6)) -> 0 | AZ8: =IF(OR($A8="",AZ$6="",NOT(ISNUMBER($H$2))),"",SUMIFS(数据录入!$G$5:$G$4999,数据录入!$C$5:$C$4999,$A8,数据录入!$B$5:$B$4999,AZ$6)) -> 0 | BA8: =IF(OR($A8="",BA$6="",NOT(ISNUMBER($H$2))),"",SUMIFS(数据录入!$F$5:$F$4999,数据录入!$C$5:$C$4999,$A8,数据录入!$B$5:$B$4999,BA$6)) -> 0 | BB8: =IF(OR($A8="",BB$6="",NOT(ISNUMBER($H$2))),"",SUMIFS(数据录入!$G$5:$G$4999,数据录入!$C$5:$C$4999,$A8,数据录入!$B$5:$B$4999,BB$6)) -> 0 | BC8: =IF(OR($A8="",BC$6="",NOT(ISNUMBER($H$2))),"",SUMIFS(数据录入!$F$5:$F$4999,数据录入!$C$5:$C$4999,$A8,数据录入!$B$5:$B$4999,BC$6)) -> 0 | BD8: =IF(OR($A8="",BD$6="",NOT(ISNUMBER($H$2))),"",SUMIFS(数据录入!$G$5:$G$4999,数据录入!$C$5:$C$4999,$A8,数据录入!$B$5:$B$4999,BD$6)) -> 0 | BE8: =IF(OR($A8="",BE$6="",NOT(ISNUMBER($H$2))),"",SUMIFS(数据录入!$F$5:$F$4999,数据录入!$C$5:$C$4999,$A8,数据录入!$B$5:$B$4999,BE$6)) -> 0 | BF8: =IF(OR($A8="",BF$6="",NOT(ISNUMBER($H$2))),"",SUMIFS(数据录入!$G$5:$G$4999,数据录入!$C$5:$C$4999,$A8,数据录入!$B$5:$B$4999,BF$6)) -> 0 | BG8: =IF(OR($A8="",BG$6="",NOT(ISNUMBER($H$2))),"",SUMIFS(数据录入!$F$5:$F$4999,数据录入!$C$5:$C$4999,$A8,数据录入!$B$5:$B$4999,BG$6)) -> 0 | BH8: =IF(OR($A8="",BH$6="",NOT(ISNUMBER($H$2))),"",SUMIFS(数据录入!$G$5:$G$4999,数据录入!$C$5:$C$4999,$A8,数据录入!$B$5:$B$4999,BH$6)) -> 0 | BI8: =IF(OR($A8="",BI$6="",NOT(ISNUMBER($H$2))),"",SUMIFS(数据录入!$F$5:$F$4999,数据录入!$C$5:$C$4999,$A8,数据录入!$B$5:$B$4999,BI$6)) -> 0 | BJ8: =IF(OR($A8="",BJ$6="",NOT(ISNUMBER($H$2))),"",SUMIFS(数据录入!$G$5:$G$4999,数据录入!$C$5:$C$4999,$A8,数据录入!$B$5:$B$4999,BJ$6)) -> 0 | BK8: =IF(OR($A8="",BK$6="",NOT(ISNUMBER($H$2))),"",SUMIFS(数据录入!$F$5:$F$4999,数据录入!$C$5:$C$4999,$A8,数据录入!$B$5:$B$4999,BK$6)) | BL8: =IF(OR($A8="",BL$6="",NOT(ISNUMBER($H$2))),"",SUMIFS(数据录入!$G$5:$G$4999,数据录入!$C$5:$C$4999,$A8,数据录入!$B$5:$B$4999,BL$6)) | BM8: =IF($A8="","",SUMIF($C$7:$BL$7,"收款",C8:BL8)) -> 2000 | BN8: =IF($A8="","",SUMIF($C$7:$BL$7,"付款",C8:BL8)) -> 200 | BO8: =IF($A8="","",B8+BM8-BN8) -> 1800
A9: 微信 | B9: =IF(OR($A9="",NOT(ISNUMBER($H$2))),"",SUMIFS(数据录入!$H$5:$H$4999,数据录入!$C$5:$C$4999,$A9,数据录入!$E$5:$E$4999,"期初余额",数据录入!$B$5:$B$4999,"<="&$B$2)+SUMIFS(数据录入!$F$5:$F$4999,数据录入!$C$5:$C$4999,$A9,数据录入!$B$5:$B$4999,"<"&$B$2)-SUMIFS(数据录入!$G$5:$G$4999,数据录入!$C$5:$C$4999,$A9,数据录入!$B$5:$B$4999,"<"&$B$2)) -> 0 | C9: =IF(OR($A9="",C$6="",NOT(ISNUMBER($H$2))),"",SUMIFS(数据录入!$F$5:$F$4999,数据录入!$C$5:$C$4999,$A9,数据录入!$B$5:$B$4999,C$6)) -> 0 | D9: =IF(OR($A9="",D$6="",NOT(ISNUMBER($H$2))),"",SUMIFS(数据录入!$G$5:$G$4999,数据录入!$C$5:$C$4999,$A9,数据录入!$B$5:$B$4999,D$6)) -> 700 | E9: =IF(OR($A9="",E$6="",NOT(ISNUMBER($H$2))),"",SUMIFS(数据录入!$F$5:$F$4999,数据录入!$C$5:$C$4999,$A9,数据录入!$B$5:$B$4999,E$6)) -> 0 | F9: =IF(OR($A9="",F$6="",NOT(ISNUMBER($H$2))),"",SUMIFS(数据录入!$G$5:$G$4999,数据录入!$C$5:$C$4999,$A9,数据录入!$B$5:$B$4999,F$6)) -> 0 | G9: =IF(OR($A9="",G$6="",NOT(ISNUMBER($H$2))),"",SUMIFS(数据录入!$F$5:$F$4999,数据录入!$C$5:$C$4999,$A9,数据录入!$B$5:$B$4999,G$6)) -> 0 | H9: =IF(OR($A9="",H$6="",NOT(ISNUMBER($H$2))),"",SUMIFS(数据录入!$G$5:$G$4999,数据录入!$C$5:$C$4999,$A9,数据录入!$B$5:$B$4999,H$6)) -> 0 | I9: =IF(OR($A9="",I$6="",NOT(ISNUMBER($H$2))),"",SUMIFS(数据录入!$F$5:$F$4999,数据录入!$C$5:$C$4999,$A9,数据录入!$B$5:$B$4999,I$6)) -> 0 | J9: =IF(OR($A9="",J$6="",NOT(ISNUMBER($H$2))),"",SUMIFS(数据录入!$G$5:$G$4999,数据录入!$C$5:$C$4999,$A9,数据录入!$B$5:$B$4999,J$6)) -> 0 | K9: =IF(OR($A9="",K$6="",NOT(ISNUMBER($H$2))),"",SUMIFS(数据录入!$F$5:$F$4999,数据录入!$C$5:$C$4999,$A9,数据录入!$B$5:$B$4999,K$6)) -> 0 | L9: =IF(OR($A9="",L$6="",NOT(ISNUMBER($H$2))),"",SUMIFS(数据录入!$G$5:$G$4999,数据录入!$C$5:$C$4999,$A9,数据录入!$B$5:$B$4999,L$6)) -> 0 | M9: =IF(OR($A9="",M$6="",NOT(ISNUMBER($H$2))),"",SUMIFS(数据录入!$F$5:$F$4999,数据录入!$C$5:$C$4999,$A9,数据录入!$B$5:$B$4999,M$6)) -> 0 | N9: =IF(OR($A9="",N$6="",NOT(ISNUMBER($H$2))),"",SUMIFS(数据录入!$G$5:$G$4999,数据录入!$C$5:$C$4999,$A9,数据录入!$B$5:$B$4999,N$6)) -> 0 | O9: =IF(OR($A9="",O$6="",NOT(ISNUMBER($H$2))),"",SUMIFS(数据录入!$F$5:$F$4999,数据录入!$C$5:$C$4999,$A9,数据录入!$B$5:$B$4999,O$6)) -> 0 | P9: =IF(OR($A9="",P$6="",NOT(ISNUMBER($H$2))),"",SUMIFS(数据录入!$G$5:$G$4999,数据录入!$C$5:$C$4999,$A9,数据录入!$B$5:$B$4999,P$6)) -> 0 | Q9: =IF(OR($A9="",Q$6="",NOT(ISNUMBER($H$2))),"",SUMIFS(数据录入!$F$5:$F$4999,数据录入!$C$5:$C$4999,$A9,数据录入!$B$5:$B$4999,Q$6)) -> 0 | R9: =IF(OR($A9="",R$6="",NOT(ISNUMBER($H$2))),"",SUMIFS(数据录入!$G$5:$G$4999,数据录入!$C$5:$C$4999,$A9,数据录入!$B$5:$B$4999,R$6)) -> 0 | S9: =IF(OR($A9="",S$6="",NOT(ISNUMBER($H$2))),"",SUMIFS(数据录入!$F$5:$F$4999,数据录入!$C$5:$C$4999,$A9,数据录入!$B$5:$B$4999,S$6)) -> 0 | T9: =IF(OR($A9="",T$6="",NOT(ISNUMBER($H$2))),"",SUMIFS(数据录入!$G$5:$G$4999,数据录入!$C$5:$C$4999,$A9,数据录入!$B$5:$B$4999,T$6)) -> 0 | U9: =IF(OR($A9="",U$6="",NOT(ISNUMBER($H$2))),"",SUMIFS(数据录入!$F$5:$F$4999,数据录入!$C$5:$C$4999,$A9,数据录入!$B$5:$B$4999,U$6)) -> 0 | V9: =IF(OR($A9="",V$6="",NOT(ISNUMBER($H$2))),"",SUMIFS(数据录入!$G$5:$G$4999,数据录入!$C$5:$C$4999,$A9,数据录入!$B$5:$B$4999,V$6)) -> 0 | W9: =IF(OR($A9="",W$6="",NOT(ISNUMBER($H$2))),"",SUMIFS(数据录入!$F$5:$F$4999,数据录入!$C$5:$C$4999,$A9,数据录入!$B$5:$B$4999,W$6)) -> 0 | X9: =IF(OR($A9="",X$6="",NOT(ISNUMBER($H$2))),"",SUMIFS(数据录入!$G$5:$G$4999,数据录入!$C$5:$C$4999,$A9,数据录入!$B$5:$B$4999,X$6)) -> 0 | Y9: =IF(OR($A9="",Y$6="",NOT(ISNUMBER($H$2))),"",SUMIFS(数据录入!$F$5:$F$4999,数据录入!$C$5:$C$4999,$A9,数据录入!$B$5:$B$4999,Y$6)) -> 0 | Z9: =IF(OR($A9="",Z$6="",NOT(ISNUMBER($H$2))),"",SUMIFS(数据录入!$G$5:$G$4999,数据录入!$C$5:$C$4999,$A9,数据录入!$B$5:$B$4999,Z$6)) -> 0 | AA9: =IF(OR($A9="",AA$6="",NOT(ISNUMBER($H$2))),"",SUMIFS(数据录入!$F$5:$F$4999,数据录入!$C$5:$C$4999,$A9,数据录入!$B$5:$B$4999,AA$6)) -> 0 | AB9: =IF(OR($A9="",AB$6="",NOT(ISNUMBER($H$2))),"",SUMIFS(数据录入!$G$5:$G$4999,数据录入!$C$5:$C$4999,$A9,数据录入!$B$5:$B$4999,AB$6)) -> 0 | AC9: =IF(OR($A9="",AC$6="",NOT(ISNUMBER($H$2))),"",SUMIFS(数据录入!$F$5:$F$4999,数据录入!$C$5:$C$4999,$A9,数据录入!$B$5:$B$4999,AC$6)) -> 0 | AD9: =IF(OR($A9="",AD$6="",NOT(ISNUMBER($H$2))),"",SUMIFS(数据录入!$G$5:$G$4999,数据录入!$C$5:$C$4999,$A9,数据录入!$B$5:$B$4999,AD$6)) -> 0 | AE9: =IF(OR($A9="",AE$6="",NOT(ISNUMBER($H$2))),"",SUMIFS(数据录入!$F$5:$F$4999,数据录入!$C$5:$C$4999,$A9,数据录入!$B$5:$B$4999,AE$6)) -> 0 | AF9: =IF(OR($A9="",AF$6="",NOT(ISNUMBER($H$2))),"",SUMIFS(数据录入!$G$5:$G$4999,数据录入!$C$5:$C$4999,$A9,数据录入!$B$5:$B$4999,AF$6)) -> 0 | AG9: =IF(OR($A9="",AG$6="",NOT(ISNUMBER($H$2))),"",SUMIFS(数据录入!$F$5:$F$4999,数据录入!$C$5:$C$4999,$A9,数据录入!$B$5:$B$4999,AG$6)) -> 0 | AH9: =IF(OR($A9="",AH$6="",NOT(ISNUMBER($H$2))),"",SUMIFS(数据录入!$G$5:$G$4999,数据录入!$C$5:$C$4999,$A9,数据录入!$B$5:$B$4999,AH$6)) -> 0 | AI9: =IF(OR($A9="",AI$6="",NOT(ISNUMBER($H$2))),"",SUMIFS(数据录入!$F$5:$F$4999,数据录入!$C$5:$C$4999,$A9,数据录入!$B$5:$B$4999,AI$6)) -> 0 | AJ9: =IF(OR($A9="",AJ$6="",NOT(ISNUMBER($H$2))),"",SUMIFS(数据录入!$G$5:$G$4999,数据录入!$C$5:$C$4999,$A9,数据录入!$B$5:$B$4999,AJ$6)) -> 0 | AK9: =IF(OR($A9="",AK$6="",NOT(ISNUMBER($H$2))),"",SUMIFS(数据录入!$F$5:$F$4999,数据录入!$C$5:$C$4999,$A9,数据录入!$B$5:$B$4999,AK$6)) -> 0 | AL9: =IF(OR($A9="",AL$6="",NOT(ISNUMBER($H$2))),"",SUMIFS(数据录入!$G$5:$G$4999,数据录入!$C$5:$C$4999,$A9,数据录入!$B$5:$B$4999,AL$6)) -> 0 | AM9: =IF(OR($A9="",AM$6="",NOT(ISNUMBER($H$2))),"",SUMIFS(数据录入!$F$5:$F$4999,数据录入!$C$5:$C$4999,$A9,数据录入!$B$5:$B$4999,AM$6)) -> 0 | AN9: =IF(OR($A9="",AN$6="",NOT(ISNUMBER($H$2))),"",SUMIFS(数据录入!$G$5:$G$4999,数据录入!$C$5:$C$4999,$A9,数据录入!$B$5:$B$4999,AN$6)) -> 0 | AO9: =IF(OR($A9="",AO$6="",NOT(ISNUMBER($H$2))),"",SUMIFS(数据录入!$F$5:$F$4999,数据录入!$C$5:$C$4999,$A9,数据录入!$B$5:$B$4999,AO$6)) -> 0 | AP9: =IF(OR($A9="",AP$6="",NOT(ISNUMBER($H$2))),"",SUMIFS(数据录入!$G$5:$G$4999,数据录入!$C$5:$C$4999,$A9,数据录入!$B$5:$B$4999,AP$6)) -> 0 | AQ9: =IF(OR($A9="",AQ$6="",NOT(ISNUMBER($H$2))),"",SUMIFS(数据录入!$F$5:$F$4999,数据录入!$C$5:$C$4999,$A9,数据录入!$B$5:$B$4999,AQ$6)) -> 0 | AR9: =IF(OR($A9="",AR$6="",NOT(ISNUMBER($H$2))),"",SUMIFS(数据录入!$G$5:$G$4999,数据录入!$C$5:$C$4999,$A9,数据录入!$B$5:$B$4999,AR$6)) -> 0 | AS9: =IF(OR($A9="",AS$6="",NOT(ISNUMBER($H$2))),"",SUMIFS(数据录入!$F$5:$F$4999,数据录入!$C$5:$C$4999,$A9,数据录入!$B$5:$B$4999,AS$6)) -> 0 | AT9: =IF(OR($A9="",AT$6="",NOT(ISNUMBER($H$2))),"",SUMIFS(数据录入!$G$5:$G$4999,数据录入!$C$5:$C$4999,$A9,数据录入!$B$5:$B$4999,AT$6)) -> 0 | AU9: =IF(OR($A9="",AU$6="",NOT(ISNUMBER($H$2))),"",SUMIFS(数据录入!$F$5:$F$4999,数据录入!$C$5:$C$4999,$A9,数据录入!$B$5:$B$4999,AU$6)) -> 0 | AV9: =IF(OR($A9="",AV$6="",NOT(ISNUMBER($H$2))),"",SUMIFS(数据录入!$G$5:$G$4999,数据录入!$C$5:$C$4999,$A9,数据录入!$B$5:$B$4999,AV$6)) -> 0 | AW9: =IF(OR($A9="",AW$6="",NOT(ISNUMBER($H$2))),"",SUMIFS(数据录入!$F$5:$F$4999,数据录入!$C$5:$C$4999,$A9,数据录入!$B$5:$B$4999,AW$6)) -> 0 | AX9: =IF(OR($A9="",AX$6="",NOT(ISNUMBER($H$2))),"",SUMIFS(数据录入!$G$5:$G$4999,数据录入!$C$5:$C$4999,$A9,数据录入!$B$5:$B$4999,AX$6)) -> 0 | AY9: =IF(OR($A9="",AY$6="",NOT(ISNUMBER($H$2))),"",SUMIFS(数据录入!$F$5:$F$4999,数据录入!$C$5:$C$4999,$A9,数据录入!$B$5:$B$4999,AY$6)) -> 0 | AZ9: =IF(OR($A9="",AZ$6="",NOT(ISNUMBER($H$2))),"",SUMIFS(数据录入!$G$5:$G$4999,数据录入!$C$5:$C$4999,$A9,数据录入!$B$5:$B$4999,AZ$6)) -> 0 | BA9: =IF(OR($A9="",BA$6="",NOT(ISNUMBER($H$2))),"",SUMIFS(数据录入!$F$5:$F$4999,数据录入!$C$5:$C$4999,$A9,数据录入!$B$5:$B$4999,BA$6)) -> 0 | BB9: =IF(OR($A9="",BB$6="",NOT(ISNUMBER($H$2))),"",SUMIFS(数据录入!$G$5:$G$4999,数据录入!$C$5:$C$4999,$A9,数据录入!$B$5:$B$4999,BB$6)) -> 0 | BC9: =IF(OR($A9="",BC$6="",NOT(ISNUMBER($H$2))),"",SUMIFS(数据录入!$F$5:$F$4999,数据录入!$C$5:$C$4999,$A9,数据录入!$B$5:$B$4999,BC$6)) -> 0 | BD9: =IF(OR($A9="",BD$6="",NOT(ISNUMBER($H$2))),"",SUMIFS(数据录入!$G$5:$G$4999,数据录入!$C$5:$C$4999,$A9,数据录入!$B$5:$B$4999,BD$6)) -> 0 | BE9: =IF(OR($A9="",BE$6="",NOT(ISNUMBER($H$2))),"",SUMIFS(数据录入!$F$5:$F$4999,数据录入!$C$5:$C$4999,$A9,数据录入!$B$5:$B$4999,BE$6)) -> 0 | BF9: =IF(OR($A9="",BF$6="",NOT(ISNUMBER($H$2))),"",SUMIFS(数据录入!$G$5:$G$4999,数据录入!$C$5:$C$4999,$A9,数据录入!$B$5:$B$4999,BF$6)) -> 0 | BG9: =IF(OR($A9="",BG$6="",NOT(ISNUMBER($H$2))),"",SUMIFS(数据录入!$F$5:$F$4999,数据录入!$C$5:$C$4999,$A9,数据录入!$B$5:$B$4999,BG$6)) -> 0 | BH9: =IF(OR($A9="",BH$6="",NOT(ISNUMBER($H$2))),"",SUMIFS(数据录入!$G$5:$G$4999,数据录入!$C$5:$C$4999,$A9,数据录入!$B$5:$B$4999,BH$6)) -> 0 | BI9: =IF(OR($A9="",BI$6="",NOT(ISNUMBER($H$2))),"",SUMIFS(数据录入!$F$5:$F$4999,数据录入!$C$5:$C$4999,$A9,数据录入!$B$5:$B$4999,BI$6)) -> 0 | BJ9: =IF(OR($A9="",BJ$6="",NOT(ISNUMBER($H$2))),"",SUMIFS(数据录入!$G$5:$G$4999,数据录入!$C$5:$C$4999,$A9,数据录入!$B$5:$B$4999,BJ$6)) -> 0 | BK9: =IF(OR($A9="",BK$6="",NOT(ISNUMBER($H$2))),"",SUMIFS(数据录入!$F$5:$F$4999,数据录入!$C$5:$C$4999,$A9,数据录入!$B$5:$B$4999,BK$6)) | BL9: =IF(OR($A9="",BL$6="",NOT(ISNUMBER($H$2))),"",SUMIFS(数据录入!$G$5:$G$4999,数据录入!$C$5:$C$4999,$A9,数据录入!$B$5:$B$4999,BL$6)) | BM9: =IF($A9="","",SUMIF($C$7:$BL$7,"收款",C9:BL9)) -> 0 | BN9: =IF($A9="","",SUMIF($C$7:$BL$7,"付款",C9:BL9)) -> 700 | BO9: =IF($A9="","",B9+BM9-BN9) -> -700
A10: 支付宝 | B10: =IF(OR($A10="",NOT(ISNUMBER($H$2))),"",SUMIFS(数据录入!$H$5:$H$4999,数据录入!$C$5:$C$4999,$A10,数据录入!$E$5:$E$4999,"期初余额",数据录入!$B$5:$B$4999,"<="&$B$2)+SUMIFS(数据录入!$F$5:$F$4999,数据录入!$C$5:$C$4999,$A10,数据录入!$B$5:$B$4999,"<"&$B$2)-SUMIFS(数据录入!$G$5:$G$4999,数据录入!$C$5:$C$4999,$A10,数据录入!$B$5:$B$4999,"<"&$B$2)) -> 0 | C10: =IF(OR($A10="",C$6="",NOT(ISNUMBER($H$2))),"",SUMIFS(数据录入!$F$5:$F$4999,数据录入!$C$5:$C$4999,$A10,数据录入!$B$5:$B$4999,C$6)) -> 0 | D10: =IF(OR($A10="",D$6="",NOT(ISNUMBER($H$2))),"",SUMIFS(数据录入!$G$5:$G$4999,数据录入!$C$5:$C$4999,$A10,数据录入!$B$5:$B$4999,D$6)) -> 800 | E10: =IF(OR($A10="",E$6="",NOT(ISNUMBER($H$2))),"",SUMIFS(数据录入!$F$5:$F$4999,数据录入!$C$5:$C$4999,$A10,数据录入!$B$5:$B$4999,E$6)) -> 0 | F10: =IF(OR($A10="",F$6="",NOT(ISNUMBER($H$2))),"",SUMIFS(数据录入!$G$5:$G$4999,数据录入!$C$5:$C$4999,$A10,数据录入!$B$5:$B$4999,F$6)) -> 0 | G10: =IF(OR($A10="",G$6="",NOT(ISNUMBER($H$2))),"",SUMIFS(数据录入!$F$5:$F$4999,数据录入!$C$5:$C$4999,$A10,数据录入!$B$5:$B$4999,G$6)) -> 0 | H10: =IF(OR($A10="",H$6="",NOT(ISNUMBER($H$2))),"",SUMIFS(数据录入!$G$5:$G$4999,数据录入!$C$5:$C$4999,$A10,数据录入!$B$5:$B$4999,H$6)) -> 0 | I10: =IF(OR($A10="",I$6="",NOT(ISNUMBER($H$2))),"",SUMIFS(数据录入!$F$5:$F$4999,数据录入!$C$5:$C$4999,$A10,数据录入!$B$5:$B$4999,I$6)) -> 0 | J10: =IF(OR($A10="",J$6="",NOT(ISNUMBER($H$2))),"",SUMIFS(数据录入!$G$5:$G$4999,数据录入!$C$5:$C$4999,$A10,数据录入!$B$5:$B$4999,J$6)) -> 0 | K10: =IF(OR($A10="",K$6="",NOT(ISNUMBER($H$2))),"",SUMIFS(数据录入!$F$5:$F$4999,数据录入!$C$5:$C$4999,$A10,数据录入!$B$5:$B$4999,K$6)) -> 0 | L10: =IF(OR($A10="",L$6="",NOT(ISNUMBER($H$2))),"",SUMIFS(数据录入!$G$5:$G$4999,数据录入!$C$5:$C$4999,$A10,数据录入!$B$5:$B$4999,L$6)) -> 0 | M10: =IF(OR($A10="",M$6="",NOT(ISNUMBER($H$2))),"",SUMIFS(数据录入!$F$5:$F$4999,数据录入!$C$5:$C$4999,$A10,数据录入!$B$5:$B$4999,M$6)) -> 0 | N10: =IF(OR($A10="",N$6="",NOT(ISNUMBER($H$2))),"",SUMIFS(数据录入!$G$5:$G$4999,数据录入!$C$5:$C$4999,$A10,数据录入!$B$5:$B$4999,N$6)) -> 0 | O10: =IF(OR($A10="",O$6="",NOT(ISNUMBER($H$2))),"",SUMIFS(数据录入!$F$5:$F$4999,数据录入!$C$5:$C$4999,$A10,数据录入!$B$5:$B$4999,O$6)) -> 0 | P10: =IF(OR($A10="",P$6="",NOT(ISNUMBER($H$2))),"",SUMIFS(数据录入!$G$5:$G$4999,数据录入!$C$5:$C$4999,$A10,数据录入!$B$5:$B$4999,P$6)) -> 0 | Q10: =IF(OR($A10="",Q$6="",NOT(ISNUMBER($H$2))),"",SUMIFS(数据录入!$F$5:$F$4999,数据录入!$C$5:$C$4999,$A10,数据录入!$B$5:$B$4999,Q$6)) -> 0 | R10: =IF(OR($A10="",R$6="",NOT(ISNUMBER($H$2))),"",SUMIFS(数据录入!$G$5:$G$4999,数据录入!$C$5:$C$4999,$A10,数据录入!$B$5:$B$4999,R$6)) -> 0 | S10: =IF(OR($A10="",S$6="",NOT(ISNUMBER($H$2))),"",SUMIFS(数据录入!$F$5:$F$4999,数据录入!$C$5:$C$4999,$A10,数据录入!$B$5:$B$4999,S$6)) -> 0 | T10: =IF(OR($A10="",T$6="",NOT(ISNUMBER($H$2))),"",SUMIFS(数据录入!$G$5:$G$4999,数据录入!$C$5:$C$4999,$A10,数据录入!$B$5:$B$4999,T$6)) -> 0 | U10: =IF(OR($A10="",U$6="",NOT(ISNUMBER($H$2))),"",SUMIFS(数据录入!$F$5:$F$4999,数据录入!$C$5:$C$4999,$A10,数据录入!$B$5:$B$4999,U$6)) -> 0 | V10: =IF(OR($A10="",V$6="",NOT(ISNUMBER($H$2))),"",SUMIFS(数据录入!$G$5:$G$4999,数据录入!$C$5:$C$4999,$A10,数据录入!$B$5:$B$4999,V$6)) -> 0 | W10: =IF(OR($A10="",W$6="",NOT(ISNUMBER($H$2))),"",SUMIFS(数据录入!$F$5:$F$4999,数据录入!$C$5:$C$4999,$A10,数据录入!$B$5:$B$4999,W$6)) -> 0 | X10: =IF(OR($A10="",X$6="",NOT(ISNUMBER($H$2))),"",SUMIFS(数据录入!$G$5:$G$4999,数据录入!$C$5:$C$4999,$A10,数据录入!$B$5:$B$4999,X$6)) -> 0 | Y10: =IF(OR($A10="",Y$6="",NOT(ISNUMBER($H$2))),"",SUMIFS(数据录入!$F$5:$F$4999,数据录入!$C$5:$C$4999,$A10,数据录入!$B$5:$B$4999,Y$6)) -> 0 | Z10: =IF(OR($A10="",Z$6="",NOT(ISNUMBER($H$2))),"",SUMIFS(数据录入!$G$5:$G$4999,数据录入!$C$5:$C$4999,$A10,数据录入!$B$5:$B$4999,Z$6)) -> 0 | AA10: =IF(OR($A10="",AA$6="",NOT(ISNUMBER($H$2))),"",SUMIFS(数据录入!$F$5:$F$4999,数据录入!$C$5:$C$4999,$A10,数据录入!$B$5:$B$4999,AA$6)) -> 0 | AB10: =IF(OR($A10="",AB$6="",NOT(ISNUMBER($H$2))),"",SUMIFS(数据录入!$G$5:$G$4999,数据录入!$C$5:$C$4999,$A10,数据录入!$B$5:$B$4999,AB$6)) -> 0 | AC10: =IF(OR($A10="",AC$6="",NOT(ISNUMBER($H$2))),"",SUMIFS(数据录入!$F$5:$F$4999,数据录入!$C$5:$C$4999,$A10,数据录入!$B$5:$B$4999,AC$6)) -> 0 | AD10: =IF(OR($A10="",AD$6="",NOT(ISNUMBER($H$2))),"",SUMIFS(数据录入!$G$5:$G$4999,数据录入!$C$5:$C$4999,$A10,数据录入!$B$5:$B$4999,AD$6)) -> 0 | AE10: =IF(OR($A10="",AE$6="",NOT(ISNUMBER($H$2))),"",SUMIFS(数据录入!$F$5:$F$4999,数据录入!$C$5:$C$4999,$A10,数据录入!$B$5:$B$4999,AE$6)) -> 0 | AF10: =IF(OR($A10="",AF$6="",NOT(ISNUMBER($H$2))),"",SUMIFS(数据录入!$G$5:$G$4999,数据录入!$C$5:$C$4999,$A10,数据录入!$B$5:$B$4999,AF$6)) -> 0 | AG10: =IF(OR($A10="",AG$6="",NOT(ISNUMBER($H$2))),"",SUMIFS(数据录入!$F$5:$F$4999,数据录入!$C$5:$C$4999,$A10,数据录入!$B$5:$B$4999,AG$6)) -> 0 | AH10: =IF(OR($A10="",AH$6="",NOT(ISNUMBER($H$2))),"",SUMIFS(数据录入!$G$5:$G$4999,数据录入!$C$5:$C$4999,$A10,数据录入!$B$5:$B$4999,AH$6)) -> 0 | AI10: =IF(OR($A10="",AI$6="",NOT(ISNUMBER($H$2))),"",SUMIFS(数据录入!$F$5:$F$4999,数据录入!$C$5:$C$4999,$A10,数据录入!$B$5:$B$4999,AI$6)) -> 0 | AJ10: =IF(OR($A10="",AJ$6="",NOT(ISNUMBER($H$2))),"",SUMIFS(数据录入!$G$5:$G$4999,数据录入!$C$5:$C$4999,$A10,数据录入!$B$5:$B$4999,AJ$6)) -> 0 | AK10: =IF(OR($A10="",AK$6="",NOT(ISNUMBER($H$2))),"",SUMIFS(数据录入!$F$5:$F$4999,数据录入!$C$5:$C$4999,$A10,数据录入!$B$5:$B$4999,AK$6)) -> 0 | AL10: =IF(OR($A10="",AL$6="",NOT(ISNUMBER($H$2))),"",SUMIFS(数据录入!$G$5:$G$4999,数据录入!$C$5:$C$4999,$A10,数据录入!$B$5:$B$4999,AL$6)) -> 0 | AM10: =IF(OR($A10="",AM$6="",NOT(ISNUMBER($H$2))),"",SUMIFS(数据录入!$F$5:$F$4999,数据录入!$C$5:$C$4999,$A10,数据录入!$B$5:$B$4999,AM$6)) -> 0 | AN10: =IF(OR($A10="",AN$6="",NOT(ISNUMBER($H$2))),"",SUMIFS(数据录入!$G$5:$G$4999,数据录入!$C$5:$C$4999,$A10,数据录入!$B$5:$B$4999,AN$6)) -> 0 | AO10: =IF(OR($A10="",AO$6="",NOT(ISNUMBER($H$2))),"",SUMIFS(数据录入!$F$5:$F$4999,数据录入!$C$5:$C$4999,$A10,数据录入!$B$5:$B$4999,AO$6)) -> 0 | AP10: =IF(OR($A10="",AP$6="",NOT(ISNUMBER($H$2))),"",SUMIFS(数据录入!$G$5:$G$4999,数据录入!$C$5:$C$4999,$A10,数据录入!$B$5:$B$4999,AP$6)) -> 0 | AQ10: =IF(OR($A10="",AQ$6="",NOT(ISNUMBER($H$2))),"",SUMIFS(数据录入!$F$5:$F$4999,数据录入!$C$5:$C$4999,$A10,数据录入!$B$5:$B$4999,AQ$6)) -> 0 | AR10: =IF(OR($A10="",AR$6="",NOT(ISNUMBER($H$2))),"",SUMIFS(数据录入!$G$5:$G$4999,数据录入!$C$5:$C$4999,$A10,数据录入!$B$5:$B$4999,AR$6)) -> 0 | AS10: =IF(OR($A10="",AS$6="",NOT(ISNUMBER($H$2))),"",SUMIFS(数据录入!$F$5:$F$4999,数据录入!$C$5:$C$4999,$A10,数据录入!$B$5:$B$4999,AS$6)) -> 0 | AT10: =IF(OR($A10="",AT$6="",NOT(ISNUMBER($H$2))),"",SUMIFS(数据录入!$G$5:$G$4999,数据录入!$C$5:$C$4999,$A10,数据录入!$B$5:$B$4999,AT$6)) -> 0 | AU10: =IF(OR($A10="",AU$6="",NOT(ISNUMBER($H$2))),"",SUMIFS(数据录入!$F$5:$F$4999,数据录入!$C$5:$C$4999,$A10,数据录入!$B$5:$B$4999,AU$6)) -> 0 | AV10: =IF(OR($A10="",AV$6="",NOT(ISNUMBER($H$2))),"",SUMIFS(数据录入!$G$5:$G$4999,数据录入!$C$5:$C$4999,$A10,数据录入!$B$5:$B$4999,AV$6)) -> 0 | AW10: =IF(OR($A10="",AW$6="",NOT(ISNUMBER($H$2))),"",SUMIFS(数据录入!$F$5:$F$4999,数据录入!$C$5:$C$4999,$A10,数据录入!$B$5:$B$4999,AW$6)) -> 0 | AX10: =IF(OR($A10="",AX$6="",NOT(ISNUMBER($H$2))),"",SUMIFS(数据录入!$G$5:$G$4999,数据录入!$C$5:$C$4999,$A10,数据录入!$B$5:$B$4999,AX$6)) -> 0 | AY10: =IF(OR($A10="",AY$6="",NOT(ISNUMBER($H$2))),"",SUMIFS(数据录入!$F$5:$F$4999,数据录入!$C$5:$C$4999,$A10,数据录入!$B$5:$B$4999,AY$6)) -> 0 | AZ10: =IF(OR($A10="",AZ$6="",NOT(ISNUMBER($H$2))),"",SUMIFS(数据录入!$G$5:$G$4999,数据录入!$C$5:$C$4999,$A10,数据录入!$B$5:$B$4999,AZ$6)) -> 0 | BA10: =IF(OR($A10="",BA$6="",NOT(ISNUMBER($H$2))),"",SUMIFS(数据录入!$F$5:$F$4999,数据录入!$C$5:$C$4999,$A10,数据录入!$B$5:$B$4999,BA$6)) -> 0 | BB10: =IF(OR($A10="",BB$6="",NOT(ISNUMBER($H$2))),"",SUMIFS(数据录入!$G$5:$G$4999,数据录入!$C$5:$C$4999,$A10,数据录入!$B$5:$B$4999,BB$6)) -> 0 | BC10: =IF(OR($A10="",BC$6="",NOT(ISNUMBER($H$2))),"",SUMIFS(数据录入!$F$5:$F$4999,数据录入!$C$5:$C$4999,$A10,数据录入!$B$5:$B$4999,BC$6)) -> 0 | BD10: =IF(OR($A10="",BD$6="",NOT(ISNUMBER($H$2))),"",SUMIFS(数据录入!$G$5:$G$4999,数据录入!$C$5:$C$4999,$A10,数据录入!$B$5:$B$4999,BD$6)) -> 0 | BE10: =IF(OR($A10="",BE$6="",NOT(ISNUMBER($H$2))),"",SUMIFS(数据录入!$F$5:$F$4999,数据录入!$C$5:$C$4999,$A10,数据录入!$B$5:$B$4999,BE$6)) -> 0 | BF10: =IF(OR($A10="",BF$6="",NOT(ISNUMBER($H$2))),"",SUMIFS(数据录入!$G$5:$G$4999,数据录入!$C$5:$C$4999,$A10,数据录入!$B$5:$B$4999,BF$6)) -> 0 | BG10: =IF(OR($A10="",BG$6="",NOT(ISNUMBER($H$2))),"",SUMIFS(数据录入!$F$5:$F$4999,数据录入!$C$5:$C$4999,$A10,数据录入!$B$5:$B$4999,BG$6)) -> 0 | BH10: =IF(OR($A10="",BH$6="",NOT(ISNUMBER($H$2))),"",SUMIFS(数据录入!$G$5:$G$4999,数据录入!$C$5:$C$4999,$A10,数据录入!$B$5:$B$4999,BH$6)) -> 0 | BI10: =IF(OR($A10="",BI$6="",NOT(ISNUMBER($H$2))),"",SUMIFS(数据录入!$F$5:$F$4999,数据录入!$C$5:$C$4999,$A10,数据录入!$B$5:$B$4999,BI$6)) -> 0 | BJ10: =IF(OR($A10="",BJ$6="",NOT(ISNUMBER($H$2))),"",SUMIFS(数据录入!$G$5:$G$4999,数据录入!$C$5:$C$4999,$A10,数据录入!$B$5:$B$4999,BJ$6)) -> 0 | BK10: =IF(OR($A10="",BK$6="",NOT(ISNUMBER($H$2))),"",SUMIFS(数据录入!$F$5:$F$4999,数据录入!$C$5:$C$4999,$A10,数据录入!$B$5:$B$4999,BK$6)) | BL10: =IF(OR($A10="",BL$6="",NOT(ISNUMBER($H$2))),"",SUMIFS(数据录入!$G$5:$G$4999,数据录入!$C$5:$C$4999,$A10,数据录入!$B$5:$B$4999,BL$6)) | BM10: =IF($A10="","",SUMIF($C$7:$BL$7,"收款",C10:BL10)) -> 0 | BN10: =IF($A10="","",SUMIF($C$7:$BL$7,"付款",C10:BL10)) -> 800 | BO10: =IF($A10="","",B10+BM10-BN10) -> -800
A11: 杭州 | B11: =IF(OR($A11="",NOT(ISNUMBER($H$2))),"",SUMIFS(数据录入!$H$5:$H$4999,数据录入!$C$5:$C$4999,$A11,数据录入!$E$5:$E$4999,"期初余额",数据录入!$B$5:$B$4999,"<="&$B$2)+SUMIFS(数据录入!$F$5:$F$4999,数据录入!$C$5:$C$4999,$A11,数据录入!$B$5:$B$4999,"<"&$B$2)-SUMIFS(数据录入!$G$5:$G$4999,数据录入!$C$5:$C$4999,$A11,数据录入!$B$5:$B$4999,"<"&$B$2)) -> 0 | C11: =IF(OR($A11="",C$6="",NOT(ISNUMBER($H$2))),"",SUMIFS(数据录入!$F$5:$F$4999,数据录入!$C$5:$C$4999,$A11,数据录入!$B$5:$B$4999,C$6)) -> 5000 | D11: =IF(OR($A11="",D$6="",NOT(ISNUMBER($H$2))),"",SUMIFS(数据录入!$G$5:$G$4999,数据录入!$C$5:$C$4999,$A11,数据录入!$B$5:$B$4999,D$6)) -> 500 | E11: =IF(OR($A11="",E$6="",NOT(ISNUMBER($H$2))),"",SUMIFS(数据录入!$F$5:$F$4999,数据录入!$C$5:$C$4999,$A11,数据录入!$B$5:$B$4999,E$6)) -> 0 | F11: =IF(OR($A11="",F$6="",NOT(ISNUMBER($H$2))),"",SUMIFS(数据录入!$G$5:$G$4999,数据录入!$C$5:$C$4999,$A11,数据录入!$B$5:$B$4999,F$6)) -> 0 | G11: =IF(OR($A11="",G$6="",NOT(ISNUMBER($H$2))),"",SUMIFS(数据录入!$F$5:$F$4999,数据录入!$C$5:$C$4999,$A11,数据录入!$B$5:$B$4999,G$6)) -> 0 | H11: =IF(OR($A11="",H$6="",NOT(ISNUMBER($H$2))),"",SUMIFS(数据录入!$G$5:$G$4999,数据录入!$C$5:$C$4999,$A11,数据录入!$B$5:$B$4999,H$6)) -> 0 | I11: =IF(OR($A11="",I$6="",NOT(ISNUMBER($H$2))),"",SUMIFS(数据录入!$F$5:$F$4999,数据录入!$C$5:$C$4999,$A11,数据录入!$B$5:$B$4999,I$6)) -> 0 | J11: =IF(OR($A11="",J$6="",NOT(ISNUMBER($H$2))),"",SUMIFS(数据录入!$G$5:$G$4999,数据录入!$C$5:$C$4999,$A11,数据录入!$B$5:$B$4999,J$6)) -> 0 | K11: =IF(OR($A11="",K$6="",NOT(ISNUMBER($H$2))),"",SUMIFS(数据录入!$F$5:$F$4999,数据录入!$C$5:$C$4999,$A11,数据录入!$B$5:$B$4999,K$6)) -> 0 | L11: =IF(OR($A11="",L$6="",NOT(ISNUMBER($H$2))),"",SUMIFS(数据录入!$G$5:$G$4999,数据录入!$C$5:$C$4999,$A11,数据录入!$B$5:$B$4999,L$6)) -> 0 | M11: =IF(OR($A11="",M$6="",NOT(ISNUMBER($H$2))),"",SUMIFS(数据录入!$F$5:$F$4999,数据录入!$C$5:$C$4999,$A11,数据录入!$B$5:$B$4999,M$6)) -> 0 | N11: =IF(OR($A11="",N$6="",NOT(ISNUMBER($H$2))),"",SUMIFS(数据录入!$G$5:$G$4999,数据录入!$C$5:$C$4999,$A11,数据录入!$B$5:$B$4999,N$6)) -> 0 | O11: =IF(OR($A11="",O$6="",NOT(ISNUMBER($H$2))),"",SUMIFS(数据录入!$F$5:$F$4999,数据录入!$C$5:$C$4999,$A11,数据录入!$B$5:$B$4999,O$6)) -> 0 | P11: =IF(OR($A11="",P$6="",NOT(ISNUMBER($H$2))),"",SUMIFS(数据录入!$G$5:$G$4999,数据录入!$C$5:$C$4999,$A11,数据录入!$B$5:$B$4999,P$6)) -> 0 | Q11: =IF(OR($A11="",Q$6="",NOT(ISNUMBER($H$2))),"",SUMIFS(数据录入!$F$5:$F$4999,数据录入!$C$5:$C$4999,$A11,数据录入!$B$5:$B$4999,Q$6)) -> 0 | R11: =IF(OR($A11="",R$6="",NOT(ISNUMBER($H$2))),"",SUMIFS(数据录入!$G$5:$G$4999,数据录入!$C$5:$C$4999,$A11,数据录入!$B$5:$B$4999,R$6)) -> 0 | S11: =IF(OR($A11="",S$6="",NOT(ISNUMBER($H$2))),"",SUMIFS(数据录入!$F$5:$F$4999,数据录入!$C$5:$C$4999,$A11,数据录入!$B$5:$B$4999,S$6)) -> 0 | T11: =IF(OR($A11="",T$6="",NOT(ISNUMBER($H$2))),"",SUMIFS(数据录入!$G$5:$G$4999,数据录入!$C$5:$C$4999,$A11,数据录入!$B$5:$B$4999,T$6)) -> 0 | U11: =IF(OR($A11="",U$6="",NOT(ISNUMBER($H$2))),"",SUMIFS(数据录入!$F$5:$F$4999,数据录入!$C$5:$C$4999,$A11,数据录入!$B$5:$B$4999,U$6)) -> 0 | V11: =IF(OR($A11="",V$6="",NOT(ISNUMBER($H$2))),"",SUMIFS(数据录入!$G$5:$G$4999,数据录入!$C$5:$C$4999,$A11,数据录入!$B$5:$B$4999,V$6)) -> 0 | W11: =IF(OR($A11="",W$6="",NOT(ISNUMBER($H$2))),"",SUMIFS(数据录入!$F$5:$F$4999,数据录入!$C$5:$C$4999,$A11,数据录入!$B$5:$B$4999,W$6)) -> 0 | X11: =IF(OR($A11="",X$6="",NOT(ISNUMBER($H$2))),"",SUMIFS(数据录入!$G$5:$G$4999,数据录入!$C$5:$C$4999,$A11,数据录入!$B$5:$B$4999,X$6)) -> 0 | Y11: =IF(OR($A11="",Y$6="",NOT(ISNUMBER($H$2))),"",SUMIFS(数据录入!$F$5:$F$4999,数据录入!$C$5:$C$4999,$A11,数据录入!$B$5:$B$4999,Y$6)) -> 0 | Z11: =IF(OR($A11="",Z$6="",NOT(ISNUMBER($H$2))),"",SUMIFS(数据录入!$G$5:$G$4999,数据录入!$C$5:$C$4999,$A11,数据录入!$B$5:$B$4999,Z$6)) -> 0 | AA11: =IF(OR($A11="",AA$6="",NOT(ISNUMBER($H$2))),"",SUMIFS(数据录入!$F$5:$F$4999,数据录入!$C$5:$C$4999,$A11,数据录入!$B$5:$B$4999,AA$6)) -> 0 | AB11: =IF(OR($A11="",AB$6="",NOT(ISNUMBER($H$2))),"",SUMIFS(数据录入!$G$5:$G$4999,数据录入!$C$5:$C$4999,$A11,数据录入!$B$5:$B$4999,AB$6)) -> 0 | AC11: =IF(OR($A11="",AC$6="",NOT(ISNUMBER($H$2))),"",SUMIFS(数据录入!$F$5:$F$4999,数据录入!$C$5:$C$4999,$A11,数据录入!$B$5:$B$4999,AC$6)) -> 0 | AD11: =IF(OR($A11="",AD$6="",NOT(ISNUMBER($H$2))),"",SUMIFS(数据录入!$G$5:$G$4999,数据录入!$C$5:$C$4999,$A11,数据录入!$B$5:$B$4999,AD$6)) -> 0 | AE11: =IF(OR($A11="",AE$6="",NOT(ISNUMBER($H$2))),"",SUMIFS(数据录入!$F$5:$F$4999,数据录入!$C$5:$C$4999,$A11,数据录入!$B$5:$B$4999,AE$6)) -> 0 | AF11: =IF(OR($A11="",AF$6="",NOT(ISNUMBER($H$2))),"",SUMIFS(数据录入!$G$5:$G$4999,数据录入!$C$5:$C$4999,$A11,数据录入!$B$5:$B$4999,AF$6)) -> 0 | AG11: =IF(OR($A11="",AG$6="",NOT(ISNUMBER($H$2))),"",SUMIFS(数据录入!$F$5:$F$4999,数据录入!$C$5:$C$4999,$A11,数据录入!$B$5:$B$4999,AG$6)) -> 0 | AH11: =IF(OR($A11="",AH$6="",NOT(ISNUMBER($H$2))),"",SUMIFS(数据录入!$G$5:$G$4999,数据录入!$C$5:$C$4999,$A11,数据录入!$B$5:$B$4999,AH$6)) -> 0 | AI11: =IF(OR($A11="",AI$6="",NOT(ISNUMBER($H$2))),"",SUMIFS(数据录入!$F$5:$F$4999,数据录入!$C$5:$C$4999,$A11,数据录入!$B$5:$B$4999,AI$6)) -> 0 | AJ11: =IF(OR($A11="",AJ$6="",NOT(ISNUMBER($H$2))),"",SUMIFS(数据录入!$G$5:$G$4999,数据录入!$C$5:$C$4999,$A11,数据录入!$B$5:$B$4999,AJ$6)) -> 0 | AK11: =IF(OR($A11="",AK$6="",NOT(ISNUMBER($H$2))),"",SUMIFS(数据录入!$F$5:$F$4999,数据录入!$C$5:$C$4999,$A11,数据录入!$B$5:$B$4999,AK$6)) -> 0 | AL11: =IF(OR($A11="",AL$6="",NOT(ISNUMBER($H$2))),"",SUMIFS(数据录入!$G$5:$G$4999,数据录入!$C$5:$C$4999,$A11,数据录入!$B$5:$B$4999,AL$6)) -> 0 | AM11: =IF(OR($A11="",AM$6="",NOT(ISNUMBER($H$2))),"",SUMIFS(数据录入!$F$5:$F$4999,数据录入!$C$5:$C$4999,$A11,数据录入!$B$5:$B$4999,AM$6)) -> 0 | AN11: =IF(OR($A11="",AN$6="",NOT(ISNUMBER($H$2))),"",SUMIFS(数据录入!$G$5:$G$4999,数据录入!$C$5:$C$4999,$A11,数据录入!$B$5:$B$4999,AN$6)) -> 0 | AO11: =IF(OR($A11="",AO$6="",NOT(ISNUMBER($H$2))),"",SUMIFS(数据录入!$F$5:$F$4999,数据录入!$C$5:$C$4999,$A11,数据录入!$B$5:$B$4999,AO$6)) -> 0 | AP11: =IF(OR($A11="",AP$6="",NOT(ISNUMBER($H$2))),"",SUMIFS(数据录入!$G$5:$G$4999,数据录入!$C$5:$C$4999,$A11,数据录入!$B$5:$B$4999,AP$6)) -> 0 | AQ11: =IF(OR($A11="",AQ$6="",NOT(ISNUMBER($H$2))),"",SUMIFS(数据录入!$F$5:$F$4999,数据录入!$C$5:$C$4999,$A11,数据录入!$B$5:$B$4999,AQ$6)) -> 0 | AR11: =IF(OR($A11="",AR$6="",NOT(ISNUMBER($H$2))),"",SUMIFS(数据录入!$G$5:$G$4999,数据录入!$C$5:$C$4999,$A11,数据录入!$B$5:$B$4999,AR$6)) -> 0 | AS11: =IF(OR($A11="",AS$6="",NOT(ISNUMBER($H$2))),"",SUMIFS(数据录入!$F$5:$F$4999,数据录入!$C$5:$C$4999,$A11,数据录入!$B$5:$B$4999,AS$6)) -> 0 | AT11: =IF(OR($A11="",AT$6="",NOT(ISNUMBER($H$2))),"",SUMIFS(数据录入!$G$5:$G$4999,数据录入!$C$5:$C$4999,$A11,数据录入!$B$5:$B$4999,AT$6)) -> 0 | AU11: =IF(OR($A11="",AU$6="",NOT(ISNUMBER($H$2))),"",SUMIFS(数据录入!$F$5:$F$4999,数据录入!$C$5:$C$4999,$A11,数据录入!$B$5:$B$4999,AU$6)) -> 0 | AV11: =IF(OR($A11="",AV$6="",NOT(ISNUMBER($H$2))),"",SUMIFS(数据录入!$G$5:$G$4999,数据录入!$C$5:$C$4999,$A11,数据录入!$B$5:$B$4999,AV$6)) -> 0 | AW11: =IF(OR($A11="",AW$6="",NOT(ISNUMBER($H$2))),"",SUMIFS(数据录入!$F$5:$F$4999,数据录入!$C$5:$C$4999,$A11,数据录入!$B$5:$B$4999,AW$6)) -> 0 | AX11: =IF(OR($A11="",AX$6="",NOT(ISNUMBER($H$2))),"",SUMIFS(数据录入!$G$5:$G$4999,数据录入!$C$5:$C$4999,$A11,数据录入!$B$5:$B$4999,AX$6)) -> 0 | AY11: =IF(OR($A11="",AY$6="",NOT(ISNUMBER($H$2))),"",SUMIFS(数据录入!$F$5:$F$4999,数据录入!$C$5:$C$4999,$A11,数据录入!$B$5:$B$4999,AY$6)) -> 0 | AZ11: =IF(OR($A11="",AZ$6="",NOT(ISNUMBER($H$2))),"",SUMIFS(数据录入!$G$5:$G$4999,数据录入!$C$5:$C$4999,$A11,数据录入!$B$5:$B$4999,AZ$6)) -> 0 | BA11: =IF(OR($A11="",BA$6="",NOT(ISNUMBER($H$2))),"",SUMIFS(数据录入!$F$5:$F$4999,数据录入!$C$5:$C$4999,$A11,数据录入!$B$5:$B$4999,BA$6)) -> 0 | BB11: =IF(OR($A11="",BB$6="",NOT(ISNUMBER($H$2))),"",SUMIFS(数据录入!$G$5:$G$4999,数据录入!$C$5:$C$4999,$A11,数据录入!$B$5:$B$4999,BB$6)) -> 0 | BC11: =IF(OR($A11="",BC$6="",NOT(ISNUMBER($H$2))),"",SUMIFS(数据录入!$F$5:$F$4999,数据录入!$C$5:$C$4999,$A11,数据录入!$B$5:$B$4999,BC$6)) -> 0 | BD11: =IF(OR($A11="",BD$6="",NOT(ISNUMBER($H$2))),"",SUMIFS(数据录入!$G$5:$G$4999,数据录入!$C$5:$C$4999,$A11,数据录入!$B$5:$B$4999,BD$6)) -> 0 | BE11: =IF(OR($A11="",BE$6="",NOT(ISNUMBER($H$2))),"",SUMIFS(数据录入!$F$5:$F$4999,数据录入!$C$5:$C$4999,$A11,数据录入!$B$5:$B$4999,BE$6)) -> 0 | BF11: =IF(OR($A11="",BF$6="",NOT(ISNUMBER($H$2))),"",SUMIFS(数据录入!$G$5:$G$4999,数据录入!$C$5:$C$4999,$A11,数据录入!$B$5:$B$4999,BF$6)) -> 0 | BG11: =IF(OR($A11="",BG$6="",NOT(ISNUMBER($H$2))),"",SUMIFS(数据录入!$F$5:$F$4999,数据录入!$C$5:$C$4999,$A11,数据录入!$B$5:$B$4999,BG$6)) -> 0 | BH11: =IF(OR($A11="",BH$6="",NOT(ISNUMBER($H$2))),"",SUMIFS(数据录入!$G$5:$G$4999,数据录入!$C$5:$C$4999,$A11,数据录入!$B$5:$B$4999,BH$6)) -> 0 | BI11: =IF(OR($A11="",BI$6="",NOT(ISNUMBER($H$2))),"",SUMIFS(数据录入!$F$5:$F$4999,数据录入!$C$5:$C$4999,$A11,数据录入!$B$5:$B$4999,BI$6)) -> 0 | BJ11: =IF(OR($A11="",BJ$6="",NOT(ISNUMBER($H$2))),"",SUMIFS(数据录入!$G$5:$G$4999,数据录入!$C$5:$C$4999,$A11,数据录入!$B$5:$B$4999,BJ$6)) -> 0 | BK11: =IF(OR($A11="",BK$6="",NOT(ISNUMBER($H$2))),"",SUMIFS(数据录入!$F$5:$F$4999,数据录入!$C$5:$C$4999,$A11,数据录入!$B$5:$B$4999,BK$6)) | BL11: =IF(OR($A11="",BL$6="",NOT(ISNUMBER($H$2))),"",SUMIFS(数据录入!$G$5:$G$4999,数据录入!$C$5:$C$4999,$A11,数据录入!$B$5:$B$4999,BL$6)) | BM11: =IF($A11="","",SUMIF($C$7:$BL$7,"收款",C11:BL11)) -> 5000 | BN11: =IF($A11="","",SUMIF($C$7:$BL$7,"付款",C11:BL11)) -> 500 | BO11: =IF($A11="","",B11+BM11-BN11) -> 4500
