Workbook

Sheet 首页
A1: 内帐财务管理系统 · 稳定重构版
A2: 日常只录：资金流水 + 销售录入 + 采购录入；其他报表自动生成。
A4: 查询月份 | B4: 46174
A5: 本月销售额 | D5: 客户回款 | G5: 本月毛利 | J5: 本月净利润
A6: =SUMIFS(销售录入!$I$4:$I$203,销售录入!$B$4:$B$203,TEXT($B$4,"yyyy-mm")) -> 26080 | D6: =SUMIFS(资金流水!$J$4:$J$203,资金流水!$D$4:$D$203,"客户回款",资金流水!$B$4:$B$203,TEXT($B$4,"yyyy-mm")) -> 20000 | G6: =库存收发存!M3 -> 13040 | J6: =利润表!C27 -> -8360
A9: 当前资金 | D9: 应收余额 | G9: 逾期应收 | J9: 应付余额
A10: =账户余额!H55 -> 848600 | D10: =应收跟进!F3 -> 164080 | G10: =应收跟进!L3 -> 138000 | J10: =应付跟进!F3 -> 220300
A13: 未来30天应付 | D13: 库存金额 | G13: 资金安全余量 | J13: 勾稽状态
A14: =应付跟进!G3 -> 16500 | D14: =库存收发存!J3 -> 107260 | G14: =账户余额!H55-应付跟进!G3 -> 832100 | J14: =财务勾稽核查!E15 -> 全部正常，可月结
A18: 日常入口：资金流水 ｜ 销售录入 ｜ 采购录入 月末检查：财务勾稽核查 ｜ 利润表 ｜ 资产负债表

Sheet 基础资料
A1: 基础资料（统一维护）
A2: 各模块横向并列维护；新增资料直接在对应模块下方继续录入。
A3: 资金账户 | F3: 部门 | J3: 员工 | O3: 商品档案 | X3: 客户档案 | AD3: 供应商档案 | AJ3: 资金流水分类 | AO3: 会计科目及报表映射
A4: 账户名称 | B4: 账户类型 | C4: 资金科目 | D4: 状态 | F4: 部门名称 | G4: 状态 | H4: 备注 | J4: 员工姓名 | K4: 部门 | L4: 岗位 | M4: 状态 | O4: 商品编号 | P4: 商品名称 | Q4: 规格型号 | R4: 单位 | S4: 状态 | T4: 参考成本 | U4: 参考售价 | V4: 备注 | W4: 库存显示 | X4: 客户编号 | Y4: 客户名称 | Z4: 业务员 | AA4: 账期(天) | AB4: 状态 | AD4: 供应商编号 | AE4: 供应商名称 | AF4: 采购员 | AG4: 账期(天) | AH4: 状态 | AJ4: 收支类型 | AK4: 收支科目 | AL4: 建议借方科目 | AM4: 建议贷方科目 | AO4: 科目编码 | AP4: 科目名称 | AQ4: 科目类别 | AR4: 余额方向 | AS4: 启用状态 | AT4: 资产负债表项目 | AU4: 利润表项目 | AV4: 现金流性质 | AW4: 辅助核算
A5: 现金 | B5: 现金类 | C5: 1001 | D5: 正常 | F5: 销售部 | G5: 正常 | J5: 张伟 | K5: 销售部 | L5: 销售 | M5: 正常 | O5: P001 | P5: A配件 | Q5: A-01 | R5: 个 | S5: 正常 | T5: 100 | U5: 200 | W5: =IF(P5="","",IF(SUMIFS(期初数据!$S$5:$S$14,期初数据!$P$5:$P$14,P5)+SUMIFS(采购录入!$G$4:$G$203,采购录入!$D$4:$D$203,P5,采购录入!$A$4:$A$203,"<="&EOMONTH(首页!$B$4,0))-SUMIFS(销售录入!$G$4:$G$203,销售录入!$D$4:$D$203,P5,销售录入!$A$4:$A$203,"<="&EOMONTH(首页!$B$4,0))<>0,"显示",IF(COUNTIFS(采购录入!$D$4:$D$203,P5,采购录入!$B$4:$B$203,TEXT(首页!$B$4,"yyyy-mm"))+COUNTIFS(销售录入!$D$4:$D$203,P5,销售录入!$B$4:$B$203,TEXT(首页!$B$4,"yyyy-mm"))>0,"显示",""))) -> 显示 | X5: C001 | Y5: 客户A | Z5: 张伟 | AA5: 30 | AB5: 正常 | AD5: S001 | AE5: 供应商A | AF5: 王强 | AG5: 30 | AH5: 正常 | AJ5: 收入 | AK5: 客户回款 | AL5: 1002 | AM5: 1122 | AO5: 1001 | AP5: 库存现金 | AQ5: 资产 | AR5: 借 | AS5: 启用 | AT5: 货币资金 | AV5: 非现金/资产负债 | AW5: 无
A6: 工商银行 | B6: 银行类 | C6: 1002 | D6: 正常 | F6: 财务部 | G6: 正常 | J6: 李娜 | K6: 销售部 | L6: 销售 | M6: 正常 | O6: P002 | P6: B配件 | Q6: B-02 | R6: 个 | S6: 正常 | T6: 125 | U6: 250 | W6: =IF(P6="","",IF(SUMIFS(期初数据!$S$5:$S$14,期初数据!$P$5:$P$14,P6)+SUMIFS(采购录入!$G$4:$G$203,采购录入!$D$4:$D$203,P6,采购录入!$A$4:$A$203,"<="&EOMONTH(首页!$B$4,0))-SUMIFS(销售录入!$G$4:$G$203,销售录入!$D$4:$D$203,P6,销售录入!$A$4:$A$203,"<="&EOMONTH(首页!$B$4,0))<>0,"显示",IF(COUNTIFS(采购录入!$D$4:$D$203,P6,采购录入!$B$4:$B$203,TEXT(首页!$B$4,"yyyy-mm"))+COUNTIFS(销售录入!$D$4:$D$203,P6,销售录入!$B$4:$B$203,TEXT(首页!$B$4,"yyyy-mm"))>0,"显示",""))) -> 显示 | X6: C002 | Y6: 客户B | Z6: 李娜 | AA6: 30 | AB6: 正常 | AD6: S002 | AE6: 供应商B | AF6: 王强 | AG6: 30 | AH6: 正常 | AJ6: 收入 | AK6: 服务收入 | AL6: 1002 | AM6: 6051 | AO6: 1002 | AP6: 银行存款 | AQ6: 资产 | AR6: 借 | AS6: 启用 | AT6: 货币资金 | AV6: 非现金/资产负债 | AW6: 无
A7: 农业银行 | B7: 银行类 | C7: 1002 | D7: 正常 | F7: 行政部 | G7: 正常 | J7: 王强 | K7: 采购部 | L7: 采购 | M7: 正常 | O7: P003 | P7: C配件 | Q7: C-03 | R7: 个 | S7: 正常 | T7: 50 | U7: 100 | W7: =IF(P7="","",IF(SUMIFS(期初数据!$S$5:$S$14,期初数据!$P$5:$P$14,P7)+SUMIFS(采购录入!$G$4:$G$203,采购录入!$D$4:$D$203,P7,采购录入!$A$4:$A$203,"<="&EOMONTH(首页!$B$4,0))-SUMIFS(销售录入!$G$4:$G$203,销售录入!$D$4:$D$203,P7,销售录入!$A$4:$A$203,"<="&EOMONTH(首页!$B$4,0))<>0,"显示",IF(COUNTIFS(采购录入!$D$4:$D$203,P7,采购录入!$B$4:$B$203,TEXT(首页!$B$4,"yyyy-mm"))+COUNTIFS(销售录入!$D$4:$D$203,P7,销售录入!$B$4:$B$203,TEXT(首页!$B$4,"yyyy-mm"))>0,"显示",""))) -> 显示 | X7: C003 | Y7: 客户C | Z7: 张伟 | AA7: 45 | AB7: 正常 | AD7: S003 | AE7: 供应商C | AF7: 王强 | AG7: 45 | AH7: 正常 | AJ7: 收入 | AK7: 其他业务收入 | AL7: 1002 | AM7: 6051 | AO7: 1012 | AP7: 其他货币资金 | AQ7: 资产 | AR7: 借 | AS7: 启用 | AT7: 货币资金 | AV7: 非现金/资产负债 | AW7: 无
A8: 建设银行 | B8: 银行类 | C8: 1002 | D8: 正常 | F8: 采购部 | G8: 正常 | J8: 陈敏 | K8: 行政部 | L8: 行政 | M8: 正常 | O8: P004 | P8: D配件 | Q8: D-04 | R8: 个 | S8: 正常 | T8: 200 | U8: 400 | W8: =IF(P8="","",IF(SUMIFS(期初数据!$S$5:$S$14,期初数据!$P$5:$P$14,P8)+SUMIFS(采购录入!$G$4:$G$203,采购录入!$D$4:$D$203,P8,采购录入!$A$4:$A$203,"<="&EOMONTH(首页!$B$4,0))-SUMIFS(销售录入!$G$4:$G$203,销售录入!$D$4:$D$203,P8,销售录入!$A$4:$A$203,"<="&EOMONTH(首页!$B$4,0))<>0,"显示",IF(COUNTIFS(采购录入!$D$4:$D$203,P8,采购录入!$B$4:$B$203,TEXT(首页!$B$4,"yyyy-mm"))+COUNTIFS(销售录入!$D$4:$D$203,P8,销售录入!$B$4:$B$203,TEXT(首页!$B$4,"yyyy-mm"))>0,"显示",""))) -> 显示 | X8: C004 | Y8: 客户D | Z8: 李娜 | AA8: 30 | AB8: 正常 | AD8: S004 | AE8: 供应商D | AF8: 王强 | AG8: 30 | AH8: 正常 | AJ8: 收入 | AK8: 利息收入 | AL8: 1002 | AM8: 6051 | AO8: 1101 | AP8: 交易性金融资产 | AQ8: 资产 | AR8: 借 | AS8: 启用 | AT8: 交易性金融资产 | AV8: 非现金/资产负债 | AW8: 无
A9: 招商银行 | B9: 银行类 | C9: 1002 | D9: 正常 | F9: 生产一部 | G9: 正常 | J9: 赵静 | K9: 财务部 | L9: 财务 | M9: 正常 | O9: P005 | P9: E配件 | Q9: E-05 | R9: 个 | S9: 正常 | T9: 25 | U9: 50 | W9: =IF(P9="","",IF(SUMIFS(期初数据!$S$5:$S$14,期初数据!$P$5:$P$14,P9)+SUMIFS(采购录入!$G$4:$G$203,采购录入!$D$4:$D$203,P9,采购录入!$A$4:$A$203,"<="&EOMONTH(首页!$B$4,0))-SUMIFS(销售录入!$G$4:$G$203,销售录入!$D$4:$D$203,P9,销售录入!$A$4:$A$203,"<="&EOMONTH(首页!$B$4,0))<>0,"显示",IF(COUNTIFS(采购录入!$D$4:$D$203,P9,采购录入!$B$4:$B$203,TEXT(首页!$B$4,"yyyy-mm"))+COUNTIFS(销售录入!$D$4:$D$203,P9,销售录入!$B$4:$B$203,TEXT(首页!$B$4,"yyyy-mm"))>0,"显示",""))) -> 显示 | X9: C005 | Y9: 客户E | Z9: 张伟 | AA9: 60 | AB9: 正常 | AD9: S005 | AE9: 供应商E | AF9: 王强 | AG9: 60 | AH9: 正常 | AJ9: 收入 | AK9: 租赁收入 | AL9: 1002 | AM9: 6051 | AO9: 1121 | AP9: 应收票据 | AQ9: 资产 | AR9: 借 | AS9: 启用 | AT9: 应收票据 | AV9: 非现金/资产负债 | AW9: 无
A10: 中国银行 | B10: 银行类 | C10: 1002 | D10: 正常 | F10: 生产二部 | G10: 正常 | J10: 刘洋 | K10: 仓储部 | L10: 仓储 | M10: 正常 | O10: P006 | P10: F配件 | Q10: F-06 | R10: 个 | S10: 正常 | T10: 80 | U10: 160 | W10: =IF(P10="","",IF(SUMIFS(期初数据!$S$5:$S$14,期初数据!$P$5:$P$14,P10)+SUMIFS(采购录入!$G$4:$G$203,采购录入!$D$4:$D$203,P10,采购录入!$A$4:$A$203,"<="&EOMONTH(首页!$B$4,0))-SUMIFS(销售录入!$G$4:$G$203,销售录入!$D$4:$D$203,P10,销售录入!$A$4:$A$203,"<="&EOMONTH(首页!$B$4,0))<>0,"显示",IF(COUNTIFS(采购录入!$D$4:$D$203,P10,采购录入!$B$4:$B$203,TEXT(首页!$B$4,"yyyy-mm"))+COUNTIFS(销售录入!$D$4:$D$203,P10,销售录入!$B$4:$B$203,TEXT(首页!$B$4,"yyyy-mm"))>0,"显示",""))) -> 显示 | X10: C006 | Y10: 客户F | Z10: 李娜 | AA10: 30 | AB10: 正常 | AD10: S006 | AE10: 供应商F | AF10: 王强 | AG10: 30 | AH10: 正常 | AJ10: 收入 | AK10: 废料收入 | AL10: 1002 | AM10: 6051 | AO10: 1122 | AP10: 应收账款 | AQ10: 资产 | AR10: 借 | AS10: 启用 | AT10: 应收账款 | AV10: 非现金/资产负债 | AW10: 客户
A11: 微信 | B11: 电子账户 | C11: 1002 | D11: 正常 | F11: 仓储部 | G11: 正常 | J11: 周磊 | K11: 生产一部 | L11: 生产 | M11: 正常 | O11: P007 | P11: G配件 | Q11: G-07 | R11: 个 | S11: 正常 | T11: 75 | U11: 150 | W11: =IF(P11="","",IF(SUMIFS(期初数据!$S$5:$S$14,期初数据!$P$5:$P$14,P11)+SUMIFS(采购录入!$G$4:$G$203,采购录入!$D$4:$D$203,P11,采购录入!$A$4:$A$203,"<="&EOMONTH(首页!$B$4,0))-SUMIFS(销售录入!$G$4:$G$203,销售录入!$D$4:$D$203,P11,销售录入!$A$4:$A$203,"<="&EOMONTH(首页!$B$4,0))<>0,"显示",IF(COUNTIFS(采购录入!$D$4:$D$203,P11,采购录入!$B$4:$B$203,TEXT(首页!$B$4,"yyyy-mm"))+COUNTIFS(销售录入!$D$4:$D$203,P11,销售录入!$B$4:$B$203,TEXT(首页!$B$4,"yyyy-mm"))>0,"显示",""))) -> 显示 | X11: C007 | Y11: 客户G | Z11: 张伟 | AA11: 45 | AB11: 正常 | AD11: S007 | AE11: 供应商G | AF11: 王强 | AG11: 45 | AH11: 正常 | AJ11: 收入 | AK11: 补贴收入 | AL11: 1002 | AM11: 6051 | AO11: 1123 | AP11: 预付账款 | AQ11: 资产 | AR11: 借 | AS11: 启用 | AT11: 预付款项 | AV11: 非现金/资产负债 | AW11: 供应商
A12: 支付宝 | B12: 电子账户 | C12: 1002 | D12: 正常 | F12: 电商部 | G12: 正常 | J12: 孙悦 | K12: 电商部 | L12: 电商 | M12: 正常 | O12: P008 | P12: H配件 | Q12: H-08 | R12: 个 | S12: 正常 | T12: 150 | U12: 300 | W12: =IF(P12="","",IF(SUMIFS(期初数据!$S$5:$S$14,期初数据!$P$5:$P$14,P12)+SUMIFS(采购录入!$G$4:$G$203,采购录入!$D$4:$D$203,P12,采购录入!$A$4:$A$203,"<="&EOMONTH(首页!$B$4,0))-SUMIFS(销售录入!$G$4:$G$203,销售录入!$D$4:$D$203,P12,销售录入!$A$4:$A$203,"<="&EOMONTH(首页!$B$4,0))<>0,"显示",IF(COUNTIFS(采购录入!$D$4:$D$203,P12,采购录入!$B$4:$B$203,TEXT(首页!$B$4,"yyyy-mm"))+COUNTIFS(销售录入!$D$4:$D$203,P12,销售录入!$B$4:$B$203,TEXT(首页!$B$4,"yyyy-mm"))>0,"显示",""))) -> 显示 | X12: C008 | Y12: 客户H | Z12: 李娜 | AA12: 30 | AB12: 正常 | AD12: S008 | AE12: 供应商H | AF12: 王强 | AG12: 30 | AH12: 正常 | AJ12: 收入 | AK12: 返点收入 | AL12: 1002 | AM12: 6051 | AO12: 1131 | AP12: 应收股利 | AQ12: 资产 | AR12: 借 | AS12: 启用 | AT12: 应收股利 | AV12: 非现金/资产负债 | AW12: 无
A13: 备用金 | B13: 现金类 | C13: 1001 | D13: 正常 | F13: 售后部 | G13: 正常 | J13: 吴刚 | K13: 售后部 | L13: 售后 | M13: 正常 | O13: P009 | P13: I配件 | Q13: I-09 | R13: 个 | S13: 正常 | T13: 30 | U13: 60 | W13: =IF(P13="","",IF(SUMIFS(期初数据!$S$5:$S$14,期初数据!$P$5:$P$14,P13)+SUMIFS(采购录入!$G$4:$G$203,采购录入!$D$4:$D$203,P13,采购录入!$A$4:$A$203,"<="&EOMONTH(首页!$B$4,0))-SUMIFS(销售录入!$G$4:$G$203,销售录入!$D$4:$D$203,P13,销售录入!$A$4:$A$203,"<="&EOMONTH(首页!$B$4,0))<>0,"显示",IF(COUNTIFS(采购录入!$D$4:$D$203,P13,采购录入!$B$4:$B$203,TEXT(首页!$B$4,"yyyy-mm"))+COUNTIFS(销售录入!$D$4:$D$203,P13,销售录入!$B$4:$B$203,TEXT(首页!$B$4,"yyyy-mm"))>0,"显示",""))) -> 显示 | X13: C009 | Y13: 客户I | Z13: 张伟 | AA13: 30 | AB13: 正常 | AD13: S009 | AE13: 供应商I | AF13: 王强 | AG13: 30 | AH13: 正常 | AJ13: 收入 | AK13: 手续费返还 | AL13: 1002 | AM13: 6051 | AO13: 1132 | AP13: 应收利息 | AQ13: 资产 | AR13: 借 | AS13: 启用 | AT13: 应收利息 | AV13: 非现金/资产负债 | AW13: 无
A14: 其他账户 | B14: 银行类 | C14: 1002 | D14: 正常 | F14: 管理层 | G14: 正常 | J14: 郑欣 | K14: 管理层 | L14: 管理 | M14: 正常 | O14: P010 | P14: J配件 | Q14: J-10 | R14: 个 | S14: 正常 | T14: 60 | U14: 120 | W14: =IF(P14="","",IF(SUMIFS(期初数据!$S$5:$S$14,期初数据!$P$5:$P$14,P14)+SUMIFS(采购录入!$G$4:$G$203,采购录入!$D$4:$D$203,P14,采购录入!$A$4:$A$203,"<="&EOMONTH(首页!$B$4,0))-SUMIFS(销售录入!$G$4:$G$203,销售录入!$D$4:$D$203,P14,销售录入!$A$4:$A$203,"<="&EOMONTH(首页!$B$4,0))<>0,"显示",IF(COUNTIFS(采购录入!$D$4:$D$203,P14,采购录入!$B$4:$B$203,TEXT(首页!$B$4,"yyyy-mm"))+COUNTIFS(销售录入!$D$4:$D$203,P14,销售录入!$B$4:$B$203,TEXT(首页!$B$4,"yyyy-mm"))>0,"显示",""))) -> 显示 | X14: C010 | Y14: 客户J | Z14: 李娜 | AA14: 60 | AB14: 正常 | AD14: S010 | AE14: 供应商J | AF14: 王强 | AG14: 60 | AH14: 正常 | AJ14: 收入 | AK14: 其他收入 | AL14: 1002 | AM14: 6051 | AO14: 1221 | AP14: 其他应收款 | AQ14: 资产 | AR14: 借 | AS14: 启用 | AT14: 其他应收款 | AV14: 非现金/资产负债 | AW14: 员工/其他
W15: =IF(P15="","",IF(SUMIFS(期初数据!$S$5:$S$14,期初数据!$P$5:$P$14,P15)+SUMIFS(采购录入!$G$4:$G$203,采购录入!$D$4:$D$203,P15,采购录入!$A$4:$A$203,"<="&EOMONTH(首页!$B$4,0))-SUMIFS(销售录入!$G$4:$G$203,销售录入!$D$4:$D$203,P15,销售录入!$A$4:$A$203,"<="&EOMONTH(首页!$B$4,0))<>0,"显示",IF(COUNTIFS(采购录入!$D$4:$D$203,P15,采购录入!$B$4:$B$203,TEXT(首页!$B$4,"yyyy-mm"))+COUNTIFS(销售录入!$D$4:$D$203,P15,销售录入!$B$4:$B$203,TEXT(首页!$B$4,"yyyy-mm"))>0,"显示",""))) | AJ15: 支出 | AK15: 供应商付款 | AL15: 2202 | AM15: 1002 | AO15: 1231 | AP15: 坏账准备 | AQ15: 资产 | AR15: 贷 | AS15: 启用 | AT15: 应收账款 | AV15: 非现金/资产负债 | AW15: 无
W16: =IF(P16="","",IF(SUMIFS(期初数据!$S$5:$S$14,期初数据!$P$5:$P$14,P16)+SUMIFS(采购录入!$G$4:$G$203,采购录入!$D$4:$D$203,P16,采购录入!$A$4:$A$203,"<="&EOMONTH(首页!$B$4,0))-SUMIFS(销售录入!$G$4:$G$203,销售录入!$D$4:$D$203,P16,销售录入!$A$4:$A$203,"<="&EOMONTH(首页!$B$4,0))<>0,"显示",IF(COUNTIFS(采购录入!$D$4:$D$203,P16,采购录入!$B$4:$B$203,TEXT(首页!$B$4,"yyyy-mm"))+COUNTIFS(销售录入!$D$4:$D$203,P16,销售录入!$B$4:$B$203,TEXT(首页!$B$4,"yyyy-mm"))>0,"显示",""))) | AJ16: 支出 | AK16: 办公费 | AL16: 6602 | AM16: 1002 | AO16: 1401 | AP16: 材料采购 | AQ16: 资产 | AR16: 借 | AS16: 启用 | AT16: 存货 | AV16: 非现金/资产负债 | AW16: 无
W17: =IF(P17="","",IF(SUMIFS(期初数据!$S$5:$S$14,期初数据!$P$5:$P$14,P17)+SUMIFS(采购录入!$G$4:$G$203,采购录入!$D$4:$D$203,P17,采购录入!$A$4:$A$203,"<="&EOMONTH(首页!$B$4,0))-SUMIFS(销售录入!$G$4:$G$203,销售录入!$D$4:$D$203,P17,销售录入!$A$4:$A$203,"<="&EOMONTH(首页!$B$4,0))<>0,"显示",IF(COUNTIFS(采购录入!$D$4:$D$203,P17,采购录入!$B$4:$B$203,TEXT(首页!$B$4,"yyyy-mm"))+COUNTIFS(销售录入!$D$4:$D$203,P17,销售录入!$B$4:$B$203,TEXT(首页!$B$4,"yyyy-mm"))>0,"显示",""))) | AJ17: 支出 | AK17: 房租 | AL17: 6602 | AM17: 1002 | AO17: 1402 | AP17: 在途物资 | AQ17: 资产 | AR17: 借 | AS17: 启用 | AT17: 存货 | AV17: 非现金/资产负债 | AW17: 无
W18: =IF(P18="","",IF(SUMIFS(期初数据!$S$5:$S$14,期初数据!$P$5:$P$14,P18)+SUMIFS(采购录入!$G$4:$G$203,采购录入!$D$4:$D$203,P18,采购录入!$A$4:$A$203,"<="&EOMONTH(首页!$B$4,0))-SUMIFS(销售录入!$G$4:$G$203,销售录入!$D$4:$D$203,P18,销售录入!$A$4:$A$203,"<="&EOMONTH(首页!$B$4,0))<>0,"显示",IF(COUNTIFS(采购录入!$D$4:$D$203,P18,采购录入!$B$4:$B$203,TEXT(首页!$B$4,"yyyy-mm"))+COUNTIFS(销售录入!$D$4:$D$203,P18,销售录入!$B$4:$B$203,TEXT(首页!$B$4,"yyyy-mm"))>0,"显示",""))) | AJ18: 支出 | AK18: 水电费 | AL18: 6602 | AM18: 1002 | AO18: 1403 | AP18: 原材料 | AQ18: 资产 | AR18: 借 | AS18: 启用 | AT18: 存货 | AV18: 非现金/资产负债 | AW18: 无
W19: =IF(P19="","",IF(SUMIFS(期初数据!$S$5:$S$14,期初数据!$P$5:$P$14,P19)+SUMIFS(采购录入!$G$4:$G$203,采购录入!$D$4:$D$203,P19,采购录入!$A$4:$A$203,"<="&EOMONTH(首页!$B$4,0))-SUMIFS(销售录入!$G$4:$G$203,销售录入!$D$4:$D$203,P19,销售录入!$A$4:$A$203,"<="&EOMONTH(首页!$B$4,0))<>0,"显示",IF(COUNTIFS(采购录入!$D$4:$D$203,P19,采购录入!$B$4:$B$203,TEXT(首页!$B$4,"yyyy-mm"))+COUNTIFS(销售录入!$D$4:$D$203,P19,销售录入!$B$4:$B$203,TEXT(首页!$B$4,"yyyy-mm"))>0,"显示",""))) | AJ19: 支出 | AK19: 维修费 | AL19: 6602 | AM19: 1002 | AO19: 1404 | AP19: 材料成本差异 | AQ19: 资产 | AR19: 借 | AS19: 启用 | AT19: 存货 | AV19: 非现金/资产负债 | AW19: 无
W20: =IF(P20="","",IF(SUMIFS(期初数据!$S$5:$S$14,期初数据!$P$5:$P$14,P20)+SUMIFS(采购录入!$G$4:$G$203,采购录入!$D$4:$D$203,P20,采购录入!$A$4:$A$203,"<="&EOMONTH(首页!$B$4,0))-SUMIFS(销售录入!$G$4:$G$203,销售录入!$D$4:$D$203,P20,销售录入!$A$4:$A$203,"<="&EOMONTH(首页!$B$4,0))<>0,"显示",IF(COUNTIFS(采购录入!$D$4:$D$203,P20,采购录入!$B$4:$B$203,TEXT(首页!$B$4,"yyyy-mm"))+COUNTIFS(销售录入!$D$4:$D$203,P20,销售录入!$B$4:$B$203,TEXT(首页!$B$4,"yyyy-mm"))>0,"显示",""))) | AJ20: 支出 | AK20: 工资 | AL20: 6602 | AM20: 1002 | AO20: 1405 | AP20: 库存商品 | AQ20: 资产 | AR20: 借 | AS20: 启用 | AT20: 存货 | AV20: 非现金/资产负债 | AW20: 无
W21: =IF(P21="","",IF(SUMIFS(期初数据!$S$5:$S$14,期初数据!$P$5:$P$14,P21)+SUMIFS(采购录入!$G$4:$G$203,采购录入!$D$4:$D$203,P21,采购录入!$A$4:$A$203,"<="&EOMONTH(首页!$B$4,0))-SUMIFS(销售录入!$G$4:$G$203,销售录入!$D$4:$D$203,P21,销售录入!$A$4:$A$203,"<="&EOMONTH(首页!$B$4,0))<>0,"显示",IF(COUNTIFS(采购录入!$D$4:$D$203,P21,采购录入!$B$4:$B$203,TEXT(首页!$B$4,"yyyy-mm"))+COUNTIFS(销售录入!$D$4:$D$203,P21,销售录入!$B$4:$B$203,TEXT(首页!$B$4,"yyyy-mm"))>0,"显示",""))) | AJ21: 支出 | AK21: 差旅费 | AL21: 6602 | AM21: 1002 | AO21: 1406 | AP21: 发出商品 | AQ21: 资产 | AR21: 借 | AS21: 启用 | AT21: 存货 | AV21: 非现金/资产负债 | AW21: 无
W22: =IF(P22="","",IF(SUMIFS(期初数据!$S$5:$S$14,期初数据!$P$5:$P$14,P22)+SUMIFS(采购录入!$G$4:$G$203,采购录入!$D$4:$D$203,P22,采购录入!$A$4:$A$203,"<="&EOMONTH(首页!$B$4,0))-SUMIFS(销售录入!$G$4:$G$203,销售录入!$D$4:$D$203,P22,销售录入!$A$4:$A$203,"<="&EOMONTH(首页!$B$4,0))<>0,"显示",IF(COUNTIFS(采购录入!$D$4:$D$203,P22,采购录入!$B$4:$B$203,TEXT(首页!$B$4,"yyyy-mm"))+COUNTIFS(销售录入!$D$4:$D$203,P22,销售录入!$B$4:$B$203,TEXT(首页!$B$4,"yyyy-mm"))>0,"显示",""))) | AJ22: 支出 | AK22: 其他费用 | AL22: 6602 | AM22: 1002 | AO22: 1407 | AP22: 商品进销差价 | AQ22: 资产 | AR22: 贷 | AS22: 启用 | AT22: 存货 | AV22: 非现金/资产负债 | AW22: 无
W23: =IF(P23="","",IF(SUMIFS(期初数据!$S$5:$S$14,期初数据!$P$5:$P$14,P23)+SUMIFS(采购录入!$G$4:$G$203,采购录入!$D$4:$D$203,P23,采购录入!$A$4:$A$203,"<="&EOMONTH(首页!$B$4,0))-SUMIFS(销售录入!$G$4:$G$203,销售录入!$D$4:$D$203,P23,销售录入!$A$4:$A$203,"<="&EOMONTH(首页!$B$4,0))<>0,"显示",IF(COUNTIFS(采购录入!$D$4:$D$203,P23,采购录入!$B$4:$B$203,TEXT(首页!$B$4,"yyyy-mm"))+COUNTIFS(销售录入!$D$4:$D$203,P23,销售录入!$B$4:$B$203,TEXT(首页!$B$4,"yyyy-mm"))>0,"显示",""))) | AJ23: 支出 | AK23: 广告费 | AL23: 6601 | AM23: 1002 | AO23: 1408 | AP23: 委托加工物资 | AQ23: 资产 | AR23: 借 | AS23: 启用 | AT23: 存货 | AV23: 非现金/资产负债 | AW23: 无
W24: =IF(P24="","",IF(SUMIFS(期初数据!$S$5:$S$14,期初数据!$P$5:$P$14,P24)+SUMIFS(采购录入!$G$4:$G$203,采购录入!$D$4:$D$203,P24,采购录入!$A$4:$A$203,"<="&EOMONTH(首页!$B$4,0))-SUMIFS(销售录入!$G$4:$G$203,销售录入!$D$4:$D$203,P24,销售录入!$A$4:$A$203,"<="&EOMONTH(首页!$B$4,0))<>0,"显示",IF(COUNTIFS(采购录入!$D$4:$D$203,P24,采购录入!$B$4:$B$203,TEXT(首页!$B$4,"yyyy-mm"))+COUNTIFS(销售录入!$D$4:$D$203,P24,销售录入!$B$4:$B$203,TEXT(首页!$B$4,"yyyy-mm"))>0,"显示",""))) | AJ24: 支出 | AK24: 物流费 | AL24: 6601 | AM24: 1002 | AO24: 1411 | AP24: 周转材料 | AQ24: 资产 | AR24: 借 | AS24: 启用 | AT24: 存货 | AV24: 非现金/资产负债 | AW24: 无
W25: =IF(P25="","",IF(SUMIFS(期初数据!$S$5:$S$14,期初数据!$P$5:$P$14,P25)+SUMIFS(采购录入!$G$4:$G$203,采购录入!$D$4:$D$203,P25,采购录入!$A$4:$A$203,"<="&EOMONTH(首页!$B$4,0))-SUMIFS(销售录入!$G$4:$G$203,销售录入!$D$4:$D$203,P25,销售录入!$A$4:$A$203,"<="&EOMONTH(首页!$B$4,0))<>0,"显示",IF(COUNTIFS(采购录入!$D$4:$D$203,P25,采购录入!$B$4:$B$203,TEXT(首页!$B$4,"yyyy-mm"))+COUNTIFS(销售录入!$D$4:$D$203,P25,销售录入!$B$4:$B$203,TEXT(首页!$B$4,"yyyy-mm"))>0,"显示",""))) | AJ25: 支出 | AK25: 财务手续费 | AL25: 6603 | AM25: 1002 | AO25: 1471 | AP25: 存货跌价准备 | AQ25: 资产 | AR25: 贷 | AS25: 启用 | AT25: 存货 | AV25: 非现金/资产负债 | AW25: 无
W26: =IF(P26="","",IF(SUMIFS(期初数据!$S$5:$S$14,期初数据!$P$5:$P$14,P26)+SUMIFS(采购录入!$G$4:$G$203,采购录入!$D$4:$D$203,P26,采购录入!$A$4:$A$203,"<="&EOMONTH(首页!$B$4,0))-SUMIFS(销售录入!$G$4:$G$203,销售录入!$D$4:$D$203,P26,销售录入!$A$4:$A$203,"<="&EOMONTH(首页!$B$4,0))<>0,"显示",IF(COUNTIFS(采购录入!$D$4:$D$203,P26,采购录入!$B$4:$B$203,TEXT(首页!$B$4,"yyyy-mm"))+COUNTIFS(销售录入!$D$4:$D$203,P26,销售录入!$B$4:$B$203,TEXT(首页!$B$4,"yyyy-mm"))>0,"显示",""))) | AJ26: 转账 | AK26: 账户转账 | AL26: 1002 | AM26: 1002 | AO26: 1501 | AP26: 债权投资 | AQ26: 资产 | AR26: 借 | AS26: 启用 | AT26: 债权投资 | AV26: 投资活动 | AW26: 无
W27: =IF(P27="","",IF(SUMIFS(期初数据!$S$5:$S$14,期初数据!$P$5:$P$14,P27)+SUMIFS(采购录入!$G$4:$G$203,采购录入!$D$4:$D$203,P27,采购录入!$A$4:$A$203,"<="&EOMONTH(首页!$B$4,0))-SUMIFS(销售录入!$G$4:$G$203,销售录入!$D$4:$D$203,P27,销售录入!$A$4:$A$203,"<="&EOMONTH(首页!$B$4,0))<>0,"显示",IF(COUNTIFS(采购录入!$D$4:$D$203,P27,采购录入!$B$4:$B$203,TEXT(首页!$B$4,"yyyy-mm"))+COUNTIFS(销售录入!$D$4:$D$203,P27,销售录入!$B$4:$B$203,TEXT(首页!$B$4,"yyyy-mm"))>0,"显示",""))) | AO27: 1511 | AP27: 长期股权投资 | AQ27: 资产 | AR27: 借 | AS27: 启用 | AT27: 长期股权投资 | AV27: 投资活动 | AW27: 无
W28: =IF(P28="","",IF(SUMIFS(期初数据!$S$5:$S$14,期初数据!$P$5:$P$14,P28)+SUMIFS(采购录入!$G$4:$G$203,采购录入!$D$4:$D$203,P28,采购录入!$A$4:$A$203,"<="&EOMONTH(首页!$B$4,0))-SUMIFS(销售录入!$G$4:$G$203,销售录入!$D$4:$D$203,P28,销售录入!$A$4:$A$203,"<="&EOMONTH(首页!$B$4,0))<>0,"显示",IF(COUNTIFS(采购录入!$D$4:$D$203,P28,采购录入!$B$4:$B$203,TEXT(首页!$B$4,"yyyy-mm"))+COUNTIFS(销售录入!$D$4:$D$203,P28,销售录入!$B$4:$B$203,TEXT(首页!$B$4,"yyyy-mm"))>0,"显示",""))) | AO28: 1521 | AP28: 投资性房地产 | AQ28: 资产 | AR28: 借 | AS28: 启用 | AT28: 投资性房地产 | AV28: 非现金/资产负债 | AW28: 无
W29: =IF(P29="","",IF(SUMIFS(期初数据!$S$5:$S$14,期初数据!$P$5:$P$14,P29)+SUMIFS(采购录入!$G$4:$G$203,采购录入!$D$4:$D$203,P29,采购录入!$A$4:$A$203,"<="&EOMONTH(首页!$B$4,0))-SUMIFS(销售录入!$G$4:$G$203,销售录入!$D$4:$D$203,P29,销售录入!$A$4:$A$203,"<="&EOMONTH(首页!$B$4,0))<>0,"显示",IF(COUNTIFS(采购录入!$D$4:$D$203,P29,采购录入!$B$4:$B$203,TEXT(首页!$B$4,"yyyy-mm"))+COUNTIFS(销售录入!$D$4:$D$203,P29,销售录入!$B$4:$B$203,TEXT(首页!$B$4,"yyyy-mm"))>0,"显示",""))) | AO29: 1601 | AP29: 固定资产 | AQ29: 资产 | AR29: 借 | AS29: 启用 | AT29: 固定资产 | AV29: 投资活动 | AW29: 无
W30: =IF(P30="","",IF(SUMIFS(期初数据!$S$5:$S$14,期初数据!$P$5:$P$14,P30)+SUMIFS(采购录入!$G$4:$G$203,采购录入!$D$4:$D$203,P30,采购录入!$A$4:$A$203,"<="&EOMONTH(首页!$B$4,0))-SUMIFS(销售录入!$G$4:$G$203,销售录入!$D$4:$D$203,P30,销售录入!$A$4:$A$203,"<="&EOMONTH(首页!$B$4,0))<>0,"显示",IF(COUNTIFS(采购录入!$D$4:$D$203,P30,采购录入!$B$4:$B$203,TEXT(首页!$B$4,"yyyy-mm"))+COUNTIFS(销售录入!$D$4:$D$203,P30,销售录入!$B$4:$B$203,TEXT(首页!$B$4,"yyyy-mm"))>0,"显示",""))) | AO30: 1602 | AP30: 累计折旧 | AQ30: 资产 | AR30: 贷 | AS30: 启用 | AT30: 固定资产 | AV30: 非现金/资产负债 | AW30: 无
W31: =IF(P31="","",IF(SUMIFS(期初数据!$S$5:$S$14,期初数据!$P$5:$P$14,P31)+SUMIFS(采购录入!$G$4:$G$203,采购录入!$D$4:$D$203,P31,采购录入!$A$4:$A$203,"<="&EOMONTH(首页!$B$4,0))-SUMIFS(销售录入!$G$4:$G$203,销售录入!$D$4:$D$203,P31,销售录入!$A$4:$A$203,"<="&EOMONTH(首页!$B$4,0))<>0,"显示",IF(COUNTIFS(采购录入!$D$4:$D$203,P31,采购录入!$B$4:$B$203,TEXT(首页!$B$4,"yyyy-mm"))+COUNTIFS(销售录入!$D$4:$D$203,P31,销售录入!$B$4:$B$203,TEXT(首页!$B$4,"yyyy-mm"))>0,"显示",""))) | AO31: 1604 | AP31: 在建工程 | AQ31: 资产 | AR31: 借 | AS31: 启用 | AT31: 在建工程 | AV31: 投资活动 | AW31: 无
W32: =IF(P32="","",IF(SUMIFS(期初数据!$S$5:$S$14,期初数据!$P$5:$P$14,P32)+SUMIFS(采购录入!$G$4:$G$203,采购录入!$D$4:$D$203,P32,采购录入!$A$4:$A$203,"<="&EOMONTH(首页!$B$4,0))-SUMIFS(销售录入!$G$4:$G$203,销售录入!$D$4:$D$203,P32,销售录入!$A$4:$A$203,"<="&EOMONTH(首页!$B$4,0))<>0,"显示",IF(COUNTIFS(采购录入!$D$4:$D$203,P32,采购录入!$B$4:$B$203,TEXT(首页!$B$4,"yyyy-mm"))+COUNTIFS(销售录入!$D$4:$D$203,P32,销售录入!$B$4:$B$203,TEXT(首页!$B$4,"yyyy-mm"))>0,"显示",""))) | AO32: 1605 | AP32: 工程物资 | AQ32: 资产 | AR32: 借 | AS32: 启用 | AT32: 在建工程 | AV32: 非现金/资产负债 | AW32: 无
W33: =IF(P33="","",IF(SUMIFS(期初数据!$S$5:$S$14,期初数据!$P$5:$P$14,P33)+SUMIFS(采购录入!$G$4:$G$203,采购录入!$D$4:$D$203,P33,采购录入!$A$4:$A$203,"<="&EOMONTH(首页!$B$4,0))-SUMIFS(销售录入!$G$4:$G$203,销售录入!$D$4:$D$203,P33,销售录入!$A$4:$A$203,"<="&EOMONTH(首页!$B$4,0))<>0,"显示",IF(COUNTIFS(采购录入!$D$4:$D$203,P33,采购录入!$B$4:$B$203,TEXT(首页!$B$4,"yyyy-mm"))+COUNTIFS(销售录入!$D$4:$D$203,P33,销售录入!$B$4:$B$203,TEXT(首页!$B$4,"yyyy-mm"))>0,"显示",""))) | AO33: 1606 | AP33: 固定资产清理 | AQ33: 资产 | AR33: 借 | AS33: 启用 | AT33: 固定资产 | AV33: 非现金/资产负债 | AW33: 无
W34: =IF(P34="","",IF(SUMIFS(期初数据!$S$5:$S$14,期初数据!$P$5:$P$14,P34)+SUMIFS(采购录入!$G$4:$G$203,采购录入!$D$4:$D$203,P34,采购录入!$A$4:$A$203,"<="&EOMONTH(首页!$B$4,0))-SUMIFS(销售录入!$G$4:$G$203,销售录入!$D$4:$D$203,P34,销售录入!$A$4:$A$203,"<="&EOMONTH(首页!$B$4,0))<>0,"显示",IF(COUNTIFS(采购录入!$D$4:$D$203,P34,采购录入!$B$4:$B$203,TEXT(首页!$B$4,"yyyy-mm"))+COUNTIFS(销售录入!$D$4:$D$203,P34,销售录入!$B$4:$B$203,TEXT(首页!$B$4,"yyyy-mm"))>0,"显示",""))) | AO34: 1701 | AP34: 无形资产 | AQ34: 资产 | AR34: 借 | AS34: 启用 | AT34: 无形资产 | AV34: 投资活动 | AW34: 无
W35: =IF(P35="","",IF(SUMIFS(期初数据!$S$5:$S$14,期初数据!$P$5:$P$14,P35)+SUMIFS(采购录入!$G$4:$G$203,采购录入!$D$4:$D$203,P35,采购录入!$A$4:$A$203,"<="&EOMONTH(首页!$B$4,0))-SUMIFS(销售录入!$G$4:$G$203,销售录入!$D$4:$D$203,P35,销售录入!$A$4:$A$203,"<="&EOMONTH(首页!$B$4,0))<>0,"显示",IF(COUNTIFS(采购录入!$D$4:$D$203,P35,采购录入!$B$4:$B$203,TEXT(首页!$B$4,"yyyy-mm"))+COUNTIFS(销售录入!$D$4:$D$203,P35,销售录入!$B$4:$B$203,TEXT(首页!$B$4,"yyyy-mm"))>0,"显示",""))) | AO35: 1702 | AP35: 累计摊销 | AQ35: 资产 | AR35: 贷 | AS35: 启用 | AT35: 无形资产 | AV35: 非现金/资产负债 | AW35: 无
W36: =IF(P36="","",IF(SUMIFS(期初数据!$S$5:$S$14,期初数据!$P$5:$P$14,P36)+SUMIFS(采购录入!$G$4:$G$203,采购录入!$D$4:$D$203,P36,采购录入!$A$4:$A$203,"<="&EOMONTH(首页!$B$4,0))-SUMIFS(销售录入!$G$4:$G$203,销售录入!$D$4:$D$203,P36,销售录入!$A$4:$A$203,"<="&EOMONTH(首页!$B$4,0))<>0,"显示",IF(COUNTIFS(采购录入!$D$4:$D$203,P36,采购录入!$B$4:$B$203,TEXT(首页!$B$4,"yyyy-mm"))+COUNTIFS(销售录入!$D$4:$D$203,P36,销售录入!$B$4:$B$203,TEXT(首页!$B$4,"yyyy-mm"))>0,"显示",""))) | AO36: 1801 | AP36: 长期待摊费用 | AQ36: 资产 | AR36: 借 | AS36: 启用 | AT36: 长期待摊费用 | AV36: 非现金/资产负债 | AW36: 无
W37: =IF(P37="","",IF(SUMIFS(期初数据!$S$5:$S$14,期初数据!$P$5:$P$14,P37)+SUMIFS(采购录入!$G$4:$G$203,采购录入!$D$4:$D$203,P37,采购录入!$A$4:$A$203,"<="&EOMONTH(首页!$B$4,0))-SUMIFS(销售录入!$G$4:$G$203,销售录入!$D$4:$D$203,P37,销售录入!$A$4:$A$203,"<="&EOMONTH(首页!$B$4,0))<>0,"显示",IF(COUNTIFS(采购录入!$D$4:$D$203,P37,采购录入!$B$4:$B$203,TEXT(首页!$B$4,"yyyy-mm"))+COUNTIFS(销售录入!$D$4:$D$203,P37,销售录入!$B$4:$B$203,TEXT(首页!$B$4,"yyyy-mm"))>0,"显示",""))) | AO37: 1811 | AP37: 递延所得税资产 | AQ37: 资产 | AR37: 借 | AS37: 启用 | AT37: 递延所得税资产 | AV37: 非现金/资产负债 | AW37: 无
W38: =IF(P38="","",IF(SUMIFS(期初数据!$S$5:$S$14,期初数据!$P$5:$P$14,P38)+SUMIFS(采购录入!$G$4:$G$203,采购录入!$D$4:$D$203,P38,采购录入!$A$4:$A$203,"<="&EOMONTH(首页!$B$4,0))-SUMIFS(销售录入!$G$4:$G$203,销售录入!$D$4:$D$203,P38,销售录入!$A$4:$A$203,"<="&EOMONTH(首页!$B$4,0))<>0,"显示",IF(COUNTIFS(采购录入!$D$4:$D$203,P38,采购录入!$B$4:$B$203,TEXT(首页!$B$4,"yyyy-mm"))+COUNTIFS(销售录入!$D$4:$D$203,P38,销售录入!$B$4:$B$203,TEXT(首页!$B$4,"yyyy-mm"))>0,"显示",""))) | AO38: 1901 | AP38: 待处理财产损溢 | AQ38: 资产 | AR38: 借 | AS38: 启用 | AT38: 其他流动资产 | AV38: 非现金/资产负债 | AW38: 无
... W60: =IF(P60="","",IF(SUMIFS(期初数据!$S$5:$S$14,期初数据!$P$5:$P$14,P60)+SUMIFS(采购录入!$G$4:$G$203,采购录入!$D$4:$D$203,P60,采购录入!$A$4:$A$203,"<="&EOMONTH(首页!$B$4,0))-SUMIFS(销售录入!$G$4:$G$203,销售录入!$D$4:$D$203,P60,销售录入!$A$4:$A$203,"<="&EOMONTH(首页!$B$4,0))<>0,"显示",IF(COUNTIFS(采购录入!$D$4:$D$203,P60,采购录入!$B$4:$B$203,TEXT(首页!$B$4,"yyyy-mm"))+COUNTIFS(销售录入!$D$4:$D$203,P60,销售录入!$B$4:$B$203,TEXT(首页!$B$4,"yyyy-mm"))>0,"显示",""))) | AO60: 4101 | AP60: 盈余公积 | AQ60: 权益 | AR60: 贷 | AS60: 启用 | AT60: 盈余公积 | AV60: 非现金/资产负债 | AW60: 无
W61: =IF(P61="","",IF(SUMIFS(期初数据!$S$5:$S$14,期初数据!$P$5:$P$14,P61)+SUMIFS(采购录入!$G$4:$G$203,采购录入!$D$4:$D$203,P61,采购录入!$A$4:$A$203,"<="&EOMONTH(首页!$B$4,0))-SUMIFS(销售录入!$G$4:$G$203,销售录入!$D$4:$D$203,P61,销售录入!$A$4:$A$203,"<="&EOMONTH(首页!$B$4,0))<>0,"显示",IF(COUNTIFS(采购录入!$D$4:$D$203,P61,采购录入!$B$4:$B$203,TEXT(首页!$B$4,"yyyy-mm"))+COUNTIFS(销售录入!$D$4:$D$203,P61,销售录入!$B$4:$B$203,TEXT(首页!$B$4,"yyyy-mm"))>0,"显示",""))) | AO61: 4103 | AP61: 本年利润 | AQ61: 权益 | AR61: 贷 | AS61: 启用 | AV61: 非现金/资产负债 | AW61: 无
...

Sheet 期初数据
A1: 期初数据（年初只录一次）
A3: 资金期初 | F3: 应收期初 | K3: 应付期初 | P3: 库存期初 | X3: 会计科目期初
A4: 账户 | B4: 类型 | C4: 期初余额 | D4: 备注 | F4: 客户 | G4: 原业务日期 | H4: 期初应收 | I4: 备注 | K4: 供应商 | L4: 原业务日期 | M4: 期初应付 | N4: 备注 | P4: 商品 | Q4: 规格 | R4: 单位 | S4: 期初数量 | T4: 期初单位成本 | U4: 期初金额 | V4: 备注 | X4: 科目编码 | Y4: 科目名称 | Z4: 科目类别 | AA4: 方向 | AB4: 期初借方 | AC4: 期初贷方 | AD4: 备注
A5: 现金 | B5: 现金类 | C5: 50000 | D5: 演示 | F5: 客户A | G5: 46023 | H5: 15000 | I5: 演示 | K5: 供应商A | L5: 46023 | M5: 25000 | N5: 演示 | P5: A配件 | Q5: A-01 | R5: 个 | S5: 100 | T5: 100 | U5: 10000 | V5: 演示 | X5: 1001 | Y5: 库存现金 | Z5: 资产 | AA5: 借 | AB5: 55000 | AC5: 0 | AD5: 演示
A6: 工商银行 | B6: 银行类 | C6: 300000 | D6: 演示 | F6: 客户B | G6: 46023 | H6: 12000 | I6: 演示 | K6: 供应商B | L6: 46023 | M6: 22000 | N6: 演示 | P6: B配件 | Q6: B-02 | R6: 个 | S6: 80 | T6: 125 | U6: 10000 | V6: 演示 | X6: 1002 | Y6: 银行存款 | Z6: 资产 | AA6: 借 | AB6: 805000 | AC6: 0 | AD6: 演示
A7: 农业银行 | B7: 银行类 | C7: 200000 | D7: 演示 | F7: 客户C | G7: 46023 | H7: 18000 | I7: 演示 | K7: 供应商C | L7: 46023 | M7: 18000 | N7: 演示 | P7: C配件 | Q7: C-03 | R7: 个 | S7: 200 | T7: 50 | U7: 10000 | V7: 演示 | X7: 1012 | Y7: 其他货币资金 | Z7: 资产 | AA7: 借 | AB7: 0 | AC7: 0
A8: 建设银行 | B8: 银行类 | C8: 120000 | D8: 演示 | F8: 客户D | G8: 46023 | H8: 8000 | I8: 演示 | K8: 供应商D | L8: 46023 | M8: 30000 | N8: 演示 | P8: D配件 | Q8: D-04 | R8: 个 | S8: 50 | T8: 200 | U8: 10000 | V8: 演示 | X8: 1101 | Y8: 交易性金融资产 | Z8: 资产 | AA8: 借 | AB8: 0 | AC8: 0
A9: 招商银行 | B9: 银行类 | C9: 80000 | D9: 演示 | F9: 客户E | G9: 46023 | H9: 25000 | I9: 演示 | K9: 供应商E | L9: 46023 | M9: 15000 | N9: 演示 | P9: E配件 | Q9: E-05 | R9: 个 | S9: 400 | T9: 25 | U9: 10000 | V9: 演示 | X9: 1121 | Y9: 应收票据 | Z9: 资产 | AA9: 借 | AB9: 0 | AC9: 0
A10: 中国银行 | B10: 银行类 | C10: 60000 | D10: 演示 | F10: 客户F | G10: 46023 | H10: 16000 | I10: 演示 | K10: 供应商F | L10: 46023 | M10: 24000 | N10: 演示 | P10: F配件 | Q10: F-06 | R10: 个 | S10: 100 | T10: 80 | U10: 8000 | V10: 演示 | X10: 1122 | Y10: 应收账款 | Z10: 资产 | AA10: 借 | AB10: 158000 | AC10: 0 | AD10: 演示
A11: 微信 | B11: 电子账户 | C11: 20000 | D11: 演示 | F11: 客户G | G11: 46023 | H11: 14000 | I11: 演示 | K11: 供应商G | L11: 46023 | M11: 20000 | N11: 演示 | P11: G配件 | Q11: G-07 | R11: 个 | S11: 120 | T11: 75 | U11: 9000 | V11: 演示 | X11: 1123 | Y11: 预付账款 | Z11: 资产 | AA11: 借 | AB11: 0 | AC11: 0
A12: 支付宝 | B12: 电子账户 | C12: 15000 | D12: 演示 | F12: 客户H | G12: 46023 | H12: 20000 | I12: 演示 | K12: 供应商H | L12: 46023 | M12: 16000 | N12: 演示 | P12: H配件 | Q12: H-08 | R12: 个 | S12: 60 | T12: 150 | U12: 9000 | V12: 演示 | X12: 1131 | Y12: 应收股利 | Z12: 资产 | AA12: 借 | AB12: 0 | AC12: 0
A13: 备用金 | B13: 现金类 | C13: 5000 | D13: 演示 | F13: 客户I | G13: 46023 | H13: 10000 | I13: 演示 | K13: 供应商I | L13: 46023 | M13: 18000 | N13: 演示 | P13: I配件 | Q13: I-09 | R13: 个 | S13: 300 | T13: 30 | U13: 9000 | V13: 演示 | X13: 1132 | Y13: 应收利息 | Z13: 资产 | AA13: 借 | AB13: 0 | AC13: 0
A14: 其他账户 | B14: 银行类 | C14: 10000 | D14: 演示 | F14: 客户J | G14: 46023 | H14: 20000 | I14: 演示 | K14: 供应商J | L14: 46023 | M14: 22000 | N14: 演示 | P14: J配件 | Q14: J-10 | R14: 个 | S14: 250 | T14: 60 | U14: 15000 | V14: 演示 | X14: 1221 | Y14: 其他应收款 | Z14: 资产 | AA14: 借 | AB14: 0 | AC14: 0
X15: 1231 | Y15: 坏账准备 | Z15: 资产 | AA15: 贷 | AB15: 0 | AC15: 0
X16: 1401 | Y16: 材料采购 | Z16: 资产 | AA16: 借 | AB16: 0 | AC16: 0
X17: 1402 | Y17: 在途物资 | Z17: 资产 | AA17: 借 | AB17: 0 | AC17: 0
X18: 1403 | Y18: 原材料 | Z18: 资产 | AA18: 借 | AB18: 0 | AC18: 0
X19: 1404 | Y19: 材料成本差异 | Z19: 资产 | AA19: 借 | AB19: 0 | AC19: 0
X20: 1405 | Y20: 库存商品 | Z20: 资产 | AA20: 借 | AB20: 100000 | AC20: 0 | AD20: 演示
X21: 1406 | Y21: 发出商品 | Z21: 资产 | AA21: 借 | AB21: 0 | AC21: 0
X22: 1407 | Y22: 商品进销差价 | Z22: 资产 | AA22: 贷 | AB22: 0 | AC22: 0
X23: 1408 | Y23: 委托加工物资 | Z23: 资产 | AA23: 借 | AB23: 0 | AC23: 0
X24: 1411 | Y24: 周转材料 | Z24: 资产 | AA24: 借 | AB24: 0 | AC24: 0
X25: 1471 | Y25: 存货跌价准备 | Z25: 资产 | AA25: 贷 | AB25: 0 | AC25: 0
X26: 1501 | Y26: 债权投资 | Z26: 资产 | AA26: 借 | AB26: 0 | AC26: 0
X27: 1511 | Y27: 长期股权投资 | Z27: 资产 | AA27: 借 | AB27: 0 | AC27: 0
X28: 1521 | Y28: 投资性房地产 | Z28: 资产 | AA28: 借 | AB28: 0 | AC28: 0
X29: 1601 | Y29: 固定资产 | Z29: 资产 | AA29: 借 | AB29: 600000 | AC29: 0 | AD29: 演示
X30: 1602 | Y30: 累计折旧 | Z30: 资产 | AA30: 贷 | AB30: 0 | AC30: 0
X31: 1604 | Y31: 在建工程 | Z31: 资产 | AA31: 借 | AB31: 0 | AC31: 0
X32: 1605 | Y32: 工程物资 | Z32: 资产 | AA32: 借 | AB32: 0 | AC32: 0
X33: 1606 | Y33: 固定资产清理 | Z33: 资产 | AA33: 借 | AB33: 0 | AC33: 0
X34: 1701 | Y34: 无形资产 | Z34: 资产 | AA34: 借 | AB34: 0 | AC34: 0
X35: 1702 | Y35: 累计摊销 | Z35: 资产 | AA35: 贷 | AB35: 0 | AC35: 0
X36: 1801 | Y36: 长期待摊费用 | Z36: 资产 | AA36: 借 | AB36: 0 | AC36: 0
X37: 1811 | Y37: 递延所得税资产 | Z37: 资产 | AA37: 借 | AB37: 0 | AC37: 0
X38: 1901 | Y38: 待处理财产损溢 | Z38: 资产 | AA38: 借 | AB38: 0 | AC38: 0
X39: 1905 | Y39: 其他流动资产 | Z39: 资产 | AA39: 借 | AB39: 0 | AC39: 0
X40: 1906 | Y40: 其他非流动资产 | Z40: 资产 | AA40: 借 | AB40: 0 | AC40: 0
X41: 2001 | Y41: 短期借款 | Z41: 负债 | AA41: 贷 | AB41: 0 | AC41: 300000 | AD41: 演示
...

Sheet 资金流水
A1: 资金流水（唯一实际收付款录入口）
A2: 所有实际到账、付款、费用、工资、账户转账只在这里登记；销售、采购不要重复登记收入/成本。
A3: 日期 | B3: 月份 | C3: 收支类型 | D3: 收支科目 | E3: 账户 | F3: 往来单位/转入账户 | G3: 部门 | H3: 员工 | I3: 摘要 | J3: 收入金额 | K3: 支出金额 | L3: 账户余额 | M3: 资金科目 | N3: 转入资金科目 | O3: 借方科目 | P3: 贷方科目 | Q3: 发生金额 | R3: 月结检查
A4: 46175 | B4: =IF(A4="","",TEXT(A4,"yyyy-mm")) -> 2026-06 | C4: =IF(D4="","",IFERROR(INDEX(基础资料!$AJ$5:$AJ$204,MATCH(D4,基础资料!$AK$5:$AK$204,0)),"")) -> 收入 | D4: 客户回款 | E4: 工商银行 | F4: 客户A | G4: 销售部 | H4: 张伟 | I4: 收到客户A货款 | J4: 12000 | K4: 0 | L4: =IF(OR(A4="",E4=""),"",SUMIFS(期初数据!$C$5:$C$14,期初数据!$A$5:$A$14,E4)+SUMIFS($J$4:J4,$E$4:E4,E4)-SUMIFS($K$4:K4,$E$4:E4,E4)+SUMIFS($K$4:K4,$F$4:F4,E4,$D$4:D4,"账户转账")) -> 312000 | M4: =IF(E4="","",IFERROR(VLOOKUP(E4,基础资料!$A$5:$C$204,3,FALSE),"")) -> 1002 | N4: =IF(D4="账户转账",IFERROR(VLOOKUP(F4,基础资料!$A$5:$C$204,3,FALSE),""),"") | O4: =IF(D4="","",IF(D4="账户转账",N4,IFERROR(IF(VLOOKUP(D4,基础资料!$AK$5:$AM$204,2,FALSE)="1002",M4,VLOOKUP(D4,基础资料!$AK$5:$AM$204,2,FALSE)),""))) -> 1002 | P4: =IF(D4="","",IF(D4="账户转账",M4,IFERROR(IF(VLOOKUP(D4,基础资料!$AK$5:$AM$204,3,FALSE)="1002",M4,VLOOKUP(D4,基础资料!$AK$5:$AM$204,3,FALSE)),""))) -> 1122 | Q4: =IF(A4="","",N(J4)+N(K4)) -> 12000 | R4: =IF(A4="","","可录入") -> 可录入
A5: 46176 | B5: =IF(A5="","",TEXT(A5,"yyyy-mm")) -> 2026-06 | C5: =IF(D5="","",IFERROR(INDEX(基础资料!$AJ$5:$AJ$204,MATCH(D5,基础资料!$AK$5:$AK$204,0)),"")) -> 支出 | D5: 供应商付款 | E5: 工商银行 | F5: 供应商A | G5: 采购部 | H5: 王强 | I5: 支付供应商A货款 | J5: 0 | K5: 10000 | L5: =IF(OR(A5="",E5=""),"",SUMIFS(期初数据!$C$5:$C$14,期初数据!$A$5:$A$14,E5)+SUMIFS($J$4:J5,$E$4:E5,E5)-SUMIFS($K$4:K5,$E$4:E5,E5)+SUMIFS($K$4:K5,$F$4:F5,E5,$D$4:D5,"账户转账")) -> 302000 | M5: =IF(E5="","",IFERROR(VLOOKUP(E5,基础资料!$A$5:$C$204,3,FALSE),"")) -> 1002 | N5: =IF(D5="账户转账",IFERROR(VLOOKUP(F5,基础资料!$A$5:$C$204,3,FALSE),""),"") | O5: =IF(D5="","",IF(D5="账户转账",N5,IFERROR(IF(VLOOKUP(D5,基础资料!$AK$5:$AM$204,2,FALSE)="1002",M5,VLOOKUP(D5,基础资料!$AK$5:$AM$204,2,FALSE)),""))) -> 2202 | P5: =IF(D5="","",IF(D5="账户转账",M5,IFERROR(IF(VLOOKUP(D5,基础资料!$AK$5:$AM$204,3,FALSE)="1002",M5,VLOOKUP(D5,基础资料!$AK$5:$AM$204,3,FALSE)),""))) -> 1002 | Q5: =IF(A5="","",N(J5)+N(K5)) -> 10000 | R5: =IF(A5="","","可录入") -> 可录入
A6: 46178 | B6: =IF(A6="","",TEXT(A6,"yyyy-mm")) -> 2026-06 | C6: =IF(D6="","",IFERROR(INDEX(基础资料!$AJ$5:$AJ$204,MATCH(D6,基础资料!$AK$5:$AK$204,0)),"")) -> 支出 | D6: 办公费 | E6: 微信 | G6: 行政部 | H6: 陈敏 | I6: 购买办公用品 | J6: 0 | K6: 800 | L6: =IF(OR(A6="",E6=""),"",SUMIFS(期初数据!$C$5:$C$14,期初数据!$A$5:$A$14,E6)+SUMIFS($J$4:J6,$E$4:E6,E6)-SUMIFS($K$4:K6,$E$4:E6,E6)+SUMIFS($K$4:K6,$F$4:F6,E6,$D$4:D6,"账户转账")) -> 19200 | M6: =IF(E6="","",IFERROR(VLOOKUP(E6,基础资料!$A$5:$C$204,3,FALSE),"")) -> 1002 | N6: =IF(D6="账户转账",IFERROR(VLOOKUP(F6,基础资料!$A$5:$C$204,3,FALSE),""),"") | O6: =IF(D6="","",IF(D6="账户转账",N6,IFERROR(IF(VLOOKUP(D6,基础资料!$AK$5:$AM$204,2,FALSE)="1002",M6,VLOOKUP(D6,基础资料!$AK$5:$AM$204,2,FALSE)),""))) -> 6602 | P6: =IF(D6="","",IF(D6="账户转账",M6,IFERROR(IF(VLOOKUP(D6,基础资料!$AK$5:$AM$204,3,FALSE)="1002",M6,VLOOKUP(D6,基础资料!$AK$5:$AM$204,3,FALSE)),""))) -> 1002 | Q6: =IF(A6="","",N(J6)+N(K6)) -> 800 | R6: =IF(A6="","","可录入") -> 可录入
A7: 46181 | B7: =IF(A7="","",TEXT(A7,"yyyy-mm")) -> 2026-06 | C7: =IF(D7="","",IFERROR(INDEX(基础资料!$AJ$5:$AJ$204,MATCH(D7,基础资料!$AK$5:$AK$204,0)),"")) -> 支出 | D7: 房租 | E7: 农业银行 | G7: 行政部 | H7: 陈敏 | I7: 支付6月房租 | J7: 0 | K7: 5000 | L7: =IF(OR(A7="",E7=""),"",SUMIFS(期初数据!$C$5:$C$14,期初数据!$A$5:$A$14,E7)+SUMIFS($J$4:J7,$E$4:E7,E7)-SUMIFS($K$4:K7,$E$4:E7,E7)+SUMIFS($K$4:K7,$F$4:F7,E7,$D$4:D7,"账户转账")) -> 195000 | M7: =IF(E7="","",IFERROR(VLOOKUP(E7,基础资料!$A$5:$C$204,3,FALSE),"")) -> 1002 | N7: =IF(D7="账户转账",IFERROR(VLOOKUP(F7,基础资料!$A$5:$C$204,3,FALSE),""),"") | O7: =IF(D7="","",IF(D7="账户转账",N7,IFERROR(IF(VLOOKUP(D7,基础资料!$AK$5:$AM$204,2,FALSE)="1002",M7,VLOOKUP(D7,基础资料!$AK$5:$AM$204,2,FALSE)),""))) -> 6602 | P7: =IF(D7="","",IF(D7="账户转账",M7,IFERROR(IF(VLOOKUP(D7,基础资料!$AK$5:$AM$204,3,FALSE)="1002",M7,VLOOKUP(D7,基础资料!$AK$5:$AM$204,3,FALSE)),""))) -> 1002 | Q7: =IF(A7="","",N(J7)+N(K7)) -> 5000 | R7: =IF(A7="","","可录入") -> 可录入
A8: 46183 | B8: =IF(A8="","",TEXT(A8,"yyyy-mm")) -> 2026-06 | C8: =IF(D8="","",IFERROR(INDEX(基础资料!$AJ$5:$AJ$204,MATCH(D8,基础资料!$AK$5:$AK$204,0)),"")) -> 支出 | D8: 水电费 | E8: 工商银行 | G8: 行政部 | H8: 陈敏 | I8: 支付水电费 | J8: 0 | K8: 1800 | L8: =IF(OR(A8="",E8=""),"",SUMIFS(期初数据!$C$5:$C$14,期初数据!$A$5:$A$14,E8)+SUMIFS($J$4:J8,$E$4:E8,E8)-SUMIFS($K$4:K8,$E$4:E8,E8)+SUMIFS($K$4:K8,$F$4:F8,E8,$D$4:D8,"账户转账")) -> 300200 | M8: =IF(E8="","",IFERROR(VLOOKUP(E8,基础资料!$A$5:$C$204,3,FALSE),"")) -> 1002 | N8: =IF(D8="账户转账",IFERROR(VLOOKUP(F8,基础资料!$A$5:$C$204,3,FALSE),""),"") | O8: =IF(D8="","",IF(D8="账户转账",N8,IFERROR(IF(VLOOKUP(D8,基础资料!$AK$5:$AM$204,2,FALSE)="1002",M8,VLOOKUP(D8,基础资料!$AK$5:$AM$204,2,FALSE)),""))) -> 6602 | P8: =IF(D8="","",IF(D8="账户转账",M8,IFERROR(IF(VLOOKUP(D8,基础资料!$AK$5:$AM$204,3,FALSE)="1002",M8,VLOOKUP(D8,基础资料!$AK$5:$AM$204,3,FALSE)),""))) -> 1002 | Q8: =IF(A8="","",N(J8)+N(K8)) -> 1800 | R8: =IF(A8="","","可录入") -> 可录入
A9: 46185 | B9: =IF(A9="","",TEXT(A9,"yyyy-mm")) -> 2026-06 | C9: =IF(D9="","",IFERROR(INDEX(基础资料!$AJ$5:$AJ$204,MATCH(D9,基础资料!$AK$5:$AK$204,0)),"")) -> 支出 | D9: 广告费 | E9: 支付宝 | G9: 电商部 | H9: 孙悦 | I9: 广告投放 | J9: 0 | K9: 2000 | L9: =IF(OR(A9="",E9=""),"",SUMIFS(期初数据!$C$5:$C$14,期初数据!$A$5:$A$14,E9)+SUMIFS($J$4:J9,$E$4:E9,E9)-SUMIFS($K$4:K9,$E$4:E9,E9)+SUMIFS($K$4:K9,$F$4:F9,E9,$D$4:D9,"账户转账")) -> 13000 | M9: =IF(E9="","",IFERROR(VLOOKUP(E9,基础资料!$A$5:$C$204,3,FALSE),"")) -> 1002 | N9: =IF(D9="账户转账",IFERROR(VLOOKUP(F9,基础资料!$A$5:$C$204,3,FALSE),""),"") | O9: =IF(D9="","",IF(D9="账户转账",N9,IFERROR(IF(VLOOKUP(D9,基础资料!$AK$5:$AM$204,2,FALSE)="1002",M9,VLOOKUP(D9,基础资料!$AK$5:$AM$204,2,FALSE)),""))) -> 6601 | P9: =IF(D9="","",IF(D9="账户转账",M9,IFERROR(IF(VLOOKUP(D9,基础资料!$AK$5:$AM$204,3,FALSE)="1002",M9,VLOOKUP(D9,基础资料!$AK$5:$AM$204,3,FALSE)),""))) -> 1002 | Q9: =IF(A9="","",N(J9)+N(K9)) -> 2000 | R9: =IF(A9="","","可录入") -> 可录入
A10: 46188 | B10: =IF(A10="","",TEXT(A10,"yyyy-mm")) -> 2026-06 | C10: =IF(D10="","",IFERROR(INDEX(基础资料!$AJ$5:$AJ$204,MATCH(D10,基础资料!$AK$5:$AK$204,0)),"")) -> 支出 | D10: 工资 | E10: 工商银行 | G10: 财务部 | H10: 赵静 | I10: 支付工资 | J10: 0 | K10: 15000 | L10: =IF(OR(A10="",E10=""),"",SUMIFS(期初数据!$C$5:$C$14,期初数据!$A$5:$A$14,E10)+SUMIFS($J$4:J10,$E$4:E10,E10)-SUMIFS($K$4:K10,$E$4:E10,E10)+SUMIFS($K$4:K10,$F$4:F10,E10,$D$4:D10,"账户转账")) -> 285200 | M10: =IF(E10="","",IFERROR(VLOOKUP(E10,基础资料!$A$5:$C$204,3,FALSE),"")) -> 1002 | N10: =IF(D10="账户转账",IFERROR(VLOOKUP(F10,基础资料!$A$5:$C$204,3,FALSE),""),"") | O10: =IF(D10="","",IF(D10="账户转账",N10,IFERROR(IF(VLOOKUP(D10,基础资料!$AK$5:$AM$204,2,FALSE)="1002",M10,VLOOKUP(D10,基础资料!$AK$5:$AM$204,2,FALSE)),""))) -> 6602 | P10: =IF(D10="","",IF(D10="账户转账",M10,IFERROR(IF(VLOOKUP(D10,基础资料!$AK$5:$AM$204,3,FALSE)="1002",M10,VLOOKUP(D10,基础资料!$AK$5:$AM$204,3,FALSE)),""))) -> 1002 | Q10: =IF(A10="","",N(J10)+N(K10)) -> 15000 | R10: =IF(A10="","","可录入") -> 可录入
A11: 46191 | B11: =IF(A11="","",TEXT(A11,"yyyy-mm")) -> 2026-06 | C11: =IF(D11="","",IFERROR(INDEX(基础资料!$AJ$5:$AJ$204,MATCH(D11,基础资料!$AK$5:$AK$204,0)),"")) -> 收入 | D11: 服务收入 | E11: 中国银行 | G11: 管理层 | H11: 郑欣 | I11: 服务收入 | J11: 3200 | K11: 0 | L11: =IF(OR(A11="",E11=""),"",SUMIFS(期初数据!$C$5:$C$14,期初数据!$A$5:$A$14,E11)+SUMIFS($J$4:J11,$E$4:E11,E11)-SUMIFS($K$4:K11,$E$4:E11,E11)+SUMIFS($K$4:K11,$F$4:F11,E11,$D$4:D11,"账户转账")) -> 63200 | M11: =IF(E11="","",IFERROR(VLOOKUP(E11,基础资料!$A$5:$C$204,3,FALSE),"")) -> 1002 | N11: =IF(D11="账户转账",IFERROR(VLOOKUP(F11,基础资料!$A$5:$C$204,3,FALSE),""),"") | O11: =IF(D11="","",IF(D11="账户转账",N11,IFERROR(IF(VLOOKUP(D11,基础资料!$AK$5:$AM$204,2,FALSE)="1002",M11,VLOOKUP(D11,基础资料!$AK$5:$AM$204,2,FALSE)),""))) -> 1002 | P11: =IF(D11="","",IF(D11="账户转账",M11,IFERROR(IF(VLOOKUP(D11,基础资料!$AK$5:$AM$204,3,FALSE)="1002",M11,VLOOKUP(D11,基础资料!$AK$5:$AM$204,3,FALSE)),""))) -> 6051 | Q11: =IF(A11="","",N(J11)+N(K11)) -> 3200 | R11: =IF(A11="","","可录入") -> 可录入
A12: 46193 | B12: =IF(A12="","",TEXT(A12,"yyyy-mm")) -> 2026-06 | C12: =IF(D12="","",IFERROR(INDEX(基础资料!$AJ$5:$AJ$204,MATCH(D12,基础资料!$AK$5:$AK$204,0)),"")) -> 转账 | D12: 账户转账 | E12: 工商银行 | F12: 建设银行 | G12: 财务部 | H12: 赵静 | I12: 账户转账 | J12: 0 | K12: 20000 | L12: =IF(OR(A12="",E12=""),"",SUMIFS(期初数据!$C$5:$C$14,期初数据!$A$5:$A$14,E12)+SUMIFS($J$4:J12,$E$4:E12,E12)-SUMIFS($K$4:K12,$E$4:E12,E12)+SUMIFS($K$4:K12,$F$4:F12,E12,$D$4:D12,"账户转账")) -> 265200 | M12: =IF(E12="","",IFERROR(VLOOKUP(E12,基础资料!$A$5:$C$204,3,FALSE),"")) -> 1002 | N12: =IF(D12="账户转账",IFERROR(VLOOKUP(F12,基础资料!$A$5:$C$204,3,FALSE),""),"") -> 1002 | O12: =IF(D12="","",IF(D12="账户转账",N12,IFERROR(IF(VLOOKUP(D12,基础资料!$AK$5:$AM$204,2,FALSE)="1002",M12,VLOOKUP(D12,基础资料!$AK$5:$AM$204,2,FALSE)),""))) -> 1002 | P12: =IF(D12="","",IF(D12="账户转账",M12,IFERROR(IF(VLOOKUP(D12,基础资料!$AK$5:$AM$204,3,FALSE)="1002",M12,VLOOKUP(D12,基础资料!$AK$5:$AM$204,3,FALSE)),""))) -> 1002 | Q12: =IF(A12="","",N(J12)+N(K12)) -> 20000 | R12: =IF(A12="","","可录入") -> 可录入
A13: 46198 | B13: =IF(A13="","",TEXT(A13,"yyyy-mm")) -> 2026-06 | C13: =IF(D13="","",IFERROR(INDEX(基础资料!$AJ$5:$AJ$204,MATCH(D13,基础资料!$AK$5:$AK$204,0)),"")) -> 收入 | D13: 客户回款 | E13: 建设银行 | F13: 客户B | G13: 销售部 | H13: 李娜 | I13: 收到客户B货款 | J13: 8000 | K13: 0 | L13: =IF(OR(A13="",E13=""),"",SUMIFS(期初数据!$C$5:$C$14,期初数据!$A$5:$A$14,E13)+SUMIFS($J$4:J13,$E$4:E13,E13)-SUMIFS($K$4:K13,$E$4:E13,E13)+SUMIFS($K$4:K13,$F$4:F13,E13,$D$4:D13,"账户转账")) -> 148000 | M13: =IF(E13="","",IFERROR(VLOOKUP(E13,基础资料!$A$5:$C$204,3,FALSE),"")) -> 1002 | N13: =IF(D13="账户转账",IFERROR(VLOOKUP(F13,基础资料!$A$5:$C$204,3,FALSE),""),"") | O13: =IF(D13="","",IF(D13="账户转账",N13,IFERROR(IF(VLOOKUP(D13,基础资料!$AK$5:$AM$204,2,FALSE)="1002",M13,VLOOKUP(D13,基础资料!$AK$5:$AM$204,2,FALSE)),""))) -> 1002 | P13: =IF(D13="","",IF(D13="账户转账",M13,IFERROR(IF(VLOOKUP(D13,基础资料!$AK$5:$AM$204,3,FALSE)="1002",M13,VLOOKUP(D13,基础资料!$AK$5:$AM$204,3,FALSE)),""))) -> 1122 | Q13: =IF(A13="","",N(J13)+N(K13)) -> 8000 | R13: =IF(A13="","","可录入") -> 可录入
B14: =IF(A14="","",TEXT(A14,"yyyy-mm")) | C14: =IF(D14="","",IFERROR(INDEX(基础资料!$AJ$5:$AJ$204,MATCH(D14,基础资料!$AK$5:$AK$204,0)),"")) | L14: =IF(OR(A14="",E14=""),"",SUMIFS(期初数据!$C$5:$C$14,期初数据!$A$5:$A$14,E14)+SUMIFS($J$4:J14,$E$4:E14,E14)-SUMIFS($K$4:K14,$E$4:E14,E14)+SUMIFS($K$4:K14,$F$4:F14,E14,$D$4:D14,"账户转账")) | M14: =IF(E14="","",IFERROR(VLOOKUP(E14,基础资料!$A$5:$C$204,3,FALSE),"")) | N14: =IF(D14="账户转账",IFERROR(VLOOKUP(F14,基础资料!$A$5:$C$204,3,FALSE),""),"") | O14: =IF(D14="","",IF(D14="账户转账",N14,IFERROR(IF(VLOOKUP(D14,基础资料!$AK$5:$AM$204,2,FALSE)="1002",M14,VLOOKUP(D14,基础资料!$AK$5:$AM$204,2,FALSE)),""))) | P14: =IF(D14="","",IF(D14="账户转账",M14,IFERROR(IF(VLOOKUP(D14,基础资料!$AK$5:$AM$204,3,FALSE)="1002",M14,VLOOKUP(D14,基础资料!$AK$5:$AM$204,3,FALSE)),""))) | Q14: =IF(A14="","",N(J14)+N(K14)) | R14: =IF(A14="","","可录入")
B15: =IF(A15="","",TEXT(A15,"yyyy-mm")) | C15: =IF(D15="","",IFERROR(INDEX(基础资料!$AJ$5:$AJ$204,MATCH(D15,基础资料!$AK$5:$AK$204,0)),"")) | L15: =IF(OR(A15="",E15=""),"",SUMIFS(期初数据!$C$5:$C$14,期初数据!$A$5:$A$14,E15)+SUMIFS($J$4:J15,$E$4:E15,E15)-SUMIFS($K$4:K15,$E$4:E15,E15)+SUMIFS($K$4:K15,$F$4:F15,E15,$D$4:D15,"账户转账")) | M15: =IF(E15="","",IFERROR(VLOOKUP(E15,基础资料!$A$5:$C$204,3,FALSE),"")) | N15: =IF(D15="账户转账",IFERROR(VLOOKUP(F15,基础资料!$A$5:$C$204,3,FALSE),""),"") | O15: =IF(D15="","",IF(D15="账户转账",N15,IFERROR(IF(VLOOKUP(D15,基础资料!$AK$5:$AM$204,2,FALSE)="1002",M15,VLOOKUP(D15,基础资料!$AK$5:$AM$204,2,FALSE)),""))) | P15: =IF(D15="","",IF(D15="账户转账",M15,IFERROR(IF(VLOOKUP(D15,基础资料!$AK$5:$AM$204,3,FALSE)="1002",M15,VLOOKUP(D15,基础资料!$AK$5:$AM$204,3,FALSE)),""))) | Q15: =IF(A15="","",N(J15)+N(K15)) | R15: =IF(A15="","","可录入")
B16: =IF(A16="","",TEXT(A16,"yyyy-mm")) | C16: =IF(D16="","",IFERROR(INDEX(基础资料!$AJ$5:$AJ$204,MATCH(D16,基础资料!$AK$5:$AK$204,0)),"")) | L16: =IF(OR(A16="",E16=""),"",SUMIFS(期初数据!$C$5:$C$14,期初数据!$A$5:$A$14,E16)+SUMIFS($J$4:J16,$E$4:E16,E16)-SUMIFS($K$4:K16,$E$4:E16,E16)+SUMIFS($K$4:K16,$F$4:F16,E16,$D$4:D16,"账户转账")) | M16: =IF(E16="","",IFERROR(VLOOKUP(E16,基础资料!$A$5:$C$204,3,FALSE),"")) | N16: =IF(D16="账户转账",IFERROR(VLOOKUP(F16,基础资料!$A$5:$C$204,3,FALSE),""),"") | O16: =IF(D16="","",IF(D16="账户转账",N16,IFERROR(IF(VLOOKUP(D16,基础资料!$AK$5:$AM$204,2,FALSE)="1002",M16,VLOOKUP(D16,基础资料!$AK$5:$AM$204,2,FALSE)),""))) | P16: =IF(D16="","",IF(D16="账户转账",M16,IFERROR(IF(VLOOKUP(D16,基础资料!$AK$5:$AM$204,3,FALSE)="1002",M16,VLOOKUP(D16,基础资料!$AK$5:$AM$204,3,FALSE)),""))) | Q16: =IF(A16="","",N(J16)+N(K16)) | R16: =IF(A16="","","可录入")
B17: =IF(A17="","",TEXT(A17,"yyyy-mm")) | C17: =IF(D17="","",IFERROR(INDEX(基础资料!$AJ$5:$AJ$204,MATCH(D17,基础资料!$AK$5:$AK$204,0)),"")) | L17: =IF(OR(A17="",E17=""),"",SUMIFS(期初数据!$C$5:$C$14,期初数据!$A$5:$A$14,E17)+SUMIFS($J$4:J17,$E$4:E17,E17)-SUMIFS($K$4:K17,$E$4:E17,E17)+SUMIFS($K$4:K17,$F$4:F17,E17,$D$4:D17,"账户转账")) | M17: =IF(E17="","",IFERROR(VLOOKUP(E17,基础资料!$A$5:$C$204,3,FALSE),"")) | N17: =IF(D17="账户转账",IFERROR(VLOOKUP(F17,基础资料!$A$5:$C$204,3,FALSE),""),"") | O17: =IF(D17="","",IF(D17="账户转账",N17,IFERROR(IF(VLOOKUP(D17,基础资料!$AK$5:$AM$204,2,FALSE)="1002",M17,VLOOKUP(D17,基础资料!$AK$5:$AM$204,2,FALSE)),""))) | P17: =IF(D17="","",IF(D17="账户转账",M17,IFERROR(IF(VLOOKUP(D17,基础资料!$AK$5:$AM$204,3,FALSE)="1002",M17,VLOOKUP(D17,基础资料!$AK$5:$AM$204,3,FALSE)),""))) | Q17: =IF(A17="","",N(J17)+N(K17)) | R17: =IF(A17="","","可录入")
B18: =IF(A18="","",TEXT(A18,"yyyy-mm")) | C18: =IF(D18="","",IFERROR(INDEX(基础资料!$AJ$5:$AJ$204,MATCH(D18,基础资料!$AK$5:$AK$204,0)),"")) | L18: =IF(OR(A18="",E18=""),"",SUMIFS(期初数据!$C$5:$C$14,期初数据!$A$5:$A$14,E18)+SUMIFS($J$4:J18,$E$4:E18,E18)-SUMIFS($K$4:K18,$E$4:E18,E18)+SUMIFS($K$4:K18,$F$4:F18,E18,$D$4:D18,"账户转账")) | M18: =IF(E18="","",IFERROR(VLOOKUP(E18,基础资料!$A$5:$C$204,3,FALSE),"")) | N18: =IF(D18="账户转账",IFERROR(VLOOKUP(F18,基础资料!$A$5:$C$204,3,FALSE),""),"") | O18: =IF(D18="","",IF(D18="账户转账",N18,IFERROR(IF(VLOOKUP(D18,基础资料!$AK$5:$AM$204,2,FALSE)="1002",M18,VLOOKUP(D18,基础资料!$AK$5:$AM$204,2,FALSE)),""))) | P18: =IF(D18="","",IF(D18="账户转账",M18,IFERROR(IF(VLOOKUP(D18,基础资料!$AK$5:$AM$204,3,FALSE)="1002",M18,VLOOKUP(D18,基础资料!$AK$5:$AM$204,3,FALSE)),""))) | Q18: =IF(A18="","",N(J18)+N(K18)) | R18: =IF(A18="","","可录入")
B19: =IF(A19="","",TEXT(A19,"yyyy-mm")) | C19: =IF(D19="","",IFERROR(INDEX(基础资料!$AJ$5:$AJ$204,MATCH(D19,基础资料!$AK$5:$AK$204,0)),"")) | L19: =IF(OR(A19="",E19=""),"",SUMIFS(期初数据!$C$5:$C$14,期初数据!$A$5:$A$14,E19)+SUMIFS($J$4:J19,$E$4:E19,E19)-SUMIFS($K$4:K19,$E$4:E19,E19)+SUMIFS($K$4:K19,$F$4:F19,E19,$D$4:D19,"账户转账")) | M19: =IF(E19="","",IFERROR(VLOOKUP(E19,基础资料!$A$5:$C$204,3,FALSE),"")) | N19: =IF(D19="账户转账",IFERROR(VLOOKUP(F19,基础资料!$A$5:$C$204,3,FALSE),""),"") | O19: =IF(D19="","",IF(D19="账户转账",N19,IFERROR(IF(VLOOKUP(D19,基础资料!$AK$5:$AM$204,2,FALSE)="1002",M19,VLOOKUP(D19,基础资料!$AK$5:$AM$204,2,FALSE)),""))) | P19: =IF(D19="","",IF(D19="账户转账",M19,IFERROR(IF(VLOOKUP(D19,基础资料!$AK$5:$AM$204,3,FALSE)="1002",M19,VLOOKUP(D19,基础资料!$AK$5:$AM$204,3,FALSE)),""))) | Q19: =IF(A19="","",N(J19)+N(K19)) | R19: =IF(A19="","","可录入")
B20: =IF(A20="","",TEXT(A20,"yyyy-mm")) | C20: =IF(D20="","",IFERROR(INDEX(基础资料!$AJ$5:$AJ$204,MATCH(D20,基础资料!$AK$5:$AK$204,0)),"")) | L20: =IF(OR(A20="",E20=""),"",SUMIFS(期初数据!$C$5:$C$14,期初数据!$A$5:$A$14,E20)+SUMIFS($J$4:J20,$E$4:E20,E20)-SUMIFS($K$4:K20,$E$4:E20,E20)+SUMIFS($K$4:K20,$F$4:F20,E20,$D$4:D20,"账户转账")) | M20: =IF(E20="","",IFERROR(VLOOKUP(E20,基础资料!$A$5:$C$204,3,FALSE),"")) | N20: =IF(D20="账户转账",IFERROR(VLOOKUP(F20,基础资料!$A$5:$C$204,3,FALSE),""),"") | O20: =IF(D20="","",IF(D20="账户转账",N20,IFERROR(IF(VLOOKUP(D20,基础资料!$AK$5:$AM$204,2,FALSE)="1002",M20,VLOOKUP(D20,基础资料!$AK$5:$AM$204,2,FALSE)),""))) | P20: =IF(D20="","",IF(D20="账户转账",M20,IFERROR(IF(VLOOKUP(D20,基础资料!$AK$5:$AM$204,3,FALSE)="1002",M20,VLOOKUP(D20,基础资料!$AK$5:$AM$204,3,FALSE)),""))) | Q20: =IF(A20="","",N(J20)+N(K20)) | R20: =IF(A20="","","可录入")
B21: =IF(A21="","",TEXT(A21,"yyyy-mm")) | C21: =IF(D21="","",IFERROR(INDEX(基础资料!$AJ$5:$AJ$204,MATCH(D21,基础资料!$AK$5:$AK$204,0)),"")) | L21: =IF(OR(A21="",E21=""),"",SUMIFS(期初数据!$C$5:$C$14,期初数据!$A$5:$A$14,E21)+SUMIFS($J$4:J21,$E$4:E21,E21)-SUMIFS($K$4:K21,$E$4:E21,E21)+SUMIFS($K$4:K21,$F$4:F21,E21,$D$4:D21,"账户转账")) | M21: =IF(E21="","",IFERROR(VLOOKUP(E21,基础资料!$A$5:$C$204,3,FALSE),"")) | N21: =IF(D21="账户转账",IFERROR(VLOOKUP(F21,基础资料!$A$5:$C$204,3,FALSE),""),"") | O21: =IF(D21="","",IF(D21="账户转账",N21,IFERROR(IF(VLOOKUP(D21,基础资料!$AK$5:$AM$204,2,FALSE)="1002",M21,VLOOKUP(D21,基础资料!$AK$5:$AM$204,2,FALSE)),""))) | P21: =IF(D21="","",IF(D21="账户转账",M21,IFERROR(IF(VLOOKUP(D21,基础资料!$AK$5:$AM$204,3,FALSE)="1002",M21,VLOOKUP(D21,基础资料!$AK$5:$AM$204,3,FALSE)),""))) | Q21: =IF(A21="","",N(J21)+N(K21)) | R21: =IF(A21="","","可录入")
B22: =IF(A22="","",TEXT(A22,"yyyy-mm")) | C22: =IF(D22="","",IFERROR(INDEX(基础资料!$AJ$5:$AJ$204,MATCH(D22,基础资料!$AK$5:$AK$204,0)),"")) | L22: =IF(OR(A22="",E22=""),"",SUMIFS(期初数据!$C$5:$C$14,期初数据!$A$5:$A$14,E22)+SUMIFS($J$4:J22,$E$4:E22,E22)-SUMIFS($K$4:K22,$E$4:E22,E22)+SUMIFS($K$4:K22,$F$4:F22,E22,$D$4:D22,"账户转账")) | M22: =IF(E22="","",IFERROR(VLOOKUP(E22,基础资料!$A$5:$C$204,3,FALSE),"")) | N22: =IF(D22="账户转账",IFERROR(VLOOKUP(F22,基础资料!$A$5:$C$204,3,FALSE),""),"") | O22: =IF(D22="","",IF(D22="账户转账",N22,IFERROR(IF(VLOOKUP(D22,基础资料!$AK$5:$AM$204,2,FALSE)="1002",M22,VLOOKUP(D22,基础资料!$AK$5:$AM$204,2,FALSE)),""))) | P22: =IF(D22="","",IF(D22="账户转账",M22,IFERROR(IF(VLOOKUP(D22,基础资料!$AK$5:$AM$204,3,FALSE)="1002",M22,VLOOKUP(D22,基础资料!$AK$5:$AM$204,3,FALSE)),""))) | Q22: =IF(A22="","",N(J22)+N(K22)) | R22: =IF(A22="","","可录入")
B23: =IF(A23="","",TEXT(A23,"yyyy-mm")) | C23: =IF(D23="","",IFERROR(INDEX(基础资料!$AJ$5:$AJ$204,MATCH(D23,基础资料!$AK$5:$AK$204,0)),"")) | L23: =IF(OR(A23="",E23=""),"",SUMIFS(期初数据!$C$5:$C$14,期初数据!$A$5:$A$14,E23)+SUMIFS($J$4:J23,$E$4:E23,E23)-SUMIFS($K$4:K23,$E$4:E23,E23)+SUMIFS($K$4:K23,$F$4:F23,E23,$D$4:D23,"账户转账")) | M23: =IF(E23="","",IFERROR(VLOOKUP(E23,基础资料!$A$5:$C$204,3,FALSE),"")) | N23: =IF(D23="账户转账",IFERROR(VLOOKUP(F23,基础资料!$A$5:$C$204,3,FALSE),""),"") | O23: =IF(D23="","",IF(D23="账户转账",N23,IFERROR(IF(VLOOKUP(D23,基础资料!$AK$5:$AM$204,2,FALSE)="1002",M23,VLOOKUP(D23,基础资料!$AK$5:$AM$204,2,FALSE)),""))) | P23: =IF(D23="","",IF(D23="账户转账",M23,IFERROR(IF(VLOOKUP(D23,基础资料!$AK$5:$AM$204,3,FALSE)="1002",M23,VLOOKUP(D23,基础资料!$AK$5:$AM$204,3,FALSE)),""))) | Q23: =IF(A23="","",N(J23)+N(K23)) | R23: =IF(A23="","","可录入")
B24: =IF(A24="","",TEXT(A24,"yyyy-mm")) | C24: =IF(D24="","",IFERROR(INDEX(基础资料!$AJ$5:$AJ$204,MATCH(D24,基础资料!$AK$5:$AK$204,0)),"")) | L24: =IF(OR(A24="",E24=""),"",SUMIFS(期初数据!$C$5:$C$14,期初数据!$A$5:$A$14,E24)+SUMIFS($J$4:J24,$E$4:E24,E24)-SUMIFS($K$4:K24,$E$4:E24,E24)+SUMIFS($K$4:K24,$F$4:F24,E24,$D$4:D24,"账户转账")) | M24: =IF(E24="","",IFERROR(VLOOKUP(E24,基础资料!$A$5:$C$204,3,FALSE),"")) | N24: =IF(D24="账户转账",IFERROR(VLOOKUP(F24,基础资料!$A$5:$C$204,3,FALSE),""),"") | O24: =IF(D24="","",IF(D24="账户转账",N24,IFERROR(IF(VLOOKUP(D24,基础资料!$AK$5:$AM$204,2,FALSE)="1002",M24,VLOOKUP(D24,基础资料!$AK$5:$AM$204,2,FALSE)),""))) | P24: =IF(D24="","",IF(D24="账户转账",M24,IFERROR(IF(VLOOKUP(D24,基础资料!$AK$5:$AM$204,3,FALSE)="1002",M24,VLOOKUP(D24,基础资料!$AK$5:$AM$204,3,FALSE)),""))) | Q24: =IF(A24="","",N(J24)+N(K24)) | R24: =IF(A24="","","可录入")
B25: =IF(A25="","",TEXT(A25,"yyyy-mm")) | C25: =IF(D25="","",IFERROR(INDEX(基础资料!$AJ$5:$AJ$204,MATCH(D25,基础资料!$AK$5:$AK$204,0)),"")) | L25: =IF(OR(A25="",E25=""),"",SUMIFS(期初数据!$C$5:$C$14,期初数据!$A$5:$A$14,E25)+SUMIFS($J$4:J25,$E$4:E25,E25)-SUMIFS($K$4:K25,$E$4:E25,E25)+SUMIFS($K$4:K25,$F$4:F25,E25,$D$4:D25,"账户转账")) | M25: =IF(E25="","",IFERROR(VLOOKUP(E25,基础资料!$A$5:$C$204,3,FALSE),"")) | N25: =IF(D25="账户转账",IFERROR(VLOOKUP(F25,基础资料!$A$5:$C$204,3,FALSE),""),"") | O25: =IF(D25="","",IF(D25="账户转账",N25,IFERROR(IF(VLOOKUP(D25,基础资料!$AK$5:$AM$204,2,FALSE)="1002",M25,VLOOKUP(D25,基础资料!$AK$5:$AM$204,2,FALSE)),""))) | P25: =IF(D25="","",IF(D25="账户转账",M25,IFERROR(IF(VLOOKUP(D25,基础资料!$AK$5:$AM$204,3,FALSE)="1002",M25,VLOOKUP(D25,基础资料!$AK$5:$AM$204,3,FALSE)),""))) | Q25: =IF(A25="","",N(J25)+N(K25)) | R25: =IF(A25="","","可录入")
... B203: =IF(A203="","",TEXT(A203,"yyyy-mm")) | C203: =IF(D203="","",IFERROR(INDEX(基础资料!$AJ$5:$AJ$204,MATCH(D203,基础资料!$AK$5:$AK$204,0)),"")) | L203: =IF(OR(A203="",E203=""),"",SUMIFS(期初数据!$C$5:$C$14,期初数据!$A$5:$A$14,E203)+SUMIFS($J$4:J203,$E$4:E203,E203)-SUMIFS($K$4:K203,$E$4:E203,E203)+SUMIFS($K$4:K203,$F$4:F203,E203,$D$4:D203,"账户转账")) | M203: =IF(E203="","",IFERROR(VLOOKUP(E203,基础资料!$A$5:$C$204,3,FALSE),"")) | N203: =IF(D203="账户转账",IFERROR(VLOOKUP(F203,基础资料!$A$5:$C$204,3,FALSE),""),"") | O203: =IF(D203="","",IF(D203="账户转账",N203,IFERROR(IF(VLOOKUP(D203,基础资料!$AK$5:$AM$204,2,FALSE)="1002",M203,VLOOKUP(D203,基础资料!$AK$5:$AM$204,2,FALSE)),""))) | P203: =IF(D203="","",IF(D203="账户转账",M203,IFERROR(IF(VLOOKUP(D203,基础资料!$AK$5:$AM$204,3,FALSE)="1002",M203,VLOOKUP(D203,基础资料!$AK$5:$AM$204,3,FALSE)),""))) | Q203: =IF(A203="","",N(J203)+N(K203)) | R203: =IF(A203="","","可录入")

Sheet 销售录入
A1: 销售录入（销售业务唯一入口）
A2: 客户销售只在这里登记；回款只在资金流水登记。销售单价每笔手工填写。
A3: 日期 | B3: 月份 | C3: 客户 | D3: 商品 | E3: 规格 | F3: 单位 | G3: 数量 | H3: 销售单价（手工） | I3: 销售金额 | J3: 成本单价 | K3: 销售成本 | L3: 到期日 | M3: 部门 | N3: 业务员 | O3: 备注 | P3: 月结检查 | Q3: 毛利金额
A4: 46174 | B4: =IF(A4="","",TEXT(A4,"yyyy-mm")) -> 2026-06 | C4: 客户A | D4: A配件 | E4: =IF(D4="","",IFERROR(VLOOKUP(D4,基础资料!$P$5:$R$204,2,FALSE),"")) -> A-01 | F4: =IF(D4="","",IFERROR(VLOOKUP(D4,基础资料!$P$5:$R$204,3,FALSE),"")) -> 个 | G4: 20 | H4: 200 | I4: =IF(OR(G4="",H4=""),"",G4*H4) -> 4000 | J4: =IF(D4="","",IFERROR(VLOOKUP(D4,基础资料!$P$5:$T$204,5,FALSE),0)) -> 100 | K4: =IF(OR(G4="",J4=""),"",G4*J4) -> 2000 | L4: =IF(OR(A4="",C4=""),"",A4+IFERROR(VLOOKUP(C4,基础资料!$Y$5:$AA$204,3,FALSE),0)) -> 46204 | M4: 销售部 | N4: 张伟 | O4: 演示销售 | P4: =IF(A4="","","可录入") -> 可录入 | Q4: =IF(I4="","",I4-K4) -> 2000
A5: 46176 | B5: =IF(A5="","",TEXT(A5,"yyyy-mm")) -> 2026-06 | C5: 客户B | D5: B配件 | E5: =IF(D5="","",IFERROR(VLOOKUP(D5,基础资料!$P$5:$R$204,2,FALSE),"")) -> B-02 | F5: =IF(D5="","",IFERROR(VLOOKUP(D5,基础资料!$P$5:$R$204,3,FALSE),"")) -> 个 | G5: 15 | H5: 250 | I5: =IF(OR(G5="",H5=""),"",G5*H5) -> 3750 | J5: =IF(D5="","",IFERROR(VLOOKUP(D5,基础资料!$P$5:$T$204,5,FALSE),0)) -> 125 | K5: =IF(OR(G5="",J5=""),"",G5*J5) -> 1875 | L5: =IF(OR(A5="",C5=""),"",A5+IFERROR(VLOOKUP(C5,基础资料!$Y$5:$AA$204,3,FALSE),0)) -> 46206 | M5: 销售部 | N5: 李娜 | O5: 演示销售 | P5: =IF(A5="","","可录入") -> 可录入 | Q5: =IF(I5="","",I5-K5) -> 1875
A6: 46178 | B6: =IF(A6="","",TEXT(A6,"yyyy-mm")) -> 2026-06 | C6: 客户C | D6: C配件 | E6: =IF(D6="","",IFERROR(VLOOKUP(D6,基础资料!$P$5:$R$204,2,FALSE),"")) -> C-03 | F6: =IF(D6="","",IFERROR(VLOOKUP(D6,基础资料!$P$5:$R$204,3,FALSE),"")) -> 个 | G6: 30 | H6: 100 | I6: =IF(OR(G6="",H6=""),"",G6*H6) -> 3000 | J6: =IF(D6="","",IFERROR(VLOOKUP(D6,基础资料!$P$5:$T$204,5,FALSE),0)) -> 50 | K6: =IF(OR(G6="",J6=""),"",G6*J6) -> 1500 | L6: =IF(OR(A6="",C6=""),"",A6+IFERROR(VLOOKUP(C6,基础资料!$Y$5:$AA$204,3,FALSE),0)) -> 46223 | M6: 销售部 | N6: 张伟 | O6: 演示销售 | P6: =IF(A6="","","可录入") -> 可录入 | Q6: =IF(I6="","",I6-K6) -> 1500
A7: 46180 | B7: =IF(A7="","",TEXT(A7,"yyyy-mm")) -> 2026-06 | C7: 客户D | D7: D配件 | E7: =IF(D7="","",IFERROR(VLOOKUP(D7,基础资料!$P$5:$R$204,2,FALSE),"")) -> D-04 | F7: =IF(D7="","",IFERROR(VLOOKUP(D7,基础资料!$P$5:$R$204,3,FALSE),"")) -> 个 | G7: 8 | H7: 400 | I7: =IF(OR(G7="",H7=""),"",G7*H7) -> 3200 | J7: =IF(D7="","",IFERROR(VLOOKUP(D7,基础资料!$P$5:$T$204,5,FALSE),0)) -> 200 | K7: =IF(OR(G7="",J7=""),"",G7*J7) -> 1600 | L7: =IF(OR(A7="",C7=""),"",A7+IFERROR(VLOOKUP(C7,基础资料!$Y$5:$AA$204,3,FALSE),0)) -> 46210 | M7: 销售部 | N7: 李娜 | O7: 演示销售 | P7: =IF(A7="","","可录入") -> 可录入 | Q7: =IF(I7="","",I7-K7) -> 1600
A8: 46182 | B8: =IF(A8="","",TEXT(A8,"yyyy-mm")) -> 2026-06 | C8: 客户E | D8: E配件 | E8: =IF(D8="","",IFERROR(VLOOKUP(D8,基础资料!$P$5:$R$204,2,FALSE),"")) -> E-05 | F8: =IF(D8="","",IFERROR(VLOOKUP(D8,基础资料!$P$5:$R$204,3,FALSE),"")) -> 个 | G8: 50 | H8: 50 | I8: =IF(OR(G8="",H8=""),"",G8*H8) -> 2500 | J8: =IF(D8="","",IFERROR(VLOOKUP(D8,基础资料!$P$5:$T$204,5,FALSE),0)) -> 25 | K8: =IF(OR(G8="",J8=""),"",G8*J8) -> 1250 | L8: =IF(OR(A8="",C8=""),"",A8+IFERROR(VLOOKUP(C8,基础资料!$Y$5:$AA$204,3,FALSE),0)) -> 46242 | M8: 电商部 | N8: 孙悦 | O8: 演示销售 | P8: =IF(A8="","","可录入") -> 可录入 | Q8: =IF(I8="","",I8-K8) -> 1250
A9: 46184 | B9: =IF(A9="","",TEXT(A9,"yyyy-mm")) -> 2026-06 | C9: 客户F | D9: F配件 | E9: =IF(D9="","",IFERROR(VLOOKUP(D9,基础资料!$P$5:$R$204,2,FALSE),"")) -> F-06 | F9: =IF(D9="","",IFERROR(VLOOKUP(D9,基础资料!$P$5:$R$204,3,FALSE),"")) -> 个 | G9: 12 | H9: 160 | I9: =IF(OR(G9="",H9=""),"",G9*H9) -> 1920 | J9: =IF(D9="","",IFERROR(VLOOKUP(D9,基础资料!$P$5:$T$204,5,FALSE),0)) -> 80 | K9: =IF(OR(G9="",J9=""),"",G9*J9) -> 960 | L9: =IF(OR(A9="",C9=""),"",A9+IFERROR(VLOOKUP(C9,基础资料!$Y$5:$AA$204,3,FALSE),0)) -> 46214 | M9: 销售部 | N9: 李娜 | O9: 演示销售 | P9: =IF(A9="","","可录入") -> 可录入 | Q9: =IF(I9="","",I9-K9) -> 960
A10: 46186 | B10: =IF(A10="","",TEXT(A10,"yyyy-mm")) -> 2026-06 | C10: 客户G | D10: G配件 | E10: =IF(D10="","",IFERROR(VLOOKUP(D10,基础资料!$P$5:$R$204,2,FALSE),"")) -> G-07 | F10: =IF(D10="","",IFERROR(VLOOKUP(D10,基础资料!$P$5:$R$204,3,FALSE),"")) -> 个 | G10: 15 | H10: 150 | I10: =IF(OR(G10="",H10=""),"",G10*H10) -> 2250 | J10: =IF(D10="","",IFERROR(VLOOKUP(D10,基础资料!$P$5:$T$204,5,FALSE),0)) -> 75 | K10: =IF(OR(G10="",J10=""),"",G10*J10) -> 1125 | L10: =IF(OR(A10="",C10=""),"",A10+IFERROR(VLOOKUP(C10,基础资料!$Y$5:$AA$204,3,FALSE),0)) -> 46231 | M10: 销售部 | N10: 张伟 | O10: 演示销售 | P10: =IF(A10="","","可录入") -> 可录入 | Q10: =IF(I10="","",I10-K10) -> 1125
A11: 46188 | B11: =IF(A11="","",TEXT(A11,"yyyy-mm")) -> 2026-06 | C11: 客户H | D11: H配件 | E11: =IF(D11="","",IFERROR(VLOOKUP(D11,基础资料!$P$5:$R$204,2,FALSE),"")) -> H-08 | F11: =IF(D11="","",IFERROR(VLOOKUP(D11,基础资料!$P$5:$R$204,3,FALSE),"")) -> 个 | G11: 6 | H11: 300 | I11: =IF(OR(G11="",H11=""),"",G11*H11) -> 1800 | J11: =IF(D11="","",IFERROR(VLOOKUP(D11,基础资料!$P$5:$T$204,5,FALSE),0)) -> 150 | K11: =IF(OR(G11="",J11=""),"",G11*J11) -> 900 | L11: =IF(OR(A11="",C11=""),"",A11+IFERROR(VLOOKUP(C11,基础资料!$Y$5:$AA$204,3,FALSE),0)) -> 46218 | M11: 销售部 | N11: 李娜 | O11: 演示销售 | P11: =IF(A11="","","可录入") -> 可录入 | Q11: =IF(I11="","",I11-K11) -> 900
A12: 46190 | B12: =IF(A12="","",TEXT(A12,"yyyy-mm")) -> 2026-06 | C12: 客户I | D12: I配件 | E12: =IF(D12="","",IFERROR(VLOOKUP(D12,基础资料!$P$5:$R$204,2,FALSE),"")) -> I-09 | F12: =IF(D12="","",IFERROR(VLOOKUP(D12,基础资料!$P$5:$R$204,3,FALSE),"")) -> 个 | G12: 25 | H12: 60 | I12: =IF(OR(G12="",H12=""),"",G12*H12) -> 1500 | J12: =IF(D12="","",IFERROR(VLOOKUP(D12,基础资料!$P$5:$T$204,5,FALSE),0)) -> 30 | K12: =IF(OR(G12="",J12=""),"",G12*J12) -> 750 | L12: =IF(OR(A12="",C12=""),"",A12+IFERROR(VLOOKUP(C12,基础资料!$Y$5:$AA$204,3,FALSE),0)) -> 46220 | M12: 销售部 | N12: 张伟 | O12: 演示销售 | P12: =IF(A12="","","可录入") -> 可录入 | Q12: =IF(I12="","",I12-K12) -> 750
A13: 46192 | B13: =IF(A13="","",TEXT(A13,"yyyy-mm")) -> 2026-06 | C13: 客户J | D13: J配件 | E13: =IF(D13="","",IFERROR(VLOOKUP(D13,基础资料!$P$5:$R$204,2,FALSE),"")) -> J-10 | F13: =IF(D13="","",IFERROR(VLOOKUP(D13,基础资料!$P$5:$R$204,3,FALSE),"")) -> 个 | G13: 18 | H13: 120 | I13: =IF(OR(G13="",H13=""),"",G13*H13) -> 2160 | J13: =IF(D13="","",IFERROR(VLOOKUP(D13,基础资料!$P$5:$T$204,5,FALSE),0)) -> 60 | K13: =IF(OR(G13="",J13=""),"",G13*J13) -> 1080 | L13: =IF(OR(A13="",C13=""),"",A13+IFERROR(VLOOKUP(C13,基础资料!$Y$5:$AA$204,3,FALSE),0)) -> 46252 | M13: 销售部 | N13: 李娜 | O13: 演示销售 | P13: =IF(A13="","","可录入") -> 可录入 | Q13: =IF(I13="","",I13-K13) -> 1080
B14: =IF(A14="","",TEXT(A14,"yyyy-mm")) | E14: =IF(D14="","",IFERROR(VLOOKUP(D14,基础资料!$P$5:$R$204,2,FALSE),"")) | F14: =IF(D14="","",IFERROR(VLOOKUP(D14,基础资料!$P$5:$R$204,3,FALSE),"")) | I14: =IF(OR(G14="",H14=""),"",G14*H14) | J14: =IF(D14="","",IFERROR(VLOOKUP(D14,基础资料!$P$5:$T$204,5,FALSE),0)) | K14: =IF(OR(G14="",J14=""),"",G14*J14) | L14: =IF(OR(A14="",C14=""),"",A14+IFERROR(VLOOKUP(C14,基础资料!$Y$5:$AA$204,3,FALSE),0)) | P14: =IF(A14="","","可录入") | Q14: =IF(I14="","",I14-K14)
B15: =IF(A15="","",TEXT(A15,"yyyy-mm")) | E15: =IF(D15="","",IFERROR(VLOOKUP(D15,基础资料!$P$5:$R$204,2,FALSE),"")) | F15: =IF(D15="","",IFERROR(VLOOKUP(D15,基础资料!$P$5:$R$204,3,FALSE),"")) | I15: =IF(OR(G15="",H15=""),"",G15*H15) | J15: =IF(D15="","",IFERROR(VLOOKUP(D15,基础资料!$P$5:$T$204,5,FALSE),0)) | K15: =IF(OR(G15="",J15=""),"",G15*J15) | L15: =IF(OR(A15="",C15=""),"",A15+IFERROR(VLOOKUP(C15,基础资料!$Y$5:$AA$204,3,FALSE),0)) | P15: =IF(A15="","","可录入") | Q15: =IF(I15="","",I15-K15)
B16: =IF(A16="","",TEXT(A16,"yyyy-mm")) | E16: =IF(D16="","",IFERROR(VLOOKUP(D16,基础资料!$P$5:$R$204,2,FALSE),"")) | F16: =IF(D16="","",IFERROR(VLOOKUP(D16,基础资料!$P$5:$R$204,3,FALSE),"")) | I16: =IF(OR(G16="",H16=""),"",G16*H16) | J16: =IF(D16="","",IFERROR(VLOOKUP(D16,基础资料!$P$5:$T$204,5,FALSE),0)) | K16: =IF(OR(G16="",J16=""),"",G16*J16) | L16: =IF(OR(A16="",C16=""),"",A16+IFERROR(VLOOKUP(C16,基础资料!$Y$5:$AA$204,3,FALSE),0)) | P16: =IF(A16="","","可录入") | Q16: =IF(I16="","",I16-K16)
B17: =IF(A17="","",TEXT(A17,"yyyy-mm")) | E17: =IF(D17="","",IFERROR(VLOOKUP(D17,基础资料!$P$5:$R$204,2,FALSE),"")) | F17: =IF(D17="","",IFERROR(VLOOKUP(D17,基础资料!$P$5:$R$204,3,FALSE),"")) | I17: =IF(OR(G17="",H17=""),"",G17*H17) | J17: =IF(D17="","",IFERROR(VLOOKUP(D17,基础资料!$P$5:$T$204,5,FALSE),0)) | K17: =IF(OR(G17="",J17=""),"",G17*J17) | L17: =IF(OR(A17="",C17=""),"",A17+IFERROR(VLOOKUP(C17,基础资料!$Y$5:$AA$204,3,FALSE),0)) | P17: =IF(A17="","","可录入") | Q17: =IF(I17="","",I17-K17)
B18: =IF(A18="","",TEXT(A18,"yyyy-mm")) | E18: =IF(D18="","",IFERROR(VLOOKUP(D18,基础资料!$P$5:$R$204,2,FALSE),"")) | F18: =IF(D18="","",IFERROR(VLOOKUP(D18,基础资料!$P$5:$R$204,3,FALSE),"")) | I18: =IF(OR(G18="",H18=""),"",G18*H18) | J18: =IF(D18="","",IFERROR(VLOOKUP(D18,基础资料!$P$5:$T$204,5,FALSE),0)) | K18: =IF(OR(G18="",J18=""),"",G18*J18) | L18: =IF(OR(A18="",C18=""),"",A18+IFERROR(VLOOKUP(C18,基础资料!$Y$5:$AA$204,3,FALSE),0)) | P18: =IF(A18="","","可录入") | Q18: =IF(I18="","",I18-K18)
B19: =IF(A19="","",TEXT(A19,"yyyy-mm")) | E19: =IF(D19="","",IFERROR(VLOOKUP(D19,基础资料!$P$5:$R$204,2,FALSE),"")) | F19: =IF(D19="","",IFERROR(VLOOKUP(D19,基础资料!$P$5:$R$204,3,FALSE),"")) | I19: =IF(OR(G19="",H19=""),"",G19*H19) | J19: =IF(D19="","",IFERROR(VLOOKUP(D19,基础资料!$P$5:$T$204,5,FALSE),0)) | K19: =IF(OR(G19="",J19=""),"",G19*J19) | L19: =IF(OR(A19="",C19=""),"",A19+IFERROR(VLOOKUP(C19,基础资料!$Y$5:$AA$204,3,FALSE),0)) | P19: =IF(A19="","","可录入") | Q19: =IF(I19="","",I19-K19)
B20: =IF(A20="","",TEXT(A20,"yyyy-mm")) | E20: =IF(D20="","",IFERROR(VLOOKUP(D20,基础资料!$P$5:$R$204,2,FALSE),"")) | F20: =IF(D20="","",IFERROR(VLOOKUP(D20,基础资料!$P$5:$R$204,3,FALSE),"")) | I20: =IF(OR(G20="",H20=""),"",G20*H20) | J20: =IF(D20="","",IFERROR(VLOOKUP(D20,基础资料!$P$5:$T$204,5,FALSE),0)) | K20: =IF(OR(G20="",J20=""),"",G20*J20) | L20: =IF(OR(A20="",C20=""),"",A20+IFERROR(VLOOKUP(C20,基础资料!$Y$5:$AA$204,3,FALSE),0)) | P20: =IF(A20="","","可录入") | Q20: =IF(I20="","",I20-K20)
B21: =IF(A21="","",TEXT(A21,"yyyy-mm")) | E21: =IF(D21="","",IFERROR(VLOOKUP(D21,基础资料!$P$5:$R$204,2,FALSE),"")) | F21: =IF(D21="","",IFERROR(VLOOKUP(D21,基础资料!$P$5:$R$204,3,FALSE),"")) | I21: =IF(OR(G21="",H21=""),"",G21*H21) | J21: =IF(D21="","",IFERROR(VLOOKUP(D21,基础资料!$P$5:$T$204,5,FALSE),0)) | K21: =IF(OR(G21="",J21=""),"",G21*J21) | L21: =IF(OR(A21="",C21=""),"",A21+IFERROR(VLOOKUP(C21,基础资料!$Y$5:$AA$204,3,FALSE),0)) | P21: =IF(A21="","","可录入") | Q21: =IF(I21="","",I21-K21)
B22: =IF(A22="","",TEXT(A22,"yyyy-mm")) | E22: =IF(D22="","",IFERROR(VLOOKUP(D22,基础资料!$P$5:$R$204,2,FALSE),"")) | F22: =IF(D22="","",IFERROR(VLOOKUP(D22,基础资料!$P$5:$R$204,3,FALSE),"")) | I22: =IF(OR(G22="",H22=""),"",G22*H22) | J22: =IF(D22="","",IFERROR(VLOOKUP(D22,基础资料!$P$5:$T$204,5,FALSE),0)) | K22: =IF(OR(G22="",J22=""),"",G22*J22) | L22: =IF(OR(A22="",C22=""),"",A22+IFERROR(VLOOKUP(C22,基础资料!$Y$5:$AA$204,3,FALSE),0)) | P22: =IF(A22="","","可录入") | Q22: =IF(I22="","",I22-K22)
