Workbook

Sheet 首页
A1: 内账财务管理系统
A2: 日常只录四张表：资金流水 · 销售录入 · 采购录入 · 其他凭证 → 总账与全部报表自动生成
A3: 会计年度 | B3: 2026 | D3: 查询月份 | E3: 46023 | G3: ← 全表只有这两格需要设置。跨年度把会计年度改成新的一年，所有报表自动切换，不用改任何公式。
A5: 本月月份 | B5: =TEXT($E$3,"yyyy-mm") -> 2026-01 | D5: 本月月初 | E5: =DATE(YEAR($E$3),MONTH($E$3),1) -> 46023 | G5: 本月月末 | H5: =EOMONTH($E$3,0) -> 46053
B6: =$E$5 -> 46023
B7: =$H$5 -> 46053
A9: 本月营业收入 | D9: 本月毛利 | G9: 本月净利润 | J9: 本年累计净利润
A10: =利润表!$C$6 -> 24600 | D10: =利润表!$C$6-利润表!$C$9 -> 11137.5 | G10: =利润表!$C$27 -> -20662.5 | J10: =利润表!$D$27 -> -20662.5
A12: 货币资金余额 | D12: 应收账款余额 | G12: 应付账款余额 | J12: 存货金额
A13: =账户余额!$H$36 -> 332200 | D13: =应收跟进!$F$156 -> 46686 | G13: =应付跟进!$F$156 -> 21752.5 | J13: =库存收发存!$K$206 -> 40387.5
A15: 逾期应收 | D15: 本月经营现金净额 | G15: 资产总计 | J15: 所有者权益
A16: =应收跟进!$L$156 -> 20696 | D16: =现金流量表!$C$15 -> -2800 | G16: =资产负债表!$C$25 -> 506773.5 | J16: =资产负债表!$G$28 -> 457937.5
A18: 月结状态 | D18: =财务勾稽核查!$E$23&" （"&财务勾稽核查!$C$23&"） "&IF(财务勾稽核查!$E$23="✓ 可以月结","全部勾稽通过，可以结账。","请到【财务勾稽核查】查看未通过的项目。") -> ✓ 可以月结 （16 / 16 项通过） 全部勾稽通过，可以结账。
A20: 每月怎么用
A21: 第 1 步 | B21: 启用时先做一次 | D21: 【科目参数】核对科目和收支科目 →【基础资料】建档案 →【期初数据】录期初余额
A22: 第 2 步 | B22: 平时随时录 | D22: 收付款记【资金流水】；卖出记【销售录入】；进货记【采购录入】
A23: 第 3 步 | B23: 月末做一次 | D23: 工资社保计提、折旧摊销、税金计提记【其他凭证】
A24: 第 4 步 | B24: 月末检查 | D24: 把【首页】查询月份切到本月 →【财务勾稽核查】全部✓ → 打印报表
A25: 第 5 步 | B25: 年末 | D25: 【其他凭证】做结转损益，次年在新文件的【期初数据】录新年度期初

Sheet 操作说明
B2: 操作说明
B4: 一、这套账的设计
B5: 只有四个录入口 | C5: 资金流水（实际收付的钱）、销售录入（卖出去的东西）、采购录入（买进来的东西）、其他凭证（不涉及收付款的账，如计提折旧）。除此之外所有表都是自动算出来的，不要手工改。
B6: 每行自动生成分录 | C6: 每一行业务都会自动算出借方科目和贷方科目，金额相同。所以借贷永远相等，资产负债表永远平——除非期初就没配平。
B7: 没有写死的科目和年份 | C7: 科目表可以随便加，年份改【首页】的会计年度就行，所有报表自动跟着走，不需要改任何公式。
B8: 二、启用步骤（只做一次）
B9: 1. 核对科目参数 | C9: 【科目参数】里已经内置了小企业会计准则的全套科目。行业特殊的科目直接在下面加行；用不到的把「启用」改成停用（不要删行）。
B10: 2. 配置收支科目 | C10: 【科目参数】②是资金流水下拉的来源。每一条要配「对方科目」——就是这笔钱的另一半。比如「房租物业」对方科目是 6602 管理费用，「客户回款」对方科目是 1122 应收账款。行业不同，主要就改这张表。
B11: 3. 建立基础资料 | C11: 【基础资料】里录账户、部门、员工、商品、客户、供应商。停用请改「状态」，不要删整行。
B12: 4. 录入期初 | C12: 【期初数据】录启用那一天的余额。注意两件事：⑤会计科目期初必须借贷相等；5xxx/6xxx 损益类科目不要录期初。
B13: 5. 核对期初 | C13: 到【财务勾稽核查】看第 2～7 项是不是全部✓。期初没配平，后面所有报表都不会平。
B14: 三、年中启用怎么办
B15: 期初只录资产负债 | C15: 比如 8 月才开始用，【期初数据】录的是 7 月 31 日的资产、负债、所有者权益余额，不要把 1～7 月的收入费用录进去。
B16: 本年已发生损益 | C16: 1～7 月的收入和费用，到【其他凭证】按月各做一笔汇总分录补录（业务类型选「年初建账」）。这样利润表的本年累计才是完整的，资产负债表也不会不平。
B17: 四、每月流程
B18: 平时 | C18: 收到钱、付出钱 → 资金流水；卖货开单 → 销售录入；进货收料 → 采购录入。每张表最右边的【校验】列必须是「√」，红色提示必须当天改掉。
B19: 月末 | C19: 工资计提、社保计提、折旧、摊销、税金计提 → 其他凭证。然后把【首页】的查询月份切到本月。
B20: 结账前 | C20: 【财务勾稽核查】必须全部✓。第 14 项「查询月份有业务数据」如果报错，说明这个月一笔账都没有，此时报表全是 0，不要误以为账平了。
B21: 五、常见问题
B22: 资产负债表不平 | C22: 按顺序查勾稽核查的第 2 项（期初借贷）、第 3 项（表间平衡）。九成是期初没配平，或某个科目在【科目参数】里没填「资产负债表项目」。
B23: 应收和总账对不上 | C23: 资金流水里「客户回款」的【往来单位】必须从下拉里选，手打的名字或多一个空格，SUMIFS 就匹配不上，钱进了总账却没冲掉这个客户的应收。
B24: 现金流量表和银行对不上 | C24: 某个收支科目在【科目参数】②里没配「现金流量表项目」。查勾稽核查第 12 项。
B25: 销售成本不对 | C25: 成本单价是按「期初 + 该笔销售日期之前的入库」算移动加权平均。如果这个商品还没有采购记录，会退回用【基础资料】里的参考成本；参考成本也没填就会是 0，校验列会提示。
B26: 要加行怎么办 | C26: 各表都预留了行数（资金流水 500 行、销售采购各 400 行）。不够时请在数据区中间插入整行再复制公式，不要在最后一行下面直接粘贴，那会盖掉合计行。
B27: 六、注意
B28: 不要删整行 | C28: 基础资料、期初数据都是横向分区共用行号，删整行会同时删掉旁边几个区的数据。要清空请选中单元格按 Delete。
B29: 不要动白色和灰色区域 | C29: 黄色是录入区，白色/灰色是公式区。公式被覆盖后不会有任何报错，但报表会静默算错。
B30: 年内不要做结转损益 | C30: 损益科目的余额本身就是本年利润，资产负债表已经自动接住了。结转损益只在 12 月做一次。

Sheet 使用说明
B2: 内账财务管理系统 · 通用版 使用说明
B4: 适用范围
B5: 一套开箱即用的 Excel 内账（管理账）系统，适用于贸易、零售、服务、加工等各类中小企业。只录四张表，总账与全部报表自动生成。
B6: 25 张表怎么分
B7: 入口 | C7: 首页（仪表盘）· 操作说明 · 使用说明（本页）
B8: 配置 | C8: 科目参数（会计科目 + 收支科目）· 基础资料（账户/部门/员工/商品/客户/供应商）· 期初数据
B9: 录入（只有这四张手工填） | C9: 资金流水 · 销售录入 · 采购录入 · 其他凭证
B10: 总账报表 | C10: 科目余额表 · 科目分析 · 利润表 · 资产负债表 · 现金流量表
B11: 业务辅助 | C11: 账户余额 · 库存收发存 · 应收跟进 · 应付跟进 · 固定资产台账 · 工资表 · 辅助核算 · 客户对账单 · 供应商对账单 · 经营分析
B12: 月结 | C12: 财务勾稽核查（16 项跨表比对）
B13: 核心设计
B14: 每行业务自带分录对 | C14: 每一行录入都会自动算出借方科目、贷方科目和金额，一行同时贡献一借一贷。所以借贷是结构性相等，不可能出现单边挂账。
B15: 没有写死的科目和年份 | C15: 科目表随便加，年度在首页改一格，所有报表自动跟随。科目余额表以「期间 + 科目」为键统一汇总。
B16: 兼容性 | C16: 全部使用 Excel 2007 就有的函数，没有 FILTER / XLOOKUP / TEXTJOIN 等动态数组函数。WPS 个人版、Excel 2016 都能正常打开和重算。
B17: 快速开始（只做一次）
B18: 1. 改首页两格 | C18: 会计年度、查询月份。
B19: 2. 配收支科目 | C19: 【科目参数】第二区，每条配好「对方科目」——这笔钱的另一半。这是适配不同行业的主要工作：餐饮加「食材采购」、电商加「平台佣金」、诊所加「药品采购」。
B20: 3. 建档案 | C20: 【基础资料】录账户、部门、员工、商品、客户、供应商。
B21: 4. 录期初 | C21: 【期初数据】录启用日的资产、负债、所有者权益余额。⑤会计科目期初必须借贷相等。
B22: 5. 核对 | C22: 【财务勾稽核查】第 2～7 项全部 ✓ 之后再开始日常录入。
B23: 每月流程
B24: 平时 | C24: 收付款 → 资金流水；卖出 → 销售录入；买入 → 采购录入。
B25: 月末 | C25: 工资 / 社保 / 折旧 / 摊销 / 税金计提 → 其他凭证。
B26: 结账前 | C26: 首页切到本月 →【财务勾稽核查】全部 ✓ → 打印报表。
B27: 年末 | C27: 【其他凭证】做结转损益，次年在新文件的【期初数据】录新年度期初。
B28: 关键口径
B29: 销售成本 | C29: 按「期初 + 该笔销售日期之前的入库」计算移动加权平均单价。无采购记录时退回商品档案的参考成本。
B30: 库存金额 | C30: 期初金额 + 采购金额 − 结转成本，与科目余额表的「库存商品」永远一致。
B31: 账龄分桶 | C31: 按到期日累计应收额减累计回款，等价于回款先冲抵最早的单据（FIFO）。
B32: 未分配利润 | C32: 利润分配类科目余额 + 利润表本年净利润。年末做了结转损益也不会重复计算。
B33: 现金流量表 | C33: 直接法，按收支科目自动归类；账户间内部转账不计入。
B34: 年中启用 | C34: 期初只录资产负债权益，本年已发生的收入费用到【其他凭证】按月补录（业务类型选「年初建账」）。损益类科目不要录期初。
B35: 容量
B36: 资金流水 500 行 · 销售 400 行 · 采购 400 行 · 其他凭证 300 行 · 会计科目 120 个 · 商品 200 · 客户/供应商各 150 · 员工 60 · 固定资产 100。
B37: 不够时在数据区中间插入整行再复制公式，不要在最后一行下面直接粘贴（会盖掉合计行）。
B38: 颜色约定
B39: 淡黄底＝手工录入 ｜ 白 / 灰底＝公式自动计算，请勿覆盖 ｜ 绿色字＝引用其他工作表 ｜ 红底＝校验未通过，必须处理。
B40: 工作表标签也按功能分色：深蓝＝入口，灰＝配置，橙＝录入，绿＝总账报表，蓝＝业务辅助，红＝月结检查。
B41: 注意
B42: 不要删整行 | C42: 基础资料、期初数据是横向分区共用行号，删整行会同时删掉旁边几个区的数据。清空请选中单元格按 Delete。
...

Sheet 科目参数
A1: 科目参数
A2: 会计科目表决定报表怎么出数；收支科目表决定每一笔资金流水自动记到哪个科目。两张表都可以按自己行业增删。
A4: 一、会计科目表（报表按这里的映射自动归集，不要删除已用科目） | K4: 二、收支科目表（资金流水的下拉来源，决定自动分录）
A5: 科目编码 | B5: 科目名称 | C5: 类别 | D5: 余额 方向 | E5: 启用 | F5: 资产负债表项目 | G5: 利润表项目 | H5: 现金流性质 | I5: 辅助核算 | K5: 序号 | L5: 收支 类型 | M5: 收支科目 | N5: 对方科目 编码 | O5: 对方科目名称 | P5: 现金流量表项目 | Q5: 说明
A6: 1001 | B6: 库存现金 | C6: 资产 | D6: 借 | E6: 启用 | F6: 货币资金 | H6: 现金类 | I6: — | K6: =IF($M6="","",ROW()-5) -> 1 | L6: 收入 | M6: 客户回款 | N6: 1122 | O6: =IF($N6="","",IFERROR(INDEX($B$6:$B$125,MATCH($N6,$A$6:$A$125,0)),"⚠科目不存在")) -> 应收账款 | P6: 销售商品、提供劳务收到的现金
A7: 1002 | B7: 银行存款 | C7: 资产 | D7: 借 | E7: 启用 | F7: 货币资金 | H7: 现金类 | I7: — | K7: =IF($M7="","",ROW()-5) -> 2 | L7: 收入 | M7: 预收货款 | N7: 2203 | O7: =IF($N7="","",IFERROR(INDEX($B$6:$B$125,MATCH($N7,$A$6:$A$125,0)),"⚠科目不存在")) -> 预收账款 | P7: 销售商品、提供劳务收到的现金
A8: 1012 | B8: 其他货币资金 | C8: 资产 | D8: 借 | E8: 启用 | F8: 货币资金 | H8: 现金类 | I8: — | K8: =IF($M8="","",ROW()-5) -> 3 | L8: 收入 | M8: 现销收入 | N8: 6001 | O8: =IF($N8="","",IFERROR(INDEX($B$6:$B$125,MATCH($N8,$A$6:$A$125,0)),"⚠科目不存在")) -> 主营业务收入 | P8: 销售商品、提供劳务收到的现金
A9: 1101 | B9: 交易性金融资产 | C9: 资产 | D9: 借 | E9: 启用 | F9: 交易性金融资产 | H9: 投资活动 | I9: — | K9: =IF($M9="","",ROW()-5) -> 4 | L9: 收入 | M9: 其他业务收入 | N9: 6051 | O9: =IF($N9="","",IFERROR(INDEX($B$6:$B$125,MATCH($N9,$A$6:$A$125,0)),"⚠科目不存在")) -> 其他业务收入 | P9: 收到的其他与经营活动有关的现金
A10: 1121 | B10: 应收票据 | C10: 资产 | D10: 借 | E10: 启用 | F10: 应收票据 | H10: 经营活动 | I10: 客户 | K10: =IF($M10="","",ROW()-5) -> 5 | L10: 收入 | M10: 政府补助 | N10: 6117 | O10: =IF($N10="","",IFERROR(INDEX($B$6:$B$125,MATCH($N10,$A$6:$A$125,0)),"⚠科目不存在")) -> 其他收益 | P10: 收到的其他与经营活动有关的现金
A11: 1122 | B11: 应收账款 | C11: 资产 | D11: 借 | E11: 启用 | F11: 应收账款 | H11: 经营活动 | I11: 客户 | K11: =IF($M11="","",ROW()-5) -> 6 | L11: 收入 | M11: 利息收入 | N11: 6603 | O11: =IF($N11="","",IFERROR(INDEX($B$6:$B$125,MATCH($N11,$A$6:$A$125,0)),"⚠科目不存在")) -> 财务费用 | P11: 收到的其他与经营活动有关的现金
A12: 1123 | B12: 预付账款 | C12: 资产 | D12: 借 | E12: 启用 | F12: 预付款项 | H12: 经营活动 | I12: 供应商 | K12: =IF($M12="","",ROW()-5) -> 7 | L12: 收入 | M12: 租金收入 | N12: 6051 | O12: =IF($N12="","",IFERROR(INDEX($B$6:$B$125,MATCH($N12,$A$6:$A$125,0)),"⚠科目不存在")) -> 其他业务收入 | P12: 收到的其他与经营活动有关的现金
A13: 1131 | B13: 应收股利 | C13: 资产 | D13: 借 | E13: 启用 | F13: 其他应收款 | H13: 投资活动 | I13: — | K13: =IF($M13="","",ROW()-5) -> 8 | L13: 收入 | M13: 废料收入 | N13: 6051 | O13: =IF($N13="","",IFERROR(INDEX($B$6:$B$125,MATCH($N13,$A$6:$A$125,0)),"⚠科目不存在")) -> 其他业务收入 | P13: 收到的其他与经营活动有关的现金
A14: 1132 | B14: 应收利息 | C14: 资产 | D14: 借 | E14: 启用 | F14: 其他应收款 | H14: 投资活动 | I14: — | K14: =IF($M14="","",ROW()-5) -> 9 | L14: 收入 | M14: 退回押金保证金 | N14: 1221 | O14: =IF($N14="","",IFERROR(INDEX($B$6:$B$125,MATCH($N14,$A$6:$A$125,0)),"⚠科目不存在")) -> 其他应收款 | P14: 收到的其他与经营活动有关的现金
A15: 1221 | B15: 其他应收款 | C15: 资产 | D15: 借 | E15: 启用 | F15: 其他应收款 | H15: 经营活动 | I15: 员工/其他 | K15: =IF($M15="","",ROW()-5) -> 10 | L15: 收入 | M15: 收回备用金 | N15: 1221 | O15: =IF($N15="","",IFERROR(INDEX($B$6:$B$125,MATCH($N15,$A$6:$A$125,0)),"⚠科目不存在")) -> 其他应收款 | P15: 收到的其他与经营活动有关的现金
A16: 1231 | B16: 坏账准备 | C16: 资产 | D16: 贷 | E16: 启用 | F16: 应收账款 | H16: 非现金 | I16: — | K16: =IF($M16="","",ROW()-5) -> 11 | L16: 收入 | M16: 营业外收入 | N16: 6301 | O16: =IF($N16="","",IFERROR(INDEX($B$6:$B$125,MATCH($N16,$A$6:$A$125,0)),"⚠科目不存在")) -> 营业外收入 | P16: 收到的其他与经营活动有关的现金
A17: 1401 | B17: 材料采购 | C17: 资产 | D17: 借 | E17: 启用 | F17: 存货 | H17: 经营活动 | I17: — | K17: =IF($M17="","",ROW()-5) -> 12 | L17: 收入 | M17: 处置固定资产收入 | N17: 1606 | O17: =IF($N17="","",IFERROR(INDEX($B$6:$B$125,MATCH($N17,$A$6:$A$125,0)),"⚠科目不存在")) -> 固定资产清理 | P17: 处置固定资产收回的现金净额
... A53: 4002 | B53: 资本公积 | C53: 权益 | D53: 贷 | E53: 启用 | F53: 资本公积 | H53: 筹资活动 | I53: — | K53: =IF($M53="","",ROW()-5) -> 48 | L53: 支出 | M53: 对外投资 | N53: 1511 | O53: =IF($N53="","",IFERROR(INDEX($B$6:$B$125,MATCH($N53,$A$6:$A$125,0)),"⚠科目不存在")) -> 长期股权投资 | P53: 投资支付的现金
A54: 4101 | B54: 盈余公积 | C54: 权益 | D54: 贷 | E54: 启用 | F54: 盈余公积 | H54: 非现金 | I54: — | K54: =IF($M54="","",ROW()-5) -> 49 | L54: 转账 | M54: 账户转账 | O54: =IF($N54="","",IFERROR(INDEX($B$6:$B$125,MATCH($N54,$A$6:$A$125,0)),"⚠科目不存在")) | P54: —
A55: 4103 | B55: 本年利润 | C55: 权益 | D55: 贷 | E55: 启用 | F55: 未分配利润 | H55: 非现金 | I55: — | K55: =IF($M55="","",ROW()-5) | O55: =IF($N55="","",IFERROR(INDEX($B$6:$B$125,MATCH($N55,$A$6:$A$125,0)),"⚠科目不存在"))
A56: 4104 | B56: 利润分配 | C56: 权益 | D56: 贷 | E56: 启用 | F56: 未分配利润 | H56: 筹资活动 | I56: — | K56: =IF($M56="","",ROW()-5) | O56: =IF($N56="","",IFERROR(INDEX($B$6:$B$125,MATCH($N56,$A$6:$A$125,0)),"⚠科目不存在"))
A57: 5001 | B57: 生产成本 | C57: 成本 | D57: 借 | E57: 启用 | F57: 存货 | H57: 经营活动 | I57: — | K57: =IF($M57="","",ROW()-5) | O57: =IF($N57="","",IFERROR(INDEX($B$6:$B$125,MATCH($N57,$A$6:$A$125,0)),"⚠科目不存在"))
A58: 5101 | B58: 制造费用 | C58: 成本 | D58: 借 | E58: 启用 | F58: 存货 | H58: 经营活动 | I58: 部门 | K58: =IF($M58="","",ROW()-5) | O58: =IF($N58="","",IFERROR(INDEX($B$6:$B$125,MATCH($N58,$A$6:$A$125,0)),"⚠科目不存在"))
A59: 5201 | B59: 劳务成本 | C59: 成本 | D59: 借 | E59: 启用 | F59: 存货 | H59: 经营活动 | I59: — | K59: =IF($M59="","",ROW()-5) | O59: =IF($N59="","",IFERROR(INDEX($B$6:$B$125,MATCH($N59,$A$6:$A$125,0)),"⚠科目不存在"))
A60: 6001 | B60: 主营业务收入 | C60: 收入 | D60: 贷 | E60: 启用 | G60: 主营业务收入 | H60: 经营活动 | I60: 客户/商品 | K60: =IF($M60="","",ROW()-5) | O60: =IF($N60="","",IFERROR(INDEX($B$6:$B$125,MATCH($N60,$A$6:$A$125,0)),"⚠科目不存在"))
A61: 6051 | B61: 其他业务收入 | C61: 收入 | D61: 贷 | E61: 启用 | G61: 其他业务收入 | H61: 经营活动 | I61: 客户 | K61: =IF($M61="","",ROW()-5) | O61: =IF($N61="","",IFERROR(INDEX($B$6:$B$125,MATCH($N61,$A$6:$A$125,0)),"⚠科目不存在"))
A62: 6111 | B62: 投资收益 | C62: 收入 | D62: 贷 | E62: 启用 | G62: 投资收益 | H62: 投资活动 | I62: — | K62: =IF($M62="","",ROW()-5) | O62: =IF($N62="","",IFERROR(INDEX($B$6:$B$125,MATCH($N62,$A$6:$A$125,0)),"⚠科目不存在"))
A63: 6115 | B63: 资产处置收益 | C63: 收入 | D63: 贷 | E63: 启用 | G63: 资产处置收益 | H63: 投资活动 | I63: — | K63: =IF($M63="","",ROW()-5) | O63: =IF($N63="","",IFERROR(INDEX($B$6:$B$125,MATCH($N63,$A$6:$A$125,0)),"⚠科目不存在"))
A64: 6117 | B64: 其他收益 | C64: 收入 | D64: 贷 | E64: 启用 | G64: 其他收益 | H64: 经营活动 | I64: — | K64: =IF($M64="","",ROW()-5) | O64: =IF($N64="","",IFERROR(INDEX($B$6:$B$125,MATCH($N64,$A$6:$A$125,0)),"⚠科目不存在"))
A65: 6301 | B65: 营业外收入 | C65: 收入 | D65: 贷 | E65: 启用 | G65: 营业外收入 | H65: 经营活动 | I65: — | K65: =IF($M65="","",ROW()-5) | O65: =IF($N65="","",IFERROR(INDEX($B$6:$B$125,MATCH($N65,$A$6:$A$125,0)),"⚠科目不存在"))
A66: 6401 | B66: 主营业务成本 | C66: 费用 | D66: 借 | E66: 启用 | G66: 主营业务成本 | H66: 经营活动 | I66: 客户/商品 | K66: =IF($M66="","",ROW()-5) | O66: =IF($N66="","",IFERROR(INDEX($B$6:$B$125,MATCH($N66,$A$6:$A$125,0)),"⚠科目不存在"))
A67: 6402 | B67: 其他业务成本 | C67: 费用 | D67: 借 | E67: 启用 | G67: 其他业务成本 | H67: 经营活动 | I67: — | K67: =IF($M67="","",ROW()-5) | O67: =IF($N67="","",IFERROR(INDEX($B$6:$B$125,MATCH($N67,$A$6:$A$125,0)),"⚠科目不存在"))
A68: 6403 | B68: 税金及附加 | C68: 费用 | D68: 借 | E68: 启用 | G68: 税金及附加 | H68: 经营活动 | I68: — | K68: =IF($M68="","",ROW()-5) | O68: =IF($N68="","",IFERROR(INDEX($B$6:$B$125,MATCH($N68,$A$6:$A$125,0)),"⚠科目不存在"))
A69: 6601 | B69: 销售费用 | C69: 费用 | D69: 借 | E69: 启用 | G69: 销售费用 | H69: 经营活动 | I69: 部门/员工 | K69: =IF($M69="","",ROW()-5) | O69: =IF($N69="","",IFERROR(INDEX($B$6:$B$125,MATCH($N69,$A$6:$A$125,0)),"⚠科目不存在"))
A70: 6602 | B70: 管理费用 | C70: 费用 | D70: 借 | E70: 启用 | G70: 管理费用 | H70: 经营活动 | I70: 部门/员工 | K70: =IF($M70="","",ROW()-5) | O70: =IF($N70="","",IFERROR(INDEX($B$6:$B$125,MATCH($N70,$A$6:$A$125,0)),"⚠科目不存在"))
A71: 6603 | B71: 财务费用 | C71: 费用 | D71: 借 | E71: 启用 | G71: 财务费用 | H71: 经营活动 | I71: — | K71: =IF($M71="","",ROW()-5) | O71: =IF($N71="","",IFERROR(INDEX($B$6:$B$125,MATCH($N71,$A$6:$A$125,0)),"⚠科目不存在"))
... A76: 6801 | B76: 所得税费用 | C76: 费用 | D76: 借 | E76: 启用 | G76: 所得税费用 | H76: 经营活动 | I76: — | K76: =IF($M76="","",ROW()-5) | O76: =IF($N76="","",IFERROR(INDEX($B$6:$B$125,MATCH($N76,$A$6:$A$125,0)),"⚠科目不存在"))
K77: =IF($M77="","",ROW()-5) | O77: =IF($N77="","",IFERROR(INDEX($B$6:$B$125,MATCH($N77,$A$6:$A$125,0)),"⚠科目不存在"))
K78: =IF($M78="","",ROW()-5) | O78: =IF($N78="","",IFERROR(INDEX($B$6:$B$125,MATCH($N78,$A$6:$A$125,0)),"⚠科目不存在"))
K79: =IF($M79="","",ROW()-5) | O79: =IF($N79="","",IFERROR(INDEX($B$6:$B$125,MATCH($N79,$A$6:$A$125,0)),"⚠科目不存在"))
K80: =IF($M80="","",ROW()-5) | O80: =IF($N80="","",IFERROR(INDEX($B$6:$B$125,MATCH($N80,$A$6:$A$125,0)),"⚠科目不存在"))
...

Sheet 基础资料
A1: 基础资料
A2: 所有下拉都来自这里。要停用某个档案请把【状态】改成停用，不要删除整行——本表六个区共用行号，删行会同时删掉其他区的档案。
A4: ① 资金账户 | G4: ② 部门 | K4: ③ 员工 | P4: ④ 商品 / 材料 / 服务 | Y4: ⑤ 客户 | AE4: ⑥ 供应商
A5: 账户名称 | B5: 账户类型 | C5: 资金科目 编码 | D5: 状态 | E5: 备注 | G5: 部门名称 | H5: 状态 | I5: 备注 | K5: 姓名 | L5: 所属部门 | M5: 岗位 | N5: 状态 | P5: 商品编号 | Q5: 商品名称 | R5: 规格型号 | S5: 单位 | T5: 参考售价 | U5: 参考成本 | V5: 是否 存货 | W5: 状态 | Y5: 客户编号 | Z5: 客户名称 | AA5: 业务员 | AB5: 账期 (天) | AC5: 状态 | AE5: 供应商编号 | AF5: 供应商名称 | AG5: 采购员 | AH5: 账期 (天) | AI5: 状态
A6: 库存现金 | B6: 现金 | C6: 1001 | D6: 正常 | G6: 销售部 | H6: 正常 | K6: 张伟 | L6: 销售部 | M6: 销售 | N6: 正常 | P6: P001 | Q6: A型配件 | R6: A-01 | S6: 个 | T6: 200 | U6: 100 | V6: 是 | W6: 正常 | Y6: C001 | Z6: 示例客户甲 | AA6: 张伟 | AB6: 30 | AC6: 正常 | AE6: S001 | AF6: 示例供应商甲 | AG6: 李娜 | AH6: 30 | AI6: 正常
A7: 工商银行 | B7: 银行 | C7: 1002 | D7: 正常 | G7: 采购部 | H7: 正常 | K7: 李娜 | L7: 采购部 | M7: 采购 | N7: 正常 | P7: P002 | Q7: B型配件 | R7: B-02 | S7: 个 | T7: 350 | U7: 220 | V7: 是 | W7: 正常 | Y7: C002 | Z7: 示例客户乙 | AA7: 张伟 | AB7: 60 | AC7: 正常 | AE7: S002 | AF7: 示例供应商乙 | AG7: 李娜 | AH7: 45 | AI7: 正常
A8: 支付宝 | B8: 第三方 | C8: 1012 | D8: 正常 | G8: 财务部 | H8: 正常 | K8: 王强 | L8: 财务部 | M8: 会计 | N8: 正常 | P8: P003 | Q8: C型组件 | R8: C-10 | S8: 套 | T8: 1200 | U8: 780 | V8: 是 | W8: 正常 | Y8: C003 | Z8: 示例客户丙 | AA8: 张伟 | AB8: 0 | AC8: 正常
A9: 微信 | B9: 第三方 | C9: 1012 | D9: 正常 | G9: 行政部 | H9: 正常 | K9: 赵敏 | L9: 行政部 | M9: 行政 | N9: 正常 | P9: F001 | Q9: 安装服务 | R9: — | S9: 次 | T9: 800 | U9: 0 | V9: 否 | W9: 正常
A207: 颜色约定：淡黄色＝手工录入 ｜ 白色 / 灰色＝公式自动计算，请勿覆盖 ｜ 绿色字＝引用其他工作表，改动会连锁出错。整行删除会破坏结构，清空请选中后按 Delete。

Sheet 期初数据
A1: 期初数据（启用时录一次）
A2: 只录启用日的资产、负债、所有者权益余额。本年已发生的收入和费用请到【其他凭证】按月补录，不要录在这里，否则资产负债表会不平。
A3: 平衡校验： | B3: 明细合计·资金 | C3: =SUM($B$6:$B$35) -> 335000 | E3: 明细合计·应收 | F3: =SUM($G$6:$G$155) -> 80000 | J3: 明细合计·应付 | K3: =SUM($L$6:$L$155) -> 40000 | O3: 明细合计·存货 | P3: =SUM($T$6:$T$205) -> 36600 | W3: 科目借方合计 | X3: =SUM($Z$6:$Z$125) -> 571600 | Z3: 科目贷方合计 | AA3: =SUM($AA$6:$AA$125) -> 571600 | AB3: =IF(ABS(SUM($Z$6:$Z$125)-SUM($AA$6:$AA$125))<0.01,"✓ 借贷平衡","✗ 借贷不平，差额 "&TEXT(SUM($Z$6:$Z$125)-SUM($AA$6:$AA$125),"#,##0.00")) -> ✓ 借贷平衡
A4: ① 资金期初 | E4: ② 应收期初 | J4: ③ 应付期初 | O4: ④ 存货期初 | W4: ⑤ 会计科目期初（总账口径，必须借贷相等）
A5: 账户 | B5: 期初余额 | C5: 备注 | E5: 客户 | F5: 原业务日期 | G5: 期初应收 | H5: 备注 | J5: 供应商 | K5: 原业务日期 | L5: 期初应付 | M5: 备注 | O5: 商品 | P5: 规格 | Q5: 单位 | R5: 期初数量 | S5: 期初单位成本 | T5: 期初金额 | U5: 备注 | W5: 科目编码 | X5: 科目名称 | Y5: 方向 | Z5: 期初借方 | AA5: 期初贷方 | AB5: 备注
A6: 库存现金 | B6: 20000 | E6: 示例客户甲 | F6: 45992 | G6: 50000 | J6: 示例供应商甲 | K6: 46001 | L6: 40000 | O6: A型配件 | P6: =IF($O6="","",IFERROR(INDEX(基础资料!$R$6:$R$205,MATCH($O6,基础资料!$Q$6:$Q$205,0)),"")) -> A-01 | Q6: =IF($O6="","",IFERROR(INDEX(基础资料!$S$6:$S$205,MATCH($O6,基础资料!$Q$6:$Q$205,0)),"")) -> 个 | R6: 100 | S6: 100 | T6: =IF($O6="","",ROUND(N($R6)*N($S6),2)) -> 10000 | W6: 1001 | X6: =IF($W6="","",IFERROR(INDEX(科目参数!$B$6:$B$125,MATCH($W6,科目参数!$A$6:$A$125,0)),"⚠科目不存在")) -> 库存现金 | Y6: =IF($W6="","",IFERROR(INDEX(科目参数!$D$6:$D$125,MATCH($W6,科目参数!$A$6:$A$125,0)),"")) -> 借 | Z6: 20000 | AA6: 0
A7: 工商银行 | B7: 300000 | E7: 示例客户乙 | F7: 45976 | G7: 30000 | O7: B型配件 | P7: =IF($O7="","",IFERROR(INDEX(基础资料!$R$6:$R$205,MATCH($O7,基础资料!$Q$6:$Q$205,0)),"")) -> B-02 | Q7: =IF($O7="","",IFERROR(INDEX(基础资料!$S$6:$S$205,MATCH($O7,基础资料!$Q$6:$Q$205,0)),"")) -> 个 | R7: 50 | S7: 220 | T7: =IF($O7="","",ROUND(N($R7)*N($S7),2)) -> 11000 | W7: 1002 | X7: =IF($W7="","",IFERROR(INDEX(科目参数!$B$6:$B$125,MATCH($W7,科目参数!$A$6:$A$125,0)),"⚠科目不存在")) -> 银行存款 | Y7: =IF($W7="","",IFERROR(INDEX(科目参数!$D$6:$D$125,MATCH($W7,科目参数!$A$6:$A$125,0)),"")) -> 借 | Z7: 300000 | AA7: 0
A8: 支付宝 | B8: 15000 | O8: C型组件 | P8: =IF($O8="","",IFERROR(INDEX(基础资料!$R$6:$R$205,MATCH($O8,基础资料!$Q$6:$Q$205,0)),"")) -> C-10 | Q8: =IF($O8="","",IFERROR(INDEX(基础资料!$S$6:$S$205,MATCH($O8,基础资料!$Q$6:$Q$205,0)),"")) -> 套 | R8: 20 | S8: 780 | T8: =IF($O8="","",ROUND(N($R8)*N($S8),2)) -> 15600 | W8: 1012 | X8: =IF($W8="","",IFERROR(INDEX(科目参数!$B$6:$B$125,MATCH($W8,科目参数!$A$6:$A$125,0)),"⚠科目不存在")) -> 其他货币资金 | Y8: =IF($W8="","",IFERROR(INDEX(科目参数!$D$6:$D$125,MATCH($W8,科目参数!$A$6:$A$125,0)),"")) -> 借 | Z8: 15000 | AA8: 0
P9: =IF($O9="","",IFERROR(INDEX(基础资料!$R$6:$R$205,MATCH($O9,基础资料!$Q$6:$Q$205,0)),"")) | Q9: =IF($O9="","",IFERROR(INDEX(基础资料!$S$6:$S$205,MATCH($O9,基础资料!$Q$6:$Q$205,0)),"")) | T9: =IF($O9="","",ROUND(N($R9)*N($S9),2)) | W9: 1122 | X9: =IF($W9="","",IFERROR(INDEX(科目参数!$B$6:$B$125,MATCH($W9,科目参数!$A$6:$A$125,0)),"⚠科目不存在")) -> 应收账款 | Y9: =IF($W9="","",IFERROR(INDEX(科目参数!$D$6:$D$125,MATCH($W9,科目参数!$A$6:$A$125,0)),"")) -> 借 | Z9: 80000 | AA9: 0
P10: =IF($O10="","",IFERROR(INDEX(基础资料!$R$6:$R$205,MATCH($O10,基础资料!$Q$6:$Q$205,0)),"")) | Q10: =IF($O10="","",IFERROR(INDEX(基础资料!$S$6:$S$205,MATCH($O10,基础资料!$Q$6:$Q$205,0)),"")) | T10: =IF($O10="","",ROUND(N($R10)*N($S10),2)) | W10: 1405 | X10: =IF($W10="","",IFERROR(INDEX(科目参数!$B$6:$B$125,MATCH($W10,科目参数!$A$6:$A$125,0)),"⚠科目不存在")) -> 库存商品 | Y10: =IF($W10="","",IFERROR(INDEX(科目参数!$D$6:$D$125,MATCH($W10,科目参数!$A$6:$A$125,0)),"")) -> 借 | Z10: 36600 | AA10: 0
P11: =IF($O11="","",IFERROR(INDEX(基础资料!$R$6:$R$205,MATCH($O11,基础资料!$Q$6:$Q$205,0)),"")) | Q11: =IF($O11="","",IFERROR(INDEX(基础资料!$S$6:$S$205,MATCH($O11,基础资料!$Q$6:$Q$205,0)),"")) | T11: =IF($O11="","",ROUND(N($R11)*N($S11),2)) | W11: 1601 | X11: =IF($W11="","",IFERROR(INDEX(科目参数!$B$6:$B$125,MATCH($W11,科目参数!$A$6:$A$125,0)),"⚠科目不存在")) -> 固定资产 | Y11: =IF($W11="","",IFERROR(INDEX(科目参数!$D$6:$D$125,MATCH($W11,科目参数!$A$6:$A$125,0)),"")) -> 借 | Z11: 120000 | AA11: 0
P12: =IF($O12="","",IFERROR(INDEX(基础资料!$R$6:$R$205,MATCH($O12,基础资料!$Q$6:$Q$205,0)),"")) | Q12: =IF($O12="","",IFERROR(INDEX(基础资料!$S$6:$S$205,MATCH($O12,基础资料!$Q$6:$Q$205,0)),"")) | T12: =IF($O12="","",ROUND(N($R12)*N($S12),2)) | W12: 1602 | X12: =IF($W12="","",IFERROR(INDEX(科目参数!$B$6:$B$125,MATCH($W12,科目参数!$A$6:$A$125,0)),"⚠科目不存在")) -> 累计折旧 | Y12: =IF($W12="","",IFERROR(INDEX(科目参数!$D$6:$D$125,MATCH($W12,科目参数!$A$6:$A$125,0)),"")) -> 贷 | Z12: 0 | AA12: 30000
P13: =IF($O13="","",IFERROR(INDEX(基础资料!$R$6:$R$205,MATCH($O13,基础资料!$Q$6:$Q$205,0)),"")) | Q13: =IF($O13="","",IFERROR(INDEX(基础资料!$S$6:$S$205,MATCH($O13,基础资料!$Q$6:$Q$205,0)),"")) | T13: =IF($O13="","",ROUND(N($R13)*N($S13),2)) | W13: 2202 | X13: =IF($W13="","",IFERROR(INDEX(科目参数!$B$6:$B$125,MATCH($W13,科目参数!$A$6:$A$125,0)),"⚠科目不存在")) -> 应付账款 | Y13: =IF($W13="","",IFERROR(INDEX(科目参数!$D$6:$D$125,MATCH($W13,科目参数!$A$6:$A$125,0)),"")) -> 贷 | Z13: 0 | AA13: 40000
P14: =IF($O14="","",IFERROR(INDEX(基础资料!$R$6:$R$205,MATCH($O14,基础资料!$Q$6:$Q$205,0)),"")) | Q14: =IF($O14="","",IFERROR(INDEX(基础资料!$S$6:$S$205,MATCH($O14,基础资料!$Q$6:$Q$205,0)),"")) | T14: =IF($O14="","",ROUND(N($R14)*N($S14),2)) | W14: 2211 | X14: =IF($W14="","",IFERROR(INDEX(科目参数!$B$6:$B$125,MATCH($W14,科目参数!$A$6:$A$125,0)),"⚠科目不存在")) -> 应付职工薪酬 | Y14: =IF($W14="","",IFERROR(INDEX(科目参数!$D$6:$D$125,MATCH($W14,科目参数!$A$6:$A$125,0)),"")) -> 贷 | Z14: 0 | AA14: 15000
P15: =IF($O15="","",IFERROR(INDEX(基础资料!$R$6:$R$205,MATCH($O15,基础资料!$Q$6:$Q$205,0)),"")) | Q15: =IF($O15="","",IFERROR(INDEX(基础资料!$S$6:$S$205,MATCH($O15,基础资料!$Q$6:$Q$205,0)),"")) | T15: =IF($O15="","",ROUND(N($R15)*N($S15),2)) | W15: 2221 | X15: =IF($W15="","",IFERROR(INDEX(科目参数!$B$6:$B$125,MATCH($W15,科目参数!$A$6:$A$125,0)),"⚠科目不存在")) -> 应交税费 | Y15: =IF($W15="","",IFERROR(INDEX(科目参数!$D$6:$D$125,MATCH($W15,科目参数!$A$6:$A$125,0)),"")) -> 贷 | Z15: 0 | AA15: 8000
P16: =IF($O16="","",IFERROR(INDEX(基础资料!$R$6:$R$205,MATCH($O16,基础资料!$Q$6:$Q$205,0)),"")) | Q16: =IF($O16="","",IFERROR(INDEX(基础资料!$S$6:$S$205,MATCH($O16,基础资料!$Q$6:$Q$205,0)),"")) | T16: =IF($O16="","",ROUND(N($R16)*N($S16),2)) | W16: 4001 | X16: =IF($W16="","",IFERROR(INDEX(科目参数!$B$6:$B$125,MATCH($W16,科目参数!$A$6:$A$125,0)),"⚠科目不存在")) -> 实收资本 | Y16: =IF($W16="","",IFERROR(INDEX(科目参数!$D$6:$D$125,MATCH($W16,科目参数!$A$6:$A$125,0)),"")) -> 贷 | Z16: 0 | AA16: 400000
P17: =IF($O17="","",IFERROR(INDEX(基础资料!$R$6:$R$205,MATCH($O17,基础资料!$Q$6:$Q$205,0)),"")) | Q17: =IF($O17="","",IFERROR(INDEX(基础资料!$S$6:$S$205,MATCH($O17,基础资料!$Q$6:$Q$205,0)),"")) | T17: =IF($O17="","",ROUND(N($R17)*N($S17),2)) | W17: 4104 | X17: =IF($W17="","",IFERROR(INDEX(科目参数!$B$6:$B$125,MATCH($W17,科目参数!$A$6:$A$125,0)),"⚠科目不存在")) -> 利润分配 | Y17: =IF($W17="","",IFERROR(INDEX(科目参数!$D$6:$D$125,MATCH($W17,科目参数!$A$6:$A$125,0)),"")) -> 贷 | Z17: 0 | AA17: 78600
P18: =IF($O18="","",IFERROR(INDEX(基础资料!$R$6:$R$205,MATCH($O18,基础资料!$Q$6:$Q$205,0)),"")) | Q18: =IF($O18="","",IFERROR(INDEX(基础资料!$S$6:$S$205,MATCH($O18,基础资料!$Q$6:$Q$205,0)),"")) | T18: =IF($O18="","",ROUND(N($R18)*N($S18),2)) | X18: =IF($W18="","",IFERROR(INDEX(科目参数!$B$6:$B$125,MATCH($W18,科目参数!$A$6:$A$125,0)),"⚠科目不存在")) | Y18: =IF($W18="","",IFERROR(INDEX(科目参数!$D$6:$D$125,MATCH($W18,科目参数!$A$6:$A$125,0)),""))
P19: =IF($O19="","",IFERROR(INDEX(基础资料!$R$6:$R$205,MATCH($O19,基础资料!$Q$6:$Q$205,0)),"")) | Q19: =IF($O19="","",IFERROR(INDEX(基础资料!$S$6:$S$205,MATCH($O19,基础资料!$Q$6:$Q$205,0)),"")) | T19: =IF($O19="","",ROUND(N($R19)*N($S19),2)) | X19: =IF($W19="","",IFERROR(INDEX(科目参数!$B$6:$B$125,MATCH($W19,科目参数!$A$6:$A$125,0)),"⚠科目不存在")) | Y19: =IF($W19="","",IFERROR(INDEX(科目参数!$D$6:$D$125,MATCH($W19,科目参数!$A$6:$A$125,0)),""))
P20: =IF($O20="","",IFERROR(INDEX(基础资料!$R$6:$R$205,MATCH($O20,基础资料!$Q$6:$Q$205,0)),"")) | Q20: =IF($O20="","",IFERROR(INDEX(基础资料!$S$6:$S$205,MATCH($O20,基础资料!$Q$6:$Q$205,0)),"")) | T20: =IF($O20="","",ROUND(N($R20)*N($S20),2)) | X20: =IF($W20="","",IFERROR(INDEX(科目参数!$B$6:$B$125,MATCH($W20,科目参数!$A$6:$A$125,0)),"⚠科目不存在")) | Y20: =IF($W20="","",IFERROR(INDEX(科目参数!$D$6:$D$125,MATCH($W20,科目参数!$A$6:$A$125,0)),""))
P21: =IF($O21="","",IFERROR(INDEX(基础资料!$R$6:$R$205,MATCH($O21,基础资料!$Q$6:$Q$205,0)),"")) | Q21: =IF($O21="","",IFERROR(INDEX(基础资料!$S$6:$S$205,MATCH($O21,基础资料!$Q$6:$Q$205,0)),"")) | T21: =IF($O21="","",ROUND(N($R21)*N($S21),2)) | X21: =IF($W21="","",IFERROR(INDEX(科目参数!$B$6:$B$125,MATCH($W21,科目参数!$A$6:$A$125,0)),"⚠科目不存在")) | Y21: =IF($W21="","",IFERROR(INDEX(科目参数!$D$6:$D$125,MATCH($W21,科目参数!$A$6:$A$125,0)),""))
P22: =IF($O22="","",IFERROR(INDEX(基础资料!$R$6:$R$205,MATCH($O22,基础资料!$Q$6:$Q$205,0)),"")) | Q22: =IF($O22="","",IFERROR(INDEX(基础资料!$S$6:$S$205,MATCH($O22,基础资料!$Q$6:$Q$205,0)),"")) | T22: =IF($O22="","",ROUND(N($R22)*N($S22),2)) | X22: =IF($W22="","",IFERROR(INDEX(科目参数!$B$6:$B$125,MATCH($W22,科目参数!$A$6:$A$125,0)),"⚠科目不存在")) | Y22: =IF($W22="","",IFERROR(INDEX(科目参数!$D$6:$D$125,MATCH($W22,科目参数!$A$6:$A$125,0)),""))
P23: =IF($O23="","",IFERROR(INDEX(基础资料!$R$6:$R$205,MATCH($O23,基础资料!$Q$6:$Q$205,0)),"")) | Q23: =IF($O23="","",IFERROR(INDEX(基础资料!$S$6:$S$205,MATCH($O23,基础资料!$Q$6:$Q$205,0)),"")) | T23: =IF($O23="","",ROUND(N($R23)*N($S23),2)) | X23: =IF($W23="","",IFERROR(INDEX(科目参数!$B$6:$B$125,MATCH($W23,科目参数!$A$6:$A$125,0)),"⚠科目不存在")) | Y23: =IF($W23="","",IFERROR(INDEX(科目参数!$D$6:$D$125,MATCH($W23,科目参数!$A$6:$A$125,0)),""))
P24: =IF($O24="","",IFERROR(INDEX(基础资料!$R$6:$R$205,MATCH($O24,基础资料!$Q$6:$Q$205,0)),"")) | Q24: =IF($O24="","",IFERROR(INDEX(基础资料!$S$6:$S$205,MATCH($O24,基础资料!$Q$6:$Q$205,0)),"")) | T24: =IF($O24="","",ROUND(N($R24)*N($S24),2)) | X24: =IF($W24="","",IFERROR(INDEX(科目参数!$B$6:$B$125,MATCH($W24,科目参数!$A$6:$A$125,0)),"⚠科目不存在")) | Y24: =IF($W24="","",IFERROR(INDEX(科目参数!$D$6:$D$125,MATCH($W24,科目参数!$A$6:$A$125,0)),""))
P25: =IF($O25="","",IFERROR(INDEX(基础资料!$R$6:$R$205,MATCH($O25,基础资料!$Q$6:$Q$205,0)),"")) | Q25: =IF($O25="","",IFERROR(INDEX(基础资料!$S$6:$S$205,MATCH($O25,基础资料!$Q$6:$Q$205,0)),"")) | T25: =IF($O25="","",ROUND(N($R25)*N($S25),2)) | X25: =IF($W25="","",IFERROR(INDEX(科目参数!$B$6:$B$125,MATCH($W25,科目参数!$A$6:$A$125,0)),"⚠科目不存在")) | Y25: =IF($W25="","",IFERROR(INDEX(科目参数!$D$6:$D$125,MATCH($W25,科目参数!$A$6:$A$125,0)),""))
P26: =IF($O26="","",IFERROR(INDEX(基础资料!$R$6:$R$205,MATCH($O26,基础资料!$Q$6:$Q$205,0)),"")) | Q26: =IF($O26="","",IFERROR(INDEX(基础资料!$S$6:$S$205,MATCH($O26,基础资料!$Q$6:$Q$205,0)),"")) | T26: =IF($O26="","",ROUND(N($R26)*N($S26),2)) | X26: =IF($W26="","",IFERROR(INDEX(科目参数!$B$6:$B$125,MATCH($W26,科目参数!$A$6:$A$125,0)),"⚠科目不存在")) | Y26: =IF($W26="","",IFERROR(INDEX(科目参数!$D$6:$D$125,MATCH($W26,科目参数!$A$6:$A$125,0)),""))
P27: =IF($O27="","",IFERROR(INDEX(基础资料!$R$6:$R$205,MATCH($O27,基础资料!$Q$6:$Q$205,0)),"")) | Q27: =IF($O27="","",IFERROR(INDEX(基础资料!$S$6:$S$205,MATCH($O27,基础资料!$Q$6:$Q$205,0)),"")) | T27: =IF($O27="","",ROUND(N($R27)*N($S27),2)) | X27: =IF($W27="","",IFERROR(INDEX(科目参数!$B$6:$B$125,MATCH($W27,科目参数!$A$6:$A$125,0)),"⚠科目不存在")) | Y27: =IF($W27="","",IFERROR(INDEX(科目参数!$D$6:$D$125,MATCH($W27,科目参数!$A$6:$A$125,0)),""))
P28: =IF($O28="","",IFERROR(INDEX(基础资料!$R$6:$R$205,MATCH($O28,基础资料!$Q$6:$Q$205,0)),"")) | Q28: =IF($O28="","",IFERROR(INDEX(基础资料!$S$6:$S$205,MATCH($O28,基础资料!$Q$6:$Q$205,0)),"")) | T28: =IF($O28="","",ROUND(N($R28)*N($S28),2)) | X28: =IF($W28="","",IFERROR(INDEX(科目参数!$B$6:$B$125,MATCH($W28,科目参数!$A$6:$A$125,0)),"⚠科目不存在")) | Y28: =IF($W28="","",IFERROR(INDEX(科目参数!$D$6:$D$125,MATCH($W28,科目参数!$A$6:$A$125,0)),""))
P29: =IF($O29="","",IFERROR(INDEX(基础资料!$R$6:$R$205,MATCH($O29,基础资料!$Q$6:$Q$205,0)),"")) | Q29: =IF($O29="","",IFERROR(INDEX(基础资料!$S$6:$S$205,MATCH($O29,基础资料!$Q$6:$Q$205,0)),"")) | T29: =IF($O29="","",ROUND(N($R29)*N($S29),2)) | X29: =IF($W29="","",IFERROR(INDEX(科目参数!$B$6:$B$125,MATCH($W29,科目参数!$A$6:$A$125,0)),"⚠科目不存在")) | Y29: =IF($W29="","",IFERROR(INDEX(科目参数!$D$6:$D$125,MATCH($W29,科目参数!$A$6:$A$125,0)),""))
... P125: =IF($O125="","",IFERROR(INDEX(基础资料!$R$6:$R$205,MATCH($O125,基础资料!$Q$6:$Q$205,0)),"")) | Q125: =IF($O125="","",IFERROR(INDEX(基础资料!$S$6:$S$205,MATCH($O125,基础资料!$Q$6:$Q$205,0)),"")) | T125: =IF($O125="","",ROUND(N($R125)*N($S125),2)) | X125: =IF($W125="","",IFERROR(INDEX(科目参数!$B$6:$B$125,MATCH($W125,科目参数!$A$6:$A$125,0)),"⚠科目不存在")) | Y125: =IF($W125="","",IFERROR(INDEX(科目参数!$D$6:$D$125,MATCH($W125,科目参数!$A$6:$A$125,0)),""))
P126: =IF($O126="","",IFERROR(INDEX(基础资料!$R$6:$R$205,MATCH($O126,基础资料!$Q$6:$Q$205,0)),"")) | Q126: =IF($O126="","",IFERROR(INDEX(基础资料!$S$6:$S$205,MATCH($O126,基础资料!$Q$6:$Q$205,0)),"")) | T126: =IF($O126="","",ROUND(N($R126)*N($S126),2)) | W126: 损益类科目（6xxx / 5xxx）不要填期初。
P127: =IF($O127="","",IFERROR(INDEX(基础资料!$R$6:$R$205,MATCH($O127,基础资料!$Q$6:$Q$205,0)),"")) | Q127: =IF($O127="","",IFERROR(INDEX(基础资料!$S$6:$S$205,MATCH($O127,基础资料!$Q$6:$Q$205,0)),"")) | T127: =IF($O127="","",ROUND(N($R127)*N($S127),2))
P128: =IF($O128="","",IFERROR(INDEX(基础资料!$R$6:$R$205,MATCH($O128,基础资料!$Q$6:$Q$205,0)),"")) | Q128: =IF($O128="","",IFERROR(INDEX(基础资料!$S$6:$S$205,MATCH($O128,基础资料!$Q$6:$Q$205,0)),"")) | T128: =IF($O128="","",ROUND(N($R128)*N($S128),2))
P129: =IF($O129="","",IFERROR(INDEX(基础资料!$R$6:$R$205,MATCH($O129,基础资料!$Q$6:$Q$205,0)),"")) | Q129: =IF($O129="","",IFERROR(INDEX(基础资料!$S$6:$S$205,MATCH($O129,基础资料!$Q$6:$Q$205,0)),"")) | T129: =IF($O129="","",ROUND(N($R129)*N($S129),2))
P130: =IF($O130="","",IFERROR(INDEX(基础资料!$R$6:$R$205,MATCH($O130,基础资料!$Q$6:$Q$205,0)),"")) | Q130: =IF($O130="","",IFERROR(INDEX(基础资料!$S$6:$S$205,MATCH($O130,基础资料!$Q$6:$Q$205,0)),"")) | T130: =IF($O130="","",ROUND(N($R130)*N($S130),2))
P131: =IF($O131="","",IFERROR(INDEX(基础资料!$R$6:$R$205,MATCH($O131,基础资料!$Q$6:$Q$205,0)),"")) | Q131: =IF($O131="","",IFERROR(INDEX(基础资料!$S$6:$S$205,MATCH($O131,基础资料!$Q$6:$Q$205,0)),"")) | T131: =IF($O131="","",ROUND(N($R131)*N($S131),2))
P132: =IF($O132="","",IFERROR(INDEX(基础资料!$R$6:$R$205,MATCH($O132,基础资料!$Q$6:$Q$205,0)),"")) | Q132: =IF($O132="","",IFERROR(INDEX(基础资料!$S$6:$S$205,MATCH($O132,基础资料!$Q$6:$Q$205,0)),"")) | T132: =IF($O132="","",ROUND(N($R132)*N($S132),2))
P133: =IF($O133="","",IFERROR(INDEX(基础资料!$R$6:$R$205,MATCH($O133,基础资料!$Q$6:$Q$205,0)),"")) | Q133: =IF($O133="","",IFERROR(INDEX(基础资料!$S$6:$S$205,MATCH($O133,基础资料!$Q$6:$Q$205,0)),"")) | T133: =IF($O133="","",ROUND(N($R133)*N($S133),2))
P134: =IF($O134="","",IFERROR(INDEX(基础资料!$R$6:$R$205,MATCH($O134,基础资料!$Q$6:$Q$205,0)),"")) | Q134: =IF($O134="","",IFERROR(INDEX(基础资料!$S$6:$S$205,MATCH($O134,基础资料!$Q$6:$Q$205,0)),"")) | T134: =IF($O134="","",ROUND(N($R134)*N($S134),2))
P135: =IF($O135="","",IFERROR(INDEX(基础资料!$R$6:$R$205,MATCH($O135,基础资料!$Q$6:$Q$205,0)),"")) | Q135: =IF($O135="","",IFERROR(INDEX(基础资料!$S$6:$S$205,MATCH($O135,基础资料!$Q$6:$Q$205,0)),"")) | T135: =IF($O135="","",ROUND(N($R135)*N($S135),2))
...

Sheet 资金流水
A1: 资金流水
A2: 所有实际收到、付出的钱只在这里登记一次。每一行自动生成一借一贷，借贷天然相等。
A3: 录入区 · 黄色格子手工填写 | N3: 系统自动计算区 · 请勿修改
A4: 单据编号 | B4: 日期 | C4: 月份 | D4: 收支 类型 | E4: 收支科目 | F4: 账户 | G4: 往来单位 / 转入账户 | H4: 部门 | I4: 员工 | J4: 摘要 | K4: 收入金额 | L4: 支出金额 | M4: 校验 | N4: 发生金额 | O4: 借方科目 | P4: 贷方科目 | Q4: 现金流量表项目 | R4: 该账户余额 | S4: 对方科目 | T4: 本账户 资金科目 | U4: 转入账户 资金科目 | V4: 对账 序号 | W4: 对账 序号
A5: =IF($B5="","","ZJ"&TEXT($B5,"yyyymm")&"-"&TEXT(ROW()-4,"000")) -> ZJ202601-001 | B5: 46030 | C5: =IF($B5="","",TEXT($B5,"yyyy-mm")) -> 2026-01 | D5: =IF($E5="","",IFERROR(INDEX(科目参数!$L$6:$L$85,MATCH($E5,科目参数!$M$6:$M$85,0)),"⚠")) -> 收入 | E5: 客户回款 | F5: 工商银行 | G5: 示例客户甲 | H5: 财务部 | I5: 王强 | J5: 收甲客户货款 | K5: 50000 | M5: =IF($B5="","",IF(NOT(ISNUMBER($B5)),"日期不是日期格式",IF(YEAR($B5)<>首页!$B$3,"不在会计年度",IF($E5="","未选收支科目",IF($D5="⚠","收支科目不存在",IF($F5="","未选账户",IF($T5="","账户未设资金科目",IF(AND($D5="转账",$U5=""),"转入账户无效",IF(AND(N($K5)>0,N($L5)>0),"收支不能同时填",IF(AND($D5="收入",N($K5)<=0),"收入金额须大于0",IF(AND($D5<>"收入",N($L5)<=0),"支出金额须大于0",IF($O5="","借方科目缺失",IF($P5="","贷方科目缺失","√"))))))))))))) -> √ | N5: =IF($B5="","",IF($D5="收入",N($K5),N($L5))) -> 50000 | O5: =IF($B5="","",IF($D5="收入",$T5,IF($D5="转账",$U5,$S5))) -> 1002 | P5: =IF($B5="","",IF($D5="收入",$S5,$T5)) -> 1122 | Q5: =IF($E5="","",IF($D5="转账","—",IFERROR(INDEX(科目参数!$P$6:$P$85,MATCH($E5,科目参数!$M$6:$M$85,0)),""))) -> 销售商品、提供劳务收到的现金 | R5: =IF($B5="","",SUMIFS(期初数据!$B$6:$B$35,期初数据!$A$6:$A$35,$F5)+SUMIFS($N$5:$N5,$F$5:$F5,$F5,$D$5:$D5,"收入")-SUMIFS($N$5:$N5,$F$5:$F5,$F5,$D$5:$D5,"支出")-SUMIFS($N$5:$N5,$F$5:$F5,$F5,$D$5:$D5,"转账")+SUMIFS($N$5:$N5,$G$5:$G5,$F5,$D$5:$D5,"转账")) -> 350000 | S5: =IF($E5="","",IFERROR(INDEX(科目参数!$N$6:$N$85,MATCH($E5,科目参数!$M$6:$M$85,0)),"")) -> 1122 | T5: =IF($F5="","",IFERROR(INDEX(基础资料!$C$6:$C$35,MATCH($F5,基础资料!$A$6:$A$35,0)),"")) -> 1002 | U5: =IF($G5="","",IFERROR(INDEX(基础资料!$C$6:$C$35,MATCH($G5,基础资料!$A$6:$A$35,0)),"")) | V5: =IF(AND($G5=客户对账单!$B$3,$E5="客户回款",$B5>=客户对账单!$E$3,$B5<=客户对账单!$H$3),COUNTIFS($G$5:$G5,客户对账单!$B$3,$E$5:$E5,"客户回款",$B$5:$B5,">="&客户对账单!$E$3,$B$5:$B5,"<="&客户对账单!$H$3),"") -> 1 | W5: =IF(AND($G5=供应商对账单!$B$3,$E5="供应商付款",$B5>=供应商对账单!$E$3,$B5<=供应商对账单!$H$3),COUNTIFS($G$5:$G5,供应商对账单!$B$3,$E$5:$E5,"供应商付款",$B$5:$B5,">="&供应商对账单!$E$3,$B$5:$B5,"<="&供应商对账单!$H$3),"")
A6: =IF($B6="","","ZJ"&TEXT($B6,"yyyymm")&"-"&TEXT(ROW()-4,"000")) -> ZJ202601-002 | B6: 46032 | C6: =IF($B6="","",TEXT($B6,"yyyy-mm")) -> 2026-01 | D6: =IF($E6="","",IFERROR(INDEX(科目参数!$L$6:$L$85,MATCH($E6,科目参数!$M$6:$M$85,0)),"⚠")) -> 支出 | E6: 办公费 | F6: 库存现金 | H6: 行政部 | I6: 赵敏 | J6: 买文具 | L6: 800 | M6: =IF($B6="","",IF(NOT(ISNUMBER($B6)),"日期不是日期格式",IF(YEAR($B6)<>首页!$B$3,"不在会计年度",IF($E6="","未选收支科目",IF($D6="⚠","收支科目不存在",IF($F6="","未选账户",IF($T6="","账户未设资金科目",IF(AND($D6="转账",$U6=""),"转入账户无效",IF(AND(N($K6)>0,N($L6)>0),"收支不能同时填",IF(AND($D6="收入",N($K6)<=0),"收入金额须大于0",IF(AND($D6<>"收入",N($L6)<=0),"支出金额须大于0",IF($O6="","借方科目缺失",IF($P6="","贷方科目缺失","√"))))))))))))) -> √ | N6: =IF($B6="","",IF($D6="收入",N($K6),N($L6))) -> 800 | O6: =IF($B6="","",IF($D6="收入",$T6,IF($D6="转账",$U6,$S6))) -> 6602 | P6: =IF($B6="","",IF($D6="收入",$S6,$T6)) -> 1001 | Q6: =IF($E6="","",IF($D6="转账","—",IFERROR(INDEX(科目参数!$P$6:$P$85,MATCH($E6,科目参数!$M$6:$M$85,0)),""))) -> 支付的其他与经营活动有关的现金 | R6: =IF($B6="","",SUMIFS(期初数据!$B$6:$B$35,期初数据!$A$6:$A$35,$F6)+SUMIFS($N$5:$N6,$F$5:$F6,$F6,$D$5:$D6,"收入")-SUMIFS($N$5:$N6,$F$5:$F6,$F6,$D$5:$D6,"支出")-SUMIFS($N$5:$N6,$F$5:$F6,$F6,$D$5:$D6,"转账")+SUMIFS($N$5:$N6,$G$5:$G6,$F6,$D$5:$D6,"转账")) -> 19200 | S6: =IF($E6="","",IFERROR(INDEX(科目参数!$N$6:$N$85,MATCH($E6,科目参数!$M$6:$M$85,0)),"")) -> 6602 | T6: =IF($F6="","",IFERROR(INDEX(基础资料!$C$6:$C$35,MATCH($F6,基础资料!$A$6:$A$35,0)),"")) -> 1001 | U6: =IF($G6="","",IFERROR(INDEX(基础资料!$C$6:$C$35,MATCH($G6,基础资料!$A$6:$A$35,0)),"")) | V6: =IF(AND($G6=客户对账单!$B$3,$E6="客户回款",$B6>=客户对账单!$E$3,$B6<=客户对账单!$H$3),COUNTIFS($G$5:$G6,客户对账单!$B$3,$E$5:$E6,"客户回款",$B$5:$B6,">="&客户对账单!$E$3,$B$5:$B6,"<="&客户对账单!$H$3),"") | W6: =IF(AND($G6=供应商对账单!$B$3,$E6="供应商付款",$B6>=供应商对账单!$E$3,$B6<=供应商对账单!$H$3),COUNTIFS($G$5:$G6,供应商对账单!$B$3,$E$5:$E6,"供应商付款",$B$5:$B6,">="&供应商对账单!$E$3,$B$5:$B6,"<="&供应商对账单!$H$3),"")
A7: =IF($B7="","","ZJ"&TEXT($B7,"yyyymm")&"-"&TEXT(ROW()-4,"000")) -> ZJ202601-003 | B7: 46037 | C7: =IF($B7="","",TEXT($B7,"yyyy-mm")) -> 2026-01 | D7: =IF($E7="","",IFERROR(INDEX(科目参数!$L$6:$L$85,MATCH($E7,科目参数!$M$6:$M$85,0)),"⚠")) -> 支出 | E7: 供应商付款 | F7: 工商银行 | G7: 示例供应商甲 | H7: 财务部 | I7: 王强 | J7: 付甲供应商 | L7: 40000 | M7: =IF($B7="","",IF(NOT(ISNUMBER($B7)),"日期不是日期格式",IF(YEAR($B7)<>首页!$B$3,"不在会计年度",IF($E7="","未选收支科目",IF($D7="⚠","收支科目不存在",IF($F7="","未选账户",IF($T7="","账户未设资金科目",IF(AND($D7="转账",$U7=""),"转入账户无效",IF(AND(N($K7)>0,N($L7)>0),"收支不能同时填",IF(AND($D7="收入",N($K7)<=0),"收入金额须大于0",IF(AND($D7<>"收入",N($L7)<=0),"支出金额须大于0",IF($O7="","借方科目缺失",IF($P7="","贷方科目缺失","√"))))))))))))) -> √ | N7: =IF($B7="","",IF($D7="收入",N($K7),N($L7))) -> 40000 | O7: =IF($B7="","",IF($D7="收入",$T7,IF($D7="转账",$U7,$S7))) -> 2202 | P7: =IF($B7="","",IF($D7="收入",$S7,$T7)) -> 1002 | Q7: =IF($E7="","",IF($D7="转账","—",IFERROR(INDEX(科目参数!$P$6:$P$85,MATCH($E7,科目参数!$M$6:$M$85,0)),""))) -> 购买商品、接受劳务支付的现金 | R7: =IF($B7="","",SUMIFS(期初数据!$B$6:$B$35,期初数据!$A$6:$A$35,$F7)+SUMIFS($N$5:$N7,$F$5:$F7,$F7,$D$5:$D7,"收入")-SUMIFS($N$5:$N7,$F$5:$F7,$F7,$D$5:$D7,"支出")-SUMIFS($N$5:$N7,$F$5:$F7,$F7,$D$5:$D7,"转账")+SUMIFS($N$5:$N7,$G$5:$G7,$F7,$D$5:$D7,"转账")) -> 310000 | S7: =IF($E7="","",IFERROR(INDEX(科目参数!$N$6:$N$85,MATCH($E7,科目参数!$M$6:$M$85,0)),"")) -> 2202 | T7: =IF($F7="","",IFERROR(INDEX(基础资料!$C$6:$C$35,MATCH($F7,基础资料!$A$6:$A$35,0)),"")) -> 1002 | U7: =IF($G7="","",IFERROR(INDEX(基础资料!$C$6:$C$35,MATCH($G7,基础资料!$A$6:$A$35,0)),"")) | V7: =IF(AND($G7=客户对账单!$B$3,$E7="客户回款",$B7>=客户对账单!$E$3,$B7<=客户对账单!$H$3),COUNTIFS($G$5:$G7,客户对账单!$B$3,$E$5:$E7,"客户回款",$B$5:$B7,">="&客户对账单!$E$3,$B$5:$B7,"<="&客户对账单!$H$3),"") | W7: =IF(AND($G7=供应商对账单!$B$3,$E7="供应商付款",$B7>=供应商对账单!$E$3,$B7<=供应商对账单!$H$3),COUNTIFS($G$5:$G7,供应商对账单!$B$3,$E$5:$E7,"供应商付款",$B$5:$B7,">="&供应商对账单!$E$3,$B$5:$B7,"<="&供应商对账单!$H$3),"") -> 1
A8: =IF($B8="","","ZJ"&TEXT($B8,"yyyymm")&"-"&TEXT(ROW()-4,"000")) -> ZJ202601-004 | B8: 46042 | C8: =IF($B8="","",TEXT($B8,"yyyy-mm")) -> 2026-01 | D8: =IF($E8="","",IFERROR(INDEX(科目参数!$L$6:$L$85,MATCH($E8,科目参数!$M$6:$M$85,0)),"⚠")) -> 支出 | E8: 房租物业 | F8: 工商银行 | H8: 行政部 | I8: 赵敏 | J8: 1月房租 | L8: 8000 | M8: =IF($B8="","",IF(NOT(ISNUMBER($B8)),"日期不是日期格式",IF(YEAR($B8)<>首页!$B$3,"不在会计年度",IF($E8="","未选收支科目",IF($D8="⚠","收支科目不存在",IF($F8="","未选账户",IF($T8="","账户未设资金科目",IF(AND($D8="转账",$U8=""),"转入账户无效",IF(AND(N($K8)>0,N($L8)>0),"收支不能同时填",IF(AND($D8="收入",N($K8)<=0),"收入金额须大于0",IF(AND($D8<>"收入",N($L8)<=0),"支出金额须大于0",IF($O8="","借方科目缺失",IF($P8="","贷方科目缺失","√"))))))))))))) -> √ | N8: =IF($B8="","",IF($D8="收入",N($K8),N($L8))) -> 8000 | O8: =IF($B8="","",IF($D8="收入",$T8,IF($D8="转账",$U8,$S8))) -> 6602 | P8: =IF($B8="","",IF($D8="收入",$S8,$T8)) -> 1002 | Q8: =IF($E8="","",IF($D8="转账","—",IFERROR(INDEX(科目参数!$P$6:$P$85,MATCH($E8,科目参数!$M$6:$M$85,0)),""))) -> 支付的其他与经营活动有关的现金 | R8: =IF($B8="","",SUMIFS(期初数据!$B$6:$B$35,期初数据!$A$6:$A$35,$F8)+SUMIFS($N$5:$N8,$F$5:$F8,$F8,$D$5:$D8,"收入")-SUMIFS($N$5:$N8,$F$5:$F8,$F8,$D$5:$D8,"支出")-SUMIFS($N$5:$N8,$F$5:$F8,$F8,$D$5:$D8,"转账")+SUMIFS($N$5:$N8,$G$5:$G8,$F8,$D$5:$D8,"转账")) -> 302000 | S8: =IF($E8="","",IFERROR(INDEX(科目参数!$N$6:$N$85,MATCH($E8,科目参数!$M$6:$M$85,0)),"")) -> 6602 | T8: =IF($F8="","",IFERROR(INDEX(基础资料!$C$6:$C$35,MATCH($F8,基础资料!$A$6:$A$35,0)),"")) -> 1002 | U8: =IF($G8="","",IFERROR(INDEX(基础资料!$C$6:$C$35,MATCH($G8,基础资料!$A$6:$A$35,0)),"")) | V8: =IF(AND($G8=客户对账单!$B$3,$E8="客户回款",$B8>=客户对账单!$E$3,$B8<=客户对账单!$H$3),COUNTIFS($G$5:$G8,客户对账单!$B$3,$E$5:$E8,"客户回款",$B$5:$B8,">="&客户对账单!$E$3,$B$5:$B8,"<="&客户对账单!$H$3),"") | W8: =IF(AND($G8=供应商对账单!$B$3,$E8="供应商付款",$B8>=供应商对账单!$E$3,$B8<=供应商对账单!$H$3),COUNTIFS($G$5:$G8,供应商对账单!$B$3,$E$5:$E8,"供应商付款",$B$5:$B8,">="&供应商对账单!$E$3,$B$5:$B8,"<="&供应商对账单!$H$3),"")
A9: =IF($B9="","","ZJ"&TEXT($B9,"yyyymm")&"-"&TEXT(ROW()-4,"000")) -> ZJ202601-005 | B9: 46047 | C9: =IF($B9="","",TEXT($B9,"yyyy-mm")) -> 2026-01 | D9: =IF($E9="","",IFERROR(INDEX(科目参数!$L$6:$L$85,MATCH($E9,科目参数!$M$6:$M$85,0)),"⚠")) -> 支出 | E9: 工资发放 | F9: 工商银行 | H9: 财务部 | I9: 王强 | J9: 发上月工资 | L9: 15000 | M9: =IF($B9="","",IF(NOT(ISNUMBER($B9)),"日期不是日期格式",IF(YEAR($B9)<>首页!$B$3,"不在会计年度",IF($E9="","未选收支科目",IF($D9="⚠","收支科目不存在",IF($F9="","未选账户",IF($T9="","账户未设资金科目",IF(AND($D9="转账",$U9=""),"转入账户无效",IF(AND(N($K9)>0,N($L9)>0),"收支不能同时填",IF(AND($D9="收入",N($K9)<=0),"收入金额须大于0",IF(AND($D9<>"收入",N($L9)<=0),"支出金额须大于0",IF($O9="","借方科目缺失",IF($P9="","贷方科目缺失","√"))))))))))))) -> √ | N9: =IF($B9="","",IF($D9="收入",N($K9),N($L9))) -> 15000 | O9: =IF($B9="","",IF($D9="收入",$T9,IF($D9="转账",$U9,$S9))) -> 2211 | P9: =IF($B9="","",IF($D9="收入",$S9,$T9)) -> 1002 | Q9: =IF($E9="","",IF($D9="转账","—",IFERROR(INDEX(科目参数!$P$6:$P$85,MATCH($E9,科目参数!$M$6:$M$85,0)),""))) -> 支付给职工以及为职工支付的现金 | R9: =IF($B9="","",SUMIFS(期初数据!$B$6:$B$35,期初数据!$A$6:$A$35,$F9)+SUMIFS($N$5:$N9,$F$5:$F9,$F9,$D$5:$D9,"收入")-SUMIFS($N$5:$N9,$F$5:$F9,$F9,$D$5:$D9,"支出")-SUMIFS($N$5:$N9,$F$5:$F9,$F9,$D$5:$D9,"转账")+SUMIFS($N$5:$N9,$G$5:$G9,$F9,$D$5:$D9,"转账")) -> 287000 | S9: =IF($E9="","",IFERROR(INDEX(科目参数!$N$6:$N$85,MATCH($E9,科目参数!$M$6:$M$85,0)),"")) -> 2211 | T9: =IF($F9="","",IFERROR(INDEX(基础资料!$C$6:$C$35,MATCH($F9,基础资料!$A$6:$A$35,0)),"")) -> 1002 | U9: =IF($G9="","",IFERROR(INDEX(基础资料!$C$6:$C$35,MATCH($G9,基础资料!$A$6:$A$35,0)),"")) | V9: =IF(AND($G9=客户对账单!$B$3,$E9="客户回款",$B9>=客户对账单!$E$3,$B9<=客户对账单!$H$3),COUNTIFS($G$5:$G9,客户对账单!$B$3,$E$5:$E9,"客户回款",$B$5:$B9,">="&客户对账单!$E$3,$B$5:$B9,"<="&客户对账单!$H$3),"") | W9: =IF(AND($G9=供应商对账单!$B$3,$E9="供应商付款",$B9>=供应商对账单!$E$3,$B9<=供应商对账单!$H$3),COUNTIFS($G$5:$G9,供应商对账单!$B$3,$E$5:$E9,"供应商付款",$B$5:$B9,">="&供应商对账单!$E$3,$B$5:$B9,"<="&供应商对账单!$H$3),"")
A10: =IF($B10="","","ZJ"&TEXT($B10,"yyyymm")&"-"&TEXT(ROW()-4,"000")) -> ZJ202601-006 | B10: 46050 | C10: =IF($B10="","",TEXT($B10,"yyyy-mm")) -> 2026-01 | D10: =IF($E10="","",IFERROR(INDEX(科目参数!$L$6:$L$85,MATCH($E10,科目参数!$M$6:$M$85,0)),"⚠")) -> 收入 | E10: 客户回款 | F10: 支付宝 | G10: 示例客户乙 | H10: 财务部 | I10: 王强 | J10: 收乙客户货款 | K10: 11000 | M10: =IF($B10="","",IF(NOT(ISNUMBER($B10)),"日期不是日期格式",IF(YEAR($B10)<>首页!$B$3,"不在会计年度",IF($E10="","未选收支科目",IF($D10="⚠","收支科目不存在",IF($F10="","未选账户",IF($T10="","账户未设资金科目",IF(AND($D10="转账",$U10=""),"转入账户无效",IF(AND(N($K10)>0,N($L10)>0),"收支不能同时填",IF(AND($D10="收入",N($K10)<=0),"收入金额须大于0",IF(AND($D10<>"收入",N($L10)<=0),"支出金额须大于0",IF($O10="","借方科目缺失",IF($P10="","贷方科目缺失","√"))))))))))))) -> √ | N10: =IF($B10="","",IF($D10="收入",N($K10),N($L10))) -> 11000 | O10: =IF($B10="","",IF($D10="收入",$T10,IF($D10="转账",$U10,$S10))) -> 1012 | P10: =IF($B10="","",IF($D10="收入",$S10,$T10)) -> 1122 | Q10: =IF($E10="","",IF($D10="转账","—",IFERROR(INDEX(科目参数!$P$6:$P$85,MATCH($E10,科目参数!$M$6:$M$85,0)),""))) -> 销售商品、提供劳务收到的现金 | R10: =IF($B10="","",SUMIFS(期初数据!$B$6:$B$35,期初数据!$A$6:$A$35,$F10)+SUMIFS($N$5:$N10,$F$5:$F10,$F10,$D$5:$D10,"收入")-SUMIFS($N$5:$N10,$F$5:$F10,$F10,$D$5:$D10,"支出")-SUMIFS($N$5:$N10,$F$5:$F10,$F10,$D$5:$D10,"转账")+SUMIFS($N$5:$N10,$G$5:$G10,$F10,$D$5:$D10,"转账")) -> 26000 | S10: =IF($E10="","",IFERROR(INDEX(科目参数!$N$6:$N$85,MATCH($E10,科目参数!$M$6:$M$85,0)),"")) -> 1122 | T10: =IF($F10="","",IFERROR(INDEX(基础资料!$C$6:$C$35,MATCH($F10,基础资料!$A$6:$A$35,0)),"")) -> 1012 | U10: =IF($G10="","",IFERROR(INDEX(基础资料!$C$6:$C$35,MATCH($G10,基础资料!$A$6:$A$35,0)),"")) | V10: =IF(AND($G10=客户对账单!$B$3,$E10="客户回款",$B10>=客户对账单!$E$3,$B10<=客户对账单!$H$3),COUNTIFS($G$5:$G10,客户对账单!$B$3,$E$5:$E10,"客户回款",$B$5:$B10,">="&客户对账单!$E$3,$B$5:$B10,"<="&客户对账单!$H$3),"") | W10: =IF(AND($G10=供应商对账单!$B$3,$E10="供应商付款",$B10>=供应商对账单!$E$3,$B10<=供应商对账单!$H$3),COUNTIFS($G$5:$G10,供应商对账单!$B$3,$E$5:$E10,"供应商付款",$B$5:$B10,">="&供应商对账单!$E$3,$B$5:$B10,"<="&供应商对账单!$H$3),"")
A11: =IF($B11="","","ZJ"&TEXT($B11,"yyyymm")&"-"&TEXT(ROW()-4,"000")) -> ZJ202601-007 | B11: 46052 | C11: =IF($B11="","",TEXT($B11,"yyyy-mm")) -> 2026-01 | D11: =IF($E11="","",IFERROR(INDEX(科目参数!$L$6:$L$85,MATCH($E11,科目参数!$M$6:$M$85,0)),"⚠")) -> 转账 | E11: 账户转账 | F11: 工商银行 | G11: 库存现金 | H11: 财务部 | I11: 王强 | J11: 提现备用 | L11: 5000 | M11: =IF($B11="","",IF(NOT(ISNUMBER($B11)),"日期不是日期格式",IF(YEAR($B11)<>首页!$B$3,"不在会计年度",IF($E11="","未选收支科目",IF($D11="⚠","收支科目不存在",IF($F11="","未选账户",IF($T11="","账户未设资金科目",IF(AND($D11="转账",$U11=""),"转入账户无效",IF(AND(N($K11)>0,N($L11)>0),"收支不能同时填",IF(AND($D11="收入",N($K11)<=0),"收入金额须大于0",IF(AND($D11<>"收入",N($L11)<=0),"支出金额须大于0",IF($O11="","借方科目缺失",IF($P11="","贷方科目缺失","√"))))))))))))) -> √ | N11: =IF($B11="","",IF($D11="收入",N($K11),N($L11))) -> 5000 | O11: =IF($B11="","",IF($D11="收入",$T11,IF($D11="转账",$U11,$S11))) -> 1001 | P11: =IF($B11="","",IF($D11="收入",$S11,$T11)) -> 1002 | Q11: =IF($E11="","",IF($D11="转账","—",IFERROR(INDEX(科目参数!$P$6:$P$85,MATCH($E11,科目参数!$M$6:$M$85,0)),""))) -> — | R11: =IF($B11="","",SUMIFS(期初数据!$B$6:$B$35,期初数据!$A$6:$A$35,$F11)+SUMIFS($N$5:$N11,$F$5:$F11,$F11,$D$5:$D11,"收入")-SUMIFS($N$5:$N11,$F$5:$F11,$F11,$D$5:$D11,"支出")-SUMIFS($N$5:$N11,$F$5:$F11,$F11,$D$5:$D11,"转账")+SUMIFS($N$5:$N11,$G$5:$G11,$F11,$D$5:$D11,"转账")) -> 282000 | S11: =IF($E11="","",IFERROR(INDEX(科目参数!$N$6:$N$85,MATCH($E11,科目参数!$M$6:$M$85,0)),"")) -> 0 | T11: =IF($F11="","",IFERROR(INDEX(基础资料!$C$6:$C$35,MATCH($F11,基础资料!$A$6:$A$35,0)),"")) -> 1002 | U11: =IF($G11="","",IFERROR(INDEX(基础资料!$C$6:$C$35,MATCH($G11,基础资料!$A$6:$A$35,0)),"")) -> 1001 | V11: =IF(AND($G11=客户对账单!$B$3,$E11="客户回款",$B11>=客户对账单!$E$3,$B11<=客户对账单!$H$3),COUNTIFS($G$5:$G11,客户对账单!$B$3,$E$5:$E11,"客户回款",$B$5:$B11,">="&客户对账单!$E$3,$B$5:$B11,"<="&客户对账单!$H$3),"") | W11: =IF(AND($G11=供应商对账单!$B$3,$E11="供应商付款",$B11>=供应商对账单!$E$3,$B11<=供应商对账单!$H$3),COUNTIFS($G$5:$G11,供应商对账单!$B$3,$E$5:$E11,"供应商付款",$B$5:$B11,">="&供应商对账单!$E$3,$B$5:$B11,"<="&供应商对账单!$H$3),"")
A12: =IF($B12="","","ZJ"&TEXT($B12,"yyyymm")&"-"&TEXT(ROW()-4,"000")) | C12: =IF($B12="","",TEXT($B12,"yyyy-mm")) | D12: =IF($E12="","",IFERROR(INDEX(科目参数!$L$6:$L$85,MATCH($E12,科目参数!$M$6:$M$85,0)),"⚠")) | M12: =IF($B12="","",IF(NOT(ISNUMBER($B12)),"日期不是日期格式",IF(YEAR($B12)<>首页!$B$3,"不在会计年度",IF($E12="","未选收支科目",IF($D12="⚠","收支科目不存在",IF($F12="","未选账户",IF($T12="","账户未设资金科目",IF(AND($D12="转账",$U12=""),"转入账户无效",IF(AND(N($K12)>0,N($L12)>0),"收支不能同时填",IF(AND($D12="收入",N($K12)<=0),"收入金额须大于0",IF(AND($D12<>"收入",N($L12)<=0),"支出金额须大于0",IF($O12="","借方科目缺失",IF($P12="","贷方科目缺失","√"))))))))))))) | N12: =IF($B12="","",IF($D12="收入",N($K12),N($L12))) | O12: =IF($B12="","",IF($D12="收入",$T12,IF($D12="转账",$U12,$S12))) | P12: =IF($B12="","",IF($D12="收入",$S12,$T12)) | Q12: =IF($E12="","",IF($D12="转账","—",IFERROR(INDEX(科目参数!$P$6:$P$85,MATCH($E12,科目参数!$M$6:$M$85,0)),""))) | R12: =IF($B12="","",SUMIFS(期初数据!$B$6:$B$35,期初数据!$A$6:$A$35,$F12)+SUMIFS($N$5:$N12,$F$5:$F12,$F12,$D$5:$D12,"收入")-SUMIFS($N$5:$N12,$F$5:$F12,$F12,$D$5:$D12,"支出")-SUMIFS($N$5:$N12,$F$5:$F12,$F12,$D$5:$D12,"转账")+SUMIFS($N$5:$N12,$G$5:$G12,$F12,$D$5:$D12,"转账")) | S12: =IF($E12="","",IFERROR(INDEX(科目参数!$N$6:$N$85,MATCH($E12,科目参数!$M$6:$M$85,0)),"")) | T12: =IF($F12="","",IFERROR(INDEX(基础资料!$C$6:$C$35,MATCH($F12,基础资料!$A$6:$A$35,0)),"")) | U12: =IF($G12="","",IFERROR(INDEX(基础资料!$C$6:$C$35,MATCH($G12,基础资料!$A$6:$A$35,0)),"")) | V12: =IF(AND($G12=客户对账单!$B$3,$E12="客户回款",$B12>=客户对账单!$E$3,$B12<=客户对账单!$H$3),COUNTIFS($G$5:$G12,客户对账单!$B$3,$E$5:$E12,"客户回款",$B$5:$B12,">="&客户对账单!$E$3,$B$5:$B12,"<="&客户对账单!$H$3),"") | W12: =IF(AND($G12=供应商对账单!$B$3,$E12="供应商付款",$B12>=供应商对账单!$E$3,$B12<=供应商对账单!$H$3),COUNTIFS($G$5:$G12,供应商对账单!$B$3,$E$5:$E12,"供应商付款",$B$5:$B12,">="&供应商对账单!$E$3,$B$5:$B12,"<="&供应商对账单!$H$3),"")
A13: =IF($B13="","","ZJ"&TEXT($B13,"yyyymm")&"-"&TEXT(ROW()-4,"000")) | C13: =IF($B13="","",TEXT($B13,"yyyy-mm")) | D13: =IF($E13="","",IFERROR(INDEX(科目参数!$L$6:$L$85,MATCH($E13,科目参数!$M$6:$M$85,0)),"⚠")) | M13: =IF($B13="","",IF(NOT(ISNUMBER($B13)),"日期不是日期格式",IF(YEAR($B13)<>首页!$B$3,"不在会计年度",IF($E13="","未选收支科目",IF($D13="⚠","收支科目不存在",IF($F13="","未选账户",IF($T13="","账户未设资金科目",IF(AND($D13="转账",$U13=""),"转入账户无效",IF(AND(N($K13)>0,N($L13)>0),"收支不能同时填",IF(AND($D13="收入",N($K13)<=0),"收入金额须大于0",IF(AND($D13<>"收入",N($L13)<=0),"支出金额须大于0",IF($O13="","借方科目缺失",IF($P13="","贷方科目缺失","√"))))))))))))) | N13: =IF($B13="","",IF($D13="收入",N($K13),N($L13))) | O13: =IF($B13="","",IF($D13="收入",$T13,IF($D13="转账",$U13,$S13))) | P13: =IF($B13="","",IF($D13="收入",$S13,$T13)) | Q13: =IF($E13="","",IF($D13="转账","—",IFERROR(INDEX(科目参数!$P$6:$P$85,MATCH($E13,科目参数!$M$6:$M$85,0)),""))) | R13: =IF($B13="","",SUMIFS(期初数据!$B$6:$B$35,期初数据!$A$6:$A$35,$F13)+SUMIFS($N$5:$N13,$F$5:$F13,$F13,$D$5:$D13,"收入")-SUMIFS($N$5:$N13,$F$5:$F13,$F13,$D$5:$D13,"支出")-SUMIFS($N$5:$N13,$F$5:$F13,$F13,$D$5:$D13,"转账")+SUMIFS($N$5:$N13,$G$5:$G13,$F13,$D$5:$D13,"转账")) | S13: =IF($E13="","",IFERROR(INDEX(科目参数!$N$6:$N$85,MATCH($E13,科目参数!$M$6:$M$85,0)),"")) | T13: =IF($F13="","",IFERROR(INDEX(基础资料!$C$6:$C$35,MATCH($F13,基础资料!$A$6:$A$35,0)),"")) | U13: =IF($G13="","",IFERROR(INDEX(基础资料!$C$6:$C$35,MATCH($G13,基础资料!$A$6:$A$35,0)),"")) | V13: =IF(AND($G13=客户对账单!$B$3,$E13="客户回款",$B13>=客户对账单!$E$3,$B13<=客户对账单!$H$3),COUNTIFS($G$5:$G13,客户对账单!$B$3,$E$5:$E13,"客户回款",$B$5:$B13,">="&客户对账单!$E$3,$B$5:$B13,"<="&客户对账单!$H$3),"") | W13: =IF(AND($G13=供应商对账单!$B$3,$E13="供应商付款",$B13>=供应商对账单!$E$3,$B13<=供应商对账单!$H$3),COUNTIFS($G$5:$G13,供应商对账单!$B$3,$E$5:$E13,"供应商付款",$B$5:$B13,">="&供应商对账单!$E$3,$B$5:$B13,"<="&供应商对账单!$H$3),"")
A14: =IF($B14="","","ZJ"&TEXT($B14,"yyyymm")&"-"&TEXT(ROW()-4,"000")) | C14: =IF($B14="","",TEXT($B14,"yyyy-mm")) | D14: =IF($E14="","",IFERROR(INDEX(科目参数!$L$6:$L$85,MATCH($E14,科目参数!$M$6:$M$85,0)),"⚠")) | M14: =IF($B14="","",IF(NOT(ISNUMBER($B14)),"日期不是日期格式",IF(YEAR($B14)<>首页!$B$3,"不在会计年度",IF($E14="","未选收支科目",IF($D14="⚠","收支科目不存在",IF($F14="","未选账户",IF($T14="","账户未设资金科目",IF(AND($D14="转账",$U14=""),"转入账户无效",IF(AND(N($K14)>0,N($L14)>0),"收支不能同时填",IF(AND($D14="收入",N($K14)<=0),"收入金额须大于0",IF(AND($D14<>"收入",N($L14)<=0),"支出金额须大于0",IF($O14="","借方科目缺失",IF($P14="","贷方科目缺失","√"))))))))))))) | N14: =IF($B14="","",IF($D14="收入",N($K14),N($L14))) | O14: =IF($B14="","",IF($D14="收入",$T14,IF($D14="转账",$U14,$S14))) | P14: =IF($B14="","",IF($D14="收入",$S14,$T14)) | Q14: =IF($E14="","",IF($D14="转账","—",IFERROR(INDEX(科目参数!$P$6:$P$85,MATCH($E14,科目参数!$M$6:$M$85,0)),""))) | R14: =IF($B14="","",SUMIFS(期初数据!$B$6:$B$35,期初数据!$A$6:$A$35,$F14)+SUMIFS($N$5:$N14,$F$5:$F14,$F14,$D$5:$D14,"收入")-SUMIFS($N$5:$N14,$F$5:$F14,$F14,$D$5:$D14,"支出")-SUMIFS($N$5:$N14,$F$5:$F14,$F14,$D$5:$D14,"转账")+SUMIFS($N$5:$N14,$G$5:$G14,$F14,$D$5:$D14,"转账")) | S14: =IF($E14="","",IFERROR(INDEX(科目参数!$N$6:$N$85,MATCH($E14,科目参数!$M$6:$M$85,0)),"")) | T14: =IF($F14="","",IFERROR(INDEX(基础资料!$C$6:$C$35,MATCH($F14,基础资料!$A$6:$A$35,0)),"")) | U14: =IF($G14="","",IFERROR(INDEX(基础资料!$C$6:$C$35,MATCH($G14,基础资料!$A$6:$A$35,0)),"")) | V14: =IF(AND($G14=客户对账单!$B$3,$E14="客户回款",$B14>=客户对账单!$E$3,$B14<=客户对账单!$H$3),COUNTIFS($G$5:$G14,客户对账单!$B$3,$E$5:$E14,"客户回款",$B$5:$B14,">="&客户对账单!$E$3,$B$5:$B14,"<="&客户对账单!$H$3),"") | W14: =IF(AND($G14=供应商对账单!$B$3,$E14="供应商付款",$B14>=供应商对账单!$E$3,$B14<=供应商对账单!$H$3),COUNTIFS($G$5:$G14,供应商对账单!$B$3,$E$5:$E14,"供应商付款",$B$5:$B14,">="&供应商对账单!$E$3,$B$5:$B14,"<="&供应商对账单!$H$3),"")
A15: =IF($B15="","","ZJ"&TEXT($B15,"yyyymm")&"-"&TEXT(ROW()-4,"000")) | C15: =IF($B15="","",TEXT($B15,"yyyy-mm")) | D15: =IF($E15="","",IFERROR(INDEX(科目参数!$L$6:$L$85,MATCH($E15,科目参数!$M$6:$M$85,0)),"⚠")) | M15: =IF($B15="","",IF(NOT(ISNUMBER($B15)),"日期不是日期格式",IF(YEAR($B15)<>首页!$B$3,"不在会计年度",IF($E15="","未选收支科目",IF($D15="⚠","收支科目不存在",IF($F15="","未选账户",IF($T15="","账户未设资金科目",IF(AND($D15="转账",$U15=""),"转入账户无效",IF(AND(N($K15)>0,N($L15)>0),"收支不能同时填",IF(AND($D15="收入",N($K15)<=0),"收入金额须大于0",IF(AND($D15<>"收入",N($L15)<=0),"支出金额须大于0",IF($O15="","借方科目缺失",IF($P15="","贷方科目缺失","√"))))))))))))) | N15: =IF($B15="","",IF($D15="收入",N($K15),N($L15))) | O15: =IF($B15="","",IF($D15="收入",$T15,IF($D15="转账",$U15,$S15))) | P15: =IF($B15="","",IF($D15="收入",$S15,$T15)) | Q15: =IF($E15="","",IF($D15="转账","—",IFERROR(INDEX(科目参数!$P$6:$P$85,MATCH($E15,科目参数!$M$6:$M$85,0)),""))) | R15: =IF($B15="","",SUMIFS(期初数据!$B$6:$B$35,期初数据!$A$6:$A$35,$F15)+SUMIFS($N$5:$N15,$F$5:$F15,$F15,$D$5:$D15,"收入")-SUMIFS($N$5:$N15,$F$5:$F15,$F15,$D$5:$D15,"支出")-SUMIFS($N$5:$N15,$F$5:$F15,$F15,$D$5:$D15,"转账")+SUMIFS($N$5:$N15,$G$5:$G15,$F15,$D$5:$D15,"转账")) | S15: =IF($E15="","",IFERROR(INDEX(科目参数!$N$6:$N$85,MATCH($E15,科目参数!$M$6:$M$85,0)),"")) | T15: =IF($F15="","",IFERROR(INDEX(基础资料!$C$6:$C$35,MATCH($F15,基础资料!$A$6:$A$35,0)),"")) | U15: =IF($G15="","",IFERROR(INDEX(基础资料!$C$6:$C$35,MATCH($G15,基础资料!$A$6:$A$35,0)),"")) | V15: =IF(AND($G15=客户对账单!$B$3,$E15="客户回款",$B15>=客户对账单!$E$3,$B15<=客户对账单!$H$3),COUNTIFS($G$5:$G15,客户对账单!$B$3,$E$5:$E15,"客户回款",$B$5:$B15,">="&客户对账单!$E$3,$B$5:$B15,"<="&客户对账单!$H$3),"") | W15: =IF(AND($G15=供应商对账单!$B$3,$E15="供应商付款",$B15>=供应商对账单!$E$3,$B15<=供应商对账单!$H$3),COUNTIFS($G$5:$G15,供应商对账单!$B$3,$E$5:$E15,"供应商付款",$B$5:$B15,">="&供应商对账单!$E$3,$B$5:$B15,"<="&供应商对账单!$H$3),"")
A16: =IF($B16="","","ZJ"&TEXT($B16,"yyyymm")&"-"&TEXT(ROW()-4,"000")) | C16: =IF($B16="","",TEXT($B16,"yyyy-mm")) | D16: =IF($E16="","",IFERROR(INDEX(科目参数!$L$6:$L$85,MATCH($E16,科目参数!$M$6:$M$85,0)),"⚠")) | M16: =IF($B16="","",IF(NOT(ISNUMBER($B16)),"日期不是日期格式",IF(YEAR($B16)<>首页!$B$3,"不在会计年度",IF($E16="","未选收支科目",IF($D16="⚠","收支科目不存在",IF($F16="","未选账户",IF($T16="","账户未设资金科目",IF(AND($D16="转账",$U16=""),"转入账户无效",IF(AND(N($K16)>0,N($L16)>0),"收支不能同时填",IF(AND($D16="收入",N($K16)<=0),"收入金额须大于0",IF(AND($D16<>"收入",N($L16)<=0),"支出金额须大于0",IF($O16="","借方科目缺失",IF($P16="","贷方科目缺失","√"))))))))))))) | N16: =IF($B16="","",IF($D16="收入",N($K16),N($L16))) | O16: =IF($B16="","",IF($D16="收入",$T16,IF($D16="转账",$U16,$S16))) | P16: =IF($B16="","",IF($D16="收入",$S16,$T16)) | Q16: =IF($E16="","",IF($D16="转账","—",IFERROR(INDEX(科目参数!$P$6:$P$85,MATCH($E16,科目参数!$M$6:$M$85,0)),""))) | R16: =IF($B16="","",SUMIFS(期初数据!$B$6:$B$35,期初数据!$A$6:$A$35,$F16)+SUMIFS($N$5:$N16,$F$5:$F16,$F16,$D$5:$D16,"收入")-SUMIFS($N$5:$N16,$F$5:$F16,$F16,$D$5:$D16,"支出")-SUMIFS($N$5:$N16,$F$5:$F16,$F16,$D$5:$D16,"转账")+SUMIFS($N$5:$N16,$G$5:$G16,$F16,$D$5:$D16,"转账")) | S16: =IF($E16="","",IFERROR(INDEX(科目参数!$N$6:$N$85,MATCH($E16,科目参数!$M$6:$M$85,0)),"")) | T16: =IF($F16="","",IFERROR(INDEX(基础资料!$C$6:$C$35,MATCH($F16,基础资料!$A$6:$A$35,0)),"")) | U16: =IF($G16="","",IFERROR(INDEX(基础资料!$C$6:$C$35,MATCH($G16,基础资料!$A$6:$A$35,0)),"")) | V16: =IF(AND($G16=客户对账单!$B$3,$E16="客户回款",$B16>=客户对账单!$E$3,$B16<=客户对账单!$H$3),COUNTIFS($G$5:$G16,客户对账单!$B$3,$E$5:$E16,"客户回款",$B$5:$B16,">="&客户对账单!$E$3,$B$5:$B16,"<="&客户对账单!$H$3),"") | W16: =IF(AND($G16=供应商对账单!$B$3,$E16="供应商付款",$B16>=供应商对账单!$E$3,$B16<=供应商对账单!$H$3),COUNTIFS($G$5:$G16,供应商对账单!$B$3,$E$5:$E16,"供应商付款",$B$5:$B16,">="&供应商对账单!$E$3,$B$5:$B16,"<="&供应商对账单!$H$3),"")
A17: =IF($B17="","","ZJ"&TEXT($B17,"yyyymm")&"-"&TEXT(ROW()-4,"000")) | C17: =IF($B17="","",TEXT($B17,"yyyy-mm")) | D17: =IF($E17="","",IFERROR(INDEX(科目参数!$L$6:$L$85,MATCH($E17,科目参数!$M$6:$M$85,0)),"⚠")) | M17: =IF($B17="","",IF(NOT(ISNUMBER($B17)),"日期不是日期格式",IF(YEAR($B17)<>首页!$B$3,"不在会计年度",IF($E17="","未选收支科目",IF($D17="⚠","收支科目不存在",IF($F17="","未选账户",IF($T17="","账户未设资金科目",IF(AND($D17="转账",$U17=""),"转入账户无效",IF(AND(N($K17)>0,N($L17)>0),"收支不能同时填",IF(AND($D17="收入",N($K17)<=0),"收入金额须大于0",IF(AND($D17<>"收入",N($L17)<=0),"支出金额须大于0",IF($O17="","借方科目缺失",IF($P17="","贷方科目缺失","√"))))))))))))) | N17: =IF($B17="","",IF($D17="收入",N($K17),N($L17))) | O17: =IF($B17="","",IF($D17="收入",$T17,IF($D17="转账",$U17,$S17))) | P17: =IF($B17="","",IF($D17="收入",$S17,$T17)) | Q17: =IF($E17="","",IF($D17="转账","—",IFERROR(INDEX(科目参数!$P$6:$P$85,MATCH($E17,科目参数!$M$6:$M$85,0)),""))) | R17: =IF($B17="","",SUMIFS(期初数据!$B$6:$B$35,期初数据!$A$6:$A$35,$F17)+SUMIFS($N$5:$N17,$F$5:$F17,$F17,$D$5:$D17,"收入")-SUMIFS($N$5:$N17,$F$5:$F17,$F17,$D$5:$D17,"支出")-SUMIFS($N$5:$N17,$F$5:$F17,$F17,$D$5:$D17,"转账")+SUMIFS($N$5:$N17,$G$5:$G17,$F17,$D$5:$D17,"转账")) | S17: =IF($E17="","",IFERROR(INDEX(科目参数!$N$6:$N$85,MATCH($E17,科目参数!$M$6:$M$85,0)),"")) | T17: =IF($F17="","",IFERROR(INDEX(基础资料!$C$6:$C$35,MATCH($F17,基础资料!$A$6:$A$35,0)),"")) | U17: =IF($G17="","",IFERROR(INDEX(基础资料!$C$6:$C$35,MATCH($G17,基础资料!$A$6:$A$35,0)),"")) | V17: =IF(AND($G17=客户对账单!$B$3,$E17="客户回款",$B17>=客户对账单!$E$3,$B17<=客户对账单!$H$3),COUNTIFS($G$5:$G17,客户对账单!$B$3,$E$5:$E17,"客户回款",$B$5:$B17,">="&客户对账单!$E$3,$B$5:$B17,"<="&客户对账单!$H$3),"") | W17: =IF(AND($G17=供应商对账单!$B$3,$E17="供应商付款",$B17>=供应商对账单!$E$3,$B17<=供应商对账单!$H$3),COUNTIFS($G$5:$G17,供应商对账单!$B$3,$E$5:$E17,"供应商付款",$B$5:$B17,">="&供应商对账单!$E$3,$B$5:$B17,"<="&供应商对账单!$H$3),"")
A18: =IF($B18="","","ZJ"&TEXT($B18,"yyyymm")&"-"&TEXT(ROW()-4,"000")) | C18: =IF($B18="","",TEXT($B18,"yyyy-mm")) | D18: =IF($E18="","",IFERROR(INDEX(科目参数!$L$6:$L$85,MATCH($E18,科目参数!$M$6:$M$85,0)),"⚠")) | M18: =IF($B18="","",IF(NOT(ISNUMBER($B18)),"日期不是日期格式",IF(YEAR($B18)<>首页!$B$3,"不在会计年度",IF($E18="","未选收支科目",IF($D18="⚠","收支科目不存在",IF($F18="","未选账户",IF($T18="","账户未设资金科目",IF(AND($D18="转账",$U18=""),"转入账户无效",IF(AND(N($K18)>0,N($L18)>0),"收支不能同时填",IF(AND($D18="收入",N($K18)<=0),"收入金额须大于0",IF(AND($D18<>"收入",N($L18)<=0),"支出金额须大于0",IF($O18="","借方科目缺失",IF($P18="","贷方科目缺失","√"))))))))))))) | N18: =IF($B18="","",IF($D18="收入",N($K18),N($L18))) | O18: =IF($B18="","",IF($D18="收入",$T18,IF($D18="转账",$U18,$S18))) | P18: =IF($B18="","",IF($D18="收入",$S18,$T18)) | Q18: =IF($E18="","",IF($D18="转账","—",IFERROR(INDEX(科目参数!$P$6:$P$85,MATCH($E18,科目参数!$M$6:$M$85,0)),""))) | R18: =IF($B18="","",SUMIFS(期初数据!$B$6:$B$35,期初数据!$A$6:$A$35,$F18)+SUMIFS($N$5:$N18,$F$5:$F18,$F18,$D$5:$D18,"收入")-SUMIFS($N$5:$N18,$F$5:$F18,$F18,$D$5:$D18,"支出")-SUMIFS($N$5:$N18,$F$5:$F18,$F18,$D$5:$D18,"转账")+SUMIFS($N$5:$N18,$G$5:$G18,$F18,$D$5:$D18,"转账")) | S18: =IF($E18="","",IFERROR(INDEX(科目参数!$N$6:$N$85,MATCH($E18,科目参数!$M$6:$M$85,0)),"")) | T18: =IF($F18="","",IFERROR(INDEX(基础资料!$C$6:$C$35,MATCH($F18,基础资料!$A$6:$A$35,0)),"")) | U18: =IF($G18="","",IFERROR(INDEX(基础资料!$C$6:$C$35,MATCH($G18,基础资料!$A$6:$A$35,0)),"")) | V18: =IF(AND($G18=客户对账单!$B$3,$E18="客户回款",$B18>=客户对账单!$E$3,$B18<=客户对账单!$H$3),COUNTIFS($G$5:$G18,客户对账单!$B$3,$E$5:$E18,"客户回款",$B$5:$B18,">="&客户对账单!$E$3,$B$5:$B18,"<="&客户对账单!$H$3),"") | W18: =IF(AND($G18=供应商对账单!$B$3,$E18="供应商付款",$B18>=供应商对账单!$E$3,$B18<=供应商对账单!$H$3),COUNTIFS($G$5:$G18,供应商对账单!$B$3,$E$5:$E18,"供应商付款",$B$5:$B18,">="&供应商对账单!$E$3,$B$5:$B18,"<="&供应商对账单!$H$3),"")
A19: =IF($B19="","","ZJ"&TEXT($B19,"yyyymm")&"-"&TEXT(ROW()-4,"000")) | C19: =IF($B19="","",TEXT($B19,"yyyy-mm")) | D19: =IF($E19="","",IFERROR(INDEX(科目参数!$L$6:$L$85,MATCH($E19,科目参数!$M$6:$M$85,0)),"⚠")) | M19: =IF($B19="","",IF(NOT(ISNUMBER($B19)),"日期不是日期格式",IF(YEAR($B19)<>首页!$B$3,"不在会计年度",IF($E19="","未选收支科目",IF($D19="⚠","收支科目不存在",IF($F19="","未选账户",IF($T19="","账户未设资金科目",IF(AND($D19="转账",$U19=""),"转入账户无效",IF(AND(N($K19)>0,N($L19)>0),"收支不能同时填",IF(AND($D19="收入",N($K19)<=0),"收入金额须大于0",IF(AND($D19<>"收入",N($L19)<=0),"支出金额须大于0",IF($O19="","借方科目缺失",IF($P19="","贷方科目缺失","√"))))))))))))) | N19: =IF($B19="","",IF($D19="收入",N($K19),N($L19))) | O19: =IF($B19="","",IF($D19="收入",$T19,IF($D19="转账",$U19,$S19))) | P19: =IF($B19="","",IF($D19="收入",$S19,$T19)) | Q19: =IF($E19="","",IF($D19="转账","—",IFERROR(INDEX(科目参数!$P$6:$P$85,MATCH($E19,科目参数!$M$6:$M$85,0)),""))) | R19: =IF($B19="","",SUMIFS(期初数据!$B$6:$B$35,期初数据!$A$6:$A$35,$F19)+SUMIFS($N$5:$N19,$F$5:$F19,$F19,$D$5:$D19,"收入")-SUMIFS($N$5:$N19,$F$5:$F19,$F19,$D$5:$D19,"支出")-SUMIFS($N$5:$N19,$F$5:$F19,$F19,$D$5:$D19,"转账")+SUMIFS($N$5:$N19,$G$5:$G19,$F19,$D$5:$D19,"转账")) | S19: =IF($E19="","",IFERROR(INDEX(科目参数!$N$6:$N$85,MATCH($E19,科目参数!$M$6:$M$85,0)),"")) | T19: =IF($F19="","",IFERROR(INDEX(基础资料!$C$6:$C$35,MATCH($F19,基础资料!$A$6:$A$35,0)),"")) | U19: =IF($G19="","",IFERROR(INDEX(基础资料!$C$6:$C$35,MATCH($G19,基础资料!$A$6:$A$35,0)),"")) | V19: =IF(AND($G19=客户对账单!$B$3,$E19="客户回款",$B19>=客户对账单!$E$3,$B19<=客户对账单!$H$3),COUNTIFS($G$5:$G19,客户对账单!$B$3,$E$5:$E19,"客户回款",$B$5:$B19,">="&客户对账单!$E$3,$B$5:$B19,"<="&客户对账单!$H$3),"") | W19: =IF(AND($G19=供应商对账单!$B$3,$E19="供应商付款",$B19>=供应商对账单!$E$3,$B19<=供应商对账单!$H$3),COUNTIFS($G$5:$G19,供应商对账单!$B$3,$E$5:$E19,"供应商付款",$B$5:$B19,">="&供应商对账单!$E$3,$B$5:$B19,"<="&供应商对账单!$H$3),"")
A20: =IF($B20="","","ZJ"&TEXT($B20,"yyyymm")&"-"&TEXT(ROW()-4,"000")) | C20: =IF($B20="","",TEXT($B20,"yyyy-mm")) | D20: =IF($E20="","",IFERROR(INDEX(科目参数!$L$6:$L$85,MATCH($E20,科目参数!$M$6:$M$85,0)),"⚠")) | M20: =IF($B20="","",IF(NOT(ISNUMBER($B20)),"日期不是日期格式",IF(YEAR($B20)<>首页!$B$3,"不在会计年度",IF($E20="","未选收支科目",IF($D20="⚠","收支科目不存在",IF($F20="","未选账户",IF($T20="","账户未设资金科目",IF(AND($D20="转账",$U20=""),"转入账户无效",IF(AND(N($K20)>0,N($L20)>0),"收支不能同时填",IF(AND($D20="收入",N($K20)<=0),"收入金额须大于0",IF(AND($D20<>"收入",N($L20)<=0),"支出金额须大于0",IF($O20="","借方科目缺失",IF($P20="","贷方科目缺失","√"))))))))))))) | N20: =IF($B20="","",IF($D20="收入",N($K20),N($L20))) | O20: =IF($B20="","",IF($D20="收入",$T20,IF($D20="转账",$U20,$S20))) | P20: =IF($B20="","",IF($D20="收入",$S20,$T20)) | Q20: =IF($E20="","",IF($D20="转账","—",IFERROR(INDEX(科目参数!$P$6:$P$85,MATCH($E20,科目参数!$M$6:$M$85,0)),""))) | R20: =IF($B20="","",SUMIFS(期初数据!$B$6:$B$35,期初数据!$A$6:$A$35,$F20)+SUMIFS($N$5:$N20,$F$5:$F20,$F20,$D$5:$D20,"收入")-SUMIFS($N$5:$N20,$F$5:$F20,$F20,$D$5:$D20,"支出")-SUMIFS($N$5:$N20,$F$5:$F20,$F20,$D$5:$D20,"转账")+SUMIFS($N$5:$N20,$G$5:$G20,$F20,$D$5:$D20,"转账")) | S20: =IF($E20="","",IFERROR(INDEX(科目参数!$N$6:$N$85,MATCH($E20,科目参数!$M$6:$M$85,0)),"")) | T20: =IF($F20="","",IFERROR(INDEX(基础资料!$C$6:$C$35,MATCH($F20,基础资料!$A$6:$A$35,0)),"")) | U20: =IF($G20="","",IFERROR(INDEX(基础资料!$C$6:$C$35,MATCH($G20,基础资料!$A$6:$A$35,0)),"")) | V20: =IF(AND($G20=客户对账单!$B$3,$E20="客户回款",$B20>=客户对账单!$E$3,$B20<=客户对账单!$H$3),COUNTIFS($G$5:$G20,客户对账单!$B$3,$E$5:$E20,"客户回款",$B$5:$B20,">="&客户对账单!$E$3,$B$5:$B20,"<="&客户对账单!$H$3),"") | W20: =IF(AND($G20=供应商对账单!$B$3,$E20="供应商付款",$B20>=供应商对账单!$E$3,$B20<=供应商对账单!$H$3),COUNTIFS($G$5:$G20,供应商对账单!$B$3,$E$5:$E20,"供应商付款",$B$5:$B20,">="&供应商对账单!$E$3,$B$5:$B20,"<="&供应商对账单!$H$3),"")
