Workbook

Sheet 首页
A1: 三公司财务账套 · 2026 年
A2: 农业基地 / 木业 / 科技，一套表三家账。录【购销流水】【资金流水】【生产加工】【其他分录】四张表，报表自己出。一年一套：把【参数设置】的会计年度改成下一年，另存一个文件就是新账。
A4: 会计年度 | B4: =参数设置!$B$5 -> 2026 | C4: 本年凭证数 | D4: =COUNTIF(记账分录!$P$6:$P$5505,"有") -> 222 | E4: =IF(校验中心!$E$42=0,"√ 全部校验通过，可以出报表","✗ 校验中心还有 "&校验中心!$E$42&" 项没过，先去【校验中心】看红色那几行") -> √ 全部校验通过，可以出报表
A6: 一、三家公司关键数（口径＝各报表页当前选的期间，默认整年）
A7: 指 标 | B7: 农业基地公司 | C7: 木业公司 | D7: 科技公司 | E7: 三家合计 | G7: 账户余额 | H7: =资金账户!$K$27 -> 1274240
A8: 营业收入 | B8: ='农业-利润表'!$C$6 -> 329000 | C8: ='木业-利润表'!$C$6 -> 582000 | D8: ='科技-利润表'!$C$6 -> 444750 | E8: =SUM(B8:D8) -> 1355750 | G8: 账实核对 | H8: =资金账户!$G$30 -> √ 账实一致
A9: 营业成本 | B9: ='农业-利润表'!$C$7 -> 177927.62 | C9: ='木业-利润表'!$C$7 -> 366029.05 | D9: ='科技-利润表'!$C$7 -> 138396.43 | E9: =SUM(B9:D9) -> 682353.1 | G9: 内部交易 | H9: =IF(COUNTIF(内部交易核对!$I$6:$I$11,"✗*")=0,"√ 三家之间对得上","✗ 有 "&COUNTIF(内部交易核对!$I$6:$I$11,"✗*")&" 对对不上") -> √ 三家之间对得上
A10: 毛利 | B10: =B8-B9 -> 151072.38 | C10: =C8-C9 -> 215970.95 | D10: =D8-D9 -> 306353.57 | E10: =SUM(B10:D10) -> 673396.9 | G10: 合并后收入 | H10: =三公司合并报表!$G$8 -> 1110750
A11: 营业利润 | B11: ='农业-利润表'!$C$14 -> 22072.38 | C11: ='木业-利润表'!$C$14 -> 71150.95 | D11: ='科技-利润表'!$C$14 -> 169693.57 | E11: =SUM(B11:D11) -> 262916.9 | G11: 合并后净利 | H11: =三公司合并报表!$G$21 -> 244916.9
A12: 利润总额 | B12: ='农业-利润表'!$C$17 -> 22072.38 | C12: ='木业-利润表'!$C$17 -> 71150.95 | D12: ='科技-利润表'!$C$17 -> 169693.57 | E12: =SUM(B12:D12) -> 262916.9
A13: 净利润 | B13: ='农业-利润表'!$C$19 -> 22072.38 | C13: ='木业-利润表'!$C$19 -> 65150.95 | D13: ='科技-利润表'!$C$19 -> 157693.57 | E13: =SUM(B13:D13) -> 244916.9
A14: 资产总计 | B14: ='农业-资产负债表'!$C$25 -> 2310272.4 | C14: ='木业-资产负债表'!$C$25 -> 1686400.9 | D14: ='科技-资产负债表'!$C$25 -> 1267433.6 | E14: =SUM(B14:D14) -> 5264106.9
A15: 货币资金 | B15: ='农业-资产负债表'!$C$7 -> 319200 | C15: ='木业-资产负债表'!$C$7 -> 420380 | D15: ='科技-资产负债表'!$C$7 -> 534660 | E15: =SUM(B15:D15) -> 1274240
A16: 存货 | B16: ='农业-资产负债表'!$C$11 -> 68072.38 | C16: ='木业-资产负债表'!$C$11 -> 212020.95 | D16: ='科技-资产负债表'!$C$11 -> 124023.57 | E16: =SUM(B16:D16) -> 404116.9
A17: 应收账款 | B17: ='农业-资产负债表'!$C$8 -> 73000 | C17: ='木业-资产负债表'!$C$8 -> 368000 | D17: ='科技-资产负债表'!$C$8 -> 202750 | E17: =SUM(B17:D17) -> 643750
A18: 应付账款 | B18: ='农业-资产负债表'!$G$8 -> 48200 | C18: ='木业-资产负债表'!$G$8 -> 127000 | D18: ='科技-资产负债表'!$G$8 -> 61000 | E18: =SUM(B18:D18) -> 236200
A19: 负债合计 | B19: ='农业-资产负债表'!$G$16 -> 328200 | C19: ='木业-资产负债表'!$G$16 -> 620000 | D19: ='科技-资产负债表'!$G$16 -> 90600 | E19: =SUM(B19:D19) -> 1038800
A20: 所有者权益 | B20: ='农业-资产负债表'!$G$22 -> 1982072.4 | C20: ='木业-资产负债表'!$G$22 -> 1066400.9 | D20: ='科技-资产负债表'!$G$22 -> 1176833.6 | E20: =SUM(B20:D20) -> 4225306.9
A21: 毛利率 | B21: =IF(ROUND(B8,2)=0,"—",B10/B8) -> 0.45918657 | C21: =IF(ROUND(C8,2)=0,"—",C10/C8) -> 0.37108411 | D21: =IF(ROUND(D8,2)=0,"—",D10/D8) -> 0.68882197 | E21: =IF(ROUND(E8,2)=0,"—",E10/E8) -> 0.49669696
A23: 二、常用入口
A24: ① 每天录这四张 | B24: =HYPERLINK("#'购销流水'!A1","购销流水") -> 购销流水 | C24: =HYPERLINK("#'资金流水'!A1","资金流水") -> 资金流水 | D24: =HYPERLINK("#'生产加工'!A1","生产加工") -> 生产加工 | E24: =HYPERLINK("#'其他分录'!A1","其他分录") -> 其他分录
A25: ② 先建好档案 | B25: =HYPERLINK("#'参数设置'!A1","参数设置") -> 参数设置 | C25: =HYPERLINK("#'商品档案'!A1","商品档案") -> 商品档案 | D25: =HYPERLINK("#'往来单位'!A1","往来单位") -> 往来单位 | E25: =HYPERLINK("#'资金账户'!A1","资金账户") -> 资金账户
B26: =HYPERLINK("#'期初余额'!A1","期初余额") -> 期初余额 | C26: =HYPERLINK("#'会计科目表'!A1","会计科目表") -> 会计科目表 | D26: =HYPERLINK("#'记账规则'!A1","记账规则") -> 记账规则
A27: ③ 出报表 | B27: =HYPERLINK("#'农业-资产负债表'!A1","农业-资产负债表") -> 农业-资产负债表 | C27: =HYPERLINK("#'农业-利润表'!A1","农业-利润表") -> 农业-利润表 | D27: =HYPERLINK("#'木业-资产负债表'!A1","木业-资产负债表") -> 木业-资产负债表 | E27: =HYPERLINK("#'木业-利润表'!A1","木业-利润表") -> 木业-利润表
B28: =HYPERLINK("#'科技-资产负债表'!A1","科技-资产负债表") -> 科技-资产负债表 | C28: =HYPERLINK("#'科技-利润表'!A1","科技-利润表") -> 科技-利润表 | D28: =HYPERLINK("#'三公司合并报表'!A1","三公司合并报表") -> 三公司合并报表
A29: ④ 查台账 | B29: =HYPERLINK("#'科目余额表'!A1","科目余额表") -> 科目余额表 | C29: =HYPERLINK("#'记账分录'!A1","记账分录") -> 记账分录 | D29: =HYPERLINK("#'进销存台账'!A1","进销存台账") -> 进销存台账 | E29: =HYPERLINK("#'收发存查询'!A1","收发存查询") -> 收发存查询
B30: =HYPERLINK("#'往来台账'!A1","往来台账") -> 往来台账 | C30: =HYPERLINK("#'税费台账'!A1","税费台账") -> 税费台账 | D30: =HYPERLINK("#'费用统计'!A1","费用统计") -> 费用统计 | E30: =HYPERLINK("#'内部交易核对'!A1","内部交易核对") -> 内部交易核对
A31: ⑤ 对数 | B31: =HYPERLINK("#'校验中心'!A1","校验中心") -> 校验中心 | C31: =HYPERLINK("#'使用说明'!A1","使用说明") -> 使用说明
A33: 三、表格容量（快满了就去【生成脚本】把容量数字改大重跑，或直接新开一年）
A34: 购销流水 | B34: =COUNT(购销流水!$B$6:$B$805) -> 20 | C34: 800 | D34: =IF($C34=0,"",$B34/$C34) -> 0.025 | E34: =IF($B34/$C34>0.9,"✗ 快满了","√ 够用") -> √ 够用
A35: 资金流水 | B35: =COUNT(资金流水!$B$6:$B$605) -> 34 | C35: 600 | D35: =IF($C35=0,"",$B35/$C35) -> 0.056666667 | E35: =IF($B35/$C35>0.9,"✗ 快满了","√ 够用") -> √ 够用
A36: 生产加工 | B36: =COUNT(生产加工!$B$6:$B$305) -> 36 | C36: 300 | D36: =IF($C36=0,"",$B36/$C36) -> 0.12 | E36: =IF($B36/$C36>0.9,"✗ 快满了","√ 够用") -> √ 够用
A37: 其他分录 | B37: =COUNT(其他分录!$B$6:$B$255) -> 10 | C37: 250 | D37: =IF($C37=0,"",$B37/$C37) -> 0.04 | E37: =IF($B37/$C37>0.9,"✗ 快满了","√ 够用") -> √ 够用
A38: 商品档案 | B38: =COUNTA(商品档案!$A$6:$A$65) -> 25 | C38: 60 | D38: =IF($C38=0,"",$B38/$C38) -> 0.41666667 | E38: =IF($B38/$C38>0.9,"✗ 快满了","√ 够用") -> √ 够用
A39: 往来单位 | B39: =COUNTA(往来单位!$A$6:$A$85) -> 23 | C39: 80 | D39: =IF($C39=0,"",$B39/$C39) -> 0.2875 | E39: =IF($B39/$C39>0.9,"✗ 快满了","√ 够用") -> √ 够用

Sheet 使用说明
A1: 使用说明
A2: 照着这个顺序走一遍，这套表就能自己跑起来。
B5: 主题 | C5: 说 明
A6: 一、这套表怎么转
B7: 四张录入表 | C7: 【购销流水】进货卖货（只管货和票，一律挂应收应付）｜【资金流水】所有账户的收支｜【生产加工】领料、加工费、产成品入库｜【其他分录】折旧摊销计提结转。
B8: 自动往下走 | C8: 四张表 →【记账分录】按【记账规则】展开成借贷 →【科目余额表】→ 三家的资产负债表、利润表和【三公司合并报表】。中间不用你手工做凭证。
B9: 一年一套 | C9: 【参数设置】把会计年度改成新的一年，把四张录入表的数据清掉，再把上年各表的期末数抄到【期初余额】，就是新一年的账。建议每年另存一个文件。
A10: 二、先把档案建好
B11: 参数设置 | C11: 会计年度、附加税率、所得税率，以及「费用项目」清单（资金流水和其他分录的下拉就取这一列）。
B12: 商品档案 | C12: 三家的料和成品。存货/收入/成本科目决定这个商品记到哪个科目。税率一列只是开票时选哪一档的提醒，内账含税核算，不参与计算。
B13: 往来单位 | C13: 客户、供应商、农户，以及三家公司互相。标了「是否内部＝是」的，购销流水会认成内部交易，合并报表按它抵销。
B14: 资金账户 | C14: 实际开了几个户就登几个。几家公司共用一个账号也照登，账户余额按账户算，账务按公司各记各的。
B15: 期初余额 | C15: 左边科目年初余额（借贷各一列），中间存货年初数量金额，右边往来按单位拆。三块都有对账提示。
B16: 会计科目表 / 记账规则 | C16: 一般不用动。要加科目就照格式加一行，「报表项目」必须用报表上已有的项目名。要改某类业务的借贷走向，就去【记账规则】改那一行。
A17: 三、日常录入
B18: 购销流水 | C18: 选公司、业务类型、往来单位、商品编码，填数量和**含税单价**即可，金额＝数量×单价，不拆税。退货用「销售退回/采购退回」，数量填正数。
B19: 向农户收购原木 | C19: 往来单位选那个农户，发票类型选「收购发票」，单价就填实际收购价。内账含税核算，收购价全额进原材料成本，不再拆 9% 进项——能不能抵扣是外账报税的事，内账只看实际付了多少钱。
B20: 资金流水 | C20: 收支混在一张表上按时间顺序录：收进来填「收入金额」，付出去填「支出金额」，金额都是含税实收实付数，右边「账户余额」逐行滚出来。业务类型决定对方科目怎么走，规则里写「@对方」的才要你自己选对方科目。收付货款记得选往来单位，这样【往来台账】才冲得掉；「关联单号」写对应的购销流水序号，日后好核销。
B21: 几家共用一个账号 | C21: 共用账户在【资金账户】里「使用公司」写清楚。资金流水每一行照样选自己的公司，所以账户余额是这个账号的真实余额，而各公司账上的银行存款是各自的——【资金账户】底下有一行「账实对账」把两边加总对上。
B22: 生产加工 | C22: 一个批次号一次加工：先记「领用投入」和「加工费用」，再记「产成品入库」。产出行不用填金额，本批投入合计会按「权重」自动分摊；一批只有一个产出，权重留空就行。
B23: 其他分录 | C23: 折旧、摊销、计提工资、计提房租，一借一贷。一借多贷拆成几行。**税不在这里计提**——内账按实缴，交税那天在【资金流水】记一笔就行。也不用做「结转本年利润」，报表会自动把损益结进未分配利润，你自己再结一次会重复。
A24: 四、看报表
B25: 按起止日期筛选 | C25: 所有汇总和查询表第 3 行都有「年度 / 起始日期 / 截止日期」。都留空＝全部期间；只填年度＝整年；填了起止就按起止。录入表和明细表不筛选，全部显示。
B26: 资产负债表 | C26: 年初数取期初余额表；期末数算到截止日期。未分配利润＝年初未分配＋本年净利润。最后一行「平衡校验」必须是 √。
B27: 利润表 | C27: 「本期金额」是起止区间的发生额，「本年累计」是年初到截止日的累计。下面附毛利率和净利率。
B28: 合并报表 | C28: 三家单体＋小计＋内部抵销＝合并数。内部销售收入/成本、内部应收应付自动抵；「未实现内部存货利润」要你自己估一个填进去（上面有算法），不填按 0。
B29: 进销存台账 / 收发存查询 | C29: 【进销存台账】是全年口径、成本基准表，加权平均单价就在这张表上算，购销结转成本和生产领用都按它取价，所以它不随日期筛选变。要看某段时间的收发存，用【收发存查询】。
B30: 往来台账 / 税费台账 / 费用统计 | C30: 往来台账按公司看每家客户供应商的应收应付；税费台账按公司按月按税种列实缴税费和税负率；费用统计上半张按费用项目、下半张按会计科目。
A31: 五、几个口径说明
B32: 存货计价 | C32: 全年加权平均（含税口径）：单价＝（期初金额＋采购入库金额＋生产入库金额）÷ 对应数量。不含出库，所以不会循环引用。年中看的成本是按全年均价倒推的，和逐笔移动平均会有小差异。
B33: 含税核算 / 实交税费 | C33: 这是内账，全部含税：卖多少钱记多少收入，进货花多少钱记多少成本，费用付多少记多少，一律不拆进项销项，科目表里也没有进项/销项税额。税走【资金流水】的「缴纳税费」——交增值税、附加税、印花税、个税进「税金及附加」，交企业所得税进「所得税费用」，费用项目里选具体税种，【税费台账】按月按税种摊开、给出全年税负率。内部交易两边都是同一个含税金额，所以【内部交易核对】要求分毫不差。
B34: 税率参数只是参考 | C34: 【参数设置】上的附加税率和所得税率不参与任何计算，只是你自己估税时的提醒。实际交了多少，就在【资金流水】记多少。农林牧渔里的林木种植所得免征企业所得税、自产农产品销售免征增值税，所以农业基地公司示例里全年税费是 0。
B35: 示例数据 | C35: 四张录入表里都放了示例（购销 20 条、资金 34 条、生产 36 条、其他分录 10 条），专门用来现场验公式。正式用之前，把这些行整行删掉即可，【期初余额】和【商品档案】里的示例也一并换成你自己的。

Sheet 参数设置
A1: 参数设置
A2: 一年一套表：先把下面的会计年度改成本年度，再另存为新文件，就是新一年的账。这套表是内账口径——全部含税核算、税按实缴进费用，右边有说明。
A5: 会计年度 | B5: 2026 | C5: 期初日期 | D5: =DATE($B$5,1,1) -> 46023 | E5: 期末日期 | F5: =DATE($B$5,12,31) -> 46387 | G5: 附加税率（参考） | H5: 0.12 | I5: 所得税率（参考） | J5: 0.05
A6: 说明 | B6: 本账套是内账：收入成本费用一律含税核算，税按实际缴纳当期计入费用，不计提、不拆进项销项。这两个税率只是算税时给你参考用（附加税＝城建 7%＋教育费附加 3%＋地方教育附加 2%；所得税按小微实际税负 5%），表里的任何计算都不用它们。农林牧渔中的林木种植所得免征企业所得税、自产农产品销售免征增值税，农业基地公司示例里就没有税。
A8: 一、三家公司
A9: 简称（各表都用这个） | B9: 公司全称 | C9: 纳税人身份 | D9: 主营业务
A10: 农业 | B10: 农业基地公司 | C10: 一般纳税人 | D10: 林木种植（原木）、艾草种植，自产农产品免征增值税 | J10: =COUNTIFS(记账分录!$F$6:$F$5505,$A10) -> 70
A11: 木业 | B11: 木业公司 | C11: 一般纳税人 | D11: 收购原木加工板材、模板、方料并销售 | J11: =COUNTIFS(记账分录!$F$6:$F$5505,$A11) -> 76
A12: 科技 | B12: 科技公司 | C12: 一般纳税人 | D12: 收购干艾草提取艾草精油及衍生品并销售 | J12: =COUNTIFS(记账分录!$F$6:$F$5505,$A12) -> 76
A14: 二、费用项目（资金流水 / 生产加工 / 其他分录 的「费用项目」下拉就是这一列）
A15: 费用项目 | B15: 默认归集科目 | C15: 本年合计（三家）
A16: 办公费 | B16: 管理费用 | C16: =IF($A16="","",费用统计!$E$7) -> 3200 | F16: 内账口径（这套表的核心约定）：
A17: 差旅费 | B17: 管理费用 | C17: =IF($A17="","",费用统计!$E$8) -> 1800 | F17: 含税核算 | G17: 收入、成本、费用一律按实际成交的含税金额入账，不拆进项销项，也不设进项/销项科目
A18: 业务招待费 | B18: 管理费用 | C18: =IF($A18="","",费用统计!$E$9) -> 0 | F18: 实交税费 | G18: 增值税、附加税、所得税、个税都在实际缴纳那个月，按缴的钱直接进费用
A19: 水电费 | B19: 管理费用 | C19: =IF($A19="","",费用统计!$E$10) -> 8600 | F19: 缴税怎么录 | G19: 【资金流水】选「缴纳税费」→ 对方科目选税金及附加或所得税费用 → 费用项目选税种
A20: 燃料动力费 | B20: 生产成本 | C20: =IF($A20="","",费用统计!$E$11) -> 14000 | F20: 不计提税金 | G20: 不做「计提应交税费」的分录，资产负债表上也就没有应交税费余额（期初有欠税除外）
A21: 房租物业 | B21: 管理费用 | C21: =IF($A21="","",费用统计!$E$12) -> 24000 | F21: 开票税率 | G21: 商品档案上的税率只用来提醒开票时选哪一档，不参与任何计算
A22: 工资薪金 | B22: 应付职工薪酬 | C22: =IF($A22="","",费用统计!$E$13) -> 280000
A23: 社保公积金 | B23: 管理费用 | C23: =IF($A23="","",费用统计!$E$14) -> 12000
A24: 折旧费 | B24: 管理费用 | C24: =IF($A24="","",费用统计!$E$15) -> 196000
A25: 摊销费 | B25: 管理费用 | C25: =IF($A25="","",费用统计!$E$16) -> 30000
A26: 修理维护费 | B26: 管理费用 | C26: =IF($A26="","",费用统计!$E$17) -> 0
A27: 低值易耗品 | B27: 管理费用 | C27: =IF($A27="","",费用统计!$E$18) -> 860
A28: 运输费 | B28: 销售费用 | C28: =IF($A28="","",费用统计!$E$19) -> 0
A29: 广告推广费 | B29: 销售费用 | C29: =IF($A29="","",费用统计!$E$20) -> 26500
A30: 平台服务费 | B30: 销售费用 | C30: =IF($A30="","",费用统计!$E$21) -> 9600
A31: 包装费 | B31: 销售费用 | C31: =IF($A31="","",费用统计!$E$22) -> 0
A32: 检测认证费 | B32: 管理费用 | C32: =IF($A32="","",费用统计!$E$23) -> 0
A33: 咨询服务费 | B33: 管理费用 | C33: =IF($A33="","",费用统计!$E$24) -> 0
A34: 利息支出 | B34: 财务费用 | C34: =IF($A34="","",费用统计!$E$25) -> 6000
A35: 银行手续费 | B35: 财务费用 | C35: =IF($A35="","",费用统计!$E$26) -> 0
A36: 保险费 | B36: 管理费用 | C36: =IF($A36="","",费用统计!$E$27) -> 0
A37: 林地管护费 | B37: 生产成本 | C37: =IF($A37="","",费用统计!$E$28) -> 0
A38: 采伐运输费 | B38: 生产成本 | C38: =IF($A38="","",费用统计!$E$29) -> 25000
A39: 研发材料费 | B39: 研发费用 | C39: =IF($A39="","",费用统计!$E$30) -> 0
A40: 增值税 | B40: 税金及附加 | C40: =IF($A40="","",费用统计!$E$31) -> 0
A41: 城建税及附加 | B41: 税金及附加 | C41: =IF($A41="","",费用统计!$E$32) -> 0
A42: 印花税 | B42: 税金及附加 | C42: =IF($A42="","",费用统计!$E$33) -> 0
A43: 企业所得税 | B43: 所得税费用 | C43: =IF($A43="","",费用统计!$E$34) -> 0
A44: 个人所得税 | B44: 税金及附加 | C44: =IF($A44="","",费用统计!$E$35) -> 0
...

Sheet 会计科目表
A1: 会计科目表
A2: 报表就是按「报表项目」这一列汇总出来的。加科目照着填一行即可；「余额方向」决定期末余额怎么算，「报表项目」必须用资产负债表/利润表上已有的项目名。
A5: 科目编码 | B5: 科目名称 | C5: 科目类别 | D5: 余额方向 | E5: 所属报表 | F5: 报表项目 | G5: 往来核算 | H5: 本年借方发生 | I5: 本年贷方发生 | J5: 备注
A6: 1001 | B6: 库存现金 | C6: 资产 | D6: 借 | E6: 资产负债表 | F6: 货币资金 | G6: 否 | H6: =IF($B6="","",SUMIFS(记账分录!$I$6:$I$5505,记账分录!$H$6:$H$5505,$B6)) -> 0 | I6: =IF($B6="","",SUMIFS(记账分录!$J$6:$J$5505,记账分录!$H$6:$H$5505,$B6)) -> 2660
A7: 1002 | B7: 银行存款 | C7: 资产 | D7: 借 | E7: 资产负债表 | F7: 货币资金 | G7: 否 | H7: =IF($B7="","",SUMIFS(记账分录!$I$6:$I$5505,记账分录!$H$6:$H$5505,$B7)) -> 1206000 | I7: =IF($B7="","",SUMIFS(记账分录!$J$6:$J$5505,记账分录!$H$6:$H$5505,$B7)) -> 699100
A8: 1012 | B8: 其他货币资金 | C8: 资产 | D8: 借 | E8: 资产负债表 | F8: 货币资金 | G8: 否 | H8: =IF($B8="","",SUMIFS(记账分录!$I$6:$I$5505,记账分录!$H$6:$H$5505,$B8)) -> 0 | I8: =IF($B8="","",SUMIFS(记账分录!$J$6:$J$5505,记账分录!$H$6:$H$5505,$B8)) -> 0
A9: 1122 | B9: 应收账款 | C9: 资产 | D9: 借 | E9: 资产负债表 | F9: 应收账款 | G9: 是 | H9: =IF($B9="","",SUMIFS(记账分录!$I$6:$I$5505,记账分录!$H$6:$H$5505,$B9)) -> 1355750 | I9: =IF($B9="","",SUMIFS(记账分录!$J$6:$J$5505,记账分录!$H$6:$H$5505,$B9)) -> 956000
A10: 1123 | B10: 预付账款 | C10: 资产 | D10: 借 | E10: 资产负债表 | F10: 预付款项 | G10: 是 | H10: =IF($B10="","",SUMIFS(记账分录!$I$6:$I$5505,记账分录!$H$6:$H$5505,$B10)) -> 0 | I10: =IF($B10="","",SUMIFS(记账分录!$J$6:$J$5505,记账分录!$H$6:$H$5505,$B10)) -> 0
A11: 1221 | B11: 其他应收款 | C11: 资产 | D11: 借 | E11: 资产负债表 | F11: 其他应收款 | G11: 是 | H11: =IF($B11="","",SUMIFS(记账分录!$I$6:$I$5505,记账分录!$H$6:$H$5505,$B11)) -> 0 | I11: =IF($B11="","",SUMIFS(记账分录!$J$6:$J$5505,记账分录!$H$6:$H$5505,$B11)) -> 0
A12: 1403 | B12: 原材料 | C12: 资产 | D12: 借 | E12: 资产负债表 | F12: 存货 | G12: 否 | H12: =IF($B12="","",SUMIFS(记账分录!$I$6:$I$5505,记账分录!$H$6:$H$5505,$B12)) -> 401080 | I12: =IF($B12="","",SUMIFS(记账分录!$J$6:$J$5505,记账分录!$H$6:$H$5505,$B12)) -> 340766.29
A13: 1405 | B13: 库存商品 | C13: 资产 | D13: 借 | E13: 资产负债表 | F13: 存货 | G13: 否 | H13: =IF($B13="","",SUMIFS(记账分录!$I$6:$I$5505,记账分录!$H$6:$H$5505,$B13)) -> 751441.01 | I13: =IF($B13="","",SUMIFS(记账分录!$J$6:$J$5505,记账分录!$H$6:$H$5505,$B13)) -> 792027.82
A14: 1411 | B14: 周转材料 | C14: 资产 | D14: 借 | E14: 资产负债表 | F14: 存货 | G14: 否 | H14: =IF($B14="","",SUMIFS(记账分录!$I$6:$I$5505,记账分录!$H$6:$H$5505,$B14)) -> 0 | I14: =IF($B14="","",SUMIFS(记账分录!$J$6:$J$5505,记账分录!$H$6:$H$5505,$B14)) -> 0
A15: 1501 | B15: 生产成本 | C15: 成本 | D15: 借 | E15: 资产负债表 | F15: 存货 | G15: 否 | H15: =IF($B15="","",SUMIFS(记账分录!$I$6:$I$5505,记账分录!$H$6:$H$5505,$B15)) -> 751441.01 | I15: =IF($B15="","",SUMIFS(记账分录!$J$6:$J$5505,记账分录!$H$6:$H$5505,$B15)) -> 751441.01
A16: 1601 | B16: 固定资产 | C16: 资产 | D16: 借 | E16: 资产负债表 | F16: 固定资产原价 | G16: 否 | H16: =IF($B16="","",SUMIFS(记账分录!$I$6:$I$5505,记账分录!$H$6:$H$5505,$B16)) -> 0 | I16: =IF($B16="","",SUMIFS(记账分录!$J$6:$J$5505,记账分录!$H$6:$H$5505,$B16)) -> 0
A17: 1602 | B17: 累计折旧 | C17: 资产 | D17: 贷 | E17: 资产负债表 | F17: 累计折旧 | G17: 否 | H17: =IF($B17="","",SUMIFS(记账分录!$I$6:$I$5505,记账分录!$H$6:$H$5505,$B17)) -> 0 | I17: =IF($B17="","",SUMIFS(记账分录!$J$6:$J$5505,记账分录!$H$6:$H$5505,$B17)) -> 176000
... A46: 6801 | B46: 所得税费用 | C46: 损益-费用 | D46: 借 | E46: 利润表 | F46: 所得税费用 | G46: 否 | H46: =IF($B46="","",SUMIFS(记账分录!$I$6:$I$5505,记账分录!$H$6:$H$5505,$B46)) -> 18000 | I46: =IF($B46="","",SUMIFS(记账分录!$J$6:$J$5505,记账分录!$H$6:$H$5505,$B46)) -> 0
H47: =IF($B47="","",SUMIFS(记账分录!$I$6:$I$5505,记账分录!$H$6:$H$5505,$B47)) | I47: =IF($B47="","",SUMIFS(记账分录!$J$6:$J$5505,记账分录!$H$6:$H$5505,$B47))
H48: =IF($B48="","",SUMIFS(记账分录!$I$6:$I$5505,记账分录!$H$6:$H$5505,$B48)) | I48: =IF($B48="","",SUMIFS(记账分录!$J$6:$J$5505,记账分录!$H$6:$H$5505,$B48))
H49: =IF($B49="","",SUMIFS(记账分录!$I$6:$I$5505,记账分录!$H$6:$H$5505,$B49)) | I49: =IF($B49="","",SUMIFS(记账分录!$J$6:$J$5505,记账分录!$H$6:$H$5505,$B49))
H50: =IF($B50="","",SUMIFS(记账分录!$I$6:$I$5505,记账分录!$H$6:$H$5505,$B50)) | I50: =IF($B50="","",SUMIFS(记账分录!$J$6:$J$5505,记账分录!$H$6:$H$5505,$B50))
H51: =IF($B51="","",SUMIFS(记账分录!$I$6:$I$5505,记账分录!$H$6:$H$5505,$B51)) | I51: =IF($B51="","",SUMIFS(记账分录!$J$6:$J$5505,记账分录!$H$6:$H$5505,$B51))
H52: =IF($B52="","",SUMIFS(记账分录!$I$6:$I$5505,记账分录!$H$6:$H$5505,$B52)) | I52: =IF($B52="","",SUMIFS(记账分录!$J$6:$J$5505,记账分录!$H$6:$H$5505,$B52))
H53: =IF($B53="","",SUMIFS(记账分录!$I$6:$I$5505,记账分录!$H$6:$H$5505,$B53)) | I53: =IF($B53="","",SUMIFS(记账分录!$J$6:$J$5505,记账分录!$H$6:$H$5505,$B53))
H54: =IF($B54="","",SUMIFS(记账分录!$I$6:$I$5505,记账分录!$H$6:$H$5505,$B54)) | I54: =IF($B54="","",SUMIFS(记账分录!$J$6:$J$5505,记账分录!$H$6:$H$5505,$B54))
H55: =IF($B55="","",SUMIFS(记账分录!$I$6:$I$5505,记账分录!$H$6:$H$5505,$B55)) | I55: =IF($B55="","",SUMIFS(记账分录!$J$6:$J$5505,记账分录!$H$6:$H$5505,$B55))
H56: =IF($B56="","",SUMIFS(记账分录!$I$6:$I$5505,记账分录!$H$6:$H$5505,$B56)) | I56: =IF($B56="","",SUMIFS(记账分录!$J$6:$J$5505,记账分录!$H$6:$H$5505,$B56))
H57: =IF($B57="","",SUMIFS(记账分录!$I$6:$I$5505,记账分录!$H$6:$H$5505,$B57)) | I57: =IF($B57="","",SUMIFS(记账分录!$J$6:$J$5505,记账分录!$H$6:$H$5505,$B57))
H58: =IF($B58="","",SUMIFS(记账分录!$I$6:$I$5505,记账分录!$H$6:$H$5505,$B58)) | I58: =IF($B58="","",SUMIFS(记账分录!$J$6:$J$5505,记账分录!$H$6:$H$5505,$B58))
... H85: =IF($B85="","",SUMIFS(记账分录!$I$6:$I$5505,记账分录!$H$6:$H$5505,$B85)) | I85: =IF($B85="","",SUMIFS(记账分录!$J$6:$J$5505,记账分录!$H$6:$H$5505,$B85))

Sheet 记账规则
A1: 记账规则（业务类型 → 借贷分录）
A2: 录入表只填业务，借贷两条腿由这张表决定。科目里的 @ 是占位符：@结算＝按结算方式取（挂账→应收/应付、现金→库存现金、银行→银行存款）；@存货/@收入/@成本＝按商品档案该商品设的科目取；@账户＝资金流水那行选的账户；@对方＝那行填的对方科目。看不惯哪条改哪条，改完全表立刻跟着变。
A4: 一、购销流水（4 条腿：结算 / 收入或存货 / 结转成本借 / 结转成本贷）
A5: 业务类型 | B5: 说明 | C5: 腿1 科目 | D5: 腿1 借贷 | E5: 腿1 取值 | F5: 腿2 科目 | G5: 腿2 借贷 | H5: 腿2 取值 | I5: 腿3 科目 | J5: 腿3 借贷 | K5: 腿3 取值 | L5: 腿4 科目 | M5: 腿4 借贷 | N5: 腿4 取值
A6: 销售出库 | B6: 按含税金额确认收入，同时结转销售成本 | C6: @结算 | D6: 借 | E6: 金额 | F6: @收入 | G6: 贷 | H6: 金额 | I6: @成本 | J6: 借 | K6: 成本金额 | L6: @存货 | M6: 贷 | N6: 成本金额
A7: 采购入库 | B7: 按含税金额直接进存货，不拆进项 | C7: @结算 | D7: 贷 | E7: 金额 | F7: @存货 | G7: 借 | H7: 金额
A8: 销售退回 | B8: 客户退货，收入与成本同时冲回 | C8: @结算 | D8: 贷 | E8: 金额 | F8: @收入 | G8: 借 | H8: 金额 | I8: @成本 | J8: 贷 | K8: 成本金额 | L8: @存货 | M8: 借 | N8: 成本金额
A9: 采购退回 | B9: 退货给供应商，按含税金额冲存货 | C9: @结算 | D9: 借 | E9: 金额 | F9: @存货 | G9: 贷 | H9: 金额
A11: 二、资金流水（2 条腿：账户 / 对方）
A12: 业务类型 | B12: 说明 | C12: 腿1 科目 | D12: 腿1 借贷 | E12: 腿1 取值 | F12: 腿2 科目 | G12: 腿2 借贷 | H12: 腿2 取值
A13: 收客户货款 | B13: 收回应收账款 | C13: @账户 | D13: 借 | E13: 金额 | F13: 应收账款 | G13: 贷 | H13: 金额
A14: 付供应商货款 | B14: 支付应付账款 | C14: @账户 | D14: 贷 | E14: 金额 | F14: 应付账款 | G14: 借 | H14: 金额
A15: 收预收款 | B15: 客户预付货款 | C15: @账户 | D15: 借 | E15: 金额 | F15: 预收账款 | G15: 贷 | H15: 金额
A16: 付预付款 | B16: 预付供应商货款 | C16: @账户 | D16: 贷 | E16: 金额 | F16: 预付账款 | G16: 借 | H16: 金额
A17: 收其他应收款 | B17: 收回借出/代垫款 | C17: @账户 | D17: 借 | E17: 金额 | F17: 其他应收款 | G17: 贷 | H17: 金额
A18: 借出代垫款 | B18: 借出或代垫款项 | C18: @账户 | D18: 贷 | E18: 金额 | F18: 其他应收款 | G18: 借 | H18: 金额
A19: 收往来借入款 | B19: 收到关联方/个人借入 | C19: @账户 | D19: 借 | E19: 金额 | F19: 其他应付款 | G19: 贷 | H19: 金额
A20: 付其他应付款 | B20: 归还关联方/个人借入 | C20: @账户 | D20: 贷 | E20: 金额 | F20: 其他应付款 | G20: 借 | H20: 金额
A21: 费用支出 | B21: 付费用，含税全额进费用科目 | C21: @账户 | D21: 贷 | E21: 金额 | F21: @对方 | G21: 借 | H21: 金额
A22: 缴纳税费 | B22: 实际缴的税当期进费用 | C22: @账户 | D22: 贷 | E22: 金额 | F22: @对方 | G22: 借 | H22: 金额
A23: 现销收款 | B23: 不开票或即收即开的收入（含税） | C23: @账户 | D23: 借 | E23: 金额 | F23: @对方 | G23: 贷 | H23: 金额
... A32: 其他支出 | B32: 营业外支出等 | C32: @账户 | D32: 贷 | E32: 金额 | F32: @对方 | G32: 借 | H32: 金额
A34: 三、生产加工（2 条腿）
A35: 业务类型 | B35: 说明 | C35: 腿1 科目 | D35: 腿1 借贷 | E35: 腿1 取值 | F35: 腿2 科目 | G35: 腿2 借贷 | H35: 腿2 取值
A36: 领用投入 | B36: 领原料进车间，按加权平均成本出库 | C36: 生产成本 | D36: 借 | E36: 记账金额 | F36: @存货 | G36: 贷 | H36: 记账金额
A37: 加工费用 | B37: 人工/能耗/折旧等计入本批成本 | C37: 生产成本 | D37: 借 | E37: 记账金额 | F37: @对方 | G37: 贷 | H37: 记账金额
A38: 产成品入库 | B38: 本批投入合计按权重分摊到产出 | C38: @存货 | D38: 借 | E38: 记账金额 | F38: 生产成本 | G38: 贷 | H38: 记账金额
A40: 四、其他分录 | B40: 没有规则表——直接在【其他分录】里填借方科目、贷方科目和金额，一借一贷。一借多贷就拆成几行写。

Sheet 商品档案
A1: 商品档案
A2: 三家公司的料和成品都登在这里，用「所属公司」分开。存货/收入/成本科目决定这个商品的分录进哪个科目。内账是含税核算，「开票参考税率」只是登记开票时用哪档，不参与任何计算。
A5: 商品编码 | B5: 商品名称 | C5: 规格型号 | D5: 单位 | E5: 所属公司 | F5: 存货类别 | G5: 存货科目 | H5: 收入科目 | I5: 成本科目 | J5: 开票参考税率 | K5: 备注 | L5: 本年结存金额 | M5: 校验
A6: NY01 | B6: 原木 | C6: 杉木/松木 4m | D6: 立方米 | E6: 农业 | F6: 产成品 | G6: 库存商品 | H6: 主营业务收入 | I6: 主营业务成本 | J6: 0 | K6: 自产林木采伐，销售免征增值税 | L6: =IF($A6="","",SUMIFS(进销存台账!$U$6:$U$65,进销存台账!$B$6:$B$65,$A6,进销存台账!$A$6:$A$65,$E6)) -> 41322.22 | M6: =IF($A6="","",IF(COUNTIF($A$6:$A$65,$A6)>1,"编码重复",IF($B6="","缺名称",IF(COUNTIF(会计科目表!$B$6:$B$85,$G6)=0,"存货科目不存在",IF(AND($F6<>"原材料",COUNTIF(会计科目表!$B$6:$B$85,$H6)=0),"收入科目不存在","OK"))))) -> OK
A7: NY02 | B7: 湿艾草 | C7: 鲜艾草 | D7: 公斤 | E7: 农业 | F7: 半成品 | G7: 库存商品 | H7: 主营业务收入 | I7: 主营业务成本 | J7: 0 | K7: 采收后未烘干，用于烘制干艾草 | L7: =IF($A7="","",SUMIFS(进销存台账!$U$6:$U$65,进销存台账!$B$6:$B$65,$A7,进销存台账!$A$6:$A$65,$E7)) -> 0 | M7: =IF($A7="","",IF(COUNTIF($A$6:$A$65,$A7)>1,"编码重复",IF($B7="","缺名称",IF(COUNTIF(会计科目表!$B$6:$B$85,$G7)=0,"存货科目不存在",IF(AND($F7<>"原材料",COUNTIF(会计科目表!$B$6:$B$85,$H7)=0),"收入科目不存在","OK"))))) -> OK
A8: NY03 | B8: 干艾草 | C8: 含水率≤12% | D8: 公斤 | E8: 农业 | F8: 产成品 | G8: 库存商品 | H8: 主营业务收入 | I8: 主营业务成本 | J8: 0 | K8: 自产农产品，销售免征增值税 | L8: =IF($A8="","",SUMIFS(进销存台账!$U$6:$U$65,进销存台账!$B$6:$B$65,$A8,进销存台账!$A$6:$A$65,$E8)) -> 14527.94 | M8: =IF($A8="","",IF(COUNTIF($A$6:$A$65,$A8)>1,"编码重复",IF($B8="","缺名称",IF(COUNTIF(会计科目表!$B$6:$B$85,$G8)=0,"存货科目不存在",IF(AND($F8<>"原材料",COUNTIF(会计科目表!$B$6:$B$85,$H8)=0),"收入科目不存在","OK"))))) -> OK
A9: NY04 | B9: 树苗 | C9: 杉木苗 | D9: 株 | E9: 农业 | F9: 原材料 | G9: 原材料 | J9: 0 | K9: 外购苗木免税 | L9: =IF($A9="","",SUMIFS(进销存台账!$U$6:$U$65,进销存台账!$B$6:$B$65,$A9,进销存台账!$A$6:$A$65,$E9)) -> 0 | M9: =IF($A9="","",IF(COUNTIF($A$6:$A$65,$A9)>1,"编码重复",IF($B9="","缺名称",IF(COUNTIF(会计科目表!$B$6:$B$85,$G9)=0,"存货科目不存在",IF(AND($F9<>"原材料",COUNTIF(会计科目表!$B$6:$B$85,$H9)=0),"收入科目不存在","OK"))))) -> OK
A10: NY05 | B10: 肥料 | C10: 复合肥 | D10: 吨 | E10: 农业 | F10: 原材料 | G10: 原材料 | J10: 0 | K10: 化肥免征增值税 | L10: =IF($A10="","",SUMIFS(进销存台账!$U$6:$U$65,进销存台账!$B$6:$B$65,$A10,进销存台账!$A$6:$A$65,$E10)) -> 11222.22 | M10: =IF($A10="","",IF(COUNTIF($A$6:$A$65,$A10)>1,"编码重复",IF($B10="","缺名称",IF(COUNTIF(会计科目表!$B$6:$B$85,$G10)=0,"存货科目不存在",IF(AND($F10<>"原材料",COUNTIF(会计科目表!$B$6:$B$85,$H10)=0),"收入科目不存在","OK"))))) -> OK
A11: NY06 | B11: 农药 | D11: 公斤 | E11: 农业 | F11: 原材料 | G11: 原材料 | J11: 0 | K11: 农药免征增值税 | L11: =IF($A11="","",SUMIFS(进销存台账!$U$6:$U$65,进销存台账!$B$6:$B$65,$A11,进销存台账!$A$6:$A$65,$E11)) -> 1000 | M11: =IF($A11="","",IF(COUNTIF($A$6:$A$65,$A11)>1,"编码重复",IF($B11="","缺名称",IF(COUNTIF(会计科目表!$B$6:$B$85,$G11)=0,"存货科目不存在",IF(AND($F11<>"原材料",COUNTIF(会计科目表!$B$6:$B$85,$H11)=0),"收入科目不存在","OK"))))) -> OK
A12: MY01 | B12: *木制品*木板 | C12: 1220×2440×18mm | D12: 张 | E12: 木业 | F12: 产成品 | G12: 库存商品 | H12: 主营业务收入 | I12: 主营业务成本 | J12: 0.13 | K12: 开票品名按税盘选 | L12: =IF($A12="","",SUMIFS(进销存台账!$U$6:$U$65,进销存台账!$B$6:$B$65,$A12,进销存台账!$A$6:$A$65,$E12)) -> 39699.9 | M12: =IF($A12="","",IF(COUNTIF($A$6:$A$65,$A12)>1,"编码重复",IF($B12="","缺名称",IF(COUNTIF(会计科目表!$B$6:$B$85,$G12)=0,"存货科目不存在",IF(AND($F12<>"原材料",COUNTIF(会计科目表!$B$6:$B$85,$H12)=0),"收入科目不存在","OK"))))) -> OK
A13: MY02 | B13: *木制品*模板 | C13: 1220×2440×15mm | D13: 张 | E13: 木业 | F13: 产成品 | G13: 库存商品 | H13: 主营业务收入 | I13: 主营业务成本 | J13: 0.13 | L13: =IF($A13="","",SUMIFS(进销存台账!$U$6:$U$65,进销存台账!$B$6:$B$65,$A13,进销存台账!$A$6:$A$65,$E13)) -> 18904.11 | M13: =IF($A13="","",IF(COUNTIF($A$6:$A$65,$A13)>1,"编码重复",IF($B13="","缺名称",IF(COUNTIF(会计科目表!$B$6:$B$85,$G13)=0,"存货科目不存在",IF(AND($F13<>"原材料",COUNTIF(会计科目表!$B$6:$B$85,$H13)=0),"收入科目不存在","OK"))))) -> OK
A14: MY03 | B14: *木制品*方料 | D14: 立方米 | E14: 木业 | F14: 产成品 | G14: 库存商品 | H14: 主营业务收入 | I14: 主营业务成本 | J14: 0.13 | L14: =IF($A14="","",SUMIFS(进销存台账!$U$6:$U$65,进销存台账!$B$6:$B$65,$A14,进销存台账!$A$6:$A$65,$E14)) -> 0 | M14: =IF($A14="","",IF(COUNTIF($A$6:$A$65,$A14)>1,"编码重复",IF($B14="","缺名称",IF(COUNTIF(会计科目表!$B$6:$B$85,$G14)=0,"存货科目不存在",IF(AND($F14<>"原材料",COUNTIF(会计科目表!$B$6:$B$85,$H14)=0),"收入科目不存在","OK"))))) -> OK
A15: MY04 | B15: *木制品*建筑方料 | D15: 立方米 | E15: 木业 | F15: 产成品 | G15: 库存商品 | H15: 主营业务收入 | I15: 主营业务成本 | J15: 0.13 | L15: =IF($A15="","",SUMIFS(进销存台账!$U$6:$U$65,进销存台账!$B$6:$B$65,$A15,进销存台账!$A$6:$A$65,$E15)) -> 0 | M15: =IF($A15="","",IF(COUNTIF($A$6:$A$65,$A15)>1,"编码重复",IF($B15="","缺名称",IF(COUNTIF(会计科目表!$B$6:$B$85,$G15)=0,"存货科目不存在",IF(AND($F15<>"原材料",COUNTIF(会计科目表!$B$6:$B$85,$H15)=0),"收入科目不存在","OK"))))) -> OK
A16: MY05 | B16: *木制品*包装箱板材 | D16: 立方米 | E16: 木业 | F16: 产成品 | G16: 库存商品 | H16: 主营业务收入 | I16: 主营业务成本 | J16: 0.13 | L16: =IF($A16="","",SUMIFS(进销存台账!$U$6:$U$65,进销存台账!$B$6:$B$65,$A16,进销存台账!$A$6:$A$65,$E16)) -> 4476.54 | M16: =IF($A16="","",IF(COUNTIF($A$6:$A$65,$A16)>1,"编码重复",IF($B16="","缺名称",IF(COUNTIF(会计科目表!$B$6:$B$85,$G16)=0,"存货科目不存在",IF(AND($F16<>"原材料",COUNTIF(会计科目表!$B$6:$B$85,$H16)=0),"收入科目不存在","OK"))))) -> OK
A17: MY06 | B17: *林业产品*建筑木方料 | D17: 立方米 | E17: 木业 | F17: 产成品 | G17: 库存商品 | H17: 主营业务收入 | I17: 主营业务成本 | J17: 0.09 | K17: 初级林产品开票按 9% | L17: =IF($A17="","",SUMIFS(进销存台账!$U$6:$U$65,进销存台账!$B$6:$B$65,$A17,进销存台账!$A$6:$A$65,$E17)) -> 4789.04 | M17: =IF($A17="","",IF(COUNTIF($A$6:$A$65,$A17)>1,"编码重复",IF($B17="","缺名称",IF(COUNTIF(会计科目表!$B$6:$B$85,$G17)=0,"存货科目不存在",IF(AND($F17<>"原材料",COUNTIF(会计科目表!$B$6:$B$85,$H17)=0),"收入科目不存在","OK"))))) -> OK
A18: MY07 | B18: 原木 | C18: 外购/内购 4m | D18: 立方米 | E18: 木业 | F18: 原材料 | G18: 原材料 | J18: 0.09 | K18: 向农业基地公司和农户收购 | L18: =IF($A18="","",SUMIFS(进销存台账!$U$6:$U$65,进销存台账!$B$6:$B$65,$A18,进销存台账!$A$6:$A$65,$E18)) -> 126301.36 | M18: =IF($A18="","",IF(COUNTIF($A$6:$A$65,$A18)>1,"编码重复",IF($B18="","缺名称",IF(COUNTIF(会计科目表!$B$6:$B$85,$G18)=0,"存货科目不存在",IF(AND($F18<>"原材料",COUNTIF(会计科目表!$B$6:$B$85,$H18)=0),"收入科目不存在","OK"))))) -> OK
A19: MY08 | B19: 胶水 | C19: 脲醛胶 | D19: 公斤 | E19: 木业 | F19: 原材料 | G19: 原材料 | J19: 0.13 | L19: =IF($A19="","",SUMIFS(进销存台账!$U$6:$U$65,进销存台账!$B$6:$B$65,$A19,进销存台账!$A$6:$A$65,$E19)) -> 17850 | M19: =IF($A19="","",IF(COUNTIF($A$6:$A$65,$A19)>1,"编码重复",IF($B19="","缺名称",IF(COUNTIF(会计科目表!$B$6:$B$85,$G19)=0,"存货科目不存在",IF(AND($F19<>"原材料",COUNTIF(会计科目表!$B$6:$B$85,$H19)=0),"收入科目不存在","OK"))))) -> OK
A20: MY09 | B20: 木屑边角料 | D20: 吨 | E20: 木业 | F20: 产成品 | G20: 库存商品 | H20: 其他业务收入 | I20: 其他业务成本 | J20: 0.13 | K20: 副产品 | L20: =IF($A20="","",SUMIFS(进销存台账!$U$6:$U$65,进销存台账!$B$6:$B$65,$A20,进销存台账!$A$6:$A$65,$E20)) -> 0 | M20: =IF($A20="","",IF(COUNTIF($A$6:$A$65,$A20)>1,"编码重复",IF($B20="","缺名称",IF(COUNTIF(会计科目表!$B$6:$B$85,$G20)=0,"存货科目不存在",IF(AND($F20<>"原材料",COUNTIF(会计科目表!$B$6:$B$85,$H20)=0),"收入科目不存在","OK"))))) -> OK
A21: KJ01 | B21: 艾草精油原液 | C21: 10kg/桶 | D21: 公斤 | E21: 科技 | F21: 半成品 | G21: 库存商品 | H21: 主营业务收入 | I21: 主营业务成本 | J21: 0.13 | K21: 提取后待灌装 | L21: =IF($A21="","",SUMIFS(进销存台账!$U$6:$U$65,进销存台账!$B$6:$B$65,$A21,进销存台账!$A$6:$A$65,$E21)) -> 79941.44 | M21: =IF($A21="","",IF(COUNTIF($A$6:$A$65,$A21)>1,"编码重复",IF($B21="","缺名称",IF(COUNTIF(会计科目表!$B$6:$B$85,$G21)=0,"存货科目不存在",IF(AND($F21<>"原材料",COUNTIF(会计科目表!$B$6:$B$85,$H21)=0),"收入科目不存在","OK"))))) -> OK
A22: KJ02 | B22: 艾草精油10ml | C22: 10ml/瓶 | D22: 瓶 | E22: 科技 | F22: 产成品 | G22: 库存商品 | H22: 主营业务收入 | I22: 主营业务成本 | J22: 0.13 | L22: =IF($A22="","",SUMIFS(进销存台账!$U$6:$U$65,进销存台账!$B$6:$B$65,$A22,进销存台账!$A$6:$A$65,$E22)) -> 13113.51 | M22: =IF($A22="","",IF(COUNTIF($A$6:$A$65,$A22)>1,"编码重复",IF($B22="","缺名称",IF(COUNTIF(会计科目表!$B$6:$B$85,$G22)=0,"存货科目不存在",IF(AND($F22<>"原材料",COUNTIF(会计科目表!$B$6:$B$85,$H22)=0),"收入科目不存在","OK"))))) -> OK
A23: KJ03 | B23: 艾草精油30ml | C23: 30ml/瓶 | D23: 瓶 | E23: 科技 | F23: 产成品 | G23: 库存商品 | H23: 主营业务收入 | I23: 主营业务成本 | J23: 0.13 | L23: =IF($A23="","",SUMIFS(进销存台账!$U$6:$U$65,进销存台账!$B$6:$B$65,$A23,进销存台账!$A$6:$A$65,$E23)) -> 0 | M23: =IF($A23="","",IF(COUNTIF($A$6:$A$65,$A23)>1,"编码重复",IF($B23="","缺名称",IF(COUNTIF(会计科目表!$B$6:$B$85,$G23)=0,"存货科目不存在",IF(AND($F23<>"原材料",COUNTIF(会计科目表!$B$6:$B$85,$H23)=0),"收入科目不存在","OK"))))) -> OK
A24: KJ04 | B24: 艾草纯露 | C24: 100ml/瓶 | D24: 瓶 | E24: 科技 | F24: 产成品 | G24: 库存商品 | H24: 主营业务收入 | I24: 主营业务成本 | J24: 0.13 | K24: 蒸馏水相 | L24: =IF($A24="","",SUMIFS(进销存台账!$U$6:$U$65,进销存台账!$B$6:$B$65,$A24,进销存台账!$A$6:$A$65,$E24)) -> 2475.52 | M24: =IF($A24="","",IF(COUNTIF($A$6:$A$65,$A24)>1,"编码重复",IF($B24="","缺名称",IF(COUNTIF(会计科目表!$B$6:$B$85,$G24)=0,"存货科目不存在",IF(AND($F24<>"原材料",COUNTIF(会计科目表!$B$6:$B$85,$H24)=0),"收入科目不存在","OK"))))) -> OK
A25: KJ05 | B25: 艾草精油皂 | C25: 100g/块 | D25: 块 | E25: 科技 | F25: 产成品 | G25: 库存商品 | H25: 主营业务收入 | I25: 主营业务成本 | J25: 0.13 | L25: =IF($A25="","",SUMIFS(进销存台账!$U$6:$U$65,进销存台账!$B$6:$B$65,$A25,进销存台账!$A$6:$A$65,$E25)) -> 2362.97 | M25: =IF($A25="","",IF(COUNTIF($A$6:$A$65,$A25)>1,"编码重复",IF($B25="","缺名称",IF(COUNTIF(会计科目表!$B$6:$B$85,$G25)=0,"存货科目不存在",IF(AND($F25<>"原材料",COUNTIF(会计科目表!$B$6:$B$85,$H25)=0),"收入科目不存在","OK"))))) -> OK
A26: KJ06 | B26: 艾草精油膏 | C26: 20g/盒 | D26: 盒 | E26: 科技 | F26: 产成品 | G26: 库存商品 | H26: 主营业务收入 | I26: 主营业务成本 | J26: 0.13 | L26: =IF($A26="","",SUMIFS(进销存台账!$U$6:$U$65,进销存台账!$B$6:$B$65,$A26,进销存台账!$A$6:$A$65,$E26)) -> 0 | M26: =IF($A26="","",IF(COUNTIF($A$6:$A$65,$A26)>1,"编码重复",IF($B26="","缺名称",IF(COUNTIF(会计科目表!$B$6:$B$85,$G26)=0,"存货科目不存在",IF(AND($F26<>"原材料",COUNTIF(会计科目表!$B$6:$B$85,$H26)=0),"收入科目不存在","OK"))))) -> OK
A27: KJ07 | B27: 艾草香薰 | D27: 盒 | E27: 科技 | F27: 产成品 | G27: 库存商品 | H27: 主营业务收入 | I27: 主营业务成本 | J27: 0.13 | L27: =IF($A27="","",SUMIFS(进销存台账!$U$6:$U$65,进销存台账!$B$6:$B$65,$A27,进销存台账!$A$6:$A$65,$E27)) -> 0 | M27: =IF($A27="","",IF(COUNTIF($A$6:$A$65,$A27)>1,"编码重复",IF($B27="","缺名称",IF(COUNTIF(会计科目表!$B$6:$B$85,$G27)=0,"存货科目不存在",IF(AND($F27<>"原材料",COUNTIF(会计科目表!$B$6:$B$85,$H27)=0),"收入科目不存在","OK"))))) -> OK
A28: KJ08 | B28: 干艾草 | C28: 含水率≤12% | D28: 公斤 | E28: 科技 | F28: 原材料 | G28: 原材料 | J28: 0.09 | K28: 向农业基地公司收购 | L28: =IF($A28="","",SUMIFS(进销存台账!$U$6:$U$65,进销存台账!$B$6:$B$65,$A28,进销存台账!$A$6:$A$65,$E28)) -> 2690.91 | M28: =IF($A28="","",IF(COUNTIF($A$6:$A$65,$A28)>1,"编码重复",IF($B28="","缺名称",IF(COUNTIF(会计科目表!$B$6:$B$85,$G28)=0,"存货科目不存在",IF(AND($F28<>"原材料",COUNTIF(会计科目表!$B$6:$B$85,$H28)=0),"收入科目不存在","OK"))))) -> OK
A29: KJ09 | B29: 包装瓶 | C29: 10ml 玻璃瓶 | D29: 个 | E29: 科技 | F29: 原材料 | G29: 原材料 | J29: 0.13 | L29: =IF($A29="","",SUMIFS(进销存台账!$U$6:$U$65,进销存台账!$B$6:$B$65,$A29,进销存台账!$A$6:$A$65,$E29)) -> 18742.86 | M29: =IF($A29="","",IF(COUNTIF($A$6:$A$65,$A29)>1,"编码重复",IF($B29="","缺名称",IF(COUNTIF(会计科目表!$B$6:$B$85,$G29)=0,"存货科目不存在",IF(AND($F29<>"原材料",COUNTIF(会计科目表!$B$6:$B$85,$H29)=0),"收入科目不存在","OK"))))) -> OK
A30: KJ10 | B30: 纸盒 | D30: 个 | E30: 科技 | F30: 原材料 | G30: 原材料 | J30: 0.13 | L30: =IF($A30="","",SUMIFS(进销存台账!$U$6:$U$65,进销存台账!$B$6:$B$65,$A30,进销存台账!$A$6:$A$65,$E30)) -> 4696.36 | M30: =IF($A30="","",IF(COUNTIF($A$6:$A$65,$A30)>1,"编码重复",IF($B30="","缺名称",IF(COUNTIF(会计科目表!$B$6:$B$85,$G30)=0,"存货科目不存在",IF(AND($F30<>"原材料",COUNTIF(会计科目表!$B$6:$B$85,$H30)=0),"收入科目不存在","OK"))))) -> OK
L31: =IF($A31="","",SUMIFS(进销存台账!$U$6:$U$65,进销存台账!$B$6:$B$65,$A31,进销存台账!$A$6:$A$65,$E31)) | M31: =IF($A31="","",IF(COUNTIF($A$6:$A$65,$A31)>1,"编码重复",IF($B31="","缺名称",IF(COUNTIF(会计科目表!$B$6:$B$85,$G31)=0,"存货科目不存在",IF(AND($F31<>"原材料",COUNTIF(会计科目表!$B$6:$B$85,$H31)=0),"收入科目不存在","OK")))))
L32: =IF($A32="","",SUMIFS(进销存台账!$U$6:$U$65,进销存台账!$B$6:$B$65,$A32,进销存台账!$A$6:$A$65,$E32)) | M32: =IF($A32="","",IF(COUNTIF($A$6:$A$65,$A32)>1,"编码重复",IF($B32="","缺名称",IF(COUNTIF(会计科目表!$B$6:$B$85,$G32)=0,"存货科目不存在",IF(AND($F32<>"原材料",COUNTIF(会计科目表!$B$6:$B$85,$H32)=0),"收入科目不存在","OK")))))
L33: =IF($A33="","",SUMIFS(进销存台账!$U$6:$U$65,进销存台账!$B$6:$B$65,$A33,进销存台账!$A$6:$A$65,$E33)) | M33: =IF($A33="","",IF(COUNTIF($A$6:$A$65,$A33)>1,"编码重复",IF($B33="","缺名称",IF(COUNTIF(会计科目表!$B$6:$B$85,$G33)=0,"存货科目不存在",IF(AND($F33<>"原材料",COUNTIF(会计科目表!$B$6:$B$85,$H33)=0),"收入科目不存在","OK")))))
L34: =IF($A34="","",SUMIFS(进销存台账!$U$6:$U$65,进销存台账!$B$6:$B$65,$A34,进销存台账!$A$6:$A$65,$E34)) | M34: =IF($A34="","",IF(COUNTIF($A$6:$A$65,$A34)>1,"编码重复",IF($B34="","缺名称",IF(COUNTIF(会计科目表!$B$6:$B$85,$G34)=0,"存货科目不存在",IF(AND($F34<>"原材料",COUNTIF(会计科目表!$B$6:$B$85,$H34)=0),"收入科目不存在","OK")))))
L35: =IF($A35="","",SUMIFS(进销存台账!$U$6:$U$65,进销存台账!$B$6:$B$65,$A35,进销存台账!$A$6:$A$65,$E35)) | M35: =IF($A35="","",IF(COUNTIF($A$6:$A$65,$A35)>1,"编码重复",IF($B35="","缺名称",IF(COUNTIF(会计科目表!$B$6:$B$85,$G35)=0,"存货科目不存在",IF(AND($F35<>"原材料",COUNTIF(会计科目表!$B$6:$B$85,$H35)=0),"收入科目不存在","OK")))))
L36: =IF($A36="","",SUMIFS(进销存台账!$U$6:$U$65,进销存台账!$B$6:$B$65,$A36,进销存台账!$A$6:$A$65,$E36)) | M36: =IF($A36="","",IF(COUNTIF($A$6:$A$65,$A36)>1,"编码重复",IF($B36="","缺名称",IF(COUNTIF(会计科目表!$B$6:$B$85,$G36)=0,"存货科目不存在",IF(AND($F36<>"原材料",COUNTIF(会计科目表!$B$6:$B$85,$H36)=0),"收入科目不存在","OK")))))
L37: =IF($A37="","",SUMIFS(进销存台账!$U$6:$U$65,进销存台账!$B$6:$B$65,$A37,进销存台账!$A$6:$A$65,$E37)) | M37: =IF($A37="","",IF(COUNTIF($A$6:$A$65,$A37)>1,"编码重复",IF($B37="","缺名称",IF(COUNTIF(会计科目表!$B$6:$B$85,$G37)=0,"存货科目不存在",IF(AND($F37<>"原材料",COUNTIF(会计科目表!$B$6:$B$85,$H37)=0),"收入科目不存在","OK")))))
L38: =IF($A38="","",SUMIFS(进销存台账!$U$6:$U$65,进销存台账!$B$6:$B$65,$A38,进销存台账!$A$6:$A$65,$E38)) | M38: =IF($A38="","",IF(COUNTIF($A$6:$A$65,$A38)>1,"编码重复",IF($B38="","缺名称",IF(COUNTIF(会计科目表!$B$6:$B$85,$G38)=0,"存货科目不存在",IF(AND($F38<>"原材料",COUNTIF(会计科目表!$B$6:$B$85,$H38)=0),"收入科目不存在","OK")))))
L39: =IF($A39="","",SUMIFS(进销存台账!$U$6:$U$65,进销存台账!$B$6:$B$65,$A39,进销存台账!$A$6:$A$65,$E39)) | M39: =IF($A39="","",IF(COUNTIF($A$6:$A$65,$A39)>1,"编码重复",IF($B39="","缺名称",IF(COUNTIF(会计科目表!$B$6:$B$85,$G39)=0,"存货科目不存在",IF(AND($F39<>"原材料",COUNTIF(会计科目表!$B$6:$B$85,$H39)=0),"收入科目不存在","OK")))))
L40: =IF($A40="","",SUMIFS(进销存台账!$U$6:$U$65,进销存台账!$B$6:$B$65,$A40,进销存台账!$A$6:$A$65,$E40)) | M40: =IF($A40="","",IF(COUNTIF($A$6:$A$65,$A40)>1,"编码重复",IF($B40="","缺名称",IF(COUNTIF(会计科目表!$B$6:$B$85,$G40)=0,"存货科目不存在",IF(AND($F40<>"原材料",COUNTIF(会计科目表!$B$6:$B$85,$H40)=0),"收入科目不存在","OK")))))
L41: =IF($A41="","",SUMIFS(进销存台账!$U$6:$U$65,进销存台账!$B$6:$B$65,$A41,进销存台账!$A$6:$A$65,$E41)) | M41: =IF($A41="","",IF(COUNTIF($A$6:$A$65,$A41)>1,"编码重复",IF($B41="","缺名称",IF(COUNTIF(会计科目表!$B$6:$B$85,$G41)=0,"存货科目不存在",IF(AND($F41<>"原材料",COUNTIF(会计科目表!$B$6:$B$85,$H41)=0),"收入科目不存在","OK")))))
L42: =IF($A42="","",SUMIFS(进销存台账!$U$6:$U$65,进销存台账!$B$6:$B$65,$A42,进销存台账!$A$6:$A$65,$E42)) | M42: =IF($A42="","",IF(COUNTIF($A$6:$A$65,$A42)>1,"编码重复",IF($B42="","缺名称",IF(COUNTIF(会计科目表!$B$6:$B$85,$G42)=0,"存货科目不存在",IF(AND($F42<>"原材料",COUNTIF(会计科目表!$B$6:$B$85,$H42)=0),"收入科目不存在","OK")))))
...

Sheet 往来单位
A1: 往来单位
A2: 客户、供应商、以及三家公司互相之间。「是否内部」标「是」的，购销流水会自动认成内部交易，合并报表按它抵销。
A5: 单位名称 | B5: 类型 | C5: 说明 | D5: 是否内部 | E5: 本年应收发生 | F5: 本年应付发生 | G5: 期末应收余额 | H5: 期末应付余额 | I5: 校验
A6: 农业基地公司 | B6: 内部关联 | C6: 本账套三家之一 | D6: 是 | E6: =IF($A6="","",SUMIFS(记账分录!$I$6:$I$5505,记账分录!$H$6:$H$5505,"应收账款",记账分录!$K$6:$K$5505,$A6)) -> 0 | F6: =IF($A6="","",SUMIFS(记账分录!$J$6:$J$5505,记账分录!$H$6:$H$5505,"应付账款",记账分录!$K$6:$K$5505,$A6)) -> 245000 | G6: =IF($A6="","",$E6-SUMIFS(记账分录!$J$6:$J$5505,记账分录!$H$6:$H$5505,"应收账款",记账分录!$K$6:$K$5505,$A6)) -> 0 | H6: =IF($A6="","",$F6-SUMIFS(记账分录!$I$6:$I$5505,记账分录!$H$6:$H$5505,"应付账款",记账分录!$K$6:$K$5505,$A6)) -> 55000 | I6: =IF($A6="","",IF(COUNTIF($A$6:$A$85,$A6)>1,"名称重复","OK")) -> OK
A7: 木业公司 | B7: 内部关联 | C7: 本账套三家之一 | D7: 是 | E7: =IF($A7="","",SUMIFS(记账分录!$I$6:$I$5505,记账分录!$H$6:$H$5505,"应收账款",记账分录!$K$6:$K$5505,$A7)) -> 189000 | F7: =IF($A7="","",SUMIFS(记账分录!$J$6:$J$5505,记账分录!$H$6:$H$5505,"应付账款",记账分录!$K$6:$K$5505,$A7)) -> 0 | G7: =IF($A7="","",$E7-SUMIFS(记账分录!$J$6:$J$5505,记账分录!$H$6:$H$5505,"应收账款",记账分录!$K$6:$K$5505,$A7)) -> 39000 | H7: =IF($A7="","",$F7-SUMIFS(记账分录!$I$6:$I$5505,记账分录!$H$6:$H$5505,"应付账款",记账分录!$K$6:$K$5505,$A7)) -> 0 | I7: =IF($A7="","",IF(COUNTIF($A$6:$A$85,$A7)>1,"名称重复","OK")) -> OK
A8: 科技公司 | B8: 内部关联 | C8: 本账套三家之一 | D8: 是 | E8: =IF($A8="","",SUMIFS(记账分录!$I$6:$I$5505,记账分录!$H$6:$H$5505,"应收账款",记账分录!$K$6:$K$5505,$A8)) -> 56000 | F8: =IF($A8="","",SUMIFS(记账分录!$J$6:$J$5505,记账分录!$H$6:$H$5505,"应付账款",记账分录!$K$6:$K$5505,$A8)) -> 0 | G8: =IF($A8="","",$E8-SUMIFS(记账分录!$J$6:$J$5505,记账分录!$H$6:$H$5505,"应收账款",记账分录!$K$6:$K$5505,$A8)) -> 16000 | H8: =IF($A8="","",$F8-SUMIFS(记账分录!$I$6:$I$5505,记账分录!$H$6:$H$5505,"应付账款",记账分录!$K$6:$K$5505,$A8)) -> 0 | I8: =IF($A8="","",IF(COUNTIF($A$6:$A$85,$A8)>1,"名称重复","OK")) -> OK
A9: 鑫隆建材 | B9: 客户 | C9: 木业 · 板材 | D9: 否 | E9: =IF($A9="","",SUMIFS(记账分录!$I$6:$I$5505,记账分录!$H$6:$H$5505,"应收账款",记账分录!$K$6:$K$5505,$A9)) -> 363000 | F9: =IF($A9="","",SUMIFS(记账分录!$J$6:$J$5505,记账分录!$H$6:$H$5505,"应付账款",记账分录!$K$6:$K$5505,$A9)) -> 0 | G9: =IF($A9="","",$E9-SUMIFS(记账分录!$J$6:$J$5505,记账分录!$H$6:$H$5505,"应收账款",记账分录!$K$6:$K$5505,$A9)) -> 63000 | H9: =IF($A9="","",$F9-SUMIFS(记账分录!$I$6:$I$5505,记账分录!$H$6:$H$5505,"应付账款",记账分录!$K$6:$K$5505,$A9)) -> 0 | I9: =IF($A9="","",IF(COUNTIF($A$6:$A$85,$A9)>1,"名称重复","OK")) -> OK
A10: 中建八局项目部 | B10: 客户 | C10: 木业 · 模板 | D10: 否 | E10: =IF($A10="","",SUMIFS(记账分录!$I$6:$I$5505,记账分录!$H$6:$H$5505,"应收账款",记账分录!$K$6:$K$5505,$A10)) -> 105000 | F10: =IF($A10="","",SUMIFS(记账分录!$J$6:$J$5505,记账分录!$H$6:$H$5505,"应付账款",记账分录!$K$6:$K$5505,$A10)) -> 0 | G10: =IF($A10="","",$E10-SUMIFS(记账分录!$J$6:$J$5505,记账分录!$H$6:$H$5505,"应收账款",记账分录!$K$6:$K$5505,$A10)) -> 105000 | H10: =IF($A10="","",$F10-SUMIFS(记账分录!$I$6:$I$5505,记账分录!$H$6:$H$5505,"应付账款",记账分录!$K$6:$K$5505,$A10)) -> 0 | I10: =IF($A10="","",IF(COUNTIF($A$6:$A$85,$A10)>1,"名称重复","OK")) -> OK
A11: 顺达包装 | B11: 客户 | C11: 木业 · 包装箱板材 | D11: 否 | E11: =IF($A11="","",SUMIFS(记账分录!$I$6:$I$5505,记账分录!$H$6:$H$5505,"应收账款",记账分录!$K$6:$K$5505,$A11)) -> 92250 | F11: =IF($A11="","",SUMIFS(记账分录!$J$6:$J$5505,记账分录!$H$6:$H$5505,"应付账款",记账分录!$K$6:$K$5505,$A11)) -> 0 | G11: =IF($A11="","",$E11-SUMIFS(记账分录!$J$6:$J$5505,记账分录!$H$6:$H$5505,"应收账款",记账分录!$K$6:$K$5505,$A11)) -> 22250 | H11: =IF($A11="","",$F11-SUMIFS(记账分录!$I$6:$I$5505,记账分录!$H$6:$H$5505,"应付账款",记账分录!$K$6:$K$5505,$A11)) -> 0 | I11: =IF($A11="","",IF(COUNTIF($A$6:$A$85,$A11)>1,"名称重复","OK")) -> OK
A12: 恒诚建筑 | B12: 客户 | C12: 木业 · 建筑木方料 | D12: 否 | E12: =IF($A12="","",SUMIFS(记账分录!$I$6:$I$5505,记账分录!$H$6:$H$5505,"应收账款",记账分录!$K$6:$K$5505,$A12)) -> 21750 | F12: =IF($A12="","",SUMIFS(记账分录!$J$6:$J$5505,记账分录!$H$6:$H$5505,"应付账款",记账分录!$K$6:$K$5505,$A12)) -> 0 | G12: =IF($A12="","",$E12-SUMIFS(记账分录!$J$6:$J$5505,记账分录!$H$6:$H$5505,"应收账款",记账分录!$K$6:$K$5505,$A12)) -> 21750 | H12: =IF($A12="","",$F12-SUMIFS(记账分录!$I$6:$I$5505,记账分录!$H$6:$H$5505,"应付账款",记账分录!$K$6:$K$5505,$A12)) -> 0 | I12: =IF($A12="","",IF(COUNTIF($A$6:$A$85,$A12)>1,"名称重复","OK")) -> OK
A13: 恒信木材行 | B13: 客户 | C13: 农业 · 原木 | D13: 否 | E13: =IF($A13="","",SUMIFS(记账分录!$I$6:$I$5505,记账分录!$H$6:$H$5505,"应收账款",记账分录!$K$6:$K$5505,$A13)) -> 66000 | F13: =IF($A13="","",SUMIFS(记账分录!$J$6:$J$5505,记账分录!$H$6:$H$5505,"应付账款",记账分录!$K$6:$K$5505,$A13)) -> 0 | G13: =IF($A13="","",$E13-SUMIFS(记账分录!$J$6:$J$5505,记账分录!$H$6:$H$5505,"应收账款",记账分录!$K$6:$K$5505,$A13)) -> 0 | H13: =IF($A13="","",$F13-SUMIFS(记账分录!$I$6:$I$5505,记账分录!$H$6:$H$5505,"应付账款",记账分录!$K$6:$K$5505,$A13)) -> 0 | I13: =IF($A13="","",IF(COUNTIF($A$6:$A$85,$A13)>1,"名称重复","OK")) -> OK
A14: 安康艾制品厂 | B14: 客户 | C14: 农业 · 干艾草 | D14: 否 | E14: =IF($A14="","",SUMIFS(记账分录!$I$6:$I$5505,记账分录!$H$6:$H$5505,"应收账款",记账分录!$K$6:$K$5505,$A14)) -> 18000 | F14: =IF($A14="","",SUMIFS(记账分录!$J$6:$J$5505,记账分录!$H$6:$H$5505,"应付账款",记账分录!$K$6:$K$5505,$A14)) -> 0 | G14: =IF($A14="","",$E14-SUMIFS(记账分录!$J$6:$J$5505,记账分录!$H$6:$H$5505,"应收账款",记账分录!$K$6:$K$5505,$A14)) -> 18000 | H14: =IF($A14="","",$F14-SUMIFS(记账分录!$I$6:$I$5505,记账分录!$H$6:$H$5505,"应付账款",记账分录!$K$6:$K$5505,$A14)) -> 0 | I14: =IF($A14="","",IF(COUNTIF($A$6:$A$85,$A14)>1,"名称重复","OK")) -> OK
A15: 康养电商 | B15: 客户 | C15: 科技 · 精油 | D15: 否 | E15: =IF($A15="","",SUMIFS(记账分录!$I$6:$I$5505,记账分录!$H$6:$H$5505,"应收账款",记账分录!$K$6:$K$5505,$A15)) -> 324750 | F15: =IF($A15="","",SUMIFS(记账分录!$J$6:$J$5505,记账分录!$H$6:$H$5505,"应付账款",记账分录!$K$6:$K$5505,$A15)) -> 0 | G15: =IF($A15="","",$E15-SUMIFS(记账分录!$J$6:$J$5505,记账分录!$H$6:$H$5505,"应收账款",记账分录!$K$6:$K$5505,$A15)) -> 84750 | H15: =IF($A15="","",$F15-SUMIFS(记账分录!$I$6:$I$5505,记账分录!$H$6:$H$5505,"应付账款",记账分录!$K$6:$K$5505,$A15)) -> 0 | I15: =IF($A15="","",IF(COUNTIF($A$6:$A$85,$A15)>1,"名称重复","OK")) -> OK
A16: 美悦日化 | B16: 客户 | C16: 科技 · 纯露 | D16: 否 | E16: =IF($A16="","",SUMIFS(记账分录!$I$6:$I$5505,记账分录!$H$6:$H$5505,"应收账款",记账分录!$K$6:$K$5505,$A16)) -> 120000 | F16: =IF($A16="","",SUMIFS(记账分录!$J$6:$J$5505,记账分录!$H$6:$H$5505,"应付账款",记账分录!$K$6:$K$5505,$A16)) -> 0 | G16: =IF($A16="","",$E16-SUMIFS(记账分录!$J$6:$J$5505,记账分录!$H$6:$H$5505,"应收账款",记账分录!$K$6:$K$5505,$A16)) -> 30000 | H16: =IF($A16="","",$F16-SUMIFS(记账分录!$I$6:$I$5505,记账分录!$H$6:$H$5505,"应付账款",记账分录!$K$6:$K$5505,$A16)) -> 0 | I16: =IF($A16="","",IF(COUNTIF($A$6:$A$85,$A16)>1,"名称重复","OK")) -> OK
A17: 张德富（农户） | B17: 供应商 | C17: 木业 · 向农户收购原木，开农产品收购发票 | D17: 否 | E17: =IF($A17="","",SUMIFS(记账分录!$I$6:$I$5505,记账分录!$H$6:$H$5505,"应收账款",记账分录!$K$6:$K$5505,$A17)) -> 0 | F17: =IF($A17="","",SUMIFS(记账分录!$J$6:$J$5505,记账分录!$H$6:$H$5505,"应付账款",记账分录!$K$6:$K$5505,$A17)) -> 58800 | G17: =IF($A17="","",$E17-SUMIFS(记账分录!$J$6:$J$5505,记账分录!$H$6:$H$5505,"应收账款",记账分录!$K$6:$K$5505,$A17)) -> 0 | H17: =IF($A17="","",$F17-SUMIFS(记账分录!$I$6:$I$5505,记账分录!$H$6:$H$5505,"应付账款",记账分录!$K$6:$K$5505,$A17)) -> 0 | I17: =IF($A17="","",IF(COUNTIF($A$6:$A$85,$A17)>1,"名称重复","OK")) -> OK
... A28: 农商银行 | B28: 其他 | C28: 借款开户行 | D28: 否 | E28: =IF($A28="","",SUMIFS(记账分录!$I$6:$I$5505,记账分录!$H$6:$H$5505,"应收账款",记账分录!$K$6:$K$5505,$A28)) -> 0 | F28: =IF($A28="","",SUMIFS(记账分录!$J$6:$J$5505,记账分录!$H$6:$H$5505,"应付账款",记账分录!$K$6:$K$5505,$A28)) -> 0 | G28: =IF($A28="","",$E28-SUMIFS(记账分录!$J$6:$J$5505,记账分录!$H$6:$H$5505,"应收账款",记账分录!$K$6:$K$5505,$A28)) -> 0 | H28: =IF($A28="","",$F28-SUMIFS(记账分录!$I$6:$I$5505,记账分录!$H$6:$H$5505,"应付账款",记账分录!$K$6:$K$5505,$A28)) -> 0 | I28: =IF($A28="","",IF(COUNTIF($A$6:$A$85,$A28)>1,"名称重复","OK")) -> OK
E29: =IF($A29="","",SUMIFS(记账分录!$I$6:$I$5505,记账分录!$H$6:$H$5505,"应收账款",记账分录!$K$6:$K$5505,$A29)) | F29: =IF($A29="","",SUMIFS(记账分录!$J$6:$J$5505,记账分录!$H$6:$H$5505,"应付账款",记账分录!$K$6:$K$5505,$A29)) | G29: =IF($A29="","",$E29-SUMIFS(记账分录!$J$6:$J$5505,记账分录!$H$6:$H$5505,"应收账款",记账分录!$K$6:$K$5505,$A29)) | H29: =IF($A29="","",$F29-SUMIFS(记账分录!$I$6:$I$5505,记账分录!$H$6:$H$5505,"应付账款",记账分录!$K$6:$K$5505,$A29)) | I29: =IF($A29="","",IF(COUNTIF($A$6:$A$85,$A29)>1,"名称重复","OK"))
E30: =IF($A30="","",SUMIFS(记账分录!$I$6:$I$5505,记账分录!$H$6:$H$5505,"应收账款",记账分录!$K$6:$K$5505,$A30)) | F30: =IF($A30="","",SUMIFS(记账分录!$J$6:$J$5505,记账分录!$H$6:$H$5505,"应付账款",记账分录!$K$6:$K$5505,$A30)) | G30: =IF($A30="","",$E30-SUMIFS(记账分录!$J$6:$J$5505,记账分录!$H$6:$H$5505,"应收账款",记账分录!$K$6:$K$5505,$A30)) | H30: =IF($A30="","",$F30-SUMIFS(记账分录!$I$6:$I$5505,记账分录!$H$6:$H$5505,"应付账款",记账分录!$K$6:$K$5505,$A30)) | I30: =IF($A30="","",IF(COUNTIF($A$6:$A$85,$A30)>1,"名称重复","OK"))
E31: =IF($A31="","",SUMIFS(记账分录!$I$6:$I$5505,记账分录!$H$6:$H$5505,"应收账款",记账分录!$K$6:$K$5505,$A31)) | F31: =IF($A31="","",SUMIFS(记账分录!$J$6:$J$5505,记账分录!$H$6:$H$5505,"应付账款",记账分录!$K$6:$K$5505,$A31)) | G31: =IF($A31="","",$E31-SUMIFS(记账分录!$J$6:$J$5505,记账分录!$H$6:$H$5505,"应收账款",记账分录!$K$6:$K$5505,$A31)) | H31: =IF($A31="","",$F31-SUMIFS(记账分录!$I$6:$I$5505,记账分录!$H$6:$H$5505,"应付账款",记账分录!$K$6:$K$5505,$A31)) | I31: =IF($A31="","",IF(COUNTIF($A$6:$A$85,$A31)>1,"名称重复","OK"))
E32: =IF($A32="","",SUMIFS(记账分录!$I$6:$I$5505,记账分录!$H$6:$H$5505,"应收账款",记账分录!$K$6:$K$5505,$A32)) | F32: =IF($A32="","",SUMIFS(记账分录!$J$6:$J$5505,记账分录!$H$6:$H$5505,"应付账款",记账分录!$K$6:$K$5505,$A32)) | G32: =IF($A32="","",$E32-SUMIFS(记账分录!$J$6:$J$5505,记账分录!$H$6:$H$5505,"应收账款",记账分录!$K$6:$K$5505,$A32)) | H32: =IF($A32="","",$F32-SUMIFS(记账分录!$I$6:$I$5505,记账分录!$H$6:$H$5505,"应付账款",记账分录!$K$6:$K$5505,$A32)) | I32: =IF($A32="","",IF(COUNTIF($A$6:$A$85,$A32)>1,"名称重复","OK"))
E33: =IF($A33="","",SUMIFS(记账分录!$I$6:$I$5505,记账分录!$H$6:$H$5505,"应收账款",记账分录!$K$6:$K$5505,$A33)) | F33: =IF($A33="","",SUMIFS(记账分录!$J$6:$J$5505,记账分录!$H$6:$H$5505,"应付账款",记账分录!$K$6:$K$5505,$A33)) | G33: =IF($A33="","",$E33-SUMIFS(记账分录!$J$6:$J$5505,记账分录!$H$6:$H$5505,"应收账款",记账分录!$K$6:$K$5505,$A33)) | H33: =IF($A33="","",$F33-SUMIFS(记账分录!$I$6:$I$5505,记账分录!$H$6:$H$5505,"应付账款",记账分录!$K$6:$K$5505,$A33)) | I33: =IF($A33="","",IF(COUNTIF($A$6:$A$85,$A33)>1,"名称重复","OK"))
E34: =IF($A34="","",SUMIFS(记账分录!$I$6:$I$5505,记账分录!$H$6:$H$5505,"应收账款",记账分录!$K$6:$K$5505,$A34)) | F34: =IF($A34="","",SUMIFS(记账分录!$J$6:$J$5505,记账分录!$H$6:$H$5505,"应付账款",记账分录!$K$6:$K$5505,$A34)) | G34: =IF($A34="","",$E34-SUMIFS(记账分录!$J$6:$J$5505,记账分录!$H$6:$H$5505,"应收账款",记账分录!$K$6:$K$5505,$A34)) | H34: =IF($A34="","",$F34-SUMIFS(记账分录!$I$6:$I$5505,记账分录!$H$6:$H$5505,"应付账款",记账分录!$K$6:$K$5505,$A34)) | I34: =IF($A34="","",IF(COUNTIF($A$6:$A$85,$A34)>1,"名称重复","OK"))
E35: =IF($A35="","",SUMIFS(记账分录!$I$6:$I$5505,记账分录!$H$6:$H$5505,"应收账款",记账分录!$K$6:$K$5505,$A35)) | F35: =IF($A35="","",SUMIFS(记账分录!$J$6:$J$5505,记账分录!$H$6:$H$5505,"应付账款",记账分录!$K$6:$K$5505,$A35)) | G35: =IF($A35="","",$E35-SUMIFS(记账分录!$J$6:$J$5505,记账分录!$H$6:$H$5505,"应收账款",记账分录!$K$6:$K$5505,$A35)) | H35: =IF($A35="","",$F35-SUMIFS(记账分录!$I$6:$I$5505,记账分录!$H$6:$H$5505,"应付账款",记账分录!$K$6:$K$5505,$A35)) | I35: =IF($A35="","",IF(COUNTIF($A$6:$A$85,$A35)>1,"名称重复","OK"))
E36: =IF($A36="","",SUMIFS(记账分录!$I$6:$I$5505,记账分录!$H$6:$H$5505,"应收账款",记账分录!$K$6:$K$5505,$A36)) | F36: =IF($A36="","",SUMIFS(记账分录!$J$6:$J$5505,记账分录!$H$6:$H$5505,"应付账款",记账分录!$K$6:$K$5505,$A36)) | G36: =IF($A36="","",$E36-SUMIFS(记账分录!$J$6:$J$5505,记账分录!$H$6:$H$5505,"应收账款",记账分录!$K$6:$K$5505,$A36)) | H36: =IF($A36="","",$F36-SUMIFS(记账分录!$I$6:$I$5505,记账分录!$H$6:$H$5505,"应付账款",记账分录!$K$6:$K$5505,$A36)) | I36: =IF($A36="","",IF(COUNTIF($A$6:$A$85,$A36)>1,"名称重复","OK"))
E37: =IF($A37="","",SUMIFS(记账分录!$I$6:$I$5505,记账分录!$H$6:$H$5505,"应收账款",记账分录!$K$6:$K$5505,$A37)) | F37: =IF($A37="","",SUMIFS(记账分录!$J$6:$J$5505,记账分录!$H$6:$H$5505,"应付账款",记账分录!$K$6:$K$5505,$A37)) | G37: =IF($A37="","",$E37-SUMIFS(记账分录!$J$6:$J$5505,记账分录!$H$6:$H$5505,"应收账款",记账分录!$K$6:$K$5505,$A37)) | H37: =IF($A37="","",$F37-SUMIFS(记账分录!$I$6:$I$5505,记账分录!$H$6:$H$5505,"应付账款",记账分录!$K$6:$K$5505,$A37)) | I37: =IF($A37="","",IF(COUNTIF($A$6:$A$85,$A37)>1,"名称重复","OK"))
E38: =IF($A38="","",SUMIFS(记账分录!$I$6:$I$5505,记账分录!$H$6:$H$5505,"应收账款",记账分录!$K$6:$K$5505,$A38)) | F38: =IF($A38="","",SUMIFS(记账分录!$J$6:$J$5505,记账分录!$H$6:$H$5505,"应付账款",记账分录!$K$6:$K$5505,$A38)) | G38: =IF($A38="","",$E38-SUMIFS(记账分录!$J$6:$J$5505,记账分录!$H$6:$H$5505,"应收账款",记账分录!$K$6:$K$5505,$A38)) | H38: =IF($A38="","",$F38-SUMIFS(记账分录!$I$6:$I$5505,记账分录!$H$6:$H$5505,"应付账款",记账分录!$K$6:$K$5505,$A38)) | I38: =IF($A38="","",IF(COUNTIF($A$6:$A$85,$A38)>1,"名称重复","OK"))
E39: =IF($A39="","",SUMIFS(记账分录!$I$6:$I$5505,记账分录!$H$6:$H$5505,"应收账款",记账分录!$K$6:$K$5505,$A39)) | F39: =IF($A39="","",SUMIFS(记账分录!$J$6:$J$5505,记账分录!$H$6:$H$5505,"应付账款",记账分录!$K$6:$K$5505,$A39)) | G39: =IF($A39="","",$E39-SUMIFS(记账分录!$J$6:$J$5505,记账分录!$H$6:$H$5505,"应收账款",记账分录!$K$6:$K$5505,$A39)) | H39: =IF($A39="","",$F39-SUMIFS(记账分录!$I$6:$I$5505,记账分录!$H$6:$H$5505,"应付账款",记账分录!$K$6:$K$5505,$A39)) | I39: =IF($A39="","",IF(COUNTIF($A$6:$A$85,$A39)>1,"名称重复","OK"))
E40: =IF($A40="","",SUMIFS(记账分录!$I$6:$I$5505,记账分录!$H$6:$H$5505,"应收账款",记账分录!$K$6:$K$5505,$A40)) | F40: =IF($A40="","",SUMIFS(记账分录!$J$6:$J$5505,记账分录!$H$6:$H$5505,"应付账款",记账分录!$K$6:$K$5505,$A40)) | G40: =IF($A40="","",$E40-SUMIFS(记账分录!$J$6:$J$5505,记账分录!$H$6:$H$5505,"应收账款",记账分录!$K$6:$K$5505,$A40)) | H40: =IF($A40="","",$F40-SUMIFS(记账分录!$I$6:$I$5505,记账分录!$H$6:$H$5505,"应付账款",记账分录!$K$6:$K$5505,$A40)) | I40: =IF($A40="","",IF(COUNTIF($A$6:$A$85,$A40)>1,"名称重复","OK"))
... E85: =IF($A85="","",SUMIFS(记账分录!$I$6:$I$5505,记账分录!$H$6:$H$5505,"应收账款",记账分录!$K$6:$K$5505,$A85)) | F85: =IF($A85="","",SUMIFS(记账分录!$J$6:$J$5505,记账分录!$H$6:$H$5505,"应付账款",记账分录!$K$6:$K$5505,$A85)) | G85: =IF($A85="","",$E85-SUMIFS(记账分录!$J$6:$J$5505,记账分录!$H$6:$H$5505,"应收账款",记账分录!$K$6:$K$5505,$A85)) | H85: =IF($A85="","",$F85-SUMIFS(记账分录!$I$6:$I$5505,记账分录!$H$6:$H$5505,"应付账款",记账分录!$K$6:$K$5505,$A85)) | I85: =IF($A85="","",IF(COUNTIF($A$6:$A$85,$A85)>1,"名称重复","OK"))

Sheet 资金账户
A1: 资金账户
A2: 几家公司共用几个账号，就按实际开的户登在这里。「对应科目」决定这个账户在账上走库存现金还是银行存款；共用账户照样在【资金流水】里按公司分别记账，账户余额是账户的，科目余额是各公司自己的，两边在下面对账。
A5: 账户编码 | B5: 账户名称 | C5: 开户行 / 说明 | D5: 账号 | E5: 账户类型 | F5: 对应科目 | G5: 使用公司 | H5: 期初余额 | I5: 本期收入 | J5: 本期支出 | K5: 期末余额 | L5: 校验
A6: X01 | B6: 现金-总部 | C6: 出纳保管的备用金，三家共用一个钱箱 | D6: — | E6: 现金 | F6: 库存现金 | G6: 三家共用 | H6: 10000 | I6: =IF($B6="","",SUMIFS(资金流水!$I$6:$I$605,资金流水!$D$6:$D$605,$B6)) -> 0 | J6: =IF($B6="","",SUMIFS(资金流水!$J$6:$J$605,资金流水!$D$6:$D$605,$B6)) -> 2660 | K6: =IF($B6="","",ROUND(N($H6)+$I6-$J6,2)) -> 7340 | L6: =IF($B6="","",IF(COUNTIF($B$6:$B$25,$B6)>1,"账户名称重复",IF(ISNA(MATCH($F6,会计科目表!$B$6:$B$85,0)),"对应科目不存在",IF($K6<0,"✗ 期末余额为负","OK")))) -> OK
A7: Y01 | B7: 农商银行-基本户 | C7: 农业基地公司基本户 | D7: 62×××××××××1001 | E7: 银行 | F7: 银行存款 | G7: 农业 | H7: 180000 | I7: =IF($B7="","",SUMIFS(资金流水!$I$6:$I$605,资金流水!$D$6:$D$605,$B7)) -> 256000 | J7: =IF($B7="","",SUMIFS(资金流水!$J$6:$J$605,资金流水!$D$6:$D$605,$B7)) -> 120000 | K7: =IF($B7="","",ROUND(N($H7)+$I7-$J7,2)) -> 316000 | L7: =IF($B7="","",IF(COUNTIF($B$6:$B$25,$B7)>1,"账户名称重复",IF(ISNA(MATCH($F7,会计科目表!$B$6:$B$85,0)),"对应科目不存在",IF($K7<0,"✗ 期末余额为负","OK")))) -> OK
A8: Y02 | B8: 工商银行-基本户 | C8: 木业公司基本户 | D8: 62×××××××××2002 | E8: 银行 | F8: 银行存款 | G8: 木业 | H8: 260000 | I8: =IF($B8="","",SUMIFS(资金流水!$I$6:$I$605,资金流水!$D$6:$D$605,$B8)) -> 220000 | J8: =IF($B8="","",SUMIFS(资金流水!$J$6:$J$605,资金流水!$D$6:$D$605,$B8)) -> 311760 | K8: =IF($B8="","",ROUND(N($H8)+$I8-$J8,2)) -> 168240 | L8: =IF($B8="","",IF(COUNTIF($B$6:$B$25,$B8)>1,"账户名称重复",IF(ISNA(MATCH($F8,会计科目表!$B$6:$B$85,0)),"对应科目不存在",IF($K8<0,"✗ 期末余额为负","OK")))) -> OK
A9: Y03 | B9: 建设银行-基本户 | C9: 科技公司基本户 | D9: 62×××××××××3003 | E9: 银行 | F9: 银行存款 | G9: 科技 | H9: 320000 | I9: =IF($B9="","",SUMIFS(资金流水!$I$6:$I$605,资金流水!$D$6:$D$605,$B9)) -> 190000 | J9: =IF($B9="","",SUMIFS(资金流水!$J$6:$J$605,资金流水!$D$6:$D$605,$B9)) -> 162340 | K9: =IF($B9="","",ROUND(N($H9)+$I9-$J9,2)) -> 347660 | L9: =IF($B9="","",IF(COUNTIF($B$6:$B$25,$B9)>1,"账户名称重复",IF(ISNA(MATCH($F9,会计科目表!$B$6:$B$85,0)),"对应科目不存在",IF($K9<0,"✗ 期末余额为负","OK")))) -> OK
A10: Y04 | B10: 农商银行-共用户 | C10: 木业、科技共用的收款户，按公司分别记账 | D10: 62×××××××××4004 | E10: 银行 | F10: 银行存款 | G10: 木业 / 科技 | H10: 0 | I10: =IF($B10="","",SUMIFS(资金流水!$I$6:$I$605,资金流水!$D$6:$D$605,$B10)) -> 540000 | J10: =IF($B10="","",SUMIFS(资金流水!$J$6:$J$605,资金流水!$D$6:$D$605,$B10)) -> 105000 | K10: =IF($B10="","",ROUND(N($H10)+$I10-$J10,2)) -> 435000 | L10: =IF($B10="","",IF(COUNTIF($B$6:$B$25,$B10)>1,"账户名称重复",IF(ISNA(MATCH($F10,会计科目表!$B$6:$B$85,0)),"对应科目不存在",IF($K10<0,"✗ 期末余额为负","OK")))) -> OK
I11: =IF($B11="","",SUMIFS(资金流水!$I$6:$I$605,资金流水!$D$6:$D$605,$B11)) | J11: =IF($B11="","",SUMIFS(资金流水!$J$6:$J$605,资金流水!$D$6:$D$605,$B11)) | K11: =IF($B11="","",ROUND(N($H11)+$I11-$J11,2)) | L11: =IF($B11="","",IF(COUNTIF($B$6:$B$25,$B11)>1,"账户名称重复",IF(ISNA(MATCH($F11,会计科目表!$B$6:$B$85,0)),"对应科目不存在",IF($K11<0,"✗ 期末余额为负","OK"))))
I12: =IF($B12="","",SUMIFS(资金流水!$I$6:$I$605,资金流水!$D$6:$D$605,$B12)) | J12: =IF($B12="","",SUMIFS(资金流水!$J$6:$J$605,资金流水!$D$6:$D$605,$B12)) | K12: =IF($B12="","",ROUND(N($H12)+$I12-$J12,2)) | L12: =IF($B12="","",IF(COUNTIF($B$6:$B$25,$B12)>1,"账户名称重复",IF(ISNA(MATCH($F12,会计科目表!$B$6:$B$85,0)),"对应科目不存在",IF($K12<0,"✗ 期末余额为负","OK"))))
I13: =IF($B13="","",SUMIFS(资金流水!$I$6:$I$605,资金流水!$D$6:$D$605,$B13)) | J13: =IF($B13="","",SUMIFS(资金流水!$J$6:$J$605,资金流水!$D$6:$D$605,$B13)) | K13: =IF($B13="","",ROUND(N($H13)+$I13-$J13,2)) | L13: =IF($B13="","",IF(COUNTIF($B$6:$B$25,$B13)>1,"账户名称重复",IF(ISNA(MATCH($F13,会计科目表!$B$6:$B$85,0)),"对应科目不存在",IF($K13<0,"✗ 期末余额为负","OK"))))
I14: =IF($B14="","",SUMIFS(资金流水!$I$6:$I$605,资金流水!$D$6:$D$605,$B14)) | J14: =IF($B14="","",SUMIFS(资金流水!$J$6:$J$605,资金流水!$D$6:$D$605,$B14)) | K14: =IF($B14="","",ROUND(N($H14)+$I14-$J14,2)) | L14: =IF($B14="","",IF(COUNTIF($B$6:$B$25,$B14)>1,"账户名称重复",IF(ISNA(MATCH($F14,会计科目表!$B$6:$B$85,0)),"对应科目不存在",IF($K14<0,"✗ 期末余额为负","OK"))))
I15: =IF($B15="","",SUMIFS(资金流水!$I$6:$I$605,资金流水!$D$6:$D$605,$B15)) | J15: =IF($B15="","",SUMIFS(资金流水!$J$6:$J$605,资金流水!$D$6:$D$605,$B15)) | K15: =IF($B15="","",ROUND(N($H15)+$I15-$J15,2)) | L15: =IF($B15="","",IF(COUNTIF($B$6:$B$25,$B15)>1,"账户名称重复",IF(ISNA(MATCH($F15,会计科目表!$B$6:$B$85,0)),"对应科目不存在",IF($K15<0,"✗ 期末余额为负","OK"))))
I16: =IF($B16="","",SUMIFS(资金流水!$I$6:$I$605,资金流水!$D$6:$D$605,$B16)) | J16: =IF($B16="","",SUMIFS(资金流水!$J$6:$J$605,资金流水!$D$6:$D$605,$B16)) | K16: =IF($B16="","",ROUND(N($H16)+$I16-$J16,2)) | L16: =IF($B16="","",IF(COUNTIF($B$6:$B$25,$B16)>1,"账户名称重复",IF(ISNA(MATCH($F16,会计科目表!$B$6:$B$85,0)),"对应科目不存在",IF($K16<0,"✗ 期末余额为负","OK"))))
I17: =IF($B17="","",SUMIFS(资金流水!$I$6:$I$605,资金流水!$D$6:$D$605,$B17)) | J17: =IF($B17="","",SUMIFS(资金流水!$J$6:$J$605,资金流水!$D$6:$D$605,$B17)) | K17: =IF($B17="","",ROUND(N($H17)+$I17-$J17,2)) | L17: =IF($B17="","",IF(COUNTIF($B$6:$B$25,$B17)>1,"账户名称重复",IF(ISNA(MATCH($F17,会计科目表!$B$6:$B$85,0)),"对应科目不存在",IF($K17<0,"✗ 期末余额为负","OK"))))
I18: =IF($B18="","",SUMIFS(资金流水!$I$6:$I$605,资金流水!$D$6:$D$605,$B18)) | J18: =IF($B18="","",SUMIFS(资金流水!$J$6:$J$605,资金流水!$D$6:$D$605,$B18)) | K18: =IF($B18="","",ROUND(N($H18)+$I18-$J18,2)) | L18: =IF($B18="","",IF(COUNTIF($B$6:$B$25,$B18)>1,"账户名称重复",IF(ISNA(MATCH($F18,会计科目表!$B$6:$B$85,0)),"对应科目不存在",IF($K18<0,"✗ 期末余额为负","OK"))))
I19: =IF($B19="","",SUMIFS(资金流水!$I$6:$I$605,资金流水!$D$6:$D$605,$B19)) | J19: =IF($B19="","",SUMIFS(资金流水!$J$6:$J$605,资金流水!$D$6:$D$605,$B19)) | K19: =IF($B19="","",ROUND(N($H19)+$I19-$J19,2)) | L19: =IF($B19="","",IF(COUNTIF($B$6:$B$25,$B19)>1,"账户名称重复",IF(ISNA(MATCH($F19,会计科目表!$B$6:$B$85,0)),"对应科目不存在",IF($K19<0,"✗ 期末余额为负","OK"))))
I20: =IF($B20="","",SUMIFS(资金流水!$I$6:$I$605,资金流水!$D$6:$D$605,$B20)) | J20: =IF($B20="","",SUMIFS(资金流水!$J$6:$J$605,资金流水!$D$6:$D$605,$B20)) | K20: =IF($B20="","",ROUND(N($H20)+$I20-$J20,2)) | L20: =IF($B20="","",IF(COUNTIF($B$6:$B$25,$B20)>1,"账户名称重复",IF(ISNA(MATCH($F20,会计科目表!$B$6:$B$85,0)),"对应科目不存在",IF($K20<0,"✗ 期末余额为负","OK"))))
I21: =IF($B21="","",SUMIFS(资金流水!$I$6:$I$605,资金流水!$D$6:$D$605,$B21)) | J21: =IF($B21="","",SUMIFS(资金流水!$J$6:$J$605,资金流水!$D$6:$D$605,$B21)) | K21: =IF($B21="","",ROUND(N($H21)+$I21-$J21,2)) | L21: =IF($B21="","",IF(COUNTIF($B$6:$B$25,$B21)>1,"账户名称重复",IF(ISNA(MATCH($F21,会计科目表!$B$6:$B$85,0)),"对应科目不存在",IF($K21<0,"✗ 期末余额为负","OK"))))
I22: =IF($B22="","",SUMIFS(资金流水!$I$6:$I$605,资金流水!$D$6:$D$605,$B22)) | J22: =IF($B22="","",SUMIFS(资金流水!$J$6:$J$605,资金流水!$D$6:$D$605,$B22)) | K22: =IF($B22="","",ROUND(N($H22)+$I22-$J22,2)) | L22: =IF($B22="","",IF(COUNTIF($B$6:$B$25,$B22)>1,"账户名称重复",IF(ISNA(MATCH($F22,会计科目表!$B$6:$B$85,0)),"对应科目不存在",IF($K22<0,"✗ 期末余额为负","OK"))))
... I25: =IF($B25="","",SUMIFS(资金流水!$I$6:$I$605,资金流水!$D$6:$D$605,$B25)) | J25: =IF($B25="","",SUMIFS(资金流水!$J$6:$J$605,资金流水!$D$6:$D$605,$B25)) | K25: =IF($B25="","",ROUND(N($H25)+$I25-$J25,2)) | L25: =IF($B25="","",IF(COUNTIF($B$6:$B$25,$B25)>1,"账户名称重复",IF(ISNA(MATCH($F25,会计科目表!$B$6:$B$85,0)),"对应科目不存在",IF($K25<0,"✗ 期末余额为负","OK"))))
A27: 合 计 | B27: 全部账户 | H27: =SUM(H$6:H$25) -> 770000 | I27: =SUM(I$6:I$25) -> 1206000 | J27: =SUM(J$6:J$25) -> 701760 | K27: =SUM(K$6:K$25) -> 1274240
A29: 账实对账 | B29: 全部账户余额合计，应当等于三家公司「库存现金＋银行存款」的科目余额合计。共用账户会让某一家的账面银行存款对不上单个账号，但三家加总一定对得上。
A30: 账户余额合计 | B30: =$K$27 -> 1274240 | D30: 三家科目余额合计 | E30: =SUMIFS(科目余额表!$L$7:$L$246,科目余额表!$A$7:$A$246,参数设置!$A$10,科目余额表!$C$7:$C$246,"库存现金")+SUMIFS(科目余额表!$L$7:$L$246,科目余额表!$A$7:$A$246,参数设置!$A$10,科目余额表!$C$7:$C$246,"银行存款")+SUMIFS(科目余额表!$L$7:$L$246,科目余额表!$A$7:$A$246,参数设置!$A$11,科目余额表!$C$7:$C$246,"库存现金")+SUMIFS(科目余额表!$L$7:$L$246,科目余额表!$A$7:$A$246,参数设置!$A$11,科目余额表!$C$7:$C$246,"银行存款")+SUMIFS(科目余额表!$L$7:$L$246,科目余额表!$A$7:$A$246,参数设置!$A$12,科目余额表!$C$7:$C$246,"库存现金")+SUMIFS(科目余额表!$L$7:$L$246,科目余额表!$A$7:$A$246,参数设置!$A$12,科目余额表!$C$7:$C$246,"银行存款") -> 1274240 | G30: =IF(ROUND($B$30-$E$30,2)=0,"√ 账实一致","✗ 差 "&TEXT($B$30-$E$30,"#,##0.00")&" （多半是购销或其他分录直接动了现金/银行，没走资金流水）") -> √ 账实一致

Sheet 期初余额
A1: 期初余额（2026-01-01）
A2: 左边填各公司的科目年初余额（借贷各一列），右边填存货的年初数量和金额。两边要对得上：右边某公司「库存商品」的金额合计，必须等于左边该公司库存商品的借方余额，下面有校验。
A5: 公司 | B5: 科目名称 | C5: 借方余额 | D5: 贷方余额 | E5: 备注 | F5: 校验 | H5: 公司 | I5: 商品编码 | J5: 商品名称 | K5: 期初数量 | L5: 期初金额 | M5: 期初单价 | N5: 校验 | P5: 公司 | Q5: 往来单位 | R5: 年初应收 | S5: 年初应付 | T5: 校验
A6: 农业 | B6: 库存现金 | C6: 5000 | F6: =IF(AND($A6="",$B6=""),"",IF(SUMPRODUCT(($B$6:$B$185=$B6)*($A$6:$A$185=$A6))>1,"同公司同科目重复",IF(ISNA(MATCH($B6,会计科目表!$B$6:$B$85,0)),"科目不存在",IF(AND(N($C6)<>0,N($D6)<>0),"借贷不能同时有数","OK")))) -> OK | H6: 农业 | I6: NY01 | J6: =IF($I6="","",IFERROR(INDEX(商品档案!$B$6:$B$65,MATCH($I6,商品档案!$A$6:$A$65,0)),"")) -> 原木 | K6: 120 | L6: 60000 | M6: =IF(N($K6)=0,"",ROUND(N($L6)/N($K6),4)) -> 500 | N6: =IF($I6="","",IF(ISNA(MATCH($I6,商品档案!$A$6:$A$65,0)),"商品不存在",IF(IFERROR(INDEX(商品档案!$E$6:$E$65,MATCH($I6,商品档案!$A$6:$A$65,0)),"")<>$H6,"商品不属于该公司","OK"))) -> OK | P6: 农业 | Q6: 县农资公司 | S6: 35000 | T6: =IF($Q6="","",IF(ISNA(MATCH($Q6,往来单位!$A$6:$A$85,0)),"单位未建档","OK")) -> OK
A7: 农业 | B7: 银行存款 | C7: 180000 | F7: =IF(AND($A7="",$B7=""),"",IF(SUMPRODUCT(($B$6:$B$185=$B7)*($A$6:$A$185=$A7))>1,"同公司同科目重复",IF(ISNA(MATCH($B7,会计科目表!$B$6:$B$85,0)),"科目不存在",IF(AND(N($C7)<>0,N($D7)<>0),"借贷不能同时有数","OK")))) -> OK | H7: 农业 | I7: NY03 | J7: =IF($I7="","",IFERROR(INDEX(商品档案!$B$6:$B$65,MATCH($I7,商品档案!$A$6:$A$65,0)),"")) -> 干艾草 | K7: 2000 | L7: 18000 | M7: =IF(N($K7)=0,"",ROUND(N($L7)/N($K7),4)) -> 9 | N7: =IF($I7="","",IF(ISNA(MATCH($I7,商品档案!$A$6:$A$65,0)),"商品不存在",IF(IFERROR(INDEX(商品档案!$E$6:$E$65,MATCH($I7,商品档案!$A$6:$A$65,0)),"")<>$H7,"商品不属于该公司","OK"))) -> OK | P7: 木业 | Q7: 鑫隆建材 | R7: 156000 | T7: =IF($Q7="","",IF(ISNA(MATCH($Q7,往来单位!$A$6:$A$85,0)),"单位未建档","OK")) -> OK
A8: 农业 | B8: 原材料 | C8: 12000 | F8: =IF(AND($A8="",$B8=""),"",IF(SUMPRODUCT(($B$6:$B$185=$B8)*($A$6:$A$185=$A8))>1,"同公司同科目重复",IF(ISNA(MATCH($B8,会计科目表!$B$6:$B$85,0)),"科目不存在",IF(AND(N($C8)<>0,N($D8)<>0),"借贷不能同时有数","OK")))) -> OK | H8: 农业 | I8: NY05 | J8: =IF($I8="","",IFERROR(INDEX(商品档案!$B$6:$B$65,MATCH($I8,商品档案!$A$6:$A$65,0)),"")) -> 肥料 | K8: 10 | L8: 11000 | M8: =IF(N($K8)=0,"",ROUND(N($L8)/N($K8),4)) -> 1100 | N8: =IF($I8="","",IF(ISNA(MATCH($I8,商品档案!$A$6:$A$65,0)),"商品不存在",IF(IFERROR(INDEX(商品档案!$E$6:$E$65,MATCH($I8,商品档案!$A$6:$A$65,0)),"")<>$H8,"商品不属于该公司","OK"))) -> OK | P8: 木业 | Q8: 华鑫化工 | S8: 88000 | T8: =IF($Q8="","",IF(ISNA(MATCH($Q8,往来单位!$A$6:$A$85,0)),"单位未建档","OK")) -> OK
A9: 农业 | B9: 库存商品 | C9: 78000 | F9: =IF(AND($A9="",$B9=""),"",IF(SUMPRODUCT(($B$6:$B$185=$B9)*($A$6:$A$185=$A9))>1,"同公司同科目重复",IF(ISNA(MATCH($B9,会计科目表!$B$6:$B$85,0)),"科目不存在",IF(AND(N($C9)<>0,N($D9)<>0),"借贷不能同时有数","OK")))) -> OK | H9: 农业 | I9: NY06 | J9: =IF($I9="","",IFERROR(INDEX(商品档案!$B$6:$B$65,MATCH($I9,商品档案!$A$6:$A$65,0)),"")) -> 农药 | K9: 100 | L9: 1000 | M9: =IF(N($K9)=0,"",ROUND(N($L9)/N($K9),4)) -> 10 | N9: =IF($I9="","",IF(ISNA(MATCH($I9,商品档案!$A$6:$A$65,0)),"商品不存在",IF(IFERROR(INDEX(商品档案!$E$6:$E$65,MATCH($I9,商品档案!$A$6:$A$65,0)),"")<>$H9,"商品不属于该公司","OK"))) -> OK | P9: 科技 | Q9: 康养电商 | R9: 88000 | T9: =IF($Q9="","",IF(ISNA(MATCH($Q9,往来单位!$A$6:$A$85,0)),"单位未建档","OK")) -> OK
A10: 农业 | B10: 生产性生物资产 | C10: 600000 | F10: =IF(AND($A10="",$B10=""),"",IF(SUMPRODUCT(($B$6:$B$185=$B10)*($A$6:$A$185=$A10))>1,"同公司同科目重复",IF(ISNA(MATCH($B10,会计科目表!$B$6:$B$85,0)),"科目不存在",IF(AND(N($C10)<>0,N($D10)<>0),"借贷不能同时有数","OK")))) -> OK | H10: 木业 | I10: MY07 | J10: =IF($I10="","",IFERROR(INDEX(商品档案!$B$6:$B$65,MATCH($I10,商品档案!$A$6:$A$65,0)),"")) -> 原木 | K10: 80 | L10: 76000 | M10: =IF(N($K10)=0,"",ROUND(N($L10)/N($K10),4)) -> 950 | N10: =IF($I10="","",IF(ISNA(MATCH($I10,商品档案!$A$6:$A$65,0)),"商品不存在",IF(IFERROR(INDEX(商品档案!$E$6:$E$65,MATCH($I10,商品档案!$A$6:$A$65,0)),"")<>$H10,"商品不属于该公司","OK"))) -> OK | P10: 科技 | Q10: 晶诚玻璃 | S10: 45000 | T10: =IF($Q10="","",IF(ISNA(MATCH($Q10,往来单位!$A$6:$A$85,0)),"单位未建档","OK")) -> OK
A11: 农业 | B11: 生物资产累计折旧 | D11: 40000 | F11: =IF(AND($A11="",$B11=""),"",IF(SUMPRODUCT(($B$6:$B$185=$B11)*($A$6:$A$185=$A11))>1,"同公司同科目重复",IF(ISNA(MATCH($B11,会计科目表!$B$6:$B$85,0)),"科目不存在",IF(AND(N($C11)<>0,N($D11)<>0),"借贷不能同时有数","OK")))) -> OK | H11: 木业 | I11: MY08 | J11: =IF($I11="","",IFERROR(INDEX(商品档案!$B$6:$B$65,MATCH($I11,商品档案!$A$6:$A$65,0)),"")) -> 胶水 | K11: 300 | L11: 5850 | M11: =IF(N($K11)=0,"",ROUND(N($L11)/N($K11),4)) -> 19.5 | N11: =IF($I11="","",IF(ISNA(MATCH($I11,商品档案!$A$6:$A$65,0)),"商品不存在",IF(IFERROR(INDEX(商品档案!$E$6:$E$65,MATCH($I11,商品档案!$A$6:$A$65,0)),"")<>$H11,"商品不属于该公司","OK"))) -> OK | T11: =IF($Q11="","",IF(ISNA(MATCH($Q11,往来单位!$A$6:$A$85,0)),"单位未建档","OK"))
A12: 农业 | B12: 无形资产 | C12: 1200000 | F12: =IF(AND($A12="",$B12=""),"",IF(SUMPRODUCT(($B$6:$B$185=$B12)*($A$6:$A$185=$A12))>1,"同公司同科目重复",IF(ISNA(MATCH($B12,会计科目表!$B$6:$B$85,0)),"科目不存在",IF(AND(N($C12)<>0,N($D12)<>0),"借贷不能同时有数","OK")))) -> OK | H12: 木业 | I12: MY01 | J12: =IF($I12="","",IFERROR(INDEX(商品档案!$B$6:$B$65,MATCH($I12,商品档案!$A$6:$A$65,0)),"")) -> *木制品*木板 | K12: 800 | L12: 76800 | M12: =IF(N($K12)=0,"",ROUND(N($L12)/N($K12),4)) -> 96 | N12: =IF($I12="","",IF(ISNA(MATCH($I12,商品档案!$A$6:$A$65,0)),"商品不存在",IF(IFERROR(INDEX(商品档案!$E$6:$E$65,MATCH($I12,商品档案!$A$6:$A$65,0)),"")<>$H12,"商品不属于该公司","OK"))) -> OK | T12: =IF($Q12="","",IF(ISNA(MATCH($Q12,往来单位!$A$6:$A$85,0)),"单位未建档","OK"))
A13: 农业 | B13: 累计摊销 | D13: 48000 | F13: =IF(AND($A13="",$B13=""),"",IF(SUMPRODUCT(($B$6:$B$185=$B13)*($A$6:$A$185=$A13))>1,"同公司同科目重复",IF(ISNA(MATCH($B13,会计科目表!$B$6:$B$85,0)),"科目不存在",IF(AND(N($C13)<>0,N($D13)<>0),"借贷不能同时有数","OK")))) -> OK | H13: 木业 | I13: MY02 | J13: =IF($I13="","",IFERROR(INDEX(商品档案!$B$6:$B$65,MATCH($I13,商品档案!$A$6:$A$65,0)),"")) -> *木制品*模板 | K13: 300 | L13: 27600 | M13: =IF(N($K13)=0,"",ROUND(N($L13)/N($K13),4)) -> 92 | N13: =IF($I13="","",IF(ISNA(MATCH($I13,商品档案!$A$6:$A$65,0)),"商品不存在",IF(IFERROR(INDEX(商品档案!$E$6:$E$65,MATCH($I13,商品档案!$A$6:$A$65,0)),"")<>$H13,"商品不属于该公司","OK"))) -> OK | T13: =IF($Q13="","",IF(ISNA(MATCH($Q13,往来单位!$A$6:$A$85,0)),"单位未建档","OK"))
A14: 农业 | B14: 固定资产 | C14: 260000 | F14: =IF(AND($A14="",$B14=""),"",IF(SUMPRODUCT(($B$6:$B$185=$B14)*($A$6:$A$185=$A14))>1,"同公司同科目重复",IF(ISNA(MATCH($B14,会计科目表!$B$6:$B$85,0)),"科目不存在",IF(AND(N($C14)<>0,N($D14)<>0),"借贷不能同时有数","OK")))) -> OK | H14: 科技 | I14: KJ08 | J14: =IF($I14="","",IFERROR(INDEX(商品档案!$B$6:$B$65,MATCH($I14,商品档案!$A$6:$A$65,0)),"")) -> 干艾草 | K14: 1500 | L14: 18000 | M14: =IF(N($K14)=0,"",ROUND(N($L14)/N($K14),4)) -> 12 | N14: =IF($I14="","",IF(ISNA(MATCH($I14,商品档案!$A$6:$A$65,0)),"商品不存在",IF(IFERROR(INDEX(商品档案!$E$6:$E$65,MATCH($I14,商品档案!$A$6:$A$65,0)),"")<>$H14,"商品不属于该公司","OK"))) -> OK | T14: =IF($Q14="","",IF(ISNA(MATCH($Q14,往来单位!$A$6:$A$85,0)),"单位未建档","OK"))
