Workbook

Sheet 汇总
A1: 维 保 汇 总 · 梯子状态、数量、回款情况（全自动，不用填）
A2: ★ 这张表只读不填。数字全部从《电梯档案》和各维保组的表里自动汇总，那边改了这边跟着变。 ★ 只有第 3 行三个淡黄格可以改：统计年度（④ 按年度用）、到期提醒天数（到期 / 年检 / 免保提醒都按它）、付款宽限天数（每期期初过了这几天还没收才算逾期，原表多数写「七日内付」，默认 7）。
A3: 统计年度 | B3: 2026 | C3: 到期提醒天数 | D3: 30 | E3: 付款宽限天数 | F3: 7 | G3: 今天 | H3: =TODAY() -> 46288
A5: ① 梯子情况（来自《电梯档案》）：维保状态 / 梯型 / 维保人员 / 年检与免保提醒
A6: 维保状态 | B6: 台量 | C6: 占比 | D6: 免保已到期或 30天内到期 | F6: 梯型 | G6: 台量 | H6: 占比 | J6: 维保人员 | K6: 台量 | M6: 提醒 | N6: 台数
A7: 正常维保 | B7: =SUMIF(电梯档案!$W$2:$W$800,$A7,电梯档案!$N$2:$N$800) -> 0 | C7: =IFERROR($B7/$B$14,"") -> 0 | F7: 客梯 | G7: =SUMIF(电梯档案!$H$2:$H$800,"客梯",电梯档案!$N$2:$N$800) -> 127 | H7: =IFERROR($G7/$G$14,"") -> 0.42192691 | J7: 已排维保人员 | K7: =SUMIF(电梯档案!$V$2:$V$800,"?*",电梯档案!$N$2:$N$800)-$K$8 -> 39 | M7: 年检/限速器/载重 已过期 | N7: =COUNTIF(电梯档案!$Z$2:$Z$800,"*已过期*") -> 0
A8: 安装免保 | B8: =SUMIF(电梯档案!$W$2:$W$800,$A8,电梯档案!$N$2:$N$800) -> 0 | C8: =IFERROR($B8/$B$14,"") -> 0 | D8: =COUNTIFS(电梯档案!$W$2:$W$800,$A8,电梯档案!$Y$2:$Y$800,"▲免保已到期*")+COUNTIFS(电梯档案!$W$2:$W$800,$A8,电梯档案!$Y$2:$Y$800,"免保剩*") -> 0 | F8: 客梯(无机房) | G8: =SUMIF(电梯档案!$H$2:$H$800,"客梯(无机房)",电梯档案!$N$2:$N$800)+SUMIF(电梯档案!$H$2:$H$800,"客梯（无机房）",电梯档案!$N$2:$N$800) -> 80 | H8: =IFERROR($G8/$G$14,"") -> 0.26578073 | J8: 写着「未排」 | K8: =SUMIF(电梯档案!$V$2:$V$800,"未排",电梯档案!$N$2:$N$800) -> 8 | M8: 年检/限速器/载重 快到期 | N8: =COUNTIFS(电梯档案!$Z$2:$Z$800,"*剩*",电梯档案!$Z$2:$Z$800,"<>*已过期*") -> 3
A9: 技术免保 | B9: =SUMIF(电梯档案!$W$2:$W$800,$A9,电梯档案!$N$2:$N$800) -> 0 | C9: =IFERROR($B9/$B$14,"") -> 0 | D9: =COUNTIFS(电梯档案!$W$2:$W$800,$A9,电梯档案!$Y$2:$Y$800,"▲免保已到期*")+COUNTIFS(电梯档案!$W$2:$W$800,$A9,电梯档案!$Y$2:$Y$800,"免保剩*") -> 0 | F9: 货梯 | G9: =SUMIF(电梯档案!$H$2:$H$800,"货梯",电梯档案!$N$2:$N$800) -> 25 | H9: =IFERROR($G9/$G$14,"") -> 0.083056478 | J9: 维保人员没填 | K9: =$K$10-$K$7-$K$8 -> 254 | M9: 免保已到期该转收费 | N9: =COUNTIF(电梯档案!$Y$2:$Y$800,"▲免保已到期*") -> 0
A10: 质保期内 | B10: =SUMIF(电梯档案!$W$2:$W$800,$A10,电梯档案!$N$2:$N$800) -> 0 | C10: =IFERROR($B10/$B$14,"") -> 0 | D10: =COUNTIFS(电梯档案!$W$2:$W$800,$A10,电梯档案!$Y$2:$Y$800,"▲免保已到期*")+COUNTIFS(电梯档案!$W$2:$W$800,$A10,电梯档案!$Y$2:$Y$800,"免保剩*") -> 0 | F10: 扶梯 | G10: =SUMIF(电梯档案!$H$2:$H$800,"扶梯",电梯档案!$N$2:$N$800) -> 3 | H10: =IFERROR($G10/$G$14,"") -> 0.0099667774 | J10: 合计 | K10: =SUM(电梯档案!$N$2:$N$800) -> 301 | M10: 免保快到期 | N10: =COUNTIF(电梯档案!$Y$2:$Y$800,"免保剩*") -> 0
A11: 暂停维保 | B11: =SUMIF(电梯档案!$W$2:$W$800,$A11,电梯档案!$N$2:$N$800) -> 0 | C11: =IFERROR($B11/$B$14,"") -> 0 | F11: 人行道 | G11: =SUMIF(电梯档案!$H$2:$H$800,"人行道",电梯档案!$N$2:$N$800) -> 4 | H11: =IFERROR($G11/$G$14,"") -> 0.013289037 | M11: 免保没填到期日 | N11: =COUNTIF(电梯档案!$Y$2:$Y$800,"▲免保到期日没填") -> 0
A12: 已解约 | B12: =SUMIF(电梯档案!$W$2:$W$800,$A12,电梯档案!$N$2:$N$800) -> 0 | C12: =IFERROR($B12/$B$14,"") -> 0 | F12: 杂物梯 | G12: =SUMIF(电梯档案!$H$2:$H$800,"杂物梯",电梯档案!$N$2:$N$800) -> 1 | H12: =IFERROR($G12/$G$14,"") -> 0.0033222591 | M12: 档案在册台量 | N12: =SUM(电梯档案!$N$2:$N$800) -> 301
A13: 还没填维保状态 | B13: =$B$14-SUM($B$7:$B$12) -> 301 | C13: =IFERROR($B13/$B$14,"") -> 1 | F13: 其他 / 梯型没填 | G13: =$G$14-SUM($G$7:$G$12) -> 61 | H13: =IFERROR($G13/$G$14,"") -> 0.20265781 | M13: 各组合同台量合计 | N13: =$C$25 -> 218
A14: 在册总台量 | B14: =SUM(电梯档案!$N$2:$N$800) -> 301 | C14: =IF($B$14=0,"",1) -> 1 | D14: =SUM($D$7:$D$12) -> 0 | F14: 合计 | G14: =SUM(电梯档案!$N$2:$N$800) -> 301 | H14: =IF($G$14=0,"",1) -> 1 | M14: 档案比合同多出的台量 | N14: =$N$12-$N$13 -> 83
M15: ↑ 多出来的就是在档案里、但还没挂到任何一张维保组合同上的梯子（或合同台量没填）。
A17: ② 各维保组：合同与回款（每组一行）
A18: 维保组 | B18: 项目 行数 | C18: 合同 台量 | D18: 合同 未回 | E18: 已到期 | F18: 即将 到期 | G18: 免保 项目 | H18: 合同应收 | I18: 合同外 维修费 | J18: 总应收 | K18: 开票金额 | L18: 收款金额 | M18: 收现金额 | N18: 收款不开票 | O18: 已收合计 | P18: 回款率 | Q18: 开票应收额 (开票未到账) | R18: 到账未开票 (待补票) | S18: 未开票应收 | T18: 应收余额 (欠款) | U18: 截至今天应收 (按付款周期) | V18: 逾期未收
A19: 刘丕斌徐少斌夏凯 | B19: =COUNTIF(刘丕斌徐少斌夏凯!$AJ$3:$AJ$1001,"?*") -> 10 | C19: =SUM(刘丕斌徐少斌夏凯!$H$3:$H$1001) -> 15 | D19: =COUNTIF(刘丕斌徐少斌夏凯!$F$3:$F$1001,"*合同未回*") -> 0 | E19: =COUNTIF(刘丕斌徐少斌夏凯!$F$3:$F$1001,"*已到期*") -> 0 | F19: =COUNTIF(刘丕斌徐少斌夏凯!$F$3:$F$1001,"*即将到期*") -> 0 | G19: =COUNTIF(刘丕斌徐少斌夏凯!$AC$3:$AC$1001,"安装免保")+COUNTIF(刘丕斌徐少斌夏凯!$AC$3:$AC$1001,"技术免保")+COUNTIF(刘丕斌徐少斌夏凯!$AC$3:$AC$1001,"质保期内") -> 0 | H19: =SUM(刘丕斌徐少斌夏凯!$J$3:$J$1001) -> 56600 | I19: =SUM(刘丕斌徐少斌夏凯!$K$3:$K$1001) -> 0 | J19: =SUM(刘丕斌徐少斌夏凯!$L$3:$L$1001) -> 56600 | K19: =SUM(刘丕斌徐少斌夏凯!$N$3:$N$1001) -> 0 | L19: =SUM(刘丕斌徐少斌夏凯!$P$3:$P$1001) -> 0 | M19: =SUM(刘丕斌徐少斌夏凯!$Q$3:$Q$1001) -> 0 | N19: =SUM(刘丕斌徐少斌夏凯!$R$3:$R$1001) -> 0 | O19: =$L19+$M19+$N19 -> 0 | P19: =IFERROR($O19/$J19,"") -> 0 | Q19: =SUM(刘丕斌徐少斌夏凯!$S$3:$S$1001) -> 0 | R19: =SUM(刘丕斌徐少斌夏凯!$T$3:$T$1001) -> 0 | S19: =SUM(刘丕斌徐少斌夏凯!$U$3:$U$1001) -> 56600 | T19: =SUM(刘丕斌徐少斌夏凯!$V$3:$V$1001) -> 56600 | U19: =SUM(刘丕斌徐少斌夏凯!$AF$3:$AF$1001) -> 3200 | V19: =SUM(刘丕斌徐少斌夏凯!$AG$3:$AG$1001) -> 3200
A20: 陆莹杨凯 | B20: =COUNTIF(陆莹杨凯!$AI$3:$AI$1001,"?*") -> 31 | C20: =SUM(陆莹杨凯!$H$3:$H$1001) -> 4 | D20: =COUNTIF(陆莹杨凯!$F$3:$F$1001,"*合同未回*") -> 30 | E20: =COUNTIF(陆莹杨凯!$F$3:$F$1001,"*已到期*") -> 0 | F20: =COUNTIF(陆莹杨凯!$F$3:$F$1001,"*即将到期*") -> 0 | G20: =COUNTIF(陆莹杨凯!$AB$3:$AB$1001,"安装免保")+COUNTIF(陆莹杨凯!$AB$3:$AB$1001,"技术免保")+COUNTIF(陆莹杨凯!$AB$3:$AB$1001,"质保期内") -> 0 | H20: =SUM(陆莹杨凯!$J$3:$J$1001) -> 14400 | I20: =SUM(陆莹杨凯!$L$3:$L$1001) -> 350 | J20: =SUM(陆莹杨凯!$M$3:$M$1001) -> 14750 | K20: =SUM(陆莹杨凯!$O$3:$O$1001) -> 0 | L20: =SUM(陆莹杨凯!$Q$3:$Q$1001) -> 0 | M20: =SUM(陆莹杨凯!$R$3:$R$1001) -> 0 | N20: =SUM(陆莹杨凯!$S$3:$S$1001) -> 0 | O20: =$L20+$M20+$N20 -> 0 | P20: =IFERROR($O20/$J20,"") -> 0 | Q20: =SUM(陆莹杨凯!$T$3:$T$1001) -> 0 | R20: =SUM(陆莹杨凯!$U$3:$U$1001) -> 0 | S20: =SUM(陆莹杨凯!$V$3:$V$1001) -> 14750 | T20: =SUM(陆莹杨凯!$W$3:$W$1001) -> 14750 | U20: =SUM(陆莹杨凯!$AE$3:$AE$1001) -> 350 | V20: =SUM(陆莹杨凯!$AF$3:$AF$1001) -> 350
A21: 刘坤田超 | B21: =COUNTIF(刘坤田超!$AK$3:$AK$1001,"?*") -> 11 | C21: =SUM(刘坤田超!$I$3:$I$1001) -> 55 | D21: =COUNTIF(刘坤田超!$F$3:$F$1001,"*合同未回*") -> 8 | E21: =COUNTIF(刘坤田超!$F$3:$F$1001,"*已到期*") -> 0 | F21: =COUNTIF(刘坤田超!$F$3:$F$1001,"*即将到期*") -> 0 | G21: =COUNTIF(刘坤田超!$AD$3:$AD$1001,"安装免保")+COUNTIF(刘坤田超!$AD$3:$AD$1001,"技术免保")+COUNTIF(刘坤田超!$AD$3:$AD$1001,"质保期内") -> 0 | H21: =SUM(刘坤田超!$K$3:$K$1001) -> 10000 | I21: =SUM(刘坤田超!$L$3:$L$1001) -> 0 | J21: =SUM(刘坤田超!$M$3:$M$1001) -> 10000 | K21: =SUM(刘坤田超!$O$3:$O$1001) -> 0 | L21: =SUM(刘坤田超!$Q$3:$Q$1001) -> 0 | M21: =SUM(刘坤田超!$R$3:$R$1001) -> 0 | N21: =SUM(刘坤田超!$S$3:$S$1001) -> 0 | O21: =$L21+$M21+$N21 -> 0 | P21: =IFERROR($O21/$J21,"") -> 0 | Q21: =SUM(刘坤田超!$T$3:$T$1001) -> 0 | R21: =SUM(刘坤田超!$U$3:$U$1001) -> 0 | S21: =SUM(刘坤田超!$V$3:$V$1001) -> 10000 | T21: =SUM(刘坤田超!$W$3:$W$1001) -> 10000 | U21: =SUM(刘坤田超!$AG$3:$AG$1001) -> 0 | V21: =SUM(刘坤田超!$AH$3:$AH$1001) -> 0
A22: 陈彪姚永华梅思阳 | B22: =COUNTIF(陈彪姚永华梅思阳!$AK$3:$AK$1001,"?*") -> 88 | C22: =SUM(陈彪姚永华梅思阳!$I$3:$I$1001) -> 95 | D22: =COUNTIF(陈彪姚永华梅思阳!$F$3:$F$1001,"*合同未回*") -> 79 | E22: =COUNTIF(陈彪姚永华梅思阳!$F$3:$F$1001,"*已到期*") -> 0 | F22: =COUNTIF(陈彪姚永华梅思阳!$F$3:$F$1001,"*即将到期*") -> 0 | G22: =COUNTIF(陈彪姚永华梅思阳!$AD$3:$AD$1001,"安装免保")+COUNTIF(陈彪姚永华梅思阳!$AD$3:$AD$1001,"技术免保")+COUNTIF(陈彪姚永华梅思阳!$AD$3:$AD$1001,"质保期内") -> 0 | H22: =SUM(陈彪姚永华梅思阳!$K$3:$K$1001) -> 25300 | I22: =SUM(陈彪姚永华梅思阳!$L$3:$L$1001) -> 0 | J22: =SUM(陈彪姚永华梅思阳!$M$3:$M$1001) -> 25300 | K22: =SUM(陈彪姚永华梅思阳!$O$3:$O$1001) -> 0 | L22: =SUM(陈彪姚永华梅思阳!$Q$3:$Q$1001) -> 0 | M22: =SUM(陈彪姚永华梅思阳!$R$3:$R$1001) -> 0 | N22: =SUM(陈彪姚永华梅思阳!$S$3:$S$1001) -> 0 | O22: =$L22+$M22+$N22 -> 0 | P22: =IFERROR($O22/$J22,"") -> 0 | Q22: =SUM(陈彪姚永华梅思阳!$T$3:$T$1001) -> 0 | R22: =SUM(陈彪姚永华梅思阳!$U$3:$U$1001) -> 0 | S22: =SUM(陈彪姚永华梅思阳!$V$3:$V$1001) -> 25300 | T22: =SUM(陈彪姚永华梅思阳!$W$3:$W$1001) -> 25300 | U22: =SUM(陈彪姚永华梅思阳!$AG$3:$AG$1001) -> 15300 | V22: =SUM(陈彪姚永华梅思阳!$AH$3:$AH$1001) -> 15300
A23: 胡春平 | B23: =COUNTIF(胡春平!$AJ$3:$AJ$1001,"?*") -> 45 | C23: =SUM(胡春平!$H$3:$H$1001) -> 49 | D23: =COUNTIF(胡春平!$F$3:$F$1001,"*合同未回*") -> 24 | E23: =COUNTIF(胡春平!$F$3:$F$1001,"*已到期*") -> 0 | F23: =COUNTIF(胡春平!$F$3:$F$1001,"*即将到期*") -> 0 | G23: =COUNTIF(胡春平!$AC$3:$AC$1001,"安装免保")+COUNTIF(胡春平!$AC$3:$AC$1001,"技术免保")+COUNTIF(胡春平!$AC$3:$AC$1001,"质保期内") -> 0 | H23: =SUM(胡春平!$J$3:$J$1001) -> 91800 | I23: =SUM(胡春平!$K$3:$K$1001) -> -20 | J23: =SUM(胡春平!$L$3:$L$1001) -> 91780 | K23: =SUM(胡春平!$N$3:$N$1001) -> 15480 | L23: =SUM(胡春平!$P$3:$P$1001) -> 7700 | M23: =SUM(胡春平!$Q$3:$Q$1001) -> 0 | N23: =SUM(胡春平!$R$3:$R$1001) -> 0 | O23: =$L23+$M23+$N23 -> 7700 | P23: =IFERROR($O23/$J23,"") -> 0.083896274 | Q23: =SUM(胡春平!$S$3:$S$1001) -> 7780 | R23: =SUM(胡春平!$T$3:$T$1001) -> 0 | S23: =SUM(胡春平!$U$3:$U$1001) -> 76300 | T23: =SUM(胡春平!$V$3:$V$1001) -> 84080 | U23: =SUM(胡春平!$AF$3:$AF$1001) -> 87600 | V23: =SUM(胡春平!$AG$3:$AG$1001) -> 79900
A24: Sheet5（空白模板） | B24: =COUNTIF(Sheet5!$AJ$3:$AJ$1001,"?*") -> 0 | C24: =SUM(Sheet5!$H$3:$H$1001) -> 0 | D24: =COUNTIF(Sheet5!$F$3:$F$1001,"*合同未回*") -> 0 | E24: =COUNTIF(Sheet5!$F$3:$F$1001,"*已到期*") -> 0 | F24: =COUNTIF(Sheet5!$F$3:$F$1001,"*即将到期*") -> 0 | G24: =COUNTIF(Sheet5!$AC$3:$AC$1001,"安装免保")+COUNTIF(Sheet5!$AC$3:$AC$1001,"技术免保")+COUNTIF(Sheet5!$AC$3:$AC$1001,"质保期内") -> 0 | H24: =SUM(Sheet5!$J$3:$J$1001) -> 0 | I24: =SUM(Sheet5!$K$3:$K$1001) -> 0 | J24: =SUM(Sheet5!$L$3:$L$1001) -> 0 | K24: =SUM(Sheet5!$N$3:$N$1001) -> 0 | L24: =SUM(Sheet5!$P$3:$P$1001) -> 0 | M24: =SUM(Sheet5!$Q$3:$Q$1001) -> 0 | N24: =SUM(Sheet5!$R$3:$R$1001) -> 0 | O24: =$L24+$M24+$N24 -> 0 | P24: =IFERROR($O24/$J24,"") | Q24: =SUM(Sheet5!$S$3:$S$1001) -> 0 | R24: =SUM(Sheet5!$T$3:$T$1001) -> 0 | S24: =SUM(Sheet5!$U$3:$U$1001) -> 0 | T24: =SUM(Sheet5!$V$3:$V$1001) -> 0 | U24: =SUM(Sheet5!$AF$3:$AF$1001) -> 0 | V24: =SUM(Sheet5!$AG$3:$AG$1001) -> 0
A25: 合计 | B25: =SUM(B19:B24) -> 185 | C25: =SUM(C19:C24) -> 218 | D25: =SUM(D19:D24) -> 141 | E25: =SUM(E19:E24) -> 0 | F25: =SUM(F19:F24) -> 0 | G25: =SUM(G19:G24) -> 0 | H25: =SUM(H19:H24) -> 198100 | I25: =SUM(I19:I24) -> 330 | ... O25: =SUM(O19:O24) -> 7700 | P25: =IFERROR($O25/$J25,"") -> 0.038804616 | Q25: =SUM(Q19:Q24) -> 7780 | R25: =SUM(R19:R24) -> 0 | S25: =SUM(S19:S24) -> 182950 | T25: =SUM(T19:T24) -> 190730 | U25: =SUM(U19:U24) -> 106450 | V25: =SUM(V19:V24) -> 98750
A28: ③ 收款五种情况（按维保组拆开）：钱是怎么收的、票是怎么开的
A29: 情况 | B29: 在组表里怎么填 | C29: 刘丕斌徐少斌夏凯 | D29: 陆莹杨凯 | E29: 刘坤田超 | F29: 陈彪姚永华梅思阳 | G29: 胡春平 | H29: Sheet5（空白模板） | I29: 合计 | J29: 涉及行数
A30: ① 不开票的现金账 | B30: 只填「收现金额」 | C30: =SUM(刘丕斌徐少斌夏凯!$Q$3:$Q$1001) -> 0 | D30: =SUM(陆莹杨凯!$R$3:$R$1001) -> 0 | E30: =SUM(刘坤田超!$R$3:$R$1001) -> 0 | F30: =SUM(陈彪姚永华梅思阳!$R$3:$R$1001) -> 0 | G30: =SUM(胡春平!$Q$3:$Q$1001) -> 0 | H30: =SUM(Sheet5!$Q$3:$Q$1001) -> 0 | I30: =SUM(C30:H30) -> 0 | J30: =COUNTIF(刘丕斌徐少斌夏凯!$Q$3:$Q$1001,">0")+COUNTIF(陆莹杨凯!$R$3:$R$1001,">0")+COUNTIF(刘坤田超!$R$3:$R$1001,">0")+COUNTIF(陈彪姚永华梅思阳!$R$3:$R$1001,">0")+COUNTIF(胡春平!$Q$3:$Q$1001,">0")+COUNTIF(Sheet5!$Q$3:$Q$1001,">0") -> 0
A31: ② 收款不开票（转账/微信/收据，不开票） | B31: 只填「收款不开票」 | C31: =SUM(刘丕斌徐少斌夏凯!$R$3:$R$1001) -> 0 | D31: =SUM(陆莹杨凯!$S$3:$S$1001) -> 0 | E31: =SUM(刘坤田超!$S$3:$S$1001) -> 0 | F31: =SUM(陈彪姚永华梅思阳!$S$3:$S$1001) -> 0 | G31: =SUM(胡春平!$R$3:$R$1001) -> 0 | H31: =SUM(Sheet5!$R$3:$R$1001) -> 0 | I31: =SUM(C31:H31) -> 0 | J31: =COUNTIF(刘丕斌徐少斌夏凯!$R$3:$R$1001,">0")+COUNTIF(陆莹杨凯!$S$3:$S$1001,">0")+COUNTIF(刘坤田超!$S$3:$S$1001,">0")+COUNTIF(陈彪姚永华梅思阳!$S$3:$S$1001,">0")+COUNTIF(胡春平!$R$3:$R$1001,">0")+COUNTIF(Sheet5!$R$3:$R$1001,">0") -> 0
A32: ③ 开票收款（票开了、钱也到了） | B32: 「开票金额」和「收款金额」都填 | C32: =SUM(刘丕斌徐少斌夏凯!$AK$3:$AK$1001) -> 0 | D32: =SUM(陆莹杨凯!$AJ$3:$AJ$1001) -> 0 | E32: =SUM(刘坤田超!$AL$3:$AL$1001) -> 0 | F32: =SUM(陈彪姚永华梅思阳!$AL$3:$AL$1001) -> 0 | G32: =SUM(胡春平!$AK$3:$AK$1001) -> 7700 | H32: =SUM(Sheet5!$AK$3:$AK$1001) -> 0 | I32: =SUM(C32:H32) -> 7700 | J32: =COUNTIF(刘丕斌徐少斌夏凯!$AK$3:$AK$1001,">0")+COUNTIF(陆莹杨凯!$AJ$3:$AJ$1001,">0")+COUNTIF(刘坤田超!$AL$3:$AL$1001,">0")+COUNTIF(陈彪姚永华梅思阳!$AL$3:$AL$1001,">0")+COUNTIF(胡春平!$AK$3:$AK$1001,">0")+COUNTIF(Sheet5!$AK$3:$AK$1001,">0") -> 2
A33: ④ 开票未到账（开票应收额） | B33: 只填「开票金额」，钱没到 | C33: =SUM(刘丕斌徐少斌夏凯!$S$3:$S$1001) -> 0 | D33: =SUM(陆莹杨凯!$T$3:$T$1001) -> 0 | E33: =SUM(刘坤田超!$T$3:$T$1001) -> 0 | F33: =SUM(陈彪姚永华梅思阳!$T$3:$T$1001) -> 0 | G33: =SUM(胡春平!$S$3:$S$1001) -> 7780 | H33: =SUM(Sheet5!$S$3:$S$1001) -> 0 | I33: =SUM(C33:H33) -> 7780 | J33: =COUNTIF(刘丕斌徐少斌夏凯!$S$3:$S$1001,">0")+COUNTIF(陆莹杨凯!$T$3:$T$1001,">0")+COUNTIF(刘坤田超!$T$3:$T$1001,">0")+COUNTIF(陈彪姚永华梅思阳!$T$3:$T$1001,">0")+COUNTIF(胡春平!$S$3:$S$1001,">0")+COUNTIF(Sheet5!$S$3:$S$1001,">0") -> 2
A34: ⑤ 到账未开票（待补票） | B34: 只填「收款金额」，票还没开 | C34: =SUM(刘丕斌徐少斌夏凯!$T$3:$T$1001) -> 0 | D34: =SUM(陆莹杨凯!$U$3:$U$1001) -> 0 | E34: =SUM(刘坤田超!$U$3:$U$1001) -> 0 | F34: =SUM(陈彪姚永华梅思阳!$U$3:$U$1001) -> 0 | G34: =SUM(胡春平!$T$3:$T$1001) -> 0 | H34: =SUM(Sheet5!$T$3:$T$1001) -> 0 | I34: =SUM(C34:H34) -> 0 | J34: =COUNTIF(刘丕斌徐少斌夏凯!$T$3:$T$1001,">0")+COUNTIF(陆莹杨凯!$U$3:$U$1001,">0")+COUNTIF(刘坤田超!$U$3:$U$1001,">0")+COUNTIF(陈彪姚永华梅思阳!$U$3:$U$1001,">0")+COUNTIF(胡春平!$T$3:$T$1001,">0")+COUNTIF(Sheet5!$T$3:$T$1001,">0") -> 0
A35: 未开票也未收（未开票应收） | B35: 自动：还欠的钱里没开票的部分 | C35: =SUM(刘丕斌徐少斌夏凯!$U$3:$U$1001) -> 56600 | D35: =SUM(陆莹杨凯!$V$3:$V$1001) -> 14750 | E35: =SUM(刘坤田超!$V$3:$V$1001) -> 10000 | F35: =SUM(陈彪姚永华梅思阳!$V$3:$V$1001) -> 25300 | G35: =SUM(胡春平!$U$3:$U$1001) -> 76300 | H35: =SUM(Sheet5!$U$3:$U$1001) -> 0 | I35: =SUM(C35:H35) -> 182950 | J35: =COUNTIF(刘丕斌徐少斌夏凯!$U$3:$U$1001,">0")+COUNTIF(陆莹杨凯!$V$3:$V$1001,">0")+COUNTIF(刘坤田超!$V$3:$V$1001,">0")+COUNTIF(陈彪姚永华梅思阳!$V$3:$V$1001,">0")+COUNTIF(胡春平!$U$3:$U$1001,">0")+COUNTIF(Sheet5!$U$3:$U$1001,">0") -> 35
A36: 应收余额（最后还欠多少） | B36: 自动：总应收 − 收款 − 收现 − 收款不开票 | C36: =SUM(刘丕斌徐少斌夏凯!$V$3:$V$1001) -> 56600 | D36: =SUM(陆莹杨凯!$W$3:$W$1001) -> 14750 | E36: =SUM(刘坤田超!$W$3:$W$1001) -> 10000 | F36: =SUM(陈彪姚永华梅思阳!$W$3:$W$1001) -> 25300 | G36: =SUM(胡春平!$V$3:$V$1001) -> 84080 | H36: =SUM(Sheet5!$V$3:$V$1001) -> 0 | I36: =SUM(C36:H36) -> 190730 | J36: =COUNTIF(刘丕斌徐少斌夏凯!$V$3:$V$1001,">0")+COUNTIF(陆莹杨凯!$W$3:$W$1001,">0")+COUNTIF(刘坤田超!$W$3:$W$1001,">0")+COUNTIF(陈彪姚永华梅思阳!$W$3:$W$1001,">0")+COUNTIF(胡春平!$V$3:$V$1001,">0")+COUNTIF(Sheet5!$V$3:$V$1001,">0") -> 37
A39: ④ 按年度看欠款（年度＝合同起始日所在年份；「统计年度」在第 3 行改）：26 年没收完的，27 年在「往年合同」里接着看
A40: 维保组 | B40: 本年度合同 总应收 | C40: 本年度合同 已收 | D40: 本年度合同 应收余额 | E40: 往年合同 应收余额(结转) | F40: 以后年度合同 应收余额 | G40: 没填合同期的 应收余额 | H40: 累计应收余额 (全部)
A41: 刘丕斌徐少斌夏凯 | B41: =SUMIFS(刘丕斌徐少斌夏凯!$L$3:$L$1001,刘丕斌徐少斌夏凯!$AL$3:$AL$1001,统计年度) -> 11200 | C41: =SUMIFS(刘丕斌徐少斌夏凯!$P$3:$P$1001,刘丕斌徐少斌夏凯!$AL$3:$AL$1001,统计年度)+SUMIFS(刘丕斌徐少斌夏凯!$Q$3:$Q$1001,刘丕斌徐少斌夏凯!$AL$3:$AL$1001,统计年度)+SUMIFS(刘丕斌徐少斌夏凯!$R$3:$R$1001,刘丕斌徐少斌夏凯!$AL$3:$AL$1001,统计年度) -> 0 | D41: =SUMIFS(刘丕斌徐少斌夏凯!$V$3:$V$1001,刘丕斌徐少斌夏凯!$AL$3:$AL$1001,统计年度) -> 11200 | E41: =SUMIFS(刘丕斌徐少斌夏凯!$V$3:$V$1001,刘丕斌徐少斌夏凯!$AL$3:$AL$1001,"<"&统计年度) -> 0 | F41: =SUMIFS(刘丕斌徐少斌夏凯!$V$3:$V$1001,刘丕斌徐少斌夏凯!$AL$3:$AL$1001,">"&统计年度) -> 0 | G41: =ROUND($H41-$D41-$E41-$F41,2) -> 45400 | H41: =SUM(刘丕斌徐少斌夏凯!$V$3:$V$1001) -> 56600
A42: 陆莹杨凯 | B42: =SUMIFS(陆莹杨凯!$M$3:$M$1001,陆莹杨凯!$AK$3:$AK$1001,统计年度) -> 14750 | C42: =SUMIFS(陆莹杨凯!$Q$3:$Q$1001,陆莹杨凯!$AK$3:$AK$1001,统计年度)+SUMIFS(陆莹杨凯!$R$3:$R$1001,陆莹杨凯!$AK$3:$AK$1001,统计年度)+SUMIFS(陆莹杨凯!$S$3:$S$1001,陆莹杨凯!$AK$3:$AK$1001,统计年度) -> 0 | D42: =SUMIFS(陆莹杨凯!$W$3:$W$1001,陆莹杨凯!$AK$3:$AK$1001,统计年度) -> 14750 | E42: =SUMIFS(陆莹杨凯!$W$3:$W$1001,陆莹杨凯!$AK$3:$AK$1001,"<"&统计年度) -> 0 | F42: =SUMIFS(陆莹杨凯!$W$3:$W$1001,陆莹杨凯!$AK$3:$AK$1001,">"&统计年度) -> 0 | G42: =ROUND($H42-$D42-$E42-$F42,2) -> 0 | H42: =SUM(陆莹杨凯!$W$3:$W$1001) -> 14750
A43: 刘坤田超 | B43: =SUMIFS(刘坤田超!$M$3:$M$1001,刘坤田超!$AM$3:$AM$1001,统计年度) -> 0 | C43: =SUMIFS(刘坤田超!$Q$3:$Q$1001,刘坤田超!$AM$3:$AM$1001,统计年度)+SUMIFS(刘坤田超!$R$3:$R$1001,刘坤田超!$AM$3:$AM$1001,统计年度)+SUMIFS(刘坤田超!$S$3:$S$1001,刘坤田超!$AM$3:$AM$1001,统计年度) -> 0 | D43: =SUMIFS(刘坤田超!$W$3:$W$1001,刘坤田超!$AM$3:$AM$1001,统计年度) -> 0 | E43: =SUMIFS(刘坤田超!$W$3:$W$1001,刘坤田超!$AM$3:$AM$1001,"<"&统计年度) -> 0 | F43: =SUMIFS(刘坤田超!$W$3:$W$1001,刘坤田超!$AM$3:$AM$1001,">"&统计年度) -> 0 | G43: =ROUND($H43-$D43-$E43-$F43,2) -> 10000 | H43: =SUM(刘坤田超!$W$3:$W$1001) -> 10000
A44: 陈彪姚永华梅思阳 | B44: =SUMIFS(陈彪姚永华梅思阳!$M$3:$M$1001,陈彪姚永华梅思阳!$AM$3:$AM$1001,统计年度) -> 15300 | C44: =SUMIFS(陈彪姚永华梅思阳!$Q$3:$Q$1001,陈彪姚永华梅思阳!$AM$3:$AM$1001,统计年度)+SUMIFS(陈彪姚永华梅思阳!$R$3:$R$1001,陈彪姚永华梅思阳!$AM$3:$AM$1001,统计年度)+SUMIFS(陈彪姚永华梅思阳!$S$3:$S$1001,陈彪姚永华梅思阳!$AM$3:$AM$1001,统计年度) -> 0 | D44: =SUMIFS(陈彪姚永华梅思阳!$W$3:$W$1001,陈彪姚永华梅思阳!$AM$3:$AM$1001,统计年度) -> 15300 | E44: =SUMIFS(陈彪姚永华梅思阳!$W$3:$W$1001,陈彪姚永华梅思阳!$AM$3:$AM$1001,"<"&统计年度) -> 0 | F44: =SUMIFS(陈彪姚永华梅思阳!$W$3:$W$1001,陈彪姚永华梅思阳!$AM$3:$AM$1001,">"&统计年度) -> 0 | G44: =ROUND($H44-$D44-$E44-$F44,2) -> 10000 | H44: =SUM(陈彪姚永华梅思阳!$W$3:$W$1001) -> 25300
A45: 胡春平 | B45: =SUMIFS(胡春平!$L$3:$L$1001,胡春平!$AL$3:$AL$1001,统计年度) -> 59200 | C45: =SUMIFS(胡春平!$P$3:$P$1001,胡春平!$AL$3:$AL$1001,统计年度)+SUMIFS(胡春平!$Q$3:$Q$1001,胡春平!$AL$3:$AL$1001,统计年度)+SUMIFS(胡春平!$R$3:$R$1001,胡春平!$AL$3:$AL$1001,统计年度) -> 7700 | D45: =SUMIFS(胡春平!$V$3:$V$1001,胡春平!$AL$3:$AL$1001,统计年度) -> 51500 | E45: =SUMIFS(胡春平!$V$3:$V$1001,胡春平!$AL$3:$AL$1001,"<"&统计年度) -> 28400 | F45: =SUMIFS(胡春平!$V$3:$V$1001,胡春平!$AL$3:$AL$1001,">"&统计年度) -> 0 | G45: =ROUND($H45-$D45-$E45-$F45,2) -> 4180 | H45: =SUM(胡春平!$V$3:$V$1001) -> 84080
A46: Sheet5（空白模板） | B46: =SUMIFS(Sheet5!$L$3:$L$1001,Sheet5!$AL$3:$AL$1001,统计年度) -> 0 | C46: =SUMIFS(Sheet5!$P$3:$P$1001,Sheet5!$AL$3:$AL$1001,统计年度)+SUMIFS(Sheet5!$Q$3:$Q$1001,Sheet5!$AL$3:$AL$1001,统计年度)+SUMIFS(Sheet5!$R$3:$R$1001,Sheet5!$AL$3:$AL$1001,统计年度) -> 0 | D46: =SUMIFS(Sheet5!$V$3:$V$1001,Sheet5!$AL$3:$AL$1001,统计年度) -> 0 | E46: =SUMIFS(Sheet5!$V$3:$V$1001,Sheet5!$AL$3:$AL$1001,"<"&统计年度) -> 0 | F46: =SUMIFS(Sheet5!$V$3:$V$1001,Sheet5!$AL$3:$AL$1001,">"&统计年度) -> 0 | G46: =ROUND($H46-$D46-$E46-$F46,2) -> 0 | H46: =SUM(Sheet5!$V$3:$V$1001) -> 0
...

Sheet 电梯档案
A1: 注意事项 | B1: 使用单位 | C1: 项目名称 | D1: 型号 | E1: 注册代码 | F1: 963333应急救 援标识牌编号 | G1: 生产厂家 | H1: 梯型 | I1: 层 | J1: 站 | K1: 门 | L1: 载重 | M1: 速度/宽度 | N1: 台量 | O1: 设备编号 | P1: 使用编号 | Q1: 其它(下次年检日期) | R1: 制造 日期 | S1: 限速器校验（下次） | T1: 载重试验125%（下次） | U1: 维保性质 | V1: 维保人员 | W1: 维保状态 | X1: 免保/质保 到期日 | Y1: 维保状态提醒 | Z1: 年检/校验提醒 | AA1: 年检(认出的日期) | AB1: 限速器(认出的日期) | AC1: 载重试验(认出的日期)
B2: 武汉中海联机电工程有限公司 | C2: 滨江苑一期7号楼（汪益新） | D2: KLWG | E2: 3110420100201911Z156 | F2: 110647 | G2: 康力电梯 | H2: 客梯 | I2: 8 | J2: 8 | L2: 800kg | M2: 1.0m/s | N2: 1 | O2: 10045590-0010 | P2: 1#客 | Y2: =IF(TRIM($B2&$C2)="","",IF(OR($W2="安装免保",$W2="技术免保",$W2="质保期内"),IF(NOT(ISNUMBER($X2)),"▲免保到期日没填",IF($X2<TODAY(),"▲免保已到期，转收费",IF($X2-TODAY()<=提醒天数,"免保剩"&($X2-TODAY())&"天","免保中"))),IF($W2="暂停维保","暂停中",IF($W2="已解约","已解约","")))) | Z2: =IF(TRIM($B2&$C2)="","",TRIM(IF($AA2="","",IF($AA2<TODAY(),"年检已过期"&(TODAY()-$AA2)&"天 ",IF($AA2-TODAY()<=提醒天数,"年检剩"&($AA2-TODAY())&"天 ","")))&IF($AB2="","",IF($AB2<TODAY(),"限速器已过期"&(TODAY()-$AB2)&"天 ",IF($AB2-TODAY()<=提醒天数,"限速器剩"&($AB2-TODAY())&"天 ","")))&IF($AC2="","",IF($AC2<TODAY(),"载重试验已过期"&(TODAY()-$AC2)&"天 ",IF($AC2-TODAY()<=提醒天数,"载重试验剩"&($AC2-TODAY())&"天 ",""))))) | AA2: =IF(TRIM($Q2&"")="","",IF(ISNUMBER($Q2),IF($Q2>10000,$Q2,IFERROR(DATE(INT($Q2),IF(ROUND(MOD($Q2,1)*100,0)>12,ROUND(MOD($Q2,1)*10,0),ROUND(MOD($Q2,1)*100,0))+1,0),"")),IFERROR(IF(LEN($Q2)-LEN(SUBSTITUTE($Q2,".",""))>=2,DATEVALUE(SUBSTITUTE(TRIM($Q2),".","-")),DATE(VALUE(LEFT(TRIM($Q2),4)),VALUE(MID(TRIM($Q2),6,2))+1,0)),""))) | AB2: =IF(TRIM($S2&"")="","",IF(ISNUMBER($S2),IF($S2>10000,$S2,IFERROR(DATE(INT($S2),IF(ROUND(MOD($S2,1)*100,0)>12,ROUND(MOD($S2,1)*10,0),ROUND(MOD($S2,1)*100,0))+1,0),"")),IFERROR(IF(LEN($S2)-LEN(SUBSTITUTE($S2,".",""))>=2,DATEVALUE(SUBSTITUTE(TRIM($S2),".","-")),DATE(VALUE(LEFT(TRIM($S2),4)),VALUE(MID(TRIM($S2),6,2))+1,0)),""))) | AC2: =IF(TRIM($T2&"")="","",IF(ISNUMBER($T2),IF($T2>10000,$T2,IFERROR(DATE(INT($T2),IF(ROUND(MOD($T2,1)*100,0)>12,ROUND(MOD($T2,1)*10,0),ROUND(MOD($T2,1)*100,0))+1,0),"")),IFERROR(IF(LEN($T2)-LEN(SUBSTITUTE($T2,".",""))>=2,DATEVALUE(SUBSTITUTE(TRIM($T2),".","-")),DATE(VALUE(LEFT(TRIM($T2),4)),VALUE(MID(TRIM($T2),6,2))+1,0)),"")))
B3: 武汉明海定慧商业管理有限公司 | C3: 六渡桥 | D3: FSLK | E3: 31104201032017070035 | F3: 010829 | G3: 浙江梅轮电梯公司 | H3: 客梯 | I3: 10 | J3: 7 | K3: 7 | L3: 800kg | M3: 1.5m/s | N3: 1 | O3: 17ML-2601 | P3: L1#客 | Y3: =IF(TRIM($B3&$C3)="","",IF(OR($W3="安装免保",$W3="技术免保",$W3="质保期内"),IF(NOT(ISNUMBER($X3)),"▲免保到期日没填",IF($X3<TODAY(),"▲免保已到期，转收费",IF($X3-TODAY()<=提醒天数,"免保剩"&($X3-TODAY())&"天","免保中"))),IF($W3="暂停维保","暂停中",IF($W3="已解约","已解约","")))) | Z3: =IF(TRIM($B3&$C3)="","",TRIM(IF($AA3="","",IF($AA3<TODAY(),"年检已过期"&(TODAY()-$AA3)&"天 ",IF($AA3-TODAY()<=提醒天数,"年检剩"&($AA3-TODAY())&"天 ","")))&IF($AB3="","",IF($AB3<TODAY(),"限速器已过期"&(TODAY()-$AB3)&"天 ",IF($AB3-TODAY()<=提醒天数,"限速器剩"&($AB3-TODAY())&"天 ","")))&IF($AC3="","",IF($AC3<TODAY(),"载重试验已过期"&(TODAY()-$AC3)&"天 ",IF($AC3-TODAY()<=提醒天数,"载重试验剩"&($AC3-TODAY())&"天 ",""))))) | AA3: =IF(TRIM($Q3&"")="","",IF(ISNUMBER($Q3),IF($Q3>10000,$Q3,IFERROR(DATE(INT($Q3),IF(ROUND(MOD($Q3,1)*100,0)>12,ROUND(MOD($Q3,1)*10,0),ROUND(MOD($Q3,1)*100,0))+1,0),"")),IFERROR(IF(LEN($Q3)-LEN(SUBSTITUTE($Q3,".",""))>=2,DATEVALUE(SUBSTITUTE(TRIM($Q3),".","-")),DATE(VALUE(LEFT(TRIM($Q3),4)),VALUE(MID(TRIM($Q3),6,2))+1,0)),""))) | AB3: =IF(TRIM($S3&"")="","",IF(ISNUMBER($S3),IF($S3>10000,$S3,IFERROR(DATE(INT($S3),IF(ROUND(MOD($S3,1)*100,0)>12,ROUND(MOD($S3,1)*10,0),ROUND(MOD($S3,1)*100,0))+1,0),"")),IFERROR(IF(LEN($S3)-LEN(SUBSTITUTE($S3,".",""))>=2,DATEVALUE(SUBSTITUTE(TRIM($S3),".","-")),DATE(VALUE(LEFT(TRIM($S3),4)),VALUE(MID(TRIM($S3),6,2))+1,0)),""))) | AC3: =IF(TRIM($T3&"")="","",IF(ISNUMBER($T3),IF($T3>10000,$T3,IFERROR(DATE(INT($T3),IF(ROUND(MOD($T3,1)*100,0)>12,ROUND(MOD($T3,1)*10,0),ROUND(MOD($T3,1)*100,0))+1,0),"")),IFERROR(IF(LEN($T3)-LEN(SUBSTITUTE($T3,".",""))>=2,DATEVALUE(SUBSTITUTE(TRIM($T3),".","-")),DATE(VALUE(LEFT(TRIM($T3),4)),VALUE(MID(TRIM($T3),6,2))+1,0)),"")))
B4: 武汉华茂医院有限公司 | C4: 圣心医院 | D4: EBJ30 | E4: 3110420100201811X814 | F4: 102951 | G4: 怡达快速电梯 | H4: 客梯 | I4: 4 | J4: 4 | K4: 4 | L4: 1600kg | M4: 1.0m/s | N4: 1 | O4: H070058.1 | P4: 医梯1# | Y4: =IF(TRIM($B4&$C4)="","",IF(OR($W4="安装免保",$W4="技术免保",$W4="质保期内"),IF(NOT(ISNUMBER($X4)),"▲免保到期日没填",IF($X4<TODAY(),"▲免保已到期，转收费",IF($X4-TODAY()<=提醒天数,"免保剩"&($X4-TODAY())&"天","免保中"))),IF($W4="暂停维保","暂停中",IF($W4="已解约","已解约","")))) | Z4: =IF(TRIM($B4&$C4)="","",TRIM(IF($AA4="","",IF($AA4<TODAY(),"年检已过期"&(TODAY()-$AA4)&"天 ",IF($AA4-TODAY()<=提醒天数,"年检剩"&($AA4-TODAY())&"天 ","")))&IF($AB4="","",IF($AB4<TODAY(),"限速器已过期"&(TODAY()-$AB4)&"天 ",IF($AB4-TODAY()<=提醒天数,"限速器剩"&($AB4-TODAY())&"天 ","")))&IF($AC4="","",IF($AC4<TODAY(),"载重试验已过期"&(TODAY()-$AC4)&"天 ",IF($AC4-TODAY()<=提醒天数,"载重试验剩"&($AC4-TODAY())&"天 ",""))))) | AA4: =IF(TRIM($Q4&"")="","",IF(ISNUMBER($Q4),IF($Q4>10000,$Q4,IFERROR(DATE(INT($Q4),IF(ROUND(MOD($Q4,1)*100,0)>12,ROUND(MOD($Q4,1)*10,0),ROUND(MOD($Q4,1)*100,0))+1,0),"")),IFERROR(IF(LEN($Q4)-LEN(SUBSTITUTE($Q4,".",""))>=2,DATEVALUE(SUBSTITUTE(TRIM($Q4),".","-")),DATE(VALUE(LEFT(TRIM($Q4),4)),VALUE(MID(TRIM($Q4),6,2))+1,0)),""))) | AB4: =IF(TRIM($S4&"")="","",IF(ISNUMBER($S4),IF($S4>10000,$S4,IFERROR(DATE(INT($S4),IF(ROUND(MOD($S4,1)*100,0)>12,ROUND(MOD($S4,1)*10,0),ROUND(MOD($S4,1)*100,0))+1,0),"")),IFERROR(IF(LEN($S4)-LEN(SUBSTITUTE($S4,".",""))>=2,DATEVALUE(SUBSTITUTE(TRIM($S4),".","-")),DATE(VALUE(LEFT(TRIM($S4),4)),VALUE(MID(TRIM($S4),6,2))+1,0)),""))) | AC4: =IF(TRIM($T4&"")="","",IF(ISNUMBER($T4),IF($T4>10000,$T4,IFERROR(DATE(INT($T4),IF(ROUND(MOD($T4,1)*100,0)>12,ROUND(MOD($T4,1)*10,0),ROUND(MOD($T4,1)*100,0))+1,0),"")),IFERROR(IF(LEN($T4)-LEN(SUBSTITUTE($T4,".",""))>=2,DATEVALUE(SUBSTITUTE(TRIM($T4),".","-")),DATE(VALUE(LEFT(TRIM($T4),4)),VALUE(MID(TRIM($T4),6,2))+1,0)),"")))
B5: 武汉华茂医院有限公司 | C5: 圣心医院 | D5: EBJ30 | E5: 3110420100201811X815 | F5: 102952 | G5: 怡达快速电梯 | H5: 客梯 | I5: 4 | J5: 4 | K5: 4 | L5: 1600kg | M5: 1.0m/s | N5: 1 | O5: H070058.2 | P5: 医梯2# | Y5: =IF(TRIM($B5&$C5)="","",IF(OR($W5="安装免保",$W5="技术免保",$W5="质保期内"),IF(NOT(ISNUMBER($X5)),"▲免保到期日没填",IF($X5<TODAY(),"▲免保已到期，转收费",IF($X5-TODAY()<=提醒天数,"免保剩"&($X5-TODAY())&"天","免保中"))),IF($W5="暂停维保","暂停中",IF($W5="已解约","已解约","")))) | Z5: =IF(TRIM($B5&$C5)="","",TRIM(IF($AA5="","",IF($AA5<TODAY(),"年检已过期"&(TODAY()-$AA5)&"天 ",IF($AA5-TODAY()<=提醒天数,"年检剩"&($AA5-TODAY())&"天 ","")))&IF($AB5="","",IF($AB5<TODAY(),"限速器已过期"&(TODAY()-$AB5)&"天 ",IF($AB5-TODAY()<=提醒天数,"限速器剩"&($AB5-TODAY())&"天 ","")))&IF($AC5="","",IF($AC5<TODAY(),"载重试验已过期"&(TODAY()-$AC5)&"天 ",IF($AC5-TODAY()<=提醒天数,"载重试验剩"&($AC5-TODAY())&"天 ",""))))) | AA5: =IF(TRIM($Q5&"")="","",IF(ISNUMBER($Q5),IF($Q5>10000,$Q5,IFERROR(DATE(INT($Q5),IF(ROUND(MOD($Q5,1)*100,0)>12,ROUND(MOD($Q5,1)*10,0),ROUND(MOD($Q5,1)*100,0))+1,0),"")),IFERROR(IF(LEN($Q5)-LEN(SUBSTITUTE($Q5,".",""))>=2,DATEVALUE(SUBSTITUTE(TRIM($Q5),".","-")),DATE(VALUE(LEFT(TRIM($Q5),4)),VALUE(MID(TRIM($Q5),6,2))+1,0)),""))) | AB5: =IF(TRIM($S5&"")="","",IF(ISNUMBER($S5),IF($S5>10000,$S5,IFERROR(DATE(INT($S5),IF(ROUND(MOD($S5,1)*100,0)>12,ROUND(MOD($S5,1)*10,0),ROUND(MOD($S5,1)*100,0))+1,0),"")),IFERROR(IF(LEN($S5)-LEN(SUBSTITUTE($S5,".",""))>=2,DATEVALUE(SUBSTITUTE(TRIM($S5),".","-")),DATE(VALUE(LEFT(TRIM($S5),4)),VALUE(MID(TRIM($S5),6,2))+1,0)),""))) | AC5: =IF(TRIM($T5&"")="","",IF(ISNUMBER($T5),IF($T5>10000,$T5,IFERROR(DATE(INT($T5),IF(ROUND(MOD($T5,1)*100,0)>12,ROUND(MOD($T5,1)*10,0),ROUND(MOD($T5,1)*100,0))+1,0),"")),IFERROR(IF(LEN($T5)-LEN(SUBSTITUTE($T5,".",""))>=2,DATEVALUE(SUBSTITUTE(TRIM($T5),".","-")),DATE(VALUE(LEFT(TRIM($T5),4)),VALUE(MID(TRIM($T5),6,2))+1,0)),"")))
B6: 湖北长江人民艺术剧院有限责任公司 | C6: 长江人艺D8小剧场 | D6: MEGA-P | E6: 31104201062025120001 | G6: 住富电梯科技有限公司 | H6: 客梯 | I6: 8 | J6: 8 | K6: 8 | L6: 1500kg | M6: 1.5m/s | N6: 1 | O6: F09193 | P6: 3#客 | Y6: =IF(TRIM($B6&$C6)="","",IF(OR($W6="安装免保",$W6="技术免保",$W6="质保期内"),IF(NOT(ISNUMBER($X6)),"▲免保到期日没填",IF($X6<TODAY(),"▲免保已到期，转收费",IF($X6-TODAY()<=提醒天数,"免保剩"&($X6-TODAY())&"天","免保中"))),IF($W6="暂停维保","暂停中",IF($W6="已解约","已解约","")))) | Z6: =IF(TRIM($B6&$C6)="","",TRIM(IF($AA6="","",IF($AA6<TODAY(),"年检已过期"&(TODAY()-$AA6)&"天 ",IF($AA6-TODAY()<=提醒天数,"年检剩"&($AA6-TODAY())&"天 ","")))&IF($AB6="","",IF($AB6<TODAY(),"限速器已过期"&(TODAY()-$AB6)&"天 ",IF($AB6-TODAY()<=提醒天数,"限速器剩"&($AB6-TODAY())&"天 ","")))&IF($AC6="","",IF($AC6<TODAY(),"载重试验已过期"&(TODAY()-$AC6)&"天 ",IF($AC6-TODAY()<=提醒天数,"载重试验剩"&($AC6-TODAY())&"天 ",""))))) | AA6: =IF(TRIM($Q6&"")="","",IF(ISNUMBER($Q6),IF($Q6>10000,$Q6,IFERROR(DATE(INT($Q6),IF(ROUND(MOD($Q6,1)*100,0)>12,ROUND(MOD($Q6,1)*10,0),ROUND(MOD($Q6,1)*100,0))+1,0),"")),IFERROR(IF(LEN($Q6)-LEN(SUBSTITUTE($Q6,".",""))>=2,DATEVALUE(SUBSTITUTE(TRIM($Q6),".","-")),DATE(VALUE(LEFT(TRIM($Q6),4)),VALUE(MID(TRIM($Q6),6,2))+1,0)),""))) | AB6: =IF(TRIM($S6&"")="","",IF(ISNUMBER($S6),IF($S6>10000,$S6,IFERROR(DATE(INT($S6),IF(ROUND(MOD($S6,1)*100,0)>12,ROUND(MOD($S6,1)*10,0),ROUND(MOD($S6,1)*100,0))+1,0),"")),IFERROR(IF(LEN($S6)-LEN(SUBSTITUTE($S6,".",""))>=2,DATEVALUE(SUBSTITUTE(TRIM($S6),".","-")),DATE(VALUE(LEFT(TRIM($S6),4)),VALUE(MID(TRIM($S6),6,2))+1,0)),""))) | AC6: =IF(TRIM($T6&"")="","",IF(ISNUMBER($T6),IF($T6>10000,$T6,IFERROR(DATE(INT($T6),IF(ROUND(MOD($T6,1)*100,0)>12,ROUND(MOD($T6,1)*10,0),ROUND(MOD($T6,1)*100,0))+1,0),"")),IFERROR(IF(LEN($T6)-LEN(SUBSTITUTE($T6,".",""))>=2,DATEVALUE(SUBSTITUTE(TRIM($T6),".","-")),DATE(VALUE(LEFT(TRIM($T6),4)),VALUE(MID(TRIM($T6),6,2))+1,0)),"")))
B7: 湖北长江人民艺术剧院有限责任公司 | C7: 小东门华中村64号 | D7: MEGA-MRL | E7: 31104201062022100030 | G7: 住友富士 | H7: 客梯(无机房) | I7: 7 | J7: 7 | L7: 1000kg | M7: 1.0m/s | N7: 1 | O7: 908133 | P7: 1#客 | Y7: =IF(TRIM($B7&$C7)="","",IF(OR($W7="安装免保",$W7="技术免保",$W7="质保期内"),IF(NOT(ISNUMBER($X7)),"▲免保到期日没填",IF($X7<TODAY(),"▲免保已到期，转收费",IF($X7-TODAY()<=提醒天数,"免保剩"&($X7-TODAY())&"天","免保中"))),IF($W7="暂停维保","暂停中",IF($W7="已解约","已解约","")))) | Z7: =IF(TRIM($B7&$C7)="","",TRIM(IF($AA7="","",IF($AA7<TODAY(),"年检已过期"&(TODAY()-$AA7)&"天 ",IF($AA7-TODAY()<=提醒天数,"年检剩"&($AA7-TODAY())&"天 ","")))&IF($AB7="","",IF($AB7<TODAY(),"限速器已过期"&(TODAY()-$AB7)&"天 ",IF($AB7-TODAY()<=提醒天数,"限速器剩"&($AB7-TODAY())&"天 ","")))&IF($AC7="","",IF($AC7<TODAY(),"载重试验已过期"&(TODAY()-$AC7)&"天 ",IF($AC7-TODAY()<=提醒天数,"载重试验剩"&($AC7-TODAY())&"天 ",""))))) | AA7: =IF(TRIM($Q7&"")="","",IF(ISNUMBER($Q7),IF($Q7>10000,$Q7,IFERROR(DATE(INT($Q7),IF(ROUND(MOD($Q7,1)*100,0)>12,ROUND(MOD($Q7,1)*10,0),ROUND(MOD($Q7,1)*100,0))+1,0),"")),IFERROR(IF(LEN($Q7)-LEN(SUBSTITUTE($Q7,".",""))>=2,DATEVALUE(SUBSTITUTE(TRIM($Q7),".","-")),DATE(VALUE(LEFT(TRIM($Q7),4)),VALUE(MID(TRIM($Q7),6,2))+1,0)),""))) | AB7: =IF(TRIM($S7&"")="","",IF(ISNUMBER($S7),IF($S7>10000,$S7,IFERROR(DATE(INT($S7),IF(ROUND(MOD($S7,1)*100,0)>12,ROUND(MOD($S7,1)*10,0),ROUND(MOD($S7,1)*100,0))+1,0),"")),IFERROR(IF(LEN($S7)-LEN(SUBSTITUTE($S7,".",""))>=2,DATEVALUE(SUBSTITUTE(TRIM($S7),".","-")),DATE(VALUE(LEFT(TRIM($S7),4)),VALUE(MID(TRIM($S7),6,2))+1,0)),""))) | AC7: =IF(TRIM($T7&"")="","",IF(ISNUMBER($T7),IF($T7>10000,$T7,IFERROR(DATE(INT($T7),IF(ROUND(MOD($T7,1)*100,0)>12,ROUND(MOD($T7,1)*10,0),ROUND(MOD($T7,1)*100,0))+1,0),"")),IFERROR(IF(LEN($T7)-LEN(SUBSTITUTE($T7,".",""))>=2,DATEVALUE(SUBSTITUTE(TRIM($T7),".","-")),DATE(VALUE(LEFT(TRIM($T7),4)),VALUE(MID(TRIM($T7),6,2))+1,0)),"")))
B8: 湖北长江人民艺术剧院有限责任公司 | C8: 小东门华中村64号 | D8: MEGA-MRL | E8: 31104201062022100031 | G8: 住友富士 | H8: 客梯(无机房) | I8: 7 | J8: 7 | L8: 1000kg | M8: 1.0m/s | N8: 1 | O8: 908134 | P8: 2#客 | Y8: =IF(TRIM($B8&$C8)="","",IF(OR($W8="安装免保",$W8="技术免保",$W8="质保期内"),IF(NOT(ISNUMBER($X8)),"▲免保到期日没填",IF($X8<TODAY(),"▲免保已到期，转收费",IF($X8-TODAY()<=提醒天数,"免保剩"&($X8-TODAY())&"天","免保中"))),IF($W8="暂停维保","暂停中",IF($W8="已解约","已解约","")))) | Z8: =IF(TRIM($B8&$C8)="","",TRIM(IF($AA8="","",IF($AA8<TODAY(),"年检已过期"&(TODAY()-$AA8)&"天 ",IF($AA8-TODAY()<=提醒天数,"年检剩"&($AA8-TODAY())&"天 ","")))&IF($AB8="","",IF($AB8<TODAY(),"限速器已过期"&(TODAY()-$AB8)&"天 ",IF($AB8-TODAY()<=提醒天数,"限速器剩"&($AB8-TODAY())&"天 ","")))&IF($AC8="","",IF($AC8<TODAY(),"载重试验已过期"&(TODAY()-$AC8)&"天 ",IF($AC8-TODAY()<=提醒天数,"载重试验剩"&($AC8-TODAY())&"天 ",""))))) | AA8: =IF(TRIM($Q8&"")="","",IF(ISNUMBER($Q8),IF($Q8>10000,$Q8,IFERROR(DATE(INT($Q8),IF(ROUND(MOD($Q8,1)*100,0)>12,ROUND(MOD($Q8,1)*10,0),ROUND(MOD($Q8,1)*100,0))+1,0),"")),IFERROR(IF(LEN($Q8)-LEN(SUBSTITUTE($Q8,".",""))>=2,DATEVALUE(SUBSTITUTE(TRIM($Q8),".","-")),DATE(VALUE(LEFT(TRIM($Q8),4)),VALUE(MID(TRIM($Q8),6,2))+1,0)),""))) | AB8: =IF(TRIM($S8&"")="","",IF(ISNUMBER($S8),IF($S8>10000,$S8,IFERROR(DATE(INT($S8),IF(ROUND(MOD($S8,1)*100,0)>12,ROUND(MOD($S8,1)*10,0),ROUND(MOD($S8,1)*100,0))+1,0),"")),IFERROR(IF(LEN($S8)-LEN(SUBSTITUTE($S8,".",""))>=2,DATEVALUE(SUBSTITUTE(TRIM($S8),".","-")),DATE(VALUE(LEFT(TRIM($S8),4)),VALUE(MID(TRIM($S8),6,2))+1,0)),""))) | AC8: =IF(TRIM($T8&"")="","",IF(ISNUMBER($T8),IF($T8>10000,$T8,IFERROR(DATE(INT($T8),IF(ROUND(MOD($T8,1)*100,0)>12,ROUND(MOD($T8,1)*10,0),ROUND(MOD($T8,1)*100,0))+1,0),"")),IFERROR(IF(LEN($T8)-LEN(SUBSTITUTE($T8,".",""))>=2,DATEVALUE(SUBSTITUTE(TRIM($T8),".","-")),DATE(VALUE(LEFT(TRIM($T8),4)),VALUE(MID(TRIM($T8),6,2))+1,0)),"")))
B9: 金禧建设集团有限公司 | C9: 金禧中北路221号 | D9: MTP | E9: 31104201062019090001 | F9: 095986 | G9: 曼隆蒂森克虏伯电梯 | H9: 客梯 | I9: 11 | J9: 11 | L9: 1000kg | M9: 1.75m/s | N9: 1 | O9: M19NJ1136 | P9: 1# | Y9: =IF(TRIM($B9&$C9)="","",IF(OR($W9="安装免保",$W9="技术免保",$W9="质保期内"),IF(NOT(ISNUMBER($X9)),"▲免保到期日没填",IF($X9<TODAY(),"▲免保已到期，转收费",IF($X9-TODAY()<=提醒天数,"免保剩"&($X9-TODAY())&"天","免保中"))),IF($W9="暂停维保","暂停中",IF($W9="已解约","已解约","")))) | Z9: =IF(TRIM($B9&$C9)="","",TRIM(IF($AA9="","",IF($AA9<TODAY(),"年检已过期"&(TODAY()-$AA9)&"天 ",IF($AA9-TODAY()<=提醒天数,"年检剩"&($AA9-TODAY())&"天 ","")))&IF($AB9="","",IF($AB9<TODAY(),"限速器已过期"&(TODAY()-$AB9)&"天 ",IF($AB9-TODAY()<=提醒天数,"限速器剩"&($AB9-TODAY())&"天 ","")))&IF($AC9="","",IF($AC9<TODAY(),"载重试验已过期"&(TODAY()-$AC9)&"天 ",IF($AC9-TODAY()<=提醒天数,"载重试验剩"&($AC9-TODAY())&"天 ",""))))) | AA9: =IF(TRIM($Q9&"")="","",IF(ISNUMBER($Q9),IF($Q9>10000,$Q9,IFERROR(DATE(INT($Q9),IF(ROUND(MOD($Q9,1)*100,0)>12,ROUND(MOD($Q9,1)*10,0),ROUND(MOD($Q9,1)*100,0))+1,0),"")),IFERROR(IF(LEN($Q9)-LEN(SUBSTITUTE($Q9,".",""))>=2,DATEVALUE(SUBSTITUTE(TRIM($Q9),".","-")),DATE(VALUE(LEFT(TRIM($Q9),4)),VALUE(MID(TRIM($Q9),6,2))+1,0)),""))) | AB9: =IF(TRIM($S9&"")="","",IF(ISNUMBER($S9),IF($S9>10000,$S9,IFERROR(DATE(INT($S9),IF(ROUND(MOD($S9,1)*100,0)>12,ROUND(MOD($S9,1)*10,0),ROUND(MOD($S9,1)*100,0))+1,0),"")),IFERROR(IF(LEN($S9)-LEN(SUBSTITUTE($S9,".",""))>=2,DATEVALUE(SUBSTITUTE(TRIM($S9),".","-")),DATE(VALUE(LEFT(TRIM($S9),4)),VALUE(MID(TRIM($S9),6,2))+1,0)),""))) | AC9: =IF(TRIM($T9&"")="","",IF(ISNUMBER($T9),IF($T9>10000,$T9,IFERROR(DATE(INT($T9),IF(ROUND(MOD($T9,1)*100,0)>12,ROUND(MOD($T9,1)*10,0),ROUND(MOD($T9,1)*100,0))+1,0),"")),IFERROR(IF(LEN($T9)-LEN(SUBSTITUTE($T9,".",""))>=2,DATEVALUE(SUBSTITUTE(TRIM($T9),".","-")),DATE(VALUE(LEFT(TRIM($T9),4)),VALUE(MID(TRIM($T9),6,2))+1,0)),"")))
B10: 湖北南远电缆科技有限公司 | C10: 南远电缆 | D10: LTHX2000/0.5-VF | E10: 31204201002018051055 | F10: 099118 | G10: 菱王电梯股份有限公司 | H10: 货梯 | I10: 4 | J10: 4 | L10: 2000kg | M10: 0.5m/s | N10: 1 | O10: 17H002199 | P10: 1#货梯 | Y10: =IF(TRIM($B10&$C10)="","",IF(OR($W10="安装免保",$W10="技术免保",$W10="质保期内"),IF(NOT(ISNUMBER($X10)),"▲免保到期日没填",IF($X10<TODAY(),"▲免保已到期，转收费",IF($X10-TODAY()<=提醒天数,"免保剩"&($X10-TODAY())&"天","免保中"))),IF($W10="暂停维保","暂停中",IF($W10="已解约","已解约","")))) | Z10: =IF(TRIM($B10&$C10)="","",TRIM(IF($AA10="","",IF($AA10<TODAY(),"年检已过期"&(TODAY()-$AA10)&"天 ",IF($AA10-TODAY()<=提醒天数,"年检剩"&($AA10-TODAY())&"天 ","")))&IF($AB10="","",IF($AB10<TODAY(),"限速器已过期"&(TODAY()-$AB10)&"天 ",IF($AB10-TODAY()<=提醒天数,"限速器剩"&($AB10-TODAY())&"天 ","")))&IF($AC10="","",IF($AC10<TODAY(),"载重试验已过期"&(TODAY()-$AC10)&"天 ",IF($AC10-TODAY()<=提醒天数,"载重试验剩"&($AC10-TODAY())&"天 ",""))))) | AA10: =IF(TRIM($Q10&"")="","",IF(ISNUMBER($Q10),IF($Q10>10000,$Q10,IFERROR(DATE(INT($Q10),IF(ROUND(MOD($Q10,1)*100,0)>12,ROUND(MOD($Q10,1)*10,0),ROUND(MOD($Q10,1)*100,0))+1,0),"")),IFERROR(IF(LEN($Q10)-LEN(SUBSTITUTE($Q10,".",""))>=2,DATEVALUE(SUBSTITUTE(TRIM($Q10),".","-")),DATE(VALUE(LEFT(TRIM($Q10),4)),VALUE(MID(TRIM($Q10),6,2))+1,0)),""))) | AB10: =IF(TRIM($S10&"")="","",IF(ISNUMBER($S10),IF($S10>10000,$S10,IFERROR(DATE(INT($S10),IF(ROUND(MOD($S10,1)*100,0)>12,ROUND(MOD($S10,1)*10,0),ROUND(MOD($S10,1)*100,0))+1,0),"")),IFERROR(IF(LEN($S10)-LEN(SUBSTITUTE($S10,".",""))>=2,DATEVALUE(SUBSTITUTE(TRIM($S10),".","-")),DATE(VALUE(LEFT(TRIM($S10),4)),VALUE(MID(TRIM($S10),6,2))+1,0)),""))) | AC10: =IF(TRIM($T10&"")="","",IF(ISNUMBER($T10),IF($T10>10000,$T10,IFERROR(DATE(INT($T10),IF(ROUND(MOD($T10,1)*100,0)>12,ROUND(MOD($T10,1)*10,0),ROUND(MOD($T10,1)*100,0))+1,0),"")),IFERROR(IF(LEN($T10)-LEN(SUBSTITUTE($T10,".",""))>=2,DATEVALUE(SUBSTITUTE(TRIM($T10),".","-")),DATE(VALUE(LEFT(TRIM($T10),4)),VALUE(MID(TRIM($T10),6,2))+1,0)),"")))
B11: 湖北南远电缆科技有限公司 | C11: 南远电缆 | D11: CHOI-III | E11: 31104201012022107422 | G11: 沈阳远大智能工业集团 | H11: 客梯 | I11: 6 | J11: 6 | K11: 6 | L11: 1600kg | M11: 1.0m/s | N11: 1 | O11: BLTSY22K/20366 | P11: L1#客梯 | Y11: =IF(TRIM($B11&$C11)="","",IF(OR($W11="安装免保",$W11="技术免保",$W11="质保期内"),IF(NOT(ISNUMBER($X11)),"▲免保到期日没填",IF($X11<TODAY(),"▲免保已到期，转收费",IF($X11-TODAY()<=提醒天数,"免保剩"&($X11-TODAY())&"天","免保中"))),IF($W11="暂停维保","暂停中",IF($W11="已解约","已解约","")))) | Z11: =IF(TRIM($B11&$C11)="","",TRIM(IF($AA11="","",IF($AA11<TODAY(),"年检已过期"&(TODAY()-$AA11)&"天 ",IF($AA11-TODAY()<=提醒天数,"年检剩"&($AA11-TODAY())&"天 ","")))&IF($AB11="","",IF($AB11<TODAY(),"限速器已过期"&(TODAY()-$AB11)&"天 ",IF($AB11-TODAY()<=提醒天数,"限速器剩"&($AB11-TODAY())&"天 ","")))&IF($AC11="","",IF($AC11<TODAY(),"载重试验已过期"&(TODAY()-$AC11)&"天 ",IF($AC11-TODAY()<=提醒天数,"载重试验剩"&($AC11-TODAY())&"天 ",""))))) | AA11: =IF(TRIM($Q11&"")="","",IF(ISNUMBER($Q11),IF($Q11>10000,$Q11,IFERROR(DATE(INT($Q11),IF(ROUND(MOD($Q11,1)*100,0)>12,ROUND(MOD($Q11,1)*10,0),ROUND(MOD($Q11,1)*100,0))+1,0),"")),IFERROR(IF(LEN($Q11)-LEN(SUBSTITUTE($Q11,".",""))>=2,DATEVALUE(SUBSTITUTE(TRIM($Q11),".","-")),DATE(VALUE(LEFT(TRIM($Q11),4)),VALUE(MID(TRIM($Q11),6,2))+1,0)),""))) | AB11: =IF(TRIM($S11&"")="","",IF(ISNUMBER($S11),IF($S11>10000,$S11,IFERROR(DATE(INT($S11),IF(ROUND(MOD($S11,1)*100,0)>12,ROUND(MOD($S11,1)*10,0),ROUND(MOD($S11,1)*100,0))+1,0),"")),IFERROR(IF(LEN($S11)-LEN(SUBSTITUTE($S11,".",""))>=2,DATEVALUE(SUBSTITUTE(TRIM($S11),".","-")),DATE(VALUE(LEFT(TRIM($S11),4)),VALUE(MID(TRIM($S11),6,2))+1,0)),""))) | AC11: =IF(TRIM($T11&"")="","",IF(ISNUMBER($T11),IF($T11>10000,$T11,IFERROR(DATE(INT($T11),IF(ROUND(MOD($T11,1)*100,0)>12,ROUND(MOD($T11,1)*10,0),ROUND(MOD($T11,1)*100,0))+1,0),"")),IFERROR(IF(LEN($T11)-LEN(SUBSTITUTE($T11,".",""))>=2,DATEVALUE(SUBSTITUTE(TRIM($T11),".","-")),DATE(VALUE(LEFT(TRIM($T11),4)),VALUE(MID(TRIM($T11),6,2))+1,0)),"")))
B12: 武汉市黄陂区鑫捷惠超市（个体工商户） | C12: 黄陂雅迪 | D12: F2000D05S-C0 | E12: 30134201162013060001 | F12: 092260 | G12: 江南嘉捷电梯 | H12: 货梯 | I12: 4 | J12: 4 | L12: 2000kg | M12: 0.5m/s | N12: 1 | O12: 12J50060 | P12: 1#货 | Y12: =IF(TRIM($B12&$C12)="","",IF(OR($W12="安装免保",$W12="技术免保",$W12="质保期内"),IF(NOT(ISNUMBER($X12)),"▲免保到期日没填",IF($X12<TODAY(),"▲免保已到期，转收费",IF($X12-TODAY()<=提醒天数,"免保剩"&($X12-TODAY())&"天","免保中"))),IF($W12="暂停维保","暂停中",IF($W12="已解约","已解约","")))) | Z12: =IF(TRIM($B12&$C12)="","",TRIM(IF($AA12="","",IF($AA12<TODAY(),"年检已过期"&(TODAY()-$AA12)&"天 ",IF($AA12-TODAY()<=提醒天数,"年检剩"&($AA12-TODAY())&"天 ","")))&IF($AB12="","",IF($AB12<TODAY(),"限速器已过期"&(TODAY()-$AB12)&"天 ",IF($AB12-TODAY()<=提醒天数,"限速器剩"&($AB12-TODAY())&"天 ","")))&IF($AC12="","",IF($AC12<TODAY(),"载重试验已过期"&(TODAY()-$AC12)&"天 ",IF($AC12-TODAY()<=提醒天数,"载重试验剩"&($AC12-TODAY())&"天 ",""))))) | AA12: =IF(TRIM($Q12&"")="","",IF(ISNUMBER($Q12),IF($Q12>10000,$Q12,IFERROR(DATE(INT($Q12),IF(ROUND(MOD($Q12,1)*100,0)>12,ROUND(MOD($Q12,1)*10,0),ROUND(MOD($Q12,1)*100,0))+1,0),"")),IFERROR(IF(LEN($Q12)-LEN(SUBSTITUTE($Q12,".",""))>=2,DATEVALUE(SUBSTITUTE(TRIM($Q12),".","-")),DATE(VALUE(LEFT(TRIM($Q12),4)),VALUE(MID(TRIM($Q12),6,2))+1,0)),""))) | AB12: =IF(TRIM($S12&"")="","",IF(ISNUMBER($S12),IF($S12>10000,$S12,IFERROR(DATE(INT($S12),IF(ROUND(MOD($S12,1)*100,0)>12,ROUND(MOD($S12,1)*10,0),ROUND(MOD($S12,1)*100,0))+1,0),"")),IFERROR(IF(LEN($S12)-LEN(SUBSTITUTE($S12,".",""))>=2,DATEVALUE(SUBSTITUTE(TRIM($S12),".","-")),DATE(VALUE(LEFT(TRIM($S12),4)),VALUE(MID(TRIM($S12),6,2))+1,0)),""))) | AC12: =IF(TRIM($T12&"")="","",IF(ISNUMBER($T12),IF($T12>10000,$T12,IFERROR(DATE(INT($T12),IF(ROUND(MOD($T12,1)*100,0)>12,ROUND(MOD($T12,1)*10,0),ROUND(MOD($T12,1)*100,0))+1,0),"")),IFERROR(IF(LEN($T12)-LEN(SUBSTITUTE($T12,".",""))>=2,DATEVALUE(SUBSTITUTE(TRIM($T12),".","-")),DATE(VALUE(LEFT(TRIM($T12),4)),VALUE(MID(TRIM($T12),6,2))+1,0)),"")))
B13: 武汉尊品益康意食品有限公司 | C13: 意康意厂房 | D13: LTHX | E13: 31204201002019073047 | F13: 108416 | G13: 菱王电梯股份有限公司 | H13: 货梯 | I13: 5 | J13: 5 | L13: 2000kg | M13: 0.5m/s | N13: 1 | O13: 18H001296 | P13: 1#货 | Y13: =IF(TRIM($B13&$C13)="","",IF(OR($W13="安装免保",$W13="技术免保",$W13="质保期内"),IF(NOT(ISNUMBER($X13)),"▲免保到期日没填",IF($X13<TODAY(),"▲免保已到期，转收费",IF($X13-TODAY()<=提醒天数,"免保剩"&($X13-TODAY())&"天","免保中"))),IF($W13="暂停维保","暂停中",IF($W13="已解约","已解约","")))) | Z13: =IF(TRIM($B13&$C13)="","",TRIM(IF($AA13="","",IF($AA13<TODAY(),"年检已过期"&(TODAY()-$AA13)&"天 ",IF($AA13-TODAY()<=提醒天数,"年检剩"&($AA13-TODAY())&"天 ","")))&IF($AB13="","",IF($AB13<TODAY(),"限速器已过期"&(TODAY()-$AB13)&"天 ",IF($AB13-TODAY()<=提醒天数,"限速器剩"&($AB13-TODAY())&"天 ","")))&IF($AC13="","",IF($AC13<TODAY(),"载重试验已过期"&(TODAY()-$AC13)&"天 ",IF($AC13-TODAY()<=提醒天数,"载重试验剩"&($AC13-TODAY())&"天 ",""))))) | AA13: =IF(TRIM($Q13&"")="","",IF(ISNUMBER($Q13),IF($Q13>10000,$Q13,IFERROR(DATE(INT($Q13),IF(ROUND(MOD($Q13,1)*100,0)>12,ROUND(MOD($Q13,1)*10,0),ROUND(MOD($Q13,1)*100,0))+1,0),"")),IFERROR(IF(LEN($Q13)-LEN(SUBSTITUTE($Q13,".",""))>=2,DATEVALUE(SUBSTITUTE(TRIM($Q13),".","-")),DATE(VALUE(LEFT(TRIM($Q13),4)),VALUE(MID(TRIM($Q13),6,2))+1,0)),""))) | AB13: =IF(TRIM($S13&"")="","",IF(ISNUMBER($S13),IF($S13>10000,$S13,IFERROR(DATE(INT($S13),IF(ROUND(MOD($S13,1)*100,0)>12,ROUND(MOD($S13,1)*10,0),ROUND(MOD($S13,1)*100,0))+1,0),"")),IFERROR(IF(LEN($S13)-LEN(SUBSTITUTE($S13,".",""))>=2,DATEVALUE(SUBSTITUTE(TRIM($S13),".","-")),DATE(VALUE(LEFT(TRIM($S13),4)),VALUE(MID(TRIM($S13),6,2))+1,0)),""))) | AC13: =IF(TRIM($T13&"")="","",IF(ISNUMBER($T13),IF($T13>10000,$T13,IFERROR(DATE(INT($T13),IF(ROUND(MOD($T13,1)*100,0)>12,ROUND(MOD($T13,1)*10,0),ROUND(MOD($T13,1)*100,0))+1,0),"")),IFERROR(IF(LEN($T13)-LEN(SUBSTITUTE($T13,".",""))>=2,DATEVALUE(SUBSTITUTE(TRIM($T13),".","-")),DATE(VALUE(LEFT(TRIM($T13),4)),VALUE(MID(TRIM($T13),6,2))+1,0)),"")))
B14: 武汉尊品益康意食品有限公司 | C14: 意康意厂房 | D14: LTHX | E14: 31204201002019073048 | F14: 108417 | G14: 菱王电梯股份有限公司 | H14: 货梯 | I14: 5 | J14: 5 | L14: 2000kg | M14: 0.5m/s | N14: 1 | O14: 18H001297 | P14: 2#货 | Y14: =IF(TRIM($B14&$C14)="","",IF(OR($W14="安装免保",$W14="技术免保",$W14="质保期内"),IF(NOT(ISNUMBER($X14)),"▲免保到期日没填",IF($X14<TODAY(),"▲免保已到期，转收费",IF($X14-TODAY()<=提醒天数,"免保剩"&($X14-TODAY())&"天","免保中"))),IF($W14="暂停维保","暂停中",IF($W14="已解约","已解约","")))) | Z14: =IF(TRIM($B14&$C14)="","",TRIM(IF($AA14="","",IF($AA14<TODAY(),"年检已过期"&(TODAY()-$AA14)&"天 ",IF($AA14-TODAY()<=提醒天数,"年检剩"&($AA14-TODAY())&"天 ","")))&IF($AB14="","",IF($AB14<TODAY(),"限速器已过期"&(TODAY()-$AB14)&"天 ",IF($AB14-TODAY()<=提醒天数,"限速器剩"&($AB14-TODAY())&"天 ","")))&IF($AC14="","",IF($AC14<TODAY(),"载重试验已过期"&(TODAY()-$AC14)&"天 ",IF($AC14-TODAY()<=提醒天数,"载重试验剩"&($AC14-TODAY())&"天 ",""))))) | AA14: =IF(TRIM($Q14&"")="","",IF(ISNUMBER($Q14),IF($Q14>10000,$Q14,IFERROR(DATE(INT($Q14),IF(ROUND(MOD($Q14,1)*100,0)>12,ROUND(MOD($Q14,1)*10,0),ROUND(MOD($Q14,1)*100,0))+1,0),"")),IFERROR(IF(LEN($Q14)-LEN(SUBSTITUTE($Q14,".",""))>=2,DATEVALUE(SUBSTITUTE(TRIM($Q14),".","-")),DATE(VALUE(LEFT(TRIM($Q14),4)),VALUE(MID(TRIM($Q14),6,2))+1,0)),""))) | AB14: =IF(TRIM($S14&"")="","",IF(ISNUMBER($S14),IF($S14>10000,$S14,IFERROR(DATE(INT($S14),IF(ROUND(MOD($S14,1)*100,0)>12,ROUND(MOD($S14,1)*10,0),ROUND(MOD($S14,1)*100,0))+1,0),"")),IFERROR(IF(LEN($S14)-LEN(SUBSTITUTE($S14,".",""))>=2,DATEVALUE(SUBSTITUTE(TRIM($S14),".","-")),DATE(VALUE(LEFT(TRIM($S14),4)),VALUE(MID(TRIM($S14),6,2))+1,0)),""))) | AC14: =IF(TRIM($T14&"")="","",IF(ISNUMBER($T14),IF($T14>10000,$T14,IFERROR(DATE(INT($T14),IF(ROUND(MOD($T14,1)*100,0)>12,ROUND(MOD($T14,1)*10,0),ROUND(MOD($T14,1)*100,0))+1,0),"")),IFERROR(IF(LEN($T14)-LEN(SUBSTITUTE($T14,".",""))>=2,DATEVALUE(SUBSTITUTE(TRIM($T14),".","-")),DATE(VALUE(LEFT(TRIM($T14),4)),VALUE(MID(TRIM($T14),6,2))+1,0)),"")))
B15: 武汉尊品益康意食品有限公司 | C15: 意康意厂房 | D15: LTHX | E15: 31204201002019073049 | F15: 108418 | G15: 菱王电梯股份有限公司 | H15: 货梯 | I15: 5 | J15: 5 | L15: 2000kg | M15: 0.5m/s | N15: 1 | O15: 18H001298 | P15: 3#货 | Y15: =IF(TRIM($B15&$C15)="","",IF(OR($W15="安装免保",$W15="技术免保",$W15="质保期内"),IF(NOT(ISNUMBER($X15)),"▲免保到期日没填",IF($X15<TODAY(),"▲免保已到期，转收费",IF($X15-TODAY()<=提醒天数,"免保剩"&($X15-TODAY())&"天","免保中"))),IF($W15="暂停维保","暂停中",IF($W15="已解约","已解约","")))) | Z15: =IF(TRIM($B15&$C15)="","",TRIM(IF($AA15="","",IF($AA15<TODAY(),"年检已过期"&(TODAY()-$AA15)&"天 ",IF($AA15-TODAY()<=提醒天数,"年检剩"&($AA15-TODAY())&"天 ","")))&IF($AB15="","",IF($AB15<TODAY(),"限速器已过期"&(TODAY()-$AB15)&"天 ",IF($AB15-TODAY()<=提醒天数,"限速器剩"&($AB15-TODAY())&"天 ","")))&IF($AC15="","",IF($AC15<TODAY(),"载重试验已过期"&(TODAY()-$AC15)&"天 ",IF($AC15-TODAY()<=提醒天数,"载重试验剩"&($AC15-TODAY())&"天 ",""))))) | AA15: =IF(TRIM($Q15&"")="","",IF(ISNUMBER($Q15),IF($Q15>10000,$Q15,IFERROR(DATE(INT($Q15),IF(ROUND(MOD($Q15,1)*100,0)>12,ROUND(MOD($Q15,1)*10,0),ROUND(MOD($Q15,1)*100,0))+1,0),"")),IFERROR(IF(LEN($Q15)-LEN(SUBSTITUTE($Q15,".",""))>=2,DATEVALUE(SUBSTITUTE(TRIM($Q15),".","-")),DATE(VALUE(LEFT(TRIM($Q15),4)),VALUE(MID(TRIM($Q15),6,2))+1,0)),""))) | AB15: =IF(TRIM($S15&"")="","",IF(ISNUMBER($S15),IF($S15>10000,$S15,IFERROR(DATE(INT($S15),IF(ROUND(MOD($S15,1)*100,0)>12,ROUND(MOD($S15,1)*10,0),ROUND(MOD($S15,1)*100,0))+1,0),"")),IFERROR(IF(LEN($S15)-LEN(SUBSTITUTE($S15,".",""))>=2,DATEVALUE(SUBSTITUTE(TRIM($S15),".","-")),DATE(VALUE(LEFT(TRIM($S15),4)),VALUE(MID(TRIM($S15),6,2))+1,0)),""))) | AC15: =IF(TRIM($T15&"")="","",IF(ISNUMBER($T15),IF($T15>10000,$T15,IFERROR(DATE(INT($T15),IF(ROUND(MOD($T15,1)*100,0)>12,ROUND(MOD($T15,1)*10,0),ROUND(MOD($T15,1)*100,0))+1,0),"")),IFERROR(IF(LEN($T15)-LEN(SUBSTITUTE($T15,".",""))>=2,DATEVALUE(SUBSTITUTE(TRIM($T15),".","-")),DATE(VALUE(LEFT(TRIM($T15),4)),VALUE(MID(TRIM($T15),6,2))+1,0)),"")))
B16: 武汉尊品益康意食品有限公司 | C16: 意康意厂房 | D16: LTHX | E16: 31204201002019073050 | F16: 108419 | G16: 菱王电梯股份有限公司 | H16: 货梯 | I16: 6 | J16: 6 | L16: 2000kg | M16: 0.5m/s | N16: 1 | O16: 18H001299 | P16: 4#货 | Y16: =IF(TRIM($B16&$C16)="","",IF(OR($W16="安装免保",$W16="技术免保",$W16="质保期内"),IF(NOT(ISNUMBER($X16)),"▲免保到期日没填",IF($X16<TODAY(),"▲免保已到期，转收费",IF($X16-TODAY()<=提醒天数,"免保剩"&($X16-TODAY())&"天","免保中"))),IF($W16="暂停维保","暂停中",IF($W16="已解约","已解约","")))) | Z16: =IF(TRIM($B16&$C16)="","",TRIM(IF($AA16="","",IF($AA16<TODAY(),"年检已过期"&(TODAY()-$AA16)&"天 ",IF($AA16-TODAY()<=提醒天数,"年检剩"&($AA16-TODAY())&"天 ","")))&IF($AB16="","",IF($AB16<TODAY(),"限速器已过期"&(TODAY()-$AB16)&"天 ",IF($AB16-TODAY()<=提醒天数,"限速器剩"&($AB16-TODAY())&"天 ","")))&IF($AC16="","",IF($AC16<TODAY(),"载重试验已过期"&(TODAY()-$AC16)&"天 ",IF($AC16-TODAY()<=提醒天数,"载重试验剩"&($AC16-TODAY())&"天 ",""))))) | AA16: =IF(TRIM($Q16&"")="","",IF(ISNUMBER($Q16),IF($Q16>10000,$Q16,IFERROR(DATE(INT($Q16),IF(ROUND(MOD($Q16,1)*100,0)>12,ROUND(MOD($Q16,1)*10,0),ROUND(MOD($Q16,1)*100,0))+1,0),"")),IFERROR(IF(LEN($Q16)-LEN(SUBSTITUTE($Q16,".",""))>=2,DATEVALUE(SUBSTITUTE(TRIM($Q16),".","-")),DATE(VALUE(LEFT(TRIM($Q16),4)),VALUE(MID(TRIM($Q16),6,2))+1,0)),""))) | AB16: =IF(TRIM($S16&"")="","",IF(ISNUMBER($S16),IF($S16>10000,$S16,IFERROR(DATE(INT($S16),IF(ROUND(MOD($S16,1)*100,0)>12,ROUND(MOD($S16,1)*10,0),ROUND(MOD($S16,1)*100,0))+1,0),"")),IFERROR(IF(LEN($S16)-LEN(SUBSTITUTE($S16,".",""))>=2,DATEVALUE(SUBSTITUTE(TRIM($S16),".","-")),DATE(VALUE(LEFT(TRIM($S16),4)),VALUE(MID(TRIM($S16),6,2))+1,0)),""))) | AC16: =IF(TRIM($T16&"")="","",IF(ISNUMBER($T16),IF($T16>10000,$T16,IFERROR(DATE(INT($T16),IF(ROUND(MOD($T16,1)*100,0)>12,ROUND(MOD($T16,1)*10,0),ROUND(MOD($T16,1)*100,0))+1,0),"")),IFERROR(IF(LEN($T16)-LEN(SUBSTITUTE($T16,".",""))>=2,DATEVALUE(SUBSTITUTE(TRIM($T16),".","-")),DATE(VALUE(LEFT(TRIM($T16),4)),VALUE(MID(TRIM($T16),6,2))+1,0)),"")))
B17: 武汉尊品益康意食品有限公司 | C17: 意康意厂房 | D17: LTK | E17: 3110420100201907Z115 | F17: 108415 | G17: 菱王电梯股份有限公司 | H17: 客梯 | I17: 6 | J17: 6 | L17: 1050kg | M17: 1.0m/s | N17: 1 | O17: 18K001875 | P17: 1#客 | Y17: =IF(TRIM($B17&$C17)="","",IF(OR($W17="安装免保",$W17="技术免保",$W17="质保期内"),IF(NOT(ISNUMBER($X17)),"▲免保到期日没填",IF($X17<TODAY(),"▲免保已到期，转收费",IF($X17-TODAY()<=提醒天数,"免保剩"&($X17-TODAY())&"天","免保中"))),IF($W17="暂停维保","暂停中",IF($W17="已解约","已解约","")))) | Z17: =IF(TRIM($B17&$C17)="","",TRIM(IF($AA17="","",IF($AA17<TODAY(),"年检已过期"&(TODAY()-$AA17)&"天 ",IF($AA17-TODAY()<=提醒天数,"年检剩"&($AA17-TODAY())&"天 ","")))&IF($AB17="","",IF($AB17<TODAY(),"限速器已过期"&(TODAY()-$AB17)&"天 ",IF($AB17-TODAY()<=提醒天数,"限速器剩"&($AB17-TODAY())&"天 ","")))&IF($AC17="","",IF($AC17<TODAY(),"载重试验已过期"&(TODAY()-$AC17)&"天 ",IF($AC17-TODAY()<=提醒天数,"载重试验剩"&($AC17-TODAY())&"天 ",""))))) | AA17: =IF(TRIM($Q17&"")="","",IF(ISNUMBER($Q17),IF($Q17>10000,$Q17,IFERROR(DATE(INT($Q17),IF(ROUND(MOD($Q17,1)*100,0)>12,ROUND(MOD($Q17,1)*10,0),ROUND(MOD($Q17,1)*100,0))+1,0),"")),IFERROR(IF(LEN($Q17)-LEN(SUBSTITUTE($Q17,".",""))>=2,DATEVALUE(SUBSTITUTE(TRIM($Q17),".","-")),DATE(VALUE(LEFT(TRIM($Q17),4)),VALUE(MID(TRIM($Q17),6,2))+1,0)),""))) | AB17: =IF(TRIM($S17&"")="","",IF(ISNUMBER($S17),IF($S17>10000,$S17,IFERROR(DATE(INT($S17),IF(ROUND(MOD($S17,1)*100,0)>12,ROUND(MOD($S17,1)*10,0),ROUND(MOD($S17,1)*100,0))+1,0),"")),IFERROR(IF(LEN($S17)-LEN(SUBSTITUTE($S17,".",""))>=2,DATEVALUE(SUBSTITUTE(TRIM($S17),".","-")),DATE(VALUE(LEFT(TRIM($S17),4)),VALUE(MID(TRIM($S17),6,2))+1,0)),""))) | AC17: =IF(TRIM($T17&"")="","",IF(ISNUMBER($T17),IF($T17>10000,$T17,IFERROR(DATE(INT($T17),IF(ROUND(MOD($T17,1)*100,0)>12,ROUND(MOD($T17,1)*10,0),ROUND(MOD($T17,1)*100,0))+1,0),"")),IFERROR(IF(LEN($T17)-LEN(SUBSTITUTE($T17,".",""))>=2,DATEVALUE(SUBSTITUTE(TRIM($T17),".","-")),DATE(VALUE(LEFT(TRIM($T17),4)),VALUE(MID(TRIM($T17),6,2))+1,0)),"")))
B18: 武汉光谷铁神新材料孵化器有限公司 | C18: 光谷铁神孵化器 | D18: MAX-E1050-C01.75 | E18: 31104201192020010040 | F18: 梯11鄂A28927（20） | G18: 广州广日 | H18: 客梯 | I18: 17 | J18: 17 | K18: 17 | L18: 1050kg | M18: 1.75m/s | N18: 1 | O18: 19278033001 | P18: 1号楼1#梯 | Y18: =IF(TRIM($B18&$C18)="","",IF(OR($W18="安装免保",$W18="技术免保",$W18="质保期内"),IF(NOT(ISNUMBER($X18)),"▲免保到期日没填",IF($X18<TODAY(),"▲免保已到期，转收费",IF($X18-TODAY()<=提醒天数,"免保剩"&($X18-TODAY())&"天","免保中"))),IF($W18="暂停维保","暂停中",IF($W18="已解约","已解约","")))) | Z18: =IF(TRIM($B18&$C18)="","",TRIM(IF($AA18="","",IF($AA18<TODAY(),"年检已过期"&(TODAY()-$AA18)&"天 ",IF($AA18-TODAY()<=提醒天数,"年检剩"&($AA18-TODAY())&"天 ","")))&IF($AB18="","",IF($AB18<TODAY(),"限速器已过期"&(TODAY()-$AB18)&"天 ",IF($AB18-TODAY()<=提醒天数,"限速器剩"&($AB18-TODAY())&"天 ","")))&IF($AC18="","",IF($AC18<TODAY(),"载重试验已过期"&(TODAY()-$AC18)&"天 ",IF($AC18-TODAY()<=提醒天数,"载重试验剩"&($AC18-TODAY())&"天 ",""))))) | AA18: =IF(TRIM($Q18&"")="","",IF(ISNUMBER($Q18),IF($Q18>10000,$Q18,IFERROR(DATE(INT($Q18),IF(ROUND(MOD($Q18,1)*100,0)>12,ROUND(MOD($Q18,1)*10,0),ROUND(MOD($Q18,1)*100,0))+1,0),"")),IFERROR(IF(LEN($Q18)-LEN(SUBSTITUTE($Q18,".",""))>=2,DATEVALUE(SUBSTITUTE(TRIM($Q18),".","-")),DATE(VALUE(LEFT(TRIM($Q18),4)),VALUE(MID(TRIM($Q18),6,2))+1,0)),""))) | AB18: =IF(TRIM($S18&"")="","",IF(ISNUMBER($S18),IF($S18>10000,$S18,IFERROR(DATE(INT($S18),IF(ROUND(MOD($S18,1)*100,0)>12,ROUND(MOD($S18,1)*10,0),ROUND(MOD($S18,1)*100,0))+1,0),"")),IFERROR(IF(LEN($S18)-LEN(SUBSTITUTE($S18,".",""))>=2,DATEVALUE(SUBSTITUTE(TRIM($S18),".","-")),DATE(VALUE(LEFT(TRIM($S18),4)),VALUE(MID(TRIM($S18),6,2))+1,0)),""))) | AC18: =IF(TRIM($T18&"")="","",IF(ISNUMBER($T18),IF($T18>10000,$T18,IFERROR(DATE(INT($T18),IF(ROUND(MOD($T18,1)*100,0)>12,ROUND(MOD($T18,1)*10,0),ROUND(MOD($T18,1)*100,0))+1,0),"")),IFERROR(IF(LEN($T18)-LEN(SUBSTITUTE($T18,".",""))>=2,DATEVALUE(SUBSTITUTE(TRIM($T18),".","-")),DATE(VALUE(LEFT(TRIM($T18),4)),VALUE(MID(TRIM($T18),6,2))+1,0)),"")))
B19: 武汉光谷铁神新材料孵化器有限公司 | C19: 光谷铁神孵化器 | D19: MAX-E1050-C01.75 | E19: 31104201192020010041 | F19: 梯11鄂A28928（20） | G19: 广州广日 | H19: 客梯 | I19: 16 | J19: 16 | K19: 16 | L19: 1050kg | M19: 1.75m/s | N19: 1 | O19: 19278033002 | P19: 1号楼2#梯 | Y19: =IF(TRIM($B19&$C19)="","",IF(OR($W19="安装免保",$W19="技术免保",$W19="质保期内"),IF(NOT(ISNUMBER($X19)),"▲免保到期日没填",IF($X19<TODAY(),"▲免保已到期，转收费",IF($X19-TODAY()<=提醒天数,"免保剩"&($X19-TODAY())&"天","免保中"))),IF($W19="暂停维保","暂停中",IF($W19="已解约","已解约","")))) | Z19: =IF(TRIM($B19&$C19)="","",TRIM(IF($AA19="","",IF($AA19<TODAY(),"年检已过期"&(TODAY()-$AA19)&"天 ",IF($AA19-TODAY()<=提醒天数,"年检剩"&($AA19-TODAY())&"天 ","")))&IF($AB19="","",IF($AB19<TODAY(),"限速器已过期"&(TODAY()-$AB19)&"天 ",IF($AB19-TODAY()<=提醒天数,"限速器剩"&($AB19-TODAY())&"天 ","")))&IF($AC19="","",IF($AC19<TODAY(),"载重试验已过期"&(TODAY()-$AC19)&"天 ",IF($AC19-TODAY()<=提醒天数,"载重试验剩"&($AC19-TODAY())&"天 ",""))))) | AA19: =IF(TRIM($Q19&"")="","",IF(ISNUMBER($Q19),IF($Q19>10000,$Q19,IFERROR(DATE(INT($Q19),IF(ROUND(MOD($Q19,1)*100,0)>12,ROUND(MOD($Q19,1)*10,0),ROUND(MOD($Q19,1)*100,0))+1,0),"")),IFERROR(IF(LEN($Q19)-LEN(SUBSTITUTE($Q19,".",""))>=2,DATEVALUE(SUBSTITUTE(TRIM($Q19),".","-")),DATE(VALUE(LEFT(TRIM($Q19),4)),VALUE(MID(TRIM($Q19),6,2))+1,0)),""))) | AB19: =IF(TRIM($S19&"")="","",IF(ISNUMBER($S19),IF($S19>10000,$S19,IFERROR(DATE(INT($S19),IF(ROUND(MOD($S19,1)*100,0)>12,ROUND(MOD($S19,1)*10,0),ROUND(MOD($S19,1)*100,0))+1,0),"")),IFERROR(IF(LEN($S19)-LEN(SUBSTITUTE($S19,".",""))>=2,DATEVALUE(SUBSTITUTE(TRIM($S19),".","-")),DATE(VALUE(LEFT(TRIM($S19),4)),VALUE(MID(TRIM($S19),6,2))+1,0)),""))) | AC19: =IF(TRIM($T19&"")="","",IF(ISNUMBER($T19),IF($T19>10000,$T19,IFERROR(DATE(INT($T19),IF(ROUND(MOD($T19,1)*100,0)>12,ROUND(MOD($T19,1)*10,0),ROUND(MOD($T19,1)*100,0))+1,0),"")),IFERROR(IF(LEN($T19)-LEN(SUBSTITUTE($T19,".",""))>=2,DATEVALUE(SUBSTITUTE(TRIM($T19),".","-")),DATE(VALUE(LEFT(TRIM($T19),4)),VALUE(MID(TRIM($T19),6,2))+1,0)),"")))
B20: 武汉光谷铁神新材料孵化器有限公司 | C20: 光谷铁神孵化器 | D20: MAX-E1050-C01.75 | E20: 31104201192020010042 | F20: 梯11鄂A28929（20） | G20: 广州广日 | H20: 客梯 | I20: 14 | J20: 14 | K20: 14 | L20: 1050kg | M20: 1.75m/s | N20: 1 | O20: 19278033003 | P20: 2号楼1#梯 | Y20: =IF(TRIM($B20&$C20)="","",IF(OR($W20="安装免保",$W20="技术免保",$W20="质保期内"),IF(NOT(ISNUMBER($X20)),"▲免保到期日没填",IF($X20<TODAY(),"▲免保已到期，转收费",IF($X20-TODAY()<=提醒天数,"免保剩"&($X20-TODAY())&"天","免保中"))),IF($W20="暂停维保","暂停中",IF($W20="已解约","已解约","")))) | Z20: =IF(TRIM($B20&$C20)="","",TRIM(IF($AA20="","",IF($AA20<TODAY(),"年检已过期"&(TODAY()-$AA20)&"天 ",IF($AA20-TODAY()<=提醒天数,"年检剩"&($AA20-TODAY())&"天 ","")))&IF($AB20="","",IF($AB20<TODAY(),"限速器已过期"&(TODAY()-$AB20)&"天 ",IF($AB20-TODAY()<=提醒天数,"限速器剩"&($AB20-TODAY())&"天 ","")))&IF($AC20="","",IF($AC20<TODAY(),"载重试验已过期"&(TODAY()-$AC20)&"天 ",IF($AC20-TODAY()<=提醒天数,"载重试验剩"&($AC20-TODAY())&"天 ",""))))) | AA20: =IF(TRIM($Q20&"")="","",IF(ISNUMBER($Q20),IF($Q20>10000,$Q20,IFERROR(DATE(INT($Q20),IF(ROUND(MOD($Q20,1)*100,0)>12,ROUND(MOD($Q20,1)*10,0),ROUND(MOD($Q20,1)*100,0))+1,0),"")),IFERROR(IF(LEN($Q20)-LEN(SUBSTITUTE($Q20,".",""))>=2,DATEVALUE(SUBSTITUTE(TRIM($Q20),".","-")),DATE(VALUE(LEFT(TRIM($Q20),4)),VALUE(MID(TRIM($Q20),6,2))+1,0)),""))) | AB20: =IF(TRIM($S20&"")="","",IF(ISNUMBER($S20),IF($S20>10000,$S20,IFERROR(DATE(INT($S20),IF(ROUND(MOD($S20,1)*100,0)>12,ROUND(MOD($S20,1)*10,0),ROUND(MOD($S20,1)*100,0))+1,0),"")),IFERROR(IF(LEN($S20)-LEN(SUBSTITUTE($S20,".",""))>=2,DATEVALUE(SUBSTITUTE(TRIM($S20),".","-")),DATE(VALUE(LEFT(TRIM($S20),4)),VALUE(MID(TRIM($S20),6,2))+1,0)),""))) | AC20: =IF(TRIM($T20&"")="","",IF(ISNUMBER($T20),IF($T20>10000,$T20,IFERROR(DATE(INT($T20),IF(ROUND(MOD($T20,1)*100,0)>12,ROUND(MOD($T20,1)*10,0),ROUND(MOD($T20,1)*100,0))+1,0),"")),IFERROR(IF(LEN($T20)-LEN(SUBSTITUTE($T20,".",""))>=2,DATEVALUE(SUBSTITUTE(TRIM($T20),".","-")),DATE(VALUE(LEFT(TRIM($T20),4)),VALUE(MID(TRIM($T20),6,2))+1,0)),"")))
B21: 武汉光谷铁神新材料孵化器有限公司 | C21: 光谷铁神孵化器 | D21: MAX-E1050-C01.75 | E21: 31104201192020010043 | F21: 梯11鄂A28930（20） | G21: 广州广日 | H21: 客梯 | I21: 14 | J21: 14 | K21: 14 | L21: 1050kg | M21: 1.75m/s | N21: 1 | O21: 19278033004 | P21: 3号楼1#梯 | Y21: =IF(TRIM($B21&$C21)="","",IF(OR($W21="安装免保",$W21="技术免保",$W21="质保期内"),IF(NOT(ISNUMBER($X21)),"▲免保到期日没填",IF($X21<TODAY(),"▲免保已到期，转收费",IF($X21-TODAY()<=提醒天数,"免保剩"&($X21-TODAY())&"天","免保中"))),IF($W21="暂停维保","暂停中",IF($W21="已解约","已解约","")))) | Z21: =IF(TRIM($B21&$C21)="","",TRIM(IF($AA21="","",IF($AA21<TODAY(),"年检已过期"&(TODAY()-$AA21)&"天 ",IF($AA21-TODAY()<=提醒天数,"年检剩"&($AA21-TODAY())&"天 ","")))&IF($AB21="","",IF($AB21<TODAY(),"限速器已过期"&(TODAY()-$AB21)&"天 ",IF($AB21-TODAY()<=提醒天数,"限速器剩"&($AB21-TODAY())&"天 ","")))&IF($AC21="","",IF($AC21<TODAY(),"载重试验已过期"&(TODAY()-$AC21)&"天 ",IF($AC21-TODAY()<=提醒天数,"载重试验剩"&($AC21-TODAY())&"天 ",""))))) | AA21: =IF(TRIM($Q21&"")="","",IF(ISNUMBER($Q21),IF($Q21>10000,$Q21,IFERROR(DATE(INT($Q21),IF(ROUND(MOD($Q21,1)*100,0)>12,ROUND(MOD($Q21,1)*10,0),ROUND(MOD($Q21,1)*100,0))+1,0),"")),IFERROR(IF(LEN($Q21)-LEN(SUBSTITUTE($Q21,".",""))>=2,DATEVALUE(SUBSTITUTE(TRIM($Q21),".","-")),DATE(VALUE(LEFT(TRIM($Q21),4)),VALUE(MID(TRIM($Q21),6,2))+1,0)),""))) | AB21: =IF(TRIM($S21&"")="","",IF(ISNUMBER($S21),IF($S21>10000,$S21,IFERROR(DATE(INT($S21),IF(ROUND(MOD($S21,1)*100,0)>12,ROUND(MOD($S21,1)*10,0),ROUND(MOD($S21,1)*100,0))+1,0),"")),IFERROR(IF(LEN($S21)-LEN(SUBSTITUTE($S21,".",""))>=2,DATEVALUE(SUBSTITUTE(TRIM($S21),".","-")),DATE(VALUE(LEFT(TRIM($S21),4)),VALUE(MID(TRIM($S21),6,2))+1,0)),""))) | AC21: =IF(TRIM($T21&"")="","",IF(ISNUMBER($T21),IF($T21>10000,$T21,IFERROR(DATE(INT($T21),IF(ROUND(MOD($T21,1)*100,0)>12,ROUND(MOD($T21,1)*10,0),ROUND(MOD($T21,1)*100,0))+1,0),"")),IFERROR(IF(LEN($T21)-LEN(SUBSTITUTE($T21,".",""))>=2,DATEVALUE(SUBSTITUTE(TRIM($T21),".","-")),DATE(VALUE(LEFT(TRIM($T21),4)),VALUE(MID(TRIM($T21),6,2))+1,0)),"")))
B22: 武汉光谷铁神新材料孵化器有限公司 | C22: 光谷铁神孵化器 | D22: MAX-E1050-C01.75 | E22: 31104201192020010044 | F22: 梯11鄂A28931（20） | G22: 广州广日 | H22: 客梯 | I22: 13 | J22: 13 | K22: 13 | L22: 1050kg | M22: 1.75m/s | N22: 1 | O22: 19278033005 | P22: 2号楼2#梯 | Y22: =IF(TRIM($B22&$C22)="","",IF(OR($W22="安装免保",$W22="技术免保",$W22="质保期内"),IF(NOT(ISNUMBER($X22)),"▲免保到期日没填",IF($X22<TODAY(),"▲免保已到期，转收费",IF($X22-TODAY()<=提醒天数,"免保剩"&($X22-TODAY())&"天","免保中"))),IF($W22="暂停维保","暂停中",IF($W22="已解约","已解约","")))) | Z22: =IF(TRIM($B22&$C22)="","",TRIM(IF($AA22="","",IF($AA22<TODAY(),"年检已过期"&(TODAY()-$AA22)&"天 ",IF($AA22-TODAY()<=提醒天数,"年检剩"&($AA22-TODAY())&"天 ","")))&IF($AB22="","",IF($AB22<TODAY(),"限速器已过期"&(TODAY()-$AB22)&"天 ",IF($AB22-TODAY()<=提醒天数,"限速器剩"&($AB22-TODAY())&"天 ","")))&IF($AC22="","",IF($AC22<TODAY(),"载重试验已过期"&(TODAY()-$AC22)&"天 ",IF($AC22-TODAY()<=提醒天数,"载重试验剩"&($AC22-TODAY())&"天 ",""))))) | AA22: =IF(TRIM($Q22&"")="","",IF(ISNUMBER($Q22),IF($Q22>10000,$Q22,IFERROR(DATE(INT($Q22),IF(ROUND(MOD($Q22,1)*100,0)>12,ROUND(MOD($Q22,1)*10,0),ROUND(MOD($Q22,1)*100,0))+1,0),"")),IFERROR(IF(LEN($Q22)-LEN(SUBSTITUTE($Q22,".",""))>=2,DATEVALUE(SUBSTITUTE(TRIM($Q22),".","-")),DATE(VALUE(LEFT(TRIM($Q22),4)),VALUE(MID(TRIM($Q22),6,2))+1,0)),""))) | AB22: =IF(TRIM($S22&"")="","",IF(ISNUMBER($S22),IF($S22>10000,$S22,IFERROR(DATE(INT($S22),IF(ROUND(MOD($S22,1)*100,0)>12,ROUND(MOD($S22,1)*10,0),ROUND(MOD($S22,1)*100,0))+1,0),"")),IFERROR(IF(LEN($S22)-LEN(SUBSTITUTE($S22,".",""))>=2,DATEVALUE(SUBSTITUTE(TRIM($S22),".","-")),DATE(VALUE(LEFT(TRIM($S22),4)),VALUE(MID(TRIM($S22),6,2))+1,0)),""))) | AC22: =IF(TRIM($T22&"")="","",IF(ISNUMBER($T22),IF($T22>10000,$T22,IFERROR(DATE(INT($T22),IF(ROUND(MOD($T22,1)*100,0)>12,ROUND(MOD($T22,1)*10,0),ROUND(MOD($T22,1)*100,0))+1,0),"")),IFERROR(IF(LEN($T22)-LEN(SUBSTITUTE($T22,".",""))>=2,DATEVALUE(SUBSTITUTE(TRIM($T22),".","-")),DATE(VALUE(LEFT(TRIM($T22),4)),VALUE(MID(TRIM($T22),6,2))+1,0)),"")))
B23: 武汉光谷铁神新材料孵化器有限公司 | C23: 光谷铁神孵化器 | D23: MAX-E1050-C01.75 | E23: 31104201192020010045 | F23: 梯11鄂A28932（20） | G23: 广州广日 | H23: 客梯 | I23: 13 | J23: 13 | K23: 13 | L23: 1050kg | M23: 1.75m/s | N23: 1 | O23: 19278033006 | P23: 3号楼2#梯 | Y23: =IF(TRIM($B23&$C23)="","",IF(OR($W23="安装免保",$W23="技术免保",$W23="质保期内"),IF(NOT(ISNUMBER($X23)),"▲免保到期日没填",IF($X23<TODAY(),"▲免保已到期，转收费",IF($X23-TODAY()<=提醒天数,"免保剩"&($X23-TODAY())&"天","免保中"))),IF($W23="暂停维保","暂停中",IF($W23="已解约","已解约","")))) | Z23: =IF(TRIM($B23&$C23)="","",TRIM(IF($AA23="","",IF($AA23<TODAY(),"年检已过期"&(TODAY()-$AA23)&"天 ",IF($AA23-TODAY()<=提醒天数,"年检剩"&($AA23-TODAY())&"天 ","")))&IF($AB23="","",IF($AB23<TODAY(),"限速器已过期"&(TODAY()-$AB23)&"天 ",IF($AB23-TODAY()<=提醒天数,"限速器剩"&($AB23-TODAY())&"天 ","")))&IF($AC23="","",IF($AC23<TODAY(),"载重试验已过期"&(TODAY()-$AC23)&"天 ",IF($AC23-TODAY()<=提醒天数,"载重试验剩"&($AC23-TODAY())&"天 ",""))))) | AA23: =IF(TRIM($Q23&"")="","",IF(ISNUMBER($Q23),IF($Q23>10000,$Q23,IFERROR(DATE(INT($Q23),IF(ROUND(MOD($Q23,1)*100,0)>12,ROUND(MOD($Q23,1)*10,0),ROUND(MOD($Q23,1)*100,0))+1,0),"")),IFERROR(IF(LEN($Q23)-LEN(SUBSTITUTE($Q23,".",""))>=2,DATEVALUE(SUBSTITUTE(TRIM($Q23),".","-")),DATE(VALUE(LEFT(TRIM($Q23),4)),VALUE(MID(TRIM($Q23),6,2))+1,0)),""))) | AB23: =IF(TRIM($S23&"")="","",IF(ISNUMBER($S23),IF($S23>10000,$S23,IFERROR(DATE(INT($S23),IF(ROUND(MOD($S23,1)*100,0)>12,ROUND(MOD($S23,1)*10,0),ROUND(MOD($S23,1)*100,0))+1,0),"")),IFERROR(IF(LEN($S23)-LEN(SUBSTITUTE($S23,".",""))>=2,DATEVALUE(SUBSTITUTE(TRIM($S23),".","-")),DATE(VALUE(LEFT(TRIM($S23),4)),VALUE(MID(TRIM($S23),6,2))+1,0)),""))) | AC23: =IF(TRIM($T23&"")="","",IF(ISNUMBER($T23),IF($T23>10000,$T23,IFERROR(DATE(INT($T23),IF(ROUND(MOD($T23,1)*100,0)>12,ROUND(MOD($T23,1)*10,0),ROUND(MOD($T23,1)*100,0))+1,0),"")),IFERROR(IF(LEN($T23)-LEN(SUBSTITUTE($T23,".",""))>=2,DATEVALUE(SUBSTITUTE(TRIM($T23),".","-")),DATE(VALUE(LEFT(TRIM($T23),4)),VALUE(MID(TRIM($T23),6,2))+1,0)),"")))
