Workbook

Sheet 主页
A1: 02 物 料 与 周 转 物 台 账
A2: 包装物料 / 公司周转筐 / 客户自备筐 / 次果筐与托盘 ｜ 逐笔对账请到《04 综合查询对账单》 ｜ 点蓝色表名跳转
A3: =IF(N(对接源_01水果筐数!$S$1)=0,"联动状态：★★ 01 水果台账的筐数没接进来 —— 请打开【对接源_01水果筐数】按提示修复链接",IF(N(对接源_01水果筐数!$S$4)=0,"联动状态：⚠ 正在用【应急备份】的筐数（不是实时数），共 "&N(对接源_01水果筐数!$S$1)&" 行，请尽快修复链接","联动状态：✔ 正常 —— 已从《01 水果进销存台账》自动接入 "&N(对接源_01水果筐数!$S$1)&" 行筐子进出数据")) -> 联动状态：✔ 正常 —— 已从《01 水果进销存台账》自动接入 22 行筐子进出数据
A5: 一、日常录入（每天要填的表）
A6: 序号 | B6: 子表名称 | C6: 用途说明 | D6: 属性
A7: 1 | B7: 包装物料出入库明细 | C7: 物料进出与销售；计价数量和合计金额自动算 | D7: 手工录入
A8: 2 | B8: 周转筐出入库明细 | C8: 公司筐的采购、发出、客户退回、卖断；剩余库存按类型自动滚动；含收退押金 | D8: 手工录入
A9: 3 | B9: 客户自备筐明细 | C9: 客户自己带来的筐子，表外备查 | D9: 手工录入
A10: 4 | B10: 次果筐明细 | C10: 次果筐与托盘合并在这一张；含押金与退款情况 | D10: 手工录入
A11: 5 | B11: 实盘库存盘点 | C11: 只在右半边录实盘数量，左半边账面数与盘盈盘亏全自动 | D11: 半自动
A13: 二、库存与往来（全部自动，不用填）
A14: 序号 | B14: 子表名称 | C14: 用途说明 | D14: 属性
A15: 6 | B15: 物料库存结余 | C15: 按物料看期初/采购/退回/领用/销售与剩余库存、库存金额 | D15: 全自动
A16: 7 | B16: 筐子库存汇总 | C16: 公司每种筐子还剩多少、客户手上多少、公司筐总量 | D16: 全自动
A17: 8 | B17: 筐子往来汇总 | C17: 按客户/供应商看发出、退回、采购三组，已含01册带出带回的筐数 | D17: 全自动
A18: 9 | B18: 筐子销售汇总 | C18: 卖断给客户的筐子数量、金额、已收未收 | D18: 全自动
A19: 10 | B19: 自备筐汇总 | C19: 客户自备筐进出与结存，联动01册成品出库带走的自备筐 | D19: 全自动
A20: 11 | B20: 次果筐汇总 | C20: 次果筐/托盘按客户的出库、退回、未回与押金 | D20: 全自动
A21: 12 | B21: 押金汇总 | C21: 每家客户收了多少、退了多少、还欠客户多少押金 | D21: 全自动
A22: 13 | B22: 客户领用物料汇总 | C22: 按客户看各物料领用量、退回量、净领用与销售应收 | D22: 全自动
A23: 14 | B23: 收入结算汇总 | C23: 筐子销售、物料销售两项收入 ＋ 押金专区 ＋ 期末存货 | D23: 全自动
A25: 三、对接与码表
A26: 序号 | B26: 子表名称 | C26: 用途说明 | D26: 属性
A27: 15 | B27: 对接源_01水果筐数 | C27: 跨文件取《01 水果进销存台账》的筐子进出数，断链自动切备份 | D27: 全自动
A28: 16 | B28: 财务取数接口 | C28: 给《03 财务账套》按月取数用 | D28: 全自动
A29: 17 | B29: 基础资料 | C29: 物料、筐子类型、托盘类型、客户、供应商等下拉选项来源 | D29: 码表
A30: 18 | B30: 字段对照 | C30: 原有 Excel 字段 → 本册字段的对照表，存档备查 | D30: 说明
A32: 图例：浅绿＝公式自动生成，请勿覆盖 ｜ 浅蓝＝需要手工录入 ｜ 浅黄＝码表/规则，偶尔维护

Sheet 使用说明
A1: 物料与周转物台账 使 用 说 明
A2: 替代原《2025年包装物料出入库明细》《2025年筐子出入库明细》及《杨威威杨元威黄红梅》筐子部分
B4: 一、六条业务线，六张明细表
B6: ① 包装物料（气泡垫、无纺布、香梨网、苹果网、纸垫板…）→【包装物料出入库明细】
B7: ② 公司周转筐（一次性筐/杂周转筐/新周转筐/白周转筐）发放与回收 →【周转筐出入库明细】
B8: ③ 筐子卖给客户 →【筐子销售明细】（不再走②，避免重复冲减库存）
B9: ④ 客户自己带来的筐子 →【客户自备筐明细】
B10: ⑤ 拉次果专用的租借筐 →【次果筐明细】（含应收使用费）
B11: ⑥ 托盘 →【托盘出入库明细】
B13: 二、关键约定
B15: · 客户随原料车带回来的公司筐子，请在【周转筐出入库明细】登记为“退回数量”，归还者填客户名。
B16: 这样【筐子往来汇总】的“未回库数量＝发出−退回”就是完整的，不用再去水果册对数。
B17: · 筐子卖断（不再收回）的走【筐子销售明细】；只是借出的走【周转筐出入库明细】。
B18: · 【周转筐出入库明细】的“剩余库存”是公司全部筐子的滚动结存（与原表口径一致，不分类型），
... B65: "净领用"＝两者相减，才是客户真正用掉的。
A67: ★ 本 次 更 新（2026-09）
A68: 1、【自备筐汇总】口径扩大：＝【客户自备加工筐明细】＋《01》原料入库带回、原料出库带走、成品出库带走中筐子类型以「自备」开头的随货筐数。入库合计＝C＋D，出库合计＝E＋J＋K，剩余在库＝入库合计−出库合计。
A69: 2、【筐子往来汇总】V/W 两列只取《01》里筐子类型不以「自备」开头的（即公司筐）；【筐子库存汇总】也不再统计自备类型。
A70: 3、筐子类型下拉已统一加「公司…／自备…」前缀，见【基础资料】B 列。
A71: 4、【对账明细接口】新增 N～S 列（筐子类型、发出筐数、退回筐数、入库筐数、车牌号、筐子归属），供《04》的分类对账单取数，请勿改动结构。
A73: ★ 本 次 更 新（2026-09 · 第三版）
A74: 1、【筐子往来汇总】重建为 5 种公司筐（一次性/杂周转/新周转/白周转/红周转）分列：发出、退回、采购入库、销售各 5 列＋合计，再加《01》的 原料入库／原料出库／成品出库 各 5 列，最后是未回库 5 列＋合计。01 册三张明细按「筐子类型」一一对应取数，不再混在一起。
A75: 2、新增【筐子采购汇总】：按供应商汇总【周转筐出入库明细】里业务类型＝「采购入库」的数量、金额、已付与未付。
A76: 3、所有汇总界面第 2 行右边新增「开始日期／结束日期」，留空＝不限时间。
A77: 4、「退回数量」「退押金」「客户退回入库」「随货回库」等一律显示为红色负数（录入仍填正数），未回库数量＝发出＋退回（负）＋随货回库（负），可以直接相加。
A79: ★ 修 正 记 录（2026-09 · 第四版）
A80: 1、修正【对接源_01水果筐数】：原来 B 列（客户/货主）被写死指向 01 的第 4 行，导致整列都显示同一个客户、下面全是空白。现在 300 行逐行一一对应，取数正常。
... A88: 4、【财务取数接口】第四块改成每家客户两行：筐子销售款 / 物料销售款，供《03 往来对账单》分项显示。

Sheet 基础资料
A1: 基 础 资 料（下拉选项来源 + 物料价目表，可自行增删）
A2: ★ 右侧“物料价目表”的参考单价是明细表自动带价的依据，价格调整请直接改这里
A3: 物料种类 | B3: 筐子类型 | C3: 托盘类型 | D3: 客户/领取人 | E3: 供应商 | F3: 物料业务类型 | G3: 筐子业务类型 | H3: 装卸方式 | I3: 核查结果 | J3: 结算方式 | K3: 收/付款状态 | L3: 筐子用途 | N3: 物料名称 | O3: 规格 | P3: 计量单位 | R3: 库存阈值 | S3: 数量
A4: 气泡垫 | B4: 公司一次性筐 | C4: 大托盘 | D4: 聂新平 | E4: 鑫旺塑业 | F4: 期初库存 | G4: 期初库存 | H4: 依力 | I4: 1 | J4: 现金 | K4: 已收讫 | L4: 拉次果 | N4: 气泡垫 | O4: *1000 | P4: 片 | R4: 充足 | S4: 5000
A5: 无纺布 | B5: 公司杂周转筐 | D5: 王照雪 | E5: 华鑫塑业 | F5: 采购入库 | G5: 采购入库 | H5: 叉车 | I5: 待核对 | J5: 银行转账 | K5: 部分收款 | L5: 拉原料 | N5: 无纺布 | O5: *400 | P5: 个 | R5: 正常 | S5: 50
A6: 香梨网 | B6: 公司新周转筐 | D6: 伍元虎 | E6: 全修塑业 | F6: 退回入库 | G6: 退回入库 | H6: 自卸 | I6: 异常 | J6: 微信 | K6: 未收款 | L6: 拉扎伤果 | N6: 香梨网 | O6: *包 | P6: 包 | R6: 不足 | S6: 0
A7: 苹果网 | B7: 公司白周转筐 | D7: 麦麦提 | E7: 新顺发泡网 | F7: 领用出库 | G7: 领用出库 | H7: 自装 | J7: 支付宝 | K7: 无需收款 | L7: 租筐退回 | N7: 苹果网 | O7: *包 | P7: 包
A8: 纸垫板 | B8: 公司红周转筐 | D8: 热合曼 | E8: 武宁气泡垫 | F8: 销售出库 | G8: 销售出库 | H8: 快递 | J8: 承兑汇票 | K8: 已付款 | L8: 原筐出库 | N8: 纸垫板 | O8: *100张 | P8: 张
A9: 香梨纸 | B9: 自备一次性筐 | D9: 王灵云 | F9: 果然鲜自用 | G9: 果然鲜自用 | H9: 筐厂 | J9: 抵账 | K9: 部分付款 | L9: 粉碎加工 | N9: 香梨纸 | O9: *捆 | P9: 捆
A10: 苹果纸 | B10: 自备杂周转筐 | D10: 马锦祥 | F10: 报损 | G10: 报损 | H10: 自提 | J10: 赊销挂账 | K10: 未付款 | L10: 购买次果 | N10: 保温棉 | O10: *两卷/套 | P10: 套
A11: 保温棉 | D11: 贾建国 | F11: 调拨 | G11: 调拨 | H11: 无 | J11: 预收冲抵 | K11: 无需付款 | L11: 退回 | N11: 塑料布 | O11: *张 | P11: 张
A12: 塑料布 | D12: 荆建君 | L12: 其他 | N12: 五合板0.5 | O12: *块 | P12: 块
A13: 五合板0.5 | D13: 艾合买提 | N13: 五合板0.3 | O13: *块 | P13: 块
A14: 五合板0.3 | D14: 王浩 | N14: 打包带 | O14: *卷 | P14: 卷
A15: 打包带 | D15: 电商/主播 | N15: 封口袋 | P15: 个
A16: 封口袋 | D16: 吐尔逊 | N16: 打包器 | P16: 个
A17: 打包器 | D17: 张艺 | N17: 胶带 | O17: *30卷 | P17: 卷
A18: 胶带 | D18: 郭勇义 | N18: 保鲜膜 | P18: 卷
A19: 保鲜膜 | D19: 王庆文 | N19: 保鲜袋 | P19: 个
A20: 保鲜袋 | D20: 果然鲜 | N20: 一级标签 | P20: 张
A21: 一级标签 | D21: 努尔敦 | N21: 副特标签 | P21: 张
A22: 副特标签 | D22: 吐尔洪 | N22: 香梨标签 | P22: 张
A23: 香梨标签 | N23: 冷煤/氟利昂 | O23: *瓶 | P23: 瓶
A24: 冷煤/氟利昂 | N24: 新周转筐 | O24: *个 | P24: 个
A25: 公司新周转筐 | N25: 杂筐/一次性 | O25: *个 | P25: 个
A26: 公司杂周转筐
A27: 公司一次性筐
A28: 公司白周转筐
A29: 公司红周转筐

Sheet 对接源_01水果筐数
A1: 对 接 源 · 01 水 果 台 账 筐 数（跨文件自动取数 · 断链时自动改用应急备份） | R1: 有效行数 | S1: =MAX($P$5:$P$304) -> 22
A2: =IF($S$4=1,"✔ 链接正常，已自动取到 "&$S$1&" 行 ｜ 本表 1:1 对应《01 水果进销存台账模板》的【筐子进出接口】，两个文件必须放在同一个文件夹，文件名也不要改","★★ 链接没接上！当前取数来源："&$S$5&" → 请看本表右边 R6 格的修复说明（往右拉一屏）") -> ✔ 链接正常，已自动取到 22 行 ｜ 本表 1:1 对应《01 水果进销存台账模板》的【筐子进出接口】，两个文件必须放在同一个文件夹，文件名也不要改 | R2: 链接探针 | S2: =IFERROR(IF([1]筐子进出接口!$C$4=0,"未更新",[1]筐子进出接口!$C$4),"断开") -> 自备一次性筐
A3: 一、实 际 使 用 值（链接正常＝自动取数；链接断了自动切到右边备份） | I3: 二、应 急 备 份 区（手工粘贴数值） | O3: 状态 | R3: 备份行数 | S3: =COUNTIF($J$5:$J$304,"?*") -> 0
A4: 源行 | B4: 客户/货主 | C4: 筐子类型 | D4: 原料入库带回筐数 | E4: 原料出库带走筐数 | F4: 成品出库带走筐数 | G4: 发出合计 | H4: 收回合计 | I4: 备份-客户 | J4: 备份-类型 | K4: 备份-入库带回 | L4: 备份-出库带走 | M4: 备份-成品带走 | N4: 备份-发出合计 | O4: 有效 | P4: 累计 | R4: 链接可用 | S4: =IF(OR($S$2="断开",$S$2="未更新"),0,1) -> 1
A5: 4 | B5: =IF($S$4=0,IF($I5="","",$I5),IFERROR(IF([1]筐子进出接口!$B$4=0,"",[1]筐子进出接口!$B$4),"")) -> 聂新平 | C5: =IF($S$4=0,IF($J5="","",$J5),IFERROR(IF([1]筐子进出接口!$C$4=0,"",[1]筐子进出接口!$C$4),"")) -> 自备一次性筐 | D5: =IF($S$4=0,IF($K5="","",$K5),IFERROR(IF([1]筐子进出接口!$D$4=0,"",[1]筐子进出接口!$D$4),"")) -> 11421 | E5: =IF($S$4=0,IF($L5="","",$L5),IFERROR(IF([1]筐子进出接口!$E$4=0,"",[1]筐子进出接口!$E$4),"")) -> 10143 | F5: =IF($S$4=0,IF($M5="","",$M5),IFERROR(IF([1]筐子进出接口!$F$4=0,"",[1]筐子进出接口!$F$4),"")) -> 1260 | G5: =IF($S$4=0,IF($N5="","",$N5),IFERROR(IF([1]筐子进出接口!$G$4=0,"",[1]筐子进出接口!$G$4),"")) -> 11403 | H5: =IF($B5="","",N($D5)) -> 11421 | O5: =IF(AND($B5<>"",$C5<>""),1,0) -> 1 | P5: =N(P4)+$O5 -> 1 | R5: 当前取数来源 | S5: =IF($S$4=1,"自动（跨文件链接）",IF($S$3>0,"应急备份","无数据")) -> 自动（跨文件链接）
A6: 5 | B6: =IF($S$4=0,IF($I6="","",$I6),IFERROR(IF([1]筐子进出接口!$B$5=0,"",[1]筐子进出接口!$B$5),"")) -> 王照雪 | C6: =IF($S$4=0,IF($J6="","",$J6),IFERROR(IF([1]筐子进出接口!$C$5=0,"",[1]筐子进出接口!$C$5),"")) -> 公司杂周转筐 | D6: =IF($S$4=0,IF($K6="","",$K6),IFERROR(IF([1]筐子进出接口!$D$5=0,"",[1]筐子进出接口!$D$5),"")) -> 1670 | E6: =IF($S$4=0,IF($L6="","",$L6),IFERROR(IF([1]筐子进出接口!$E$5=0,"",[1]筐子进出接口!$E$5),"")) -> 1 | F6: =IF($S$4=0,IF($M6="","",$M6),IFERROR(IF([1]筐子进出接口!$F$5=0,"",[1]筐子进出接口!$F$5),"")) -> 4 | G6: =IF($S$4=0,IF($N6="","",$N6),IFERROR(IF([1]筐子进出接口!$G$5=0,"",[1]筐子进出接口!$G$5),"")) -> 5 | H6: =IF($B6="","",N($D6)) -> 1670 | O6: =IF(AND($B6<>"",$C6<>""),1,0) -> 1 | P6: =N(P5)+$O6 -> 2 | R6: =IF($S$2="断开",IF($S$3>0,"✘ 链接已断开，正在用【应急备份区】的 "&$S$3&" 行数据。修复：菜单【数据】→【编辑链接】→【更改源】，重新指向《01_水果进销存台账模板.xlsx》","✘ 链接已断开，且应急备份区是空的，筐子往来汇总里不会包含 01 水果台账带出带回的筐数。修复：菜单【数据】→【编辑链接】→【更改源】，重新指向《01_水果进销存台账模板.xlsx》"),IF($S$2="未更新",IF($S$3>0,"★ 链接还没更新，或那个文件被改名、挪走了。正在用【应急备份区】的 "&$S$3&" 行数据。修复：【数据】→【编辑链接】→先点【立即更新值】；还取不到数就点【更改源】重新指向《01_水果进销存台账模板.xlsx》","★ 链接还没更新，或那个文件被改名、挪走了，且没有应急备份。修复：【数据】→【编辑链接】→先点【立即更新值】；还取不到数就点【更改源】重新指向《01_水果进销存台账模板.xlsx》"),"✔ 链接正常，已自动取到 "&$S$1&" 行。备份区现有 "&$S$3&" 行。建议每月底把 B5:G304 复制→选择性粘贴【数值】到 I5，作为断链时的兜底")) -> ✔ 链接正常，已自动取到 22 行。备份区现有 0 行。建议每月底把 B5:G304 复制→选择性粘贴【数值】到 I5，作为断链时的兜底
A7: 6 | B7: =IF($S$4=0,IF($I7="","",$I7),IFERROR(IF([1]筐子进出接口!$B$6=0,"",[1]筐子进出接口!$B$6),"")) -> 伍元虎 | C7: =IF($S$4=0,IF($J7="","",$J7),IFERROR(IF([1]筐子进出接口!$C$6=0,"",[1]筐子进出接口!$C$6),"")) -> 自备一次性筐 | D7: =IF($S$4=0,IF($K7="","",$K7),IFERROR(IF([1]筐子进出接口!$D$6=0,"",[1]筐子进出接口!$D$6),"")) -> 87 | E7: =IF($S$4=0,IF($L7="","",$L7),IFERROR(IF([1]筐子进出接口!$E$6=0,"",[1]筐子进出接口!$E$6),"")) -> 87 | F7: =IF($S$4=0,IF($M7="","",$M7),IFERROR(IF([1]筐子进出接口!$F$6=0,"",[1]筐子进出接口!$F$6),"")) | G7: =IF($S$4=0,IF($N7="","",$N7),IFERROR(IF([1]筐子进出接口!$G$6=0,"",[1]筐子进出接口!$G$6),"")) -> 87 | H7: =IF($B7="","",N($D7)) -> 87 | O7: =IF(AND($B7<>"",$C7<>""),1,0) -> 1 | P7: =N(P6)+$O7 -> 3
A8: 7 | B8: =IF($S$4=0,IF($I8="","",$I8),IFERROR(IF([1]筐子进出接口!$B$7=0,"",[1]筐子进出接口!$B$7),"")) -> 王照雪 | C8: =IF($S$4=0,IF($J8="","",$J8),IFERROR(IF([1]筐子进出接口!$C$7=0,"",[1]筐子进出接口!$C$7),"")) -> 自备一次性筐 | D8: =IF($S$4=0,IF($K8="","",$K8),IFERROR(IF([1]筐子进出接口!$D$7=0,"",[1]筐子进出接口!$D$7),"")) -> 422 | E8: =IF($S$4=0,IF($L8="","",$L8),IFERROR(IF([1]筐子进出接口!$E$7=0,"",[1]筐子进出接口!$E$7),"")) -> 422 | F8: =IF($S$4=0,IF($M8="","",$M8),IFERROR(IF([1]筐子进出接口!$F$7=0,"",[1]筐子进出接口!$F$7),"")) | G8: =IF($S$4=0,IF($N8="","",$N8),IFERROR(IF([1]筐子进出接口!$G$7=0,"",[1]筐子进出接口!$G$7),"")) -> 422 | H8: =IF($B8="","",N($D8)) -> 422 | O8: =IF(AND($B8<>"",$C8<>""),1,0) -> 1 | P8: =N(P7)+$O8 -> 4
A9: 8 | B9: =IF($S$4=0,IF($I9="","",$I9),IFERROR(IF([1]筐子进出接口!$B$8=0,"",[1]筐子进出接口!$B$8),"")) -> 马锦祥 | C9: =IF($S$4=0,IF($J9="","",$J9),IFERROR(IF([1]筐子进出接口!$C$8=0,"",[1]筐子进出接口!$C$8),"")) -> 自备一次性筐 | D9: =IF($S$4=0,IF($K9="","",$K9),IFERROR(IF([1]筐子进出接口!$D$8=0,"",[1]筐子进出接口!$D$8),"")) -> 68 | E9: =IF($S$4=0,IF($L9="","",$L9),IFERROR(IF([1]筐子进出接口!$E$8=0,"",[1]筐子进出接口!$E$8),"")) -> 2 | F9: =IF($S$4=0,IF($M9="","",$M9),IFERROR(IF([1]筐子进出接口!$F$8=0,"",[1]筐子进出接口!$F$8),"")) | G9: =IF($S$4=0,IF($N9="","",$N9),IFERROR(IF([1]筐子进出接口!$G$8=0,"",[1]筐子进出接口!$G$8),"")) -> 2 | H9: =IF($B9="","",N($D9)) -> 68 | O9: =IF(AND($B9<>"",$C9<>""),1,0) -> 1 | P9: =N(P8)+$O9 -> 5
A10: 9 | B10: =IF($S$4=0,IF($I10="","",$I10),IFERROR(IF([1]筐子进出接口!$B$9=0,"",[1]筐子进出接口!$B$9),"")) -> 马锦祥 | C10: =IF($S$4=0,IF($J10="","",$J10),IFERROR(IF([1]筐子进出接口!$C$9=0,"",[1]筐子进出接口!$C$9),"")) -> 公司杂周转筐 | D10: =IF($S$4=0,IF($K10="","",$K10),IFERROR(IF([1]筐子进出接口!$D$9=0,"",[1]筐子进出接口!$D$9),"")) -> 1900 | E10: =IF($S$4=0,IF($L10="","",$L10),IFERROR(IF([1]筐子进出接口!$E$9=0,"",[1]筐子进出接口!$E$9),"")) | F10: =IF($S$4=0,IF($M10="","",$M10),IFERROR(IF([1]筐子进出接口!$F$9=0,"",[1]筐子进出接口!$F$9),"")) | G10: =IF($S$4=0,IF($N10="","",$N10),IFERROR(IF([1]筐子进出接口!$G$9=0,"",[1]筐子进出接口!$G$9),"")) | H10: =IF($B10="","",N($D10)) -> 1900 | O10: =IF(AND($B10<>"",$C10<>""),1,0) -> 1 | P10: =N(P9)+$O10 -> 6
A11: 10 | B11: =IF($S$4=0,IF($I11="","",$I11),IFERROR(IF([1]筐子进出接口!$B$10=0,"",[1]筐子进出接口!$B$10),"")) -> 麦麦提 | C11: =IF($S$4=0,IF($J11="","",$J11),IFERROR(IF([1]筐子进出接口!$C$10=0,"",[1]筐子进出接口!$C$10),"")) -> 公司红周转筐 | D11: =IF($S$4=0,IF($K11="","",$K11),IFERROR(IF([1]筐子进出接口!$D$10=0,"",[1]筐子进出接口!$D$10),"")) -> 2537 | E11: =IF($S$4=0,IF($L11="","",$L11),IFERROR(IF([1]筐子进出接口!$E$10=0,"",[1]筐子进出接口!$E$10),"")) | F11: =IF($S$4=0,IF($M11="","",$M11),IFERROR(IF([1]筐子进出接口!$F$10=0,"",[1]筐子进出接口!$F$10),"")) | G11: =IF($S$4=0,IF($N11="","",$N11),IFERROR(IF([1]筐子进出接口!$G$10=0,"",[1]筐子进出接口!$G$10),"")) | H11: =IF($B11="","",N($D11)) -> 2537 | O11: =IF(AND($B11<>"",$C11<>""),1,0) -> 1 | P11: =N(P10)+$O11 -> 7
A12: 11 | B12: =IF($S$4=0,IF($I12="","",$I12),IFERROR(IF([1]筐子进出接口!$B$11=0,"",[1]筐子进出接口!$B$11),"")) -> 吐尔洪 | C12: =IF($S$4=0,IF($J12="","",$J12),IFERROR(IF([1]筐子进出接口!$C$11=0,"",[1]筐子进出接口!$C$11),"")) -> 公司红周转筐 | D12: =IF($S$4=0,IF($K12="","",$K12),IFERROR(IF([1]筐子进出接口!$D$11=0,"",[1]筐子进出接口!$D$11),"")) -> 1195 | E12: =IF($S$4=0,IF($L12="","",$L12),IFERROR(IF([1]筐子进出接口!$E$11=0,"",[1]筐子进出接口!$E$11),"")) | F12: =IF($S$4=0,IF($M12="","",$M12),IFERROR(IF([1]筐子进出接口!$F$11=0,"",[1]筐子进出接口!$F$11),"")) | G12: =IF($S$4=0,IF($N12="","",$N12),IFERROR(IF([1]筐子进出接口!$G$11=0,"",[1]筐子进出接口!$G$11),"")) | H12: =IF($B12="","",N($D12)) -> 1195 | O12: =IF(AND($B12<>"",$C12<>""),1,0) -> 1 | P12: =N(P11)+$O12 -> 8
A13: 12 | B13: =IF($S$4=0,IF($I13="","",$I13),IFERROR(IF([1]筐子进出接口!$B$12=0,"",[1]筐子进出接口!$B$12),"")) -> 热合曼 | C13: =IF($S$4=0,IF($J13="","",$J13),IFERROR(IF([1]筐子进出接口!$C$12=0,"",[1]筐子进出接口!$C$12),"")) -> 公司红周转筐 | D13: =IF($S$4=0,IF($K13="","",$K13),IFERROR(IF([1]筐子进出接口!$D$12=0,"",[1]筐子进出接口!$D$12),"")) -> 1521 | E13: =IF($S$4=0,IF($L13="","",$L13),IFERROR(IF([1]筐子进出接口!$E$12=0,"",[1]筐子进出接口!$E$12),"")) | F13: =IF($S$4=0,IF($M13="","",$M13),IFERROR(IF([1]筐子进出接口!$F$12=0,"",[1]筐子进出接口!$F$12),"")) | G13: =IF($S$4=0,IF($N13="","",$N13),IFERROR(IF([1]筐子进出接口!$G$12=0,"",[1]筐子进出接口!$G$12),"")) | H13: =IF($B13="","",N($D13)) -> 1521 | O13: =IF(AND($B13<>"",$C13<>""),1,0) -> 1 | P13: =N(P12)+$O13 -> 9
A14: 13 | B14: =IF($S$4=0,IF($I14="","",$I14),IFERROR(IF([1]筐子进出接口!$B$13=0,"",[1]筐子进出接口!$B$13),"")) -> 贾建国 | C14: =IF($S$4=0,IF($J14="","",$J14),IFERROR(IF([1]筐子进出接口!$C$13=0,"",[1]筐子进出接口!$C$13),"")) -> 自备一次性筐 | D14: =IF($S$4=0,IF($K14="","",$K14),IFERROR(IF([1]筐子进出接口!$D$13=0,"",[1]筐子进出接口!$D$13),"")) -> 832 | E14: =IF($S$4=0,IF($L14="","",$L14),IFERROR(IF([1]筐子进出接口!$E$13=0,"",[1]筐子进出接口!$E$13),"")) | F14: =IF($S$4=0,IF($M14="","",$M14),IFERROR(IF([1]筐子进出接口!$F$13=0,"",[1]筐子进出接口!$F$13),"")) | G14: =IF($S$4=0,IF($N14="","",$N14),IFERROR(IF([1]筐子进出接口!$G$13=0,"",[1]筐子进出接口!$G$13),"")) | H14: =IF($B14="","",N($D14)) -> 832 | O14: =IF(AND($B14<>"",$C14<>""),1,0) -> 1 | P14: =N(P13)+$O14 -> 10
A15: 14 | B15: =IF($S$4=0,IF($I15="","",$I15),IFERROR(IF([1]筐子进出接口!$B$14=0,"",[1]筐子进出接口!$B$14),"")) -> 贾建国 | C15: =IF($S$4=0,IF($J15="","",$J15),IFERROR(IF([1]筐子进出接口!$C$14=0,"",[1]筐子进出接口!$C$14),"")) -> 自备杂周转筐 | D15: =IF($S$4=0,IF($K15="","",$K15),IFERROR(IF([1]筐子进出接口!$D$14=0,"",[1]筐子进出接口!$D$14),"")) -> 354 | E15: =IF($S$4=0,IF($L15="","",$L15),IFERROR(IF([1]筐子进出接口!$E$14=0,"",[1]筐子进出接口!$E$14),"")) | F15: =IF($S$4=0,IF($M15="","",$M15),IFERROR(IF([1]筐子进出接口!$F$14=0,"",[1]筐子进出接口!$F$14),"")) | G15: =IF($S$4=0,IF($N15="","",$N15),IFERROR(IF([1]筐子进出接口!$G$14=0,"",[1]筐子进出接口!$G$14),"")) | H15: =IF($B15="","",N($D15)) -> 354 | O15: =IF(AND($B15<>"",$C15<>""),1,0) -> 1 | P15: =N(P14)+$O15 -> 11
A16: 15 | B16: =IF($S$4=0,IF($I16="","",$I16),IFERROR(IF([1]筐子进出接口!$B$15=0,"",[1]筐子进出接口!$B$15),"")) -> 王灵云 | C16: =IF($S$4=0,IF($J16="","",$J16),IFERROR(IF([1]筐子进出接口!$C$15=0,"",[1]筐子进出接口!$C$15),"")) -> 公司红周转筐 | D16: =IF($S$4=0,IF($K16="","",$K16),IFERROR(IF([1]筐子进出接口!$D$15=0,"",[1]筐子进出接口!$D$15),"")) -> 1037 | E16: =IF($S$4=0,IF($L16="","",$L16),IFERROR(IF([1]筐子进出接口!$E$15=0,"",[1]筐子进出接口!$E$15),"")) | F16: =IF($S$4=0,IF($M16="","",$M16),IFERROR(IF([1]筐子进出接口!$F$15=0,"",[1]筐子进出接口!$F$15),"")) | G16: =IF($S$4=0,IF($N16="","",$N16),IFERROR(IF([1]筐子进出接口!$G$15=0,"",[1]筐子进出接口!$G$15),"")) | H16: =IF($B16="","",N($D16)) -> 1037 | O16: =IF(AND($B16<>"",$C16<>""),1,0) -> 1 | P16: =N(P15)+$O16 -> 12
A17: 16 | B17: =IF($S$4=0,IF($I17="","",$I17),IFERROR(IF([1]筐子进出接口!$B$16=0,"",[1]筐子进出接口!$B$16),"")) -> 杨艳玲 | C17: =IF($S$4=0,IF($J17="","",$J17),IFERROR(IF([1]筐子进出接口!$C$16=0,"",[1]筐子进出接口!$C$16),"")) -> 自备一次性筐 | D17: =IF($S$4=0,IF($K17="","",$K17),IFERROR(IF([1]筐子进出接口!$D$16=0,"",[1]筐子进出接口!$D$16),"")) -> 104 | E17: =IF($S$4=0,IF($L17="","",$L17),IFERROR(IF([1]筐子进出接口!$E$16=0,"",[1]筐子进出接口!$E$16),"")) | F17: =IF($S$4=0,IF($M17="","",$M17),IFERROR(IF([1]筐子进出接口!$F$16=0,"",[1]筐子进出接口!$F$16),"")) | G17: =IF($S$4=0,IF($N17="","",$N17),IFERROR(IF([1]筐子进出接口!$G$16=0,"",[1]筐子进出接口!$G$16),"")) | H17: =IF($B17="","",N($D17)) -> 104 | O17: =IF(AND($B17<>"",$C17<>""),1,0) -> 1 | P17: =N(P16)+$O17 -> 13
A18: 17 | B18: =IF($S$4=0,IF($I18="","",$I18),IFERROR(IF([1]筐子进出接口!$B$17=0,"",[1]筐子进出接口!$B$17),"")) -> 荆建君 | C18: =IF($S$4=0,IF($J18="","",$J18),IFERROR(IF([1]筐子进出接口!$C$17=0,"",[1]筐子进出接口!$C$17),"")) -> 公司红周转筐 | D18: =IF($S$4=0,IF($K18="","",$K18),IFERROR(IF([1]筐子进出接口!$D$17=0,"",[1]筐子进出接口!$D$17),"")) -> 1216 | E18: =IF($S$4=0,IF($L18="","",$L18),IFERROR(IF([1]筐子进出接口!$E$17=0,"",[1]筐子进出接口!$E$17),"")) | F18: =IF($S$4=0,IF($M18="","",$M18),IFERROR(IF([1]筐子进出接口!$F$17=0,"",[1]筐子进出接口!$F$17),"")) | G18: =IF($S$4=0,IF($N18="","",$N18),IFERROR(IF([1]筐子进出接口!$G$17=0,"",[1]筐子进出接口!$G$17),"")) | H18: =IF($B18="","",N($D18)) -> 1216 | O18: =IF(AND($B18<>"",$C18<>""),1,0) -> 1 | P18: =N(P17)+$O18 -> 14
A19: 18 | B19: =IF($S$4=0,IF($I19="","",$I19),IFERROR(IF([1]筐子进出接口!$B$18=0,"",[1]筐子进出接口!$B$18),"")) -> 贾建国 | C19: =IF($S$4=0,IF($J19="","",$J19),IFERROR(IF([1]筐子进出接口!$C$18=0,"",[1]筐子进出接口!$C$18),"")) -> 公司新周转筐 | D19: =IF($S$4=0,IF($K19="","",$K19),IFERROR(IF([1]筐子进出接口!$D$18=0,"",[1]筐子进出接口!$D$18),"")) -> 74 | E19: =IF($S$4=0,IF($L19="","",$L19),IFERROR(IF([1]筐子进出接口!$E$18=0,"",[1]筐子进出接口!$E$18),"")) | F19: =IF($S$4=0,IF($M19="","",$M19),IFERROR(IF([1]筐子进出接口!$F$18=0,"",[1]筐子进出接口!$F$18),"")) | G19: =IF($S$4=0,IF($N19="","",$N19),IFERROR(IF([1]筐子进出接口!$G$18=0,"",[1]筐子进出接口!$G$18),"")) | H19: =IF($B19="","",N($D19)) -> 74 | O19: =IF(AND($B19<>"",$C19<>""),1,0) -> 1 | P19: =N(P18)+$O19 -> 15
A20: 19 | B20: =IF($S$4=0,IF($I20="","",$I20),IFERROR(IF([1]筐子进出接口!$B$19=0,"",[1]筐子进出接口!$B$19),"")) -> 王照雪 | C20: =IF($S$4=0,IF($J20="","",$J20),IFERROR(IF([1]筐子进出接口!$C$19=0,"",[1]筐子进出接口!$C$19),"")) -> 公司一次性筐 | D20: =IF($S$4=0,IF($K20="","",$K20),IFERROR(IF([1]筐子进出接口!$D$19=0,"",[1]筐子进出接口!$D$19),"")) -> 543 | E20: =IF($S$4=0,IF($L20="","",$L20),IFERROR(IF([1]筐子进出接口!$E$19=0,"",[1]筐子进出接口!$E$19),"")) | F20: =IF($S$4=0,IF($M20="","",$M20),IFERROR(IF([1]筐子进出接口!$F$19=0,"",[1]筐子进出接口!$F$19),"")) | G20: =IF($S$4=0,IF($N20="","",$N20),IFERROR(IF([1]筐子进出接口!$G$19=0,"",[1]筐子进出接口!$G$19),"")) | H20: =IF($B20="","",N($D20)) -> 543 | O20: =IF(AND($B20<>"",$C20<>""),1,0) -> 1 | P20: =N(P19)+$O20 -> 16
A21: 20 | B21: =IF($S$4=0,IF($I21="","",$I21),IFERROR(IF([1]筐子进出接口!$B$20=0,"",[1]筐子进出接口!$B$20),"")) -> 努尔敦 | C21: =IF($S$4=0,IF($J21="","",$J21),IFERROR(IF([1]筐子进出接口!$C$20=0,"",[1]筐子进出接口!$C$20),"")) -> 公司红周转筐 | D21: =IF($S$4=0,IF($K21="","",$K21),IFERROR(IF([1]筐子进出接口!$D$20=0,"",[1]筐子进出接口!$D$20),"")) -> 1290 | E21: =IF($S$4=0,IF($L21="","",$L21),IFERROR(IF([1]筐子进出接口!$E$20=0,"",[1]筐子进出接口!$E$20),"")) | F21: =IF($S$4=0,IF($M21="","",$M21),IFERROR(IF([1]筐子进出接口!$F$20=0,"",[1]筐子进出接口!$F$20),"")) | G21: =IF($S$4=0,IF($N21="","",$N21),IFERROR(IF([1]筐子进出接口!$G$20=0,"",[1]筐子进出接口!$G$20),"")) | H21: =IF($B21="","",N($D21)) -> 1290 | O21: =IF(AND($B21<>"",$C21<>""),1,0) -> 1 | P21: =N(P20)+$O21 -> 17
A22: 21 | B22: =IF($S$4=0,IF($I22="","",$I22),IFERROR(IF([1]筐子进出接口!$B$21=0,"",[1]筐子进出接口!$B$21),"")) -> 王浩 | C22: =IF($S$4=0,IF($J22="","",$J22),IFERROR(IF([1]筐子进出接口!$C$21=0,"",[1]筐子进出接口!$C$21),"")) -> 公司一次性筐 | D22: =IF($S$4=0,IF($K22="","",$K22),IFERROR(IF([1]筐子进出接口!$D$21=0,"",[1]筐子进出接口!$D$21),"")) -> 1184 | E22: =IF($S$4=0,IF($L22="","",$L22),IFERROR(IF([1]筐子进出接口!$E$21=0,"",[1]筐子进出接口!$E$21),"")) | F22: =IF($S$4=0,IF($M22="","",$M22),IFERROR(IF([1]筐子进出接口!$F$21=0,"",[1]筐子进出接口!$F$21),"")) | G22: =IF($S$4=0,IF($N22="","",$N22),IFERROR(IF([1]筐子进出接口!$G$21=0,"",[1]筐子进出接口!$G$21),"")) | H22: =IF($B22="","",N($D22)) -> 1184 | O22: =IF(AND($B22<>"",$C22<>""),1,0) -> 1 | P22: =N(P21)+$O22 -> 18
A23: 22 | B23: =IF($S$4=0,IF($I23="","",$I23),IFERROR(IF([1]筐子进出接口!$B$22=0,"",[1]筐子进出接口!$B$22),"")) -> 贾建国 | C23: =IF($S$4=0,IF($J23="","",$J23),IFERROR(IF([1]筐子进出接口!$C$22=0,"",[1]筐子进出接口!$C$22),"")) -> 公司一次性筐 | D23: =IF($S$4=0,IF($K23="","",$K23),IFERROR(IF([1]筐子进出接口!$D$22=0,"",[1]筐子进出接口!$D$22),"")) -> 5 | E23: =IF($S$4=0,IF($L23="","",$L23),IFERROR(IF([1]筐子进出接口!$E$22=0,"",[1]筐子进出接口!$E$22),"")) | F23: =IF($S$4=0,IF($M23="","",$M23),IFERROR(IF([1]筐子进出接口!$F$22=0,"",[1]筐子进出接口!$F$22),"")) | G23: =IF($S$4=0,IF($N23="","",$N23),IFERROR(IF([1]筐子进出接口!$G$22=0,"",[1]筐子进出接口!$G$22),"")) | H23: =IF($B23="","",N($D23)) -> 5 | O23: =IF(AND($B23<>"",$C23<>""),1,0) -> 1 | P23: =N(P22)+$O23 -> 19
A24: 23 | B24: =IF($S$4=0,IF($I24="","",$I24),IFERROR(IF([1]筐子进出接口!$B$23=0,"",[1]筐子进出接口!$B$23),"")) -> 电商/主播 | C24: =IF($S$4=0,IF($J24="","",$J24),IFERROR(IF([1]筐子进出接口!$C$23=0,"",[1]筐子进出接口!$C$23),"")) -> 纸箱 | D24: =IF($S$4=0,IF($K24="","",$K24),IFERROR(IF([1]筐子进出接口!$D$23=0,"",[1]筐子进出接口!$D$23),"")) | E24: =IF($S$4=0,IF($L24="","",$L24),IFERROR(IF([1]筐子进出接口!$E$23=0,"",[1]筐子进出接口!$E$23),"")) | F24: =IF($S$4=0,IF($M24="","",$M24),IFERROR(IF([1]筐子进出接口!$F$23=0,"",[1]筐子进出接口!$F$23),"")) | G24: =IF($S$4=0,IF($N24="","",$N24),IFERROR(IF([1]筐子进出接口!$G$23=0,"",[1]筐子进出接口!$G$23),"")) | H24: =IF($B24="","",N($D24)) -> 0 | O24: =IF(AND($B24<>"",$C24<>""),1,0) -> 1 | P24: =N(P23)+$O24 -> 20
A25: 24 | B25: =IF($S$4=0,IF($I25="","",$I25),IFERROR(IF([1]筐子进出接口!$B$24=0,"",[1]筐子进出接口!$B$24),"")) -> 伍元虎 | C25: =IF($S$4=0,IF($J25="","",$J25),IFERROR(IF([1]筐子进出接口!$C$24=0,"",[1]筐子进出接口!$C$24),"")) -> 公司一次性筐 | D25: =IF($S$4=0,IF($K25="","",$K25),IFERROR(IF([1]筐子进出接口!$D$24=0,"",[1]筐子进出接口!$D$24),"")) | E25: =IF($S$4=0,IF($L25="","",$L25),IFERROR(IF([1]筐子进出接口!$E$24=0,"",[1]筐子进出接口!$E$24),"")) | F25: =IF($S$4=0,IF($M25="","",$M25),IFERROR(IF([1]筐子进出接口!$F$24=0,"",[1]筐子进出接口!$F$24),"")) -> 113 | G25: =IF($S$4=0,IF($N25="","",$N25),IFERROR(IF([1]筐子进出接口!$G$24=0,"",[1]筐子进出接口!$G$24),"")) -> 113 | H25: =IF($B25="","",N($D25)) -> 0 | O25: =IF(AND($B25<>"",$C25<>""),1,0) -> 1 | P25: =N(P24)+$O25 -> 21
A26: 25 | B26: =IF($S$4=0,IF($I26="","",$I26),IFERROR(IF([1]筐子进出接口!$B$25=0,"",[1]筐子进出接口!$B$25),"")) -> 王照雪 | C26: =IF($S$4=0,IF($J26="","",$J26),IFERROR(IF([1]筐子进出接口!$C$25=0,"",[1]筐子进出接口!$C$25),"")) -> 纸箱 | D26: =IF($S$4=0,IF($K26="","",$K26),IFERROR(IF([1]筐子进出接口!$D$25=0,"",[1]筐子进出接口!$D$25),"")) | E26: =IF($S$4=0,IF($L26="","",$L26),IFERROR(IF([1]筐子进出接口!$E$25=0,"",[1]筐子进出接口!$E$25),"")) | F26: =IF($S$4=0,IF($M26="","",$M26),IFERROR(IF([1]筐子进出接口!$F$25=0,"",[1]筐子进出接口!$F$25),"")) | G26: =IF($S$4=0,IF($N26="","",$N26),IFERROR(IF([1]筐子进出接口!$G$25=0,"",[1]筐子进出接口!$G$25),"")) | H26: =IF($B26="","",N($D26)) -> 0 | O26: =IF(AND($B26<>"",$C26<>""),1,0) -> 1 | P26: =N(P25)+$O26 -> 22
A27: 26 | B27: =IF($S$4=0,IF($I27="","",$I27),IFERROR(IF([1]筐子进出接口!$B$26=0,"",[1]筐子进出接口!$B$26),"")) | C27: =IF($S$4=0,IF($J27="","",$J27),IFERROR(IF([1]筐子进出接口!$C$26=0,"",[1]筐子进出接口!$C$26),"")) | D27: =IF($S$4=0,IF($K27="","",$K27),IFERROR(IF([1]筐子进出接口!$D$26=0,"",[1]筐子进出接口!$D$26),"")) | E27: =IF($S$4=0,IF($L27="","",$L27),IFERROR(IF([1]筐子进出接口!$E$26=0,"",[1]筐子进出接口!$E$26),"")) | F27: =IF($S$4=0,IF($M27="","",$M27),IFERROR(IF([1]筐子进出接口!$F$26=0,"",[1]筐子进出接口!$F$26),"")) | G27: =IF($S$4=0,IF($N27="","",$N27),IFERROR(IF([1]筐子进出接口!$G$26=0,"",[1]筐子进出接口!$G$26),"")) | H27: =IF($B27="","",N($D27)) | O27: =IF(AND($B27<>"",$C27<>""),1,0) -> 0 | P27: =N(P26)+$O27 -> 22
A28: 27 | B28: =IF($S$4=0,IF($I28="","",$I28),IFERROR(IF([1]筐子进出接口!$B$27=0,"",[1]筐子进出接口!$B$27),"")) | C28: =IF($S$4=0,IF($J28="","",$J28),IFERROR(IF([1]筐子进出接口!$C$27=0,"",[1]筐子进出接口!$C$27),"")) | D28: =IF($S$4=0,IF($K28="","",$K28),IFERROR(IF([1]筐子进出接口!$D$27=0,"",[1]筐子进出接口!$D$27),"")) | E28: =IF($S$4=0,IF($L28="","",$L28),IFERROR(IF([1]筐子进出接口!$E$27=0,"",[1]筐子进出接口!$E$27),"")) | F28: =IF($S$4=0,IF($M28="","",$M28),IFERROR(IF([1]筐子进出接口!$F$27=0,"",[1]筐子进出接口!$F$27),"")) | G28: =IF($S$4=0,IF($N28="","",$N28),IFERROR(IF([1]筐子进出接口!$G$27=0,"",[1]筐子进出接口!$G$27),"")) | H28: =IF($B28="","",N($D28)) | O28: =IF(AND($B28<>"",$C28<>""),1,0) -> 0 | P28: =N(P27)+$O28 -> 22
A29: 28 | B29: =IF($S$4=0,IF($I29="","",$I29),IFERROR(IF([1]筐子进出接口!$B$28=0,"",[1]筐子进出接口!$B$28),"")) | C29: =IF($S$4=0,IF($J29="","",$J29),IFERROR(IF([1]筐子进出接口!$C$28=0,"",[1]筐子进出接口!$C$28),"")) | D29: =IF($S$4=0,IF($K29="","",$K29),IFERROR(IF([1]筐子进出接口!$D$28=0,"",[1]筐子进出接口!$D$28),"")) | E29: =IF($S$4=0,IF($L29="","",$L29),IFERROR(IF([1]筐子进出接口!$E$28=0,"",[1]筐子进出接口!$E$28),"")) | F29: =IF($S$4=0,IF($M29="","",$M29),IFERROR(IF([1]筐子进出接口!$F$28=0,"",[1]筐子进出接口!$F$28),"")) | G29: =IF($S$4=0,IF($N29="","",$N29),IFERROR(IF([1]筐子进出接口!$G$28=0,"",[1]筐子进出接口!$G$28),"")) | H29: =IF($B29="","",N($D29)) | O29: =IF(AND($B29<>"",$C29<>""),1,0) -> 0 | P29: =N(P28)+$O29 -> 22
A30: 29 | B30: =IF($S$4=0,IF($I30="","",$I30),IFERROR(IF([1]筐子进出接口!$B$29=0,"",[1]筐子进出接口!$B$29),"")) | C30: =IF($S$4=0,IF($J30="","",$J30),IFERROR(IF([1]筐子进出接口!$C$29=0,"",[1]筐子进出接口!$C$29),"")) | D30: =IF($S$4=0,IF($K30="","",$K30),IFERROR(IF([1]筐子进出接口!$D$29=0,"",[1]筐子进出接口!$D$29),"")) | E30: =IF($S$4=0,IF($L30="","",$L30),IFERROR(IF([1]筐子进出接口!$E$29=0,"",[1]筐子进出接口!$E$29),"")) | F30: =IF($S$4=0,IF($M30="","",$M30),IFERROR(IF([1]筐子进出接口!$F$29=0,"",[1]筐子进出接口!$F$29),"")) | G30: =IF($S$4=0,IF($N30="","",$N30),IFERROR(IF([1]筐子进出接口!$G$29=0,"",[1]筐子进出接口!$G$29),"")) | H30: =IF($B30="","",N($D30)) | O30: =IF(AND($B30<>"",$C30<>""),1,0) -> 0 | P30: =N(P29)+$O30 -> 22
A31: 30 | B31: =IF($S$4=0,IF($I31="","",$I31),IFERROR(IF([1]筐子进出接口!$B$30=0,"",[1]筐子进出接口!$B$30),"")) | C31: =IF($S$4=0,IF($J31="","",$J31),IFERROR(IF([1]筐子进出接口!$C$30=0,"",[1]筐子进出接口!$C$30),"")) | D31: =IF($S$4=0,IF($K31="","",$K31),IFERROR(IF([1]筐子进出接口!$D$30=0,"",[1]筐子进出接口!$D$30),"")) | E31: =IF($S$4=0,IF($L31="","",$L31),IFERROR(IF([1]筐子进出接口!$E$30=0,"",[1]筐子进出接口!$E$30),"")) | F31: =IF($S$4=0,IF($M31="","",$M31),IFERROR(IF([1]筐子进出接口!$F$30=0,"",[1]筐子进出接口!$F$30),"")) | G31: =IF($S$4=0,IF($N31="","",$N31),IFERROR(IF([1]筐子进出接口!$G$30=0,"",[1]筐子进出接口!$G$30),"")) | H31: =IF($B31="","",N($D31)) | O31: =IF(AND($B31<>"",$C31<>""),1,0) -> 0 | P31: =N(P30)+$O31 -> 22
A32: 31 | B32: =IF($S$4=0,IF($I32="","",$I32),IFERROR(IF([1]筐子进出接口!$B$31=0,"",[1]筐子进出接口!$B$31),"")) | C32: =IF($S$4=0,IF($J32="","",$J32),IFERROR(IF([1]筐子进出接口!$C$31=0,"",[1]筐子进出接口!$C$31),"")) | D32: =IF($S$4=0,IF($K32="","",$K32),IFERROR(IF([1]筐子进出接口!$D$31=0,"",[1]筐子进出接口!$D$31),"")) | E32: =IF($S$4=0,IF($L32="","",$L32),IFERROR(IF([1]筐子进出接口!$E$31=0,"",[1]筐子进出接口!$E$31),"")) | F32: =IF($S$4=0,IF($M32="","",$M32),IFERROR(IF([1]筐子进出接口!$F$31=0,"",[1]筐子进出接口!$F$31),"")) | G32: =IF($S$4=0,IF($N32="","",$N32),IFERROR(IF([1]筐子进出接口!$G$31=0,"",[1]筐子进出接口!$G$31),"")) | H32: =IF($B32="","",N($D32)) | O32: =IF(AND($B32<>"",$C32<>""),1,0) -> 0 | P32: =N(P31)+$O32 -> 22
A33: 32 | B33: =IF($S$4=0,IF($I33="","",$I33),IFERROR(IF([1]筐子进出接口!$B$32=0,"",[1]筐子进出接口!$B$32),"")) | C33: =IF($S$4=0,IF($J33="","",$J33),IFERROR(IF([1]筐子进出接口!$C$32=0,"",[1]筐子进出接口!$C$32),"")) | D33: =IF($S$4=0,IF($K33="","",$K33),IFERROR(IF([1]筐子进出接口!$D$32=0,"",[1]筐子进出接口!$D$32),"")) | E33: =IF($S$4=0,IF($L33="","",$L33),IFERROR(IF([1]筐子进出接口!$E$32=0,"",[1]筐子进出接口!$E$32),"")) | F33: =IF($S$4=0,IF($M33="","",$M33),IFERROR(IF([1]筐子进出接口!$F$32=0,"",[1]筐子进出接口!$F$32),"")) | G33: =IF($S$4=0,IF($N33="","",$N33),IFERROR(IF([1]筐子进出接口!$G$32=0,"",[1]筐子进出接口!$G$32),"")) | H33: =IF($B33="","",N($D33)) | O33: =IF(AND($B33<>"",$C33<>""),1,0) -> 0 | P33: =N(P32)+$O33 -> 22
A34: 33 | B34: =IF($S$4=0,IF($I34="","",$I34),IFERROR(IF([1]筐子进出接口!$B$33=0,"",[1]筐子进出接口!$B$33),"")) | C34: =IF($S$4=0,IF($J34="","",$J34),IFERROR(IF([1]筐子进出接口!$C$33=0,"",[1]筐子进出接口!$C$33),"")) | D34: =IF($S$4=0,IF($K34="","",$K34),IFERROR(IF([1]筐子进出接口!$D$33=0,"",[1]筐子进出接口!$D$33),"")) | E34: =IF($S$4=0,IF($L34="","",$L34),IFERROR(IF([1]筐子进出接口!$E$33=0,"",[1]筐子进出接口!$E$33),"")) | F34: =IF($S$4=0,IF($M34="","",$M34),IFERROR(IF([1]筐子进出接口!$F$33=0,"",[1]筐子进出接口!$F$33),"")) | G34: =IF($S$4=0,IF($N34="","",$N34),IFERROR(IF([1]筐子进出接口!$G$33=0,"",[1]筐子进出接口!$G$33),"")) | H34: =IF($B34="","",N($D34)) | O34: =IF(AND($B34<>"",$C34<>""),1,0) -> 0 | P34: =N(P33)+$O34 -> 22
A35: 34 | B35: =IF($S$4=0,IF($I35="","",$I35),IFERROR(IF([1]筐子进出接口!$B$34=0,"",[1]筐子进出接口!$B$34),"")) | C35: =IF($S$4=0,IF($J35="","",$J35),IFERROR(IF([1]筐子进出接口!$C$34=0,"",[1]筐子进出接口!$C$34),"")) | D35: =IF($S$4=0,IF($K35="","",$K35),IFERROR(IF([1]筐子进出接口!$D$34=0,"",[1]筐子进出接口!$D$34),"")) | E35: =IF($S$4=0,IF($L35="","",$L35),IFERROR(IF([1]筐子进出接口!$E$34=0,"",[1]筐子进出接口!$E$34),"")) | F35: =IF($S$4=0,IF($M35="","",$M35),IFERROR(IF([1]筐子进出接口!$F$34=0,"",[1]筐子进出接口!$F$34),"")) | G35: =IF($S$4=0,IF($N35="","",$N35),IFERROR(IF([1]筐子进出接口!$G$34=0,"",[1]筐子进出接口!$G$34),"")) | H35: =IF($B35="","",N($D35)) | O35: =IF(AND($B35<>"",$C35<>""),1,0) -> 0 | P35: =N(P34)+$O35 -> 22
A36: 35 | B36: =IF($S$4=0,IF($I36="","",$I36),IFERROR(IF([1]筐子进出接口!$B$35=0,"",[1]筐子进出接口!$B$35),"")) | C36: =IF($S$4=0,IF($J36="","",$J36),IFERROR(IF([1]筐子进出接口!$C$35=0,"",[1]筐子进出接口!$C$35),"")) | D36: =IF($S$4=0,IF($K36="","",$K36),IFERROR(IF([1]筐子进出接口!$D$35=0,"",[1]筐子进出接口!$D$35),"")) | E36: =IF($S$4=0,IF($L36="","",$L36),IFERROR(IF([1]筐子进出接口!$E$35=0,"",[1]筐子进出接口!$E$35),"")) | F36: =IF($S$4=0,IF($M36="","",$M36),IFERROR(IF([1]筐子进出接口!$F$35=0,"",[1]筐子进出接口!$F$35),"")) | G36: =IF($S$4=0,IF($N36="","",$N36),IFERROR(IF([1]筐子进出接口!$G$35=0,"",[1]筐子进出接口!$G$35),"")) | H36: =IF($B36="","",N($D36)) | O36: =IF(AND($B36<>"",$C36<>""),1,0) -> 0 | P36: =N(P35)+$O36 -> 22
A37: 36 | B37: =IF($S$4=0,IF($I37="","",$I37),IFERROR(IF([1]筐子进出接口!$B$36=0,"",[1]筐子进出接口!$B$36),"")) | C37: =IF($S$4=0,IF($J37="","",$J37),IFERROR(IF([1]筐子进出接口!$C$36=0,"",[1]筐子进出接口!$C$36),"")) | D37: =IF($S$4=0,IF($K37="","",$K37),IFERROR(IF([1]筐子进出接口!$D$36=0,"",[1]筐子进出接口!$D$36),"")) | E37: =IF($S$4=0,IF($L37="","",$L37),IFERROR(IF([1]筐子进出接口!$E$36=0,"",[1]筐子进出接口!$E$36),"")) | F37: =IF($S$4=0,IF($M37="","",$M37),IFERROR(IF([1]筐子进出接口!$F$36=0,"",[1]筐子进出接口!$F$36),"")) | G37: =IF($S$4=0,IF($N37="","",$N37),IFERROR(IF([1]筐子进出接口!$G$36=0,"",[1]筐子进出接口!$G$36),"")) | H37: =IF($B37="","",N($D37)) | O37: =IF(AND($B37<>"",$C37<>""),1,0) -> 0 | P37: =N(P36)+$O37 -> 22
A38: 37 | B38: =IF($S$4=0,IF($I38="","",$I38),IFERROR(IF([1]筐子进出接口!$B$37=0,"",[1]筐子进出接口!$B$37),"")) | C38: =IF($S$4=0,IF($J38="","",$J38),IFERROR(IF([1]筐子进出接口!$C$37=0,"",[1]筐子进出接口!$C$37),"")) | D38: =IF($S$4=0,IF($K38="","",$K38),IFERROR(IF([1]筐子进出接口!$D$37=0,"",[1]筐子进出接口!$D$37),"")) | E38: =IF($S$4=0,IF($L38="","",$L38),IFERROR(IF([1]筐子进出接口!$E$37=0,"",[1]筐子进出接口!$E$37),"")) | F38: =IF($S$4=0,IF($M38="","",$M38),IFERROR(IF([1]筐子进出接口!$F$37=0,"",[1]筐子进出接口!$F$37),"")) | G38: =IF($S$4=0,IF($N38="","",$N38),IFERROR(IF([1]筐子进出接口!$G$37=0,"",[1]筐子进出接口!$G$37),"")) | H38: =IF($B38="","",N($D38)) | O38: =IF(AND($B38<>"",$C38<>""),1,0) -> 0 | P38: =N(P37)+$O38 -> 22
A39: 38 | B39: =IF($S$4=0,IF($I39="","",$I39),IFERROR(IF([1]筐子进出接口!$B$38=0,"",[1]筐子进出接口!$B$38),"")) | C39: =IF($S$4=0,IF($J39="","",$J39),IFERROR(IF([1]筐子进出接口!$C$38=0,"",[1]筐子进出接口!$C$38),"")) | D39: =IF($S$4=0,IF($K39="","",$K39),IFERROR(IF([1]筐子进出接口!$D$38=0,"",[1]筐子进出接口!$D$38),"")) | E39: =IF($S$4=0,IF($L39="","",$L39),IFERROR(IF([1]筐子进出接口!$E$38=0,"",[1]筐子进出接口!$E$38),"")) | F39: =IF($S$4=0,IF($M39="","",$M39),IFERROR(IF([1]筐子进出接口!$F$38=0,"",[1]筐子进出接口!$F$38),"")) | G39: =IF($S$4=0,IF($N39="","",$N39),IFERROR(IF([1]筐子进出接口!$G$38=0,"",[1]筐子进出接口!$G$38),"")) | H39: =IF($B39="","",N($D39)) | O39: =IF(AND($B39<>"",$C39<>""),1,0) -> 0 | P39: =N(P38)+$O39 -> 22
A40: 39 | B40: =IF($S$4=0,IF($I40="","",$I40),IFERROR(IF([1]筐子进出接口!$B$39=0,"",[1]筐子进出接口!$B$39),"")) | C40: =IF($S$4=0,IF($J40="","",$J40),IFERROR(IF([1]筐子进出接口!$C$39=0,"",[1]筐子进出接口!$C$39),"")) | D40: =IF($S$4=0,IF($K40="","",$K40),IFERROR(IF([1]筐子进出接口!$D$39=0,"",[1]筐子进出接口!$D$39),"")) | E40: =IF($S$4=0,IF($L40="","",$L40),IFERROR(IF([1]筐子进出接口!$E$39=0,"",[1]筐子进出接口!$E$39),"")) | F40: =IF($S$4=0,IF($M40="","",$M40),IFERROR(IF([1]筐子进出接口!$F$39=0,"",[1]筐子进出接口!$F$39),"")) | G40: =IF($S$4=0,IF($N40="","",$N40),IFERROR(IF([1]筐子进出接口!$G$39=0,"",[1]筐子进出接口!$G$39),"")) | H40: =IF($B40="","",N($D40)) | O40: =IF(AND($B40<>"",$C40<>""),1,0) -> 0 | P40: =N(P39)+$O40 -> 22
...

Sheet 周转筐出入库明细
A1: 周 转 筐 出 / 入 库 明 细 表
A2: ★"剩余库存"已改为按筐子类型分别滚动结存＝该类型的 期初＋采购入库＋客户退回入库 − 发出出库 − 销售出库，不再是不分类型的总数。押金：收押金/退押金按实收实退填，押金余额在【押金汇总】看
A3: 序号 | B3: 日期 | C3: 供应商/客户 | D3: 筐子类型 | E3: 票据单号 | F3: 业务类型 | G3: 期初库存 | H3: 入库数量 | I3: 退回数量(显示为负) | J3: 出库数量 | K3: 销售数量 | L3: 剩余库存 | M3: 车牌号 | N3: 装卸 | O3: 采购/销售单价 | P3: 采购/销售金额 | Q3: 收付款状态 | R3: 结算方式 | S3: 收押金 | T3: 退押金 (显示为负) | U3: 押金结清 | V3: 核查结果 | W3: 备注
A4: =IF($D4="","",ROW()-3) -> 1 | D4: 公司一次性筐 | F4: 期初库存 | G4: =IF($D4="","",N($L4)-N($H4)-N($I4)+N($J4)+N($K4)) -> 0 | H4: 69840 | I4: 0 | J4: 0 | K4: 0 | L4: =IF($D4="","",SUMIFS($H$4:$H4,$D$4:$D4,$D4)+SUMIFS($I$4:$I4,$D$4:$D4,$D4)-SUMIFS($J$4:$J4,$D$4:$D4,$D4)-SUMIFS($K$4:$K4,$D$4:$D4,$D4)) -> 69840 | P4: =IF($D4="","",ROUND((N($H4)+N($K4))*N($O4),2)) -> 0
A5: =IF($D5="","",ROW()-3) -> 2 | D5: 公司杂周转筐 | F5: 期初库存 | G5: =IF($D5="","",N($L5)-N($H5)-N($I5)+N($J5)+N($K5)) -> 0 | H5: 35928 | I5: 0 | J5: 0 | K5: 0 | L5: =IF($D5="","",SUMIFS($H$4:$H5,$D$4:$D5,$D5)+SUMIFS($I$4:$I5,$D$4:$D5,$D5)-SUMIFS($J$4:$J5,$D$4:$D5,$D5)-SUMIFS($K$4:$K5,$D$4:$D5,$D5)) -> 35928 | P5: =IF($D5="","",ROUND((N($H5)+N($K5))*N($O5),2)) -> 0
A6: =IF($D6="","",ROW()-3) -> 3 | D6: 公司新周转筐 | F6: 期初库存 | G6: =IF($D6="","",N($L6)-N($H6)-N($I6)+N($J6)+N($K6)) -> 0 | H6: 58032 | I6: 0 | J6: 0 | K6: 0 | L6: =IF($D6="","",SUMIFS($H$4:$H6,$D$4:$D6,$D6)+SUMIFS($I$4:$I6,$D$4:$D6,$D6)-SUMIFS($J$4:$J6,$D$4:$D6,$D6)-SUMIFS($K$4:$K6,$D$4:$D6,$D6)) -> 58032 | P6: =IF($D6="","",ROUND((N($H6)+N($K6))*N($O6),2)) -> 0
A7: =IF($D7="","",ROW()-3) -> 4 | D7: 公司白周转筐 | F7: 期初库存 | G7: =IF($D7="","",N($L7)-N($H7)-N($I7)+N($J7)+N($K7)) -> 0 | H7: 13968 | I7: 0 | J7: 0 | K7: 0 | L7: =IF($D7="","",SUMIFS($H$4:$H7,$D$4:$D7,$D7)+SUMIFS($I$4:$I7,$D$4:$D7,$D7)-SUMIFS($J$4:$J7,$D$4:$D7,$D7)-SUMIFS($K$4:$K7,$D$4:$D7,$D7)) -> 13968 | P7: =IF($D7="","",ROUND((N($H7)+N($K7))*N($O7),2)) -> 0
A8: =IF($D8="","",ROW()-3) -> 5 | B8: 46245 | C8: 王照雪 | D8: 公司杂周转筐 | E8: NO:0001015 | F8: 领用出库 | G8: =IF($D8="","",N($L8)-N($H8)-N($I8)+N($J8)+N($K8)) -> 35928 | H8: - | I8: - | J8: 351 | K8: - | L8: =IF($D8="","",SUMIFS($H$4:$H8,$D$4:$D8,$D8)+SUMIFS($I$4:$I8,$D$4:$D8,$D8)-SUMIFS($J$4:$J8,$D$4:$D8,$D8)-SUMIFS($K$4:$K8,$D$4:$D8,$D8)) -> 35577 | M8: 豫L*88X19 | N8: 依力 | P8: =IF($D8="","",ROUND((N($H8)+N($K8))*N($O8),2)) -> 0
A9: =IF($D9="","",ROW()-3) -> 6 | B9: 46255 | C9: 王照雪 | D9: 公司杂周转筐 | E9: NO:0001022 | F9: 领用出库 | G9: =IF($D9="","",N($L9)-N($H9)-N($I9)+N($J9)+N($K9)) -> 35577 | H9: - | I9: - | J9: 432 | K9: - | L9: =IF($D9="","",SUMIFS($H$4:$H9,$D$4:$D9,$D9)+SUMIFS($I$4:$I9,$D$4:$D9,$D9)-SUMIFS($J$4:$J9,$D$4:$D9,$D9)-SUMIFS($K$4:$K9,$D$4:$D9,$D9)) -> 35145 | M9: 豫L*88X19 | N9: 依力 | P9: =IF($D9="","",ROUND((N($H9)+N($K9))*N($O9),2)) -> 0
A10: =IF($D10="","",ROW()-3) -> 7 | B10: 46258 | C10: 王照雪 | D10: 公司杂周转筐 | E10: NO:0001031 | F10: 领用出库 | G10: =IF($D10="","",N($L10)-N($H10)-N($I10)+N($J10)+N($K10)) -> 35145 | H10: - | I10: - | J10: 282 | K10: - | L10: =IF($D10="","",SUMIFS($H$4:$H10,$D$4:$D10,$D10)+SUMIFS($I$4:$I10,$D$4:$D10,$D10)-SUMIFS($J$4:$J10,$D$4:$D10,$D10)-SUMIFS($K$4:$K10,$D$4:$D10,$D10)) -> 34863 | M10: 豫L*88X19 | N10: 依力 | P10: =IF($D10="","",ROUND((N($H10)+N($K10))*N($O10),2)) -> 0
A11: =IF($D11="","",ROW()-3) -> 8 | B11: 46260 | C11: 王照雪 | D11: 公司杂周转筐 | E11: NO:0001037 | F11: 领用出库 | G11: =IF($D11="","",N($L11)-N($H11)-N($I11)+N($J11)+N($K11)) -> 34863 | H11: - | I11: - | J11: 144 | K11: - | L11: =IF($D11="","",SUMIFS($H$4:$H11,$D$4:$D11,$D11)+SUMIFS($I$4:$I11,$D$4:$D11,$D11)-SUMIFS($J$4:$J11,$D$4:$D11,$D11)-SUMIFS($K$4:$K11,$D$4:$D11,$D11)) -> 34719 | M11: 豫L*88X19 | N11: 依力 | P11: =IF($D11="","",ROUND((N($H11)+N($K11))*N($O11),2)) -> 0
A12: =IF($D12="","",ROW()-3) -> 9 | B12: 46258 | C12: 王照雪 | D12: 公司杂周转筐 | E12: NO:0000721 | F12: 退回入库 | G12: =IF($D12="","",N($L12)-N($H12)-N($I12)+N($J12)+N($K12)) -> 34719 | H12: - | I12: 4 | J12: - | K12: - | L12: =IF($D12="","",SUMIFS($H$4:$H12,$D$4:$D12,$D12)+SUMIFS($I$4:$I12,$D$4:$D12,$D12)-SUMIFS($J$4:$J12,$D$4:$D12,$D12)-SUMIFS($K$4:$K12,$D$4:$D12,$D12)) -> 34723 | M12: 豫L*88X19 | N12: 依力 | P12: =IF($D12="","",ROUND((N($H12)+N($K12))*N($O12),2)) -> 0
A13: =IF($D13="","",ROW()-3) -> 10 | B13: 46265 | C13: 王浩 | D13: 公司一次性筐 | E13: NO:0001057 | F13: 领用出库 | G13: =IF($D13="","",N($L13)-N($H13)-N($I13)+N($J13)+N($K13)) -> 69840 | H13: - | I13: - | J13: 2040 | K13: - | L13: =IF($D13="","",SUMIFS($H$4:$H13,$D$4:$D13,$D13)+SUMIFS($I$4:$I13,$D$4:$D13,$D13)-SUMIFS($J$4:$J13,$D$4:$D13,$D13)-SUMIFS($K$4:$K13,$D$4:$D13,$D13)) -> 67800 | M13: 新Q*67674 | N13: 依力 | P13: =IF($D13="","",ROUND((N($H13)+N($K13))*N($O13),2)) -> 0
A14: =IF($D14="","",ROW()-3) -> 11 | B14: 46266 | C14: 马锦祥 | D14: 公司杂周转筐 | E14: NO:0001061 | F14: 领用出库 | G14: =IF($D14="","",N($L14)-N($H14)-N($I14)+N($J14)+N($K14)) -> 34723 | H14: - | I14: - | J14: 588 | K14: - | L14: =IF($D14="","",SUMIFS($H$4:$H14,$D$4:$D14,$D14)+SUMIFS($I$4:$I14,$D$4:$D14,$D14)-SUMIFS($J$4:$J14,$D$4:$D14,$D14)-SUMIFS($K$4:$K14,$D$4:$D14,$D14)) -> 34135 | M14: 新N*K7V85 | N14: 依力 | P14: =IF($D14="","",ROUND((N($H14)+N($K14))*N($O14),2)) -> 0
A15: =IF($D15="","",ROW()-3) -> 12 | B15: 46266 | C15: 王照雪 | D15: 公司杂周转筐 | E15: NO:0000742 | F15: 退回入库 | G15: =IF($D15="","",N($L15)-N($H15)-N($I15)+N($J15)+N($K15)) -> 34135 | H15: - | I15: 30 | J15: - | K15: - | L15: =IF($D15="","",SUMIFS($H$4:$H15,$D$4:$D15,$D15)+SUMIFS($I$4:$I15,$D$4:$D15,$D15)-SUMIFS($J$4:$J15,$D$4:$D15,$D15)-SUMIFS($K$4:$K15,$D$4:$D15,$D15)) -> 34165 | M15: 新N*D1W48 | N15: 依力 | P15: =IF($D15="","",ROUND((N($H15)+N($K15))*N($O15),2)) -> 0
A16: =IF($D16="","",ROW()-3) -> 13 | B16: 46267 | C16: 全修塑业 | D16: 公司红周转筐 | E16: NO:0000744 | F16: 采购入库 | G16: =IF($D16="","",N($L16)-N($H16)-N($I16)+N($J16)+N($K16)) -> 0 | H16: 315 | I16: - | J16: - | K16: - | L16: =IF($D16="","",SUMIFS($H$4:$H16,$D$4:$D16,$D16)+SUMIFS($I$4:$I16,$D$4:$D16,$D16)-SUMIFS($J$4:$J16,$D$4:$D16,$D16)-SUMIFS($K$4:$K16,$D$4:$D16,$D16)) -> 315 | M16: 新N*X8S48 | N16: 筐厂 | O16: 10 | P16: =IF($D16="","",ROUND((N($H16)+N($K16))*N($O16),2)) -> 3150 | Q16: 未付款 | W16: NO:2745225
A17: =IF($D17="","",ROW()-3) -> 14 | B17: 46267 | C17: 吐尔洪 | D17: 公司红周转筐 | E17: NO:0001067 | F17: 领用出库 | G17: =IF($D17="","",N($L17)-N($H17)-N($I17)+N($J17)+N($K17)) -> 315 | H17: - | I17: - | J17: 315 | K17: - | L17: =IF($D17="","",SUMIFS($H$4:$H17,$D$4:$D17,$D17)+SUMIFS($I$4:$I17,$D$4:$D17,$D17)-SUMIFS($J$4:$J17,$D$4:$D17,$D17)-SUMIFS($K$4:$K17,$D$4:$D17,$D17)) -> 0 | M17: 新N*X8S48 | N17: 筐厂 | P17: =IF($D17="","",ROUND((N($H17)+N($K17))*N($O17),2)) -> 0
A18: =IF($D18="","",ROW()-3) -> 15 | B18: 46268 | C18: 全修塑业 | D18: 公司红周转筐 | E18: NO:0000745 | F18: 采购入库 | G18: =IF($D18="","",N($L18)-N($H18)-N($I18)+N($J18)+N($K18)) -> 0 | H18: 315 | I18: - | J18: - | K18: - | L18: =IF($D18="","",SUMIFS($H$4:$H18,$D$4:$D18,$D18)+SUMIFS($I$4:$I18,$D$4:$D18,$D18)-SUMIFS($J$4:$J18,$D$4:$D18,$D18)-SUMIFS($K$4:$K18,$D$4:$D18,$D18)) -> 315 | M18: 新N*X8S48 | N18: 筐厂 | O18: 10 | P18: =IF($D18="","",ROUND((N($H18)+N($K18))*N($O18),2)) -> 3150 | Q18: 未付款 | W18: NO:2745241
A19: =IF($D19="","",ROW()-3) -> 16 | B19: 46268 | C19: 吐尔洪 | D19: 公司红周转筐 | E19: NO:0001068 | F19: 领用出库 | G19: =IF($D19="","",N($L19)-N($H19)-N($I19)+N($J19)+N($K19)) -> 315 | H19: - | I19: - | J19: 315 | K19: - | L19: =IF($D19="","",SUMIFS($H$4:$H19,$D$4:$D19,$D19)+SUMIFS($I$4:$I19,$D$4:$D19,$D19)-SUMIFS($J$4:$J19,$D$4:$D19,$D19)-SUMIFS($K$4:$K19,$D$4:$D19,$D19)) -> 0 | M19: 新N*X8S48 | N19: 筐厂 | P19: =IF($D19="","",ROUND((N($H19)+N($K19))*N($O19),2)) -> 0
A20: =IF($D20="","",ROW()-3) -> 17 | B20: 46268 | C20: 全修塑业 | D20: 公司红周转筐 | E20: NO:0000746 | F20: 采购入库 | G20: =IF($D20="","",N($L20)-N($H20)-N($I20)+N($J20)+N($K20)) -> 0 | H20: 846 | I20: - | J20: - | K20: - | L20: =IF($D20="","",SUMIFS($H$4:$H20,$D$4:$D20,$D20)+SUMIFS($I$4:$I20,$D$4:$D20,$D20)-SUMIFS($J$4:$J20,$D$4:$D20,$D20)-SUMIFS($K$4:$K20,$D$4:$D20,$D20)) -> 846 | M20: 新A*G0554 | N20: 筐厂 | O20: 10 | P20: =IF($D20="","",ROUND((N($H20)+N($K20))*N($O20),2)) -> 8460 | Q20: 未付款 | W20: NO:2745242
A21: =IF($D21="","",ROW()-3) -> 18 | B21: 46268 | C21: 热合曼 | D21: 公司红周转筐 | E21: NO:0001069 | F21: 领用出库 | G21: =IF($D21="","",N($L21)-N($H21)-N($I21)+N($J21)+N($K21)) -> 846 | H21: - | I21: - | J21: 846 | K21: - | L21: =IF($D21="","",SUMIFS($H$4:$H21,$D$4:$D21,$D21)+SUMIFS($I$4:$I21,$D$4:$D21,$D21)-SUMIFS($J$4:$J21,$D$4:$D21,$D21)-SUMIFS($K$4:$K21,$D$4:$D21,$D21)) -> 0 | M21: 新A*G0554 | N21: 筐厂 | P21: =IF($D21="","",ROUND((N($H21)+N($K21))*N($O21),2)) -> 0
A22: =IF($D22="","",ROW()-3) -> 19 | B22: 46268 | C22: 全修塑业 | D22: 公司红周转筐 | E22: NO:0000747 | F22: 采购入库 | G22: =IF($D22="","",N($L22)-N($H22)-N($I22)+N($J22)+N($K22)) -> 0 | H22: 960 | I22: - | J22: - | K22: - | L22: =IF($D22="","",SUMIFS($H$4:$H22,$D$4:$D22,$D22)+SUMIFS($I$4:$I22,$D$4:$D22,$D22)-SUMIFS($J$4:$J22,$D$4:$D22,$D22)-SUMIFS($K$4:$K22,$D$4:$D22,$D22)) -> 960 | M22: 新N*49209 | N22: 筐厂 | O22: 10 | P22: =IF($D22="","",ROUND((N($H22)+N($K22))*N($O22),2)) -> 9600 | Q22: 未付款 | W22: NO:2745243
A23: =IF($D23="","",ROW()-3) -> 20 | B23: 46268 | C23: 王灵云 | D23: 公司红周转筐 | E23: NO:0001072 | F23: 领用出库 | G23: =IF($D23="","",N($L23)-N($H23)-N($I23)+N($J23)+N($K23)) -> 960 | H23: - | I23: - | J23: 960 | K23: - | L23: =IF($D23="","",SUMIFS($H$4:$H23,$D$4:$D23,$D23)+SUMIFS($I$4:$I23,$D$4:$D23,$D23)-SUMIFS($J$4:$J23,$D$4:$D23,$D23)-SUMIFS($K$4:$K23,$D$4:$D23,$D23)) -> 0 | M23: 新N*49209 | N23: 筐厂 | P23: =IF($D23="","",ROUND((N($H23)+N($K23))*N($O23),2)) -> 0 | S23: 3000 | T23: 3000 | U23: 是
A24: =IF($D24="","",ROW()-3) -> 21 | B24: 46268 | C24: 全修塑业 | D24: 公司红周转筐 | E24: NO:0000748 | F24: 采购入库 | G24: =IF($D24="","",N($L24)-N($H24)-N($I24)+N($J24)+N($K24)) -> 0 | H24: 846 | I24: - | J24: - | K24: - | L24: =IF($D24="","",SUMIFS($H$4:$H24,$D$4:$D24,$D24)+SUMIFS($I$4:$I24,$D$4:$D24,$D24)-SUMIFS($J$4:$J24,$D$4:$D24,$D24)-SUMIFS($K$4:$K24,$D$4:$D24,$D24)) -> 846 | M24: 新A*G0554 | N24: 筐厂 | O24: 10 | P24: =IF($D24="","",ROUND((N($H24)+N($K24))*N($O24),2)) -> 8460 | Q24: 未付款 | W24: NO:2745244
A25: =IF($D25="","",ROW()-3) -> 22 | B25: 46268 | C25: 麦麦提 | D25: 公司红周转筐 | E25: NO:0001074 | F25: 领用出库 | G25: =IF($D25="","",N($L25)-N($H25)-N($I25)+N($J25)+N($K25)) -> 846 | H25: - | I25: - | J25: 846 | K25: - | L25: =IF($D25="","",SUMIFS($H$4:$H25,$D$4:$D25,$D25)+SUMIFS($I$4:$I25,$D$4:$D25,$D25)-SUMIFS($J$4:$J25,$D$4:$D25,$D25)-SUMIFS($K$4:$K25,$D$4:$D25,$D25)) -> 0 | M25: 新A*G0554 | N25: 筐厂 | P25: =IF($D25="","",ROUND((N($H25)+N($K25))*N($O25),2)) -> 0
A26: =IF($D26="","",ROW()-3) -> 23 | B26: 46268 | C26: 全修塑业 | D26: 公司红周转筐 | E26: NO:0000749 | F26: 采购入库 | G26: =IF($D26="","",N($L26)-N($H26)-N($I26)+N($J26)+N($K26)) -> 0 | H26: 936 | I26: - | J26: - | K26: - | L26: =IF($D26="","",SUMIFS($H$4:$H26,$D$4:$D26,$D26)+SUMIFS($I$4:$I26,$D$4:$D26,$D26)-SUMIFS($J$4:$J26,$D$4:$D26,$D26)-SUMIFS($K$4:$K26,$D$4:$D26,$D26)) -> 936 | M26: 新F*75240 | N26: 筐厂 | O26: 10 | P26: =IF($D26="","",ROUND((N($H26)+N($K26))*N($O26),2)) -> 9360 | Q26: 未付款 | W26: NO:2745245
A27: =IF($D27="","",ROW()-3) -> 24 | B27: 46268 | C27: 努尔敦 | D27: 公司红周转筐 | E27: NO:0001075 | F27: 领用出库 | G27: =IF($D27="","",N($L27)-N($H27)-N($I27)+N($J27)+N($K27)) -> 936 | H27: - | I27: - | J27: 936 | K27: - | L27: =IF($D27="","",SUMIFS($H$4:$H27,$D$4:$D27,$D27)+SUMIFS($I$4:$I27,$D$4:$D27,$D27)-SUMIFS($J$4:$J27,$D$4:$D27,$D27)-SUMIFS($K$4:$K27,$D$4:$D27,$D27)) -> 0 | M27: 新F*75240 | N27: 筐厂 | P27: =IF($D27="","",ROUND((N($H27)+N($K27))*N($O27),2)) -> 0
A28: =IF($D28="","",ROW()-3) -> 25 | B28: 46269 | C28: 全修塑业 | D28: 公司红周转筐 | E28: NO:0000750 | F28: 采购入库 | G28: =IF($D28="","",N($L28)-N($H28)-N($I28)+N($J28)+N($K28)) -> 0 | H28: 960 | I28: - | J28: - | K28: - | L28: =IF($D28="","",SUMIFS($H$4:$H28,$D$4:$D28,$D28)+SUMIFS($I$4:$I28,$D$4:$D28,$D28)-SUMIFS($J$4:$J28,$D$4:$D28,$D28)-SUMIFS($K$4:$K28,$D$4:$D28,$D28)) -> 960 | M28: 豫A*2737K | N28: 筐厂 | O28: 10 | P28: =IF($D28="","",ROUND((N($H28)+N($K28))*N($O28),2)) -> 9600 | Q28: 未付款 | W28: NO:2745247
A29: =IF($D29="","",ROW()-3) -> 26 | B29: 46269 | C29: 荆建君 | D29: 公司红周转筐 | E29: NO:0001077 | F29: 领用出库 | G29: =IF($D29="","",N($L29)-N($H29)-N($I29)+N($J29)+N($K29)) -> 960 | H29: - | I29: - | J29: 960 | K29: - | L29: =IF($D29="","",SUMIFS($H$4:$H29,$D$4:$D29,$D29)+SUMIFS($I$4:$I29,$D$4:$D29,$D29)-SUMIFS($J$4:$J29,$D$4:$D29,$D29)-SUMIFS($K$4:$K29,$D$4:$D29,$D29)) -> 0 | M29: 豫A*2737K | N29: 筐厂 | P29: =IF($D29="","",ROUND((N($H29)+N($K29))*N($O29),2)) -> 0
A30: =IF($D30="","",ROW()-3) -> 27 | B30: 46269 | C30: 马锦祥 | D30: 公司杂周转筐 | E30: NO:0001076 | F30: 领用出库 | G30: =IF($D30="","",N($L30)-N($H30)-N($I30)+N($J30)+N($K30)) -> 34165 | H30: - | I30: - | J30: 574 | K30: - | L30: =IF($D30="","",SUMIFS($H$4:$H30,$D$4:$D30,$D30)+SUMIFS($I$4:$I30,$D$4:$D30,$D30)-SUMIFS($J$4:$J30,$D$4:$D30,$D30)-SUMIFS($K$4:$K30,$D$4:$D30,$D30)) -> 33591 | M30: 新N*K7V85 | N30: 依力 | P30: =IF($D30="","",ROUND((N($H30)+N($K30))*N($O30),2)) -> 0
A31: =IF($D31="","",ROW()-3) -> 28 | B31: 46269 | C31: 全修塑业 | D31: 公司红周转筐 | E31: NO:0000751 | F31: 采购入库 | G31: =IF($D31="","",N($L31)-N($H31)-N($I31)+N($J31)+N($K31)) -> 0 | H31: 936 | I31: - | J31: - | K31: - | L31: =IF($D31="","",SUMIFS($H$4:$H31,$D$4:$D31,$D31)+SUMIFS($I$4:$I31,$D$4:$D31,$D31)-SUMIFS($J$4:$J31,$D$4:$D31,$D31)-SUMIFS($K$4:$K31,$D$4:$D31,$D31)) -> 936 | M31: 新F*75240 | N31: 筐厂 | O31: 10 | P31: =IF($D31="","",ROUND((N($H31)+N($K31))*N($O31),2)) -> 9360 | Q31: 未付款 | W31: NO:2745248
A32: =IF($D32="","",ROW()-3) -> 29 | B32: 46269 | C32: 努尔敦 | D32: 公司红周转筐 | E32: NO:0001078 | F32: 领用出库 | G32: =IF($D32="","",N($L32)-N($H32)-N($I32)+N($J32)+N($K32)) -> 936 | H32: - | I32: - | J32: 936 | K32: - | L32: =IF($D32="","",SUMIFS($H$4:$H32,$D$4:$D32,$D32)+SUMIFS($I$4:$I32,$D$4:$D32,$D32)-SUMIFS($J$4:$J32,$D$4:$D32,$D32)-SUMIFS($K$4:$K32,$D$4:$D32,$D32)) -> 0 | M32: 新F*75240 | N32: 筐厂 | P32: =IF($D32="","",ROUND((N($H32)+N($K32))*N($O32),2)) -> 0
A33: =IF($D33="","",ROW()-3) -> 30 | B33: 46269 | C33: 全修塑业 | D33: 公司红周转筐 | E33: NO:0000753 | F33: 采购入库 | G33: =IF($D33="","",N($L33)-N($H33)-N($I33)+N($J33)+N($K33)) -> 0 | H33: 582 | I33: - | J33: - | K33: - | L33: =IF($D33="","",SUMIFS($H$4:$H33,$D$4:$D33,$D33)+SUMIFS($I$4:$I33,$D$4:$D33,$D33)-SUMIFS($J$4:$J33,$D$4:$D33,$D33)-SUMIFS($K$4:$K33,$D$4:$D33,$D33)) -> 582 | M33: 豫A*2737K | N33: 筐厂 | O33: 10 | P33: =IF($D33="","",ROUND((N($H33)+N($K33))*N($O33),2)) -> 5820 | Q33: 未付款 | W33: NO:2745249
A34: =IF($D34="","",ROW()-3) -> 31 | B34: 46269 | C34: 荆建君 | D34: 公司红周转筐 | E34: NO:0001079 | F34: 领用出库 | G34: =IF($D34="","",N($L34)-N($H34)-N($I34)+N($J34)+N($K34)) -> 582 | H34: - | I34: - | J34: 582 | K34: - | L34: =IF($D34="","",SUMIFS($H$4:$H34,$D$4:$D34,$D34)+SUMIFS($I$4:$I34,$D$4:$D34,$D34)-SUMIFS($J$4:$J34,$D$4:$D34,$D34)-SUMIFS($K$4:$K34,$D$4:$D34,$D34)) -> 0 | M34: 豫A*2737K | N34: 筐厂 | P34: =IF($D34="","",ROUND((N($H34)+N($K34))*N($O34),2)) -> 0
A35: =IF($D35="","",ROW()-3) -> 32 | B35: 46270 | C35: 王浩 | D35: 公司一次性筐 | E35: NO:0001086 | F35: 领用出库 | G35: =IF($D35="","",N($L35)-N($H35)-N($I35)+N($J35)+N($K35)) -> 67800 | H35: - | I35: - | J35: 1320 | K35: - | L35: =IF($D35="","",SUMIFS($H$4:$H35,$D$4:$D35,$D35)+SUMIFS($I$4:$I35,$D$4:$D35,$D35)-SUMIFS($J$4:$J35,$D$4:$D35,$D35)-SUMIFS($K$4:$K35,$D$4:$D35,$D35)) -> 66480 | M35: 新M*79997 | N35: 依力 | P35: =IF($D35="","",ROUND((N($H35)+N($K35))*N($O35),2)) -> 0
A36: =IF($D36="","",ROW()-3) -> 33 | B36: 46271 | C36: 贾建国 | D36: 公司新周转筐 | E36: NO:0001087 | F36: 领用出库 | G36: =IF($D36="","",N($L36)-N($H36)-N($I36)+N($J36)+N($K36)) -> 58032 | H36: - | I36: - | J36: 252 | K36: - | L36: =IF($D36="","",SUMIFS($H$4:$H36,$D$4:$D36,$D36)+SUMIFS($I$4:$I36,$D$4:$D36,$D36)-SUMIFS($J$4:$J36,$D$4:$D36,$D36)-SUMIFS($K$4:$K36,$D$4:$D36,$D36)) -> 57780 | M36: 新N*56508 | N36: 依力 | P36: =IF($D36="","",ROUND((N($H36)+N($K36))*N($O36),2)) -> 0
A37: =IF($D37="","",ROW()-3) -> 34 | B37: 46272 | C37: 全修塑业 | D37: 公司红周转筐 | E37: NO:0000755 | F37: 采购入库 | G37: =IF($D37="","",N($L37)-N($H37)-N($I37)+N($J37)+N($K37)) -> 0 | H37: 846 | I37: - | J37: - | K37: - | L37: =IF($D37="","",SUMIFS($H$4:$H37,$D$4:$D37,$D37)+SUMIFS($I$4:$I37,$D$4:$D37,$D37)-SUMIFS($J$4:$J37,$D$4:$D37,$D37)-SUMIFS($K$4:$K37,$D$4:$D37,$D37)) -> 846 | M37: 新A*G0554 | N37: 筐厂 | O37: 10 | P37: =IF($D37="","",ROUND((N($H37)+N($K37))*N($O37),2)) -> 8460 | Q37: 未付款 | W37: NO:2745250
A38: =IF($D38="","",ROW()-3) -> 35 | B38: 46272 | C38: 麦麦提 | D38: 公司红周转筐 | E38: NO:0001089 | F38: 领用出库 | G38: =IF($D38="","",N($L38)-N($H38)-N($I38)+N($J38)+N($K38)) -> 846 | H38: - | I38: - | J38: 846 | K38: - | L38: =IF($D38="","",SUMIFS($H$4:$H38,$D$4:$D38,$D38)+SUMIFS($I$4:$I38,$D$4:$D38,$D38)-SUMIFS($J$4:$J38,$D$4:$D38,$D38)-SUMIFS($K$4:$K38,$D$4:$D38,$D38)) -> 0 | M38: 新A*G0554 | N38: 筐厂 | P38: =IF($D38="","",ROUND((N($H38)+N($K38))*N($O38),2)) -> 0
A39: =IF($D39="","",ROW()-3) -> 36 | B39: 46272 | C39: 全修塑业 | D39: 公司红周转筐 | E39: NO:0000759 | F39: 采购入库 | G39: =IF($D39="","",N($L39)-N($H39)-N($I39)+N($J39)+N($K39)) -> 0 | H39: 846 | I39: - | J39: - | K39: - | L39: =IF($D39="","",SUMIFS($H$4:$H39,$D$4:$D39,$D39)+SUMIFS($I$4:$I39,$D$4:$D39,$D39)-SUMIFS($J$4:$J39,$D$4:$D39,$D39)-SUMIFS($K$4:$K39,$D$4:$D39,$D39)) -> 846 | M39: 新A*G0554 | N39: 筐厂 | O39: 10 | P39: =IF($D39="","",ROUND((N($H39)+N($K39))*N($O39),2)) -> 8460 | Q39: 未付款 | W39: NO:2745251
A40: =IF($D40="","",ROW()-3) -> 37 | B40: 46272 | C40: 马锦祥 | D40: 公司杂周转筐 | E40: NO:0001090 | F40: 领用出库 | G40: =IF($D40="","",N($L40)-N($H40)-N($I40)+N($J40)+N($K40)) -> 33591 | H40: - | I40: - | J40: 588 | K40: - | L40: =IF($D40="","",SUMIFS($H$4:$H40,$D$4:$D40,$D40)+SUMIFS($I$4:$I40,$D$4:$D40,$D40)-SUMIFS($J$4:$J40,$D$4:$D40,$D40)-SUMIFS($K$4:$K40,$D$4:$D40,$D40)) -> 33003 | M40: 新N*K7V85 | N40: 依力 | P40: =IF($D40="","",ROUND((N($H40)+N($K40))*N($O40),2)) -> 0
...

Sheet 包装物料出入库明细
A1: 包 装 物 料 出 入 库 明 细 表
A2: ★ 计价数量＝入库＋出库−退回（退回自动冲减，不会重复收款）；合计金额＝计价数量×单价。「退回数量」照常填正数，显示成红色负数。
A3: 序号 | B3: 日期 | C3: 票据单号 | D3: 供应商/客户 | E3: 物料种类 | F3: 规格 | G3: 计量单位 | H3: 业务类型 | I3: 入库数量 | J3: 出库数量 | K3: 退回数量(显示为负) | L3: 计价数量 (退回已冲减) | M3: 单价 | N3: 合计金额 | O3: 车牌号 | P3: 收/付款 状态 | Q3: 核查结果 | R3: 备注
A4: =IF($E4="","",ROW()-3) -> 1 | B4: 46266 | D4: 果然鲜 | E4: 气泡垫 | F4: =IF($E4="","",IFERROR(INDEX(基础资料!$O$4:$O$34,MATCH($E4,基础资料!$N$4:$N$34,0))&"","")) -> *1000 | G4: =IF($E4="","",IFERROR(INDEX(基础资料!$P$4:$P$34,MATCH($E4,基础资料!$N$4:$N$34,0))&"","")) -> 片 | H4: 期初库存 | I4: 13800 | L4: =IF($E4="","",N($I4)+N($J4)-N($K4)) -> 13800 | N4: =IF($E4="","",ROUND(N($L4)*N($M4),2)) -> 0
A5: =IF($E5="","",ROW()-3) -> 2 | B5: 46266 | D5: 果然鲜 | E5: 无纺布 | F5: =IF($E5="","",IFERROR(INDEX(基础资料!$O$4:$O$34,MATCH($E5,基础资料!$N$4:$N$34,0))&"","")) -> *400 | G5: =IF($E5="","",IFERROR(INDEX(基础资料!$P$4:$P$34,MATCH($E5,基础资料!$N$4:$N$34,0))&"","")) -> 个 | H5: 期初库存 | I5: 2400 | L5: =IF($E5="","",N($I5)+N($J5)-N($K5)) -> 2400 | N5: =IF($E5="","",ROUND(N($L5)*N($M5),2)) -> 0
A6: =IF($E6="","",ROW()-3) -> 3 | B6: 46266 | D6: 果然鲜 | E6: 纸垫板 | F6: =IF($E6="","",IFERROR(INDEX(基础资料!$O$4:$O$34,MATCH($E6,基础资料!$N$4:$N$34,0))&"","")) -> *100张 | G6: =IF($E6="","",IFERROR(INDEX(基础资料!$P$4:$P$34,MATCH($E6,基础资料!$N$4:$N$34,0))&"","")) -> 张 | H6: 期初库存 | I6: 8700 | L6: =IF($E6="","",N($I6)+N($J6)-N($K6)) -> 8700 | N6: =IF($E6="","",ROUND(N($L6)*N($M6),2)) -> 0
A7: =IF($E7="","",ROW()-3) -> 4 | B7: 46266 | D7: 果然鲜 | E7: 香梨纸 | F7: =IF($E7="","",IFERROR(INDEX(基础资料!$O$4:$O$34,MATCH($E7,基础资料!$N$4:$N$34,0))&"","")) -> *捆 | G7: =IF($E7="","",IFERROR(INDEX(基础资料!$P$4:$P$34,MATCH($E7,基础资料!$N$4:$N$34,0))&"","")) -> 捆 | H7: 期初库存 | I7: 48 | L7: =IF($E7="","",N($I7)+N($J7)-N($K7)) -> 48 | N7: =IF($E7="","",ROUND(N($L7)*N($M7),2)) -> 0
A8: =IF($E8="","",ROW()-3) -> 5 | B8: 46266 | D8: 果然鲜 | E8: 冷煤/氟利昂 | F8: =IF($E8="","",IFERROR(INDEX(基础资料!$O$4:$O$34,MATCH($E8,基础资料!$N$4:$N$34,0))&"","")) -> *瓶 | G8: =IF($E8="","",IFERROR(INDEX(基础资料!$P$4:$P$34,MATCH($E8,基础资料!$N$4:$N$34,0))&"","")) -> 瓶 | H8: 期初库存 | I8: 23 | L8: =IF($E8="","",N($I8)+N($J8)-N($K8)) -> 23 | N8: =IF($E8="","",ROUND(N($L8)*N($M8),2)) -> 0
A9: =IF($E9="","",ROW()-3) -> 6 | B9: 46266 | D9: 果然鲜 | E9: 胶带 | F9: =IF($E9="","",IFERROR(INDEX(基础资料!$O$4:$O$34,MATCH($E9,基础资料!$N$4:$N$34,0))&"","")) -> *30卷 | G9: =IF($E9="","",IFERROR(INDEX(基础资料!$P$4:$P$34,MATCH($E9,基础资料!$N$4:$N$34,0))&"","")) -> 卷 | H9: 期初库存 | I9: 2 | L9: =IF($E9="","",N($I9)+N($J9)-N($K9)) -> 2 | N9: =IF($E9="","",ROUND(N($L9)*N($M9),2)) -> 0
A10: =IF($E10="","",ROW()-3) -> 7 | B10: 46266 | C10: NO:0000743 | D10: 新顺发泡网 | E10: 香梨网 | F10: =IF($E10="","",IFERROR(INDEX(基础资料!$O$4:$O$34,MATCH($E10,基础资料!$N$4:$N$34,0))&"","")) -> *包 | G10: =IF($E10="","",IFERROR(INDEX(基础资料!$P$4:$P$34,MATCH($E10,基础资料!$N$4:$N$34,0))&"","")) -> 包 | H10: 采购入库 | I10: 644 | J10: - | K10: - | L10: =IF($E10="","",N($I10)+N($J10)-N($K10)) -> 644 | M10: 37 | N10: =IF($E10="","",ROUND(N($L10)*N($M10),2)) -> 23828 | O10: 新Q*48887 | P10: 已付款 | R10: 12#
A11: =IF($E11="","",ROW()-3) -> 8 | B11: 46267 | C11: NO:0001067 | D11: 吐尔洪 | E11: 香梨网 | F11: =IF($E11="","",IFERROR(INDEX(基础资料!$O$4:$O$34,MATCH($E11,基础资料!$N$4:$N$34,0))&"","")) -> *包 | G11: =IF($E11="","",IFERROR(INDEX(基础资料!$P$4:$P$34,MATCH($E11,基础资料!$N$4:$N$34,0))&"","")) -> 包 | H11: 领用出库 | I11: - | J11: 24 | K11: - | L11: =IF($E11="","",N($I11)+N($J11)-N($K11)) -> 24 | M11: 45 | N11: =IF($E11="","",ROUND(N($L11)*N($M11),2)) -> 1080 | O11: 新N*X8S48 | P11: 未付款
A12: =IF($E12="","",ROW()-3) -> 9 | B12: 46268 | C12: NO:0001069 | D12: 热合曼 | E12: 香梨网 | F12: =IF($E12="","",IFERROR(INDEX(基础资料!$O$4:$O$34,MATCH($E12,基础资料!$N$4:$N$34,0))&"","")) -> *包 | G12: =IF($E12="","",IFERROR(INDEX(基础资料!$P$4:$P$34,MATCH($E12,基础资料!$N$4:$N$34,0))&"","")) -> 包 | H12: 领用出库 | I12: - | J12: 44 | K12: - | L12: =IF($E12="","",N($I12)+N($J12)-N($K12)) -> 44 | M12: 45 | N12: =IF($E12="","",ROUND(N($L12)*N($M12),2)) -> 1980 | O12: 新A*G0544 | P12: 未付款
A13: =IF($E13="","",ROW()-3) -> 10 | B13: 46268 | C13: NO:0001070 | D13: 麦麦提 | E13: 香梨纸 | F13: =IF($E13="","",IFERROR(INDEX(基础资料!$O$4:$O$34,MATCH($E13,基础资料!$N$4:$N$34,0))&"","")) -> *捆 | G13: =IF($E13="","",IFERROR(INDEX(基础资料!$P$4:$P$34,MATCH($E13,基础资料!$N$4:$N$34,0))&"","")) -> 捆 | H13: 领用出库 | I13: - | J13: 2 | K13: - | L13: =IF($E13="","",N($I13)+N($J13)-N($K13)) -> 2 | M13: 48 | N13: =IF($E13="","",ROUND(N($L13)*N($M13),2)) -> 96 | O13: 自提 | P13: 已收讫
A14: =IF($E14="","",ROW()-3) -> 11 | B14: 46268 | C14: NO:0001071 | D14: 热合曼 | E14: 香梨纸 | F14: =IF($E14="","",IFERROR(INDEX(基础资料!$O$4:$O$34,MATCH($E14,基础资料!$N$4:$N$34,0))&"","")) -> *捆 | G14: =IF($E14="","",IFERROR(INDEX(基础资料!$P$4:$P$34,MATCH($E14,基础资料!$N$4:$N$34,0))&"","")) -> 捆 | H14: 领用出库 | I14: - | J14: 2 | K14: - | L14: =IF($E14="","",N($I14)+N($J14)-N($K14)) -> 2 | M14: 48 | N14: =IF($E14="","",ROUND(N($L14)*N($M14),2)) -> 96 | O14: 自提 | P14: 已收讫
A15: =IF($E15="","",ROW()-3) -> 12 | B15: 46268 | C15: NO:0001074 | D15: 麦麦提 | E15: 香梨网 | F15: =IF($E15="","",IFERROR(INDEX(基础资料!$O$4:$O$34,MATCH($E15,基础资料!$N$4:$N$34,0))&"","")) -> *包 | G15: =IF($E15="","",IFERROR(INDEX(基础资料!$P$4:$P$34,MATCH($E15,基础资料!$N$4:$N$34,0))&"","")) -> 包 | H15: 领用出库 | I15: - | J15: 44 | K15: - | L15: =IF($E15="","",N($I15)+N($J15)-N($K15)) -> 44 | M15: 45 | N15: =IF($E15="","",ROUND(N($L15)*N($M15),2)) -> 1980 | O15: 新A*G0544 | P15: 未付款
A16: =IF($E16="","",ROW()-3) -> 13 | B16: 46269 | C16: NO:0001079 | D16: 荆建君 | E16: 香梨网 | F16: =IF($E16="","",IFERROR(INDEX(基础资料!$O$4:$O$34,MATCH($E16,基础资料!$N$4:$N$34,0))&"","")) -> *包 | G16: =IF($E16="","",IFERROR(INDEX(基础资料!$P$4:$P$34,MATCH($E16,基础资料!$N$4:$N$34,0))&"","")) -> 包 | H16: 领用出库 | I16: - | J16: 64 | K16: - | L16: =IF($E16="","",N($I16)+N($J16)-N($K16)) -> 64 | M16: 45 | N16: =IF($E16="","",ROUND(N($L16)*N($M16),2)) -> 2880 | O16: 豫A*2737K | P16: 未付款
A17: =IF($E17="","",ROW()-3) -> 14 | B17: 46269 | C17: NO:0001080 | D17: 努尔敦 | E17: 香梨网 | F17: =IF($E17="","",IFERROR(INDEX(基础资料!$O$4:$O$34,MATCH($E17,基础资料!$N$4:$N$34,0))&"","")) -> *包 | G17: =IF($E17="","",IFERROR(INDEX(基础资料!$P$4:$P$34,MATCH($E17,基础资料!$N$4:$N$34,0))&"","")) -> 包 | H17: 领用出库 | I17: - | J17: 120 | K17: - | L17: =IF($E17="","",N($I17)+N($J17)-N($K17)) -> 120 | M17: 45 | N17: =IF($E17="","",ROUND(N($L17)*N($M17),2)) -> 5400 | O17: 新F*75240 | P17: 未付款
A18: =IF($E18="","",ROW()-3) -> 15 | B18: 46270 | C18: NO:0001084 | D18: 热合曼 | E18: 香梨纸 | F18: =IF($E18="","",IFERROR(INDEX(基础资料!$O$4:$O$34,MATCH($E18,基础资料!$N$4:$N$34,0))&"","")) -> *捆 | G18: =IF($E18="","",IFERROR(INDEX(基础资料!$P$4:$P$34,MATCH($E18,基础资料!$N$4:$N$34,0))&"","")) -> 捆 | H18: 领用出库 | I18: - | J18: 10 | K18: - | L18: =IF($E18="","",N($I18)+N($J18)-N($K18)) -> 10 | M18: 56 | N18: =IF($E18="","",ROUND(N($L18)*N($M18),2)) -> 560 | O18: 新N*FJ0676 | P18: 未付款
A19: =IF($E19="","",ROW()-3) -> 16 | B19: 46272 | C19: NO:0001089 | D19: 麦麦提 | E19: 香梨网 | F19: =IF($E19="","",IFERROR(INDEX(基础资料!$O$4:$O$34,MATCH($E19,基础资料!$N$4:$N$34,0))&"","")) -> *包 | G19: =IF($E19="","",IFERROR(INDEX(基础资料!$P$4:$P$34,MATCH($E19,基础资料!$N$4:$N$34,0))&"","")) -> 包 | H19: 领用出库 | I19: - | J19: 48 | K19: - | L19: =IF($E19="","",N($I19)+N($J19)-N($K19)) -> 48 | M19: 45 | N19: =IF($E19="","",ROUND(N($L19)*N($M19),2)) -> 2160 | O19: 新A*G0544 | P19: 未付款
A20: =IF($E20="","",ROW()-3) -> 17 | B20: 46272 | C20: NO:0001092 | D20: 贾建国 | E20: 香梨网 | F20: =IF($E20="","",IFERROR(INDEX(基础资料!$O$4:$O$34,MATCH($E20,基础资料!$N$4:$N$34,0))&"","")) -> *包 | G20: =IF($E20="","",IFERROR(INDEX(基础资料!$P$4:$P$34,MATCH($E20,基础资料!$N$4:$N$34,0))&"","")) -> 包 | H20: 领用出库 | I20: - | J20: 32 | K20: - | L20: =IF($E20="","",N($I20)+N($J20)-N($K20)) -> 32 | M20: 45 | N20: =IF($E20="","",ROUND(N($L20)*N($M20),2)) -> 1440 | O20: 豫Q*H5591 | P20: 未付款
A21: =IF($E21="","",ROW()-3) -> 18 | B21: 46272 | C21: NO:0001092 | D21: 贾建国 | E21: 无纺布 | F21: =IF($E21="","",IFERROR(INDEX(基础资料!$O$4:$O$34,MATCH($E21,基础资料!$N$4:$N$34,0))&"","")) -> *400 | G21: =IF($E21="","",IFERROR(INDEX(基础资料!$P$4:$P$34,MATCH($E21,基础资料!$N$4:$N$34,0))&"","")) -> 个 | H21: 领用出库 | I21: - | J21: 800 | K21: - | L21: =IF($E21="","",N($I21)+N($J21)-N($K21)) -> 800 | M21: 0.5 | N21: =IF($E21="","",ROUND(N($L21)*N($M21),2)) -> 400 | O21: 豫Q*H5591 | P21: 未付款
A22: =IF($E22="","",ROW()-3) -> 19 | B22: 46272 | C22: NO:0001094 | D22: 热合曼 | E22: 香梨网 | F22: =IF($E22="","",IFERROR(INDEX(基础资料!$O$4:$O$34,MATCH($E22,基础资料!$N$4:$N$34,0))&"","")) -> *包 | G22: =IF($E22="","",IFERROR(INDEX(基础资料!$P$4:$P$34,MATCH($E22,基础资料!$N$4:$N$34,0))&"","")) -> 包 | H22: 领用出库 | I22: - | J22: 48 | K22: - | L22: =IF($E22="","",N($I22)+N($J22)-N($K22)) -> 48 | M22: 45 | N22: =IF($E22="","",ROUND(N($L22)*N($M22),2)) -> 2160 | O22: 新A*G0544 | P22: 未付款
A23: =IF($E23="","",ROW()-3) -> 20 | B23: 46273 | C23: NO:0000760 | D23: 贾建国 | E23: 无纺布 | F23: =IF($E23="","",IFERROR(INDEX(基础资料!$O$4:$O$34,MATCH($E23,基础资料!$N$4:$N$34,0))&"","")) -> *400 | G23: =IF($E23="","",IFERROR(INDEX(基础资料!$P$4:$P$34,MATCH($E23,基础资料!$N$4:$N$34,0))&"","")) -> 个 | H23: 退回入库 | I23: - | J23: - | K23: -800 | L23: =IF($E23="","",N($I23)+N($J23)-N($K23)) -> 800 | M23: -0.5 | N23: =IF($E23="","",ROUND(N($L23)*N($M23),2)) -> -400 | O23: 豫Q*H5591 | P23: 无需付款
A24: =IF($E24="","",ROW()-3) -> 21 | B24: 46274 | C24: NO:0001099 | D24: 吐尔逊 | E24: 香梨网 | F24: =IF($E24="","",IFERROR(INDEX(基础资料!$O$4:$O$34,MATCH($E24,基础资料!$N$4:$N$34,0))&"","")) -> *包 | G24: =IF($E24="","",IFERROR(INDEX(基础资料!$P$4:$P$34,MATCH($E24,基础资料!$N$4:$N$34,0))&"","")) -> 包 | H24: 领用出库 | I24: - | J24: 16 | K24: - | L24: =IF($E24="","",N($I24)+N($J24)-N($K24)) -> 16 | M24: 45 | N24: =IF($E24="","",ROUND(N($L24)*N($M24),2)) -> 720 | O24: 新M*87613 | P24: 未付款
A25: =IF($E25="","",ROW()-3) -> 22 | B25: 46274 | C25: NO:0001099 | D25: 吐尔逊 | E25: 香梨纸 | F25: =IF($E25="","",IFERROR(INDEX(基础资料!$O$4:$O$34,MATCH($E25,基础资料!$N$4:$N$34,0))&"","")) -> *捆 | G25: =IF($E25="","",IFERROR(INDEX(基础资料!$P$4:$P$34,MATCH($E25,基础资料!$N$4:$N$34,0))&"","")) -> 捆 | H25: 领用出库 | I25: - | J25: 2 | K25: - | L25: =IF($E25="","",N($I25)+N($J25)-N($K25)) -> 2 | M25: 60 | N25: =IF($E25="","",ROUND(N($L25)*N($M25),2)) -> 120 | O25: 新M*87613 | P25: 未付款
A26: =IF($E26="","",ROW()-3) -> 23 | B26: 46274 | C26: NO:0001100 | D26: 吐尔洪 | E26: 香梨网 | F26: =IF($E26="","",IFERROR(INDEX(基础资料!$O$4:$O$34,MATCH($E26,基础资料!$N$4:$N$34,0))&"","")) -> *包 | G26: =IF($E26="","",IFERROR(INDEX(基础资料!$P$4:$P$34,MATCH($E26,基础资料!$N$4:$N$34,0))&"","")) -> 包 | H26: 领用出库 | I26: - | J26: 12 | K26: - | L26: =IF($E26="","",N($I26)+N($J26)-N($K26)) -> 12 | M26: 45 | N26: =IF($E26="","",ROUND(N($L26)*N($M26),2)) -> 540 | O26: 新N*X8S48 | P26: 未付款
A27: =IF($E27="","",ROW()-3) -> 24 | B27: 46274 | C27: NO:0001105 | D27: 荆建君 | E27: 香梨网 | F27: =IF($E27="","",IFERROR(INDEX(基础资料!$O$4:$O$34,MATCH($E27,基础资料!$N$4:$N$34,0))&"","")) -> *包 | G27: =IF($E27="","",IFERROR(INDEX(基础资料!$P$4:$P$34,MATCH($E27,基础资料!$N$4:$N$34,0))&"","")) -> 包 | H27: 领用出库 | I27: 0 | J27: 48 | K27: 0 | L27: =IF($E27="","",N($I27)+N($J27)-N($K27)) -> 48 | M27: 45 | N27: =IF($E27="","",ROUND(N($L27)*N($M27),2)) -> 2160 | O27: 豫A*2737K | P27: 未付款
