Workbook

Sheet 说明
B2: 2026年度 研发费用分摊表（财务部门使用） 操作说明
B4: 一、每月操作步骤
B5: 第 1 步 维护参数 | C5: 在【参数设置】页维护项目清单、人员月费用标准、设备月折旧额、无形资产月摊销额。项目编号必须与研发部填报表一致。
B6: 第 2 步 导入工时 | C6: 收到研发部《研发工时分配表》后，把三张【年度台账】中当月新增的行，选择性粘贴为“数值”，追加到本表【01人员工时】【03设备工时】【05无形资产工时】的对应位置（列序完全一致，整块粘贴即可）。
B7: 第 3 步 自动分摊 | C7: 【02】【04】【06】三张分摊表全部由公式自动生成，无需录入。只有当月实际金额与标准不一致时（调薪、新增/处置资产、折旧提完），在最右侧【本月实际金额】列填入实际数覆盖。
B8: 第 4 步 复核 | C8: 检查【校验】列是否全部为“√”；若出现“未维护标准/未维护折旧额”，说明参数设置页缺该人员或资产。
B9: 第 5 步 汇总出账 | C9: 【07月度汇总】按月×费用类别×项目自动汇总，【08年度汇总】自动生成全年数，可直接对接研发支出辅助账与研发费用加计扣除优惠明细表。
B10: 二、分摊公式（勾稽关系）
B11: 人员人工费用 | C11: 某人某项目分摊额 ＝ 该人当月费用（工资/社保/公积金/其他）× 该人当月该项目工时 ÷ 该人当月总工时
B12: 设备折旧费 | C12: 某设备某项目分摊额 ＝ 该设备当月折旧额 × 该设备当月该项目运行工时 ÷ 该设备当月总运行工时
B13: 无形资产摊销费 | C13: 某资产某项目分摊额 ＝ 该资产当月摊销额 × 该资产当月该项目使用工时 ÷ 该资产当月总使用工时
B14: 非研发承担 | C14: 非研发承担额 ＝ 当月费用总额 − 研发各项目分摊额合计。先在研发与非研发之间划分，研发部分再细分到各项目；尾数差计入非研发，保证“非研发＋各项目＝费用总额”。
B15: 三、数据流向
B16: 工时→费用→汇总 | C16: 研发部月报（签字存档）→ 研发部年度台账 → 本表 01/03/05 工时页 → 02/04/06 分摊页 → 07 月度汇总 → 08 年度汇总 → 研发支出辅助账
B17: 四、颜色约定
B18: 黄色底纹 | C18: 手工录入区。
B19: 黑色字 | C19: 本页公式。
B20: 绿色字 | C20: 引用其他工作表的公式，请勿覆盖。
B21: 五、扩行方法
B22: 行数不够时 | C22: 选中分摊表最后一行整行复制，向下粘贴即可；汇总表的取数范围已预留到第 1000 行，扩行后无需修改汇总公式。人员分摊表每人每月固定占 4 行（工资/社保/公积金/其他），扩行须按 4 行一组整组复制。
B23: 六、备查资料
B24: 需同步归档 | C24: 研发项目立项决议、研发人员名单及考勤/工时记录、设备运行记录、工资表及社保公积金缴纳凭证、固定资产折旧明细表、无形资产摊销明细表。

Sheet 参数设置
B2: 2026年度 研发费用分摊 参数设置
B4: 一、项目清单（各表表头自动引用本表，最多 8 个项目） | K4: 费用项目清单
B5: 序号 | C5: 项目编号 | D5: 项目名称 | E5: 立项日期 | F5: 结项日期 | G5: 项目负责人 | H5: 备注 | K5: 费用项目 | L5: （人员费用分摊表按此顺序每人每月生成 4 行，勿改动顺序与文字）
B6: 1 | C6: RD01 | D6: 高导热复合胶带研发 | E6: 2026-01-05 | F6: 2026-12-31 | G6: 张三 | H6: 示例，请按实际替换 | K6: 工资
B7: 2 | C7: RD02 | D7: 低介电泡棉材料研发 | E7: 2026-02-01 | F7: 2026-11-30 | G7: 李四 | K7: 社保
B8: 3 | C8: RD03 | D8: 精密分切工艺改进 | E8: 2026-01-10 | F8: 2026-09-30 | G8: 王五 | K8: 公积金
B9: 4 | C9: RD04 | D9: 抗静电表面处理技术 | E9: 2026-03-01 | F9: 2026-12-31 | G9: 赵六 | K9: 其他
B10: 5 | C10: RD05 | D10: 超薄贴合工艺开发 | E10: 2026-04-01 | F10: 2026-12-31 | G10: 陈七
B11: 6 | C11: RD06
B12: 7 | C12: RD07
B13: 8 | C13: RD08
B15: 二、人员月费用标准（元/人·月）——单位承担部分
B16: 序号 | C16: 姓名 | D16: 工资 | E16: 社保 | F16: 公积金 | G16: 其他 | H16: 合计 | I16: 备注
B17: 1 | C17: 张三 | D17: 25000 | E17: 600 | F17: 1000 | G17: 0 | H17: =IF($C17="","",SUM(D17:G17)) | I17: 示例，请按实际替换
B18: 2 | C18: 李四 | D18: 20000 | E18: 600 | F18: 1000 | G18: 0 | H18: =IF($C18="","",SUM(D18:G18))
B19: 3 | C19: 王五 | D19: 18000 | E19: 600 | F19: 1000 | G19: 0 | H19: =IF($C19="","",SUM(D19:G19))
B20: 4 | C20: 赵六 | D20: 15000 | E20: 600 | F20: 1000 | G20: 0 | H20: =IF($C20="","",SUM(D20:G20))
B21: 5 | C21: 陈七 | D21: 16000 | E21: 600 | F21: 1000 | G21: 0 | H21: =IF($C21="","",SUM(D21:G21))
B22: 6 | H22: =IF($C22="","",SUM(D22:G22))
B23: 7 | H23: =IF($C23="","",SUM(D23:G23))
B24: 8 | H24: =IF($C24="","",SUM(D24:G24))
B25: 9 | H25: =IF($C25="","",SUM(D25:G25))
B26: 10 | H26: =IF($C26="","",SUM(D26:G26))
B27: 说明：此处为常规月标准，某月实际发放数不同的（调薪、入离职、年终奖计入），在【02人员费用分摊】最右侧“本月实际金额”列直接覆盖。
B28: 三、设备月折旧额（元/台·月）
B29: 序号 | C29: 设备编号 | D29: 设备名称 | E29: 月折旧额 | F29: 资产属性 | G29: 备注
B30: 1 | C30: 046 | D30: 贴合分条机 | E30: 1200 | F30: 共用 | G30: 示例，请按实际替换
B31: 2 | C31: 054 | D31: 风淋室 | E31: 1200 | F31: 共用
B32: 3 | C32: 084 | D32: 1450分条机 | E32: 1200 | F32: 共用
B33: 4 | C33: 083 | D33: 650贴合机 | E33: 1200 | F33: 共用
B34: 5 | C34: 072 | D34: 650表面卷曲分条机 | E34: 1200 | F34: 共用
B35: 6 | C35: 082 | D35: 精密双轴分切机 | E35: 1200 | F35: 共用
B36: 7 | C36: 071 | D36: 高精密立板式涂布机 | E36: 1200 | F36: 共用
B37: 8 | C37: 080 | D37: 傅里叶变换红外光谱仪 | E37: 1200 | F37: 共用
B38: 9 | C38: 086 | D38: 1300高精密复卷机 | E38: 1200 | F38: 共用
B39: 10 | C39: 079 | D39: 1200MM泡棉分条机 | E39: 1200 | F39: 共用
B40: 11 | C40: 081 | D40: 表面电阻测试仪 | E40: 1200 | F40: 研发专用
B41: 12
B42: 13
B43: 14
...

Sheet 01人员工时
B2: 2026年 研发人员工时（研发部报送数据，粘贴区）
P3: 数据来源： | Q3: 研发部工时台账
B4: 月份 | C4: 序号 | D4: 姓名 | E4: 当月总工时 （小时） | F4: 非研发活动工时 （小时） | G4: 各项目分配工时（小时） | P4: 分摊系数 | Q4: 备注
G5: ='参数设置'!$C$6 | H5: ='参数设置'!$C$7 | I5: ='参数设置'!$C$8 | J5: ='参数设置'!$C$9 | K5: ='参数设置'!$C$10 | L5: ='参数设置'!$C$11 | M5: ='参数设置'!$C$12 | N5: ='参数设置'!$C$13 | O5: 合计 | P5: 研发工时/总工时
G6: ='参数设置'!$D$6 | H6: ='参数设置'!$D$7 | I6: ='参数设置'!$D$8 | J6: ='参数设置'!$D$9 | K6: ='参数设置'!$D$10 | L6: ='参数设置'!$D$11 | M6: ='参数设置'!$D$12 | N6: ='参数设置'!$D$13
B7: 9 | C7: 1 | D7: 张三 | E7: 172.5 | F7: 42.5 | G7: 60 | H7: 40 | I7: 30 | O7: =IF($D7="","",SUM(G7:N7)) | P7: =IF(OR($D7="",$E7=0),"",$O7/$E7) | Q7: 示例数据，启用前请清空
B8: 9 | C8: 2 | D8: 李四 | E8: 172.5 | F8: 62.5 | H8: 50 | J8: 60 | O8: =IF($D8="","",SUM(G8:N8)) | P8: =IF(OR($D8="",$E8=0),"",$O8/$E8)
B9: 9 | C9: 3 | D9: 王五 | E9: 172.5 | F9: 52.5 | G9: 45 | I9: 45 | K9: 30 | O9: =IF($D9="","",SUM(G9:N9)) | P9: =IF(OR($D9="",$E9=0),"",$O9/$E9)
B10: 9 | C10: 4 | D10: 赵六 | E10: 172.5 | F10: 52.5 | I10: 70 | J10: 50 | O10: =IF($D10="","",SUM(G10:N10)) | P10: =IF(OR($D10="",$E10=0),"",$O10/$E10)
B11: 9 | C11: 5 | D11: 陈七 | E11: 172.5 | F11: 32.5 | G11: 30 | H11: 30 | K11: 80 | O11: =IF($D11="","",SUM(G11:N11)) | P11: =IF(OR($D11="",$E11=0),"",$O11/$E11)
O12: =IF($D12="","",SUM(G12:N12)) | P12: =IF(OR($D12="",$E12=0),"",$O12/$E12)
O13: =IF($D13="","",SUM(G13:N13)) | P13: =IF(OR($D13="",$E13=0),"",$O13/$E13)
O14: =IF($D14="","",SUM(G14:N14)) | P14: =IF(OR($D14="",$E14=0),"",$O14/$E14)
O15: =IF($D15="","",SUM(G15:N15)) | P15: =IF(OR($D15="",$E15=0),"",$O15/$E15)
O16: =IF($D16="","",SUM(G16:N16)) | P16: =IF(OR($D16="",$E16=0),"",$O16/$E16)
O17: =IF($D17="","",SUM(G17:N17)) | P17: =IF(OR($D17="",$E17=0),"",$O17/$E17)
O18: =IF($D18="","",SUM(G18:N18)) | P18: =IF(OR($D18="",$E18=0),"",$O18/$E18)
O19: =IF($D19="","",SUM(G19:N19)) | P19: =IF(OR($D19="",$E19=0),"",$O19/$E19)
O20: =IF($D20="","",SUM(G20:N20)) | P20: =IF(OR($D20="",$E20=0),"",$O20/$E20)
O21: =IF($D21="","",SUM(G21:N21)) | P21: =IF(OR($D21="",$E21=0),"",$O21/$E21)
O22: =IF($D22="","",SUM(G22:N22)) | P22: =IF(OR($D22="",$E22=0),"",$O22/$E22)
O23: =IF($D23="","",SUM(G23:N23)) | P23: =IF(OR($D23="",$E23=0),"",$O23/$E23)
... O126: =IF($D126="","",SUM(G126:N126)) | P126: =IF(OR($D126="",$E126=0),"",$O126/$E126)

Sheet 02人员费用分摊
B2: 2026年 研发人员人工费用分配表（按工时分摊）
B4: 月份 | C4: 序号 | D4: 姓名 | E4: 费用项目 | F4: 金额（元） | G4: 当月总工时 （小时） | H4: 其中：研发 工时（小时） | I4: 研发工时 占比 | J4: 费用分摊（元） | T4: 合计 （元） | U4: 校验 | V4: 本月实际 金额（覆盖） | W4: 备注
J5: 非研发 承担 | K5: ='参数设置'!$C$6 | L5: ='参数设置'!$C$7 | M5: ='参数设置'!$C$8 | N5: ='参数设置'!$C$9 | O5: ='参数设置'!$C$10 | P5: ='参数设置'!$C$11 | Q5: ='参数设置'!$C$12 | R5: ='参数设置'!$C$13 | S5: 研发 合计
K6: ='参数设置'!$D$6 | L6: ='参数设置'!$D$7 | M6: ='参数设置'!$D$8 | N6: ='参数设置'!$D$9 | O6: ='参数设置'!$D$10 | P6: ='参数设置'!$D$11 | Q6: ='参数设置'!$D$12 | R6: ='参数设置'!$D$13
B7: =IF(INDEX('01人员工时'!$D$7:$D$126,INT((ROW()-7)/4)+1)&""="","",INDEX('01人员工时'!$B$7:$B$126,INT((ROW()-7)/4)+1)) | C7: =IF($D7="","",IF(MOD(ROW()-7,4)=0,INDEX('01人员工时'!$C$7:$C$126,INT((ROW()-7)/4)+1),"")) | D7: =IF(INDEX('01人员工时'!$D$7:$D$126,INT((ROW()-7)/4)+1)&""="","",INDEX('01人员工时'!$D$7:$D$126,INT((ROW()-7)/4)+1)) | E7: =IF($D7="","",INDEX('参数设置'!$K$6:$K$9,MOD(ROW()-7,4)+1)) | F7: =IF($D7="","",IF($V7<>"",$V7,IFERROR(INDEX('参数设置'!$D$17:$G$26,MATCH($D7,'参数设置'!$C$17:$C$26,0),MATCH($E7,'参数设置'!$D$16:$G$16,0)),0))) | G7: =IF($D7="","",INDEX('01人员工时'!$E$7:$E$126,INT((ROW()-7)/4)+1)) | H7: =IF($D7="","",INDEX('01人员工时'!$O$7:$O$126,INT((ROW()-7)/4)+1)) | I7: =IF(OR($D7="",$G7=0),"",$H7/$G7) | J7: =IF($D7="","",ROUND($F7,2)-$S7) | K7: =IF(OR($D7="",$G7=0),"",ROUND($F7*INDEX('01人员工时'!G$7:G$126,INT((ROW()-7)/4)+1)/$G7,2)) | L7: =IF(OR($D7="",$G7=0),"",ROUND($F7*INDEX('01人员工时'!H$7:H$126,INT((ROW()-7)/4)+1)/$G7,2)) | M7: =IF(OR($D7="",$G7=0),"",ROUND($F7*INDEX('01人员工时'!I$7:I$126,INT((ROW()-7)/4)+1)/$G7,2)) | N7: =IF(OR($D7="",$G7=0),"",ROUND($F7*INDEX('01人员工时'!J$7:J$126,INT((ROW()-7)/4)+1)/$G7,2)) | O7: =IF(OR($D7="",$G7=0),"",ROUND($F7*INDEX('01人员工时'!K$7:K$126,INT((ROW()-7)/4)+1)/$G7,2)) | P7: =IF(OR($D7="",$G7=0),"",ROUND($F7*INDEX('01人员工时'!L$7:L$126,INT((ROW()-7)/4)+1)/$G7,2)) | Q7: =IF(OR($D7="",$G7=0),"",ROUND($F7*INDEX('01人员工时'!M$7:M$126,INT((ROW()-7)/4)+1)/$G7,2)) | R7: =IF(OR($D7="",$G7=0),"",ROUND($F7*INDEX('01人员工时'!N$7:N$126,INT((ROW()-7)/4)+1)/$G7,2)) | S7: =IF($D7="","",SUM(K7:R7)) | T7: =IF($D7="","",$J7+$S7) | U7: =IF($D7="","",IF($F7=0,"未维护标准",IF(ROUND($T7-$F7,2)=0,"√","差异")))
B8: =IF(INDEX('01人员工时'!$D$7:$D$126,INT((ROW()-7)/4)+1)&""="","",INDEX('01人员工时'!$B$7:$B$126,INT((ROW()-7)/4)+1)) | C8: =IF($D8="","",IF(MOD(ROW()-7,4)=0,INDEX('01人员工时'!$C$7:$C$126,INT((ROW()-7)/4)+1),"")) | D8: =IF(INDEX('01人员工时'!$D$7:$D$126,INT((ROW()-7)/4)+1)&""="","",INDEX('01人员工时'!$D$7:$D$126,INT((ROW()-7)/4)+1)) | E8: =IF($D8="","",INDEX('参数设置'!$K$6:$K$9,MOD(ROW()-7,4)+1)) | F8: =IF($D8="","",IF($V8<>"",$V8,IFERROR(INDEX('参数设置'!$D$17:$G$26,MATCH($D8,'参数设置'!$C$17:$C$26,0),MATCH($E8,'参数设置'!$D$16:$G$16,0)),0))) | G8: =IF($D8="","",INDEX('01人员工时'!$E$7:$E$126,INT((ROW()-7)/4)+1)) | H8: =IF($D8="","",INDEX('01人员工时'!$O$7:$O$126,INT((ROW()-7)/4)+1)) | I8: =IF(OR($D8="",$G8=0),"",$H8/$G8) | J8: =IF($D8="","",ROUND($F8,2)-$S8) | K8: =IF(OR($D8="",$G8=0),"",ROUND($F8*INDEX('01人员工时'!G$7:G$126,INT((ROW()-7)/4)+1)/$G8,2)) | L8: =IF(OR($D8="",$G8=0),"",ROUND($F8*INDEX('01人员工时'!H$7:H$126,INT((ROW()-7)/4)+1)/$G8,2)) | M8: =IF(OR($D8="",$G8=0),"",ROUND($F8*INDEX('01人员工时'!I$7:I$126,INT((ROW()-7)/4)+1)/$G8,2)) | N8: =IF(OR($D8="",$G8=0),"",ROUND($F8*INDEX('01人员工时'!J$7:J$126,INT((ROW()-7)/4)+1)/$G8,2)) | O8: =IF(OR($D8="",$G8=0),"",ROUND($F8*INDEX('01人员工时'!K$7:K$126,INT((ROW()-7)/4)+1)/$G8,2)) | P8: =IF(OR($D8="",$G8=0),"",ROUND($F8*INDEX('01人员工时'!L$7:L$126,INT((ROW()-7)/4)+1)/$G8,2)) | Q8: =IF(OR($D8="",$G8=0),"",ROUND($F8*INDEX('01人员工时'!M$7:M$126,INT((ROW()-7)/4)+1)/$G8,2)) | R8: =IF(OR($D8="",$G8=0),"",ROUND($F8*INDEX('01人员工时'!N$7:N$126,INT((ROW()-7)/4)+1)/$G8,2)) | S8: =IF($D8="","",SUM(K8:R8)) | T8: =IF($D8="","",$J8+$S8) | U8: =IF($D8="","",IF($F8=0,"未维护标准",IF(ROUND($T8-$F8,2)=0,"√","差异")))
B9: =IF(INDEX('01人员工时'!$D$7:$D$126,INT((ROW()-7)/4)+1)&""="","",INDEX('01人员工时'!$B$7:$B$126,INT((ROW()-7)/4)+1)) | C9: =IF($D9="","",IF(MOD(ROW()-7,4)=0,INDEX('01人员工时'!$C$7:$C$126,INT((ROW()-7)/4)+1),"")) | D9: =IF(INDEX('01人员工时'!$D$7:$D$126,INT((ROW()-7)/4)+1)&""="","",INDEX('01人员工时'!$D$7:$D$126,INT((ROW()-7)/4)+1)) | E9: =IF($D9="","",INDEX('参数设置'!$K$6:$K$9,MOD(ROW()-7,4)+1)) | F9: =IF($D9="","",IF($V9<>"",$V9,IFERROR(INDEX('参数设置'!$D$17:$G$26,MATCH($D9,'参数设置'!$C$17:$C$26,0),MATCH($E9,'参数设置'!$D$16:$G$16,0)),0))) | G9: =IF($D9="","",INDEX('01人员工时'!$E$7:$E$126,INT((ROW()-7)/4)+1)) | H9: =IF($D9="","",INDEX('01人员工时'!$O$7:$O$126,INT((ROW()-7)/4)+1)) | I9: =IF(OR($D9="",$G9=0),"",$H9/$G9) | J9: =IF($D9="","",ROUND($F9,2)-$S9) | K9: =IF(OR($D9="",$G9=0),"",ROUND($F9*INDEX('01人员工时'!G$7:G$126,INT((ROW()-7)/4)+1)/$G9,2)) | L9: =IF(OR($D9="",$G9=0),"",ROUND($F9*INDEX('01人员工时'!H$7:H$126,INT((ROW()-7)/4)+1)/$G9,2)) | M9: =IF(OR($D9="",$G9=0),"",ROUND($F9*INDEX('01人员工时'!I$7:I$126,INT((ROW()-7)/4)+1)/$G9,2)) | N9: =IF(OR($D9="",$G9=0),"",ROUND($F9*INDEX('01人员工时'!J$7:J$126,INT((ROW()-7)/4)+1)/$G9,2)) | O9: =IF(OR($D9="",$G9=0),"",ROUND($F9*INDEX('01人员工时'!K$7:K$126,INT((ROW()-7)/4)+1)/$G9,2)) | P9: =IF(OR($D9="",$G9=0),"",ROUND($F9*INDEX('01人员工时'!L$7:L$126,INT((ROW()-7)/4)+1)/$G9,2)) | Q9: =IF(OR($D9="",$G9=0),"",ROUND($F9*INDEX('01人员工时'!M$7:M$126,INT((ROW()-7)/4)+1)/$G9,2)) | R9: =IF(OR($D9="",$G9=0),"",ROUND($F9*INDEX('01人员工时'!N$7:N$126,INT((ROW()-7)/4)+1)/$G9,2)) | S9: =IF($D9="","",SUM(K9:R9)) | T9: =IF($D9="","",$J9+$S9) | U9: =IF($D9="","",IF($F9=0,"未维护标准",IF(ROUND($T9-$F9,2)=0,"√","差异")))
B10: =IF(INDEX('01人员工时'!$D$7:$D$126,INT((ROW()-7)/4)+1)&""="","",INDEX('01人员工时'!$B$7:$B$126,INT((ROW()-7)/4)+1)) | C10: =IF($D10="","",IF(MOD(ROW()-7,4)=0,INDEX('01人员工时'!$C$7:$C$126,INT((ROW()-7)/4)+1),"")) | D10: =IF(INDEX('01人员工时'!$D$7:$D$126,INT((ROW()-7)/4)+1)&""="","",INDEX('01人员工时'!$D$7:$D$126,INT((ROW()-7)/4)+1)) | E10: =IF($D10="","",INDEX('参数设置'!$K$6:$K$9,MOD(ROW()-7,4)+1)) | F10: =IF($D10="","",IF($V10<>"",$V10,IFERROR(INDEX('参数设置'!$D$17:$G$26,MATCH($D10,'参数设置'!$C$17:$C$26,0),MATCH($E10,'参数设置'!$D$16:$G$16,0)),0))) | G10: =IF($D10="","",INDEX('01人员工时'!$E$7:$E$126,INT((ROW()-7)/4)+1)) | H10: =IF($D10="","",INDEX('01人员工时'!$O$7:$O$126,INT((ROW()-7)/4)+1)) | I10: =IF(OR($D10="",$G10=0),"",$H10/$G10) | J10: =IF($D10="","",ROUND($F10,2)-$S10) | K10: =IF(OR($D10="",$G10=0),"",ROUND($F10*INDEX('01人员工时'!G$7:G$126,INT((ROW()-7)/4)+1)/$G10,2)) | L10: =IF(OR($D10="",$G10=0),"",ROUND($F10*INDEX('01人员工时'!H$7:H$126,INT((ROW()-7)/4)+1)/$G10,2)) | M10: =IF(OR($D10="",$G10=0),"",ROUND($F10*INDEX('01人员工时'!I$7:I$126,INT((ROW()-7)/4)+1)/$G10,2)) | N10: =IF(OR($D10="",$G10=0),"",ROUND($F10*INDEX('01人员工时'!J$7:J$126,INT((ROW()-7)/4)+1)/$G10,2)) | O10: =IF(OR($D10="",$G10=0),"",ROUND($F10*INDEX('01人员工时'!K$7:K$126,INT((ROW()-7)/4)+1)/$G10,2)) | P10: =IF(OR($D10="",$G10=0),"",ROUND($F10*INDEX('01人员工时'!L$7:L$126,INT((ROW()-7)/4)+1)/$G10,2)) | Q10: =IF(OR($D10="",$G10=0),"",ROUND($F10*INDEX('01人员工时'!M$7:M$126,INT((ROW()-7)/4)+1)/$G10,2)) | R10: =IF(OR($D10="",$G10=0),"",ROUND($F10*INDEX('01人员工时'!N$7:N$126,INT((ROW()-7)/4)+1)/$G10,2)) | S10: =IF($D10="","",SUM(K10:R10)) | T10: =IF($D10="","",$J10+$S10) | U10: =IF($D10="","",IF($F10=0,"未维护标准",IF(ROUND($T10-$F10,2)=0,"√","差异")))
B11: =IF(INDEX('01人员工时'!$D$7:$D$126,INT((ROW()-7)/4)+1)&""="","",INDEX('01人员工时'!$B$7:$B$126,INT((ROW()-7)/4)+1)) | C11: =IF($D11="","",IF(MOD(ROW()-7,4)=0,INDEX('01人员工时'!$C$7:$C$126,INT((ROW()-7)/4)+1),"")) | D11: =IF(INDEX('01人员工时'!$D$7:$D$126,INT((ROW()-7)/4)+1)&""="","",INDEX('01人员工时'!$D$7:$D$126,INT((ROW()-7)/4)+1)) | E11: =IF($D11="","",INDEX('参数设置'!$K$6:$K$9,MOD(ROW()-7,4)+1)) | F11: =IF($D11="","",IF($V11<>"",$V11,IFERROR(INDEX('参数设置'!$D$17:$G$26,MATCH($D11,'参数设置'!$C$17:$C$26,0),MATCH($E11,'参数设置'!$D$16:$G$16,0)),0))) | G11: =IF($D11="","",INDEX('01人员工时'!$E$7:$E$126,INT((ROW()-7)/4)+1)) | H11: =IF($D11="","",INDEX('01人员工时'!$O$7:$O$126,INT((ROW()-7)/4)+1)) | I11: =IF(OR($D11="",$G11=0),"",$H11/$G11) | J11: =IF($D11="","",ROUND($F11,2)-$S11) | K11: =IF(OR($D11="",$G11=0),"",ROUND($F11*INDEX('01人员工时'!G$7:G$126,INT((ROW()-7)/4)+1)/$G11,2)) | L11: =IF(OR($D11="",$G11=0),"",ROUND($F11*INDEX('01人员工时'!H$7:H$126,INT((ROW()-7)/4)+1)/$G11,2)) | M11: =IF(OR($D11="",$G11=0),"",ROUND($F11*INDEX('01人员工时'!I$7:I$126,INT((ROW()-7)/4)+1)/$G11,2)) | N11: =IF(OR($D11="",$G11=0),"",ROUND($F11*INDEX('01人员工时'!J$7:J$126,INT((ROW()-7)/4)+1)/$G11,2)) | O11: =IF(OR($D11="",$G11=0),"",ROUND($F11*INDEX('01人员工时'!K$7:K$126,INT((ROW()-7)/4)+1)/$G11,2)) | P11: =IF(OR($D11="",$G11=0),"",ROUND($F11*INDEX('01人员工时'!L$7:L$126,INT((ROW()-7)/4)+1)/$G11,2)) | Q11: =IF(OR($D11="",$G11=0),"",ROUND($F11*INDEX('01人员工时'!M$7:M$126,INT((ROW()-7)/4)+1)/$G11,2)) | R11: =IF(OR($D11="",$G11=0),"",ROUND($F11*INDEX('01人员工时'!N$7:N$126,INT((ROW()-7)/4)+1)/$G11,2)) | S11: =IF($D11="","",SUM(K11:R11)) | T11: =IF($D11="","",$J11+$S11) | U11: =IF($D11="","",IF($F11=0,"未维护标准",IF(ROUND($T11-$F11,2)=0,"√","差异")))
B12: =IF(INDEX('01人员工时'!$D$7:$D$126,INT((ROW()-7)/4)+1)&""="","",INDEX('01人员工时'!$B$7:$B$126,INT((ROW()-7)/4)+1)) | C12: =IF($D12="","",IF(MOD(ROW()-7,4)=0,INDEX('01人员工时'!$C$7:$C$126,INT((ROW()-7)/4)+1),"")) | D12: =IF(INDEX('01人员工时'!$D$7:$D$126,INT((ROW()-7)/4)+1)&""="","",INDEX('01人员工时'!$D$7:$D$126,INT((ROW()-7)/4)+1)) | E12: =IF($D12="","",INDEX('参数设置'!$K$6:$K$9,MOD(ROW()-7,4)+1)) | F12: =IF($D12="","",IF($V12<>"",$V12,IFERROR(INDEX('参数设置'!$D$17:$G$26,MATCH($D12,'参数设置'!$C$17:$C$26,0),MATCH($E12,'参数设置'!$D$16:$G$16,0)),0))) | G12: =IF($D12="","",INDEX('01人员工时'!$E$7:$E$126,INT((ROW()-7)/4)+1)) | H12: =IF($D12="","",INDEX('01人员工时'!$O$7:$O$126,INT((ROW()-7)/4)+1)) | I12: =IF(OR($D12="",$G12=0),"",$H12/$G12) | J12: =IF($D12="","",ROUND($F12,2)-$S12) | K12: =IF(OR($D12="",$G12=0),"",ROUND($F12*INDEX('01人员工时'!G$7:G$126,INT((ROW()-7)/4)+1)/$G12,2)) | L12: =IF(OR($D12="",$G12=0),"",ROUND($F12*INDEX('01人员工时'!H$7:H$126,INT((ROW()-7)/4)+1)/$G12,2)) | M12: =IF(OR($D12="",$G12=0),"",ROUND($F12*INDEX('01人员工时'!I$7:I$126,INT((ROW()-7)/4)+1)/$G12,2)) | N12: =IF(OR($D12="",$G12=0),"",ROUND($F12*INDEX('01人员工时'!J$7:J$126,INT((ROW()-7)/4)+1)/$G12,2)) | O12: =IF(OR($D12="",$G12=0),"",ROUND($F12*INDEX('01人员工时'!K$7:K$126,INT((ROW()-7)/4)+1)/$G12,2)) | P12: =IF(OR($D12="",$G12=0),"",ROUND($F12*INDEX('01人员工时'!L$7:L$126,INT((ROW()-7)/4)+1)/$G12,2)) | Q12: =IF(OR($D12="",$G12=0),"",ROUND($F12*INDEX('01人员工时'!M$7:M$126,INT((ROW()-7)/4)+1)/$G12,2)) | R12: =IF(OR($D12="",$G12=0),"",ROUND($F12*INDEX('01人员工时'!N$7:N$126,INT((ROW()-7)/4)+1)/$G12,2)) | S12: =IF($D12="","",SUM(K12:R12)) | T12: =IF($D12="","",$J12+$S12) | U12: =IF($D12="","",IF($F12=0,"未维护标准",IF(ROUND($T12-$F12,2)=0,"√","差异")))
B13: =IF(INDEX('01人员工时'!$D$7:$D$126,INT((ROW()-7)/4)+1)&""="","",INDEX('01人员工时'!$B$7:$B$126,INT((ROW()-7)/4)+1)) | C13: =IF($D13="","",IF(MOD(ROW()-7,4)=0,INDEX('01人员工时'!$C$7:$C$126,INT((ROW()-7)/4)+1),"")) | D13: =IF(INDEX('01人员工时'!$D$7:$D$126,INT((ROW()-7)/4)+1)&""="","",INDEX('01人员工时'!$D$7:$D$126,INT((ROW()-7)/4)+1)) | E13: =IF($D13="","",INDEX('参数设置'!$K$6:$K$9,MOD(ROW()-7,4)+1)) | F13: =IF($D13="","",IF($V13<>"",$V13,IFERROR(INDEX('参数设置'!$D$17:$G$26,MATCH($D13,'参数设置'!$C$17:$C$26,0),MATCH($E13,'参数设置'!$D$16:$G$16,0)),0))) | G13: =IF($D13="","",INDEX('01人员工时'!$E$7:$E$126,INT((ROW()-7)/4)+1)) | H13: =IF($D13="","",INDEX('01人员工时'!$O$7:$O$126,INT((ROW()-7)/4)+1)) | I13: =IF(OR($D13="",$G13=0),"",$H13/$G13) | J13: =IF($D13="","",ROUND($F13,2)-$S13) | K13: =IF(OR($D13="",$G13=0),"",ROUND($F13*INDEX('01人员工时'!G$7:G$126,INT((ROW()-7)/4)+1)/$G13,2)) | L13: =IF(OR($D13="",$G13=0),"",ROUND($F13*INDEX('01人员工时'!H$7:H$126,INT((ROW()-7)/4)+1)/$G13,2)) | M13: =IF(OR($D13="",$G13=0),"",ROUND($F13*INDEX('01人员工时'!I$7:I$126,INT((ROW()-7)/4)+1)/$G13,2)) | N13: =IF(OR($D13="",$G13=0),"",ROUND($F13*INDEX('01人员工时'!J$7:J$126,INT((ROW()-7)/4)+1)/$G13,2)) | O13: =IF(OR($D13="",$G13=0),"",ROUND($F13*INDEX('01人员工时'!K$7:K$126,INT((ROW()-7)/4)+1)/$G13,2)) | P13: =IF(OR($D13="",$G13=0),"",ROUND($F13*INDEX('01人员工时'!L$7:L$126,INT((ROW()-7)/4)+1)/$G13,2)) | Q13: =IF(OR($D13="",$G13=0),"",ROUND($F13*INDEX('01人员工时'!M$7:M$126,INT((ROW()-7)/4)+1)/$G13,2)) | R13: =IF(OR($D13="",$G13=0),"",ROUND($F13*INDEX('01人员工时'!N$7:N$126,INT((ROW()-7)/4)+1)/$G13,2)) | S13: =IF($D13="","",SUM(K13:R13)) | T13: =IF($D13="","",$J13+$S13) | U13: =IF($D13="","",IF($F13=0,"未维护标准",IF(ROUND($T13-$F13,2)=0,"√","差异")))
B14: =IF(INDEX('01人员工时'!$D$7:$D$126,INT((ROW()-7)/4)+1)&""="","",INDEX('01人员工时'!$B$7:$B$126,INT((ROW()-7)/4)+1)) | C14: =IF($D14="","",IF(MOD(ROW()-7,4)=0,INDEX('01人员工时'!$C$7:$C$126,INT((ROW()-7)/4)+1),"")) | D14: =IF(INDEX('01人员工时'!$D$7:$D$126,INT((ROW()-7)/4)+1)&""="","",INDEX('01人员工时'!$D$7:$D$126,INT((ROW()-7)/4)+1)) | E14: =IF($D14="","",INDEX('参数设置'!$K$6:$K$9,MOD(ROW()-7,4)+1)) | F14: =IF($D14="","",IF($V14<>"",$V14,IFERROR(INDEX('参数设置'!$D$17:$G$26,MATCH($D14,'参数设置'!$C$17:$C$26,0),MATCH($E14,'参数设置'!$D$16:$G$16,0)),0))) | G14: =IF($D14="","",INDEX('01人员工时'!$E$7:$E$126,INT((ROW()-7)/4)+1)) | H14: =IF($D14="","",INDEX('01人员工时'!$O$7:$O$126,INT((ROW()-7)/4)+1)) | I14: =IF(OR($D14="",$G14=0),"",$H14/$G14) | J14: =IF($D14="","",ROUND($F14,2)-$S14) | K14: =IF(OR($D14="",$G14=0),"",ROUND($F14*INDEX('01人员工时'!G$7:G$126,INT((ROW()-7)/4)+1)/$G14,2)) | L14: =IF(OR($D14="",$G14=0),"",ROUND($F14*INDEX('01人员工时'!H$7:H$126,INT((ROW()-7)/4)+1)/$G14,2)) | M14: =IF(OR($D14="",$G14=0),"",ROUND($F14*INDEX('01人员工时'!I$7:I$126,INT((ROW()-7)/4)+1)/$G14,2)) | N14: =IF(OR($D14="",$G14=0),"",ROUND($F14*INDEX('01人员工时'!J$7:J$126,INT((ROW()-7)/4)+1)/$G14,2)) | O14: =IF(OR($D14="",$G14=0),"",ROUND($F14*INDEX('01人员工时'!K$7:K$126,INT((ROW()-7)/4)+1)/$G14,2)) | P14: =IF(OR($D14="",$G14=0),"",ROUND($F14*INDEX('01人员工时'!L$7:L$126,INT((ROW()-7)/4)+1)/$G14,2)) | Q14: =IF(OR($D14="",$G14=0),"",ROUND($F14*INDEX('01人员工时'!M$7:M$126,INT((ROW()-7)/4)+1)/$G14,2)) | R14: =IF(OR($D14="",$G14=0),"",ROUND($F14*INDEX('01人员工时'!N$7:N$126,INT((ROW()-7)/4)+1)/$G14,2)) | S14: =IF($D14="","",SUM(K14:R14)) | T14: =IF($D14="","",$J14+$S14) | U14: =IF($D14="","",IF($F14=0,"未维护标准",IF(ROUND($T14-$F14,2)=0,"√","差异")))
B15: =IF(INDEX('01人员工时'!$D$7:$D$126,INT((ROW()-7)/4)+1)&""="","",INDEX('01人员工时'!$B$7:$B$126,INT((ROW()-7)/4)+1)) | C15: =IF($D15="","",IF(MOD(ROW()-7,4)=0,INDEX('01人员工时'!$C$7:$C$126,INT((ROW()-7)/4)+1),"")) | D15: =IF(INDEX('01人员工时'!$D$7:$D$126,INT((ROW()-7)/4)+1)&""="","",INDEX('01人员工时'!$D$7:$D$126,INT((ROW()-7)/4)+1)) | E15: =IF($D15="","",INDEX('参数设置'!$K$6:$K$9,MOD(ROW()-7,4)+1)) | F15: =IF($D15="","",IF($V15<>"",$V15,IFERROR(INDEX('参数设置'!$D$17:$G$26,MATCH($D15,'参数设置'!$C$17:$C$26,0),MATCH($E15,'参数设置'!$D$16:$G$16,0)),0))) | G15: =IF($D15="","",INDEX('01人员工时'!$E$7:$E$126,INT((ROW()-7)/4)+1)) | H15: =IF($D15="","",INDEX('01人员工时'!$O$7:$O$126,INT((ROW()-7)/4)+1)) | I15: =IF(OR($D15="",$G15=0),"",$H15/$G15) | J15: =IF($D15="","",ROUND($F15,2)-$S15) | K15: =IF(OR($D15="",$G15=0),"",ROUND($F15*INDEX('01人员工时'!G$7:G$126,INT((ROW()-7)/4)+1)/$G15,2)) | L15: =IF(OR($D15="",$G15=0),"",ROUND($F15*INDEX('01人员工时'!H$7:H$126,INT((ROW()-7)/4)+1)/$G15,2)) | M15: =IF(OR($D15="",$G15=0),"",ROUND($F15*INDEX('01人员工时'!I$7:I$126,INT((ROW()-7)/4)+1)/$G15,2)) | N15: =IF(OR($D15="",$G15=0),"",ROUND($F15*INDEX('01人员工时'!J$7:J$126,INT((ROW()-7)/4)+1)/$G15,2)) | O15: =IF(OR($D15="",$G15=0),"",ROUND($F15*INDEX('01人员工时'!K$7:K$126,INT((ROW()-7)/4)+1)/$G15,2)) | P15: =IF(OR($D15="",$G15=0),"",ROUND($F15*INDEX('01人员工时'!L$7:L$126,INT((ROW()-7)/4)+1)/$G15,2)) | Q15: =IF(OR($D15="",$G15=0),"",ROUND($F15*INDEX('01人员工时'!M$7:M$126,INT((ROW()-7)/4)+1)/$G15,2)) | R15: =IF(OR($D15="",$G15=0),"",ROUND($F15*INDEX('01人员工时'!N$7:N$126,INT((ROW()-7)/4)+1)/$G15,2)) | S15: =IF($D15="","",SUM(K15:R15)) | T15: =IF($D15="","",$J15+$S15) | U15: =IF($D15="","",IF($F15=0,"未维护标准",IF(ROUND($T15-$F15,2)=0,"√","差异")))
B16: =IF(INDEX('01人员工时'!$D$7:$D$126,INT((ROW()-7)/4)+1)&""="","",INDEX('01人员工时'!$B$7:$B$126,INT((ROW()-7)/4)+1)) | C16: =IF($D16="","",IF(MOD(ROW()-7,4)=0,INDEX('01人员工时'!$C$7:$C$126,INT((ROW()-7)/4)+1),"")) | D16: =IF(INDEX('01人员工时'!$D$7:$D$126,INT((ROW()-7)/4)+1)&""="","",INDEX('01人员工时'!$D$7:$D$126,INT((ROW()-7)/4)+1)) | E16: =IF($D16="","",INDEX('参数设置'!$K$6:$K$9,MOD(ROW()-7,4)+1)) | F16: =IF($D16="","",IF($V16<>"",$V16,IFERROR(INDEX('参数设置'!$D$17:$G$26,MATCH($D16,'参数设置'!$C$17:$C$26,0),MATCH($E16,'参数设置'!$D$16:$G$16,0)),0))) | G16: =IF($D16="","",INDEX('01人员工时'!$E$7:$E$126,INT((ROW()-7)/4)+1)) | H16: =IF($D16="","",INDEX('01人员工时'!$O$7:$O$126,INT((ROW()-7)/4)+1)) | I16: =IF(OR($D16="",$G16=0),"",$H16/$G16) | J16: =IF($D16="","",ROUND($F16,2)-$S16) | K16: =IF(OR($D16="",$G16=0),"",ROUND($F16*INDEX('01人员工时'!G$7:G$126,INT((ROW()-7)/4)+1)/$G16,2)) | L16: =IF(OR($D16="",$G16=0),"",ROUND($F16*INDEX('01人员工时'!H$7:H$126,INT((ROW()-7)/4)+1)/$G16,2)) | M16: =IF(OR($D16="",$G16=0),"",ROUND($F16*INDEX('01人员工时'!I$7:I$126,INT((ROW()-7)/4)+1)/$G16,2)) | N16: =IF(OR($D16="",$G16=0),"",ROUND($F16*INDEX('01人员工时'!J$7:J$126,INT((ROW()-7)/4)+1)/$G16,2)) | O16: =IF(OR($D16="",$G16=0),"",ROUND($F16*INDEX('01人员工时'!K$7:K$126,INT((ROW()-7)/4)+1)/$G16,2)) | P16: =IF(OR($D16="",$G16=0),"",ROUND($F16*INDEX('01人员工时'!L$7:L$126,INT((ROW()-7)/4)+1)/$G16,2)) | Q16: =IF(OR($D16="",$G16=0),"",ROUND($F16*INDEX('01人员工时'!M$7:M$126,INT((ROW()-7)/4)+1)/$G16,2)) | R16: =IF(OR($D16="",$G16=0),"",ROUND($F16*INDEX('01人员工时'!N$7:N$126,INT((ROW()-7)/4)+1)/$G16,2)) | S16: =IF($D16="","",SUM(K16:R16)) | T16: =IF($D16="","",$J16+$S16) | U16: =IF($D16="","",IF($F16=0,"未维护标准",IF(ROUND($T16-$F16,2)=0,"√","差异")))
B17: =IF(INDEX('01人员工时'!$D$7:$D$126,INT((ROW()-7)/4)+1)&""="","",INDEX('01人员工时'!$B$7:$B$126,INT((ROW()-7)/4)+1)) | C17: =IF($D17="","",IF(MOD(ROW()-7,4)=0,INDEX('01人员工时'!$C$7:$C$126,INT((ROW()-7)/4)+1),"")) | D17: =IF(INDEX('01人员工时'!$D$7:$D$126,INT((ROW()-7)/4)+1)&""="","",INDEX('01人员工时'!$D$7:$D$126,INT((ROW()-7)/4)+1)) | E17: =IF($D17="","",INDEX('参数设置'!$K$6:$K$9,MOD(ROW()-7,4)+1)) | F17: =IF($D17="","",IF($V17<>"",$V17,IFERROR(INDEX('参数设置'!$D$17:$G$26,MATCH($D17,'参数设置'!$C$17:$C$26,0),MATCH($E17,'参数设置'!$D$16:$G$16,0)),0))) | G17: =IF($D17="","",INDEX('01人员工时'!$E$7:$E$126,INT((ROW()-7)/4)+1)) | H17: =IF($D17="","",INDEX('01人员工时'!$O$7:$O$126,INT((ROW()-7)/4)+1)) | I17: =IF(OR($D17="",$G17=0),"",$H17/$G17) | J17: =IF($D17="","",ROUND($F17,2)-$S17) | K17: =IF(OR($D17="",$G17=0),"",ROUND($F17*INDEX('01人员工时'!G$7:G$126,INT((ROW()-7)/4)+1)/$G17,2)) | L17: =IF(OR($D17="",$G17=0),"",ROUND($F17*INDEX('01人员工时'!H$7:H$126,INT((ROW()-7)/4)+1)/$G17,2)) | M17: =IF(OR($D17="",$G17=0),"",ROUND($F17*INDEX('01人员工时'!I$7:I$126,INT((ROW()-7)/4)+1)/$G17,2)) | N17: =IF(OR($D17="",$G17=0),"",ROUND($F17*INDEX('01人员工时'!J$7:J$126,INT((ROW()-7)/4)+1)/$G17,2)) | O17: =IF(OR($D17="",$G17=0),"",ROUND($F17*INDEX('01人员工时'!K$7:K$126,INT((ROW()-7)/4)+1)/$G17,2)) | P17: =IF(OR($D17="",$G17=0),"",ROUND($F17*INDEX('01人员工时'!L$7:L$126,INT((ROW()-7)/4)+1)/$G17,2)) | Q17: =IF(OR($D17="",$G17=0),"",ROUND($F17*INDEX('01人员工时'!M$7:M$126,INT((ROW()-7)/4)+1)/$G17,2)) | R17: =IF(OR($D17="",$G17=0),"",ROUND($F17*INDEX('01人员工时'!N$7:N$126,INT((ROW()-7)/4)+1)/$G17,2)) | S17: =IF($D17="","",SUM(K17:R17)) | T17: =IF($D17="","",$J17+$S17) | U17: =IF($D17="","",IF($F17=0,"未维护标准",IF(ROUND($T17-$F17,2)=0,"√","差异")))
B18: =IF(INDEX('01人员工时'!$D$7:$D$126,INT((ROW()-7)/4)+1)&""="","",INDEX('01人员工时'!$B$7:$B$126,INT((ROW()-7)/4)+1)) | C18: =IF($D18="","",IF(MOD(ROW()-7,4)=0,INDEX('01人员工时'!$C$7:$C$126,INT((ROW()-7)/4)+1),"")) | D18: =IF(INDEX('01人员工时'!$D$7:$D$126,INT((ROW()-7)/4)+1)&""="","",INDEX('01人员工时'!$D$7:$D$126,INT((ROW()-7)/4)+1)) | E18: =IF($D18="","",INDEX('参数设置'!$K$6:$K$9,MOD(ROW()-7,4)+1)) | F18: =IF($D18="","",IF($V18<>"",$V18,IFERROR(INDEX('参数设置'!$D$17:$G$26,MATCH($D18,'参数设置'!$C$17:$C$26,0),MATCH($E18,'参数设置'!$D$16:$G$16,0)),0))) | G18: =IF($D18="","",INDEX('01人员工时'!$E$7:$E$126,INT((ROW()-7)/4)+1)) | H18: =IF($D18="","",INDEX('01人员工时'!$O$7:$O$126,INT((ROW()-7)/4)+1)) | I18: =IF(OR($D18="",$G18=0),"",$H18/$G18) | J18: =IF($D18="","",ROUND($F18,2)-$S18) | K18: =IF(OR($D18="",$G18=0),"",ROUND($F18*INDEX('01人员工时'!G$7:G$126,INT((ROW()-7)/4)+1)/$G18,2)) | L18: =IF(OR($D18="",$G18=0),"",ROUND($F18*INDEX('01人员工时'!H$7:H$126,INT((ROW()-7)/4)+1)/$G18,2)) | M18: =IF(OR($D18="",$G18=0),"",ROUND($F18*INDEX('01人员工时'!I$7:I$126,INT((ROW()-7)/4)+1)/$G18,2)) | N18: =IF(OR($D18="",$G18=0),"",ROUND($F18*INDEX('01人员工时'!J$7:J$126,INT((ROW()-7)/4)+1)/$G18,2)) | O18: =IF(OR($D18="",$G18=0),"",ROUND($F18*INDEX('01人员工时'!K$7:K$126,INT((ROW()-7)/4)+1)/$G18,2)) | P18: =IF(OR($D18="",$G18=0),"",ROUND($F18*INDEX('01人员工时'!L$7:L$126,INT((ROW()-7)/4)+1)/$G18,2)) | Q18: =IF(OR($D18="",$G18=0),"",ROUND($F18*INDEX('01人员工时'!M$7:M$126,INT((ROW()-7)/4)+1)/$G18,2)) | R18: =IF(OR($D18="",$G18=0),"",ROUND($F18*INDEX('01人员工时'!N$7:N$126,INT((ROW()-7)/4)+1)/$G18,2)) | S18: =IF($D18="","",SUM(K18:R18)) | T18: =IF($D18="","",$J18+$S18) | U18: =IF($D18="","",IF($F18=0,"未维护标准",IF(ROUND($T18-$F18,2)=0,"√","差异")))
... B486: =IF(INDEX('01人员工时'!$D$7:$D$126,INT((ROW()-7)/4)+1)&""="","",INDEX('01人员工时'!$B$7:$B$126,INT((ROW()-7)/4)+1)) | C486: =IF($D486="","",IF(MOD(ROW()-7,4)=0,INDEX('01人员工时'!$C$7:$C$126,INT((ROW()-7)/4)+1),"")) | D486: =IF(INDEX('01人员工时'!$D$7:$D$126,INT((ROW()-7)/4)+1)&""="","",INDEX('01人员工时'!$D$7:$D$126,INT((ROW()-7)/4)+1)) | E486: =IF($D486="","",INDEX('参数设置'!$K$6:$K$9,MOD(ROW()-7,4)+1)) | F486: =IF($D486="","",IF($V486<>"",$V486,IFERROR(INDEX('参数设置'!$D$17:$G$26,MATCH($D486,'参数设置'!$C$17:$C$26,0),MATCH($E486,'参数设置'!$D$16:$G$16,0)),0))) | G486: =IF($D486="","",INDEX('01人员工时'!$E$7:$E$126,INT((ROW()-7)/4)+1)) | H486: =IF($D486="","",INDEX('01人员工时'!$O$7:$O$126,INT((ROW()-7)/4)+1)) | I486: =IF(OR($D486="",$G486=0),"",$H486/$G486) | J486: =IF($D486="","",ROUND($F486,2)-$S486) | K486: =IF(OR($D486="",$G486=0),"",ROUND($F486*INDEX('01人员工时'!G$7:G$126,INT((ROW()-7)/4)+1)/$G486,2)) | L486: =IF(OR($D486="",$G486=0),"",ROUND($F486*INDEX('01人员工时'!H$7:H$126,INT((ROW()-7)/4)+1)/$G486,2)) | M486: =IF(OR($D486="",$G486=0),"",ROUND($F486*INDEX('01人员工时'!I$7:I$126,INT((ROW()-7)/4)+1)/$G486,2)) | N486: =IF(OR($D486="",$G486=0),"",ROUND($F486*INDEX('01人员工时'!J$7:J$126,INT((ROW()-7)/4)+1)/$G486,2)) | O486: =IF(OR($D486="",$G486=0),"",ROUND($F486*INDEX('01人员工时'!K$7:K$126,INT((ROW()-7)/4)+1)/$G486,2)) | P486: =IF(OR($D486="",$G486=0),"",ROUND($F486*INDEX('01人员工时'!L$7:L$126,INT((ROW()-7)/4)+1)/$G486,2)) | Q486: =IF(OR($D486="",$G486=0),"",ROUND($F486*INDEX('01人员工时'!M$7:M$126,INT((ROW()-7)/4)+1)/$G486,2)) | R486: =IF(OR($D486="",$G486=0),"",ROUND($F486*INDEX('01人员工时'!N$7:N$126,INT((ROW()-7)/4)+1)/$G486,2)) | S486: =IF($D486="","",SUM(K486:R486)) | T486: =IF($D486="","",$J486+$S486) | U486: =IF($D486="","",IF($F486=0,"未维护标准",IF(ROUND($T486-$F486,2)=0,"√","差异")))
B487: 全年累计 | F487: =SUM(F7:F486) | G487: =SUM(G7:G486) | H487: =SUM(H7:H486) | I487: =IF($G487=0,"",$H487/$G487) | J487: =SUM(J7:J486) | K487: =SUM(K7:K486) | L487: =SUM(L7:L486) | M487: =SUM(M7:M486) | N487: =SUM(N7:N486) | O487: =SUM(O7:O486) | P487: =SUM(P7:P486) | Q487: =SUM(Q7:Q486) | ... T487: =SUM(T7:T486)
B489: 说明：某项目分摊额＝费用总额×该项目工时÷当月总工时；非研发承担额＝费用总额−研发各项目合计（含尾差），保证“非研发＋各项目＝合计＝费用总额”。
B490: 【本月实际金额（覆盖）】列留空时按【参数设置】页标准取数；填入数字则以填入数为准。

Sheet 03设备工时
B2: 2026年 研发设备工时（研发部报送数据，粘贴区）
Q3: 数据来源： | R3: 研发部工时台账
B4: 月份 | C4: 序号 | D4: 设备编号 | E4: 设备名称 | F4: 运行总工时 （小时） | G4: 非研发活动工时 （小时） | H4: 各项目分配工时（小时） | Q4: 分摊系数 | R4: 备注
H5: ='参数设置'!$C$6 | I5: ='参数设置'!$C$7 | J5: ='参数设置'!$C$8 | K5: ='参数设置'!$C$9 | L5: ='参数设置'!$C$10 | M5: ='参数设置'!$C$11 | N5: ='参数设置'!$C$12 | O5: ='参数设置'!$C$13 | P5: 合计 | Q5: 研发工时/总工时
H6: ='参数设置'!$D$6 | I6: ='参数设置'!$D$7 | J6: ='参数设置'!$D$8 | K6: ='参数设置'!$D$9 | L6: ='参数设置'!$D$10 | M6: ='参数设置'!$D$11 | N6: ='参数设置'!$D$12 | O6: ='参数设置'!$D$13
B7: 9 | C7: 1 | D7: 046 | E7: 贴合分条机 | F7: 180 | G7: 36 | H7: 36 | I7: 36 | K7: 36 | L7: 36 | P7: =IF($D7="","",SUM(H7:O7)) | Q7: =IF(OR($D7="",$F7=0),"",$P7/$F7) | R7: 示例数据，启用前请清空
B8: 9 | C8: 2 | D8: 054 | E8: 风淋室 | F8: 180 | G8: 72 | I8: 36 | J8: 36 | K8: 36 | P8: =IF($D8="","",SUM(H8:O8)) | Q8: =IF(OR($D8="",$F8=0),"",$P8/$F8)
B9: 9 | C9: 3 | D9: 084 | E9: 1450分条机 | F9: 180 | G9: 36 | H9: 36 | I9: 36 | J9: 36 | L9: 36 | P9: =IF($D9="","",SUM(H9:O9)) | Q9: =IF(OR($D9="",$F9=0),"",$P9/$F9)
B10: 9 | C10: 4 | D10: 083 | E10: 650贴合机 | F10: 180 | G10: 72 | J10: 36 | K10: 36 | L10: 36 | P10: =IF($D10="","",SUM(H10:O10)) | Q10: =IF(OR($D10="",$F10=0),"",$P10/$F10)
B11: 9 | C11: 5 | D11: 072 | E11: 650表面卷曲分条机 | F11: 180 | G11: 108 | J11: 36 | L11: 36 | P11: =IF($D11="","",SUM(H11:O11)) | Q11: =IF(OR($D11="",$F11=0),"",$P11/$F11)
B12: 9 | C12: 6 | D12: 082 | E12: 精密双轴分切机 | F12: 180 | G12: 144 | J12: 36 | P12: =IF($D12="","",SUM(H12:O12)) | Q12: =IF(OR($D12="",$F12=0),"",$P12/$F12)
B13: 9 | C13: 7 | D13: 071 | E13: 高精密立板式涂布机 | F13: 180 | G13: 144 | J13: 36 | P13: =IF($D13="","",SUM(H13:O13)) | Q13: =IF(OR($D13="",$F13=0),"",$P13/$F13)
B14: 9 | C14: 8 | D14: 080 | E14: 傅里叶变换红外光谱仪 | F14: 180 | G14: 180 | P14: =IF($D14="","",SUM(H14:O14)) | Q14: =IF(OR($D14="",$F14=0),"",$P14/$F14)
B15: 9 | C15: 9 | D15: 086 | E15: 1300高精密复卷机 | F15: 180 | G15: 144 | I15: 36 | P15: =IF($D15="","",SUM(H15:O15)) | Q15: =IF(OR($D15="",$F15=0),"",$P15/$F15)
B16: 9 | C16: 10 | D16: 079 | E16: 1200MM泡棉分条机 | F16: 180 | G16: 144 | I16: 36 | P16: =IF($D16="","",SUM(H16:O16)) | Q16: =IF(OR($D16="",$F16=0),"",$P16/$F16)
B17: 9 | C17: 11 | D17: 081 | E17: 表面电阻测试仪 | F17: 180 | G17: 0 | H17: 36 | I17: 36 | J17: 36 | K17: 36 | L17: 36 | P17: =IF($D17="","",SUM(H17:O17)) | Q17: =IF(OR($D17="",$F17=0),"",$P17/$F17)
P18: =IF($D18="","",SUM(H18:O18)) | Q18: =IF(OR($D18="",$F18=0),"",$P18/$F18)
P19: =IF($D19="","",SUM(H19:O19)) | Q19: =IF(OR($D19="",$F19=0),"",$P19/$F19)
P20: =IF($D20="","",SUM(H20:O20)) | Q20: =IF(OR($D20="",$F20=0),"",$P20/$F20)
P21: =IF($D21="","",SUM(H21:O21)) | Q21: =IF(OR($D21="",$F21=0),"",$P21/$F21)
P22: =IF($D22="","",SUM(H22:O22)) | Q22: =IF(OR($D22="",$F22=0),"",$P22/$F22)
P23: =IF($D23="","",SUM(H23:O23)) | Q23: =IF(OR($D23="",$F23=0),"",$P23/$F23)
P24: =IF($D24="","",SUM(H24:O24)) | Q24: =IF(OR($D24="",$F24=0),"",$P24/$F24)
P25: =IF($D25="","",SUM(H25:O25)) | Q25: =IF(OR($D25="",$F25=0),"",$P25/$F25)
P26: =IF($D26="","",SUM(H26:O26)) | Q26: =IF(OR($D26="",$F26=0),"",$P26/$F26)
P27: =IF($D27="","",SUM(H27:O27)) | Q27: =IF(OR($D27="",$F27=0),"",$P27/$F27)
P28: =IF($D28="","",SUM(H28:O28)) | Q28: =IF(OR($D28="",$F28=0),"",$P28/$F28)
P29: =IF($D29="","",SUM(H29:O29)) | Q29: =IF(OR($D29="",$F29=0),"",$P29/$F29)
... P150: =IF($D150="","",SUM(H150:O150)) | Q150: =IF(OR($D150="",$F150=0),"",$P150/$F150)

Sheet 04设备折旧分摊
B2: 2026年 研发设备折旧费分摊表（按工时分摊）
B4: 月份 | C4: 序号 | D4: 设备编号 | E4: 设备名称 | F4: 月折旧额 （元） | G4: 当月总工时 （小时） | H4: 其中：研发 工时（小时） | I4: 研发工时 占比 | J4: 费用分摊（元） | T4: 合计 （元） | U4: 校验 | V4: 本月实际 金额（覆盖） | W4: 备注
J5: 非研发 承担 | K5: ='参数设置'!$C$6 | L5: ='参数设置'!$C$7 | M5: ='参数设置'!$C$8 | N5: ='参数设置'!$C$9 | O5: ='参数设置'!$C$10 | P5: ='参数设置'!$C$11 | Q5: ='参数设置'!$C$12 | R5: ='参数设置'!$C$13 | S5: 研发 合计
K6: ='参数设置'!$D$6 | L6: ='参数设置'!$D$7 | M6: ='参数设置'!$D$8 | N6: ='参数设置'!$D$9 | O6: ='参数设置'!$D$10 | P6: ='参数设置'!$D$11 | Q6: ='参数设置'!$D$12 | R6: ='参数设置'!$D$13
B7: =IF('03设备工时'!$D7="","",'03设备工时'!$B7) | C7: =IF('03设备工时'!$D7="","",'03设备工时'!$C7) | D7: =IF('03设备工时'!$D7="","",'03设备工时'!$D7) | E7: =IF($D7="","",'03设备工时'!$E7) | F7: =IF($D7="","",IF($V7<>"",$V7,IFERROR(INDEX('参数设置'!$E$30:$E$44,MATCH($D7,'参数设置'!$C$30:$C$44,0)),0))) | G7: =IF($D7="","",'03设备工时'!$F7) | H7: =IF($D7="","",'03设备工时'!$P7) | I7: =IF(OR($D7="",$G7=0),"",$H7/$G7) | J7: =IF($D7="","",ROUND($F7,2)-$S7) | K7: =IF(OR($D7="",$G7=0),"",ROUND($F7*'03设备工时'!H7/$G7,2)) | L7: =IF(OR($D7="",$G7=0),"",ROUND($F7*'03设备工时'!I7/$G7,2)) | M7: =IF(OR($D7="",$G7=0),"",ROUND($F7*'03设备工时'!J7/$G7,2)) | N7: =IF(OR($D7="",$G7=0),"",ROUND($F7*'03设备工时'!K7/$G7,2)) | O7: =IF(OR($D7="",$G7=0),"",ROUND($F7*'03设备工时'!L7/$G7,2)) | P7: =IF(OR($D7="",$G7=0),"",ROUND($F7*'03设备工时'!M7/$G7,2)) | Q7: =IF(OR($D7="",$G7=0),"",ROUND($F7*'03设备工时'!N7/$G7,2)) | R7: =IF(OR($D7="",$G7=0),"",ROUND($F7*'03设备工时'!O7/$G7,2)) | S7: =IF($D7="","",SUM(K7:R7)) | T7: =IF($D7="","",$J7+$S7) | U7: =IF($D7="","",IF($F7=0,"未维护折旧额",IF(ROUND($T7-$F7,2)=0,"√","差异"))) | W7: =IF($D7="","",IFERROR(INDEX('参数设置'!$F$30:$F$44,MATCH($D7,'参数设置'!$C$30:$C$44,0)),""))
B8: =IF('03设备工时'!$D8="","",'03设备工时'!$B8) | C8: =IF('03设备工时'!$D8="","",'03设备工时'!$C8) | D8: =IF('03设备工时'!$D8="","",'03设备工时'!$D8) | E8: =IF($D8="","",'03设备工时'!$E8) | F8: =IF($D8="","",IF($V8<>"",$V8,IFERROR(INDEX('参数设置'!$E$30:$E$44,MATCH($D8,'参数设置'!$C$30:$C$44,0)),0))) | G8: =IF($D8="","",'03设备工时'!$F8) | H8: =IF($D8="","",'03设备工时'!$P8) | I8: =IF(OR($D8="",$G8=0),"",$H8/$G8) | J8: =IF($D8="","",ROUND($F8,2)-$S8) | K8: =IF(OR($D8="",$G8=0),"",ROUND($F8*'03设备工时'!H8/$G8,2)) | L8: =IF(OR($D8="",$G8=0),"",ROUND($F8*'03设备工时'!I8/$G8,2)) | M8: =IF(OR($D8="",$G8=0),"",ROUND($F8*'03设备工时'!J8/$G8,2)) | N8: =IF(OR($D8="",$G8=0),"",ROUND($F8*'03设备工时'!K8/$G8,2)) | O8: =IF(OR($D8="",$G8=0),"",ROUND($F8*'03设备工时'!L8/$G8,2)) | P8: =IF(OR($D8="",$G8=0),"",ROUND($F8*'03设备工时'!M8/$G8,2)) | Q8: =IF(OR($D8="",$G8=0),"",ROUND($F8*'03设备工时'!N8/$G8,2)) | R8: =IF(OR($D8="",$G8=0),"",ROUND($F8*'03设备工时'!O8/$G8,2)) | S8: =IF($D8="","",SUM(K8:R8)) | T8: =IF($D8="","",$J8+$S8) | U8: =IF($D8="","",IF($F8=0,"未维护折旧额",IF(ROUND($T8-$F8,2)=0,"√","差异"))) | W8: =IF($D8="","",IFERROR(INDEX('参数设置'!$F$30:$F$44,MATCH($D8,'参数设置'!$C$30:$C$44,0)),""))
B9: =IF('03设备工时'!$D9="","",'03设备工时'!$B9) | C9: =IF('03设备工时'!$D9="","",'03设备工时'!$C9) | D9: =IF('03设备工时'!$D9="","",'03设备工时'!$D9) | E9: =IF($D9="","",'03设备工时'!$E9) | F9: =IF($D9="","",IF($V9<>"",$V9,IFERROR(INDEX('参数设置'!$E$30:$E$44,MATCH($D9,'参数设置'!$C$30:$C$44,0)),0))) | G9: =IF($D9="","",'03设备工时'!$F9) | H9: =IF($D9="","",'03设备工时'!$P9) | I9: =IF(OR($D9="",$G9=0),"",$H9/$G9) | J9: =IF($D9="","",ROUND($F9,2)-$S9) | K9: =IF(OR($D9="",$G9=0),"",ROUND($F9*'03设备工时'!H9/$G9,2)) | L9: =IF(OR($D9="",$G9=0),"",ROUND($F9*'03设备工时'!I9/$G9,2)) | M9: =IF(OR($D9="",$G9=0),"",ROUND($F9*'03设备工时'!J9/$G9,2)) | N9: =IF(OR($D9="",$G9=0),"",ROUND($F9*'03设备工时'!K9/$G9,2)) | O9: =IF(OR($D9="",$G9=0),"",ROUND($F9*'03设备工时'!L9/$G9,2)) | P9: =IF(OR($D9="",$G9=0),"",ROUND($F9*'03设备工时'!M9/$G9,2)) | Q9: =IF(OR($D9="",$G9=0),"",ROUND($F9*'03设备工时'!N9/$G9,2)) | R9: =IF(OR($D9="",$G9=0),"",ROUND($F9*'03设备工时'!O9/$G9,2)) | S9: =IF($D9="","",SUM(K9:R9)) | T9: =IF($D9="","",$J9+$S9) | U9: =IF($D9="","",IF($F9=0,"未维护折旧额",IF(ROUND($T9-$F9,2)=0,"√","差异"))) | W9: =IF($D9="","",IFERROR(INDEX('参数设置'!$F$30:$F$44,MATCH($D9,'参数设置'!$C$30:$C$44,0)),""))
B10: =IF('03设备工时'!$D10="","",'03设备工时'!$B10) | C10: =IF('03设备工时'!$D10="","",'03设备工时'!$C10) | D10: =IF('03设备工时'!$D10="","",'03设备工时'!$D10) | E10: =IF($D10="","",'03设备工时'!$E10) | F10: =IF($D10="","",IF($V10<>"",$V10,IFERROR(INDEX('参数设置'!$E$30:$E$44,MATCH($D10,'参数设置'!$C$30:$C$44,0)),0))) | G10: =IF($D10="","",'03设备工时'!$F10) | H10: =IF($D10="","",'03设备工时'!$P10) | I10: =IF(OR($D10="",$G10=0),"",$H10/$G10) | J10: =IF($D10="","",ROUND($F10,2)-$S10) | K10: =IF(OR($D10="",$G10=0),"",ROUND($F10*'03设备工时'!H10/$G10,2)) | L10: =IF(OR($D10="",$G10=0),"",ROUND($F10*'03设备工时'!I10/$G10,2)) | M10: =IF(OR($D10="",$G10=0),"",ROUND($F10*'03设备工时'!J10/$G10,2)) | N10: =IF(OR($D10="",$G10=0),"",ROUND($F10*'03设备工时'!K10/$G10,2)) | O10: =IF(OR($D10="",$G10=0),"",ROUND($F10*'03设备工时'!L10/$G10,2)) | P10: =IF(OR($D10="",$G10=0),"",ROUND($F10*'03设备工时'!M10/$G10,2)) | Q10: =IF(OR($D10="",$G10=0),"",ROUND($F10*'03设备工时'!N10/$G10,2)) | R10: =IF(OR($D10="",$G10=0),"",ROUND($F10*'03设备工时'!O10/$G10,2)) | S10: =IF($D10="","",SUM(K10:R10)) | T10: =IF($D10="","",$J10+$S10) | U10: =IF($D10="","",IF($F10=0,"未维护折旧额",IF(ROUND($T10-$F10,2)=0,"√","差异"))) | W10: =IF($D10="","",IFERROR(INDEX('参数设置'!$F$30:$F$44,MATCH($D10,'参数设置'!$C$30:$C$44,0)),""))
B11: =IF('03设备工时'!$D11="","",'03设备工时'!$B11) | C11: =IF('03设备工时'!$D11="","",'03设备工时'!$C11) | D11: =IF('03设备工时'!$D11="","",'03设备工时'!$D11) | E11: =IF($D11="","",'03设备工时'!$E11) | F11: =IF($D11="","",IF($V11<>"",$V11,IFERROR(INDEX('参数设置'!$E$30:$E$44,MATCH($D11,'参数设置'!$C$30:$C$44,0)),0))) | G11: =IF($D11="","",'03设备工时'!$F11) | H11: =IF($D11="","",'03设备工时'!$P11) | I11: =IF(OR($D11="",$G11=0),"",$H11/$G11) | J11: =IF($D11="","",ROUND($F11,2)-$S11) | K11: =IF(OR($D11="",$G11=0),"",ROUND($F11*'03设备工时'!H11/$G11,2)) | L11: =IF(OR($D11="",$G11=0),"",ROUND($F11*'03设备工时'!I11/$G11,2)) | M11: =IF(OR($D11="",$G11=0),"",ROUND($F11*'03设备工时'!J11/$G11,2)) | N11: =IF(OR($D11="",$G11=0),"",ROUND($F11*'03设备工时'!K11/$G11,2)) | O11: =IF(OR($D11="",$G11=0),"",ROUND($F11*'03设备工时'!L11/$G11,2)) | P11: =IF(OR($D11="",$G11=0),"",ROUND($F11*'03设备工时'!M11/$G11,2)) | Q11: =IF(OR($D11="",$G11=0),"",ROUND($F11*'03设备工时'!N11/$G11,2)) | R11: =IF(OR($D11="",$G11=0),"",ROUND($F11*'03设备工时'!O11/$G11,2)) | S11: =IF($D11="","",SUM(K11:R11)) | T11: =IF($D11="","",$J11+$S11) | U11: =IF($D11="","",IF($F11=0,"未维护折旧额",IF(ROUND($T11-$F11,2)=0,"√","差异"))) | W11: =IF($D11="","",IFERROR(INDEX('参数设置'!$F$30:$F$44,MATCH($D11,'参数设置'!$C$30:$C$44,0)),""))
B12: =IF('03设备工时'!$D12="","",'03设备工时'!$B12) | C12: =IF('03设备工时'!$D12="","",'03设备工时'!$C12) | D12: =IF('03设备工时'!$D12="","",'03设备工时'!$D12) | E12: =IF($D12="","",'03设备工时'!$E12) | F12: =IF($D12="","",IF($V12<>"",$V12,IFERROR(INDEX('参数设置'!$E$30:$E$44,MATCH($D12,'参数设置'!$C$30:$C$44,0)),0))) | G12: =IF($D12="","",'03设备工时'!$F12) | H12: =IF($D12="","",'03设备工时'!$P12) | I12: =IF(OR($D12="",$G12=0),"",$H12/$G12) | J12: =IF($D12="","",ROUND($F12,2)-$S12) | K12: =IF(OR($D12="",$G12=0),"",ROUND($F12*'03设备工时'!H12/$G12,2)) | L12: =IF(OR($D12="",$G12=0),"",ROUND($F12*'03设备工时'!I12/$G12,2)) | M12: =IF(OR($D12="",$G12=0),"",ROUND($F12*'03设备工时'!J12/$G12,2)) | N12: =IF(OR($D12="",$G12=0),"",ROUND($F12*'03设备工时'!K12/$G12,2)) | O12: =IF(OR($D12="",$G12=0),"",ROUND($F12*'03设备工时'!L12/$G12,2)) | P12: =IF(OR($D12="",$G12=0),"",ROUND($F12*'03设备工时'!M12/$G12,2)) | Q12: =IF(OR($D12="",$G12=0),"",ROUND($F12*'03设备工时'!N12/$G12,2)) | R12: =IF(OR($D12="",$G12=0),"",ROUND($F12*'03设备工时'!O12/$G12,2)) | S12: =IF($D12="","",SUM(K12:R12)) | T12: =IF($D12="","",$J12+$S12) | U12: =IF($D12="","",IF($F12=0,"未维护折旧额",IF(ROUND($T12-$F12,2)=0,"√","差异"))) | W12: =IF($D12="","",IFERROR(INDEX('参数设置'!$F$30:$F$44,MATCH($D12,'参数设置'!$C$30:$C$44,0)),""))
B13: =IF('03设备工时'!$D13="","",'03设备工时'!$B13) | C13: =IF('03设备工时'!$D13="","",'03设备工时'!$C13) | D13: =IF('03设备工时'!$D13="","",'03设备工时'!$D13) | E13: =IF($D13="","",'03设备工时'!$E13) | F13: =IF($D13="","",IF($V13<>"",$V13,IFERROR(INDEX('参数设置'!$E$30:$E$44,MATCH($D13,'参数设置'!$C$30:$C$44,0)),0))) | G13: =IF($D13="","",'03设备工时'!$F13) | H13: =IF($D13="","",'03设备工时'!$P13) | I13: =IF(OR($D13="",$G13=0),"",$H13/$G13) | J13: =IF($D13="","",ROUND($F13,2)-$S13) | K13: =IF(OR($D13="",$G13=0),"",ROUND($F13*'03设备工时'!H13/$G13,2)) | L13: =IF(OR($D13="",$G13=0),"",ROUND($F13*'03设备工时'!I13/$G13,2)) | M13: =IF(OR($D13="",$G13=0),"",ROUND($F13*'03设备工时'!J13/$G13,2)) | N13: =IF(OR($D13="",$G13=0),"",ROUND($F13*'03设备工时'!K13/$G13,2)) | O13: =IF(OR($D13="",$G13=0),"",ROUND($F13*'03设备工时'!L13/$G13,2)) | P13: =IF(OR($D13="",$G13=0),"",ROUND($F13*'03设备工时'!M13/$G13,2)) | Q13: =IF(OR($D13="",$G13=0),"",ROUND($F13*'03设备工时'!N13/$G13,2)) | R13: =IF(OR($D13="",$G13=0),"",ROUND($F13*'03设备工时'!O13/$G13,2)) | S13: =IF($D13="","",SUM(K13:R13)) | T13: =IF($D13="","",$J13+$S13) | U13: =IF($D13="","",IF($F13=0,"未维护折旧额",IF(ROUND($T13-$F13,2)=0,"√","差异"))) | W13: =IF($D13="","",IFERROR(INDEX('参数设置'!$F$30:$F$44,MATCH($D13,'参数设置'!$C$30:$C$44,0)),""))
B14: =IF('03设备工时'!$D14="","",'03设备工时'!$B14) | C14: =IF('03设备工时'!$D14="","",'03设备工时'!$C14) | D14: =IF('03设备工时'!$D14="","",'03设备工时'!$D14) | E14: =IF($D14="","",'03设备工时'!$E14) | F14: =IF($D14="","",IF($V14<>"",$V14,IFERROR(INDEX('参数设置'!$E$30:$E$44,MATCH($D14,'参数设置'!$C$30:$C$44,0)),0))) | G14: =IF($D14="","",'03设备工时'!$F14) | H14: =IF($D14="","",'03设备工时'!$P14) | I14: =IF(OR($D14="",$G14=0),"",$H14/$G14) | J14: =IF($D14="","",ROUND($F14,2)-$S14) | K14: =IF(OR($D14="",$G14=0),"",ROUND($F14*'03设备工时'!H14/$G14,2)) | L14: =IF(OR($D14="",$G14=0),"",ROUND($F14*'03设备工时'!I14/$G14,2)) | M14: =IF(OR($D14="",$G14=0),"",ROUND($F14*'03设备工时'!J14/$G14,2)) | N14: =IF(OR($D14="",$G14=0),"",ROUND($F14*'03设备工时'!K14/$G14,2)) | O14: =IF(OR($D14="",$G14=0),"",ROUND($F14*'03设备工时'!L14/$G14,2)) | P14: =IF(OR($D14="",$G14=0),"",ROUND($F14*'03设备工时'!M14/$G14,2)) | Q14: =IF(OR($D14="",$G14=0),"",ROUND($F14*'03设备工时'!N14/$G14,2)) | R14: =IF(OR($D14="",$G14=0),"",ROUND($F14*'03设备工时'!O14/$G14,2)) | S14: =IF($D14="","",SUM(K14:R14)) | T14: =IF($D14="","",$J14+$S14) | U14: =IF($D14="","",IF($F14=0,"未维护折旧额",IF(ROUND($T14-$F14,2)=0,"√","差异"))) | W14: =IF($D14="","",IFERROR(INDEX('参数设置'!$F$30:$F$44,MATCH($D14,'参数设置'!$C$30:$C$44,0)),""))
B15: =IF('03设备工时'!$D15="","",'03设备工时'!$B15) | C15: =IF('03设备工时'!$D15="","",'03设备工时'!$C15) | D15: =IF('03设备工时'!$D15="","",'03设备工时'!$D15) | E15: =IF($D15="","",'03设备工时'!$E15) | F15: =IF($D15="","",IF($V15<>"",$V15,IFERROR(INDEX('参数设置'!$E$30:$E$44,MATCH($D15,'参数设置'!$C$30:$C$44,0)),0))) | G15: =IF($D15="","",'03设备工时'!$F15) | H15: =IF($D15="","",'03设备工时'!$P15) | I15: =IF(OR($D15="",$G15=0),"",$H15/$G15) | J15: =IF($D15="","",ROUND($F15,2)-$S15) | K15: =IF(OR($D15="",$G15=0),"",ROUND($F15*'03设备工时'!H15/$G15,2)) | L15: =IF(OR($D15="",$G15=0),"",ROUND($F15*'03设备工时'!I15/$G15,2)) | M15: =IF(OR($D15="",$G15=0),"",ROUND($F15*'03设备工时'!J15/$G15,2)) | N15: =IF(OR($D15="",$G15=0),"",ROUND($F15*'03设备工时'!K15/$G15,2)) | O15: =IF(OR($D15="",$G15=0),"",ROUND($F15*'03设备工时'!L15/$G15,2)) | P15: =IF(OR($D15="",$G15=0),"",ROUND($F15*'03设备工时'!M15/$G15,2)) | Q15: =IF(OR($D15="",$G15=0),"",ROUND($F15*'03设备工时'!N15/$G15,2)) | R15: =IF(OR($D15="",$G15=0),"",ROUND($F15*'03设备工时'!O15/$G15,2)) | S15: =IF($D15="","",SUM(K15:R15)) | T15: =IF($D15="","",$J15+$S15) | U15: =IF($D15="","",IF($F15=0,"未维护折旧额",IF(ROUND($T15-$F15,2)=0,"√","差异"))) | W15: =IF($D15="","",IFERROR(INDEX('参数设置'!$F$30:$F$44,MATCH($D15,'参数设置'!$C$30:$C$44,0)),""))
B16: =IF('03设备工时'!$D16="","",'03设备工时'!$B16) | C16: =IF('03设备工时'!$D16="","",'03设备工时'!$C16) | D16: =IF('03设备工时'!$D16="","",'03设备工时'!$D16) | E16: =IF($D16="","",'03设备工时'!$E16) | F16: =IF($D16="","",IF($V16<>"",$V16,IFERROR(INDEX('参数设置'!$E$30:$E$44,MATCH($D16,'参数设置'!$C$30:$C$44,0)),0))) | G16: =IF($D16="","",'03设备工时'!$F16) | H16: =IF($D16="","",'03设备工时'!$P16) | I16: =IF(OR($D16="",$G16=0),"",$H16/$G16) | J16: =IF($D16="","",ROUND($F16,2)-$S16) | K16: =IF(OR($D16="",$G16=0),"",ROUND($F16*'03设备工时'!H16/$G16,2)) | L16: =IF(OR($D16="",$G16=0),"",ROUND($F16*'03设备工时'!I16/$G16,2)) | M16: =IF(OR($D16="",$G16=0),"",ROUND($F16*'03设备工时'!J16/$G16,2)) | N16: =IF(OR($D16="",$G16=0),"",ROUND($F16*'03设备工时'!K16/$G16,2)) | O16: =IF(OR($D16="",$G16=0),"",ROUND($F16*'03设备工时'!L16/$G16,2)) | P16: =IF(OR($D16="",$G16=0),"",ROUND($F16*'03设备工时'!M16/$G16,2)) | Q16: =IF(OR($D16="",$G16=0),"",ROUND($F16*'03设备工时'!N16/$G16,2)) | R16: =IF(OR($D16="",$G16=0),"",ROUND($F16*'03设备工时'!O16/$G16,2)) | S16: =IF($D16="","",SUM(K16:R16)) | T16: =IF($D16="","",$J16+$S16) | U16: =IF($D16="","",IF($F16=0,"未维护折旧额",IF(ROUND($T16-$F16,2)=0,"√","差异"))) | W16: =IF($D16="","",IFERROR(INDEX('参数设置'!$F$30:$F$44,MATCH($D16,'参数设置'!$C$30:$C$44,0)),""))
B17: =IF('03设备工时'!$D17="","",'03设备工时'!$B17) | C17: =IF('03设备工时'!$D17="","",'03设备工时'!$C17) | D17: =IF('03设备工时'!$D17="","",'03设备工时'!$D17) | E17: =IF($D17="","",'03设备工时'!$E17) | F17: =IF($D17="","",IF($V17<>"",$V17,IFERROR(INDEX('参数设置'!$E$30:$E$44,MATCH($D17,'参数设置'!$C$30:$C$44,0)),0))) | G17: =IF($D17="","",'03设备工时'!$F17) | H17: =IF($D17="","",'03设备工时'!$P17) | I17: =IF(OR($D17="",$G17=0),"",$H17/$G17) | J17: =IF($D17="","",ROUND($F17,2)-$S17) | K17: =IF(OR($D17="",$G17=0),"",ROUND($F17*'03设备工时'!H17/$G17,2)) | L17: =IF(OR($D17="",$G17=0),"",ROUND($F17*'03设备工时'!I17/$G17,2)) | M17: =IF(OR($D17="",$G17=0),"",ROUND($F17*'03设备工时'!J17/$G17,2)) | N17: =IF(OR($D17="",$G17=0),"",ROUND($F17*'03设备工时'!K17/$G17,2)) | O17: =IF(OR($D17="",$G17=0),"",ROUND($F17*'03设备工时'!L17/$G17,2)) | P17: =IF(OR($D17="",$G17=0),"",ROUND($F17*'03设备工时'!M17/$G17,2)) | Q17: =IF(OR($D17="",$G17=0),"",ROUND($F17*'03设备工时'!N17/$G17,2)) | R17: =IF(OR($D17="",$G17=0),"",ROUND($F17*'03设备工时'!O17/$G17,2)) | S17: =IF($D17="","",SUM(K17:R17)) | T17: =IF($D17="","",$J17+$S17) | U17: =IF($D17="","",IF($F17=0,"未维护折旧额",IF(ROUND($T17-$F17,2)=0,"√","差异"))) | W17: =IF($D17="","",IFERROR(INDEX('参数设置'!$F$30:$F$44,MATCH($D17,'参数设置'!$C$30:$C$44,0)),""))
B18: =IF('03设备工时'!$D18="","",'03设备工时'!$B18) | C18: =IF('03设备工时'!$D18="","",'03设备工时'!$C18) | D18: =IF('03设备工时'!$D18="","",'03设备工时'!$D18) | E18: =IF($D18="","",'03设备工时'!$E18) | F18: =IF($D18="","",IF($V18<>"",$V18,IFERROR(INDEX('参数设置'!$E$30:$E$44,MATCH($D18,'参数设置'!$C$30:$C$44,0)),0))) | G18: =IF($D18="","",'03设备工时'!$F18) | H18: =IF($D18="","",'03设备工时'!$P18) | I18: =IF(OR($D18="",$G18=0),"",$H18/$G18) | J18: =IF($D18="","",ROUND($F18,2)-$S18) | K18: =IF(OR($D18="",$G18=0),"",ROUND($F18*'03设备工时'!H18/$G18,2)) | L18: =IF(OR($D18="",$G18=0),"",ROUND($F18*'03设备工时'!I18/$G18,2)) | M18: =IF(OR($D18="",$G18=0),"",ROUND($F18*'03设备工时'!J18/$G18,2)) | N18: =IF(OR($D18="",$G18=0),"",ROUND($F18*'03设备工时'!K18/$G18,2)) | O18: =IF(OR($D18="",$G18=0),"",ROUND($F18*'03设备工时'!L18/$G18,2)) | P18: =IF(OR($D18="",$G18=0),"",ROUND($F18*'03设备工时'!M18/$G18,2)) | Q18: =IF(OR($D18="",$G18=0),"",ROUND($F18*'03设备工时'!N18/$G18,2)) | R18: =IF(OR($D18="",$G18=0),"",ROUND($F18*'03设备工时'!O18/$G18,2)) | S18: =IF($D18="","",SUM(K18:R18)) | T18: =IF($D18="","",$J18+$S18) | U18: =IF($D18="","",IF($F18=0,"未维护折旧额",IF(ROUND($T18-$F18,2)=0,"√","差异"))) | W18: =IF($D18="","",IFERROR(INDEX('参数设置'!$F$30:$F$44,MATCH($D18,'参数设置'!$C$30:$C$44,0)),""))
... B150: =IF('03设备工时'!$D150="","",'03设备工时'!$B150) | C150: =IF('03设备工时'!$D150="","",'03设备工时'!$C150) | D150: =IF('03设备工时'!$D150="","",'03设备工时'!$D150) | E150: =IF($D150="","",'03设备工时'!$E150) | F150: =IF($D150="","",IF($V150<>"",$V150,IFERROR(INDEX('参数设置'!$E$30:$E$44,MATCH($D150,'参数设置'!$C$30:$C$44,0)),0))) | G150: =IF($D150="","",'03设备工时'!$F150) | H150: =IF($D150="","",'03设备工时'!$P150) | I150: =IF(OR($D150="",$G150=0),"",$H150/$G150) | J150: =IF($D150="","",ROUND($F150,2)-$S150) | K150: =IF(OR($D150="",$G150=0),"",ROUND($F150*'03设备工时'!H150/$G150,2)) | L150: =IF(OR($D150="",$G150=0),"",ROUND($F150*'03设备工时'!I150/$G150,2)) | M150: =IF(OR($D150="",$G150=0),"",ROUND($F150*'03设备工时'!J150/$G150,2)) | N150: =IF(OR($D150="",$G150=0),"",ROUND($F150*'03设备工时'!K150/$G150,2)) | O150: =IF(OR($D150="",$G150=0),"",ROUND($F150*'03设备工时'!L150/$G150,2)) | P150: =IF(OR($D150="",$G150=0),"",ROUND($F150*'03设备工时'!M150/$G150,2)) | Q150: =IF(OR($D150="",$G150=0),"",ROUND($F150*'03设备工时'!N150/$G150,2)) | R150: =IF(OR($D150="",$G150=0),"",ROUND($F150*'03设备工时'!O150/$G150,2)) | S150: =IF($D150="","",SUM(K150:R150)) | T150: =IF($D150="","",$J150+$S150) | U150: =IF($D150="","",IF($F150=0,"未维护折旧额",IF(ROUND($T150-$F150,2)=0,"√","差异"))) | W150: =IF($D150="","",IFERROR(INDEX('参数设置'!$F$30:$F$44,MATCH($D150,'参数设置'!$C$30:$C$44,0)),""))
B151: 全年累计 | F151: =SUM(F7:F150) | G151: =SUM(G7:G150) | H151: =SUM(H7:H150) | I151: =IF($G151=0,"",$H151/$G151) | J151: =SUM(J7:J150) | K151: =SUM(K7:K150) | L151: =SUM(L7:L150) | M151: =SUM(M7:M150) | N151: =SUM(N7:N150) | O151: =SUM(O7:O150) | P151: =SUM(P7:P150) | Q151: =SUM(Q7:Q150) | ... T151: =SUM(T7:T150)
B153: 说明：某项目分摊额＝费用总额×该项目工时÷当月总工时；非研发承担额＝费用总额−研发各项目合计（含尾差），保证“非研发＋各项目＝合计＝费用总额”。
B154: 【本月实际金额（覆盖）】列留空时按【参数设置】页标准取数；填入数字则以填入数为准。

Sheet 05无形资产工时
B2: 2026年 无形资产工时（研发部报送数据，粘贴区）
Q3: 数据来源： | R3: 研发部工时台账
B4: 月份 | C4: 序号 | D4: 资产编号 | E4: 资产名称 | F4: 运行总工时 （小时） | G4: 非研发活动工时 （小时） | H4: 各项目分配工时（小时） | Q4: 分摊系数 | R4: 备注
H5: ='参数设置'!$C$6 | I5: ='参数设置'!$C$7 | J5: ='参数设置'!$C$8 | K5: ='参数设置'!$C$9 | L5: ='参数设置'!$C$10 | M5: ='参数设置'!$C$11 | N5: ='参数设置'!$C$12 | O5: ='参数设置'!$C$13 | P5: 合计 | Q5: 研发工时/总工时
H6: ='参数设置'!$D$6 | I6: ='参数设置'!$D$7 | J6: ='参数设置'!$D$8 | K6: ='参数设置'!$D$9 | L6: ='参数设置'!$D$10 | M6: ='参数设置'!$D$11 | N6: ='参数设置'!$D$12 | O6: ='参数设置'!$D$13
B7: 9 | C7: 1 | D7: Z0001 | E7: 硬力 | F7: 180 | G7: 36 | H7: 36 | I7: 36 | J7: 36 | K7: 36 | P7: =IF($D7="","",SUM(H7:O7)) | Q7: =IF(OR($D7="",$F7=0),"",$P7/$F7) | R7: 示例数据，启用前请清空
B8: 9 | C8: 2 | D8: Z0002 | E8: 泡棉 | F8: 180 | G8: 36 | I8: 36 | J8: 36 | K8: 36 | L8: 36 | P8: =IF($D8="","",SUM(H8:O8)) | Q8: =IF(OR($D8="",$F8=0),"",$P8/$F8)
B9: 9 | C9: 3 | D9: Z0003 | E9: 拉力 | F9: 180 | G9: 72 | H9: 36 | J9: 36 | L9: 36 | P9: =IF($D9="","",SUM(H9:O9)) | Q9: =IF(OR($D9="",$F9=0),"",$P9/$F9)
B10: 9 | C10: 4 | D10: Z0004 | E10: 贴合 | F10: 180 | G10: 108 | H10: 36 | I10: 36 | P10: =IF($D10="","",SUM(H10:O10)) | Q10: =IF(OR($D10="",$F10=0),"",$P10/$F10)
B11: 9 | C11: 5 | D11: Z0005 | E11: 拉手 | F11: 180 | G11: 108 | K11: 36 | L11: 36 | P11: =IF($D11="","",SUM(H11:O11)) | Q11: =IF(OR($D11="",$F11=0),"",$P11/$F11)
B12: 9 | C12: 6 | D12: Z0006 | E12: 配比 | F12: 180 | G12: 144 | J12: 36 | P12: =IF($D12="","",SUM(H12:O12)) | Q12: =IF(OR($D12="",$F12=0),"",$P12/$F12)
P13: =IF($D13="","",SUM(H13:O13)) | Q13: =IF(OR($D13="",$F13=0),"",$P13/$F13)
P14: =IF($D14="","",SUM(H14:O14)) | Q14: =IF(OR($D14="",$F14=0),"",$P14/$F14)
P15: =IF($D15="","",SUM(H15:O15)) | Q15: =IF(OR($D15="",$F15=0),"",$P15/$F15)
P16: =IF($D16="","",SUM(H16:O16)) | Q16: =IF(OR($D16="",$F16=0),"",$P16/$F16)
P17: =IF($D17="","",SUM(H17:O17)) | Q17: =IF(OR($D17="",$F17=0),"",$P17/$F17)
P18: =IF($D18="","",SUM(H18:O18)) | Q18: =IF(OR($D18="",$F18=0),"",$P18/$F18)
P19: =IF($D19="","",SUM(H19:O19)) | Q19: =IF(OR($D19="",$F19=0),"",$P19/$F19)
P20: =IF($D20="","",SUM(H20:O20)) | Q20: =IF(OR($D20="",$F20=0),"",$P20/$F20)
P21: =IF($D21="","",SUM(H21:O21)) | Q21: =IF(OR($D21="",$F21=0),"",$P21/$F21)
P22: =IF($D22="","",SUM(H22:O22)) | Q22: =IF(OR($D22="",$F22=0),"",$P22/$F22)
P23: =IF($D23="","",SUM(H23:O23)) | Q23: =IF(OR($D23="",$F23=0),"",$P23/$F23)
P24: =IF($D24="","",SUM(H24:O24)) | Q24: =IF(OR($D24="",$F24=0),"",$P24/$F24)
... P102: =IF($D102="","",SUM(H102:O102)) | Q102: =IF(OR($D102="",$F102=0),"",$P102/$F102)

Sheet 06无形资产摊销分摊
B2: 2026年 无形资产摊销费分摊表（按工时分摊）
B4: 月份 | C4: 序号 | D4: 资产编号 | E4: 资产名称 | F4: 月摊销额 （元） | G4: 当月总工时 （小时） | H4: 其中：研发 工时（小时） | I4: 研发工时 占比 | J4: 费用分摊（元） | T4: 合计 （元） | U4: 校验 | V4: 本月实际 金额（覆盖） | W4: 备注
J5: 非研发 承担 | K5: ='参数设置'!$C$6 | L5: ='参数设置'!$C$7 | M5: ='参数设置'!$C$8 | N5: ='参数设置'!$C$9 | O5: ='参数设置'!$C$10 | P5: ='参数设置'!$C$11 | Q5: ='参数设置'!$C$12 | R5: ='参数设置'!$C$13 | S5: 研发 合计
K6: ='参数设置'!$D$6 | L6: ='参数设置'!$D$7 | M6: ='参数设置'!$D$8 | N6: ='参数设置'!$D$9 | O6: ='参数设置'!$D$10 | P6: ='参数设置'!$D$11 | Q6: ='参数设置'!$D$12 | R6: ='参数设置'!$D$13
B7: =IF('05无形资产工时'!$D7="","",'05无形资产工时'!$B7) | C7: =IF('05无形资产工时'!$D7="","",'05无形资产工时'!$C7) | D7: =IF('05无形资产工时'!$D7="","",'05无形资产工时'!$D7) | E7: =IF($D7="","",'05无形资产工时'!$E7) | F7: =IF($D7="","",IF($V7<>"",$V7,IFERROR(INDEX('参数设置'!$E$48:$E$57,MATCH($D7,'参数设置'!$C$48:$C$57,0)),0))) | G7: =IF($D7="","",'05无形资产工时'!$F7) | H7: =IF($D7="","",'05无形资产工时'!$P7) | I7: =IF(OR($D7="",$G7=0),"",$H7/$G7) | J7: =IF($D7="","",ROUND($F7,2)-$S7) | K7: =IF(OR($D7="",$G7=0),"",ROUND($F7*'05无形资产工时'!H7/$G7,2)) | L7: =IF(OR($D7="",$G7=0),"",ROUND($F7*'05无形资产工时'!I7/$G7,2)) | M7: =IF(OR($D7="",$G7=0),"",ROUND($F7*'05无形资产工时'!J7/$G7,2)) | N7: =IF(OR($D7="",$G7=0),"",ROUND($F7*'05无形资产工时'!K7/$G7,2)) | O7: =IF(OR($D7="",$G7=0),"",ROUND($F7*'05无形资产工时'!L7/$G7,2)) | P7: =IF(OR($D7="",$G7=0),"",ROUND($F7*'05无形资产工时'!M7/$G7,2)) | Q7: =IF(OR($D7="",$G7=0),"",ROUND($F7*'05无形资产工时'!N7/$G7,2)) | R7: =IF(OR($D7="",$G7=0),"",ROUND($F7*'05无形资产工时'!O7/$G7,2)) | S7: =IF($D7="","",SUM(K7:R7)) | T7: =IF($D7="","",$J7+$S7) | U7: =IF($D7="","",IF($F7=0,"未维护摊销额",IF(ROUND($T7-$F7,2)=0,"√","差异")))
B8: =IF('05无形资产工时'!$D8="","",'05无形资产工时'!$B8) | C8: =IF('05无形资产工时'!$D8="","",'05无形资产工时'!$C8) | D8: =IF('05无形资产工时'!$D8="","",'05无形资产工时'!$D8) | E8: =IF($D8="","",'05无形资产工时'!$E8) | F8: =IF($D8="","",IF($V8<>"",$V8,IFERROR(INDEX('参数设置'!$E$48:$E$57,MATCH($D8,'参数设置'!$C$48:$C$57,0)),0))) | G8: =IF($D8="","",'05无形资产工时'!$F8) | H8: =IF($D8="","",'05无形资产工时'!$P8) | I8: =IF(OR($D8="",$G8=0),"",$H8/$G8) | J8: =IF($D8="","",ROUND($F8,2)-$S8) | K8: =IF(OR($D8="",$G8=0),"",ROUND($F8*'05无形资产工时'!H8/$G8,2)) | L8: =IF(OR($D8="",$G8=0),"",ROUND($F8*'05无形资产工时'!I8/$G8,2)) | M8: =IF(OR($D8="",$G8=0),"",ROUND($F8*'05无形资产工时'!J8/$G8,2)) | N8: =IF(OR($D8="",$G8=0),"",ROUND($F8*'05无形资产工时'!K8/$G8,2)) | O8: =IF(OR($D8="",$G8=0),"",ROUND($F8*'05无形资产工时'!L8/$G8,2)) | P8: =IF(OR($D8="",$G8=0),"",ROUND($F8*'05无形资产工时'!M8/$G8,2)) | Q8: =IF(OR($D8="",$G8=0),"",ROUND($F8*'05无形资产工时'!N8/$G8,2)) | R8: =IF(OR($D8="",$G8=0),"",ROUND($F8*'05无形资产工时'!O8/$G8,2)) | S8: =IF($D8="","",SUM(K8:R8)) | T8: =IF($D8="","",$J8+$S8) | U8: =IF($D8="","",IF($F8=0,"未维护摊销额",IF(ROUND($T8-$F8,2)=0,"√","差异")))
B9: =IF('05无形资产工时'!$D9="","",'05无形资产工时'!$B9) | C9: =IF('05无形资产工时'!$D9="","",'05无形资产工时'!$C9) | D9: =IF('05无形资产工时'!$D9="","",'05无形资产工时'!$D9) | E9: =IF($D9="","",'05无形资产工时'!$E9) | F9: =IF($D9="","",IF($V9<>"",$V9,IFERROR(INDEX('参数设置'!$E$48:$E$57,MATCH($D9,'参数设置'!$C$48:$C$57,0)),0))) | G9: =IF($D9="","",'05无形资产工时'!$F9) | H9: =IF($D9="","",'05无形资产工时'!$P9) | I9: =IF(OR($D9="",$G9=0),"",$H9/$G9) | J9: =IF($D9="","",ROUND($F9,2)-$S9) | K9: =IF(OR($D9="",$G9=0),"",ROUND($F9*'05无形资产工时'!H9/$G9,2)) | L9: =IF(OR($D9="",$G9=0),"",ROUND($F9*'05无形资产工时'!I9/$G9,2)) | M9: =IF(OR($D9="",$G9=0),"",ROUND($F9*'05无形资产工时'!J9/$G9,2)) | N9: =IF(OR($D9="",$G9=0),"",ROUND($F9*'05无形资产工时'!K9/$G9,2)) | O9: =IF(OR($D9="",$G9=0),"",ROUND($F9*'05无形资产工时'!L9/$G9,2)) | P9: =IF(OR($D9="",$G9=0),"",ROUND($F9*'05无形资产工时'!M9/$G9,2)) | Q9: =IF(OR($D9="",$G9=0),"",ROUND($F9*'05无形资产工时'!N9/$G9,2)) | R9: =IF(OR($D9="",$G9=0),"",ROUND($F9*'05无形资产工时'!O9/$G9,2)) | S9: =IF($D9="","",SUM(K9:R9)) | T9: =IF($D9="","",$J9+$S9) | U9: =IF($D9="","",IF($F9=0,"未维护摊销额",IF(ROUND($T9-$F9,2)=0,"√","差异")))
B10: =IF('05无形资产工时'!$D10="","",'05无形资产工时'!$B10) | C10: =IF('05无形资产工时'!$D10="","",'05无形资产工时'!$C10) | D10: =IF('05无形资产工时'!$D10="","",'05无形资产工时'!$D10) | E10: =IF($D10="","",'05无形资产工时'!$E10) | F10: =IF($D10="","",IF($V10<>"",$V10,IFERROR(INDEX('参数设置'!$E$48:$E$57,MATCH($D10,'参数设置'!$C$48:$C$57,0)),0))) | G10: =IF($D10="","",'05无形资产工时'!$F10) | H10: =IF($D10="","",'05无形资产工时'!$P10) | I10: =IF(OR($D10="",$G10=0),"",$H10/$G10) | J10: =IF($D10="","",ROUND($F10,2)-$S10) | K10: =IF(OR($D10="",$G10=0),"",ROUND($F10*'05无形资产工时'!H10/$G10,2)) | L10: =IF(OR($D10="",$G10=0),"",ROUND($F10*'05无形资产工时'!I10/$G10,2)) | M10: =IF(OR($D10="",$G10=0),"",ROUND($F10*'05无形资产工时'!J10/$G10,2)) | N10: =IF(OR($D10="",$G10=0),"",ROUND($F10*'05无形资产工时'!K10/$G10,2)) | O10: =IF(OR($D10="",$G10=0),"",ROUND($F10*'05无形资产工时'!L10/$G10,2)) | P10: =IF(OR($D10="",$G10=0),"",ROUND($F10*'05无形资产工时'!M10/$G10,2)) | Q10: =IF(OR($D10="",$G10=0),"",ROUND($F10*'05无形资产工时'!N10/$G10,2)) | R10: =IF(OR($D10="",$G10=0),"",ROUND($F10*'05无形资产工时'!O10/$G10,2)) | S10: =IF($D10="","",SUM(K10:R10)) | T10: =IF($D10="","",$J10+$S10) | U10: =IF($D10="","",IF($F10=0,"未维护摊销额",IF(ROUND($T10-$F10,2)=0,"√","差异")))
B11: =IF('05无形资产工时'!$D11="","",'05无形资产工时'!$B11) | C11: =IF('05无形资产工时'!$D11="","",'05无形资产工时'!$C11) | D11: =IF('05无形资产工时'!$D11="","",'05无形资产工时'!$D11) | E11: =IF($D11="","",'05无形资产工时'!$E11) | F11: =IF($D11="","",IF($V11<>"",$V11,IFERROR(INDEX('参数设置'!$E$48:$E$57,MATCH($D11,'参数设置'!$C$48:$C$57,0)),0))) | G11: =IF($D11="","",'05无形资产工时'!$F11) | H11: =IF($D11="","",'05无形资产工时'!$P11) | I11: =IF(OR($D11="",$G11=0),"",$H11/$G11) | J11: =IF($D11="","",ROUND($F11,2)-$S11) | K11: =IF(OR($D11="",$G11=0),"",ROUND($F11*'05无形资产工时'!H11/$G11,2)) | L11: =IF(OR($D11="",$G11=0),"",ROUND($F11*'05无形资产工时'!I11/$G11,2)) | M11: =IF(OR($D11="",$G11=0),"",ROUND($F11*'05无形资产工时'!J11/$G11,2)) | N11: =IF(OR($D11="",$G11=0),"",ROUND($F11*'05无形资产工时'!K11/$G11,2)) | O11: =IF(OR($D11="",$G11=0),"",ROUND($F11*'05无形资产工时'!L11/$G11,2)) | P11: =IF(OR($D11="",$G11=0),"",ROUND($F11*'05无形资产工时'!M11/$G11,2)) | Q11: =IF(OR($D11="",$G11=0),"",ROUND($F11*'05无形资产工时'!N11/$G11,2)) | R11: =IF(OR($D11="",$G11=0),"",ROUND($F11*'05无形资产工时'!O11/$G11,2)) | S11: =IF($D11="","",SUM(K11:R11)) | T11: =IF($D11="","",$J11+$S11) | U11: =IF($D11="","",IF($F11=0,"未维护摊销额",IF(ROUND($T11-$F11,2)=0,"√","差异")))
B12: =IF('05无形资产工时'!$D12="","",'05无形资产工时'!$B12) | C12: =IF('05无形资产工时'!$D12="","",'05无形资产工时'!$C12) | D12: =IF('05无形资产工时'!$D12="","",'05无形资产工时'!$D12) | E12: =IF($D12="","",'05无形资产工时'!$E12) | F12: =IF($D12="","",IF($V12<>"",$V12,IFERROR(INDEX('参数设置'!$E$48:$E$57,MATCH($D12,'参数设置'!$C$48:$C$57,0)),0))) | G12: =IF($D12="","",'05无形资产工时'!$F12) | H12: =IF($D12="","",'05无形资产工时'!$P12) | I12: =IF(OR($D12="",$G12=0),"",$H12/$G12) | J12: =IF($D12="","",ROUND($F12,2)-$S12) | K12: =IF(OR($D12="",$G12=0),"",ROUND($F12*'05无形资产工时'!H12/$G12,2)) | L12: =IF(OR($D12="",$G12=0),"",ROUND($F12*'05无形资产工时'!I12/$G12,2)) | M12: =IF(OR($D12="",$G12=0),"",ROUND($F12*'05无形资产工时'!J12/$G12,2)) | N12: =IF(OR($D12="",$G12=0),"",ROUND($F12*'05无形资产工时'!K12/$G12,2)) | O12: =IF(OR($D12="",$G12=0),"",ROUND($F12*'05无形资产工时'!L12/$G12,2)) | P12: =IF(OR($D12="",$G12=0),"",ROUND($F12*'05无形资产工时'!M12/$G12,2)) | Q12: =IF(OR($D12="",$G12=0),"",ROUND($F12*'05无形资产工时'!N12/$G12,2)) | R12: =IF(OR($D12="",$G12=0),"",ROUND($F12*'05无形资产工时'!O12/$G12,2)) | S12: =IF($D12="","",SUM(K12:R12)) | T12: =IF($D12="","",$J12+$S12) | U12: =IF($D12="","",IF($F12=0,"未维护摊销额",IF(ROUND($T12-$F12,2)=0,"√","差异")))
B13: =IF('05无形资产工时'!$D13="","",'05无形资产工时'!$B13) | C13: =IF('05无形资产工时'!$D13="","",'05无形资产工时'!$C13) | D13: =IF('05无形资产工时'!$D13="","",'05无形资产工时'!$D13) | E13: =IF($D13="","",'05无形资产工时'!$E13) | F13: =IF($D13="","",IF($V13<>"",$V13,IFERROR(INDEX('参数设置'!$E$48:$E$57,MATCH($D13,'参数设置'!$C$48:$C$57,0)),0))) | G13: =IF($D13="","",'05无形资产工时'!$F13) | H13: =IF($D13="","",'05无形资产工时'!$P13) | I13: =IF(OR($D13="",$G13=0),"",$H13/$G13) | J13: =IF($D13="","",ROUND($F13,2)-$S13) | K13: =IF(OR($D13="",$G13=0),"",ROUND($F13*'05无形资产工时'!H13/$G13,2)) | L13: =IF(OR($D13="",$G13=0),"",ROUND($F13*'05无形资产工时'!I13/$G13,2)) | M13: =IF(OR($D13="",$G13=0),"",ROUND($F13*'05无形资产工时'!J13/$G13,2)) | N13: =IF(OR($D13="",$G13=0),"",ROUND($F13*'05无形资产工时'!K13/$G13,2)) | O13: =IF(OR($D13="",$G13=0),"",ROUND($F13*'05无形资产工时'!L13/$G13,2)) | P13: =IF(OR($D13="",$G13=0),"",ROUND($F13*'05无形资产工时'!M13/$G13,2)) | Q13: =IF(OR($D13="",$G13=0),"",ROUND($F13*'05无形资产工时'!N13/$G13,2)) | R13: =IF(OR($D13="",$G13=0),"",ROUND($F13*'05无形资产工时'!O13/$G13,2)) | S13: =IF($D13="","",SUM(K13:R13)) | T13: =IF($D13="","",$J13+$S13) | U13: =IF($D13="","",IF($F13=0,"未维护摊销额",IF(ROUND($T13-$F13,2)=0,"√","差异")))
